# Ancient Warfare Structure Template File
# Auto-generated structure template file. created on: 3/15/2024 at: 10:25:46
# Lines beginning with # denote comments

header:
version=2.11
name=MerchantGuildMosswoodStoneTradersQuark
mods=quark
size=43,20,43
offset=23,5,26
:endheader

#### VALIDATION ####
validation:
type=ground
structureAuthor=TheOddlySeagull
survival=false
worldGenEnabled=true
unique=false
preserveBlocks=false
preventNaturalHostileSpawns=true
selectionWeight=30
clusterValue=30
minDuplicateDistance=5000
dimensionWhiteList=true
dimensionList=0
biomeGroupList=
biomeWhiteList=true
biomeList=environs:tall_oak_forest,nt:tall_oak_forest,minecraft:forest,nt:autumn_forest,nt:oak_forest,nt:mixed_forest,biomesoplenty:boreal_forest
leveling=16
fill=16
border=5
blockSwap=false
territoryName=guild
biomeReplacement=minecraft:
minGenerationHeight=0
maxGenerationHeight=255
:endvalidation

#### LAYERS ####
layer: 0
1,1,1,1,1,1,1,1,1,1,1,1,1,1,1,1,1,1,1,1,1,1,1,1,1,1,1,1,1,1,1,1,1,1,1,1,1,1,1,1,1,1,1
1,1,1,1,1,1,1,1,1,1,1,1,1,1,1,1,1,1,1,1,1,1,1,1,1,1,1,1,1,1,1,1,1,1,1,1,1,1,1,1,1,1,1
1,1,1,1,1,1,1,1,1,1,1,1,1,1,1,1,1,1,1,1,1,1,1,1,1,1,1,1,1,1,1,1,1,1,1,1,1,1,1,1,1,1,1
1,1,1,1,1,1,1,1,1,1,1,1,1,1,1,1,1,1,1,1,1,1,1,1,1,1,1,1,1,1,1,1,1,1,1,1,1,1,1,1,1,1,1
1,1,1,1,1,1,1,1,1,1,1,1,1,1,1,1,1,1,1,1,1,1,1,1,1,1,1,1,1,1,1,1,1,1,1,1,1,1,1,1,1,1,1
1,1,1,1,1,1,1,1,1,1,1,1,1,1,1,1,1,1,1,1,1,1,1,1,1,1,1,1,1,1,1,1,1,1,1,1,1,1,1,1,1,1,1
1,1,1,1,1,1,1,1,1,1,1,1,1,1,1,1,1,1,1,1,1,1,1,1,1,1,1,1,1,1,1,1,1,1,1,1,1,1,1,1,1,1,1
1,1,1,1,1,1,1,1,1,1,1,1,1,1,1,1,1,1,1,1,1,1,1,1,1,1,1,1,1,1,1,1,1,1,1,1,1,1,1,1,1,1,1
1,1,1,1,1,1,1,1,1,1,1,1,1,1,1,1,1,1,1,1,1,1,1,1,1,1,1,1,1,1,1,1,1,1,1,1,1,1,1,1,1,1,1
1,1,1,1,1,1,1,1,1,1,1,1,1,1,1,1,1,1,1,1,1,1,1,1,1,1,1,1,1,1,1,1,1,1,1,1,1,1,1,1,1,1,1
1,1,1,1,1,1,1,1,1,1,1,1,1,1,1,1,1,1,1,1,1,1,1,1,1,1,1,1,1,1,1,1,1,1,1,1,1,1,1,1,1,1,1
1,1,1,1,1,1,1,1,1,1,1,1,1,1,1,1,1,1,1,1,1,1,1,1,1,1,1,1,1,1,1,1,1,1,1,1,1,1,1,1,1,1,1
1,1,1,1,1,1,1,1,1,1,1,1,1,1,1,1,1,1,1,1,1,1,1,1,1,1,1,1,1,1,1,1,1,1,1,1,1,1,1,1,1,1,1
1,1,1,1,1,1,1,1,1,1,1,1,1,1,1,1,1,1,1,1,1,1,1,1,1,1,1,1,1,1,1,1,1,1,1,1,1,1,1,1,1,1,1
1,1,1,1,1,1,1,1,1,1,1,1,1,1,1,1,1,1,1,1,1,1,1,1,1,1,1,1,1,1,1,1,1,1,1,1,1,1,1,1,1,1,1
1,1,1,1,1,1,1,1,1,1,1,1,1,1,1,1,1,1,1,1,1,1,1,1,1,1,1,1,1,1,1,1,1,1,1,1,1,1,1,1,1,1,1
1,1,1,1,1,1,1,1,1,1,1,1,1,1,1,1,1,1,1,1,1,1,1,1,1,1,1,1,1,1,1,1,1,1,1,1,1,1,1,1,1,1,1
1,1,1,1,1,1,1,1,1,1,1,1,1,1,1,1,1,1,1,1,1,1,1,1,1,1,1,1,1,1,1,1,1,1,1,1,1,1,1,1,1,1,1
1,1,1,1,1,1,1,1,1,1,1,1,1,1,1,1,1,1,1,1,1,1,1,1,1,1,1,1,1,1,1,1,1,1,1,1,1,1,1,1,1,1,1
1,1,1,1,1,1,1,1,1,1,1,1,1,1,1,1,1,1,1,1,1,1,1,1,1,1,1,1,1,1,1,1,1,1,1,1,1,1,1,1,1,1,1
1,1,1,1,1,1,1,1,1,1,1,1,1,1,1,1,1,1,1,1,1,1,1,1,1,1,1,1,1,1,1,1,1,1,1,1,1,1,1,1,1,1,1
1,1,1,1,1,1,1,1,1,1,1,1,1,1,1,1,1,1,1,1,1,1,1,1,1,1,1,1,1,1,1,1,1,1,1,1,1,1,1,1,1,1,1
1,1,1,1,1,1,1,1,1,1,1,1,1,1,1,1,1,1,1,1,1,1,1,1,1,1,1,1,1,1,1,1,1,1,1,1,1,1,1,1,1,1,1
1,1,1,1,1,1,1,1,1,1,1,1,1,1,1,1,1,1,1,1,1,1,1,1,1,1,1,1,1,1,1,1,1,1,1,1,1,1,1,1,1,1,1
1,1,1,1,1,1,1,1,1,1,1,1,1,1,1,1,1,1,1,1,1,1,1,1,1,1,1,1,1,1,1,1,1,1,1,1,1,1,1,1,1,1,1
1,1,1,1,1,1,1,1,1,1,1,1,1,1,1,1,1,1,1,1,1,1,1,1,1,1,1,1,1,1,1,1,1,1,1,1,1,1,1,1,1,1,1
1,1,1,1,1,1,1,1,1,1,1,1,1,1,1,1,1,1,1,1,1,1,1,1,1,1,1,1,1,1,1,1,1,1,1,1,1,1,1,1,1,1,1
1,1,1,1,1,1,1,1,1,1,1,1,1,1,1,1,1,1,1,1,1,1,1,1,1,1,1,1,1,1,1,1,1,1,1,1,1,1,1,1,1,1,1
1,1,1,1,1,1,1,1,1,1,1,1,1,1,1,1,1,1,1,1,1,1,1,1,1,1,1,1,1,1,1,1,1,1,1,1,1,1,1,1,1,1,1
1,1,1,1,1,1,1,1,1,1,1,1,1,1,1,1,1,1,1,1,1,1,1,1,1,1,1,1,1,1,1,1,1,1,1,1,1,1,1,1,1,1,1
1,1,1,1,1,1,1,1,1,1,1,1,1,1,1,1,1,1,1,1,1,1,1,1,1,1,1,1,1,1,1,1,1,1,1,1,1,1,1,1,1,1,1
1,1,1,1,1,1,1,1,1,1,1,1,1,1,1,1,1,1,1,1,1,1,1,1,1,1,1,1,1,1,1,1,1,1,1,1,1,1,1,1,1,1,1
1,1,1,1,1,1,1,1,1,1,1,1,1,1,1,1,1,1,1,1,1,1,1,1,1,1,1,1,1,1,1,1,1,1,1,1,1,1,1,1,1,1,1
1,1,1,1,1,1,1,1,1,1,1,1,1,1,1,1,1,1,1,1,1,1,1,1,1,1,1,1,1,1,1,1,1,1,1,1,1,1,1,1,1,1,1
1,1,1,1,1,1,1,1,1,1,1,1,1,1,1,1,1,1,1,1,1,1,1,1,1,1,1,1,1,1,1,1,1,1,1,1,1,1,1,1,1,1,1
1,1,1,1,1,1,1,1,1,1,1,1,1,1,1,1,1,1,1,1,1,1,1,1,1,1,1,1,1,1,1,1,1,1,1,1,1,1,1,1,1,1,1
1,1,1,1,1,1,1,1,1,1,1,1,1,1,1,1,1,1,1,1,1,1,1,1,1,1,1,1,1,1,1,1,1,1,1,1,1,1,1,1,1,1,1
1,1,1,1,1,1,1,1,1,1,1,1,1,1,1,1,1,1,1,1,1,1,1,1,1,1,1,1,1,1,1,1,1,1,1,1,1,1,1,1,1,1,1
1,1,1,1,1,1,1,1,1,1,1,1,1,1,1,1,1,1,1,1,1,1,1,1,1,1,1,1,1,1,1,1,1,1,1,1,1,1,1,1,1,1,1
1,1,1,1,1,1,1,1,1,1,1,1,1,1,1,1,1,1,1,1,1,1,1,1,1,1,1,1,1,1,1,1,1,1,1,1,1,1,1,1,1,1,1
1,1,1,1,1,1,1,1,1,1,1,1,1,1,1,1,1,1,1,1,1,1,1,1,1,1,1,1,1,1,1,1,1,1,1,1,1,1,1,1,1,1,1
1,1,1,1,1,1,1,1,1,1,1,1,1,1,1,1,1,1,1,1,1,1,1,1,1,1,1,1,1,1,1,1,1,1,1,1,1,1,1,1,1,1,1
1,1,1,1,1,1,1,1,1,1,1,1,1,1,1,1,1,1,1,1,1,1,1,1,1,1,1,1,1,1,1,1,1,1,1,1,1,1,1,1,1,1,1
:endlayer
layer: 1
1,1,1,1,1,1,1,1,1,1,1,1,1,1,1,1,1,1,1,1,1,1,1,1,1,1,1,1,1,1,1,1,1,1,1,1,1,1,1,1,1,1,1
1,1,1,1,1,1,1,1,1,1,1,1,1,1,1,1,1,1,1,1,1,1,1,1,1,1,1,1,1,1,1,1,1,1,1,1,1,1,1,1,1,1,1
1,1,1,1,1,1,1,1,1,1,1,1,1,1,1,1,1,1,1,1,1,1,1,1,1,1,1,1,1,1,1,1,1,1,1,1,1,1,1,1,1,1,1
1,1,1,1,1,1,1,1,1,1,1,1,1,1,1,1,1,1,1,1,1,1,1,1,1,1,1,1,1,1,1,1,1,1,1,1,1,1,1,1,1,1,1
1,1,1,1,1,1,1,1,1,1,1,1,1,1,1,1,1,1,1,1,1,1,1,1,1,1,1,1,1,1,1,1,1,1,1,1,1,1,1,1,1,1,1
1,1,1,1,1,1,1,1,1,1,1,1,1,1,1,1,1,1,1,1,1,1,1,1,1,1,1,1,1,1,1,1,1,1,1,1,1,1,1,1,1,1,1
1,1,1,1,1,1,1,1,1,1,1,1,1,1,1,1,1,1,1,1,1,1,1,1,1,1,1,1,1,1,1,1,1,1,1,1,1,1,1,1,1,1,1
1,1,1,1,1,1,1,1,1,1,1,1,1,1,1,1,1,1,1,1,1,1,1,1,1,1,1,1,1,1,1,1,1,1,1,1,1,1,1,1,1,1,1
1,1,1,1,1,1,1,1,1,1,1,1,1,1,1,1,1,1,1,1,1,1,1,1,1,1,1,1,1,1,1,1,1,1,1,1,1,1,1,1,1,1,1
1,1,1,1,1,1,1,1,1,1,1,1,1,1,1,1,1,1,1,1,1,1,1,1,1,1,1,1,1,1,1,1,1,1,1,1,1,1,1,1,1,1,1
1,1,1,1,1,1,1,1,1,1,1,1,1,1,1,1,1,1,1,1,1,1,1,1,1,1,1,1,1,1,1,1,1,1,1,1,1,1,1,1,1,1,1
1,1,1,1,1,1,1,1,1,1,1,1,1,1,1,1,1,1,1,1,1,1,1,1,1,1,1,1,1,1,1,1,1,1,1,1,1,1,1,1,1,1,1
1,1,1,1,1,1,1,1,1,1,1,1,1,1,1,1,1,1,1,1,1,1,1,1,1,1,1,1,1,1,1,1,1,1,1,1,1,1,1,1,1,1,1
1,1,1,1,1,1,1,1,1,1,1,1,1,1,1,1,1,1,1,1,1,1,1,1,1,1,1,1,1,1,1,1,1,1,1,1,1,1,1,1,1,1,1
1,1,1,1,1,1,1,1,1,1,1,1,1,1,1,1,1,1,1,1,1,1,1,1,1,1,1,1,1,1,1,1,1,1,1,1,1,1,1,1,1,1,1
1,1,1,1,1,1,1,1,1,1,1,1,1,1,1,1,1,1,1,1,1,1,1,1,1,1,1,1,1,1,1,1,1,1,1,1,1,1,1,1,1,1,1
1,1,1,1,1,1,1,1,1,1,1,1,1,1,1,1,1,1,1,1,1,1,1,1,1,1,1,1,1,1,1,1,1,1,1,1,1,1,1,1,1,1,1
1,1,1,1,1,1,1,1,1,1,1,1,1,1,1,1,1,1,1,1,1,1,1,1,1,1,1,1,1,1,1,1,1,1,1,1,1,1,1,1,1,1,1
1,1,1,1,1,1,1,1,1,1,1,1,1,1,1,1,1,1,1,1,1,1,1,1,1,1,1,1,1,1,1,1,1,1,1,1,1,1,1,1,1,1,1
1,1,1,1,1,1,1,1,1,1,1,1,1,1,1,1,1,1,1,1,1,1,1,1,1,1,1,1,1,1,1,1,1,1,1,1,1,1,1,1,1,1,1
1,1,1,1,1,1,1,1,1,1,1,1,1,1,1,1,1,1,1,1,1,1,1,1,1,1,1,1,1,1,1,1,1,1,1,1,1,1,1,1,1,1,1
1,1,1,1,1,1,1,1,1,1,1,1,1,1,1,1,1,1,1,1,1,1,1,1,1,1,1,1,1,1,1,1,1,1,1,1,1,1,1,1,1,1,1
1,1,1,1,1,1,1,1,1,1,1,1,1,1,1,1,1,1,1,1,1,1,1,1,1,1,1,1,1,1,1,1,1,1,1,1,1,1,1,1,1,1,1
1,1,1,1,1,1,1,1,1,1,1,1,1,1,1,1,1,1,1,1,1,1,1,1,1,1,1,1,1,1,1,1,1,1,1,1,1,1,1,1,1,1,1
1,1,1,1,1,1,1,1,1,1,1,1,1,1,1,1,1,1,1,1,1,1,1,1,1,1,1,1,1,1,1,1,1,1,1,1,1,1,1,1,1,1,1
1,1,1,1,1,1,1,1,1,1,1,1,1,1,1,1,1,1,1,1,1,1,1,1,1,1,1,1,1,1,1,1,1,1,1,1,1,1,1,1,1,1,1
1,1,1,1,1,1,1,1,1,1,1,1,1,1,1,1,1,1,1,1,1,1,1,1,1,1,1,1,1,1,1,1,1,1,1,1,1,1,1,1,1,1,1
1,1,1,1,1,1,1,1,1,1,1,1,1,1,1,1,1,1,1,1,1,1,1,1,1,1,1,1,1,1,1,1,1,1,1,1,1,1,1,1,1,1,1
1,1,1,1,1,1,1,1,1,1,1,1,1,1,1,1,1,1,1,1,1,1,1,1,1,1,1,1,1,1,1,1,1,1,1,1,1,1,1,1,1,1,1
1,1,1,1,1,1,1,1,1,1,1,1,1,1,1,1,1,1,1,1,1,1,1,1,1,1,1,1,1,1,1,1,1,1,1,1,1,1,1,1,1,1,1
1,1,1,1,1,1,1,1,1,1,1,1,1,1,1,1,1,1,1,1,1,1,1,1,1,1,1,1,1,1,1,1,1,1,1,1,1,1,1,1,1,1,1
1,1,1,1,1,1,1,1,1,1,1,1,1,1,1,1,1,1,1,1,1,1,1,1,1,1,1,1,1,1,1,1,1,1,1,1,1,1,1,1,1,1,1
1,1,1,1,1,1,1,1,1,1,1,1,1,1,1,1,1,1,1,1,1,1,1,1,1,1,1,1,1,1,1,1,1,1,1,1,1,1,1,1,1,1,1
1,1,1,1,1,1,1,1,1,1,1,1,1,1,1,1,1,1,1,1,1,1,1,1,1,1,1,1,1,1,1,1,1,1,1,1,1,1,1,1,1,1,1
1,1,1,1,1,1,1,1,1,1,1,1,1,1,1,1,1,1,1,1,1,1,1,1,1,1,1,1,1,1,1,1,1,1,1,1,1,1,1,1,1,1,1
1,1,1,1,1,1,1,1,1,1,1,1,1,1,1,1,1,1,1,1,1,1,1,1,1,1,1,1,1,1,1,1,1,1,1,1,1,1,1,1,1,1,1
1,1,1,1,1,1,1,1,1,1,1,1,1,1,1,1,1,1,1,1,1,1,1,1,1,1,1,1,1,1,1,1,1,1,1,1,1,1,1,1,1,1,1
1,1,1,1,1,1,1,1,1,1,1,1,1,1,1,1,1,1,1,1,1,1,1,1,1,1,1,1,1,1,1,1,1,1,1,1,1,1,1,1,1,1,1
1,1,1,1,1,1,1,1,1,1,1,1,1,1,1,1,1,1,1,1,1,1,1,1,1,1,1,1,1,1,1,1,1,1,1,1,1,1,1,1,1,1,1
1,1,1,1,1,1,1,1,1,1,1,1,1,1,1,1,1,1,1,1,1,1,1,1,1,1,1,1,1,1,1,1,1,1,1,1,1,1,1,1,1,1,1
1,1,1,1,1,1,1,1,1,1,1,1,1,1,1,1,1,1,1,1,1,1,1,1,1,1,1,1,1,1,1,1,1,1,1,1,1,1,1,1,1,1,1
1,1,1,1,1,1,1,1,1,1,1,1,1,1,1,1,1,1,1,1,1,1,1,1,1,1,1,1,1,1,1,1,1,1,1,1,1,1,1,1,1,1,1
1,1,1,1,1,1,1,1,1,1,1,1,1,1,1,1,1,1,1,1,1,1,1,1,1,1,1,1,1,1,1,1,1,1,1,1,1,1,1,1,1,1,1
:endlayer
layer: 2
1,1,1,1,1,1,1,1,1,1,1,1,1,1,1,1,1,1,1,1,1,1,1,1,1,1,1,1,1,1,1,1,1,1,1,1,1,1,1,1,1,1,1
1,1,1,1,1,1,1,1,1,1,1,1,1,1,1,1,1,1,1,1,1,1,1,1,1,1,1,1,1,1,1,1,1,1,1,1,1,1,1,1,1,1,1
1,1,1,1,1,1,1,1,1,1,1,1,1,1,1,1,1,1,1,1,1,1,1,1,1,1,1,1,1,1,1,1,1,1,1,1,1,1,1,1,1,1,1
1,1,1,1,1,1,1,1,1,1,1,1,1,1,1,1,1,1,1,1,1,1,1,1,1,1,1,1,1,1,1,1,1,1,1,1,1,1,1,1,1,1,1
1,1,1,1,1,1,1,1,1,1,1,1,1,1,1,1,1,1,1,1,1,1,1,1,1,1,1,1,1,1,1,1,1,1,1,1,1,1,1,1,1,1,1
1,1,1,1,1,1,1,1,1,1,1,1,1,1,1,1,1,1,1,1,1,1,1,1,1,1,1,1,1,1,1,1,1,1,1,1,1,1,1,1,1,1,1
1,1,1,1,1,1,1,1,1,1,1,1,1,1,1,1,1,1,1,1,1,1,1,1,1,1,1,1,1,1,1,1,1,1,1,1,1,1,1,1,1,1,1
1,1,1,1,1,1,1,1,1,1,1,1,1,1,1,1,1,1,1,1,1,1,1,1,1,1,1,1,1,1,1,1,1,1,1,1,1,1,1,1,1,1,1
1,1,1,1,1,1,1,1,1,1,1,1,1,1,1,1,1,1,1,1,1,1,1,1,1,1,1,1,1,1,1,1,1,1,1,1,1,1,1,1,1,1,1
1,1,1,1,1,1,1,1,1,1,1,1,1,1,1,1,1,1,1,1,1,1,1,1,1,1,1,1,1,1,1,1,1,1,1,1,1,1,1,1,1,1,1
1,1,1,1,1,1,1,1,1,1,1,1,1,1,1,1,1,1,1,1,1,1,1,1,1,1,1,1,1,1,1,1,1,1,1,1,1,1,1,1,1,1,1
1,1,1,1,1,1,1,1,1,1,1,1,1,1,1,1,1,1,1,1,1,1,1,1,1,1,1,1,1,1,1,1,1,1,1,1,1,1,1,1,1,1,1
1,1,1,1,1,1,1,1,1,1,1,1,1,1,1,1,1,1,1,1,1,1,1,1,1,1,1,1,1,1,1,1,1,1,1,1,1,1,1,1,1,1,1
1,1,1,1,1,1,1,1,1,1,1,1,1,1,1,1,1,1,1,1,1,1,1,1,1,1,1,1,1,1,1,1,1,1,1,1,1,1,1,1,1,1,1
1,1,1,1,1,1,1,1,1,1,1,1,1,1,1,1,1,1,1,1,1,1,1,1,1,1,1,1,1,1,1,1,1,1,1,1,1,1,1,1,1,1,1
1,1,1,1,1,1,1,1,1,1,1,1,1,1,1,1,1,1,1,1,1,1,1,1,1,1,1,1,1,1,1,1,1,1,1,1,1,1,1,1,1,1,1
1,1,1,1,1,1,1,1,1,1,1,1,1,1,1,1,1,1,1,1,1,1,1,1,1,1,1,1,1,1,1,1,1,1,1,1,1,1,1,1,1,1,1
1,1,1,1,1,1,1,1,1,1,1,1,1,1,1,1,1,1,1,1,1,1,1,1,1,1,1,1,1,1,1,1,1,1,1,1,1,1,1,1,1,1,1
1,1,1,1,1,1,1,1,1,1,1,1,1,1,1,1,1,1,1,1,1,1,1,1,1,1,1,1,1,1,1,1,1,1,1,1,1,1,1,1,1,1,1
1,1,1,1,1,1,1,1,1,1,1,1,1,1,1,1,1,1,1,1,1,1,1,1,1,1,1,1,1,1,1,1,1,1,1,1,1,1,1,1,1,1,1
1,1,1,1,1,1,1,1,1,1,1,1,1,1,1,1,1,1,1,1,1,1,1,1,1,1,1,1,1,1,1,1,1,1,1,1,1,1,1,1,1,1,1
1,1,1,1,1,1,1,1,1,1,1,1,1,1,1,1,1,1,1,1,1,1,1,1,1,1,1,1,1,1,1,1,1,1,1,1,1,1,1,1,1,1,1
1,1,1,1,1,1,1,1,1,1,1,1,1,1,1,1,1,1,1,1,1,1,1,1,1,1,1,1,1,1,1,1,1,1,1,1,1,1,1,1,1,1,1
1,1,1,1,1,1,1,1,1,1,1,1,1,1,1,1,1,1,1,1,1,1,1,1,1,1,1,1,1,1,1,1,1,1,1,1,1,1,1,1,1,1,1
1,1,1,1,1,1,1,1,1,1,1,1,1,1,1,1,1,1,1,1,1,1,1,1,1,1,1,1,1,1,1,1,1,1,1,1,1,1,1,1,1,1,1
1,1,1,1,1,1,1,1,1,1,1,1,1,1,1,1,1,1,1,1,1,1,1,1,1,1,1,1,1,1,1,1,1,1,1,1,1,1,1,1,1,1,1
1,1,1,1,1,1,1,1,1,1,1,1,1,1,1,1,1,1,1,1,1,1,1,1,1,1,1,1,1,1,1,1,1,1,1,1,1,1,1,1,1,1,1
1,1,1,1,1,1,1,1,1,1,1,1,1,1,1,1,1,1,1,1,1,1,1,1,1,1,1,1,1,1,1,1,1,1,1,1,1,1,1,1,1,1,1
1,1,1,1,1,1,1,1,1,1,1,1,1,1,1,1,1,1,1,1,1,1,1,1,1,1,1,1,1,1,1,1,1,1,1,1,1,1,1,1,1,1,1
1,1,1,1,1,1,1,1,1,1,1,1,1,1,1,1,1,1,1,1,1,1,1,1,1,1,1,1,1,1,1,1,1,1,1,1,1,1,1,1,1,1,1
1,1,1,1,1,1,1,1,1,1,1,1,1,1,1,1,1,1,1,1,1,1,1,1,1,1,1,1,1,1,1,1,1,1,1,1,1,1,1,1,1,1,1
1,1,1,1,1,1,1,1,1,1,1,1,1,1,1,1,1,1,1,1,1,1,1,1,1,1,1,1,1,1,1,1,1,1,1,1,1,1,1,1,1,1,1
1,1,1,1,1,1,1,1,1,1,1,1,1,1,1,1,1,1,1,1,1,1,1,1,1,1,1,1,1,1,1,1,1,1,1,1,1,1,1,1,1,1,1
1,1,1,1,1,1,1,1,1,1,1,1,1,1,1,1,1,1,1,1,1,1,1,1,1,1,1,1,1,1,1,1,1,1,1,1,1,1,1,1,1,1,1
1,1,1,1,1,1,1,1,1,1,1,1,1,1,1,1,1,1,1,1,1,1,1,1,1,1,1,1,1,1,1,1,1,1,1,1,1,1,1,1,1,1,1
1,1,1,1,1,1,1,1,1,1,1,1,1,1,1,1,1,1,1,1,1,1,1,1,1,1,1,1,1,1,1,1,1,1,1,1,1,1,1,1,1,1,1
1,1,1,1,1,1,1,1,1,1,1,1,1,1,1,1,1,1,1,1,1,1,1,1,1,1,1,1,1,1,1,1,1,1,1,1,1,1,1,1,1,1,1
1,1,1,1,1,1,1,1,1,1,1,1,1,1,1,1,1,1,1,1,1,1,1,1,1,1,1,1,1,1,1,1,1,1,1,1,1,1,1,1,1,1,1
1,1,1,1,1,1,1,1,1,1,1,1,1,1,1,1,1,1,1,1,1,1,1,1,1,1,1,1,1,1,1,1,1,1,1,1,1,1,1,1,1,1,1
1,1,1,1,1,1,1,1,1,1,1,1,1,1,1,1,1,1,1,1,1,1,1,1,1,1,1,1,1,1,1,1,1,1,1,1,1,1,1,1,1,1,1
1,1,1,1,1,1,1,1,1,1,1,1,1,1,1,1,1,1,1,1,1,1,1,1,1,1,1,1,1,1,1,1,1,1,1,1,1,1,1,1,1,1,1
1,1,1,1,1,1,1,1,1,1,1,1,1,1,1,1,1,1,1,1,1,1,1,1,1,1,1,1,1,1,1,1,1,1,1,1,1,1,1,1,1,1,1
1,1,1,1,1,1,1,1,1,1,1,1,1,1,1,1,1,1,1,1,1,1,1,1,1,1,1,1,1,1,1,1,1,1,1,1,1,1,1,1,1,1,1
:endlayer
layer: 3
2,2,2,2,2,2,2,2,2,2,2,2,2,2,2,2,2,2,2,2,2,2,2,2,2,2,2,2,2,2,2,2,2,2,2,2,2,2,2,2,2,2,2
2,3,4,4,4,4,3,4,4,4,4,3,4,4,4,4,3,4,4,4,4,3,4,4,4,4,3,4,4,4,4,3,4,4,4,4,3,4,4,4,4,3,2
2,4,2,2,2,2,2,2,2,2,2,2,2,2,2,2,2,2,2,2,2,2,2,2,2,2,2,2,2,2,2,2,2,2,2,2,2,2,2,2,2,4,2
2,4,2,2,2,2,2,2,2,2,2,2,2,2,2,2,2,2,2,2,2,2,2,2,2,2,2,2,2,2,2,2,2,2,2,2,2,2,2,2,2,4,2
2,4,2,2,2,2,2,2,2,2,2,2,2,2,2,2,2,2,2,2,2,2,2,2,2,2,2,2,2,2,2,2,2,2,2,2,2,2,2,2,2,4,2
2,4,2,2,2,2,2,2,2,2,2,2,2,2,2,2,2,2,2,2,2,2,2,2,2,2,2,2,2,2,2,2,2,2,2,2,2,2,2,2,2,4,2
2,3,2,2,2,2,2,2,2,2,2,2,2,2,2,2,2,2,2,2,2,2,2,2,2,2,2,2,2,2,2,2,2,2,2,2,2,2,2,2,2,3,2
2,4,2,2,2,2,2,2,2,2,2,2,2,2,2,2,2,2,2,2,2,2,2,2,2,2,2,2,2,2,2,2,2,2,2,2,2,2,2,2,2,4,2
2,4,2,2,2,2,2,2,2,2,2,2,2,2,2,2,2,2,2,2,2,2,2,2,2,2,2,2,2,2,2,2,2,2,2,2,2,2,2,2,2,4,2
2,4,2,2,2,2,2,2,2,2,2,2,2,2,2,2,2,3,4,4,4,3,4,4,4,4,4,3,4,4,4,3,2,2,2,2,2,2,2,2,2,4,2
2,4,2,2,2,2,2,2,2,2,2,2,2,2,2,2,2,4,2,2,2,2,2,2,2,2,2,2,2,2,2,4,2,2,2,2,2,2,2,2,2,4,2
2,3,2,2,2,2,2,2,2,2,2,2,2,2,2,2,2,4,2,2,2,2,2,2,2,2,2,2,2,2,2,4,2,2,2,2,2,2,2,2,2,3,2
2,4,2,2,2,2,2,2,2,2,2,2,2,2,2,2,2,4,2,2,2,2,2,2,2,2,2,2,2,2,2,4,2,2,2,2,2,2,2,2,2,4,2
2,4,2,2,2,2,2,2,2,2,2,2,2,2,2,2,2,3,2,2,2,3,2,2,2,2,2,3,2,2,2,3,2,2,2,2,2,2,2,2,2,4,2
2,4,2,2,2,2,2,2,2,2,2,2,2,2,2,2,2,4,2,2,2,2,2,2,2,2,2,2,2,2,2,4,2,2,2,2,2,2,2,2,2,4,2
2,4,2,2,2,2,2,2,2,2,2,2,2,2,2,2,2,4,2,2,2,2,2,2,2,2,2,2,2,2,2,4,2,2,2,2,2,2,2,2,2,4,2
2,3,2,2,2,2,2,2,2,2,2,2,2,2,2,2,2,4,2,2,2,2,2,2,2,2,2,2,2,2,2,4,2,2,2,2,2,2,2,2,2,3,2
2,4,2,2,2,2,2,2,2,2,2,2,2,3,4,4,4,3,2,2,2,3,2,2,2,2,2,3,2,2,2,3,2,2,2,2,2,2,2,2,2,4,2
2,4,2,2,2,2,2,2,2,2,2,2,2,4,2,2,2,2,2,2,2,2,2,2,2,2,2,2,2,2,2,4,2,2,2,2,2,2,2,2,2,4,2
2,4,2,2,2,2,2,2,2,2,2,2,2,4,2,2,2,2,2,2,2,2,2,2,2,2,2,2,2,2,2,4,2,2,2,2,2,2,2,2,2,4,2
2,4,2,2,2,2,2,2,2,2,2,2,2,4,2,2,2,2,2,2,2,2,2,2,2,2,2,2,2,2,2,4,2,2,2,2,2,2,2,2,2,4,2
2,3,2,2,2,2,2,2,2,3,4,4,4,3,2,2,2,3,2,2,2,3,2,2,2,2,2,3,2,2,2,3,2,2,2,2,2,2,2,2,2,3,2
2,4,2,2,2,2,2,2,2,5,2,2,2,2,2,2,2,2,2,2,2,2,2,2,2,2,2,2,2,2,2,4,2,2,2,2,2,2,2,2,2,4,2
2,4,2,2,2,2,2,2,2,5,2,2,2,2,2,2,2,2,2,2,2,2,2,2,2,2,2,2,2,2,2,4,2,2,2,2,2,2,2,2,2,4,2
2,4,2,2,2,2,2,2,2,5,2,2,2,2,2,2,2,2,2,2,2,2,2,2,2,2,2,2,2,2,2,4,2,2,2,2,2,2,2,2,2,4,2
2,4,2,2,2,2,2,2,2,3,2,2,2,2,2,2,2,3,4,4,4,3,4,4,4,4,4,3,4,4,4,3,2,2,2,2,2,2,2,2,2,4,2
2,3,2,2,2,2,2,2,2,4,2,2,2,2,2,2,2,4,2,2,2,2,2,2,2,2,2,2,2,2,2,2,2,2,2,2,2,2,2,2,2,3,2
2,4,2,2,2,2,2,2,2,4,2,2,2,2,2,2,2,4,2,2,2,2,2,2,2,2,2,2,2,2,2,2,2,2,2,2,2,2,2,2,2,4,2
2,4,2,2,2,2,2,2,2,4,2,2,2,2,2,2,2,4,2,2,2,2,2,2,2,2,2,2,2,2,2,2,2,2,2,2,2,2,2,2,2,4,2
2,4,2,2,2,2,2,2,2,3,4,4,4,3,4,4,4,3,2,2,2,2,2,2,2,2,2,2,2,2,2,2,2,2,2,2,2,2,2,2,2,4,2
2,4,2,2,2,2,2,2,2,2,2,2,2,2,2,2,2,2,2,2,2,2,2,2,2,2,2,2,2,2,2,2,2,2,2,2,2,2,2,2,2,4,2
2,3,2,2,2,2,2,2,2,2,2,2,2,2,2,2,2,2,2,2,2,2,2,2,2,2,2,2,2,2,2,2,2,2,2,2,2,2,2,2,2,3,2
2,4,2,2,2,2,2,2,2,2,2,2,2,2,2,2,2,2,2,2,2,2,2,2,2,2,2,2,2,2,2,2,2,2,2,2,2,2,2,2,2,4,2
2,4,2,2,2,2,2,2,2,2,2,2,2,2,2,2,2,2,2,2,2,2,2,2,2,2,2,2,2,2,2,2,2,2,2,2,2,2,2,2,2,4,2
2,4,2,2,2,2,2,2,2,2,2,2,2,2,2,2,2,2,2,2,2,2,2,2,2,2,2,2,2,2,2,2,2,2,2,2,2,2,2,2,2,4,2
2,4,2,2,2,2,2,2,2,2,2,2,2,2,2,2,2,2,2,2,2,2,2,2,2,2,2,2,2,2,2,2,2,2,2,2,2,2,2,2,2,4,2
2,3,2,2,2,2,2,2,2,2,2,2,2,2,2,2,2,2,2,2,2,2,2,2,2,2,2,2,2,2,2,2,2,2,2,2,2,2,2,2,2,3,2
2,4,2,2,2,2,2,2,2,2,2,2,2,2,2,2,2,2,2,2,2,2,2,2,2,2,2,2,2,2,2,2,2,2,2,2,2,2,2,2,2,4,2
2,4,2,2,2,2,2,2,2,2,2,2,2,2,2,2,2,2,2,2,2,2,2,2,2,2,2,2,2,2,2,2,2,2,2,2,2,2,2,2,2,4,2
2,4,2,2,2,2,2,2,2,2,2,2,2,2,2,2,2,2,2,2,2,2,2,2,2,2,2,2,2,2,2,2,2,2,2,2,2,2,2,2,2,4,2
2,4,2,2,2,2,2,2,2,2,2,2,2,2,2,2,2,2,2,2,2,2,2,2,2,2,2,2,2,2,2,2,2,2,2,2,2,2,2,2,2,4,2
2,3,4,4,4,4,3,4,4,4,4,3,4,4,4,4,4,4,4,4,4,4,4,4,4,4,3,4,4,4,4,3,4,4,4,4,3,4,4,4,4,3,2
2,2,2,2,2,2,2,2,2,2,2,2,2,2,2,2,2,2,2,2,2,2,2,2,2,2,2,2,2,2,2,2,2,2,2,2,2,2,2,2,2,2,2
:endlayer
layer: 4
6,6,6,6,6,6,6,7,7,7,7,6,6,6,6,6,6,6,6,6,6,6,6,6,6,6,6,6,6,6,6,6,6,6,6,6,6,6,6,6,6,6,6
6,3,4,4,4,4,3,4,4,4,4,3,4,4,4,4,3,4,4,4,4,3,4,4,4,4,3,4,4,4,4,3,4,4,4,4,3,4,4,4,4,3,6
6,4,6,6,6,6,6,6,8,8,6,6,6,6,6,6,6,6,6,6,6,6,6,6,6,6,6,6,6,6,6,2,6,6,6,6,6,6,6,6,6,4,6
6,4,6,6,6,6,6,6,8,8,6,6,6,6,6,6,6,6,6,6,6,6,6,6,6,6,6,6,6,6,6,2,6,6,6,6,6,6,6,6,6,4,6
6,4,6,6,6,6,6,6,8,8,6,6,6,6,6,6,6,6,6,6,6,6,6,6,6,6,6,6,6,6,6,2,6,6,6,6,6,6,6,6,6,4,6
6,4,6,6,6,6,6,6,8,8,8,8,8,8,8,8,8,8,8,8,8,8,8,8,8,8,8,8,8,8,8,8,7,6,2,6,6,6,6,6,6,4,6
6,3,6,6,6,6,6,6,8,8,8,8,8,8,8,8,8,8,8,8,8,8,8,8,8,8,8,8,8,8,8,8,7,7,6,6,6,2,2,6,6,3,6
6,4,6,6,6,6,6,6,8,8,6,6,6,6,6,6,6,6,6,8,6,6,6,6,6,6,6,6,6,6,6,2,6,7,6,6,2,2,2,2,6,4,6
6,4,6,6,6,6,6,6,8,8,6,6,6,6,6,6,6,6,6,8,6,6,6,6,6,6,6,6,6,6,6,2,6,7,6,2,2,2,2,2,6,4,6
6,4,6,6,6,6,6,6,8,8,6,6,6,6,6,6,6,3,4,4,4,3,4,4,4,4,4,3,4,4,4,3,6,7,6,6,2,2,2,2,2,4,6
6,4,6,6,6,6,6,6,8,8,6,6,6,6,6,6,6,4,9,9,9,9,9,9,9,9,9,9,9,9,9,4,6,7,7,6,6,2,2,2,2,4,6
6,3,6,6,6,6,6,6,8,8,6,6,6,6,6,6,6,4,9,9,9,9,9,9,9,9,9,9,9,9,9,4,6,6,7,6,6,2,2,6,6,3,6
6,4,6,6,6,6,6,6,8,8,6,2,6,6,6,6,6,4,9,9,9,9,9,9,9,9,9,9,9,9,9,4,6,6,7,6,2,2,2,2,6,4,6
6,4,6,6,6,8,8,8,8,8,6,6,6,6,6,6,6,3,9,9,9,3,9,9,9,9,9,3,9,9,9,3,6,6,7,2,2,2,2,2,6,4,6
6,4,6,6,6,8,8,8,8,8,6,6,6,6,6,6,6,4,9,9,9,9,9,9,9,9,9,9,9,9,9,4,6,6,7,2,2,2,2,2,2,4,6
6,4,6,6,6,8,8,6,6,6,6,6,6,6,6,6,6,4,9,9,9,9,9,9,9,9,9,9,9,9,9,4,6,7,7,6,2,2,2,2,6,4,6
6,3,6,6,6,8,8,6,6,6,6,6,6,6,6,6,6,4,9,9,9,9,9,9,9,9,9,9,9,9,9,4,6,7,6,6,2,2,2,6,6,3,6
6,4,6,6,6,8,8,6,6,6,6,6,6,3,4,4,4,3,9,9,9,3,9,9,9,9,9,3,9,9,9,3,6,7,6,6,2,2,2,2,6,4,6
6,4,6,6,6,8,8,6,6,6,6,6,6,4,9,9,9,9,9,9,9,9,9,9,9,9,9,9,9,9,9,4,6,7,6,6,2,2,2,2,2,4,6
6,4,6,6,6,8,8,8,8,8,8,8,8,4,9,9,9,9,9,9,9,9,9,9,9,9,9,9,9,9,9,4,7,7,6,2,2,2,2,2,2,4,6
6,4,6,6,6,8,8,6,6,6,6,6,6,4,9,9,9,9,9,9,9,9,9,9,9,9,9,9,9,9,9,4,6,7,6,2,2,2,2,2,2,4,6
6,3,6,6,6,8,8,6,6,3,4,4,4,3,9,9,9,3,9,9,9,3,9,9,9,9,9,3,9,9,9,3,6,7,7,6,2,2,2,2,6,3,6
6,4,6,6,6,8,8,6,6,5,9,9,9,9,9,9,9,9,9,9,9,9,9,9,9,9,9,9,9,9,9,4,6,6,7,6,2,2,2,6,6,4,6
6,4,6,6,6,8,8,6,6,5,9,9,9,9,9,9,9,9,9,9,9,9,9,9,9,9,9,9,9,9,9,4,6,6,7,6,6,2,2,2,6,4,6
6,4,6,6,6,8,8,6,6,5,9,9,9,9,9,9,9,9,9,9,9,9,9,9,9,9,9,9,9,9,9,4,6,6,7,6,2,2,2,2,2,4,6
6,4,6,6,6,8,8,6,6,3,9,9,9,9,9,9,9,3,4,4,4,3,4,4,4,4,4,3,4,4,4,3,6,6,7,6,2,2,2,2,2,4,6
6,3,6,6,6,8,8,6,6,4,9,9,9,9,9,9,9,4,6,6,6,6,7,7,7,7,7,6,6,6,6,6,6,6,7,6,2,2,2,2,6,3,6
6,4,6,6,6,8,8,6,6,4,9,9,9,9,9,9,9,4,6,6,6,6,6,7,7,7,7,6,6,6,6,6,7,7,7,6,2,2,2,2,6,4,6
6,4,6,6,6,8,8,6,6,4,9,9,9,9,9,9,9,4,6,6,6,6,6,7,7,7,6,6,6,7,7,7,7,6,2,6,2,2,2,2,2,4,6
6,4,6,6,6,8,8,6,6,3,4,4,4,3,4,4,4,3,6,6,6,6,6,7,7,7,7,7,7,7,6,6,6,2,2,2,2,2,2,2,2,4,6
6,4,6,6,6,8,8,6,6,6,6,6,6,6,6,8,6,2,6,6,6,6,7,7,7,7,6,6,6,6,6,6,2,2,2,2,2,6,2,2,2,4,6
6,3,6,6,6,8,8,6,6,6,6,6,6,6,6,8,6,2,6,6,7,6,6,7,7,7,6,6,6,6,6,6,6,2,2,2,2,2,2,2,2,3,6
6,4,6,6,6,8,8,8,8,8,8,8,8,8,8,8,8,8,7,7,7,7,7,7,7,7,7,6,6,6,6,6,6,2,2,2,2,6,2,6,2,4,6
6,4,6,6,6,8,8,8,8,8,8,8,8,8,8,8,8,8,7,7,6,7,7,7,7,7,7,6,6,6,6,2,6,6,2,6,2,2,2,2,6,4,6
6,4,6,6,6,6,6,6,6,6,6,6,6,8,8,6,6,2,6,6,6,6,7,7,7,7,6,6,6,6,6,6,6,6,6,6,2,2,2,2,2,4,6
6,4,6,6,6,6,6,2,6,6,6,6,6,8,8,6,6,2,6,6,6,6,6,7,7,7,6,6,6,6,6,6,6,6,6,6,2,2,2,2,6,4,6
6,3,6,6,6,6,6,6,6,6,6,6,6,8,8,6,6,2,6,6,6,6,6,7,7,7,7,6,6,6,6,6,6,6,6,2,2,2,2,2,6,3,6
6,4,6,6,6,6,6,6,6,6,6,6,6,8,8,6,6,2,6,6,6,6,6,7,7,7,7,6,6,2,6,2,6,6,2,2,2,2,2,2,2,4,6
6,4,6,6,6,6,6,6,6,6,6,6,6,8,8,6,6,2,6,6,6,6,6,7,7,7,6,6,2,2,2,2,2,2,2,2,2,2,2,2,6,4,6
6,4,6,6,6,6,6,6,6,6,6,6,6,8,8,6,6,2,6,6,6,6,7,7,7,7,6,6,2,2,2,2,2,2,2,2,2,2,2,2,2,4,6
6,4,6,6,6,6,6,6,6,6,6,6,6,8,8,6,6,2,6,6,6,6,7,7,7,7,6,6,6,2,2,2,2,2,2,2,2,2,2,2,2,4,6
6,3,4,4,4,4,3,4,4,4,4,3,4,4,4,4,4,4,4,4,4,4,4,4,4,4,3,4,4,4,4,3,4,4,4,4,3,4,4,4,4,3,6
6,6,6,6,6,6,6,6,6,6,6,6,7,7,7,7,6,6,6,6,6,6,7,7,7,7,6,6,6,6,6,6,6,6,6,6,6,6,6,6,6,6,6
:endlayer
layer: 5
0,0,0,0,0,0,91,0,0,0,0,90,0,0,0,0,0,0,0,0,0,0,0,0,0,0,0,0,0,0,0,0,0,0,0,0,0,0,0,0,0,0,0
0,3,14,14,14,14,3,15,0,0,15,3,14,14,14,14,3,14,14,14,14,3,14,14,14,14,3,14,14,14,14,3,14,14,14,14,3,14,14,14,14,3,0
0,14,0,0,19,19,19,19,0,0,0,25,19,19,0,19,0,0,19,19,25,19,0,0,19,0,19,19,19,0,0,14,21,19,0,19,19,0,0,0,0,14,0
0,14,0,19,21,19,19,19,0,0,0,19,19,19,85,0,0,19,19,19,19,0,0,0,0,23,19,19,19,19,0,14,19,19,19,19,0,19,19,19,0,14,0
0,14,0,0,19,19,0,19,0,0,19,19,19,23,25,0,0,19,19,19,19,19,0,0,0,0,19,19,19,19,89,3,19,19,19,0,19,0,19,19,23,14,0
0,14,0,0,19,19,0,0,0,0,0,0,0,0,0,0,0,0,0,0,0,0,0,0,0,0,0,0,0,0,0,29,0,0,3,0,19,0,19,19,19,14,0
0,3,19,19,19,19,19,19,0,0,0,0,0,0,0,0,0,0,0,0,0,0,0,0,0,0,0,0,0,0,0,29,0,0,0,0,0,79,79,19,19,3,0
0,14,0,19,19,19,19,19,0,0,0,0,0,19,19,19,0,19,0,0,19,19,19,0,0,19,20,20,19,19,88,3,0,0,0,0,79,79,79,79,0,14,0
0,14,0,0,20,19,19,0,0,0,0,0,19,19,19,19,21,15,0,0,87,15,19,0,0,20,19,15,33,33,33,14,0,0,0,79,79,79,79,79,0,14,0
0,14,0,0,0,19,0,0,0,0,0,0,0,19,19,19,15,3,4,86,4,3,4,4,4,4,4,3,4,4,4,3,15,0,0,0,79,79,79,79,79,14,0
0,14,0,0,0,0,0,0,0,0,0,0,0,85,23,19,33,4,30,0,0,0,68,68,84,83,82,82,79,79,79,4,0,0,0,0,0,79,79,79,79,14,0
0,3,0,0,19,0,0,0,0,0,0,0,0,19,0,19,33,4,30,0,0,0,68,0,83,83,82,0,81,0,79,4,0,19,0,0,0,68,68,19,19,3,0
0,14,0,0,0,0,0,0,0,0,0,3,19,0,0,0,33,4,5,80,0,0,0,0,0,0,17,0,79,0,0,4,19,0,0,0,68,68,68,68,19,14,0
0,14,0,0,0,0,0,0,0,0,0,0,19,19,19,19,15,3,0,0,0,3,0,0,0,17,17,3,0,77,77,3,15,20,0,68,68,68,68,68,19,14,0
0,14,0,19,19,0,0,0,0,0,0,19,19,19,19,0,19,4,0,0,76,18,27,0,78,75,75,17,0,0,77,4,19,19,0,68,68,68,68,68,68,14,0
0,14,19,19,19,0,0,19,19,19,19,19,19,19,19,19,0,4,0,0,76,27,27,0,0,75,73,73,0,72,72,4,0,0,0,0,68,68,68,68,0,14,0
0,3,19,19,19,0,0,19,19,21,19,19,19,15,19,0,0,4,74,0,70,69,69,69,0,0,73,0,0,0,72,4,0,0,0,0,68,68,68,0,0,3,0
0,14,19,19,19,0,0,0,0,0,19,19,15,3,4,4,4,3,71,0,70,3,69,0,0,41,41,3,0,0,0,3,15,0,0,0,68,49,49,49,0,14,0
0,14,0,0,20,0,0,0,19,19,21,0,0,4,67,0,0,0,0,0,0,65,65,0,0,41,41,0,0,0,0,4,66,0,0,0,49,49,49,49,49,14,0
0,14,19,0,0,0,0,0,0,0,0,0,0,56,0,0,0,0,0,0,0,65,0,0,0,61,61,0,0,59,0,64,0,0,19,49,49,49,49,49,49,14,0
0,14,0,0,0,0,0,23,21,15,0,0,63,4,62,0,0,0,0,0,0,0,0,0,0,61,0,60,59,59,59,4,0,0,19,49,49,49,49,49,49,14,0
0,3,0,0,0,0,0,19,15,3,4,4,4,3,51,51,51,3,0,0,0,3,0,0,0,14,14,3,0,57,57,3,15,0,0,19,49,49,49,49,0,3,0
0,14,0,0,0,0,0,19,19,5,58,0,0,0,0,0,53,51,0,0,0,55,0,0,0,14,14,0,0,0,57,4,19,0,0,0,49,49,49,0,0,14,0
0,14,0,0,0,0,0,19,19,5,0,0,0,0,0,0,0,56,0,50,55,0,0,54,0,0,14,0,0,0,49,4,0,0,0,0,0,41,41,41,0,14,0
0,14,0,0,19,0,0,19,0,5,53,0,0,0,52,0,0,51,50,50,16,16,0,0,0,0,0,0,0,49,49,4,19,19,0,0,41,41,41,41,41,14,0
0,14,0,19,0,0,0,0,15,3,48,34,48,47,47,47,47,3,4,4,4,3,46,45,44,43,42,3,4,4,4,3,15,19,0,0,41,41,41,41,41,14,0
0,3,19,19,19,0,0,0,0,4,36,0,0,0,0,0,36,4,33,33,33,15,0,0,0,0,0,15,33,33,33,15,25,20,0,0,41,30,30,41,0,3,0
0,14,0,19,19,0,0,0,0,4,36,0,0,0,0,0,36,4,33,0,0,40,0,0,0,0,0,39,0,0,0,19,0,0,0,19,30,30,30,30,0,14,0
0,14,19,25,19,0,0,0,0,4,36,38,0,37,0,0,36,4,33,0,19,19,19,0,0,0,0,0,0,0,0,0,0,35,27,19,30,30,30,30,30,14,0
0,14,21,0,19,0,0,0,15,3,4,4,4,3,4,34,4,3,15,19,19,19,0,0,0,0,0,0,0,0,0,0,0,27,27,27,27,30,30,30,30,14,0
0,14,25,19,19,0,0,19,19,15,33,33,33,15,32,0,0,14,0,19,19,19,0,0,0,0,0,0,0,0,0,0,27,27,27,27,27,0,30,30,30,14,0
0,3,25,19,19,0,0,19,25,19,19,0,0,0,0,0,31,3,19,19,0,19,19,0,0,0,0,19,0,0,0,0,0,27,27,27,27,27,30,30,30,3,0
0,14,19,19,19,0,0,0,0,0,0,0,0,0,0,0,0,29,0,0,0,0,0,0,0,0,0,0,25,0,19,0,0,27,27,27,1,19,1,0,1,14,0
0,14,0,0,0,0,0,0,0,0,0,0,0,0,0,0,0,29,0,0,0,0,0,0,0,0,0,28,19,0,0,3,19,0,27,19,1,1,1,1,0,14,0
0,14,0,0,19,0,0,0,0,19,19,19,19,0,0,0,26,3,0,0,19,0,0,0,0,0,19,19,25,0,19,19,19,19,19,23,1,1,1,1,1,14,0
0,14,0,0,24,19,0,3,19,19,19,19,19,0,0,0,0,14,23,19,19,0,0,0,0,0,19,19,19,19,0,19,20,19,19,0,1,1,1,1,0,14,0
0,3,0,0,19,0,0,0,19,19,19,0,19,0,0,0,19,14,19,19,19,19,0,0,0,0,0,0,19,0,0,19,19,23,0,17,17,1,16,16,0,3,0
0,14,19,19,19,19,19,19,0,19,19,21,0,0,0,19,0,14,19,19,19,0,22,0,0,0,0,0,0,18,0,18,21,19,17,17,17,16,16,16,16,14,0
0,14,19,19,19,19,19,19,0,19,20,19,19,0,0,19,19,14,0,0,19,19,0,0,0,0,0,0,18,18,18,18,18,17,17,17,17,16,16,16,0,14,0
0,14,19,19,19,19,19,0,0,19,0,0,0,0,0,19,19,14,0,19,0,0,0,0,0,0,0,0,18,18,18,18,18,18,17,17,17,16,16,16,16,14,0
0,14,0,19,19,0,19,0,0,0,0,0,0,0,0,0,19,14,0,0,0,0,0,0,0,0,0,0,0,18,18,18,18,17,17,17,17,17,16,16,16,14,0
0,3,14,14,14,14,3,14,14,14,14,3,15,0,0,15,3,14,14,14,14,3,0,0,0,0,3,14,14,14,14,3,14,14,14,14,3,14,14,14,14,3,0
0,0,0,0,0,0,0,0,0,0,0,13,0,0,0,0,12,0,0,0,0,11,0,0,0,0,10,0,0,0,0,0,0,0,0,0,0,0,0,0,0,0,0
:endlayer
layer: 6
0,0,0,0,0,0,0,0,0,0,0,0,0,0,0,0,0,0,0,0,0,0,0,0,0,0,0,0,0,0,0,0,0,0,0,0,0,0,0,0,0,0,0
0,3,14,14,14,14,3,15,0,0,15,3,14,14,14,14,3,14,14,14,14,3,14,14,14,14,3,14,14,14,14,3,14,14,14,14,3,14,14,14,14,3,0
0,14,0,0,0,0,0,0,0,0,0,0,0,0,0,0,0,0,0,0,0,0,0,0,0,0,0,0,0,0,0,15,0,0,0,0,0,0,0,0,0,14,0
0,14,0,0,0,0,0,0,0,0,0,0,0,0,0,0,0,0,0,0,0,0,0,0,0,0,0,0,0,0,0,15,0,0,0,0,0,0,0,0,0,14,0
0,14,0,0,0,0,0,0,0,0,0,0,0,0,0,0,0,0,0,0,0,0,0,0,0,0,0,0,0,0,108,3,0,0,0,0,0,0,0,0,0,14,0
0,14,0,0,0,0,0,0,0,0,0,0,0,0,0,0,0,0,0,0,0,0,0,0,0,0,0,0,0,0,0,94,0,0,3,0,0,0,0,0,0,14,0
0,3,0,0,0,0,0,0,0,0,0,0,0,0,0,0,0,0,0,0,0,0,0,0,0,0,0,0,0,0,0,93,0,0,0,0,0,0,0,0,0,3,0
0,14,0,0,0,0,0,0,0,0,0,0,0,0,0,0,0,0,0,0,0,0,0,0,0,0,0,0,0,0,0,3,0,0,0,0,0,79,0,107,0,14,0
0,14,0,0,0,0,0,0,0,0,0,0,0,0,0,0,0,15,0,0,0,15,0,0,0,0,0,15,33,33,33,15,0,0,0,0,79,79,79,0,0,14,0
0,14,0,0,0,0,0,0,0,0,0,0,0,0,0,0,15,3,48,104,48,3,48,97,48,97,48,3,48,97,48,3,15,0,0,0,0,79,79,79,0,14,0
0,14,0,0,0,0,0,0,0,0,0,0,0,0,0,0,33,48,0,0,0,0,68,0,33,0,0,82,0,0,79,48,0,0,0,0,0,0,0,79,0,14,0
0,3,0,0,0,0,0,0,0,0,0,92,0,0,0,0,33,97,106,0,0,0,0,0,0,0,0,0,0,0,0,97,0,0,0,0,0,0,0,0,0,3,0
0,14,0,0,0,0,0,0,0,0,92,3,92,0,0,0,33,48,0,0,0,0,0,0,0,0,0,0,0,0,0,48,0,0,0,0,0,0,0,0,0,14,0
0,14,0,0,0,0,0,0,0,0,0,92,0,0,0,0,15,3,0,0,0,3,0,0,0,0,17,3,0,0,0,3,15,0,0,0,0,68,68,0,0,14,0
0,14,0,0,0,0,0,0,0,0,0,0,0,0,0,0,0,48,0,0,0,18,0,0,0,0,0,0,0,0,0,48,0,0,0,0,68,68,68,0,0,14,0
0,14,0,0,0,0,0,0,0,0,0,0,0,0,0,0,0,97,0,0,0,0,0,0,0,0,73,0,0,0,0,97,0,0,0,0,0,68,0,0,0,14,0
0,3,0,0,0,0,0,0,0,0,0,0,0,15,0,0,0,48,0,0,0,0,0,0,0,0,0,0,0,0,72,48,0,0,0,0,0,0,0,0,0,3,0
0,14,0,0,0,0,0,0,0,0,0,0,15,3,48,97,48,3,74,0,70,3,0,0,0,0,41,3,0,0,0,3,15,0,0,0,0,0,0,0,0,14,0
0,14,0,0,0,0,0,0,0,0,0,0,0,48,33,0,0,0,71,0,0,65,0,0,0,0,0,0,0,0,0,48,0,0,0,0,0,49,49,49,0,14,0
0,14,0,0,0,0,0,0,0,0,0,0,0,104,0,0,0,0,0,0,0,0,0,0,0,0,0,0,0,0,0,96,0,0,0,0,49,49,49,49,0,14,0
0,14,0,0,0,0,0,0,0,15,0,0,0,48,33,0,0,0,0,0,0,0,0,0,0,0,0,0,0,59,0,48,0,0,0,0,49,49,49,49,0,14,0
0,3,0,0,0,0,0,0,15,3,48,97,48,3,51,97,51,3,0,0,0,3,0,0,0,0,0,3,0,0,0,3,15,0,0,0,0,49,49,0,0,3,0
0,14,0,0,0,0,0,0,0,48,0,0,0,0,0,0,105,51,0,0,0,0,0,0,0,0,14,0,0,0,0,48,0,0,0,0,0,0,0,0,0,14,0
0,14,0,0,0,0,0,0,0,97,0,0,0,0,0,0,0,96,0,0,0,0,0,0,0,0,0,0,0,0,0,97,0,0,0,0,0,0,0,0,0,14,0
0,14,0,0,0,0,0,0,0,48,0,0,0,0,0,0,0,51,0,50,0,16,0,0,0,0,0,0,0,0,49,48,0,0,0,0,0,0,41,41,0,14,0
0,14,0,0,0,0,0,0,15,3,48,104,48,103,0,0,103,3,48,97,48,3,102,101,100,99,98,3,48,97,48,3,15,0,0,0,0,41,41,41,0,14,0
0,3,0,0,0,0,0,0,0,48,0,0,0,0,0,0,0,48,33,33,33,15,0,0,0,0,0,15,33,33,33,15,0,0,0,0,0,0,41,0,0,3,0
0,14,0,0,0,0,0,0,0,97,0,0,0,0,0,0,0,97,33,0,0,0,0,0,0,0,0,0,0,0,0,0,0,0,0,0,0,0,30,0,0,14,0
0,14,0,0,0,0,0,0,0,48,0,0,0,33,0,0,0,48,33,0,0,0,0,0,0,0,0,0,0,0,0,0,0,0,0,0,0,30,30,30,0,14,0
0,14,0,0,0,0,0,0,15,3,48,97,48,3,48,96,48,3,15,0,0,0,0,0,0,0,0,0,0,0,0,0,0,0,27,0,0,0,0,30,0,14,0
0,14,0,0,0,0,0,0,0,15,33,33,33,15,0,0,0,15,0,0,0,0,0,0,0,0,0,0,0,0,0,0,0,27,27,27,0,0,30,0,0,14,0
0,3,0,0,0,0,0,0,0,0,0,0,0,0,0,0,95,3,0,0,0,0,0,0,0,0,0,0,0,0,0,0,0,0,27,27,0,0,0,0,0,3,0
0,14,0,0,0,0,0,0,0,0,0,0,0,0,0,0,0,94,0,0,0,0,0,0,0,0,0,0,0,0,0,92,0,0,0,0,0,0,0,0,0,14,0
0,14,0,0,0,0,0,0,0,0,0,0,0,0,0,0,0,93,0,0,0,0,0,0,0,0,0,0,0,0,92,3,92,0,0,0,0,0,1,0,0,14,0
0,14,0,0,0,0,0,0,0,0,0,0,0,0,0,0,0,3,0,0,0,0,0,0,0,0,0,0,0,0,0,92,0,0,0,0,0,1,1,0,0,14,0
0,14,0,0,0,0,0,3,0,0,0,0,0,0,0,0,0,15,0,0,0,0,0,0,0,0,0,0,0,0,0,0,0,0,0,0,0,0,1,0,0,14,0
0,3,0,0,0,0,0,0,0,0,0,0,0,0,0,0,0,15,0,0,0,0,0,0,0,0,0,0,0,0,0,0,0,0,0,0,0,0,0,0,0,3,0
0,14,0,0,0,0,0,0,0,0,0,0,0,0,0,0,0,15,0,0,0,0,0,0,0,0,0,0,0,0,0,0,0,0,0,0,17,0,16,0,0,14,0
0,14,0,0,0,0,0,0,0,0,0,0,0,0,0,0,0,15,0,0,0,0,0,0,0,0,0,0,0,18,18,0,0,0,17,17,17,0,16,16,0,14,0
0,14,0,0,0,0,0,0,0,0,0,0,0,0,0,0,0,15,0,0,0,0,0,0,0,0,0,0,0,0,18,18,18,0,17,17,17,0,0,16,0,14,0
0,14,0,0,0,0,0,0,0,0,0,0,0,0,0,0,0,15,0,0,0,0,0,0,0,0,0,0,0,0,18,0,0,0,0,17,0,0,0,0,0,14,0
0,3,14,14,14,14,3,14,14,14,14,3,15,0,0,15,3,14,14,14,14,3,0,0,0,0,3,14,14,14,14,3,14,14,14,14,3,14,14,14,14,3,0
0,0,0,0,0,0,0,0,0,0,0,0,0,0,0,0,0,0,0,0,0,0,0,0,0,0,0,0,0,0,0,0,0,0,0,0,0,0,0,0,0,0,0
:endlayer
layer: 7
0,0,0,0,0,0,0,0,0,0,0,0,0,0,0,0,0,0,0,0,0,0,0,0,0,0,0,0,0,0,0,0,0,0,0,0,0,0,0,0,0,0,0
0,3,15,15,15,15,3,15,0,0,15,3,15,15,15,15,3,15,15,15,15,3,15,15,15,15,3,15,15,15,15,3,15,15,15,15,3,15,15,15,15,3,0
0,15,0,0,0,0,0,0,0,0,0,0,0,0,0,0,0,0,0,0,0,0,0,0,0,0,0,0,0,0,0,0,0,0,0,0,0,0,0,0,0,15,0
0,15,0,0,0,0,0,0,0,0,0,0,0,0,0,0,0,0,0,0,0,0,0,0,0,0,0,0,0,0,0,0,0,0,92,0,0,0,0,0,0,15,0
0,15,0,0,0,0,0,0,0,0,0,0,0,0,0,0,0,0,0,0,0,0,0,0,0,0,0,0,0,0,0,111,0,92,92,92,0,0,0,0,0,15,0
0,15,0,0,0,0,0,0,0,0,0,0,0,0,0,0,0,0,0,0,0,0,0,0,0,0,0,0,0,0,0,112,0,0,3,0,0,0,0,0,0,15,0
0,3,0,0,0,0,0,0,0,0,0,0,0,0,0,0,0,0,0,0,0,0,0,0,0,0,0,0,0,0,0,112,0,0,0,0,0,0,0,0,0,3,0
0,15,0,0,0,0,0,0,0,0,0,0,0,0,0,0,0,0,0,0,0,0,0,0,0,0,0,0,0,0,0,111,0,0,0,0,0,0,0,0,0,15,0
0,15,0,0,0,0,0,0,0,0,0,0,0,0,0,0,0,15,0,126,0,15,0,0,0,0,0,15,0,0,0,15,0,0,0,0,0,79,0,0,0,15,0
0,15,0,0,0,0,0,0,0,0,0,0,0,0,0,0,15,3,48,51,48,3,48,97,48,97,48,3,48,97,48,3,15,0,0,0,0,0,0,0,0,15,0
0,15,0,0,0,0,0,0,0,0,92,92,92,0,0,0,0,48,0,0,0,121,0,0,33,0,0,121,0,0,0,48,0,0,0,0,0,0,0,0,0,15,0
0,3,0,0,0,0,0,0,0,92,92,92,92,92,0,0,0,97,0,0,0,0,0,0,0,0,0,0,0,0,0,97,0,0,0,0,0,0,0,0,0,3,0
0,15,0,0,0,0,0,0,0,92,92,3,92,92,0,0,0,48,0,0,0,120,0,0,0,0,0,120,0,0,0,48,0,0,0,0,0,0,0,0,0,15,0
0,15,0,0,0,0,0,0,0,92,92,92,92,92,0,0,15,3,123,0,122,3,123,0,0,0,122,3,123,0,122,3,15,0,0,0,0,0,0,0,0,15,0
0,15,0,0,0,0,0,0,0,0,92,92,92,0,0,0,0,48,0,0,0,121,0,0,0,0,0,121,0,0,0,48,0,0,0,0,0,68,0,0,0,15,0
0,15,0,0,0,0,0,0,0,0,0,0,0,0,0,0,0,97,0,0,0,0,0,0,0,0,0,0,0,0,0,97,0,0,0,0,0,0,0,0,0,15,0
0,3,0,0,0,0,0,0,0,0,0,0,0,15,0,0,0,48,0,0,0,120,0,0,0,0,0,120,0,0,0,48,0,0,0,0,0,0,0,0,0,3,0
0,15,0,0,0,0,0,0,0,0,0,0,15,3,48,97,48,3,123,0,122,3,123,0,0,0,122,3,123,0,122,3,15,0,0,0,0,0,0,0,0,15,0
0,15,0,0,0,0,0,0,0,0,0,0,0,48,33,0,0,71,74,0,0,121,0,0,0,0,0,121,0,0,0,48,0,0,0,0,0,0,0,0,0,15,0
0,15,0,0,0,0,0,0,0,0,0,0,125,51,0,0,0,0,71,0,0,0,0,0,0,0,0,0,0,0,0,51,0,0,0,0,0,0,49,0,0,15,0
0,15,0,0,0,0,0,0,0,15,0,0,0,48,33,0,0,124,0,0,0,120,0,0,0,0,0,120,0,0,0,48,0,0,0,0,0,49,49,0,0,15,0
0,3,0,0,0,0,0,0,15,3,48,97,48,3,51,51,51,3,123,0,122,3,123,0,0,0,122,3,123,0,122,3,15,0,0,0,0,0,0,0,0,3,0
0,15,0,0,0,0,0,0,0,48,0,0,0,0,0,0,0,51,0,0,0,121,0,0,0,0,0,121,0,0,0,48,0,0,0,0,0,0,0,0,0,15,0
0,15,0,0,0,0,0,0,0,97,0,0,0,0,0,0,0,51,0,0,0,0,0,0,0,0,0,0,0,0,0,97,0,0,0,0,0,0,0,0,0,15,0
0,15,0,0,0,0,0,0,0,48,0,0,0,0,0,0,0,51,0,0,0,120,0,0,0,0,0,120,0,0,0,48,0,0,0,0,0,0,0,0,0,15,0
0,15,0,0,0,0,0,0,15,3,48,48,48,103,0,0,103,3,48,97,48,3,119,118,117,116,115,3,48,97,48,3,15,0,0,0,0,0,41,0,0,15,0
0,3,0,0,0,0,0,0,0,48,0,114,0,0,0,0,0,48,0,0,0,15,0,0,0,0,0,15,0,0,0,15,0,0,0,0,0,0,0,0,0,3,0
0,15,0,0,0,0,0,0,0,97,0,0,0,0,0,0,0,97,0,0,0,0,0,0,0,0,0,0,0,0,0,0,0,0,0,0,0,0,0,0,0,15,0
0,15,0,0,0,0,0,0,0,48,0,0,0,33,0,0,0,48,0,0,0,0,0,0,0,0,0,0,0,0,0,0,0,0,0,0,0,0,30,0,0,15,0
0,15,0,0,0,0,0,0,15,3,48,97,48,3,48,51,48,3,15,0,0,0,0,0,0,0,0,0,0,0,0,0,0,0,0,0,0,0,0,0,0,15,0
0,15,0,0,0,0,0,0,0,15,0,0,0,15,0,113,0,15,0,0,0,0,0,0,0,0,0,0,0,0,0,0,0,0,27,0,0,0,0,0,0,15,0
0,3,0,0,0,0,0,0,0,0,0,0,0,0,0,0,0,111,0,0,0,0,0,0,0,0,0,0,0,0,92,92,92,0,0,0,0,0,0,0,0,3,0
0,15,0,0,0,0,0,0,0,0,0,0,0,0,0,0,0,112,0,0,0,0,0,0,0,0,0,0,0,92,92,92,92,92,0,0,0,0,0,0,0,15,0
0,15,0,0,0,0,0,0,0,0,0,0,0,0,0,0,0,112,0,0,0,0,0,0,0,0,0,0,0,92,92,3,92,92,0,0,0,0,0,0,0,15,0
0,15,0,0,0,0,0,0,0,0,0,0,0,0,0,0,0,111,0,0,0,0,0,0,0,0,0,0,0,92,92,92,92,92,0,0,0,0,1,0,0,15,0
0,15,0,0,0,0,0,3,0,0,0,0,0,0,0,0,0,0,0,0,0,0,0,0,0,0,0,0,0,0,92,92,92,0,0,0,0,0,0,0,0,15,0
0,3,0,0,0,0,0,0,0,0,0,0,0,0,0,0,0,0,0,0,0,0,0,0,0,0,0,0,0,0,0,0,0,0,0,0,0,0,0,0,0,3,0
0,15,0,0,0,0,0,0,0,0,0,0,0,0,0,0,0,0,0,0,0,0,0,0,0,0,0,0,0,0,0,0,0,0,0,0,0,0,0,0,0,15,0
0,15,0,0,0,0,0,0,0,0,0,0,0,0,0,0,0,0,0,0,0,0,0,0,0,0,0,0,0,0,0,0,0,0,0,0,0,0,16,0,0,15,0
0,15,0,0,0,0,0,0,0,0,0,0,0,0,0,0,0,0,0,0,0,0,0,0,0,0,0,0,0,0,0,18,0,0,0,17,0,0,0,0,0,15,0
0,15,0,0,0,0,0,0,0,0,0,0,0,0,0,0,0,0,0,0,0,0,0,0,0,0,0,0,0,0,0,0,0,0,0,0,0,0,0,0,0,15,0
0,3,15,15,15,15,3,15,15,15,15,3,15,0,0,15,3,15,15,15,15,3,0,0,0,0,3,15,15,15,15,3,15,15,15,15,3,15,15,15,15,3,0
0,0,0,0,0,0,0,0,0,0,0,110,0,0,0,0,109,0,0,0,0,0,0,0,0,0,0,0,0,0,0,0,0,0,0,0,0,0,0,0,0,0,0
:endlayer
layer: 8
0,0,0,0,0,0,0,0,0,0,0,0,0,0,0,0,0,0,0,0,0,0,0,0,0,0,0,0,0,0,0,0,0,0,0,0,0,0,0,0,0,0,0
0,15,0,0,0,0,15,0,0,0,0,15,0,0,0,0,15,0,0,0,0,15,0,0,0,0,15,0,0,0,0,15,0,0,0,0,15,0,0,0,0,15,0
0,0,0,0,0,0,0,0,0,0,0,0,0,0,0,0,0,0,0,0,0,0,0,0,0,0,0,0,0,0,0,0,0,92,92,92,0,0,0,0,0,0,0
0,0,0,0,0,0,0,0,0,0,0,0,0,0,0,0,0,0,0,0,0,0,0,0,0,0,0,0,0,0,0,0,92,92,92,92,92,0,0,0,0,0,0
0,0,0,0,0,0,0,0,0,0,0,0,0,0,0,0,0,0,0,0,0,0,0,0,0,0,0,0,0,0,0,0,92,92,92,92,92,0,0,0,0,0,0
0,0,0,0,0,0,0,0,0,0,0,0,0,0,0,0,0,0,0,0,0,0,0,0,0,0,0,0,0,0,0,0,92,92,3,92,92,0,0,0,0,0,0
0,15,0,0,0,0,0,0,0,0,0,0,0,0,0,0,0,0,0,0,0,0,0,0,0,0,0,0,0,0,0,0,0,92,92,92,0,0,0,0,0,15,0
0,0,0,0,0,0,0,0,0,0,0,0,0,0,0,0,0,0,0,0,0,0,0,0,0,0,0,0,0,0,0,0,0,0,92,92,92,0,0,0,0,0,0
0,0,0,0,0,0,0,0,0,0,0,0,0,0,0,0,0,128,103,103,103,128,103,103,103,103,103,128,103,103,103,128,0,0,92,92,0,0,0,0,0,0,0
0,0,0,0,0,0,0,0,0,0,0,0,0,0,0,0,127,3,127,127,127,3,127,127,127,127,127,3,127,127,127,3,127,92,92,92,0,0,0,0,0,0,0
0,0,0,0,0,0,0,0,0,0,92,92,92,0,0,0,103,128,0,0,0,71,0,0,0,0,0,71,0,0,0,128,103,0,92,0,0,0,0,0,0,0,0
0,15,0,0,0,0,0,0,0,92,92,92,92,92,0,0,103,128,0,0,0,0,0,0,0,0,0,0,0,0,0,128,103,0,0,0,0,0,0,0,0,15,0
0,0,0,0,0,0,0,0,0,92,92,3,92,92,0,0,103,128,0,0,0,124,0,0,0,0,0,124,0,0,0,128,103,0,0,0,0,0,0,0,0,0,0
0,0,0,0,0,0,0,0,0,92,92,92,92,92,0,0,127,3,136,0,135,3,136,0,0,0,135,3,136,0,135,3,127,0,0,0,0,0,0,0,0,0,0
0,0,0,0,0,0,0,0,0,0,92,92,92,0,0,0,103,128,0,0,0,71,0,0,0,0,0,71,0,0,0,128,103,0,0,0,0,0,0,0,0,0,0
0,0,0,0,0,0,0,0,0,0,0,0,0,0,0,0,103,128,0,0,0,0,0,0,0,0,0,0,0,0,0,128,103,0,0,0,0,0,0,0,0,0,0
0,15,0,0,0,0,0,0,0,0,0,0,0,128,103,103,103,128,0,0,0,124,0,0,0,0,0,124,0,0,0,128,103,0,0,0,0,0,0,0,0,15,0
0,0,0,0,0,0,0,0,0,0,0,0,127,3,127,127,127,3,0,0,0,3,136,0,0,0,135,3,136,0,135,3,127,0,0,0,0,0,0,0,0,0,0
0,0,0,0,0,0,0,0,0,0,0,0,103,128,0,121,0,128,0,0,0,71,0,0,0,0,0,71,0,0,0,128,103,0,0,0,0,0,0,0,0,0,0
0,0,0,0,0,0,0,0,0,0,0,0,103,128,123,0,122,128,74,0,0,0,0,0,0,0,0,0,0,0,0,128,103,0,0,0,0,0,0,0,0,0,0
0,0,0,0,0,0,0,0,0,128,103,103,103,128,0,0,0,128,71,0,0,124,0,0,0,0,0,124,0,0,0,128,103,0,0,0,0,0,0,0,0,0,0
0,15,0,0,0,0,0,0,127,3,127,127,127,3,137,137,137,3,136,0,135,3,136,0,0,0,135,3,136,0,135,3,127,0,0,0,0,0,0,0,0,15,0
0,0,0,0,0,0,0,0,103,128,0,121,0,0,0,0,0,128,0,0,0,71,0,0,0,0,0,71,0,0,0,128,103,0,0,0,0,0,0,0,0,0,0
0,0,0,0,0,0,0,0,103,128,123,0,0,0,0,0,122,128,0,0,0,0,0,0,0,0,0,0,0,0,0,128,103,0,0,0,0,0,0,0,0,0,0
0,0,0,0,0,0,0,0,103,128,0,120,0,120,0,120,0,128,0,0,0,124,0,0,0,0,0,124,0,0,0,128,103,0,0,0,0,0,0,0,0,0,0
0,0,0,0,0,0,0,0,127,3,134,134,134,134,134,134,134,3,127,127,127,3,133,132,131,130,129,3,127,127,127,3,127,0,0,0,0,0,0,0,0,0,0
0,15,0,0,0,0,0,0,103,128,0,0,0,0,0,0,0,128,103,103,103,128,0,0,0,0,0,128,103,103,103,128,0,0,0,0,0,0,0,0,0,15,0
0,0,0,0,0,0,0,0,103,128,123,0,0,0,0,0,122,128,103,0,0,0,0,0,0,0,0,0,0,0,0,0,0,0,0,0,0,0,0,0,0,0,0
0,0,0,0,0,0,0,0,103,128,0,120,0,120,0,120,0,128,103,0,0,0,0,0,0,0,0,0,0,0,0,0,0,0,0,0,0,0,0,0,0,0,0
0,0,0,0,0,0,0,0,127,3,127,127,127,127,127,127,127,3,127,0,0,0,0,0,0,0,0,0,0,0,0,0,0,0,0,0,0,0,0,0,0,0,0
0,0,0,0,0,0,0,0,0,128,103,103,103,128,103,103,103,128,0,0,0,0,0,0,0,0,0,0,0,0,92,92,92,0,0,0,0,0,0,0,0,0,0
0,15,0,0,0,0,0,0,0,0,0,0,0,0,0,0,0,0,0,0,0,0,0,0,0,0,0,0,0,92,92,92,92,92,0,0,0,0,0,0,0,15,0
0,0,0,0,0,0,0,0,0,92,0,0,0,0,0,0,0,0,0,0,0,0,0,0,0,0,0,0,0,92,92,92,92,92,0,0,0,0,0,0,0,0,0
0,0,0,0,0,92,0,0,92,92,92,0,0,0,0,0,0,0,0,0,0,0,0,0,0,0,0,0,0,92,92,3,127,127,0,0,0,0,0,0,0,0,0
0,0,0,0,92,92,92,0,92,92,92,0,0,0,0,0,0,0,0,0,0,0,0,0,0,0,0,0,0,92,92,92,127,92,0,0,0,0,0,0,0,0,0
0,0,0,0,0,92,0,3,92,92,92,92,0,0,0,0,0,0,0,0,0,0,0,0,0,0,0,0,0,0,92,92,92,0,0,0,0,0,0,0,0,0,0
0,15,0,0,0,0,0,0,92,0,92,0,0,0,0,0,0,0,0,0,0,0,0,0,0,0,0,0,0,0,0,0,0,0,0,0,0,0,0,0,0,15,0
0,0,0,0,0,0,0,0,0,0,0,0,0,0,0,0,0,0,0,0,0,0,0,0,0,0,0,0,0,0,0,0,0,0,0,0,0,0,0,0,0,0,0
0,0,0,0,0,0,0,0,0,0,0,0,0,0,0,0,0,0,0,0,0,0,0,0,0,0,0,0,0,0,0,0,0,0,0,0,0,0,0,0,0,0,0
0,0,0,0,0,0,0,0,0,0,0,0,0,0,0,0,0,0,0,0,0,0,0,0,0,0,0,0,0,0,0,0,0,0,0,0,0,0,0,0,0,0,0
0,0,0,0,0,0,0,0,0,0,0,0,0,0,0,0,0,0,0,0,0,0,0,0,0,0,0,0,0,0,0,0,0,0,0,0,0,0,0,0,0,0,0
0,15,0,0,0,0,15,0,0,0,0,15,0,0,0,0,15,0,0,0,0,15,0,0,0,0,15,0,0,0,0,15,0,0,0,0,15,0,0,0,0,15,0
0,0,0,0,0,0,0,0,0,0,0,0,0,0,0,0,0,0,0,0,0,0,0,0,0,0,0,0,0,0,0,0,0,0,0,0,0,0,0,0,0,0,0
:endlayer
layer: 9
0,0,0,0,0,0,0,0,0,0,0,0,0,0,0,0,0,0,0,0,0,0,0,0,0,0,0,0,0,0,0,0,0,0,0,0,0,0,0,0,0,0,0
0,111,0,0,0,0,111,0,0,0,0,111,0,0,0,0,111,0,0,0,0,111,0,0,0,0,111,0,0,0,0,111,0,0,0,0,111,0,0,0,0,111,0
0,0,0,0,0,0,0,0,0,0,0,0,0,0,0,0,0,0,0,0,0,0,0,0,0,0,0,0,0,0,0,0,0,92,92,92,92,92,0,0,0,0,0
0,0,0,0,0,0,0,0,0,0,0,0,0,0,0,0,0,0,0,0,0,0,0,0,0,0,0,0,0,0,0,0,92,92,92,92,92,0,0,0,0,0,0
0,0,0,0,0,0,0,0,0,0,0,0,0,0,0,0,0,0,0,0,0,0,0,0,0,0,0,0,0,0,0,0,92,92,92,127,127,0,0,0,0,0,0
0,0,0,0,0,0,0,0,0,0,0,0,0,0,0,0,0,0,0,0,0,0,0,0,0,0,0,0,0,0,0,92,92,92,3,92,92,0,0,0,0,0,0
0,111,0,0,0,0,0,0,0,0,0,0,0,0,0,0,0,0,0,0,0,0,0,0,0,0,0,0,0,0,92,92,92,92,92,92,92,92,0,0,0,111,0
0,0,0,0,0,0,0,0,0,0,0,0,0,0,0,0,0,0,0,0,0,0,0,0,0,0,0,0,0,0,0,92,0,92,92,92,92,92,0,0,0,0,0
0,0,0,0,0,0,0,0,0,0,0,0,0,0,0,0,0,15,0,0,0,15,0,0,0,0,0,15,0,0,0,15,92,92,92,92,92,92,0,0,0,0,0
0,0,0,0,0,0,0,0,0,0,0,0,0,0,0,0,15,3,51,51,51,3,51,51,51,51,51,3,51,51,51,3,15,92,92,92,92,0,0,0,0,0,0
0,0,0,0,0,0,0,0,0,0,0,0,128,0,0,0,0,51,139,139,139,128,0,0,0,0,0,128,139,139,139,51,92,92,92,92,92,0,0,0,0,0,0
0,111,0,0,0,0,0,0,0,0,0,92,127,0,0,0,0,51,139,139,139,128,0,0,0,0,0,128,139,139,139,51,0,92,92,92,0,0,0,0,0,111,0
0,0,0,0,0,0,0,0,0,92,127,3,92,0,0,0,0,51,139,139,139,128,0,0,0,0,0,128,139,139,139,51,0,0,0,0,0,0,0,0,0,0,0
0,0,0,0,0,0,0,0,92,127,127,92,0,0,0,92,15,3,127,127,127,3,127,127,127,127,127,3,127,127,127,3,15,0,0,0,0,0,0,0,0,0,0
0,0,0,0,0,0,0,0,0,92,128,0,0,0,92,92,92,51,139,139,139,128,139,139,139,139,139,128,139,139,139,51,0,0,0,0,0,0,0,0,0,0,0
0,0,0,0,0,0,0,0,0,0,0,0,0,0,0,92,0,51,51,51,139,128,139,139,139,139,139,128,139,139,139,51,0,0,0,0,0,0,0,0,0,0,0
0,111,0,0,0,0,0,0,0,0,0,0,0,15,0,0,0,51,0,51,139,128,139,139,139,139,139,128,139,139,139,51,0,0,0,0,0,0,0,0,0,111,0
0,0,0,0,0,0,0,0,0,0,0,0,15,3,51,51,51,3,0,51,139,3,127,127,127,127,127,3,127,127,127,3,15,0,0,0,0,0,0,0,0,0,0
0,0,0,0,0,0,0,0,0,0,0,0,0,51,0,0,0,51,0,51,139,128,139,139,139,139,139,128,139,139,139,51,0,0,0,0,0,0,0,0,0,0,0
0,0,0,0,0,0,0,0,0,0,0,0,0,51,0,0,0,51,0,51,139,128,139,139,139,139,139,128,139,139,139,51,0,0,0,0,0,0,0,0,0,0,0
0,0,0,0,0,0,0,0,0,15,0,0,0,51,0,0,0,51,74,51,139,128,139,139,139,139,139,128,139,139,139,51,0,0,0,0,0,0,0,0,0,0,0
0,111,0,0,0,0,0,0,15,3,51,51,51,3,0,0,0,3,127,127,127,3,127,127,127,127,127,3,127,127,127,3,15,0,0,0,0,0,0,0,0,111,0
0,0,0,0,0,0,0,0,0,51,0,0,0,0,0,0,0,51,139,139,139,128,0,0,0,0,0,128,139,139,139,51,0,0,0,0,0,0,0,0,0,0,0
0,0,0,0,0,0,0,0,0,51,0,0,0,0,0,0,0,51,139,139,139,128,0,0,0,0,0,128,139,139,139,51,0,0,0,0,0,0,0,0,0,0,0
0,0,0,0,0,0,0,0,0,51,0,0,0,0,0,0,0,51,139,139,139,128,0,0,0,0,0,128,139,139,139,51,0,0,0,0,0,0,0,0,0,0,0
0,0,0,0,0,0,0,0,15,3,137,137,137,137,137,137,137,3,51,51,51,3,51,51,51,51,51,3,51,51,51,3,15,0,0,0,0,0,0,0,0,0,0
0,111,0,0,0,0,0,0,0,51,0,0,0,0,0,0,0,51,0,0,0,15,0,0,0,0,0,15,0,0,0,15,0,0,0,0,0,0,0,0,0,111,0
0,0,0,0,0,0,0,0,0,51,0,0,0,0,0,0,0,51,0,0,0,0,0,0,0,0,0,0,0,0,0,0,0,0,0,0,0,0,0,0,0,0,0
0,0,0,0,0,0,0,0,0,51,0,0,0,0,0,0,0,51,0,0,0,0,0,0,0,0,0,0,0,0,0,0,0,0,0,0,0,0,0,0,0,0,0
0,0,0,0,0,0,0,0,15,3,51,51,138,51,138,51,51,3,15,0,0,0,0,0,0,0,0,0,0,0,0,0,0,0,0,0,0,0,0,0,0,0,0
0,0,0,0,0,0,0,0,0,15,0,0,0,0,0,0,0,15,0,0,0,0,0,0,0,0,0,0,0,0,92,92,92,0,0,0,0,0,0,0,0,0,0
0,111,0,0,0,0,0,0,92,92,92,0,0,0,0,0,0,0,0,0,0,0,0,0,0,0,0,0,0,92,92,92,92,92,0,0,0,0,0,0,0,111,0
0,0,0,0,92,92,92,92,92,92,92,92,0,0,0,0,0,0,0,0,0,0,0,0,0,0,0,0,0,92,92,92,92,92,92,0,0,0,0,0,0,0,0
0,0,0,92,92,92,92,92,128,92,92,92,0,0,0,0,0,0,0,0,0,0,0,0,0,0,0,0,0,92,92,3,92,92,127,92,0,0,0,0,0,0,0
0,0,0,92,92,92,92,128,92,92,92,92,92,0,0,0,0,0,0,0,0,0,0,0,0,0,0,0,0,0,92,92,92,92,92,0,0,0,0,0,0,0,0
0,0,0,92,92,92,92,3,92,92,92,92,92,0,0,0,0,0,0,0,0,0,0,0,0,0,0,0,0,0,92,92,92,92,92,0,0,0,0,0,0,0,0
0,111,0,0,92,127,127,92,92,92,92,92,92,0,0,0,0,0,0,0,0,0,0,0,0,0,0,0,0,0,0,92,92,92,0,0,0,0,0,0,0,111,0
0,0,0,0,0,0,92,92,92,92,92,92,0,0,0,0,0,0,0,0,0,0,0,0,0,0,0,0,0,0,0,0,0,0,0,0,0,0,0,0,0,0,0
0,0,0,0,0,0,0,0,0,0,0,0,0,0,0,0,0,0,0,0,0,0,0,0,0,0,0,0,0,0,0,0,0,0,0,0,0,0,0,0,0,0,0
0,0,0,0,0,0,0,0,0,0,0,0,0,0,0,0,0,0,0,0,0,0,0,0,0,0,0,0,0,0,0,0,0,0,0,0,0,0,0,0,0,0,0
0,0,0,0,0,0,0,0,0,0,0,0,0,0,0,0,0,0,0,0,0,0,0,0,0,0,0,0,0,0,0,0,0,0,0,0,0,0,0,0,0,0,0
0,111,0,0,0,0,111,0,0,0,0,111,0,0,0,0,111,0,0,0,0,111,0,0,0,0,111,0,0,0,0,111,0,0,0,0,111,0,0,0,0,111,0
0,0,0,0,0,0,0,0,0,0,0,0,0,0,0,0,0,0,0,0,0,0,0,0,0,0,0,0,0,0,0,0,0,0,0,0,0,0,0,0,0,0,0
:endlayer
layer: 10
0,0,0,0,0,0,0,0,0,0,0,0,0,0,0,0,0,0,0,0,0,0,0,0,0,0,0,0,0,0,0,0,0,0,0,0,0,0,0,0,0,0,0
0,0,0,0,0,0,0,0,0,0,0,0,0,0,0,0,0,0,0,0,0,0,0,0,0,0,0,0,0,0,0,0,0,0,92,92,92,92,92,0,0,0,0
0,0,0,0,0,0,0,0,0,0,0,0,0,0,0,0,0,0,0,0,0,0,0,0,0,0,0,0,0,0,0,0,0,0,92,92,92,92,92,0,0,0,0
0,0,0,0,0,0,0,0,0,0,0,0,0,0,0,0,0,0,0,0,0,0,0,0,0,0,0,0,0,0,0,0,0,92,92,92,92,127,92,0,0,0,0
0,0,0,0,0,0,0,0,0,0,0,0,0,0,0,0,0,0,0,0,0,0,0,0,0,0,0,0,0,0,92,92,92,92,92,92,92,92,0,0,0,0,0
0,0,0,0,0,0,0,0,0,0,0,0,0,0,0,0,0,0,0,0,0,0,0,0,0,0,0,0,0,92,92,92,92,92,3,127,127,92,0,0,0,0,0
0,0,0,0,0,0,0,0,0,0,0,0,0,0,0,0,0,0,0,0,0,0,0,0,0,0,0,0,0,92,92,92,92,92,92,92,92,92,0,0,0,0,0
0,0,0,0,0,0,0,0,0,0,0,0,0,0,92,0,0,0,0,0,0,0,0,0,0,0,0,0,0,92,92,92,92,92,92,92,92,92,0,0,0,0,0
0,0,0,0,0,0,0,0,0,0,0,0,0,92,128,92,157,157,157,157,157,157,157,157,157,157,157,157,157,157,157,157,157,92,92,92,92,92,0,0,0,0,0
0,0,0,0,0,0,0,0,0,0,0,0,0,128,92,0,143,3,127,127,127,3,127,127,127,127,127,3,127,127,127,3,140,92,92,92,92,0,0,0,0,0,0
0,0,0,0,0,0,0,0,0,0,0,0,0,0,0,0,143,128,1,1,160,103,0,0,0,0,0,103,0,145,145,128,140,92,92,92,92,0,0,0,0,0,0
0,0,0,0,0,0,0,0,92,92,92,0,0,0,0,0,143,128,1,1,1,103,0,0,0,0,0,103,0,0,0,128,140,92,92,92,0,0,0,0,0,0,0
0,0,0,0,0,0,0,92,92,92,127,3,0,0,92,92,143,128,0,1,0,103,0,0,0,0,0,103,0,0,0,128,140,0,0,0,0,0,0,0,0,0,0
0,0,0,0,0,0,0,92,92,127,127,92,0,92,92,92,143,128,0,0,0,3,103,103,103,103,103,3,0,0,0,128,140,0,0,0,0,0,0,0,0,0,0
0,0,0,0,0,0,0,92,92,92,92,92,0,92,92,92,143,128,0,0,1,0,1,159,0,0,0,158,0,0,0,128,140,0,0,0,0,0,0,0,0,0,0
0,0,0,0,0,0,0,0,92,128,92,0,0,92,92,92,143,128,103,103,0,0,0,0,0,0,0,0,0,0,145,128,140,0,0,0,0,0,0,0,0,0,0
0,0,0,0,0,0,0,0,0,92,0,0,157,157,157,157,157,128,0,103,0,0,0,0,156,0,0,145,0,0,0,128,140,0,0,0,0,0,0,0,0,0,0
0,0,0,0,0,0,0,0,0,0,0,0,143,3,127,127,127,3,0,103,0,3,155,152,152,152,154,3,0,0,0,128,140,0,0,0,0,0,0,0,0,0,0
0,0,0,0,0,0,0,0,0,0,0,0,143,128,0,121,0,128,0,103,0,0,0,53,53,53,0,0,0,0,0,128,140,0,0,0,0,0,0,0,0,0,0
0,0,0,0,0,0,0,0,0,0,0,0,143,128,123,0,122,128,0,103,0,0,0,53,53,53,0,0,0,0,0,128,140,0,0,0,0,0,0,0,0,0,0
0,0,0,0,0,0,0,0,143,142,0,0,143,128,0,120,0,128,0,0,0,153,0,152,152,152,151,0,0,0,145,128,140,0,0,0,0,0,0,0,0,0,0
0,0,0,0,0,0,0,0,143,3,127,127,127,127,127,127,127,128,0,150,0,3,103,103,103,103,103,3,0,0,0,128,140,0,0,0,0,0,0,0,0,0,0
0,0,0,0,0,0,0,0,143,128,0,0,0,0,0,0,0,128,149,0,0,103,0,0,0,0,0,103,0,0,0,128,140,0,0,0,0,0,0,0,0,0,0
0,0,0,0,0,0,0,0,143,128,0,0,0,0,0,0,0,128,0,0,0,103,0,0,0,0,0,103,0,145,145,128,140,0,0,0,0,0,0,0,0,0,0
0,0,0,0,0,0,0,0,143,128,0,0,0,0,0,0,0,128,148,147,146,103,0,0,0,0,0,103,145,145,145,128,140,0,0,0,0,0,0,0,0,0,0
0,0,0,0,0,0,0,0,143,128,123,0,0,0,0,0,122,3,127,127,127,3,127,127,127,127,127,3,127,127,127,3,140,0,0,0,0,0,0,0,0,0,0
0,0,0,0,0,0,0,0,143,128,0,0,0,0,0,0,0,128,144,144,144,144,144,144,144,144,144,144,144,144,144,144,144,0,0,0,0,0,0,0,0,0,0
0,0,0,0,0,0,0,0,143,128,0,0,0,0,0,0,0,128,140,0,0,0,0,0,0,0,0,0,0,0,0,0,0,0,0,0,0,0,0,0,0,0,0
0,0,0,0,0,0,0,0,143,128,0,0,0,0,0,0,0,128,140,0,0,0,0,0,0,0,0,0,0,0,0,0,0,0,0,0,0,0,0,0,0,0,0
0,0,0,0,0,0,0,0,143,3,51,51,48,97,48,51,51,3,140,0,0,0,0,0,0,0,0,0,0,0,0,0,0,0,0,0,0,0,0,0,0,0,0
0,0,0,0,0,0,0,0,143,142,103,0,0,0,0,0,103,141,140,0,0,0,0,0,0,0,0,0,0,0,0,0,0,0,0,0,0,0,0,0,0,0,0
0,0,0,0,0,0,0,92,92,92,92,0,0,0,0,0,0,0,0,0,0,0,0,0,0,0,0,0,0,0,0,92,0,92,92,92,0,0,0,0,0,0,0
0,0,0,0,92,92,92,92,92,92,92,92,0,0,0,0,0,0,0,0,0,0,0,0,0,0,0,0,0,0,92,92,92,92,92,92,92,0,0,0,0,0,0
0,0,0,92,92,92,92,92,128,127,92,92,0,0,0,0,0,0,0,0,0,0,0,0,0,0,0,0,0,0,92,3,92,92,92,92,92,0,0,0,0,0,0
0,0,0,92,92,92,92,128,127,92,92,92,92,0,0,0,0,0,0,0,0,0,0,0,0,0,0,0,0,0,92,92,92,92,92,92,92,0,0,0,0,0,0
0,0,0,92,92,92,92,3,92,92,92,92,92,0,0,0,0,0,0,0,0,0,0,0,0,0,0,0,0,0,92,92,92,92,92,92,0,0,0,0,0,0,0
0,0,0,0,92,92,127,92,127,92,92,92,92,0,0,0,0,0,0,0,0,0,0,0,0,0,0,0,0,0,0,92,92,92,0,0,0,0,0,0,0,0,0
0,0,0,92,127,92,128,92,128,92,92,92,0,0,0,0,0,0,0,0,0,0,0,0,0,0,0,0,0,0,0,0,0,0,0,0,0,0,0,0,0,0,0
0,0,0,0,92,92,92,92,0,0,0,0,0,0,0,0,0,0,0,0,0,0,0,0,0,0,0,0,0,0,0,0,0,0,0,0,0,0,0,0,0,0,0
0,0,0,0,0,0,0,0,0,0,0,0,0,0,0,0,0,0,0,0,0,0,0,0,0,0,0,0,0,0,0,0,0,0,0,0,0,0,0,0,0,0,0
0,0,0,0,0,0,0,0,0,0,0,0,0,0,0,0,0,0,0,0,0,0,0,0,0,0,0,0,0,0,0,0,0,0,0,0,0,0,0,0,0,0,0
0,0,0,0,0,0,0,0,0,0,0,0,0,0,0,0,0,0,0,0,0,0,0,0,0,0,0,0,0,0,0,0,0,0,0,0,0,0,0,0,0,0,0
0,0,0,0,0,0,0,0,0,0,0,0,0,0,0,0,0,0,0,0,0,0,0,0,0,0,0,0,0,0,0,0,0,0,0,0,0,0,0,0,0,0,0
:endlayer
layer: 11
0,0,0,0,0,0,0,0,0,0,0,0,0,0,0,0,0,0,0,0,0,0,0,0,0,0,0,0,0,0,0,0,0,0,0,0,0,0,0,0,0,0,0
0,0,0,0,0,0,0,0,0,0,0,0,0,0,0,0,0,0,0,0,0,0,0,0,0,0,0,0,0,0,0,0,0,0,92,0,92,92,92,0,0,0,0
0,0,0,0,0,0,0,0,0,0,0,0,0,0,0,0,0,0,0,0,0,0,0,0,0,0,0,0,0,0,0,0,0,0,92,92,92,92,92,92,0,0,0
0,0,0,0,0,0,0,0,0,0,0,0,0,0,0,0,0,0,0,0,0,0,0,0,0,0,0,0,0,0,0,0,0,0,92,92,92,92,92,92,0,0,0
0,0,0,0,0,0,0,0,0,0,0,0,0,0,0,0,0,0,0,0,0,0,0,0,0,0,0,0,0,0,92,92,92,0,92,92,92,92,92,92,0,0,0
0,0,0,0,0,0,0,0,0,0,0,0,0,0,0,0,0,0,0,0,0,0,0,0,0,0,0,0,0,92,92,92,92,92,3,92,92,92,92,0,0,0,0
0,0,0,0,0,0,0,0,0,0,0,0,0,92,92,92,0,0,0,0,0,0,0,0,0,0,0,0,0,92,92,92,92,92,128,92,92,92,92,0,0,0,0
0,0,0,0,0,0,0,0,0,0,0,0,92,92,92,92,92,0,0,0,0,0,0,0,0,0,0,0,0,92,92,92,92,92,92,128,92,92,0,0,0,0,0
0,0,0,0,0,0,0,0,0,0,0,0,92,92,92,92,92,0,0,0,0,15,0,0,0,0,0,15,0,0,92,92,92,0,92,92,0,0,0,0,0,0,0
0,0,0,0,0,0,0,0,0,0,0,0,92,92,92,92,92,157,157,157,157,3,51,138,51,138,51,3,157,157,157,157,0,92,92,92,0,0,0,0,0,0,0
0,0,0,0,0,0,0,0,0,0,0,0,0,92,92,92,0,143,136,71,71,71,0,0,0,0,0,71,71,71,135,140,0,0,92,0,0,0,0,0,0,0,0
0,0,0,0,0,0,0,0,92,92,92,0,0,0,0,0,0,143,136,1,0,0,0,0,0,0,0,0,0,0,135,140,0,0,0,0,0,0,0,0,0,0,0
0,0,0,0,0,0,0,92,92,92,92,3,127,127,92,92,92,143,136,0,0,0,0,0,0,0,0,0,0,0,135,140,0,0,0,0,0,0,0,0,0,0,0
0,0,0,0,0,0,0,92,127,92,92,92,0,92,92,92,92,143,136,0,0,3,0,0,0,0,0,3,0,0,135,140,0,0,0,0,0,0,0,0,0,0,0
0,0,0,0,0,0,0,92,92,127,92,92,0,92,92,92,92,143,136,0,0,0,0,0,0,0,0,0,0,0,135,140,0,0,0,0,0,0,0,0,0,0,0
0,0,0,0,0,0,0,92,92,92,92,92,0,92,92,92,92,143,136,0,0,0,0,0,0,0,0,0,0,0,135,140,0,0,0,0,0,0,0,0,0,0,0
0,0,0,0,0,0,0,92,92,92,92,92,0,0,92,92,92,143,136,0,0,0,0,0,0,0,0,0,0,0,135,140,0,0,0,0,0,0,0,0,0,0,0
0,0,0,0,0,0,0,0,92,92,92,0,0,157,157,157,157,143,136,0,0,3,161,0,0,0,33,3,0,0,135,140,0,0,0,0,0,0,0,0,0,0,0
0,0,0,0,0,0,0,0,0,0,0,0,0,143,136,71,71,3,71,0,0,0,0,0,0,0,0,0,0,0,135,140,0,0,0,0,0,0,0,0,0,0,0
0,0,0,0,0,0,0,0,0,0,0,0,0,143,136,0,0,51,0,0,0,0,0,0,0,0,0,0,0,0,135,140,0,0,0,0,0,0,0,0,0,0,0
0,0,0,0,0,0,0,0,0,143,142,0,0,143,136,0,0,51,0,0,0,0,0,0,0,0,0,0,0,0,135,140,0,0,0,0,0,0,0,0,0,0,0
0,0,0,0,0,0,0,0,0,143,3,51,51,51,51,51,3,3,0,0,0,3,0,0,0,0,0,3,0,0,135,140,0,0,0,0,0,0,0,0,0,0,0
0,0,0,0,0,0,0,0,0,143,136,0,0,0,0,0,135,51,0,0,0,0,0,0,0,0,0,0,0,0,135,140,0,0,0,0,0,0,0,0,0,0,0
0,0,0,0,0,0,0,0,0,143,136,0,0,0,0,0,135,51,0,0,0,0,0,0,0,0,0,0,0,0,135,140,0,0,0,0,0,0,0,0,0,0,0
0,0,0,0,0,0,0,0,0,143,136,0,0,0,0,0,135,3,124,124,124,124,0,0,0,0,0,124,124,124,124,140,0,0,0,0,0,0,0,0,0,0,0
0,0,0,0,0,0,0,0,0,143,136,0,0,0,0,0,135,140,144,144,144,3,51,138,51,138,51,3,144,144,144,144,0,0,0,0,0,0,0,0,0,0,0
0,0,0,0,0,0,0,0,0,143,136,0,0,0,0,0,135,140,0,0,0,15,0,0,0,0,0,15,0,0,0,0,0,0,0,0,0,0,0,0,0,0,0
0,0,0,0,0,0,0,0,0,143,136,0,0,0,0,0,135,140,0,0,0,0,0,0,0,0,0,0,0,0,0,0,0,0,0,0,0,0,0,0,0,0,0
0,0,0,0,0,0,0,0,0,143,136,0,0,0,0,0,135,140,0,0,0,0,0,0,0,0,0,0,0,0,0,0,0,0,0,0,0,0,0,0,0,0,0
0,0,0,0,0,0,0,0,0,143,3,51,138,51,138,51,3,140,0,0,0,0,0,0,0,0,0,0,0,0,0,0,0,0,0,0,0,0,0,0,0,0,0
0,0,0,0,0,0,0,0,0,143,142,103,0,0,0,103,141,140,0,0,0,0,0,0,0,0,0,0,0,0,0,0,0,0,0,0,0,0,0,0,0,0,0
0,0,0,0,0,0,0,92,92,92,92,0,0,0,0,0,0,0,0,0,0,0,0,0,0,0,0,0,0,0,92,92,92,92,92,92,0,0,0,0,0,0,0
0,0,0,0,0,0,92,92,128,92,127,92,0,0,0,0,0,0,0,0,0,0,0,0,0,0,0,0,0,92,92,92,92,92,92,92,92,0,0,0,0,0,0
0,0,0,0,0,92,92,92,92,92,92,92,0,0,0,0,0,0,0,0,0,0,0,0,0,0,0,0,0,92,92,92,92,92,92,92,92,0,0,0,0,0,0
0,0,0,0,92,92,92,92,92,92,92,92,0,0,0,0,0,0,0,0,0,0,0,0,0,0,0,0,0,92,92,92,92,92,92,92,92,0,0,0,0,0,0
0,0,0,92,92,92,92,3,92,92,92,92,0,0,0,0,0,0,0,0,0,0,0,0,0,0,0,0,0,0,92,92,92,92,92,92,0,0,0,0,0,0,0
0,0,92,92,92,92,127,92,92,92,92,0,0,0,0,0,0,0,0,0,0,0,0,0,0,0,0,0,0,0,0,0,0,0,0,0,0,0,0,0,0,0,0
0,0,92,92,92,92,128,92,92,92,0,0,0,0,0,0,0,0,0,0,0,0,0,0,0,0,0,0,0,0,0,0,0,0,0,0,0,0,0,0,0,0,0
0,0,92,92,92,92,92,92,92,128,92,0,0,0,0,0,0,0,0,0,0,0,0,0,0,0,0,0,0,0,0,0,0,0,0,0,0,0,0,0,0,0,0
0,0,0,92,92,92,92,92,0,92,0,0,0,0,0,0,0,0,0,0,0,0,0,0,0,0,0,0,0,0,0,0,0,0,0,0,0,0,0,0,0,0,0
0,0,0,0,0,0,0,0,0,0,0,0,0,0,0,0,0,0,0,0,0,0,0,0,0,0,0,0,0,0,0,0,0,0,0,0,0,0,0,0,0,0,0
0,0,0,0,0,0,0,0,0,0,0,0,0,0,0,0,0,0,0,0,0,0,0,0,0,0,0,0,0,0,0,0,0,0,0,0,0,0,0,0,0,0,0
0,0,0,0,0,0,0,0,0,0,0,0,0,0,0,0,0,0,0,0,0,0,0,0,0,0,0,0,0,0,0,0,0,0,0,0,0,0,0,0,0,0,0
:endlayer
layer: 12
0,0,0,0,0,0,0,0,0,0,0,0,0,0,0,0,0,0,0,0,0,0,0,0,0,0,0,0,0,0,0,0,0,0,0,0,0,0,0,0,0,0,0
0,0,0,0,0,0,0,0,0,0,0,0,0,0,0,0,0,0,0,0,0,0,0,0,0,0,0,0,0,0,0,0,0,0,0,0,0,92,0,0,0,0,0
0,0,0,0,0,0,0,0,0,0,0,0,0,0,0,0,0,0,0,0,0,0,0,0,0,0,0,0,0,0,0,0,0,0,0,92,92,92,92,0,0,0,0
0,0,0,0,0,0,0,0,0,0,0,0,0,0,0,0,0,0,0,0,0,0,0,0,0,0,0,0,0,0,0,0,0,0,92,92,92,92,92,92,0,0,0
0,0,0,0,0,0,0,0,0,0,0,0,0,0,0,0,0,0,0,0,0,0,0,0,0,0,0,0,0,0,0,0,0,92,128,92,92,92,92,92,0,0,0
0,0,0,0,0,0,0,0,0,0,0,0,0,0,0,0,0,0,0,0,0,0,0,0,0,0,0,0,0,0,0,92,92,92,3,92,92,92,92,0,0,0,0
0,0,0,0,0,0,0,0,0,0,0,0,0,92,92,92,0,0,0,0,0,0,0,0,0,0,0,0,0,0,92,92,92,127,92,92,92,92,92,0,0,0,0
0,0,0,0,0,0,0,0,0,0,0,0,92,92,92,92,92,0,0,0,0,0,0,0,0,0,0,0,0,0,0,92,92,92,92,92,92,92,0,0,0,0,0
0,0,0,0,0,0,0,0,0,0,0,0,92,92,92,92,92,0,0,0,143,142,103,0,0,0,103,141,140,0,0,0,0,92,92,92,92,92,0,0,0,0,0
0,0,0,0,0,0,0,0,0,0,0,0,92,92,92,92,92,0,0,0,143,3,51,48,97,48,51,3,140,0,0,0,0,0,92,92,92,0,0,0,0,0,0
0,0,0,0,0,0,0,0,0,0,0,0,92,92,92,92,0,0,157,157,157,128,0,0,0,0,0,128,157,157,140,0,0,0,0,0,0,0,0,0,0,0,0
0,0,0,0,0,0,0,92,92,92,0,92,127,92,0,92,0,0,143,71,71,128,0,0,0,0,0,128,71,71,140,0,0,0,0,0,0,0,0,0,0,0,0
0,0,0,0,0,0,92,92,92,92,92,3,92,0,127,127,92,0,143,136,0,128,0,0,0,0,0,128,0,135,140,0,0,0,0,0,0,0,0,0,0,0,0
0,0,0,0,0,0,92,92,92,92,127,128,0,0,0,92,0,0,143,136,122,128,123,0,0,0,122,128,123,135,140,0,0,0,0,0,0,0,0,0,0,0,0
0,0,0,0,0,0,92,92,92,92,128,128,0,0,92,92,92,0,143,136,0,128,0,0,0,0,0,128,0,135,140,0,0,0,0,0,0,0,0,0,0,0,0
0,0,0,0,0,0,0,92,92,92,92,92,0,0,0,92,0,0,143,136,0,128,0,0,0,0,0,128,0,135,140,0,0,0,0,0,0,0,0,0,0,0,0
0,0,0,0,0,0,0,92,92,92,92,92,0,0,0,0,0,0,143,136,0,128,0,0,0,0,0,128,0,135,140,0,0,0,0,0,0,0,0,0,0,0,0
0,0,0,0,0,0,0,0,92,92,92,0,0,0,0,0,0,0,143,136,122,128,123,0,0,0,122,128,123,135,140,0,0,0,0,0,0,0,0,0,0,0,0
0,0,0,0,0,0,0,0,0,0,0,0,0,0,143,157,157,157,143,136,0,128,0,0,0,0,0,128,0,135,140,0,0,0,0,0,0,0,0,0,0,0,0
0,0,0,0,0,0,0,0,0,0,0,0,0,0,143,71,135,3,71,71,0,128,0,0,0,0,0,128,0,135,140,0,0,0,0,0,0,0,0,0,0,0,0
0,0,0,0,0,0,0,0,0,0,143,142,0,0,143,136,124,51,0,0,0,128,0,0,0,0,0,128,0,135,140,0,0,0,0,0,0,0,0,0,0,0,0
0,0,0,0,0,0,0,0,0,0,143,3,51,51,51,3,51,3,0,0,122,128,123,0,0,0,122,128,123,135,140,0,0,0,0,0,0,0,0,0,0,0,0
0,0,0,0,0,0,0,0,0,0,143,136,0,0,0,135,51,51,0,0,0,128,0,0,0,0,0,128,0,135,140,0,0,0,0,0,0,0,0,0,0,0,0
0,0,0,0,0,0,0,0,0,0,143,136,0,0,0,135,51,3,124,124,124,128,0,0,0,0,0,128,124,124,140,0,0,0,0,0,0,0,0,0,0,0,0
0,0,0,0,0,0,0,0,0,0,143,136,0,0,0,135,140,144,144,144,144,128,0,0,0,0,0,128,144,144,144,0,0,0,0,0,0,0,0,0,0,0,0
0,0,0,0,0,0,0,0,0,0,143,136,0,0,0,135,140,0,0,0,143,3,51,48,97,48,51,3,140,0,0,0,0,0,0,0,0,0,0,0,0,0,0
0,0,0,0,0,0,0,0,0,0,143,136,0,0,0,135,140,0,0,0,143,142,103,0,0,0,103,141,140,0,0,0,0,0,0,0,0,0,0,0,0,0,0
0,0,0,0,0,0,0,0,0,0,143,136,0,0,0,135,140,0,0,0,0,0,0,0,0,0,0,0,0,0,0,0,0,0,0,0,0,0,0,0,0,0,0
0,0,0,0,0,0,0,0,0,0,143,136,0,0,0,135,140,0,0,0,0,0,0,0,0,0,0,0,0,0,0,0,0,0,0,0,0,0,0,0,0,0,0
0,0,0,0,0,0,0,0,0,0,143,3,127,127,127,3,140,0,0,0,0,0,0,0,0,0,0,0,0,0,0,0,0,0,0,0,0,0,0,0,0,0,0
0,0,0,0,0,0,0,92,92,92,143,142,103,0,103,141,140,0,0,0,0,0,0,0,0,0,0,0,0,0,0,0,0,0,0,0,0,0,0,0,0,0,0
0,0,0,0,0,0,92,92,92,92,92,92,92,0,0,0,0,0,0,0,0,0,0,0,0,0,0,0,0,0,92,92,92,0,0,0,0,0,0,0,0,0,0
0,0,0,0,0,0,92,92,92,92,92,92,92,0,0,0,0,0,0,0,0,0,0,0,0,0,0,0,0,92,92,92,92,92,92,0,0,0,0,0,0,0,0
0,0,0,0,0,0,128,92,92,92,92,92,92,0,0,0,0,0,0,0,0,0,0,0,0,0,0,0,0,92,92,92,92,92,92,92,0,0,0,0,0,0,0
0,0,0,0,0,92,92,128,127,92,92,92,0,0,0,0,0,0,0,0,0,0,0,0,0,0,0,0,0,92,92,92,92,92,92,0,0,0,0,0,0,0,0
0,0,0,92,92,92,92,3,127,92,92,0,0,0,0,0,0,0,0,0,0,0,0,0,0,0,0,0,0,0,92,92,92,0,0,0,0,0,0,0,0,0,0
0,0,92,92,92,92,127,92,92,127,92,0,0,0,0,0,0,0,0,0,0,0,0,0,0,0,0,0,0,0,0,0,0,0,0,0,0,0,0,0,0,0,0
0,0,92,92,92,92,92,92,92,92,92,92,0,0,0,0,0,0,0,0,0,0,0,0,0,0,0,0,0,0,0,0,0,0,0,0,0,0,0,0,0,0,0
0,0,92,92,92,92,92,92,92,92,92,92,0,0,0,0,0,0,0,0,0,0,0,0,0,0,0,0,0,0,0,0,0,0,0,0,0,0,0,0,0,0,0
0,0,0,92,92,92,92,92,92,92,92,92,0,0,0,0,0,0,0,0,0,0,0,0,0,0,0,0,0,0,0,0,0,0,0,0,0,0,0,0,0,0,0
0,0,0,0,0,0,0,0,92,92,92,0,0,0,0,0,0,0,0,0,0,0,0,0,0,0,0,0,0,0,0,0,0,0,0,0,0,0,0,0,0,0,0
0,0,0,0,0,0,0,0,0,0,0,0,0,0,0,0,0,0,0,0,0,0,0,0,0,0,0,0,0,0,0,0,0,0,0,0,0,0,0,0,0,0,0
0,0,0,0,0,0,0,0,0,0,0,0,0,0,0,0,0,0,0,0,0,0,0,0,0,0,0,0,0,0,0,0,0,0,0,0,0,0,0,0,0,0,0
:endlayer
layer: 13
0,0,0,0,0,0,0,0,0,0,0,0,0,0,0,0,0,0,0,0,0,0,0,0,0,0,0,0,0,0,0,0,0,0,0,0,0,0,0,0,0,0,0
0,0,0,0,0,0,0,0,0,0,0,0,0,0,0,0,0,0,0,0,0,0,0,0,0,0,0,0,0,0,0,0,0,0,0,0,0,0,0,0,0,0,0
0,0,0,0,0,0,0,0,0,0,0,0,0,0,0,0,0,0,0,0,0,0,0,0,0,0,0,0,0,0,0,0,0,92,92,92,0,92,0,0,0,0,0
0,0,0,0,0,0,0,0,0,0,0,0,0,0,0,0,0,0,0,0,0,0,0,0,0,0,0,0,0,0,0,0,92,92,92,92,92,92,92,0,0,0,0
0,0,0,0,0,0,0,0,0,0,0,0,0,0,0,0,0,0,0,0,0,0,0,0,0,0,0,0,0,0,0,0,92,92,92,92,92,92,0,0,0,0,0
0,0,0,0,0,0,0,0,0,0,0,0,0,0,0,0,0,0,0,0,0,0,0,0,0,0,0,0,0,0,0,92,92,92,3,92,92,92,0,0,0,0,0
0,0,0,0,0,0,0,0,0,0,0,0,0,0,0,0,0,0,0,0,0,0,0,0,0,0,0,0,0,0,0,92,92,92,92,92,92,92,0,0,0,0,0
0,0,0,0,0,0,0,0,0,0,0,0,0,0,92,0,0,0,0,0,0,0,0,0,0,0,0,0,0,0,0,92,92,92,92,92,92,92,0,0,0,0,0
0,0,0,0,0,0,0,0,0,0,0,0,0,92,92,92,0,0,0,0,0,143,142,103,0,103,141,140,0,0,0,0,92,92,92,92,92,92,0,0,0,0,0
0,0,0,0,0,0,0,0,0,0,0,92,92,92,92,0,0,0,0,0,0,143,3,138,51,138,3,140,0,0,0,0,0,0,92,92,92,0,0,0,0,0,0
0,0,0,0,0,0,0,0,0,0,92,92,92,92,92,92,92,0,0,0,0,143,136,0,0,0,135,140,0,0,0,0,0,0,0,0,0,0,0,0,0,0,0
0,0,0,0,0,0,0,92,92,92,92,92,92,92,92,92,92,92,0,143,157,143,136,0,0,0,135,140,157,140,0,0,0,0,0,0,0,0,0,0,0,0,0
0,0,0,0,0,0,92,92,92,92,92,3,92,92,92,92,92,92,0,143,71,3,71,0,0,0,71,3,135,140,0,0,0,0,0,0,0,0,0,0,0,0,0
0,0,0,0,0,0,92,92,92,92,92,92,92,92,92,92,92,92,0,143,136,103,0,0,0,0,0,103,135,140,0,0,0,0,0,0,0,0,0,0,0,0,0
0,0,0,0,0,0,92,92,92,92,92,92,0,0,92,92,92,0,0,143,136,103,0,0,0,0,0,103,135,140,0,0,0,0,0,0,0,0,0,0,0,0,0
0,0,0,0,0,0,0,92,92,128,92,128,92,0,0,0,0,0,0,143,136,103,0,0,0,0,0,103,135,140,0,0,0,0,0,0,0,0,0,0,0,0,0
0,0,0,0,0,0,0,0,92,92,92,92,0,0,0,0,0,0,0,143,136,103,0,0,0,0,0,103,135,140,0,0,0,0,0,0,0,0,0,0,0,0,0
0,0,0,0,0,0,0,0,0,0,0,0,0,0,0,0,0,0,0,143,136,103,0,0,0,0,0,103,135,140,0,0,0,0,0,0,0,0,0,0,0,0,0
0,0,0,0,0,0,0,0,0,0,0,0,0,0,0,0,0,0,0,143,136,103,0,0,0,0,0,103,135,140,0,0,0,0,0,0,0,0,0,0,0,0,0
0,0,0,0,0,0,0,0,0,0,0,0,0,0,0,143,157,157,157,157,136,103,0,0,0,0,0,103,135,140,0,0,0,0,0,0,0,0,0,0,0,0,0
0,0,0,0,0,0,0,0,0,0,0,143,142,0,141,162,51,3,71,71,71,103,0,0,0,0,0,103,135,140,0,0,0,0,0,0,0,0,0,0,0,0,0
0,0,0,0,0,0,0,0,0,0,0,143,3,51,3,51,51,3,123,0,0,103,0,0,0,0,0,103,135,140,0,0,0,0,0,0,0,0,0,0,0,0,0
0,0,0,0,0,0,0,0,0,0,0,143,136,121,135,51,51,3,124,124,124,3,124,0,0,0,124,3,124,140,0,0,0,0,0,0,0,0,0,0,0,0,0
0,0,0,0,0,0,0,0,0,0,0,143,136,0,135,140,144,144,144,144,144,143,136,0,0,0,135,140,144,144,0,0,0,0,0,0,0,0,0,0,0,0,0
0,0,0,0,0,0,0,0,0,0,0,143,136,0,135,140,0,0,0,0,0,143,136,0,0,0,135,140,0,0,0,0,0,0,0,0,0,0,0,0,0,0,0
0,0,0,0,0,0,0,0,0,0,0,143,136,0,135,140,0,0,0,0,0,143,3,138,51,138,3,140,0,0,0,0,0,0,0,0,0,0,0,0,0,0,0
0,0,0,0,0,0,0,0,0,0,0,143,136,0,135,140,0,0,0,0,0,143,142,103,0,103,141,140,0,0,0,0,0,0,0,0,0,0,0,0,0,0,0
0,0,0,0,0,0,0,0,0,0,0,143,136,0,135,140,0,0,0,0,0,0,0,0,0,0,0,0,0,0,0,0,0,0,0,0,0,0,0,0,0,0,0
0,0,0,0,0,0,0,0,0,0,0,143,136,120,135,140,0,0,0,0,0,0,0,0,0,0,0,0,0,0,0,0,0,0,0,0,0,0,0,0,0,0,0
0,0,0,0,0,0,0,0,0,0,0,143,3,51,3,140,0,0,0,0,0,0,0,0,0,0,0,0,0,0,0,0,0,0,0,0,0,0,0,0,0,0,0
0,0,0,0,0,0,92,92,92,92,92,143,142,103,141,140,0,0,0,0,0,0,0,0,0,0,0,0,0,0,0,0,0,0,0,0,0,0,0,0,0,0,0
0,0,0,0,0,92,128,92,92,92,92,92,92,0,0,0,0,0,0,0,0,0,0,0,0,0,0,0,0,0,0,0,0,0,0,0,0,0,0,0,0,0,0
0,0,0,0,0,0,128,92,92,92,92,92,92,0,0,0,0,0,0,0,0,0,0,0,0,0,0,0,0,0,0,92,0,0,0,0,0,0,0,0,0,0,0
0,0,0,0,0,0,92,92,92,92,92,92,92,0,0,0,0,0,0,0,0,0,0,0,0,0,0,0,0,0,92,92,92,0,0,0,0,0,0,0,0,0,0
0,0,0,0,0,92,92,92,127,127,92,92,0,0,0,0,0,0,0,0,0,0,0,0,0,0,0,0,0,0,0,92,0,0,0,0,0,0,0,0,0,0,0
0,0,0,0,92,92,92,3,92,92,92,92,0,0,0,0,0,0,0,0,0,0,0,0,0,0,0,0,0,0,0,0,0,0,0,0,0,0,0,0,0,0,0
0,0,0,0,92,92,92,92,92,92,92,92,0,0,0,0,0,0,0,0,0,0,0,0,0,0,0,0,0,0,0,0,0,0,0,0,0,0,0,0,0,0,0
0,0,0,92,92,92,92,92,92,92,92,92,0,0,0,0,0,0,0,0,0,0,0,0,0,0,0,0,0,0,0,0,0,0,0,0,0,0,0,0,0,0,0
0,0,0,0,92,92,92,92,92,92,92,92,0,0,0,0,0,0,0,0,0,0,0,0,0,0,0,0,0,0,0,0,0,0,0,0,0,0,0,0,0,0,0
0,0,0,0,0,92,92,92,92,92,92,92,0,0,0,0,0,0,0,0,0,0,0,0,0,0,0,0,0,0,0,0,0,0,0,0,0,0,0,0,0,0,0
0,0,0,0,0,0,0,0,92,92,92,0,0,0,0,0,0,0,0,0,0,0,0,0,0,0,0,0,0,0,0,0,0,0,0,0,0,0,0,0,0,0,0
0,0,0,0,0,0,0,0,0,0,0,0,0,0,0,0,0,0,0,0,0,0,0,0,0,0,0,0,0,0,0,0,0,0,0,0,0,0,0,0,0,0,0
0,0,0,0,0,0,0,0,0,0,0,0,0,0,0,0,0,0,0,0,0,0,0,0,0,0,0,0,0,0,0,0,0,0,0,0,0,0,0,0,0,0,0
:endlayer
layer: 14
0,0,0,0,0,0,0,0,0,0,0,0,0,0,0,0,0,0,0,0,0,0,0,0,0,0,0,0,0,0,0,0,0,0,0,0,0,0,0,0,0,0,0
0,0,0,0,0,0,0,0,0,0,0,0,0,0,0,0,0,0,0,0,0,0,0,0,0,0,0,0,0,0,0,0,0,0,0,0,0,0,0,0,0,0,0
0,0,0,0,0,0,0,0,0,0,0,0,0,0,0,0,0,0,0,0,0,0,0,0,0,0,0,0,0,0,0,0,0,92,92,92,0,0,0,0,0,0,0
0,0,0,0,0,0,0,0,0,0,0,0,0,0,0,0,0,0,0,0,0,0,0,0,0,0,0,0,0,0,0,0,92,92,92,92,92,0,0,0,0,0,0
0,0,0,0,0,0,0,0,0,0,0,0,0,0,0,0,0,0,0,0,0,0,0,0,0,0,0,0,0,0,0,0,92,92,92,92,92,0,0,0,0,0,0
0,0,0,0,0,0,0,0,0,0,0,0,0,0,0,0,0,0,0,0,0,0,0,0,0,0,0,0,0,0,0,92,92,92,92,92,92,0,0,0,0,0,0
0,0,0,0,0,0,0,0,0,0,0,0,0,0,0,0,0,0,0,0,0,0,0,0,0,0,0,0,0,0,0,92,92,92,92,92,92,0,0,0,0,0,0
0,0,0,0,0,0,0,0,0,0,0,0,0,0,0,0,0,0,0,0,0,0,0,0,0,0,0,0,0,0,0,92,92,92,92,92,92,0,0,0,0,0,0
0,0,0,0,0,0,0,0,0,0,0,0,0,0,0,0,0,0,0,0,0,0,143,142,103,141,140,0,0,0,0,0,92,92,92,92,0,0,0,0,0,0,0
0,0,0,0,0,0,0,0,0,0,0,92,92,92,0,0,0,0,0,0,0,0,143,3,127,3,140,0,0,0,0,0,0,0,0,0,0,0,0,0,0,0,0
0,0,0,0,0,0,0,0,0,0,92,92,92,92,92,92,0,0,0,0,0,0,143,136,0,135,140,0,0,0,0,0,0,0,0,0,0,0,0,0,0,0,0
0,0,0,0,0,0,0,0,0,0,92,128,92,92,92,92,92,0,0,0,0,0,143,136,0,135,140,0,0,0,0,0,0,0,0,0,0,0,0,0,0,0,0
0,0,0,0,0,0,0,0,92,92,127,3,92,92,92,92,92,92,0,0,143,157,157,136,0,135,140,157,157,0,0,0,0,0,0,0,0,0,0,0,0,0,0
0,0,0,0,0,0,0,92,92,127,127,92,92,92,92,92,92,0,0,0,143,128,71,136,0,71,71,128,140,0,0,0,0,0,0,0,0,0,0,0,0,0,0
0,0,0,0,0,0,0,92,92,92,92,92,92,92,92,92,0,0,0,0,143,128,0,0,0,0,0,128,140,0,0,0,0,0,0,0,0,0,0,0,0,0,0
0,0,0,0,0,0,0,92,92,92,92,92,92,92,0,0,0,0,0,0,143,128,0,0,0,0,0,128,140,0,0,0,0,0,0,0,0,0,0,0,0,0,0
0,0,0,0,0,0,0,92,92,92,92,92,92,92,0,0,0,0,0,0,143,128,0,0,0,0,0,128,140,0,0,0,0,0,0,0,0,0,0,0,0,0,0
0,0,0,0,0,0,0,0,92,92,92,92,92,0,0,0,0,0,0,0,143,128,0,0,0,0,0,128,140,0,0,0,0,0,0,0,0,0,0,0,0,0,0
0,0,0,0,0,0,0,0,0,0,0,0,0,0,0,0,0,0,0,0,143,128,0,0,0,0,0,128,140,0,0,0,0,0,0,0,0,0,0,0,0,0,0
0,0,0,0,0,0,0,0,0,0,0,0,0,0,0,0,0,0,0,0,143,128,0,0,0,0,0,128,140,0,0,0,0,0,0,0,0,0,0,0,0,0,0
0,0,0,0,0,0,0,0,0,0,0,0,143,164,157,157,157,157,157,157,157,128,0,0,0,0,0,128,140,0,0,0,0,0,0,0,0,0,0,0,0,0,0
0,0,0,0,0,0,0,0,0,0,0,0,143,3,127,127,127,3,127,127,127,128,124,136,0,124,124,128,140,0,0,0,0,0,0,0,0,0,0,0,0,0,0
0,0,0,0,0,0,0,0,0,0,0,0,143,128,144,144,144,144,144,144,144,144,143,136,0,135,144,144,140,0,0,0,0,0,0,0,0,0,0,0,0,0,0
0,0,0,0,0,0,0,0,0,0,0,0,143,128,140,0,0,0,0,0,0,0,143,136,0,135,140,0,0,0,0,0,0,0,0,0,0,0,0,0,0,0,0
0,0,0,0,0,0,0,0,0,0,0,0,143,128,140,0,0,0,0,0,0,0,143,136,0,135,140,0,0,0,0,0,0,0,0,0,0,0,0,0,0,0,0
0,0,0,0,0,0,0,0,0,0,0,0,143,128,140,0,0,0,0,0,0,0,143,3,127,3,140,0,0,0,0,0,0,0,0,0,0,0,0,0,0,0,0
0,0,0,0,0,0,0,0,0,0,0,0,143,128,140,0,0,0,0,0,0,0,143,142,103,141,140,0,0,0,0,0,0,0,0,0,0,0,0,0,0,0,0
0,0,0,0,0,0,0,0,0,0,0,0,143,128,140,0,0,0,0,0,0,0,0,0,0,0,0,0,0,0,0,0,0,0,0,0,0,0,0,0,0,0,0
0,0,0,0,0,0,0,0,0,0,0,0,143,128,140,0,0,0,0,0,0,0,0,0,0,0,0,0,0,0,0,0,0,0,0,0,0,0,0,0,0,0,0
0,0,0,0,0,92,92,92,0,0,0,0,143,3,140,0,0,0,0,0,0,0,0,0,0,0,0,0,0,0,0,0,0,0,0,0,0,0,0,0,0,0,0
0,0,0,0,92,92,92,92,92,0,0,0,143,163,140,0,0,0,0,0,0,0,0,0,0,0,0,0,0,0,0,0,0,0,0,0,0,0,0,0,0,0,0
0,0,0,0,92,92,92,92,92,0,92,0,0,0,0,0,0,0,0,0,0,0,0,0,0,0,0,0,0,0,0,0,0,0,0,0,0,0,0,0,0,0,0
0,0,0,0,92,92,92,92,92,92,92,92,0,0,0,0,0,0,0,0,0,0,0,0,0,0,0,0,0,0,0,0,0,0,0,0,0,0,0,0,0,0,0
0,0,0,0,0,92,92,92,92,92,92,92,0,0,0,0,0,0,0,0,0,0,0,0,0,0,0,0,0,0,0,0,0,0,0,0,0,0,0,0,0,0,0
0,0,0,0,0,92,92,92,92,92,92,92,0,0,0,0,0,0,0,0,0,0,0,0,0,0,0,0,0,0,0,0,0,0,0,0,0,0,0,0,0,0,0
0,0,0,0,92,92,92,3,92,92,92,92,0,0,0,0,0,0,0,0,0,0,0,0,0,0,0,0,0,0,0,0,0,0,0,0,0,0,0,0,0,0,0
0,0,0,0,92,92,92,92,92,92,92,92,0,0,0,0,0,0,0,0,0,0,0,0,0,0,0,0,0,0,0,0,0,0,0,0,0,0,0,0,0,0,0
0,0,0,0,92,92,92,92,92,92,92,92,0,0,0,0,0,0,0,0,0,0,0,0,0,0,0,0,0,0,0,0,0,0,0,0,0,0,0,0,0,0,0
0,0,0,0,0,92,92,92,92,92,92,0,0,0,0,0,0,0,0,0,0,0,0,0,0,0,0,0,0,0,0,0,0,0,0,0,0,0,0,0,0,0,0
0,0,0,0,0,0,0,0,0,92,0,0,0,0,0,0,0,0,0,0,0,0,0,0,0,0,0,0,0,0,0,0,0,0,0,0,0,0,0,0,0,0,0
0,0,0,0,0,0,0,0,0,0,0,0,0,0,0,0,0,0,0,0,0,0,0,0,0,0,0,0,0,0,0,0,0,0,0,0,0,0,0,0,0,0,0
0,0,0,0,0,0,0,0,0,0,0,0,0,0,0,0,0,0,0,0,0,0,0,0,0,0,0,0,0,0,0,0,0,0,0,0,0,0,0,0,0,0,0
0,0,0,0,0,0,0,0,0,0,0,0,0,0,0,0,0,0,0,0,0,0,0,0,0,0,0,0,0,0,0,0,0,0,0,0,0,0,0,0,0,0,0
:endlayer
layer: 15
0,0,0,0,0,0,0,0,0,0,0,0,0,0,0,0,0,0,0,0,0,0,0,0,0,0,0,0,0,0,0,0,0,0,0,0,0,0,0,0,0,0,0
0,0,0,0,0,0,0,0,0,0,0,0,0,0,0,0,0,0,0,0,0,0,0,0,0,0,0,0,0,0,0,0,0,0,0,0,0,0,0,0,0,0,0
0,0,0,0,0,0,0,0,0,0,0,0,0,0,0,0,0,0,0,0,0,0,0,0,0,0,0,0,0,0,0,0,0,0,0,0,0,0,0,0,0,0,0
0,0,0,0,0,0,0,0,0,0,0,0,0,0,0,0,0,0,0,0,0,0,0,0,0,0,0,0,0,0,0,0,0,92,92,92,0,0,0,0,0,0,0
0,0,0,0,0,0,0,0,0,0,0,0,0,0,0,0,0,0,0,0,0,0,0,0,0,0,0,0,0,0,0,0,92,92,92,92,92,0,0,0,0,0,0
0,0,0,0,0,0,0,0,0,0,0,0,0,0,0,0,0,0,0,0,0,0,0,0,0,0,0,0,0,0,0,0,92,92,92,92,92,0,0,0,0,0,0
0,0,0,0,0,0,0,0,0,0,0,0,0,0,0,0,0,0,0,0,0,0,0,0,0,0,0,0,0,0,0,0,92,92,92,92,92,0,0,0,0,0,0
0,0,0,0,0,0,0,0,0,0,0,0,0,0,0,0,0,0,0,0,0,0,0,0,0,0,0,0,0,0,0,0,0,92,92,92,0,0,0,0,0,0,0
0,0,0,0,0,0,0,0,0,0,0,0,0,0,0,0,0,0,0,0,0,0,0,143,164,140,0,0,0,0,0,0,0,0,0,0,0,0,0,0,0,0,0
0,0,0,0,0,0,0,0,0,0,92,92,92,0,0,0,0,0,0,0,0,0,0,143,3,140,0,0,0,0,0,0,0,0,0,0,0,0,0,0,0,0,0
0,0,0,0,0,0,0,0,0,92,92,92,92,92,0,0,0,0,0,0,0,0,0,143,128,140,0,0,0,0,0,0,0,0,0,0,0,0,0,0,0,0,0
0,0,0,0,0,0,0,0,92,92,92,92,92,92,0,92,0,0,0,0,0,0,0,143,128,140,0,0,0,0,0,0,0,0,0,0,0,0,0,0,0,0,0
0,0,0,0,0,0,0,92,92,92,92,3,92,92,92,92,92,0,0,0,0,0,0,143,128,140,0,0,0,0,0,0,0,0,0,0,0,0,0,0,0,0,0
0,0,0,0,0,0,0,92,92,92,92,92,127,92,0,92,0,0,0,0,0,157,157,143,128,140,157,157,0,0,0,0,0,0,0,0,0,0,0,0,0,0,0
0,0,0,0,0,0,0,92,92,127,92,92,92,92,0,0,0,0,0,0,0,143,71,71,128,71,71,140,0,0,0,0,0,0,0,0,0,0,0,0,0,0,0
0,0,0,0,0,0,0,92,92,92,92,92,92,92,0,0,0,0,0,0,0,143,136,0,128,0,135,140,0,0,0,0,0,0,0,0,0,0,0,0,0,0,0
0,0,0,0,0,0,0,92,92,92,92,92,92,92,0,0,0,0,0,0,0,143,136,0,128,0,135,140,0,0,0,0,0,0,0,0,0,0,0,0,0,0,0
0,0,0,0,0,0,0,0,92,92,92,92,92,0,0,0,0,0,0,0,0,143,127,127,128,127,127,140,0,0,0,0,0,0,0,0,0,0,0,0,0,0,0
0,0,0,0,0,0,0,0,0,0,0,0,0,0,0,0,0,0,0,0,0,143,136,0,128,0,135,140,0,0,0,0,0,0,0,0,0,0,0,0,0,0,0
0,0,0,0,0,0,0,0,0,0,0,0,0,0,0,0,0,0,0,0,0,143,136,0,128,0,135,140,0,0,0,0,0,0,0,0,0,0,0,0,0,0,0
0,0,0,0,0,0,0,0,0,0,0,0,0,165,0,0,0,0,0,0,0,143,136,124,128,124,124,140,0,0,0,0,0,0,0,0,0,0,0,0,0,0,0
0,0,0,0,0,0,0,0,0,0,0,0,0,165,165,165,165,165,165,165,165,143,144,144,128,144,144,140,0,0,0,0,0,0,0,0,0,0,0,0,0,0,0
0,0,0,0,0,0,0,0,0,0,0,0,0,165,0,0,0,0,0,0,0,0,0,143,128,140,0,0,0,0,0,0,0,0,0,0,0,0,0,0,0,0,0
0,0,0,0,0,0,0,0,0,0,0,0,0,165,0,0,0,0,0,0,0,0,0,143,128,140,0,0,0,0,0,0,0,0,0,0,0,0,0,0,0,0,0
0,0,0,0,0,0,0,0,0,0,0,0,0,165,0,0,0,0,0,0,0,0,0,143,128,140,0,0,0,0,0,0,0,0,0,0,0,0,0,0,0,0,0
0,0,0,0,0,0,0,0,0,0,0,0,0,165,0,0,0,0,0,0,0,0,0,143,3,140,0,0,0,0,0,0,0,0,0,0,0,0,0,0,0,0,0
0,0,0,0,0,0,0,0,0,0,0,0,0,165,0,0,0,0,0,0,0,0,0,143,163,140,0,0,0,0,0,0,0,0,0,0,0,0,0,0,0,0,0
0,0,0,0,0,0,0,0,0,0,0,0,0,165,0,0,0,0,0,0,0,0,0,0,0,0,0,0,0,0,0,0,0,0,0,0,0,0,0,0,0,0,0
0,0,0,0,0,0,0,0,0,0,0,0,0,165,0,0,0,0,0,0,0,0,0,0,0,0,0,0,0,0,0,0,0,0,0,0,0,0,0,0,0,0,0
0,0,0,0,0,92,92,92,0,0,0,0,0,165,0,0,0,0,0,0,0,0,0,0,0,0,0,0,0,0,0,0,0,0,0,0,0,0,0,0,0,0,0
0,0,0,0,92,92,92,92,92,0,0,0,0,165,0,0,0,0,0,0,0,0,0,0,0,0,0,0,0,0,0,0,0,0,0,0,0,0,0,0,0,0,0
0,0,0,0,92,92,92,92,92,0,0,0,0,0,0,0,0,0,0,0,0,0,0,0,0,0,0,0,0,0,0,0,0,0,0,0,0,0,0,0,0,0,0
0,0,0,0,92,92,92,92,92,92,92,0,0,0,0,0,0,0,0,0,0,0,0,0,0,0,0,0,0,0,0,0,0,0,0,0,0,0,0,0,0,0,0
0,0,0,0,0,92,92,92,92,92,92,92,0,0,0,0,0,0,0,0,0,0,0,0,0,0,0,0,0,0,0,0,0,0,0,0,0,0,0,0,0,0,0
0,0,0,0,0,92,92,92,92,92,92,92,0,0,0,0,0,0,0,0,0,0,0,0,0,0,0,0,0,0,0,0,0,0,0,0,0,0,0,0,0,0,0
0,0,0,0,0,92,92,92,92,92,92,92,0,0,0,0,0,0,0,0,0,0,0,0,0,0,0,0,0,0,0,0,0,0,0,0,0,0,0,0,0,0,0
0,0,0,0,0,92,92,92,92,92,92,0,0,0,0,0,0,0,0,0,0,0,0,0,0,0,0,0,0,0,0,0,0,0,0,0,0,0,0,0,0,0,0
0,0,0,0,0,0,92,92,92,92,0,0,0,0,0,0,0,0,0,0,0,0,0,0,0,0,0,0,0,0,0,0,0,0,0,0,0,0,0,0,0,0,0
0,0,0,0,0,0,0,0,0,0,0,0,0,0,0,0,0,0,0,0,0,0,0,0,0,0,0,0,0,0,0,0,0,0,0,0,0,0,0,0,0,0,0
0,0,0,0,0,0,0,0,0,0,0,0,0,0,0,0,0,0,0,0,0,0,0,0,0,0,0,0,0,0,0,0,0,0,0,0,0,0,0,0,0,0,0
0,0,0,0,0,0,0,0,0,0,0,0,0,0,0,0,0,0,0,0,0,0,0,0,0,0,0,0,0,0,0,0,0,0,0,0,0,0,0,0,0,0,0
0,0,0,0,0,0,0,0,0,0,0,0,0,0,0,0,0,0,0,0,0,0,0,0,0,0,0,0,0,0,0,0,0,0,0,0,0,0,0,0,0,0,0
0,0,0,0,0,0,0,0,0,0,0,0,0,0,0,0,0,0,0,0,0,0,0,0,0,0,0,0,0,0,0,0,0,0,0,0,0,0,0,0,0,0,0
:endlayer
layer: 16
0,0,0,0,0,0,0,0,0,0,0,0,0,0,0,0,0,0,0,0,0,0,0,0,0,0,0,0,0,0,0,0,0,0,0,0,0,0,0,0,0,0,0
0,0,0,0,0,0,0,0,0,0,0,0,0,0,0,0,0,0,0,0,0,0,0,0,0,0,0,0,0,0,0,0,0,0,0,0,0,0,0,0,0,0,0
0,0,0,0,0,0,0,0,0,0,0,0,0,0,0,0,0,0,0,0,0,0,0,0,0,0,0,0,0,0,0,0,0,0,0,0,0,0,0,0,0,0,0
0,0,0,0,0,0,0,0,0,0,0,0,0,0,0,0,0,0,0,0,0,0,0,0,0,0,0,0,0,0,0,0,0,0,0,0,0,0,0,0,0,0,0
0,0,0,0,0,0,0,0,0,0,0,0,0,0,0,0,0,0,0,0,0,0,0,0,0,0,0,0,0,0,0,0,0,0,92,0,0,0,0,0,0,0,0
0,0,0,0,0,0,0,0,0,0,0,0,0,0,0,0,0,0,0,0,0,0,0,0,0,0,0,0,0,0,0,0,0,92,92,92,0,0,0,0,0,0,0
0,0,0,0,0,0,0,0,0,0,0,0,0,0,0,0,0,0,0,0,0,0,0,0,0,0,0,0,0,0,0,0,0,0,92,0,0,0,0,0,0,0,0
0,0,0,0,0,0,0,0,0,0,0,0,0,0,0,0,0,0,0,0,0,0,0,0,0,0,0,0,0,0,0,0,0,0,0,0,0,0,0,0,0,0,0
0,0,0,0,0,0,0,0,0,0,0,0,0,0,0,0,0,0,0,0,0,0,0,0,165,0,0,0,0,0,0,0,0,0,0,0,0,0,0,0,0,0,0
0,0,0,0,0,0,0,0,0,0,92,92,92,0,0,0,0,0,0,0,0,0,0,0,165,0,0,0,0,0,0,0,0,0,0,0,0,0,0,0,0,0,0
0,0,0,0,0,0,0,0,0,92,92,92,92,92,0,0,0,0,0,0,0,0,0,0,165,0,0,0,0,0,0,0,0,0,0,0,0,0,0,0,0,0,0
0,0,0,0,0,0,0,0,92,92,92,92,92,92,0,0,0,0,0,0,0,0,0,0,165,0,0,0,0,0,0,0,0,0,0,0,0,0,0,0,0,0,0
0,0,0,0,0,0,0,92,92,92,92,3,92,92,92,0,0,0,0,0,0,0,0,0,165,0,0,0,0,0,0,0,0,0,0,0,0,0,0,0,0,0,0
0,0,0,0,0,0,0,92,92,92,92,92,92,92,92,0,0,0,0,0,0,0,0,0,165,0,0,0,0,0,0,0,0,0,0,0,0,0,0,0,0,0,0
0,0,0,0,0,0,0,92,92,92,92,92,92,92,92,0,0,0,0,0,0,0,143,157,157,157,140,0,0,0,0,0,0,0,0,0,0,0,0,0,0,0,0
0,0,0,0,0,0,0,92,92,92,92,92,92,92,0,0,0,0,0,0,0,0,143,128,51,128,140,0,0,0,0,0,0,0,0,0,0,0,0,0,0,0,0
0,0,0,0,0,0,0,0,92,92,92,92,0,0,0,0,0,0,0,0,0,0,143,128,51,128,140,0,0,0,0,0,0,0,0,0,0,0,0,0,0,0,0
0,0,0,0,0,0,0,0,0,0,0,0,0,0,0,0,0,0,0,0,0,0,143,128,51,128,140,0,0,0,0,0,0,0,0,0,0,0,0,0,0,0,0
0,0,0,0,0,0,0,0,0,0,0,0,0,0,0,0,0,0,0,0,0,0,143,128,51,128,140,0,0,0,0,0,0,0,0,0,0,0,0,0,0,0,0
0,0,0,0,0,0,0,0,0,0,0,0,0,0,0,0,0,0,0,0,0,0,143,128,51,128,140,0,0,0,0,0,0,0,0,0,0,0,0,0,0,0,0
0,0,0,0,0,0,0,0,0,0,0,0,0,0,0,0,0,0,0,0,0,0,144,144,144,144,144,0,0,0,0,0,0,0,0,0,0,0,0,0,0,0,0
0,0,0,0,0,0,0,0,0,0,0,0,0,0,0,0,0,0,0,0,0,0,0,0,165,0,0,0,0,0,0,0,0,0,0,0,0,0,0,0,0,0,0
0,0,0,0,0,0,0,0,0,0,0,0,0,0,0,0,0,0,0,0,0,0,0,0,165,0,0,0,0,0,0,0,0,0,0,0,0,0,0,0,0,0,0
0,0,0,0,0,0,0,0,0,0,0,0,0,0,0,0,0,0,0,0,0,0,0,0,165,0,0,0,0,0,0,0,0,0,0,0,0,0,0,0,0,0,0
0,0,0,0,0,0,0,0,0,0,0,0,0,0,0,0,0,0,0,0,0,0,0,0,165,0,0,0,0,0,0,0,0,0,0,0,0,0,0,0,0,0,0
0,0,0,0,0,0,0,0,0,0,0,0,0,0,0,0,0,0,0,0,0,0,0,0,165,0,0,0,0,0,0,0,0,0,0,0,0,0,0,0,0,0,0
0,0,0,0,0,0,0,0,0,0,0,0,0,0,0,0,0,0,0,0,0,0,0,0,165,0,0,0,0,0,0,0,0,0,0,0,0,0,0,0,0,0,0
0,0,0,0,0,0,0,0,0,0,0,0,0,0,0,0,0,0,0,0,0,0,0,0,0,0,0,0,0,0,0,0,0,0,0,0,0,0,0,0,0,0,0
0,0,0,0,0,0,0,0,0,0,0,0,0,0,0,0,0,0,0,0,0,0,0,0,0,0,0,0,0,0,0,0,0,0,0,0,0,0,0,0,0,0,0
0,0,0,0,0,0,0,0,0,0,0,0,0,0,0,0,0,0,0,0,0,0,0,0,0,0,0,0,0,0,0,0,0,0,0,0,0,0,0,0,0,0,0
0,0,0,0,0,0,92,0,0,0,0,0,0,0,0,0,0,0,0,0,0,0,0,0,0,0,0,0,0,0,0,0,0,0,0,0,0,0,0,0,0,0,0
0,0,0,0,0,92,92,92,0,0,0,0,0,0,0,0,0,0,0,0,0,0,0,0,0,0,0,0,0,0,0,0,0,0,0,0,0,0,0,0,0,0,0
0,0,0,0,0,0,92,0,0,0,0,0,0,0,0,0,0,0,0,0,0,0,0,0,0,0,0,0,0,0,0,0,0,0,0,0,0,0,0,0,0,0,0
0,0,0,0,0,0,92,92,92,92,0,0,0,0,0,0,0,0,0,0,0,0,0,0,0,0,0,0,0,0,0,0,0,0,0,0,0,0,0,0,0,0,0
0,0,0,0,0,92,92,92,92,92,92,0,0,0,0,0,0,0,0,0,0,0,0,0,0,0,0,0,0,0,0,0,0,0,0,0,0,0,0,0,0,0,0
0,0,0,0,0,92,92,92,92,92,0,0,0,0,0,0,0,0,0,0,0,0,0,0,0,0,0,0,0,0,0,0,0,0,0,0,0,0,0,0,0,0,0
0,0,0,0,0,92,92,92,92,92,0,0,0,0,0,0,0,0,0,0,0,0,0,0,0,0,0,0,0,0,0,0,0,0,0,0,0,0,0,0,0,0,0
0,0,0,0,0,0,92,92,92,0,0,0,0,0,0,0,0,0,0,0,0,0,0,0,0,0,0,0,0,0,0,0,0,0,0,0,0,0,0,0,0,0,0
0,0,0,0,0,0,0,0,0,0,0,0,0,0,0,0,0,0,0,0,0,0,0,0,0,0,0,0,0,0,0,0,0,0,0,0,0,0,0,0,0,0,0
0,0,0,0,0,0,0,0,0,0,0,0,0,0,0,0,0,0,0,0,0,0,0,0,0,0,0,0,0,0,0,0,0,0,0,0,0,0,0,0,0,0,0
0,0,0,0,0,0,0,0,0,0,0,0,0,0,0,0,0,0,0,0,0,0,0,0,0,0,0,0,0,0,0,0,0,0,0,0,0,0,0,0,0,0,0
0,0,0,0,0,0,0,0,0,0,0,0,0,0,0,0,0,0,0,0,0,0,0,0,0,0,0,0,0,0,0,0,0,0,0,0,0,0,0,0,0,0,0
0,0,0,0,0,0,0,0,0,0,0,0,0,0,0,0,0,0,0,0,0,0,0,0,0,0,0,0,0,0,0,0,0,0,0,0,0,0,0,0,0,0,0
:endlayer
layer: 17
0,0,0,0,0,0,0,0,0,0,0,0,0,0,0,0,0,0,0,0,0,0,0,0,0,0,0,0,0,0,0,0,0,0,0,0,0,0,0,0,0,0,0
0,0,0,0,0,0,0,0,0,0,0,0,0,0,0,0,0,0,0,0,0,0,0,0,0,0,0,0,0,0,0,0,0,0,0,0,0,0,0,0,0,0,0
0,0,0,0,0,0,0,0,0,0,0,0,0,0,0,0,0,0,0,0,0,0,0,0,0,0,0,0,0,0,0,0,0,0,0,0,0,0,0,0,0,0,0
0,0,0,0,0,0,0,0,0,0,0,0,0,0,0,0,0,0,0,0,0,0,0,0,0,0,0,0,0,0,0,0,0,0,0,0,0,0,0,0,0,0,0
0,0,0,0,0,0,0,0,0,0,0,0,0,0,0,0,0,0,0,0,0,0,0,0,0,0,0,0,0,0,0,0,0,0,0,0,0,0,0,0,0,0,0
0,0,0,0,0,0,0,0,0,0,0,0,0,0,0,0,0,0,0,0,0,0,0,0,0,0,0,0,0,0,0,0,0,0,0,0,0,0,0,0,0,0,0
0,0,0,0,0,0,0,0,0,0,0,0,0,0,0,0,0,0,0,0,0,0,0,0,0,0,0,0,0,0,0,0,0,0,0,0,0,0,0,0,0,0,0
0,0,0,0,0,0,0,0,0,0,0,0,0,0,0,0,0,0,0,0,0,0,0,0,0,0,0,0,0,0,0,0,0,0,0,0,0,0,0,0,0,0,0
0,0,0,0,0,0,0,0,0,0,0,0,0,0,0,0,0,0,0,0,0,0,0,0,0,0,0,0,0,0,0,0,0,0,0,0,0,0,0,0,0,0,0
0,0,0,0,0,0,0,0,0,0,0,0,0,0,0,0,0,0,0,0,0,0,0,0,0,0,0,0,0,0,0,0,0,0,0,0,0,0,0,0,0,0,0
0,0,0,0,0,0,0,0,0,0,92,92,92,0,0,0,0,0,0,0,0,0,0,0,0,0,0,0,0,0,0,0,0,0,0,0,0,0,0,0,0,0,0
0,0,0,0,0,0,0,0,0,92,92,92,92,92,0,0,0,0,0,0,0,0,0,0,0,0,0,0,0,0,0,0,0,0,0,0,0,0,0,0,0,0,0
0,0,0,0,0,0,0,0,92,92,92,92,92,92,92,0,0,0,0,0,0,0,0,0,0,0,0,0,0,0,0,0,0,0,0,0,0,0,0,0,0,0,0
0,0,0,0,0,0,0,92,92,92,92,92,92,92,92,0,0,0,0,0,0,0,0,0,0,0,0,0,0,0,0,0,0,0,0,0,0,0,0,0,0,0,0
0,0,0,0,0,0,0,92,92,92,92,92,92,92,92,0,0,0,0,0,0,0,0,0,0,0,0,0,0,0,0,0,0,0,0,0,0,0,0,0,0,0,0
0,0,0,0,0,0,0,92,92,92,92,92,92,92,0,0,0,0,0,0,0,0,0,143,157,157,0,0,0,0,0,0,0,0,0,0,0,0,0,0,0,0,0
0,0,0,0,0,0,0,0,92,92,92,0,0,0,0,0,0,0,0,0,0,0,0,143,51,140,0,0,0,0,0,0,0,0,0,0,0,0,0,0,0,0,0
0,0,0,0,0,0,0,0,0,0,0,0,0,0,0,0,0,0,0,0,0,0,0,143,51,140,0,0,0,0,0,0,0,0,0,0,0,0,0,0,0,0,0
0,0,0,0,0,0,0,0,0,0,0,0,0,0,0,0,0,0,0,0,0,0,0,143,51,140,0,0,0,0,0,0,0,0,0,0,0,0,0,0,0,0,0
0,0,0,0,0,0,0,0,0,0,0,0,0,0,0,0,0,0,0,0,0,0,0,144,144,140,0,0,0,0,0,0,0,0,0,0,0,0,0,0,0,0,0
0,0,0,0,0,0,0,0,0,0,0,0,0,0,0,0,0,0,0,0,0,0,0,0,0,0,0,0,0,0,0,0,0,0,0,0,0,0,0,0,0,0,0
0,0,0,0,0,0,0,0,0,0,0,0,0,0,0,0,0,0,0,0,0,0,0,0,0,0,0,0,0,0,0,0,0,0,0,0,0,0,0,0,0,0,0
0,0,0,0,0,0,0,0,0,0,0,0,0,0,0,0,0,0,0,0,0,0,0,0,0,0,0,0,0,0,0,0,0,0,0,0,0,0,0,0,0,0,0
0,0,0,0,0,0,0,0,0,0,0,0,0,0,0,0,0,0,0,0,0,0,0,0,0,0,0,0,0,0,0,0,0,0,0,0,0,0,0,0,0,0,0
0,0,0,0,0,0,0,0,0,0,0,0,0,0,0,0,0,0,0,0,0,0,0,0,0,0,0,0,0,0,0,0,0,0,0,0,0,0,0,0,0,0,0
0,0,0,0,0,0,0,0,0,0,0,0,0,0,0,0,0,0,0,0,0,0,0,0,0,0,0,0,0,0,0,0,0,0,0,0,0,0,0,0,0,0,0
0,0,0,0,0,0,0,0,0,0,0,0,0,0,0,0,0,0,0,0,0,0,0,0,0,0,0,0,0,0,0,0,0,0,0,0,0,0,0,0,0,0,0
0,0,0,0,0,0,0,0,0,0,0,0,0,0,0,0,0,0,0,0,0,0,0,0,0,0,0,0,0,0,0,0,0,0,0,0,0,0,0,0,0,0,0
0,0,0,0,0,0,0,0,0,0,0,0,0,0,0,0,0,0,0,0,0,0,0,0,0,0,0,0,0,0,0,0,0,0,0,0,0,0,0,0,0,0,0
0,0,0,0,0,0,0,0,0,0,0,0,0,0,0,0,0,0,0,0,0,0,0,0,0,0,0,0,0,0,0,0,0,0,0,0,0,0,0,0,0,0,0
0,0,0,0,0,0,0,0,0,0,0,0,0,0,0,0,0,0,0,0,0,0,0,0,0,0,0,0,0,0,0,0,0,0,0,0,0,0,0,0,0,0,0
0,0,0,0,0,0,0,0,0,0,0,0,0,0,0,0,0,0,0,0,0,0,0,0,0,0,0,0,0,0,0,0,0,0,0,0,0,0,0,0,0,0,0
0,0,0,0,0,0,0,0,0,0,0,0,0,0,0,0,0,0,0,0,0,0,0,0,0,0,0,0,0,0,0,0,0,0,0,0,0,0,0,0,0,0,0
0,0,0,0,0,0,0,0,0,0,0,0,0,0,0,0,0,0,0,0,0,0,0,0,0,0,0,0,0,0,0,0,0,0,0,0,0,0,0,0,0,0,0
0,0,0,0,0,0,0,92,0,0,0,0,0,0,0,0,0,0,0,0,0,0,0,0,0,0,0,0,0,0,0,0,0,0,0,0,0,0,0,0,0,0,0
0,0,0,0,0,0,92,92,92,0,0,0,0,0,0,0,0,0,0,0,0,0,0,0,0,0,0,0,0,0,0,0,0,0,0,0,0,0,0,0,0,0,0
0,0,0,0,0,0,0,92,0,0,0,0,0,0,0,0,0,0,0,0,0,0,0,0,0,0,0,0,0,0,0,0,0,0,0,0,0,0,0,0,0,0,0
0,0,0,0,0,0,0,0,0,0,0,0,0,0,0,0,0,0,0,0,0,0,0,0,0,0,0,0,0,0,0,0,0,0,0,0,0,0,0,0,0,0,0
0,0,0,0,0,0,0,0,0,0,0,0,0,0,0,0,0,0,0,0,0,0,0,0,0,0,0,0,0,0,0,0,0,0,0,0,0,0,0,0,0,0,0
0,0,0,0,0,0,0,0,0,0,0,0,0,0,0,0,0,0,0,0,0,0,0,0,0,0,0,0,0,0,0,0,0,0,0,0,0,0,0,0,0,0,0
0,0,0,0,0,0,0,0,0,0,0,0,0,0,0,0,0,0,0,0,0,0,0,0,0,0,0,0,0,0,0,0,0,0,0,0,0,0,0,0,0,0,0
0,0,0,0,0,0,0,0,0,0,0,0,0,0,0,0,0,0,0,0,0,0,0,0,0,0,0,0,0,0,0,0,0,0,0,0,0,0,0,0,0,0,0
0,0,0,0,0,0,0,0,0,0,0,0,0,0,0,0,0,0,0,0,0,0,0,0,0,0,0,0,0,0,0,0,0,0,0,0,0,0,0,0,0,0,0
:endlayer
layer: 18
0,0,0,0,0,0,0,0,0,0,0,0,0,0,0,0,0,0,0,0,0,0,0,0,0,0,0,0,0,0,0,0,0,0,0,0,0,0,0,0,0,0,0
0,0,0,0,0,0,0,0,0,0,0,0,0,0,0,0,0,0,0,0,0,0,0,0,0,0,0,0,0,0,0,0,0,0,0,0,0,0,0,0,0,0,0
0,0,0,0,0,0,0,0,0,0,0,0,0,0,0,0,0,0,0,0,0,0,0,0,0,0,0,0,0,0,0,0,0,0,0,0,0,0,0,0,0,0,0
0,0,0,0,0,0,0,0,0,0,0,0,0,0,0,0,0,0,0,0,0,0,0,0,0,0,0,0,0,0,0,0,0,0,0,0,0,0,0,0,0,0,0
0,0,0,0,0,0,0,0,0,0,0,0,0,0,0,0,0,0,0,0,0,0,0,0,0,0,0,0,0,0,0,0,0,0,0,0,0,0,0,0,0,0,0
0,0,0,0,0,0,0,0,0,0,0,0,0,0,0,0,0,0,0,0,0,0,0,0,0,0,0,0,0,0,0,0,0,0,0,0,0,0,0,0,0,0,0
0,0,0,0,0,0,0,0,0,0,0,0,0,0,0,0,0,0,0,0,0,0,0,0,0,0,0,0,0,0,0,0,0,0,0,0,0,0,0,0,0,0,0
0,0,0,0,0,0,0,0,0,0,0,0,0,0,0,0,0,0,0,0,0,0,0,0,0,0,0,0,0,0,0,0,0,0,0,0,0,0,0,0,0,0,0
0,0,0,0,0,0,0,0,0,0,0,0,0,0,0,0,0,0,0,0,0,0,0,0,0,0,0,0,0,0,0,0,0,0,0,0,0,0,0,0,0,0,0
0,0,0,0,0,0,0,0,0,0,0,0,0,0,0,0,0,0,0,0,0,0,0,0,0,0,0,0,0,0,0,0,0,0,0,0,0,0,0,0,0,0,0
0,0,0,0,0,0,0,0,0,0,92,92,92,0,0,0,0,0,0,0,0,0,0,0,0,0,0,0,0,0,0,0,0,0,0,0,0,0,0,0,0,0,0
0,0,0,0,0,0,0,0,0,92,92,92,92,92,0,0,0,0,0,0,0,0,0,0,0,0,0,0,0,0,0,0,0,0,0,0,0,0,0,0,0,0,0
0,0,0,0,0,0,0,0,0,92,92,92,92,92,0,0,0,0,0,0,0,0,0,0,0,0,0,0,0,0,0,0,0,0,0,0,0,0,0,0,0,0,0
0,0,0,0,0,0,0,0,0,92,92,92,92,92,0,0,0,0,0,0,0,0,0,0,0,0,0,0,0,0,0,0,0,0,0,0,0,0,0,0,0,0,0
0,0,0,0,0,0,0,0,92,92,92,92,92,0,0,0,0,0,0,0,0,0,0,0,0,0,0,0,0,0,0,0,0,0,0,0,0,0,0,0,0,0,0
0,0,0,0,0,0,0,0,0,92,0,0,0,0,0,0,0,0,0,0,0,0,0,0,0,0,0,0,0,0,0,0,0,0,0,0,0,0,0,0,0,0,0
0,0,0,0,0,0,0,0,0,0,0,0,0,0,0,0,0,0,0,0,0,0,0,0,165,0,0,0,0,0,0,0,0,0,0,0,0,0,0,0,0,0,0
0,0,0,0,0,0,0,0,0,0,0,0,0,0,0,0,0,0,0,0,0,0,0,0,165,0,0,0,0,0,0,0,0,0,0,0,0,0,0,0,0,0,0
0,0,0,0,0,0,0,0,0,0,0,0,0,0,0,0,0,0,0,0,0,0,0,0,165,0,0,0,0,0,0,0,0,0,0,0,0,0,0,0,0,0,0
0,0,0,0,0,0,0,0,0,0,0,0,0,0,0,0,0,0,0,0,0,0,0,0,0,0,0,0,0,0,0,0,0,0,0,0,0,0,0,0,0,0,0
0,0,0,0,0,0,0,0,0,0,0,0,0,0,0,0,0,0,0,0,0,0,0,0,0,0,0,0,0,0,0,0,0,0,0,0,0,0,0,0,0,0,0
0,0,0,0,0,0,0,0,0,0,0,0,0,0,0,0,0,0,0,0,0,0,0,0,0,0,0,0,0,0,0,0,0,0,0,0,0,0,0,0,0,0,0
0,0,0,0,0,0,0,0,0,0,0,0,0,0,0,0,0,0,0,0,0,0,0,0,0,0,0,0,0,0,0,0,0,0,0,0,0,0,0,0,0,0,0
0,0,0,0,0,0,0,0,0,0,0,0,0,0,0,0,0,0,0,0,0,0,0,0,0,0,0,0,0,0,0,0,0,0,0,0,0,0,0,0,0,0,0
0,0,0,0,0,0,0,0,0,0,0,0,0,0,0,0,0,0,0,0,0,0,0,0,0,0,0,0,0,0,0,0,0,0,0,0,0,0,0,0,0,0,0
0,0,0,0,0,0,0,0,0,0,0,0,0,0,0,0,0,0,0,0,0,0,0,0,0,0,0,0,0,0,0,0,0,0,0,0,0,0,0,0,0,0,0
0,0,0,0,0,0,0,0,0,0,0,0,0,0,0,0,0,0,0,0,0,0,0,0,0,0,0,0,0,0,0,0,0,0,0,0,0,0,0,0,0,0,0
0,0,0,0,0,0,0,0,0,0,0,0,0,0,0,0,0,0,0,0,0,0,0,0,0,0,0,0,0,0,0,0,0,0,0,0,0,0,0,0,0,0,0
0,0,0,0,0,0,0,0,0,0,0,0,0,0,0,0,0,0,0,0,0,0,0,0,0,0,0,0,0,0,0,0,0,0,0,0,0,0,0,0,0,0,0
0,0,0,0,0,0,0,0,0,0,0,0,0,0,0,0,0,0,0,0,0,0,0,0,0,0,0,0,0,0,0,0,0,0,0,0,0,0,0,0,0,0,0
0,0,0,0,0,0,0,0,0,0,0,0,0,0,0,0,0,0,0,0,0,0,0,0,0,0,0,0,0,0,0,0,0,0,0,0,0,0,0,0,0,0,0
0,0,0,0,0,0,0,0,0,0,0,0,0,0,0,0,0,0,0,0,0,0,0,0,0,0,0,0,0,0,0,0,0,0,0,0,0,0,0,0,0,0,0
0,0,0,0,0,0,0,0,0,0,0,0,0,0,0,0,0,0,0,0,0,0,0,0,0,0,0,0,0,0,0,0,0,0,0,0,0,0,0,0,0,0,0
0,0,0,0,0,0,0,0,0,0,0,0,0,0,0,0,0,0,0,0,0,0,0,0,0,0,0,0,0,0,0,0,0,0,0,0,0,0,0,0,0,0,0
0,0,0,0,0,0,0,0,0,0,0,0,0,0,0,0,0,0,0,0,0,0,0,0,0,0,0,0,0,0,0,0,0,0,0,0,0,0,0,0,0,0,0
0,0,0,0,0,0,0,0,0,0,0,0,0,0,0,0,0,0,0,0,0,0,0,0,0,0,0,0,0,0,0,0,0,0,0,0,0,0,0,0,0,0,0
0,0,0,0,0,0,0,0,0,0,0,0,0,0,0,0,0,0,0,0,0,0,0,0,0,0,0,0,0,0,0,0,0,0,0,0,0,0,0,0,0,0,0
0,0,0,0,0,0,0,0,0,0,0,0,0,0,0,0,0,0,0,0,0,0,0,0,0,0,0,0,0,0,0,0,0,0,0,0,0,0,0,0,0,0,0
0,0,0,0,0,0,0,0,0,0,0,0,0,0,0,0,0,0,0,0,0,0,0,0,0,0,0,0,0,0,0,0,0,0,0,0,0,0,0,0,0,0,0
0,0,0,0,0,0,0,0,0,0,0,0,0,0,0,0,0,0,0,0,0,0,0,0,0,0,0,0,0,0,0,0,0,0,0,0,0,0,0,0,0,0,0
0,0,0,0,0,0,0,0,0,0,0,0,0,0,0,0,0,0,0,0,0,0,0,0,0,0,0,0,0,0,0,0,0,0,0,0,0,0,0,0,0,0,0
0,0,0,0,0,0,0,0,0,0,0,0,0,0,0,0,0,0,0,0,0,0,0,0,0,0,0,0,0,0,0,0,0,0,0,0,0,0,0,0,0,0,0
0,0,0,0,0,0,0,0,0,0,0,0,0,0,0,0,0,0,0,0,0,0,0,0,0,0,0,0,0,0,0,0,0,0,0,0,0,0,0,0,0,0,0
:endlayer
layer: 19
0,0,0,0,0,0,0,0,0,0,0,0,0,0,0,0,0,0,0,0,0,0,0,0,0,0,0,0,0,0,0,0,0,0,0,0,0,0,0,0,0,0,0
0,0,0,0,0,0,0,0,0,0,0,0,0,0,0,0,0,0,0,0,0,0,0,0,0,0,0,0,0,0,0,0,0,0,0,0,0,0,0,0,0,0,0
0,0,0,0,0,0,0,0,0,0,0,0,0,0,0,0,0,0,0,0,0,0,0,0,0,0,0,0,0,0,0,0,0,0,0,0,0,0,0,0,0,0,0
0,0,0,0,0,0,0,0,0,0,0,0,0,0,0,0,0,0,0,0,0,0,0,0,0,0,0,0,0,0,0,0,0,0,0,0,0,0,0,0,0,0,0
0,0,0,0,0,0,0,0,0,0,0,0,0,0,0,0,0,0,0,0,0,0,0,0,0,0,0,0,0,0,0,0,0,0,0,0,0,0,0,0,0,0,0
0,0,0,0,0,0,0,0,0,0,0,0,0,0,0,0,0,0,0,0,0,0,0,0,0,0,0,0,0,0,0,0,0,0,0,0,0,0,0,0,0,0,0
0,0,0,0,0,0,0,0,0,0,0,0,0,0,0,0,0,0,0,0,0,0,0,0,0,0,0,0,0,0,0,0,0,0,0,0,0,0,0,0,0,0,0
0,0,0,0,0,0,0,0,0,0,0,0,0,0,0,0,0,0,0,0,0,0,0,0,0,0,0,0,0,0,0,0,0,0,0,0,0,0,0,0,0,0,0
0,0,0,0,0,0,0,0,0,0,0,0,0,0,0,0,0,0,0,0,0,0,0,0,0,0,0,0,0,0,0,0,0,0,0,0,0,0,0,0,0,0,0
0,0,0,0,0,0,0,0,0,0,0,0,0,0,0,0,0,0,0,0,0,0,0,0,0,0,0,0,0,0,0,0,0,0,0,0,0,0,0,0,0,0,0
0,0,0,0,0,0,0,0,0,0,0,0,0,0,0,0,0,0,0,0,0,0,0,0,0,0,0,0,0,0,0,0,0,0,0,0,0,0,0,0,0,0,0
0,0,0,0,0,0,0,0,0,0,0,92,0,0,0,0,0,0,0,0,0,0,0,0,0,0,0,0,0,0,0,0,0,0,0,0,0,0,0,0,0,0,0
0,0,0,0,0,0,0,0,0,0,92,92,92,0,0,0,0,0,0,0,0,0,0,0,0,0,0,0,0,0,0,0,0,0,0,0,0,0,0,0,0,0,0
0,0,0,0,0,0,0,0,0,0,0,92,0,0,0,0,0,0,0,0,0,0,0,0,0,0,0,0,0,0,0,0,0,0,0,0,0,0,0,0,0,0,0
0,0,0,0,0,0,0,0,0,0,0,0,0,0,0,0,0,0,0,0,0,0,0,0,0,0,0,0,0,0,0,0,0,0,0,0,0,0,0,0,0,0,0
0,0,0,0,0,0,0,0,0,0,0,0,0,0,0,0,0,0,0,0,0,0,0,0,0,0,0,0,0,0,0,0,0,0,0,0,0,0,0,0,0,0,0
0,0,0,0,0,0,0,0,0,0,0,0,0,0,0,0,0,0,0,0,0,0,0,0,0,0,0,0,0,0,0,0,0,0,0,0,0,0,0,0,0,0,0
0,0,0,0,0,0,0,0,0,0,0,0,0,0,0,0,0,0,0,0,0,0,0,0,0,0,0,0,0,0,0,0,0,0,0,0,0,0,0,0,0,0,0
0,0,0,0,0,0,0,0,0,0,0,0,0,0,0,0,0,0,0,0,0,0,0,0,0,0,0,0,0,0,0,0,0,0,0,0,0,0,0,0,0,0,0
0,0,0,0,0,0,0,0,0,0,0,0,0,0,0,0,0,0,0,0,0,0,0,0,0,0,0,0,0,0,0,0,0,0,0,0,0,0,0,0,0,0,0
0,0,0,0,0,0,0,0,0,0,0,0,0,0,0,0,0,0,0,0,0,0,0,0,0,0,0,0,0,0,0,0,0,0,0,0,0,0,0,0,0,0,0
0,0,0,0,0,0,0,0,0,0,0,0,0,0,0,0,0,0,0,0,0,0,0,0,0,0,0,0,0,0,0,0,0,0,0,0,0,0,0,0,0,0,0
0,0,0,0,0,0,0,0,0,0,0,0,0,0,0,0,0,0,0,0,0,0,0,0,0,0,0,0,0,0,0,0,0,0,0,0,0,0,0,0,0,0,0
0,0,0,0,0,0,0,0,0,0,0,0,0,0,0,0,0,0,0,0,0,0,0,0,0,0,0,0,0,0,0,0,0,0,0,0,0,0,0,0,0,0,0
0,0,0,0,0,0,0,0,0,0,0,0,0,0,0,0,0,0,0,0,0,0,0,0,0,0,0,0,0,0,0,0,0,0,0,0,0,0,0,0,0,0,0
0,0,0,0,0,0,0,0,0,0,0,0,0,0,0,0,0,0,0,0,0,0,0,0,0,0,0,0,0,0,0,0,0,0,0,0,0,0,0,0,0,0,0
0,0,0,0,0,0,0,0,0,0,0,0,0,0,0,0,0,0,0,0,0,0,0,0,0,0,0,0,0,0,0,0,0,0,0,0,0,0,0,0,0,0,0
0,0,0,0,0,0,0,0,0,0,0,0,0,0,0,0,0,0,0,0,0,0,0,0,0,0,0,0,0,0,0,0,0,0,0,0,0,0,0,0,0,0,0
0,0,0,0,0,0,0,0,0,0,0,0,0,0,0,0,0,0,0,0,0,0,0,0,0,0,0,0,0,0,0,0,0,0,0,0,0,0,0,0,0,0,0
0,0,0,0,0,0,0,0,0,0,0,0,0,0,0,0,0,0,0,0,0,0,0,0,0,0,0,0,0,0,0,0,0,0,0,0,0,0,0,0,0,0,0
0,0,0,0,0,0,0,0,0,0,0,0,0,0,0,0,0,0,0,0,0,0,0,0,0,0,0,0,0,0,0,0,0,0,0,0,0,0,0,0,0,0,0
0,0,0,0,0,0,0,0,0,0,0,0,0,0,0,0,0,0,0,0,0,0,0,0,0,0,0,0,0,0,0,0,0,0,0,0,0,0,0,0,0,0,0
0,0,0,0,0,0,0,0,0,0,0,0,0,0,0,0,0,0,0,0,0,0,0,0,0,0,0,0,0,0,0,0,0,0,0,0,0,0,0,0,0,0,0
0,0,0,0,0,0,0,0,0,0,0,0,0,0,0,0,0,0,0,0,0,0,0,0,0,0,0,0,0,0,0,0,0,0,0,0,0,0,0,0,0,0,0
0,0,0,0,0,0,0,0,0,0,0,0,0,0,0,0,0,0,0,0,0,0,0,0,0,0,0,0,0,0,0,0,0,0,0,0,0,0,0,0,0,0,0
0,0,0,0,0,0,0,0,0,0,0,0,0,0,0,0,0,0,0,0,0,0,0,0,0,0,0,0,0,0,0,0,0,0,0,0,0,0,0,0,0,0,0
0,0,0,0,0,0,0,0,0,0,0,0,0,0,0,0,0,0,0,0,0,0,0,0,0,0,0,0,0,0,0,0,0,0,0,0,0,0,0,0,0,0,0
0,0,0,0,0,0,0,0,0,0,0,0,0,0,0,0,0,0,0,0,0,0,0,0,0,0,0,0,0,0,0,0,0,0,0,0,0,0,0,0,0,0,0
0,0,0,0,0,0,0,0,0,0,0,0,0,0,0,0,0,0,0,0,0,0,0,0,0,0,0,0,0,0,0,0,0,0,0,0,0,0,0,0,0,0,0
0,0,0,0,0,0,0,0,0,0,0,0,0,0,0,0,0,0,0,0,0,0,0,0,0,0,0,0,0,0,0,0,0,0,0,0,0,0,0,0,0,0,0
0,0,0,0,0,0,0,0,0,0,0,0,0,0,0,0,0,0,0,0,0,0,0,0,0,0,0,0,0,0,0,0,0,0,0,0,0,0,0,0,0,0,0
0,0,0,0,0,0,0,0,0,0,0,0,0,0,0,0,0,0,0,0,0,0,0,0,0,0,0,0,0,0,0,0,0,0,0,0,0,0,0,0,0,0,0
0,0,0,0,0,0,0,0,0,0,0,0,0,0,0,0,0,0,0,0,0,0,0,0,0,0,0,0,0,0,0,0,0,0,0,0,0,0,0,0,0,0,0
:endlayer

#### RULES ####
rule:
plugin=vanillaBlocks
number=1
data:
JSON:{blockState:{blockName:"minecraft:stone",properties:{variant:"stone"}}}
:enddata
:endrule

rule:
plugin=vanillaBlocks
number=2
data:
JSON:{blockState:{blockName:"minecraft:dirt",properties:{variant:"dirt",snowy:"false"}}}
:enddata
:endrule

rule:
plugin=vanillaBlocks
number=3
data:
JSON:{blockState:{blockName:"minecraft:log",properties:{variant:"oak",axis:"y"}}}
:enddata
:endrule

rule:
plugin=vanillaBlocks
number=4
data:
JSON:{blockState:{blockName:"minecraft:stonebrick",properties:{variant:"stonebrick"}}}
:enddata
:endrule

rule:
plugin=vanillaBlocks
number=5
data:
JSON:{blockState:{blockName:"quark:world_stone_bricks",properties:{variant:"stone_andesite_bricks"}}}
:enddata
:endrule

rule:
plugin=vanillaBlocks
number=6
data:
JSON:{blockState:{blockName:"minecraft:grass",properties:{snowy:"false"}}}
:enddata
:endrule

rule:
plugin=vanillaBlocks
number=7
data:
JSON:{blockState:{blockName:"minecraft:grass_path"}}
:enddata
:endrule

rule:
plugin=vanillaBlocks
number=8
data:
JSON:{blockState:{blockName:"quark:world_stone_pavement",properties:{variant:"stone_andesite_pavement"}}}
:enddata
:endrule

rule:
plugin=vanillaBlocks
number=9
data:
JSON:{blockState:{blockName:"quark:world_stone_pavement",properties:{variant:"stone_limestone_pavement"}}}
:enddata
:endrule

rule:
plugin=blockTile
number=10
data:
JSON:{blockState:{blockName:"ancientwarfarestructure:advanced_spawner",properties:{transparent:"true"}},teData:{id:"ancientwarfarestructure:advanced_spawner_tile",spawnerSettings:{minDelay:10,spawnDelay:9,lightSensitive:0b,spawnGroups:[{settingsList:[{remainingSpawnCount:1,hostile:1b,customTag:{ArmorDropChances:[0.085f,0.085f,0.085f,0.085f],hasCustomEquipment:0b,ArmorItems:[{},{},{},{}],skinSettings:{npcTypeName:"custom",skinTypeSelected:"default"},HandDropChances:[0.085f,0.085f],factionName:"guild",HandItems:[{id:"ancientwarfarenpc:iron_spear",Count:1b,Damage:0s},{id:"ancientwarfarenpc:iron_shield",Count:1b,Damage:0s}]},maxToSpawn:1,entityId:"ancientwarfarenpc:faction.soldier",minToSpawn:1}],groupWeight:1}],playerRange:16,respondToRedstone:0b,inventory:{Size:9,Items:[]},spawnRange:0,transparent:1b,maxDelay:10,spawnYOffset:0,xpToDrop:0,mobRange:0,debugMode:0b,maxNearbyMonsters:0}}}
:enddata
:endrule

rule:
plugin=blockTile
number=11
data:
JSON:{blockState:{blockName:"ancientwarfarestructure:advanced_spawner",properties:{transparent:"true"}},teData:{id:"ancientwarfarestructure:advanced_spawner_tile",spawnerSettings:{minDelay:10,spawnDelay:9,lightSensitive:0b,spawnGroups:[{settingsList:[{remainingSpawnCount:1,hostile:1b,customTag:{ArmorDropChances:[0.085f,0.085f,0.085f,0.085f],hasCustomEquipment:0b,ArmorItems:[{},{},{},{}],skinSettings:{npcTypeName:"custom",skinTypeSelected:"default"},HandDropChances:[0.085f,0.085f],factionName:"guild",HandItems:[{id:"ancientwarfarenpc:iron_spear",Count:1b,Damage:0s},{id:"ancientwarfarenpc:iron_shield",Count:1b,Damage:0s}]},maxToSpawn:1,entityId:"ancientwarfarenpc:faction.soldier",minToSpawn:1}],groupWeight:1}],playerRange:16,respondToRedstone:0b,inventory:{Size:9,Items:[]},spawnRange:0,transparent:1b,maxDelay:10,spawnYOffset:0,xpToDrop:0,mobRange:0,debugMode:0b,maxNearbyMonsters:0}}}
:enddata
:endrule

rule:
plugin=blockTile
number=12
data:
JSON:{blockState:{blockName:"ancientwarfarestructure:advanced_spawner",properties:{transparent:"true"}},teData:{id:"ancientwarfarestructure:advanced_spawner_tile",spawnerSettings:{minDelay:10,spawnDelay:5,lightSensitive:0b,spawnGroups:[{settingsList:[{remainingSpawnCount:1,hostile:1b,customTag:{ArmorDropChances:[0.085f,0.085f,0.085f,0.085f],hasCustomEquipment:0b,ArmorItems:[{},{},{},{}],skinSettings:{npcTypeName:"custom",skinTypeSelected:"default"},HandDropChances:[0.085f,0.085f],factionName:"guild",HandItems:[{id:"ancientwarfarenpc:iron_spear",Count:1b,Damage:0s},{id:"ancientwarfarenpc:iron_shield",Count:1b,Damage:0s}]},maxToSpawn:1,entityId:"ancientwarfarenpc:faction.soldier",minToSpawn:1}],groupWeight:1}],playerRange:16,respondToRedstone:0b,inventory:{Size:9,Items:[]},spawnRange:0,transparent:1b,maxDelay:10,spawnYOffset:0,xpToDrop:0,mobRange:0,debugMode:0b,maxNearbyMonsters:0}}}
:enddata
:endrule

rule:
plugin=blockTile
number=13
data:
JSON:{blockState:{blockName:"ancientwarfarestructure:advanced_spawner",properties:{transparent:"true"}},teData:{id:"ancientwarfarestructure:advanced_spawner_tile",spawnerSettings:{minDelay:10,spawnDelay:1,lightSensitive:0b,spawnGroups:[{settingsList:[{remainingSpawnCount:1,hostile:1b,customTag:{ArmorDropChances:[0.085f,0.085f,0.085f,0.085f],hasCustomEquipment:0b,ArmorItems:[{},{},{},{}],skinSettings:{npcTypeName:"custom",skinTypeSelected:"default"},HandDropChances:[0.085f,0.085f],factionName:"guild",HandItems:[{id:"ancientwarfarenpc:iron_spear",Count:1b,Damage:0s},{id:"ancientwarfarenpc:iron_shield",Count:1b,Damage:0s}]},maxToSpawn:1,entityId:"ancientwarfarenpc:faction.soldier",minToSpawn:1}],groupWeight:1}],playerRange:16,respondToRedstone:0b,inventory:{Size:9,Items:[]},spawnRange:0,transparent:1b,maxDelay:10,spawnYOffset:0,xpToDrop:0,mobRange:0,debugMode:0b,maxNearbyMonsters:0}}}
:enddata
:endrule

rule:
plugin=vanillaBlocks
number=14
data:
JSON:{blockState:{blockName:"quark:world_stone_bricks",properties:{variant:"stone_limestone_bricks"}}}
:enddata
:endrule

rule:
plugin=vanillaBlocks
number=15
data:
JSON:{blockState:{blockName:"quark:limestone_wall",properties:{east:"false",south:"false",north:"false",west:"false",up:"false"}}}
:enddata
:endrule

rule:
plugin=vanillaBlocks
number=16
data:
JSON:{blockState:{blockName:"minecraft:sandstone",properties:{type:"sandstone"}}}
:enddata
:endrule

rule:
plugin=vanillaBlocks
number=17
data:
JSON:{blockState:{blockName:"quark:jasper",properties:{variant:"stone_jasper"}}}
:enddata
:endrule

rule:
plugin=vanillaBlocks
number=18
data:
JSON:{blockState:{blockName:"minecraft:stone",properties:{variant:"diorite"}}}
:enddata
:endrule

rule:
plugin=vanillaBlocks
number=19
data:
JSON:{blockState:{blockName:"minecraft:tallgrass",properties:{type:"tall_grass"}}}
:enddata
:endrule

rule:
plugin=vanillaBlocks
number=20
data:
JSON:{blockState:{blockName:"minecraft:red_flower",properties:{type:"houstonia"}}}
:enddata
:endrule

rule:
plugin=vanillaBlocks
number=21
data:
JSON:{blockState:{blockName:"minecraft:red_flower",properties:{type:"oxeye_daisy"}}}
:enddata
:endrule

rule:
plugin=blockTile
number=22
data:
JSON:{blockState:{blockName:"ancientwarfarestructure:advanced_spawner",properties:{transparent:"true"}},teData:{id:"ancientwarfarestructure:advanced_spawner_tile",spawnerSettings:{minDelay:10,spawnDelay:4,lightSensitive:0b,spawnGroups:[{settingsList:[{remainingSpawnCount:1,hostile:1b,customTag:{ArmorDropChances:[0.085f,0.085f,0.085f,0.085f],CustomName:"Merchant Guild Stone Worker",hasCustomEquipment:1b,ArmorItems:[{},{},{},{}],skinSettings:{random:0b,npcTypeName:"nogg.civilian.male",skinTypeSelected:"npc_type",npcTypeSkin:"ancientwarfare:skinpack/nogg_villager_9.png"},HandDropChances:[0.085f,0.085f],factionName:"guild",HandItems:[{id:"minecraft:stone_pickaxe",Count:1b,Damage:0s},{}]},maxToSpawn:1,entityId:"ancientwarfarenpc:faction.soldier",minToSpawn:1}],groupWeight:1}],playerRange:16,respondToRedstone:0b,inventory:{Size:9,Items:[]},spawnRange:0,transparent:1b,maxDelay:10,spawnYOffset:0,xpToDrop:0,mobRange:0,debugMode:0b,maxNearbyMonsters:0}}}
:enddata
:endrule

rule:
plugin=vanillaBlocks
number=23
data:
JSON:{blockState:{blockName:"minecraft:red_flower",properties:{type:"poppy"}}}
:enddata
:endrule

rule:
plugin=blockTile
number=24
data:
JSON:{blockState:{blockName:"ancientwarfarestructure:advanced_spawner",properties:{transparent:"true"}},teData:{id:"ancientwarfarestructure:advanced_spawner_tile",spawnerSettings:{minDelay:10,spawnDelay:2,lightSensitive:0b,spawnGroups:[{settingsList:[{remainingSpawnCount:1,hostile:1b,customTag:{ArmorDropChances:[0.085f,0.085f,0.085f,0.085f],CustomName:"Merchant Guild Stone Worker",hasCustomEquipment:1b,ArmorItems:[{},{},{},{}],skinSettings:{random:0b,npcTypeName:"nogg.civilian.male",skinTypeSelected:"npc_type",npcTypeSkin:"ancientwarfare:skinpack/nogg_villager_9.png"},HandDropChances:[0.085f,0.085f],factionName:"guild",HandItems:[{id:"minecraft:stone_pickaxe",Count:1b,Damage:0s},{}]},maxToSpawn:1,entityId:"ancientwarfarenpc:faction.soldier",minToSpawn:1}],groupWeight:1}],playerRange:16,respondToRedstone:0b,inventory:{Size:9,Items:[]},spawnRange:0,transparent:1b,maxDelay:10,spawnYOffset:0,xpToDrop:0,mobRange:0,debugMode:0b,maxNearbyMonsters:0}}}
:enddata
:endrule

rule:
plugin=vanillaBlocks
number=25
data:
JSON:{blockState:{blockName:"minecraft:yellow_flower",properties:{type:"dandelion"}}}
:enddata
:endrule

rule:
plugin=blockTile
number=26
data:
JSON:{blockState:{blockName:"ancientwarfarestructure:advanced_spawner",properties:{transparent:"true"}},teData:{id:"ancientwarfarestructure:advanced_spawner_tile",spawnerSettings:{minDelay:10,spawnDelay:4,lightSensitive:0b,spawnGroups:[{settingsList:[{remainingSpawnCount:1,hostile:1b,customTag:{ArmorDropChances:[0.085f,0.085f,0.085f,0.085f],hasCustomEquipment:0b,ArmorItems:[{},{},{},{}],skinSettings:{npcTypeName:"custom",skinTypeSelected:"default"},HandDropChances:[0.085f,0.085f],factionName:"guild",HandItems:[{id:"ancientwarfarenpc:iron_spear",Count:1b,Damage:0s},{id:"ancientwarfarenpc:iron_shield",Count:1b,Damage:0s}]},maxToSpawn:1,entityId:"ancientwarfarenpc:faction.soldier",minToSpawn:1}],groupWeight:1}],playerRange:16,respondToRedstone:0b,inventory:{Size:9,Items:[]},spawnRange:0,transparent:1b,maxDelay:10,spawnYOffset:0,xpToDrop:0,mobRange:0,debugMode:0b,maxNearbyMonsters:0}}}
:enddata
:endrule

rule:
plugin=vanillaBlocks
number=27
data:
JSON:{blockState:{blockName:"minecraft:stone",properties:{variant:"granite"}}}
:enddata
:endrule

rule:
plugin=vanillaBlocks
number=28
data:
JSON:{blockState:{blockName:"minecraft:red_flower",properties:{type:"pink_tulip"}}}
:enddata
:endrule

rule:
plugin=doors
number=29
data:
JSON:{blockState:{blockName:"minecraft:spruce_door",properties:{hinge:"left",half:"lower",powered:"false",facing:"east",open:"false"}}}
:enddata
:endrule

rule:
plugin=vanillaBlocks
number=30
data:
JSON:{blockState:{blockName:"minecraft:stone",properties:{variant:"andesite"}}}
:enddata
:endrule

rule:
plugin=blockTile
number=31
data:
JSON:{blockState:{blockName:"ancientwarfarestructure:advanced_spawner",properties:{transparent:"true"}},teData:{id:"ancientwarfarestructure:advanced_spawner_tile",spawnerSettings:{minDelay:10,spawnDelay:7,lightSensitive:0b,spawnGroups:[{settingsList:[{remainingSpawnCount:1,hostile:1b,customTag:{ArmorDropChances:[0.085f,0.085f,0.085f,0.085f],hasCustomEquipment:0b,ArmorItems:[{},{},{},{}],skinSettings:{npcTypeName:"custom",skinTypeSelected:"default"},HandDropChances:[0.085f,0.085f],factionName:"guild",HandItems:[{id:"ancientwarfarenpc:iron_spear",Count:1b,Damage:0s},{id:"ancientwarfarenpc:iron_shield",Count:1b,Damage:0s}]},maxToSpawn:1,entityId:"ancientwarfarenpc:faction.soldier",minToSpawn:1}],groupWeight:1}],playerRange:16,respondToRedstone:0b,inventory:{Size:9,Items:[]},spawnRange:0,transparent:1b,maxDelay:10,spawnYOffset:0,xpToDrop:0,mobRange:0,debugMode:0b,maxNearbyMonsters:0}}}
:enddata
:endrule

rule:
plugin=blockTile
number=32
data:
JSON:{blockState:{blockName:"ancientwarfarestructure:advanced_spawner",properties:{transparent:"true"}},teData:{id:"ancientwarfarestructure:advanced_spawner_tile",spawnerSettings:{minDelay:10,spawnDelay:8,lightSensitive:0b,spawnGroups:[{settingsList:[{remainingSpawnCount:1,hostile:1b,customTag:{ArmorDropChances:[0.085f,0.085f,0.085f,0.085f],hasCustomEquipment:0b,ArmorItems:[{},{},{},{}],skinSettings:{npcTypeName:"custom",skinTypeSelected:"default"},HandDropChances:[0.085f,0.085f],factionName:"guild",HandItems:[{id:"ancientwarfarenpc:iron_spear",Count:1b,Damage:0s},{id:"ancientwarfarenpc:iron_shield",Count:1b,Damage:0s}]},maxToSpawn:1,entityId:"ancientwarfarenpc:faction.soldier",minToSpawn:1}],groupWeight:1}],playerRange:16,respondToRedstone:0b,inventory:{Size:9,Items:[]},spawnRange:0,transparent:1b,maxDelay:10,spawnYOffset:0,xpToDrop:0,mobRange:0,debugMode:0b,maxNearbyMonsters:0}}}
:enddata
:endrule

rule:
plugin=vanillaBlocks
number=33
data:
JSON:{blockState:{blockName:"minecraft:leaves",properties:{check_decay:"false",decayable:"false",variant:"oak"}}}
:enddata
:endrule

rule:
plugin=doors
number=34
data:
JSON:{blockState:{blockName:"minecraft:wooden_door",properties:{hinge:"left",half:"lower",powered:"false",facing:"north",open:"false"}}}
:enddata
:endrule

rule:
plugin=blockTile
number=35
data:
JSON:{blockState:{blockName:"ancientwarfarestructure:advanced_spawner",properties:{transparent:"true"}},teData:{id:"ancientwarfarestructure:advanced_spawner_tile",spawnerSettings:{minDelay:10,spawnDelay:3,lightSensitive:0b,spawnGroups:[{settingsList:[{remainingSpawnCount:1,hostile:1b,customTag:{ArmorDropChances:[0.085f,0.085f,0.085f,0.085f],CustomName:"Merchant Guild Stone Worker",hasCustomEquipment:1b,ArmorItems:[{},{},{},{}],skinSettings:{random:0b,npcTypeName:"nogg.civilian.male",skinTypeSelected:"npc_type",npcTypeSkin:"ancientwarfare:skinpack/nogg_villager_9.png"},HandDropChances:[0.085f,0.085f],factionName:"guild",HandItems:[{id:"minecraft:stone_pickaxe",Count:1b,Damage:0s},{}]},maxToSpawn:1,entityId:"ancientwarfarenpc:faction.soldier",minToSpawn:1}],groupWeight:1}],playerRange:16,respondToRedstone:0b,inventory:{Size:9,Items:[]},spawnRange:0,transparent:1b,maxDelay:10,spawnYOffset:0,xpToDrop:0,mobRange:0,debugMode:0b,maxNearbyMonsters:0}}}
:enddata
:endrule

rule:
plugin=vanillaBlocks
number=36
data:
JSON:{blockState:{blockName:"ancientwarfarestructure:bench",properties:{legs:"none",variant:"spruce",axis:"z"}}}
:enddata
:endrule

rule:
plugin=blockTile
number=37
data:
JSON:{blockState:{blockName:"ancientwarfarestructure:urn"},teData:{lootSettings:{lootRolls:0,splashPotion:0b,hasMessage:0b,hasLoot:0b,lootTableName:"minecraft:",spawnEntity:0b,entity:"minecraft:"},id:"ancientwarfarestructure:urn_tile"}}
:enddata
:endrule

rule:
plugin=blockTile
number=38
data:
JSON:{blockState:{blockName:"ancientwarfarestructure:advanced_spawner",properties:{transparent:"true"}},teData:{id:"ancientwarfarestructure:advanced_spawner_tile",spawnerSettings:{minDelay:10,spawnDelay:10,lightSensitive:0b,spawnGroups:[{settingsList:[{remainingSpawnCount:1,hostile:1b,customTag:{ArmorDropChances:[0.085f,0.085f,0.085f,0.085f],hasCustomEquipment:0b,ArmorItems:[{},{},{},{}],skinSettings:{npcTypeName:"custom",skinTypeSelected:"default"},HandDropChances:[0.085f,0.085f],factionName:"guild",HandItems:[{id:"ancientwarfarenpc:iron_spear",Count:1b,Damage:0s},{id:"ancientwarfarenpc:iron_shield",Count:1b,Damage:0s}]},maxToSpawn:1,entityId:"ancientwarfarenpc:faction.soldier",minToSpawn:1}],groupWeight:1}],playerRange:16,respondToRedstone:0b,inventory:{Size:9,Items:[]},spawnRange:0,transparent:1b,maxDelay:10,spawnYOffset:0,xpToDrop:0,mobRange:0,debugMode:0b,maxNearbyMonsters:0}}}
:enddata
:endrule

rule:
plugin=blockTile
number=39
data:
JSON:{blockState:{blockName:"ancientwarfarestructure:advanced_spawner",properties:{transparent:"true"}},teData:{id:"ancientwarfarestructure:advanced_spawner_tile",spawnerSettings:{minDelay:10,spawnDelay:6,lightSensitive:0b,spawnGroups:[{settingsList:[{remainingSpawnCount:1,hostile:1b,customTag:{ArmorDropChances:[0.085f,0.085f,0.085f,0.085f],hasCustomEquipment:0b,ArmorItems:[{},{},{},{}],skinSettings:{npcTypeName:"custom",skinTypeSelected:"default"},HandDropChances:[0.085f,0.085f],factionName:"guild",HandItems:[{id:"minecraft:bow",Count:1b,Damage:0s},{}]},maxToSpawn:1,entityId:"ancientwarfarenpc:faction.archer",minToSpawn:1}],groupWeight:1}],playerRange:32,respondToRedstone:0b,inventory:{Size:9,Items:[]},spawnRange:0,transparent:1b,maxDelay:10,spawnYOffset:0,xpToDrop:0,mobRange:0,debugMode:0b,maxNearbyMonsters:0}}}
:enddata
:endrule

rule:
plugin=blockTile
number=40
data:
JSON:{blockState:{blockName:"ancientwarfarestructure:advanced_spawner",properties:{transparent:"true"}},teData:{id:"ancientwarfarestructure:advanced_spawner_tile",spawnerSettings:{minDelay:10,spawnDelay:4,lightSensitive:0b,spawnGroups:[{settingsList:[{remainingSpawnCount:1,hostile:1b,customTag:{ArmorDropChances:[0.085f,0.085f,0.085f,0.085f],hasCustomEquipment:0b,ArmorItems:[{},{},{},{}],skinSettings:{npcTypeName:"custom",skinTypeSelected:"default"},HandDropChances:[0.085f,0.085f],factionName:"guild",HandItems:[{id:"minecraft:bow",Count:1b,Damage:0s},{}]},maxToSpawn:1,entityId:"ancientwarfarenpc:faction.archer",minToSpawn:1}],groupWeight:1}],playerRange:32,respondToRedstone:0b,inventory:{Size:9,Items:[]},spawnRange:0,transparent:1b,maxDelay:10,spawnYOffset:0,xpToDrop:0,mobRange:0,debugMode:0b,maxNearbyMonsters:0}}}
:enddata
:endrule

rule:
plugin=vanillaBlocks
number=41
data:
JSON:{blockState:{blockName:"quark:limestone",properties:{variant:"stone_limestone"}}}
:enddata
:endrule

rule:
plugin=blockTile
number=42
data:
JSON:{blockState:{blockName:"ancientwarfarestructure:gate_proxy"},teData:{lsb:-9117094087824269761L,id:"ancientwarfarestructure:gate_proxy_tile",msb:3513461500161442935L,render:1b}}
:enddata
:endrule

rule:
plugin=blockTile
number=43
data:
JSON:{blockState:{blockName:"ancientwarfarestructure:gate_proxy"},teData:{lsb:-9117094087824269761L,id:"ancientwarfarestructure:gate_proxy_tile",msb:3513461500161442935L,render:1b}}
:enddata
:endrule

rule:
plugin=blockTile
number=44
data:
JSON:{blockState:{blockName:"ancientwarfarestructure:gate_proxy"},teData:{lsb:-9117094087824269761L,id:"ancientwarfarestructure:gate_proxy_tile",msb:3513461500161442935L,render:1b}}
:enddata
:endrule

rule:
plugin=blockTile
number=45
data:
JSON:{blockState:{blockName:"ancientwarfarestructure:gate_proxy"},teData:{lsb:-9117094087824269761L,id:"ancientwarfarestructure:gate_proxy_tile",msb:3513461500161442935L,render:1b}}
:enddata
:endrule

rule:
plugin=blockTile
number=46
data:
JSON:{blockState:{blockName:"ancientwarfarestructure:gate_proxy"},teData:{lsb:-9117094087824269761L,id:"ancientwarfarestructure:gate_proxy_tile",msb:3513461500161442935L,render:1b}}
:enddata
:endrule

rule:
plugin=vanillaBlocks
number=47
data:
JSON:{blockState:{blockName:"quark:bark_oak_stairs",properties:{half:"top",shape:"straight",facing:"north"}}}
:enddata
:endrule

rule:
plugin=vanillaBlocks
number=48
data:
JSON:{blockState:{blockName:"quark:vertical_planks",properties:{variant:"vertical_oak_planks"}}}
:enddata
:endrule

rule:
plugin=vanillaBlocks
number=49
data:
JSON:{blockState:{blockName:"quark:basalt",properties:{variant:"stone_basalt"}}}
:enddata
:endrule

rule:
plugin=vanillaBlocks
number=50
data:
