# Ancient Warfare Structure Template File
# Auto-generated structure template file. created on: 12/11/2023 at: 23:59:54
# Lines beginning with # denote comments

header:
version=2.11
name=NoggFarmMaple_pamsharvestcraft
mods=harvestcraft
size=38,15,18
offset=20,5,9
:endheader

#### VALIDATION ####
validation:
type=ground
structureAuthor=TheOddlySeagull
survival=false
worldGenEnabled=true
unique=false
preserveBlocks=false
preventNaturalHostileSpawns=true
selectionWeight=70
clusterValue=30
minDuplicateDistance=600
dimensionWhiteList=true
dimensionList=0
biomeGroupList=nogg
biomeWhiteList=true
biomeList=minecraft:birch_forest,minecraft:birch_forest_hills
leveling=10
fill=10
border=5
blockSwap=false
territoryName=nogg
biomeReplacement=minecraft:
minGenerationHeight=0
maxGenerationHeight=0
:endvalidation

#### LAYERS ####
layer: 0
1,1,1,1,1,1,1,1,1,1,1,1,1,1,1,1,1,1,1,1,1,1,1,1,1,1,1,1,1,1,1,1,1,1,1,1,1,1
1,1,1,1,1,1,1,1,1,1,1,1,1,1,1,1,1,1,1,1,1,1,1,1,1,1,1,1,1,1,1,1,1,1,1,1,1,1
1,1,1,1,1,1,1,1,1,1,1,1,1,1,1,1,1,1,1,1,1,1,1,1,1,1,1,1,1,1,1,1,1,1,1,1,1,1
1,1,1,1,1,1,1,1,1,1,1,1,1,1,1,1,1,1,1,1,1,1,1,1,1,1,1,1,1,1,1,1,1,1,1,1,1,1
1,1,1,1,1,1,1,1,1,1,1,1,1,1,1,1,1,1,1,1,1,1,1,1,1,1,1,1,1,1,1,1,1,1,1,1,1,1
1,1,1,1,1,1,1,1,1,1,1,1,1,1,1,1,1,1,1,1,1,1,1,1,1,1,1,1,1,1,1,1,1,1,1,1,1,1
1,1,1,1,1,1,1,1,1,1,1,1,1,1,1,1,1,1,1,1,1,1,1,1,1,1,1,1,1,1,1,1,1,1,1,1,1,1
1,1,1,1,1,1,1,1,1,1,1,1,1,1,1,1,1,1,1,1,1,1,1,1,1,1,1,1,1,1,1,1,1,1,1,1,1,1
1,1,1,1,1,1,1,1,1,1,1,1,1,1,1,1,1,1,1,1,1,1,1,1,1,1,1,1,1,1,1,1,1,1,1,1,1,1
1,1,1,1,1,1,1,1,1,1,1,1,1,1,1,1,1,1,1,1,1,1,1,1,1,1,1,1,1,1,1,1,1,1,1,1,1,1
1,1,1,1,1,1,1,1,1,1,1,1,1,1,1,1,1,1,1,1,1,1,1,1,1,1,1,1,1,1,1,1,1,1,1,1,1,1
1,1,1,1,1,1,1,1,1,1,1,1,1,1,1,1,1,1,1,1,1,1,1,1,1,1,1,1,1,1,1,1,1,1,1,1,1,1
1,1,1,1,1,1,1,1,1,1,1,1,1,1,1,1,1,1,1,1,1,1,1,1,1,1,1,1,1,1,1,1,1,1,1,1,1,1
1,1,1,1,1,1,1,1,1,1,1,1,1,1,1,1,1,1,1,1,1,1,1,1,1,1,1,1,1,1,1,1,1,1,1,1,1,1
1,1,1,1,1,1,1,1,1,1,1,1,1,1,1,1,1,1,1,1,1,1,1,1,1,1,1,1,1,1,1,1,1,1,1,1,1,1
1,1,1,1,1,1,1,1,1,1,1,1,1,1,1,1,1,1,1,1,1,1,1,1,1,1,1,1,1,1,1,1,1,1,1,1,1,1
1,1,1,1,1,1,1,1,1,1,1,1,1,1,1,1,1,1,1,1,1,1,1,1,1,1,1,1,1,1,1,1,1,1,1,1,1,1
1,1,1,1,1,1,1,1,1,1,1,1,1,1,1,1,1,1,1,1,1,1,1,1,1,1,1,1,1,1,1,1,1,1,1,1,1,1
:endlayer
layer: 1
1,1,1,1,1,1,1,1,1,1,1,1,1,1,1,1,1,1,1,1,1,1,1,1,1,1,1,1,1,1,1,1,1,1,1,1,1,1
1,1,1,1,1,1,1,1,1,1,1,1,1,1,1,1,1,1,1,1,1,1,1,1,1,1,1,1,1,1,1,1,1,1,1,1,1,1
1,1,1,1,1,1,1,1,1,1,1,1,1,1,1,1,1,1,1,1,1,1,1,1,1,1,1,1,1,1,1,1,1,1,1,1,1,1
1,1,1,1,1,1,1,1,1,1,1,1,1,1,1,1,1,1,1,1,1,1,1,1,1,1,1,1,1,1,1,1,1,1,1,1,1,1
1,1,1,1,1,1,1,1,1,1,1,1,1,1,1,1,1,1,1,1,1,1,1,1,1,1,1,1,1,1,1,1,1,1,1,1,1,1
1,1,1,1,1,1,1,1,1,1,1,1,1,1,1,1,1,1,1,1,1,1,1,1,1,1,1,1,1,1,1,1,1,1,1,1,1,1
1,1,1,1,1,1,1,1,1,1,1,1,1,1,1,1,1,1,1,1,1,1,1,1,1,1,1,1,1,1,1,1,1,1,1,1,1,1
1,1,1,1,1,1,1,1,1,1,1,1,1,1,1,1,1,1,1,1,1,1,1,1,1,1,1,1,1,1,1,1,1,1,1,1,1,1
1,1,1,1,1,1,1,1,1,1,1,1,1,1,1,1,1,1,1,1,1,1,1,1,1,1,1,1,1,1,1,1,1,1,1,1,1,1
1,1,1,1,1,1,1,1,1,1,1,1,1,1,1,1,1,1,1,1,1,1,1,1,1,1,1,1,1,1,1,1,1,1,1,1,1,1
1,1,1,1,1,1,1,1,1,1,1,1,1,1,1,1,1,1,1,1,1,1,1,1,1,1,1,1,1,1,1,1,1,1,1,1,1,1
1,1,1,1,1,1,1,1,1,1,1,1,1,1,1,1,1,1,1,1,1,1,1,1,1,1,1,1,1,1,1,1,1,1,1,1,1,1
1,1,1,1,1,1,1,1,1,1,1,1,1,1,1,1,1,1,1,1,1,1,1,1,1,1,1,1,1,1,1,1,1,1,1,1,1,1
1,1,1,1,1,1,1,1,1,1,1,1,1,1,1,1,1,1,1,1,1,1,1,1,1,1,1,1,1,1,1,1,1,1,1,1,1,1
1,1,1,1,1,1,1,1,1,1,1,1,1,1,1,1,1,1,1,1,1,1,1,1,1,1,1,1,1,1,1,1,1,1,1,1,1,1
1,1,1,1,1,1,1,1,1,1,1,1,1,1,1,1,1,1,1,1,1,1,1,1,1,1,1,1,1,1,1,1,1,1,1,1,1,1
1,1,1,1,1,1,1,1,1,1,1,1,1,1,1,1,1,1,1,1,1,1,1,1,1,1,1,1,1,1,1,1,1,1,1,1,1,1
1,1,1,1,1,1,1,1,1,1,1,1,1,1,1,1,1,1,1,1,1,1,1,1,1,1,1,1,1,1,1,1,1,1,1,1,1,1
:endlayer
layer: 2
1,1,1,1,1,1,1,1,1,1,1,1,1,1,1,1,1,1,1,1,1,1,1,1,1,1,1,1,1,1,1,1,1,1,1,1,1,1
1,1,1,1,1,1,1,1,1,1,1,1,1,1,1,1,1,1,1,1,1,1,1,1,1,1,1,1,1,1,1,1,1,1,1,1,1,1
1,1,1,1,1,1,1,1,1,1,1,1,1,1,1,1,1,1,1,1,1,1,1,1,1,1,1,1,1,1,1,1,1,1,1,1,1,1
1,1,1,1,1,1,1,1,1,1,1,1,1,1,1,1,1,1,1,1,1,1,1,1,1,1,1,1,1,1,1,1,1,1,1,1,1,1
1,1,1,1,1,1,1,1,1,1,1,1,1,1,1,1,1,1,1,1,1,1,1,1,1,1,1,1,1,1,1,1,1,1,1,1,1,1
1,1,1,1,1,1,1,1,1,1,1,1,1,1,1,1,1,1,1,1,1,1,1,1,1,1,1,1,1,1,1,1,1,1,1,1,1,1
1,1,1,1,1,1,1,1,1,1,1,1,1,1,1,1,1,1,1,1,1,1,1,1,1,1,1,1,1,1,1,1,1,1,1,1,1,1
1,1,1,1,1,1,1,1,1,1,1,1,1,1,1,1,1,1,1,1,1,1,1,1,1,1,1,1,1,1,1,1,1,1,1,1,1,1
1,1,1,1,1,1,1,1,1,1,1,1,1,1,1,1,1,1,1,1,1,1,1,1,1,1,1,1,1,1,1,1,1,1,1,1,1,1
1,1,1,1,1,1,1,1,1,1,1,1,1,1,1,1,1,1,1,1,1,1,1,1,1,1,1,1,1,1,1,1,1,1,1,1,1,1
1,1,1,1,1,1,1,1,1,1,1,1,1,1,1,1,1,1,1,1,1,1,1,1,1,1,1,1,1,1,1,1,1,1,1,1,1,1
1,1,1,1,1,1,1,1,1,1,1,1,1,1,1,1,1,1,1,1,1,1,1,1,1,1,1,1,1,1,1,1,1,1,1,1,1,1
1,1,1,1,1,1,1,1,1,1,1,1,1,1,1,1,1,1,1,1,1,1,1,1,1,1,1,1,1,1,1,1,1,1,1,1,1,1
1,1,1,1,1,1,1,1,1,1,1,1,1,1,1,1,1,1,1,1,1,1,1,1,1,1,1,1,1,1,1,1,1,1,1,1,1,1
1,1,1,1,1,1,1,1,1,1,1,1,1,1,1,1,1,1,1,1,1,1,1,1,1,1,1,1,1,1,1,1,1,1,1,1,1,1
1,1,1,1,1,1,1,1,1,1,1,1,1,1,1,1,1,1,1,1,1,1,1,1,1,1,1,1,1,1,1,1,1,1,1,1,1,1
1,1,1,1,1,1,1,1,1,1,1,1,1,1,1,1,1,1,1,1,1,1,1,1,1,1,1,1,1,1,1,1,1,1,1,1,1,1
1,1,1,1,1,1,1,1,1,1,1,1,1,1,1,1,1,1,1,1,1,1,1,1,1,1,1,1,1,1,1,1,1,1,1,1,1,1
:endlayer
layer: 3
2,2,2,2,2,2,2,2,2,2,2,2,2,2,2,2,2,2,2,2,2,2,2,2,2,2,2,2,2,2,2,2,2,2,2,2,2,2
2,2,2,2,2,2,2,2,2,2,2,2,2,2,2,2,2,2,2,2,2,2,2,2,2,2,2,2,2,2,2,2,2,2,2,2,2,2
2,2,2,2,2,2,2,2,2,2,2,2,2,2,2,2,2,2,2,2,2,2,2,2,2,2,2,2,2,2,2,2,2,2,2,2,2,2
2,2,2,2,2,2,2,2,2,2,2,2,2,2,2,2,2,2,2,2,2,2,2,2,2,2,2,2,2,2,2,2,2,2,2,2,2,2
2,2,2,2,2,2,2,2,2,2,2,2,2,2,2,2,2,2,2,2,2,2,2,2,2,2,2,2,2,2,2,2,2,2,2,2,2,2
2,2,2,2,2,2,2,2,2,2,2,2,2,2,2,2,2,2,2,2,2,2,2,2,2,2,2,2,2,2,2,2,2,2,2,2,2,2
2,2,2,2,2,2,2,2,2,2,2,2,2,2,2,2,2,2,2,2,2,2,2,2,2,2,2,2,2,2,2,2,2,2,2,2,2,2
2,2,2,2,2,2,2,2,2,2,2,2,2,2,2,2,2,2,2,2,2,2,2,2,2,2,2,2,2,2,2,2,2,2,2,2,2,2
2,2,2,2,2,2,2,2,2,2,2,2,2,2,2,2,2,2,2,2,2,2,2,2,2,2,2,2,2,2,2,2,2,2,2,2,2,2
2,2,2,2,2,2,2,2,2,2,2,2,2,2,2,2,2,2,2,2,2,2,2,2,2,2,2,2,2,2,2,2,2,2,2,2,2,2
2,2,2,2,2,2,2,2,2,2,2,2,2,2,2,2,2,2,2,2,2,2,2,2,2,2,2,2,2,2,2,2,2,2,2,2,2,2
2,2,2,2,2,2,2,2,2,2,2,2,2,2,2,2,2,2,2,2,2,2,2,2,2,2,2,2,2,2,2,2,2,2,2,2,2,2
2,2,2,2,2,2,2,2,2,2,2,2,2,2,2,2,2,2,2,2,2,2,2,2,2,2,2,2,2,2,2,2,2,2,2,2,2,2
2,2,2,2,2,2,2,2,2,2,2,2,2,2,2,2,2,2,2,2,2,2,2,2,2,2,2,2,2,2,2,2,2,2,2,2,2,2
2,2,2,2,2,2,2,2,2,2,2,2,2,2,2,2,2,2,2,2,2,2,2,2,2,2,2,2,2,2,2,2,2,2,2,2,2,2
2,2,2,2,2,2,2,2,2,2,2,2,2,2,2,2,2,2,2,2,2,2,2,2,2,2,2,2,2,2,2,2,2,2,2,2,2,2
2,2,2,2,2,2,2,2,2,2,2,2,2,2,2,2,2,2,2,2,2,2,2,2,2,2,2,2,2,2,2,2,2,2,2,2,2,2
2,2,2,2,2,2,2,2,2,2,2,2,2,2,2,2,2,2,2,2,2,2,2,2,2,2,2,2,2,2,2,2,2,2,2,2,2,2
:endlayer
layer: 4
3,3,3,3,3,3,3,3,3,3,3,3,3,3,3,3,3,3,3,4,4,4,3,3,3,3,3,3,3,3,3,3,3,3,3,3,3,3
3,3,3,3,3,3,3,3,3,3,3,3,3,3,3,3,3,3,3,4,4,4,3,5,3,3,3,3,3,3,3,3,3,3,3,3,5,3
3,3,3,3,3,3,5,7,7,5,3,3,9,9,9,3,3,3,3,4,4,4,3,3,3,3,3,3,3,3,3,3,3,3,3,3,3,3
3,3,3,3,3,3,6,8,8,6,3,9,9,9,9,9,3,3,3,4,4,4,3,3,3,2,3,3,3,3,3,2,3,3,3,3,3,3
3,3,3,5,7,7,6,8,8,6,7,5,9,9,9,5,7,5,3,4,4,4,3,3,3,3,3,3,3,3,3,3,3,3,3,3,3,3
3,3,3,6,8,8,5,7,7,5,8,8,9,9,9,8,8,6,3,4,4,4,3,3,3,3,3,3,2,3,3,3,3,3,2,3,3,3
3,3,3,5,8,8,8,8,8,8,8,8,8,8,8,8,8,6,3,4,4,4,3,6,3,3,3,3,3,3,3,3,3,3,3,3,5,3
3,3,3,6,8,8,8,8,8,8,8,8,8,8,8,8,8,5,3,4,4,4,3,3,3,3,3,3,3,3,3,3,3,3,3,3,3,3
3,3,3,6,8,8,8,8,8,8,8,8,8,8,8,8,8,6,3,4,4,4,4,4,4,4,4,4,4,4,4,4,4,4,4,4,4,4
3,3,3,6,8,8,8,8,8,8,8,8,8,8,8,8,8,6,4,4,4,4,4,4,4,4,4,4,4,4,4,4,4,4,4,4,4,4
3,3,3,5,8,8,8,8,8,8,8,8,8,8,8,8,8,6,3,4,4,4,3,3,3,3,3,3,3,3,3,3,3,3,3,3,3,3
3,3,3,6,8,8,8,8,8,8,8,8,8,8,8,8,8,5,3,4,4,4,3,5,3,3,3,3,3,3,3,3,3,3,3,3,5,3
3,3,5,7,7,5,8,8,8,8,8,8,8,8,8,8,8,6,3,4,4,4,3,3,3,3,3,3,2,3,3,3,3,3,2,3,3,3
3,3,6,8,8,6,8,8,8,8,8,8,8,8,8,8,8,6,3,4,4,4,3,3,3,3,3,3,3,3,3,3,3,3,3,3,3,3
3,3,6,8,8,6,7,7,5,7,8,8,8,7,5,7,7,5,3,4,4,4,3,3,3,2,3,3,3,3,3,2,3,3,3,3,3,3
3,3,5,7,7,5,3,3,3,3,7,7,7,3,3,3,3,3,3,4,4,4,3,3,3,3,3,3,3,3,3,3,3,3,3,3,3,3
3,3,3,3,3,3,3,3,3,3,3,4,3,3,3,3,3,3,3,4,4,4,3,5,3,3,3,3,3,3,3,3,3,3,3,3,5,3
3,3,3,3,3,3,3,3,3,3,3,4,3,3,3,3,3,3,3,4,4,4,3,3,3,3,3,3,3,3,3,3,3,3,3,3,3,3
:endlayer
layer: 5
0,13,13,13,13,0,13,13,0,0,13,17,18,13,13,13,0,13,0,0,0,0,0,0,0,0,13,0,0,0,0,13,13,13,13,0,0,0
0,13,13,13,13,13,0,0,0,0,13,13,13,13,0,13,13,27,13,0,0,0,13,5,12,12,12,12,12,12,12,12,12,12,12,12,5,0
0,13,13,13,13,27,5,28,28,5,13,35,9,41,9,35,17,13,13,0,0,0,17,12,0,13,13,13,13,0,13,0,13,16,13,13,12,0
13,13,13,0,13,0,60,58,58,56,13,9,9,9,9,9,13,0,0,0,0,0,13,12,13,15,13,0,13,13,0,15,13,0,13,0,12,0
13,27,18,5,31,31,28,59,59,28,31,5,9,42,9,5,31,5,0,0,0,0,13,12,13,13,13,13,13,13,0,19,18,13,13,0,12,0
13,27,13,60,65,63,5,37,37,5,55,51,40,43,40,36,32,28,0,0,0,0,13,12,13,13,13,0,15,13,20,13,13,13,15,13,12,0
13,13,13,5,0,0,0,0,0,0,0,0,0,0,0,0,32,28,13,0,0,0,0,5,13,13,13,13,0,13,13,13,13,13,13,14,5,0
13,0,0,29,62,0,0,0,0,0,0,52,47,44,0,0,32,5,0,0,0,0,24,13,13,13,13,13,0,13,21,13,13,13,13,0,0,10
13,13,0,29,66,64,61,0,0,0,0,45,45,45,0,0,0,29,26,0,0,0,0,0,0,0,0,0,0,0,0,0,0,0,0,0,0,0
18,13,13,29,66,64,61,0,0,0,0,45,45,45,0,0,0,30,0,0,0,0,0,0,0,0,0,0,0,0,0,0,0,0,0,0,0,0
13,13,13,5,0,0,0,0,0,0,0,53,48,46,0,0,0,29,0,0,0,0,25,19,0,0,0,13,13,13,13,0,18,13,13,0,0,11
0,13,13,60,0,0,0,37,37,0,0,0,0,0,37,37,0,5,0,0,0,0,0,5,13,0,13,0,13,13,13,13,13,13,13,0,5,0
0,0,5,28,0,5,0,38,38,57,0,0,0,0,38,38,33,28,0,0,0,0,0,12,13,13,13,13,15,13,22,13,13,13,15,13,12,0
0,0,28,67,0,28,62,39,39,45,0,0,0,0,39,39,34,28,13,0,0,0,0,12,13,13,13,13,13,13,13,13,13,17,16,0,12,0
0,0,28,68,0,28,28,28,5,29,0,0,0,29,5,28,28,5,0,0,0,0,13,12,13,15,23,13,13,13,13,15,13,0,0,13,12,0
13,0,5,28,28,5,13,0,0,12,49,54,49,12,13,13,18,13,13,0,0,0,17,12,0,13,13,18,0,13,13,13,0,0,13,0,12,0
13,13,13,13,0,18,13,13,13,13,13,0,50,13,13,16,13,13,13,0,0,0,13,5,12,12,12,12,12,12,12,12,12,12,12,12,5,0
13,13,13,13,0,0,13,13,13,13,0,0,13,13,0,0,13,13,13,0,0,0,17,0,0,13,0,0,13,13,13,13,13,0,0,0,0,0
:endlayer
layer: 6
0,0,0,0,0,0,0,0,0,0,0,0,0,0,0,0,0,0,0,0,0,0,0,0,0,0,0,0,0,0,0,0,0,0,0,0,0,0
0,0,0,0,0,0,0,0,0,0,0,0,0,0,0,0,0,0,0,0,0,0,0,69,0,0,70,0,0,0,0,0,0,70,0,0,69,0
0,0,0,0,0,0,5,71,71,5,0,0,41,0,41,0,0,0,0,0,0,0,0,0,0,0,0,0,0,0,0,0,0,0,0,0,0,0
0,0,0,0,0,0,60,0,0,56,0,78,9,9,9,73,0,0,0,0,0,0,0,0,0,15,0,0,0,0,0,15,0,0,0,0,0,0
0,0,0,5,31,31,28,0,0,28,31,5,9,0,9,5,31,5,0,0,0,0,0,70,0,0,0,0,0,0,0,0,0,0,0,0,70,0
0,0,0,60,83,82,5,0,0,5,0,0,35,0,35,0,0,71,0,0,0,0,0,0,0,0,0,0,15,0,0,0,0,0,15,0,0,0
0,0,0,5,0,0,0,0,0,0,0,0,0,0,0,0,0,71,0,0,0,0,0,69,0,0,0,0,0,0,0,0,0,0,0,0,69,0
0,0,0,29,0,0,0,0,0,0,0,79,76,74,0,0,0,5,0,0,0,0,0,0,0,0,0,0,0,0,0,0,0,0,0,0,0,0
0,0,0,71,0,0,0,0,0,0,0,0,0,0,0,0,0,29,0,0,0,0,0,0,0,0,0,0,0,0,0,0,0,0,0,0,0,0
0,0,0,29,0,0,0,0,0,0,0,0,0,0,0,0,0,72,0,0,0,0,0,0,0,0,0,0,0,0,0,0,0,0,0,0,0,0
0,0,0,5,0,0,0,0,0,0,0,80,77,75,0,0,0,29,0,0,0,0,0,0,0,0,0,0,0,0,0,0,0,0,0,0,0,0
0,0,0,60,0,0,0,0,0,0,0,0,0,0,0,0,0,5,0,0,0,0,0,69,0,0,0,0,0,0,0,0,0,0,0,0,69,0
0,0,5,28,0,5,0,0,0,0,0,0,0,0,0,0,0,71,0,0,0,0,0,0,0,0,0,0,15,0,0,0,0,0,15,0,0,0
0,0,71,84,0,28,0,0,0,0,0,0,0,0,0,0,0,71,0,0,0,0,0,70,0,0,0,0,0,0,0,0,0,0,0,0,70,0
0,0,71,85,0,28,71,71,5,29,0,0,0,29,5,71,71,5,0,0,0,0,0,0,0,15,0,0,0,0,0,15,0,0,0,0,0,0
0,0,5,71,71,5,0,0,0,12,49,81,49,12,0,0,0,0,0,0,0,0,0,0,0,0,0,0,0,0,0,0,0,0,0,0,0,0
0,0,0,0,0,0,0,0,0,0,0,0,0,0,0,0,0,0,0,0,0,0,0,69,0,0,0,70,0,0,0,0,0,70,0,0,69,0
0,0,0,0,0,0,0,0,0,0,0,0,0,0,0,0,0,0,0,0,0,0,0,0,0,0,0,0,0,0,0,0,0,0,0,0,0,0
:endlayer
layer: 7
0,0,0,0,0,0,0,0,0,0,0,0,0,0,0,0,0,0,0,0,0,0,0,0,0,0,0,0,0,0,0,0,0,0,0,0,0,0
0,0,0,0,0,0,89,0,0,89,0,0,0,0,0,0,0,0,0,0,0,0,0,0,0,0,0,0,0,0,0,0,0,0,0,0,0,0
0,0,0,0,0,93,5,71,71,5,88,0,35,0,35,0,0,0,0,0,0,0,0,0,0,0,0,0,0,0,0,0,0,0,0,0,0,0
0,0,0,89,0,0,60,0,0,56,0,89,9,9,9,89,0,89,0,0,0,0,0,0,0,15,0,86,86,86,86,15,0,0,0,0,0,0
0,0,93,5,31,31,28,0,0,28,31,5,9,91,9,5,31,5,88,0,0,0,0,0,0,0,86,86,86,86,86,0,0,0,0,0,0,0
0,0,0,60,95,94,5,0,0,5,0,0,40,92,40,0,0,71,0,0,0,0,0,0,0,0,86,86,87,86,86,0,0,0,15,0,0,0
0,0,93,5,0,0,0,0,0,0,0,0,0,0,0,0,0,71,0,0,0,0,0,0,0,0,86,86,86,86,86,0,0,0,0,0,0,0
0,0,0,29,0,0,0,0,0,0,0,0,0,0,0,0,0,5,88,0,0,0,0,0,0,0,0,86,86,86,86,0,0,0,0,0,0,0
0,0,0,71,0,0,0,0,0,0,0,0,0,0,0,0,0,29,0,0,0,0,0,0,0,0,0,0,0,0,0,0,0,0,0,0,0,0
0,0,0,29,0,0,0,0,0,0,0,0,0,0,0,0,0,29,0,0,0,0,0,0,0,0,0,0,0,0,0,0,0,0,0,0,0,0
0,0,93,5,0,0,0,0,0,0,0,0,0,0,0,0,0,29,0,0,0,0,0,0,0,0,86,86,86,86,86,0,0,0,0,0,0,0
0,0,89,60,0,0,0,0,0,0,0,0,0,0,0,0,0,5,88,0,0,0,0,0,0,0,86,86,86,86,86,0,0,0,0,0,0,0
0,93,5,28,28,5,0,0,0,0,0,0,0,0,0,0,0,71,0,0,0,0,0,0,86,86,86,86,87,86,86,0,0,0,15,0,0,0
0,0,71,96,0,28,0,0,0,0,0,0,0,0,0,0,0,71,0,0,0,0,0,86,86,86,86,86,86,86,86,0,0,0,0,0,0,0
0,0,71,97,0,28,71,71,5,29,0,0,0,29,5,71,71,5,88,0,0,0,0,86,86,87,86,86,86,86,0,15,0,0,0,0,0,0
0,93,5,71,71,5,88,0,90,12,49,49,49,12,90,0,0,90,0,0,0,0,0,86,86,86,86,86,0,0,0,0,0,0,0,0,0,0
0,0,90,0,0,90,0,0,0,0,0,0,0,0,0,0,0,0,0,0,0,0,0,0,86,86,86,86,0,0,0,0,0,0,0,0,0,0
0,0,0,0,0,0,0,0,0,0,0,0,0,0,0,0,0,0,0,0,0,0,0,0,0,0,0,0,0,0,0,0,0,0,0,0,0,0
:endlayer
layer: 8
0,0,0,0,0,0,0,0,0,0,0,0,0,0,0,0,0,0,0,0,0,0,0,0,0,0,0,0,0,0,0,0,0,0,0,0,0,0
0,0,0,0,0,0,0,0,0,0,0,0,0,0,0,0,0,0,0,0,0,0,0,0,0,0,0,0,0,0,0,0,0,0,0,0,0,0
0,0,0,0,0,0,5,7,7,5,0,0,43,43,43,0,0,0,0,0,0,0,0,0,0,0,0,0,0,0,0,0,0,0,0,0,0,0
0,0,98,98,98,98,6,0,0,6,98,98,9,9,9,98,98,98,98,0,0,0,0,0,0,15,0,86,86,86,86,15,86,86,86,86,86,0
0,0,0,5,7,7,6,0,0,6,7,7,7,7,7,7,7,5,0,0,0,0,0,0,0,0,86,86,86,86,86,0,86,86,86,86,86,0
0,0,0,6,102,101,5,7,7,5,88,90,0,0,0,90,0,6,0,0,0,0,0,0,0,0,86,86,87,86,86,0,86,86,87,86,86,0
0,0,69,6,88,0,90,0,0,90,0,0,0,0,0,0,0,6,0,0,0,0,0,0,0,0,86,86,86,86,86,0,86,86,86,86,86,0
0,0,98,6,0,0,0,0,0,0,0,0,0,0,0,0,93,6,69,0,0,0,0,0,0,0,0,86,86,86,0,0,86,86,86,86,86,0
0,0,0,6,0,0,0,0,0,0,0,0,0,0,0,0,0,6,98,0,0,0,0,0,0,0,0,0,0,0,0,0,0,0,0,0,0,0
0,0,98,6,0,0,0,0,0,0,0,0,0,0,0,0,0,6,0,0,0,0,0,0,0,0,0,0,0,0,0,0,0,0,0,0,0,0
0,0,69,6,88,0,0,0,0,0,0,0,0,0,0,0,0,6,98,0,0,0,0,0,0,0,86,86,86,86,0,0,86,86,86,86,86,0
0,0,0,6,0,89,0,0,0,0,0,0,0,0,0,0,93,6,69,0,0,0,0,0,0,0,86,86,86,86,86,0,86,86,86,86,86,0
0,0,5,7,7,5,88,0,0,0,0,0,0,0,0,0,0,6,0,0,0,0,0,0,86,86,86,86,87,86,86,86,86,86,87,86,86,0
0,0,6,103,0,6,0,0,89,0,0,0,0,0,89,0,0,6,0,0,0,0,0,86,86,86,86,86,86,86,86,86,86,86,86,86,86,0
0,0,6,104,0,6,7,7,7,7,99,89,100,7,7,7,7,5,0,0,0,0,0,86,86,87,86,86,86,86,86,87,86,86,86,86,0,0
0,0,5,7,7,5,98,98,98,100,7,7,7,99,98,98,98,98,98,0,0,0,0,86,86,86,86,86,0,86,86,86,86,86,0,0,0,0
0,0,0,0,0,0,0,0,0,0,0,0,0,0,0,0,0,0,0,0,0,0,0,0,86,86,86,0,0,86,86,86,86,0,0,0,0,0
0,0,0,0,0,0,0,0,0,0,0,0,0,0,0,0,0,0,0,0,0,0,0,0,0,0,0,0,0,0,0,0,0,0,0,0,0,0
:endlayer
layer: 9
0,0,0,0,0,0,0,0,0,0,0,0,0,0,0,0,0,0,0,0,0,0,0,0,0,0,0,0,0,0,0,0,0,0,0,0,0,0
0,0,0,0,0,0,0,0,0,0,0,0,0,0,0,0,0,0,0,0,0,0,0,0,86,86,86,86,0,86,86,86,86,0,0,0,0,0
0,0,0,0,0,0,5,71,71,5,0,0,0,0,0,0,0,0,0,0,0,0,0,86,86,86,86,86,0,86,86,86,86,86,0,0,0,0
0,0,0,0,0,0,28,0,0,28,0,0,78,9,73,0,0,0,0,0,0,0,0,86,86,87,86,86,0,86,86,87,86,86,86,86,0,0
0,0,69,69,69,69,28,0,0,28,69,69,69,69,69,69,69,69,69,0,0,0,0,86,86,86,86,86,86,86,86,86,86,86,86,86,86,0
0,0,98,28,98,98,5,28,28,5,98,98,98,98,98,98,98,28,98,0,0,0,0,86,86,86,86,86,87,86,86,86,86,86,87,86,86,0
0,0,0,28,0,0,0,0,0,0,0,0,0,0,0,0,0,28,0,0,0,0,0,0,0,0,0,0,86,0,0,0,86,86,86,86,86,0
0,0,0,28,0,0,0,0,0,0,0,0,0,0,0,0,0,28,0,0,0,0,0,0,0,0,0,0,0,0,0,0,0,86,86,86,0,0
0,0,69,28,0,0,0,0,0,0,0,0,0,0,0,0,0,28,0,0,0,0,0,0,0,0,0,0,0,0,0,0,0,0,0,0,0,0
0,0,0,28,0,0,0,0,0,0,0,0,0,0,0,0,0,28,69,0,0,0,0,0,0,0,0,0,0,0,0,0,0,0,0,0,0,0
0,0,0,28,0,0,0,0,0,0,0,0,0,0,0,0,0,28,0,0,0,0,0,0,0,0,0,0,0,0,0,0,0,86,86,86,86,0
0,0,0,28,0,0,0,0,0,0,0,0,0,0,0,0,0,28,0,0,0,0,0,0,0,0,0,86,86,86,0,0,86,86,86,86,86,0
0,0,5,28,28,5,0,0,0,0,0,0,0,0,0,0,0,28,0,0,0,0,0,0,0,0,0,86,87,86,86,86,86,86,87,86,86,0
0,0,28,105,0,28,98,98,98,98,98,98,98,98,98,98,98,28,98,0,0,0,0,0,0,86,86,86,86,86,86,86,86,86,86,86,86,0
0,0,28,106,0,28,69,69,69,69,28,28,28,69,69,69,69,69,69,0,0,0,0,0,86,87,86,0,0,86,86,87,86,86,86,86,86,0
0,0,5,28,28,5,0,0,0,69,28,28,28,69,0,0,0,0,0,0,0,0,0,0,0,86,0,0,0,86,86,86,86,86,0,0,0,0
0,0,0,0,0,0,0,0,0,69,98,0,98,69,0,0,0,0,0,0,0,0,0,0,0,0,0,0,0,86,86,86,86,0,0,0,0,0
0,0,0,0,0,0,0,0,0,0,0,0,0,0,0,0,0,0,0,0,0,0,0,0,0,0,0,0,0,0,0,0,0,0,0,0,0,0
:endlayer
layer: 10
0,0,0,0,0,0,0,0,0,0,0,0,0,0,0,0,0,0,0,0,0,0,0,0,0,0,0,0,0,0,0,0,0,0,0,0,0,0
0,0,0,0,0,0,98,0,0,98,0,0,0,0,0,0,0,0,0,0,0,0,0,0,86,86,86,0,0,86,86,86,86,86,0,0,0,0
0,0,0,0,0,98,5,7,7,5,98,0,0,0,0,0,0,0,0,0,0,0,0,86,86,86,86,86,0,86,86,86,86,86,0,0,0,0
0,0,0,0,0,0,6,90,90,6,0,0,0,9,0,0,0,0,0,0,0,0,0,86,86,87,86,86,0,86,86,87,86,86,0,0,0,0
0,0,0,0,0,0,6,89,89,6,0,0,0,0,0,0,0,0,0,0,0,0,0,86,86,86,86,86,86,86,86,86,86,86,86,86,0,0
0,0,0,0,0,98,5,7,7,5,98,0,0,0,0,0,0,0,0,0,0,0,0,86,86,86,86,86,86,86,86,86,86,86,87,86,0,0
0,0,69,69,69,69,28,28,28,28,69,69,69,69,69,69,69,69,69,0,0,0,0,0,0,0,0,0,86,0,0,0,0,0,86,86,0,0
0,0,98,28,98,98,98,98,98,98,98,98,98,98,98,98,98,28,98,0,0,0,0,0,0,0,0,0,0,0,0,0,0,0,0,0,0,0
0,0,0,28,0,0,0,0,0,0,0,0,0,0,0,0,0,28,0,0,0,0,0,0,0,0,0,0,0,0,0,0,0,0,0,0,0,0
0,0,0,28,88,0,0,0,0,0,0,0,0,0,0,0,93,28,0,0,0,0,0,0,0,0,0,0,0,0,0,0,0,0,0,0,0,0
0,0,0,28,0,0,0,0,0,0,0,0,0,0,0,0,0,28,0,0,0,0,0,0,0,0,0,0,0,0,0,0,0,0,0,0,0,0
0,0,98,28,98,98,98,98,98,98,98,98,98,98,98,98,98,28,98,0,0,0,0,0,0,0,0,0,86,0,0,0,0,0,86,86,0,0
0,0,5,28,28,5,69,69,69,69,69,69,69,69,69,69,69,69,69,0,0,0,0,0,0,0,0,86,86,86,0,0,0,86,87,86,0,0
0,0,71,0,0,71,0,0,0,0,0,69,0,0,0,0,0,0,0,0,0,0,0,0,0,86,0,0,86,0,0,86,0,0,86,0,0,0
0,0,71,0,0,71,0,0,0,0,0,69,0,0,0,0,0,0,0,0,0,0,0,0,86,86,86,0,0,0,86,87,86,0,0,0,0,0
0,0,5,71,71,5,0,0,0,0,0,69,0,0,0,0,0,0,0,0,0,0,0,0,0,86,0,0,0,0,0,86,0,0,0,0,0,0
0,0,0,0,0,0,0,0,0,0,0,69,0,0,0,0,0,0,0,0,0,0,0,0,0,0,0,0,0,0,0,0,0,0,0,0,0,0
0,0,0,0,0,0,0,0,0,0,0,0,0,0,0,0,0,0,0,0,0,0,0,0,0,0,0,0,0,0,0,0,0,0,0,0,0,0
:endlayer
layer: 11
0,0,0,0,0,0,0,0,0,0,0,0,0,0,0,0,0,0,0,0,0,0,0,0,0,0,0,0,0,0,0,0,0,0,0,0,0,0
0,0,0,0,0,0,0,69,69,0,0,0,0,0,0,0,0,0,0,0,0,0,0,0,0,0,0,0,0,0,0,0,0,0,0,0,0,0
0,0,0,0,0,0,69,28,28,69,0,0,0,0,0,0,0,0,0,0,0,0,0,0,86,86,86,0,0,0,86,86,86,0,0,0,0,0
0,0,0,0,0,69,28,28,28,28,69,0,0,9,0,0,0,0,0,0,0,0,0,0,86,87,86,0,0,0,86,87,86,0,0,0,0,0
0,0,0,0,0,69,28,28,28,28,69,0,0,0,0,0,0,0,0,0,0,0,0,0,86,86,0,0,0,0,86,86,86,0,86,0,0,0
0,0,0,0,0,0,69,28,28,69,0,0,0,0,0,0,0,0,0,0,0,0,0,0,0,0,0,0,0,0,0,0,0,86,86,86,0,0
0,0,0,0,0,0,0,69,69,0,0,0,0,0,0,0,0,0,0,0,0,0,0,0,0,0,0,0,0,0,0,0,0,0,86,0,0,0
0,0,0,0,0,0,0,0,0,0,0,0,0,0,0,0,0,0,0,0,0,0,0,0,0,0,0,0,0,0,0,0,0,0,0,0,0,0
0,0,69,69,69,69,69,69,69,69,69,69,69,69,69,69,69,69,69,0,0,0,0,0,0,0,0,0,0,0,0,0,0,0,0,0,0,0
0,0,98,28,98,98,98,98,98,98,98,98,98,98,98,98,98,28,98,0,0,0,0,0,0,0,0,0,0,0,0,0,0,0,0,0,0,0
0,0,69,69,69,69,69,69,69,69,69,69,69,69,69,69,69,69,69,0,0,0,0,0,0,0,0,0,0,0,0,0,0,0,0,0,0,0
0,0,0,0,0,0,0,0,0,0,0,0,0,0,0,0,0,0,0,0,0,0,0,0,0,0,0,0,0,0,0,0,0,0,86,0,0,0
0,0,5,28,28,5,0,0,0,0,0,0,0,0,0,0,0,0,0,0,0,0,0,0,0,0,0,0,0,0,0,0,0,86,86,86,0,0
0,0,71,0,0,71,0,0,0,0,0,0,0,0,0,0,0,0,0,0,0,0,0,0,0,0,0,0,0,0,0,86,0,0,86,0,0,0
0,0,71,0,0,71,0,0,0,0,0,0,0,0,0,0,0,0,0,0,0,0,0,0,0,0,0,0,0,0,86,86,86,0,0,0,0,0
0,0,5,71,71,5,0,0,0,0,0,0,0,0,0,0,0,0,0,0,0,0,0,0,0,0,0,0,0,0,0,86,0,0,0,0,0,0
0,0,0,0,0,0,0,0,0,0,0,0,0,0,0,0,0,0,0,0,0,0,0,0,0,0,0,0,0,0,0,0,0,0,0,0,0,0
0,0,0,0,0,0,0,0,0,0,0,0,0,0,0,0,0,0,0,0,0,0,0,0,0,0,0,0,0,0,0,0,0,0,0,0,0,0
:endlayer
layer: 12
0,0,0,0,0,0,0,0,0,0,0,0,0,0,0,0,0,0,0,0,0,0,0,0,0,0,0,0,0,0,0,0,0,0,0,0,0,0
0,0,0,0,0,0,0,0,0,0,0,0,0,0,0,0,0,0,0,0,0,0,0,0,0,0,0,0,0,0,0,0,0,0,0,0,0,0
0,0,0,0,0,0,0,0,0,0,0,0,0,0,0,0,0,0,0,0,0,0,0,0,0,86,0,0,0,0,0,86,0,0,0,0,0,0
0,0,0,0,0,0,0,69,69,0,0,0,0,35,0,0,0,0,0,0,0,0,0,0,86,86,86,0,0,0,86,86,86,0,0,0,0,0
0,0,0,0,0,0,0,69,69,0,0,0,0,0,0,0,0,0,0,0,0,0,0,0,0,86,0,0,0,0,0,86,0,0,0,0,0,0
0,0,0,0,0,0,0,0,0,0,0,0,0,0,0,0,0,0,0,0,0,0,0,0,0,0,0,0,0,0,0,0,0,0,0,0,0,0
0,0,0,0,0,0,0,0,0,0,0,0,0,0,0,0,0,0,0,0,0,0,0,0,0,0,0,0,0,0,0,0,0,0,0,0,0,0
0,0,0,0,0,0,0,0,0,0,0,0,0,0,0,0,0,0,0,0,0,0,0,0,0,0,0,0,0,0,0,0,0,0,0,0,0,0
0,0,0,0,0,0,0,0,0,0,0,0,0,0,0,0,0,0,0,0,0,0,0,0,0,0,0,0,0,0,0,0,0,0,0,0,0,0
0,0,0,0,0,0,0,0,0,0,0,0,0,0,0,0,0,0,0,0,0,0,0,0,0,0,0,0,0,0,0,0,0,0,0,0,0,0
0,0,0,0,0,0,0,0,0,0,0,0,0,0,0,0,0,0,0,0,0,0,0,0,0,0,0,0,0,0,0,0,0,0,0,0,0,0
0,0,98,0,0,98,0,0,0,0,0,0,0,0,0,0,0,0,0,0,0,0,0,0,0,0,0,0,0,0,0,0,0,0,0,0,0,0
0,98,5,7,7,5,98,0,0,0,0,0,0,0,0,0,0,0,0,0,0,0,0,0,0,0,0,0,0,0,0,0,0,0,0,0,0,0
0,0,6,88,93,6,0,0,0,0,0,0,0,0,0,0,0,0,0,0,0,0,0,0,0,0,0,0,0,0,0,0,0,0,0,0,0,0
0,0,6,88,93,6,0,0,0,0,0,0,0,0,0,0,0,0,0,0,0,0,0,0,0,0,0,0,0,0,0,0,0,0,0,0,0,0
0,98,5,7,7,5,98,0,0,0,0,0,0,0,0,0,0,0,0,0,0,0,0,0,0,0,0,0,0,0,0,0,0,0,0,0,0,0
0,0,98,0,0,98,0,0,0,0,0,0,0,0,0,0,0,0,0,0,0,0,0,0,0,0,0,0,0,0,0,0,0,0,0,0,0,0
0,0,0,0,0,0,0,0,0,0,0,0,0,0,0,0,0,0,0,0,0,0,0,0,0,0,0,0,0,0,0,0,0,0,0,0,0,0
:endlayer
layer: 13
0,0,0,0,0,0,0,0,0,0,0,0,0,0,0,0,0,0,0,0,0,0,0,0,0,0,0,0,0,0,0,0,0,0,0,0,0,0
0,0,0,0,0,0,0,0,0,0,0,0,0,0,0,0,0,0,0,0,0,0,0,0,0,0,0,0,0,0,0,0,0,0,0,0,0,0
0,0,0,0,0,0,0,0,0,0,0,0,0,0,0,0,0,0,0,0,0,0,0,0,0,0,0,0,0,0,0,0,0,0,0,0,0,0
0,0,0,0,0,0,0,0,0,0,0,0,0,43,0,0,0,0,0,0,0,0,0,0,0,0,0,0,0,0,0,0,0,0,0,0,0,0
0,0,0,0,0,0,0,0,0,0,0,0,0,0,0,0,0,0,0,0,0,0,0,0,0,0,0,0,0,0,0,0,0,0,0,0,0,0
0,0,0,0,0,0,0,0,0,0,0,0,0,0,0,0,0,0,0,0,0,0,0,0,0,0,0,0,0,0,0,0,0,0,0,0,0,0
0,0,0,0,0,0,0,0,0,0,0,0,0,0,0,0,0,0,0,0,0,0,0,0,0,0,0,0,0,0,0,0,0,0,0,0,0,0
0,0,0,0,0,0,0,0,0,0,0,0,0,0,0,0,0,0,0,0,0,0,0,0,0,0,0,0,0,0,0,0,0,0,0,0,0,0
0,0,0,0,0,0,0,0,0,0,0,0,0,0,0,0,0,0,0,0,0,0,0,0,0,0,0,0,0,0,0,0,0,0,0,0,0,0
0,0,0,0,0,0,0,0,0,0,0,0,0,0,0,0,0,0,0,0,0,0,0,0,0,0,0,0,0,0,0,0,0,0,0,0,0,0
0,0,0,0,0,0,0,0,0,0,0,0,0,0,0,0,0,0,0,0,0,0,0,0,0,0,0,0,0,0,0,0,0,0,0,0,0,0
0,0,0,69,69,0,0,0,0,0,0,0,0,0,0,0,0,0,0,0,0,0,0,0,0,0,0,0,0,0,0,0,0,0,0,0,0,0
0,0,69,28,28,69,0,0,0,0,0,0,0,0,0,0,0,0,0,0,0,0,0,0,0,0,0,0,0,0,0,0,0,0,0,0,0,0
0,69,28,28,28,28,69,0,0,0,0,0,0,0,0,0,0,0,0,0,0,0,0,0,0,0,0,0,0,0,0,0,0,0,0,0,0,0
0,69,28,28,28,28,69,0,0,0,0,0,0,0,0,0,0,0,0,0,0,0,0,0,0,0,0,0,0,0,0,0,0,0,0,0,0,0
0,0,69,28,28,69,0,0,0,0,0,0,0,0,0,0,0,0,0,0,0,0,0,0,0,0,0,0,0,0,0,0,0,0,0,0,0,0
0,0,0,69,69,0,0,0,0,0,0,0,0,0,0,0,0,0,0,0,0,0,0,0,0,0,0,0,0,0,0,0,0,0,0,0,0,0
0,0,0,0,0,0,0,0,0,0,0,0,0,0,0,0,0,0,0,0,0,0,0,0,0,0,0,0,0,0,0,0,0,0,0,0,0,0
:endlayer
layer: 14
0,0,0,0,0,0,0,0,0,0,0,0,0,0,0,0,0,0,0,0,0,0,0,0,0,0,0,0,0,0,0,0,0,0,0,0,0,0
0,0,0,0,0,0,0,0,0,0,0,0,0,0,0,0,0,0,0,0,0,0,0,0,0,0,0,0,0,0,0,0,0,0,0,0,0,0
0,0,0,0,0,0,0,0,0,0,0,0,0,0,0,0,0,0,0,0,0,0,0,0,0,0,0,0,0,0,0,0,0,0,0,0,0,0
0,0,0,0,0,0,0,0,0,0,0,0,0,0,0,0,0,0,0,0,0,0,0,0,0,0,0,0,0,0,0,0,0,0,0,0,0,0
0,0,0,0,0,0,0,0,0,0,0,0,0,0,0,0,0,0,0,0,0,0,0,0,0,0,0,0,0,0,0,0,0,0,0,0,0,0
0,0,0,0,0,0,0,0,0,0,0,0,0,0,0,0,0,0,0,0,0,0,0,0,0,0,0,0,0,0,0,0,0,0,0,0,0,0
0,0,0,0,0,0,0,0,0,0,0,0,0,0,0,0,0,0,0,0,0,0,0,0,0,0,0,0,0,0,0,0,0,0,0,0,0,0
0,0,0,0,0,0,0,0,0,0,0,0,0,0,0,0,0,0,0,0,0,0,0,0,0,0,0,0,0,0,0,0,0,0,0,0,0,0
0,0,0,0,0,0,0,0,0,0,0,0,0,0,0,0,0,0,0,0,0,0,0,0,0,0,0,0,0,0,0,0,0,0,0,0,0,0
0,0,0,0,0,0,0,0,0,0,0,0,0,0,0,0,0,0,0,0,0,0,0,0,0,0,0,0,0,0,0,0,0,0,0,0,0,0
0,0,0,0,0,0,0,0,0,0,0,0,0,0,0,0,0,0,0,0,0,0,0,0,0,0,0,0,0,0,0,0,0,0,0,0,0,0
0,0,0,0,0,0,0,0,0,0,0,0,0,0,0,0,0,0,0,0,0,0,0,0,0,0,0,0,0,0,0,0,0,0,0,0,0,0
0,0,0,0,0,0,0,0,0,0,0,0,0,0,0,0,0,0,0,0,0,0,0,0,0,0,0,0,0,0,0,0,0,0,0,0,0,0
0,0,0,69,69,0,0,0,0,0,0,0,0,0,0,0,0,0,0,0,0,0,0,0,0,0,0,0,0,0,0,0,0,0,0,0,0,0
0,0,0,69,69,0,0,0,0,0,0,0,0,0,0,0,0,0,0,0,0,0,0,0,0,0,0,0,0,0,0,0,0,0,0,0,0,0
0,0,0,0,0,0,0,0,0,0,0,0,0,0,0,0,0,0,0,0,0,0,0,0,0,0,0,0,0,0,0,0,0,0,0,0,0,0
0,0,0,0,0,0,0,0,0,0,0,0,0,0,0,0,0,0,0,0,0,0,0,0,0,0,0,0,0,0,0,0,0,0,0,0,0,0
0,0,0,0,0,0,0,0,0,0,0,0,0,0,0,0,0,0,0,0,0,0,0,0,0,0,0,0,0,0,0,0,0,0,0,0,0,0
:endlayer

#### RULES ####
rule:
plugin=vanillaBlocks
number=1
data:
JSON:{blockState:{blockName:"minecraft:stone",properties:{variant:"stone"}}}
:enddata
:endrule

rule:
plugin=vanillaBlocks
number=2
data:
JSON:{blockState:{blockName:"minecraft:dirt",properties:{variant:"dirt",snowy:"false"}}}
:enddata
:endrule

rule:
plugin=vanillaBlocks
number=3
data:
JSON:{blockState:{blockName:"minecraft:grass",properties:{snowy:"false"}}}
:enddata
:endrule

rule:
plugin=vanillaBlocks
number=4
data:
JSON:{blockState:{blockName:"minecraft:grass_path"}}
:enddata
:endrule

rule:
plugin=vanillaBlocks
number=5
data:
JSON:{blockState:{blockName:"minecraft:log",properties:{variant:"birch",axis:"y"}}}
:enddata
:endrule

rule:
plugin=vanillaBlocks
number=6
data:
JSON:{blockState:{blockName:"minecraft:log",properties:{variant:"birch",axis:"z"}}}
:enddata
:endrule

rule:
plugin=vanillaBlocks
number=7
data:
JSON:{blockState:{blockName:"minecraft:log",properties:{variant:"birch",axis:"x"}}}
:enddata
:endrule

rule:
plugin=vanillaBlocks
number=8
data:
JSON:{blockState:{blockName:"minecraft:planks",properties:{variant:"oak"}}}
:enddata
:endrule

rule:
plugin=vanillaBlocks
number=9
data:
JSON:{blockState:{blockName:"minecraft:cobblestone"}}
:enddata
:endrule

rule:
plugin=blockTile
number=10
data:
JSON:{blockState:{blockName:"ancientwarfarestructure:advanced_spawner",properties:{transparent:"true"}},teData:{id:"ancientwarfarestructure:advanced_spawner_tile",spawnerSettings:{minDelay:10,spawnDelay:6,lightSensitive:0b,spawnGroups:[{settingsList:[{remainingSpawnCount:1,hostile:1b,customTag:{ArmorDropChances:[0.085f,0.085f,0.085f,0.085f],hasCustomEquipment:0b,ArmorItems:[{},{},{},{}],skinSettings:{npcTypeName:"custom",skinTypeSelected:"default"},HandDropChances:[0.085f,0.085f],factionName:"nogg",HandItems:[{id:"ancientwarfarenpc:iron_halberd",Count:1b,Damage:0s},{}]},maxToSpawn:1,entityId:"ancientwarfarenpc:faction.soldier",minToSpawn:1}],groupWeight:1}],playerRange:16,respondToRedstone:0b,inventory:{Size:9,Items:[]},spawnRange:0,transparent:1b,maxDelay:10,spawnYOffset:0,xpToDrop:0,mobRange:0,debugMode:0b,maxNearbyMonsters:0}}}
:enddata
:endrule

rule:
plugin=blockTile
number=11
data:
JSON:{blockState:{blockName:"ancientwarfarestructure:advanced_spawner",properties:{transparent:"true"}},teData:{id:"ancientwarfarestructure:advanced_spawner_tile",spawnerSettings:{minDelay:10,spawnDelay:1,lightSensitive:0b,spawnGroups:[{settingsList:[{remainingSpawnCount:1,hostile:1b,customTag:{ArmorDropChances:[0.085f,0.085f,0.085f,0.085f],hasCustomEquipment:0b,ArmorItems:[{},{},{},{}],skinSettings:{npcTypeName:"custom",skinTypeSelected:"default"},HandDropChances:[0.085f,0.085f],factionName:"nogg",HandItems:[{id:"ancientwarfarenpc:iron_halberd",Count:1b,Damage:0s},{}]},maxToSpawn:1,entityId:"ancientwarfarenpc:faction.soldier",minToSpawn:1}],groupWeight:1}],playerRange:16,respondToRedstone:0b,inventory:{Size:9,Items:[]},spawnRange:0,transparent:1b,maxDelay:10,spawnYOffset:0,xpToDrop:0,mobRange:0,debugMode:0b,maxNearbyMonsters:0}}}
:enddata
:endrule

rule:
plugin=vanillaBlocks
number=12
data:
JSON:{blockState:{blockName:"minecraft:birch_fence",properties:{east:"false",south:"false",north:"false",west:"false"}}}
:enddata
:endrule

rule:
plugin=vanillaBlocks
number=13
data:
JSON:{blockState:{blockName:"minecraft:tallgrass",properties:{type:"tall_grass"}}}
:enddata
:endrule

rule:
plugin=vanillaBlocks
number=14
data:
JSON:{blockState:{blockName:"minecraft:red_flower",properties:{type:"red_tulip"}}}
:enddata
:endrule

rule:
plugin=vanillaBlocks
number=15
data:
JSON:{blockState:{blockName:"harvestcraft:pammaple",properties:{age:"2"}}}
:enddata
:endrule

rule:
plugin=vanillaBlocks
number=16
data:
JSON:{blockState:{blockName:"minecraft:red_flower",properties:{type:"poppy"}}}
:enddata
:endrule

rule:
plugin=vanillaBlocks
number=17
data:
JSON:{blockState:{blockName:"minecraft:red_flower",properties:{type:"houstonia"}}}
:enddata
:endrule

rule:
plugin=vanillaBlocks
number=18
data:
JSON:{blockState:{blockName:"minecraft:yellow_flower",properties:{type:"dandelion"}}}
:enddata
:endrule

rule:
plugin=vanillaBlocks
number=19
data:
JSON:{blockState:{blockName:"minecraft:red_flower",properties:{type:"orange_tulip"}}}
:enddata
:endrule

rule:
plugin=vanillaBlocks
number=20
data:
JSON:{blockState:{blockName:"minecraft:red_flower",properties:{type:"pink_tulip"}}}
:enddata
:endrule

rule:
plugin=blockTile
number=21
data:
JSON:{blockState:{blockName:"ancientwarfarestructure:advanced_spawner",properties:{transparent:"true"}},teData:{id:"ancientwarfarestructure:advanced_spawner_tile",spawnerSettings:{minDelay:10,spawnDelay:7,lightSensitive:0b,spawnGroups:[{settingsList:[{remainingSpawnCount:1,hostile:1b,customTag:{ArmorDropChances:[0.085f,0.085f,0.085f,0.085f],hasCustomEquipment:0b,ArmorItems:[{},{},{},{}],skinSettings:{npcTypeName:"custom",skinTypeSelected:"default"},HandDropChances:[0.085f,0.085f],factionName:"nogg",HandItems:[{id:"minecraft:bow",Count:1b,Damage:0s},{}]},maxToSpawn:1,entityId:"ancientwarfarenpc:faction.archer.elite",minToSpawn:1}],groupWeight:1}],playerRange:32,respondToRedstone:0b,inventory:{Size:9,Items:[]},spawnRange:0,transparent:1b,maxDelay:10,spawnYOffset:0,xpToDrop:0,mobRange:0,debugMode:0b,maxNearbyMonsters:0}}}
:enddata
:endrule

rule:
plugin=blockTile
number=22
data:
JSON:{blockState:{blockName:"ancientwarfarestructure:advanced_spawner",properties:{transparent:"true"}},teData:{id:"ancientwarfarestructure:advanced_spawner_tile",spawnerSettings:{minDelay:10,spawnDelay:9,lightSensitive:0b,spawnGroups:[{settingsList:[{remainingSpawnCount:1,hostile:1b,customTag:{ArmorDropChances:[0.085f,0.085f,0.085f,0.085f],hasCustomEquipment:0b,ArmorItems:[{},{},{},{}],skinSettings:{npcTypeName:"custom",skinTypeSelected:"default"},HandDropChances:[0.085f,0.085f],factionName:"nogg",HandItems:[{},{}]},maxToSpawn:1,entityId:"ancientwarfarenpc:faction.civilian.male",minToSpawn:1}],groupWeight:1}],playerRange:16,respondToRedstone:0b,inventory:{Size:9,Items:[]},spawnRange:0,transparent:1b,maxDelay:10,spawnYOffset:0,xpToDrop:0,mobRange:0,debugMode:0b,maxNearbyMonsters:0}}}
:enddata
:endrule

rule:
plugin=vanillaBlocks
number=23
data:
JSON:{blockState:{blockName:"minecraft:red_flower",properties:{type:"white_tulip"}}}
:enddata
:endrule

rule:
plugin=blockTile
number=24
data:
JSON:{blockState:{blockName:"ancientwarfarestructure:advanced_spawner",properties:{transparent:"true"}},teData:{id:"ancientwarfarestructure:advanced_spawner_tile",spawnerSettings:{minDelay:10,spawnDelay:2,lightSensitive:0b,spawnGroups:[{settingsList:[{remainingSpawnCount:1,hostile:1b,customTag:{ArmorDropChances:[0.085f,0.085f,0.085f,0.085f],hasCustomEquipment:0b,ArmorItems:[{},{},{},{}],skinSettings:{npcTypeName:"custom",skinTypeSelected:"default"},HandDropChances:[0.085f,0.085f],factionName:"nogg",HandItems:[{id:"ancientwarfarenpc:iron_halberd",Count:1b,Damage:0s},{}]},maxToSpawn:1,entityId:"ancientwarfarenpc:faction.soldier",minToSpawn:1}],groupWeight:1}],playerRange:16,respondToRedstone:0b,inventory:{Size:9,Items:[]},spawnRange:0,transparent:1b,maxDelay:10,spawnYOffset:0,xpToDrop:0,mobRange:0,debugMode:0b,maxNearbyMonsters:0}}}
:enddata
:endrule

rule:
plugin=blockTile
number=25
data:
JSON:{blockState:{blockName:"ancientwarfarestructure:advanced_spawner",properties:{transparent:"true"}},teData:{id:"ancientwarfarestructure:advanced_spawner_tile",spawnerSettings:{minDelay:10,spawnDelay:7,lightSensitive:0b,spawnGroups:[{settingsList:[{remainingSpawnCount:1,hostile:1b,customTag:{ArmorDropChances:[0.085f,0.085f,0.085f,0.085f],hasCustomEquipment:0b,ArmorItems:[{},{},{},{}],skinSettings:{npcTypeName:"custom",skinTypeSelected:"default"},HandDropChances:[0.085f,0.085f],factionName:"nogg",HandItems:[{id:"ancientwarfarenpc:iron_halberd",Count:1b,Damage:0s},{}]},maxToSpawn:1,entityId:"ancientwarfarenpc:faction.soldier",minToSpawn:1}],groupWeight:1}],playerRange:16,respondToRedstone:0b,inventory:{Size:9,Items:[]},spawnRange:0,transparent:1b,maxDelay:10,spawnYOffset:0,xpToDrop:0,mobRange:0,debugMode:0b,maxNearbyMonsters:0}}}
:enddata
:endrule

rule:
plugin=blockTile
number=26
data:
JSON:{blockState:{blockName:"ancientwarfarestructure:advanced_spawner",properties:{transparent:"true"}},teData:{id:"ancientwarfarestructure:advanced_spawner_tile",spawnerSettings:{minDelay:10,spawnDelay:10,lightSensitive:0b,spawnGroups:[{settingsList:[{remainingSpawnCount:1,hostile:1b,customTag:{ArmorDropChances:[0.085f,0.085f,0.085f,0.085f],hasCustomEquipment:0b,ArmorItems:[{},{},{},{}],skinSettings:{npcTypeName:"custom",skinTypeSelected:"default"},HandDropChances:[0.085f,0.085f],factionName:"nogg",HandItems:[{id:"ancientwarfarenpc:iron_halberd",Count:1b,Damage:0s},{}]},maxToSpawn:1,entityId:"ancientwarfarenpc:faction.soldier",minToSpawn:1}],groupWeight:1}],playerRange:16,respondToRedstone:0b,inventory:{Size:9,Items:[]},spawnRange:0,transparent:1b,maxDelay:10,spawnYOffset:0,xpToDrop:0,mobRange:0,debugMode:0b,maxNearbyMonsters:0}}}
:enddata
:endrule

rule:
plugin=vanillaBlocks
number=27
data:
JSON:{blockState:{blockName:"minecraft:red_flower",properties:{type:"oxeye_daisy"}}}
:enddata
:endrule

rule:
plugin=vanillaBlocks
number=28
data:
JSON:{blockState:{blockName:"minecraft:planks",properties:{variant:"birch"}}}
:enddata
:endrule

rule:
plugin=vanillaBlocks
number=29
data:
JSON:{blockState:{blockName:"minecraft:stained_hardened_clay",properties:{color:"white"}}}
:enddata
:endrule

rule:
plugin=doors
number=30
data:
JSON:{blockState:{blockName:"minecraft:birch_door",properties:{hinge:"left",half:"lower",powered:"false",facing:"west",open:"false"}}}
:enddata
:endrule

rule:
plugin=vanillaBlocks
number=31
data:
JSON:{blockState:{blockName:"minecraft:birch_stairs",properties:{half:"bottom",shape:"straight",facing:"south"}}}
:enddata
:endrule

rule:
plugin=vanillaBlocks
number=32
data:
JSON:{blockState:{blockName:"minecraft:stone",properties:{variant:"smooth_andesite"}}}
:enddata
:endrule

rule:
plugin=inventory
number=33
data:
JSON:{blockState:{blockName:"minecraft:chest",properties:{facing:"west"}},lootLevel:0,teData:{Items:[],id:"minecraft:chest",Lock:""},inventoryData:{length:0,inventoryContents:[]},legacyFeatures:1b}
:enddata
:endrule

rule:
plugin=inventory
number=34
data:
JSON:{blockState:{blockName:"minecraft:chest",properties:{facing:"west"}},lootLevel:0,teData:{Items:[],id:"minecraft:chest",Lock:""},inventoryData:{length:0,inventoryContents:[]},legacyFeatures:1b}
:enddata
:endrule

rule:
plugin=vanillaBlocks
number=35
data:
JSON:{blockState:{blockName:"minecraft:cobblestone_wall",properties:{east:"false",south:"false",north:"false",variant:"cobblestone",west:"false",up:"false"}}}
:enddata
:endrule

rule:
plugin=inventory
number=36
data:
JSON:{blockState:{blockName:"minecraft:furnace",properties:{facing:"south"}},lootLevel:0,teData:{CookTime:0,BurnTime:0,Items:[],id:"minecraft:furnace",CookTimeTotal:0,Lock:""},inventoryData:{length:0,inventoryContents:[]},legacyFeatures:0b}
:enddata
:endrule

rule:
plugin=vanillaBlocks
number=37
data:
JSON:{blockState:{blockName:"ancientwarfarestructure:bench",properties:{legs:"none",variant:"birch",axis:"x"}}}
:enddata
:endrule

rule:
plugin=bed
number=38
data:
JSON:{blockState:{blockName:"minecraft:bed",properties:{part:"foot",facing:"south",occupied:"false"}},bedColor:2}
:enddata
:endrule

rule:
plugin=bed
number=39
data:
JSON:{blockState:{blockName:"minecraft:bed",properties:{part:"head",facing:"south",occupied:"false"}},bedColor:2}
:enddata
:endrule

rule:
plugin=vanillaBlocks
number=40
data:
JSON:{blockState:{blockName:"minecraft:stone_stairs",properties:{half:"bottom",shape:"straight",facing:"north"}}}
:enddata
:endrule

rule:
plugin=vanillaBlocks
number=41
data:
JSON:{blockState:{blockName:"minecraft:stone_stairs",properties:{half:"bottom",shape:"straight",facing:"south"}}}
:enddata
:endrule

rule:
plugin=vanillaBlocks
number=42
data:
JSON:{blockState:{blockName:"ancientwarfarestructure:fire_pit",properties:{lit:"true",variant:"default"}}}
:enddata
:endrule

rule:
plugin=vanillaBlocks
number=43
data:
JSON:{blockState:{blockName:"minecraft:stone_slab",properties:{half:"bottom",variant:"cobblestone"}}}
:enddata
:endrule

rule:
plugin=blockTile
number=44
data:
JSON:{blockState:{blockName:"ancientwarfarestructure:chair",properties:{visible:"true",variant:"birch",facing:"east"}},facing:"south",teData:{facing:"east",id:"ancientwarfarestructure:chair_tile"}}
:enddata
:endrule

rule:
plugin=vanillaBlocks
number=45
data:
JSON:{blockState:{blockName:"ancientwarfarestructure:table",properties:{leg_southwest:"true",leg_northwest:"true",variant:"birch",leg_northeast:"true",leg_southeast:"true"}}}
:enddata
:endrule

rule:
plugin=blockTile
number=46
data:
JSON:{blockState:{blockName:"ancientwarfarestructure:chair",properties:{visible:"true",variant:"birch",facing:"east"}},facing:"north",teData:{facing:"west",id:"ancientwarfarestructure:chair_tile"}}
:enddata
:endrule

rule:
plugin=blockTile
number=47
data:
JSON:{blockState:{blockName:"ancientwarfarestructure:chair",properties:{visible:"true",variant:"birch",facing:"east"}},facing:"south",teData:{facing:"east",id:"ancientwarfarestructure:chair_tile"}}
:enddata
:endrule

rule:
plugin=blockTile
number=48
data:
JSON:{blockState:{blockName:"ancientwarfarestructure:chair",properties:{visible:"true",variant:"birch",facing:"east"}},facing:"north",teData:{facing:"west",id:"ancientwarfarestructure:chair_tile"}}
:enddata
:endrule

rule:
plugin=vanillaBlocks
number=49
data:
JSON:{blockState:{blockName:"minecraft:glass"}}
:enddata
:endrule

rule:
plugin=blockTile
number=50
data:
JSON:{blockState:{blockName:"ancientwarfarestructure:advanced_spawner",properties:{transparent:"true"}},teData:{id:"ancientwarfarestructure:advanced_spawner_tile",spawnerSettings:{minDelay:10,spawnDelay:1,lightSensitive:0b,spawnGroups:[{settingsList:[{remainingSpawnCount:1,hostile:1b,customTag:{ArmorDropChances:[0.085f,0.085f,0.085f,0.085f],hasCustomEquipment:0b,ArmorItems:[{},{},{},{}],skinSettings:{npcTypeName:"custom",skinTypeSelected:"default"},HandDropChances:[0.085f,0.085f],factionName:"nogg",HandItems:[{id:"ancientwarfarenpc:iron_halberd",Count:1b,Damage:0s},{}]},maxToSpawn:1,entityId:"ancientwarfarenpc:faction.soldier",minToSpawn:1}],groupWeight:1}],playerRange:16,respondToRedstone:0b,inventory:{Size:9,Items:[]},spawnRange:0,transparent:1b,maxDelay:10,spawnYOffset:0,xpToDrop:0,mobRange:0,debugMode:0b,maxNearbyMonsters:0}}}
:enddata
:endrule

rule:
plugin=inventory
number=51
data:
JSON:{blockState:{blockName:"minecraft:furnace",properties:{facing:"south"}},lootLevel:0,teData:{CookTime:0,BurnTime:0,Items:[],id:"minecraft:furnace",CookTimeTotal:0,Lock:""},inventoryData:{length:0,inventoryContents:[]},legacyFeatures:0b}
:enddata
:endrule

rule:
plugin=blockTile
number=52
data:
JSON:{blockState:{blockName:"ancientwarfarestructure:chair",properties:{visible:"true",variant:"birch",facing:"east"}},facing:"south",teData:{facing:"east",id:"ancientwarfarestructure:chair_tile"}}
:enddata
:endrule

rule:
plugin=blockTile
number=53
data:
JSON:{blockState:{blockName:"ancientwarfarestructure:chair",properties:{visible:"true",variant:"birch",facing:"east"}},facing:"north",teData:{facing:"west",id:"ancientwarfarestructure:chair_tile"}}
:enddata
:endrule

rule:
plugin=doors
number=54
data:
JSON:{blockState:{blockName:"minecraft:birch_door",properties:{hinge:"left",half:"lower",powered:"false",facing:"north",open:"false"}}}
:enddata
:endrule

rule:
plugin=inventory
number=55
data:
JSON:{blockState:{blockName:"minecraft:furnace",properties:{facing:"south"}},lootLevel:0,teData:{CookTime:0,BurnTime:0,Items:[],id:"minecraft:furnace",CookTimeTotal:0,Lock:""},inventoryData:{length:0,inventoryContents:[]},legacyFeatures:0b}
:enddata
:endrule

rule:
plugin=vanillaBlocks
number=56
data:
JSON:{blockState:{blockName:"minecraft:birch_stairs",properties:{half:"bottom",shape:"straight",facing:"west"}}}
:enddata
:endrule

rule:
plugin=vanillaBlocks
number=57
data:
JSON:{blockState:{blockName:"ancientwarfarestructure:stool",properties:{variant:"birch"}}}
:enddata
:endrule

rule:
plugin=bed
number=58
data:
JSON:{blockState:{blockName:"minecraft:bed",properties:{part:"head",facing:"north",occupied:"false"}},bedColor:2}
:enddata
:endrule

rule:
plugin=bed
number=59
data:
JSON:{blockState:{blockName:"minecraft:bed",properties:{part:"foot",facing:"north",occupied:"false"}},bedColor:2}
:enddata
:endrule

rule:
plugin=vanillaBlocks
number=60
data:
JSON:{blockState:{blockName:"minecraft:birch_stairs",properties:{half:"bottom",shape:"straight",facing:"east"}}}
:enddata
:endrule

rule:
plugin=vanillaBlocks
number=61
data:
JSON:{blockState:{blockName:"ancientwarfarestructure:bench",properties:{legs:"none",variant:"birch",axis:"z"}}}
:enddata
:endrule

rule:
plugin=vanillaBlocks
number=62
data:
JSON:{blockState:{blockName:"minecraft:crafting_table"}}
:enddata
:endrule

rule:
plugin=inventory
number=63
data:
JSON:{blockState:{blockName:"minecraft:chest",properties:{facing:"south"}},lootLevel:0,teData:{Items:[],id:"minecraft:chest",Lock:""},inventoryData:{length:0,inventoryContents:[]},legacyFeatures:1b}
:enddata
:endrule

rule:
plugin=bed
number=64
data:
JSON:{blockState:{blockName:"minecraft:bed",properties:{part:"foot",facing:"west",occupied:"false"}},bedColor:2}
:enddata
:endrule

rule:
plugin=inventory
number=65
data:
JSON:{blockState:{blockName:"minecraft:chest",properties:{facing:"south"}},lootLevel:0,teData:{Items:[],id:"minecraft:chest",Lock:""},inventoryData:{length:0,inventoryContents:[]},legacyFeatures:1b}
:enddata
:endrule

rule:
plugin=bed
number=66
data:
JSON:{blockState:{blockName:"minecraft:bed",properties:{part:"head",facing:"west",occupied:"false"}},bedColor:2}
:enddata
:endrule

rule:
plugin=inventory
number=67
data:
JSON:{blockState:{blockName:"minecraft:chest",properties:{facing:"east"}},lootLevel:0,teData:{Items:[],id:"minecraft:chest",Lock:""},inventoryData:{length:0,inventoryContents:[]},legacyFeatures:1b}
:enddata
:endrule

rule:
plugin=inventory
number=68
data:
JSON:{blockState:{blockName:"minecraft:chest",properties:{facing:"east"}},lootLevel:0,teData:{Items:[],id:"minecraft:chest",Lock:""},inventoryData:{length:0,inventoryContents:[]},legacyFeatures:1b}
:enddata
:endrule

rule:
plugin=vanillaBlocks
number=69
data:
JSON:{blockState:{blockName:"minecraft:wooden_slab",properties:{half:"bottom",variant:"birch"}}}
:enddata
:endrule

rule:
plugin=vanillaBlocks
number=70
data:
JSON:{blockState:{blockName:"minecraft:torch",properties:{facing:"up"}}}
:enddata
:endrule

rule:
plugin=vanillaBlocks
number=71
data:
JSON:{blockState:{blockName:"minecraft:glass_pane",properties:{east:"false",south:"false",north:"false",west:"false"}}}
:enddata
:endrule

rule:
plugin=doors
number=72
data:
JSON:{blockState:{blockName:"minecraft:birch_door",properties:{hinge:"left",half:"upper",powered:"false",facing:"east",open:"false"}}}
:enddata
:endrule

rule:
plugin=vanillaBlocks
number=73
data:
JSON:{blockState:{blockName:"minecraft:stone_stairs",properties:{half:"bottom",shape:"straight",facing:"west"}}}
:enddata
:endrule

rule:
plugin=blockTile
number=74
data:
JSON:{blockState:{blockName:"ancientwarfarestructure:chair",properties:{visible:"false",variant:"birch",facing:"east"}},facing:"south",teData:{facing:"east",id:"ancientwarfarestructure:chair_tile",mainBlockPos:28862985535007L}}
:enddata
:endrule

rule:
plugin=blockTile
number=75
data:
JSON:{blockState:{blockName:"ancientwarfarestructure:chair",properties:{visible:"false",variant:"birch",facing:"east"}},facing:"north",teData:{facing:"west",id:"ancientwarfarestructure:chair_tile",mainBlockPos:29687619255839L}}
:enddata
:endrule

rule:
plugin=blockTile
number=76
data:
JSON:{blockState:{blockName:"ancientwarfarestructure:chair",properties:{visible:"false",variant:"birch",facing:"east"}},facing:"south",teData:{facing:"east",id:"ancientwarfarestructure:chair_tile",mainBlockPos:28862985535008L}}
:enddata
:endrule

rule:
plugin=blockTile
number=77
data:
JSON:{blockState:{blockName:"ancientwarfarestructure:chair",properties:{visible:"false",variant:"birch",facing:"east"}},facing:"north",teData:{facing:"west",id:"ancientwarfarestructure:chair_tile",mainBlockPos:29687619255840L}}
:enddata
:endrule

rule:
plugin=vanillaBlocks
number=78
data:
JSON:{blockState:{blockName:"minecraft:stone_stairs",properties:{half:"bottom",shape:"straight",facing:"east"}}}
:enddata
:endrule

rule:
plugin=blockTile
number=79
data:
JSON:{blockState:{blockName:"ancientwarfarestructure:chair",properties:{visible:"false",variant:"birch",facing:"east"}},facing:"south",teData:{facing:"east",id:"ancientwarfarestructure:chair_tile",mainBlockPos:28862985535009L}}
:enddata
:endrule

rule:
plugin=blockTile
number=80
data:
JSON:{blockState:{blockName:"ancientwarfarestructure:chair",properties:{visible:"false",variant:"birch",facing:"east"}},facing:"north",teData:{facing:"west",id:"ancientwarfarestructure:chair_tile",mainBlockPos:29687619255841L}}
:enddata
:endrule

rule:
plugin=doors
number=81
data:
JSON:{blockState:{blockName:"minecraft:birch_door",properties:{hinge:"right",half:"upper",powered:"false",facing:"east",open:"false"}}}
:enddata
:endrule

rule:
plugin=inventory
number=82
data:
JSON:{blockState:{blockName:"minecraft:chest",properties:{facing:"south"}},lootLevel:0,teData:{Items:[],id:"minecraft:chest",Lock:""},inventoryData:{length:0,inventoryContents:[]},legacyFeatures:1b}
:enddata
:endrule

rule:
plugin=inventory
number=83
data:
JSON:{blockState:{blockName:"minecraft:chest",properties:{facing:"south"}},lootLevel:0,teData:{Items:[],id:"minecraft:chest",Lock:""},inventoryData:{length:0,inventoryContents:[]},legacyFeatures:1b}
:enddata
:endrule

rule:
plugin=inventory
number=84
data:
JSON:{blockState:{blockName:"minecraft:chest",properties:{facing:"east"}},lootLevel:0,teData:{Items:[],id:"minecraft:chest",Lock:""},inventoryData:{length:0,inventoryContents:[]},legacyFeatures:1b}
:enddata
:endrule

rule:
plugin=inventory
number=85
data:
JSON:{blockState:{blockName:"minecraft:chest",properties:{facing:"east"}},lootLevel:0,teData:{Items:[],id:"minecraft:chest",Lock:""},inventoryData:{length:0,inventoryContents:[]},legacyFeatures:1b}
:enddata
:endrule

rule:
plugin=vanillaBlocks
number=86
data:
JSON:{blockState:{blockName:"minecraft:leaves",properties:{check_decay:"false",decayable:"true",variant:"spruce"}}}
:enddata
:endrule

rule:
plugin=vanillaBlocks
number=87
data:
JSON:{blockState:{blockName:"minecraft:log",properties:{variant:"spruce",axis:"y"}}}
:enddata
:endrule

rule:
plugin=vanillaBlocks
number=88
data:
JSON:{blockState:{blockName:"minecraft:torch",properties:{facing:"east"}}}
:enddata
:endrule

rule:
plugin=vanillaBlocks
number=89
data:
JSON:{blockState:{blockName:"minecraft:torch",properties:{facing:"north"}}}
:enddata
:endrule

rule:
plugin=vanillaBlocks
number=90
data:
JSON:{blockState:{blockName:"minecraft:torch",properties:{facing:"south"}}}
:enddata
:endrule

rule:
plugin=vanillaBlocks
number=91
data:
JSON:{blockState:{blockName:"minecraft:stone_stairs",properties:{half:"top",shape:"straight",facing:"north"}}}
:enddata
:endrule

rule:
plugin=vanillaBlocks
number=92
data:
JSON:{blockState:{blockName:"minecraft:stone_slab",properties:{half:"top",variant:"cobblestone"}}}
:enddata
:endrule

rule:
plugin=vanillaBlocks
number=93
data:
JSON:{blockState:{blockName:"minecraft:torch",properties:{facing:"west"}}}
:enddata
:endrule

rule:
plugin=inventory
number=94
data:
JSON:{blockState:{blockName:"minecraft:chest",properties:{facing:"south"}},lootLevel:0,teData:{Items:[],id:"minecraft:chest",Lock:""},inventoryData:{length:0,inventoryContents:[]},legacyFeatures:1b}
:enddata
:endrule

rule:
plugin=inventory
number=95
data:
JSON:{blockState:{blockName:"minecraft:chest",properties:{facing:"south"}},lootLevel:0,teData:{Items:[],id:"minecraft:chest",Lock:""},inventoryData:{length:0,inventoryContents:[]},legacyFeatures:1b}
:enddata
:endrule

rule:
plugin=inventory
number=96
data:
JSON:{blockState:{blockName:"minecraft:chest",properties:{facing:"east"}},lootLevel:0,teData:{Items:[],id:"minecraft:chest",Lock:""},inventoryData:{length:0,inventoryContents:[]},legacyFeatures:1b}
:enddata
:endrule

rule:
plugin=inventory
number=97
data:
JSON:{blockState:{blockName:"minecraft:chest",properties:{facing:"east"}},lootLevel:0,teData:{Items:[],id:"minecraft:chest",Lock:""},inventoryData:{length:0,inventoryContents:[]},legacyFeatures:1b}
:enddata
:endrule

rule:
plugin=vanillaBlocks
number=98
data:
JSON:{blockState:{blockName:"minecraft:wooden_slab",properties:{half:"top",variant:"birch"}}}
:enddata
:endrule

rule:
plugin=vanillaBlocks
number=99
data:
JSON:{blockState:{blockName:"minecraft:birch_stairs",properties:{half:"top",shape:"straight",facing:"west"}}}
:enddata
:endrule

rule:
plugin=vanillaBlocks
number=100
data:
JSON:{blockState:{blockName:"minecraft:birch_stairs",properties:{half:"top",shape:"straight",facing:"east"}}}
:enddata
:endrule

rule:
plugin=inventory
number=101
data:
JSON:{blockState:{blockName:"minecraft:chest",properties:{facing:"south"}},lootLevel:0,teData:{Items:[],id:"minecraft:chest",Lock:""},inventoryData:{length:0,inventoryContents:[]},legacyFeatures:1b}
:enddata
:endrule

rule:
plugin=inventory
number=102
data:
JSON:{blockState:{blockName:"minecraft:chest",properties:{facing:"south"}},lootLevel:0,teData:{Items:[],id:"minecraft:chest",Lock:""},inventoryData:{length:0,inventoryContents:[]},legacyFeatures:1b}
:enddata
:endrule

rule:
plugin=inventory
number=103
data:
JSON:{blockState:{blockName:"minecraft:chest",properties:{facing:"east"}},lootLevel:0,teData:{Items:[],id:"minecraft:chest",Lock:""},inventoryData:{length:0,inventoryContents:[]},legacyFeatures:1b}
:enddata
:endrule

rule:
plugin=inventory
number=104
data:
JSON:{blockState:{blockName:"minecraft:chest",properties:{facing:"east"}},lootLevel:0,teData:{Items:[],id:"minecraft:chest",Lock:""},inventoryData:{length:0,inventoryContents:[]},legacyFeatures:1b}
:enddata
:endrule

rule:
plugin=inventory
number=105
data:
JSON:{blockState:{blockName:"minecraft:chest",properties:{facing:"east"}},lootLevel:0,teData:{Items:[],id:"minecraft:chest",Lock:""},inventoryData:{length:0,inventoryContents:[]},legacyFeatures:1b}
:enddata
:endrule

rule:
plugin=inventory
number=106
data:
JSON:{blockState:{blockName:"minecraft:chest",properties:{facing:"east"}},lootLevel:0,teData:{Items:[],id:"minecraft:chest",Lock:""},inventoryData:{length:0,inventoryContents:[]},legacyFeatures:1b}
:enddata
:endrule

#### ENTITIES ####
