# Ancient Warfare Structure Template File
# Auto-generated structure template file. created on: 12/12/2023 at: 0:5:25
# Lines beginning with # denote comments

header:
version=2.11
name=NoggFarmPotatoCarrotBeetroot
mods=
size=37,15,37
offset=19,5,22
:endheader

#### VALIDATION ####
validation:
type=ground
structureAuthor=TheOddlySeagull
survival=false
worldGenEnabled=true
unique=false
preserveBlocks=true
preventNaturalHostileSpawns=false
selectionWeight=70
clusterValue=30
minDuplicateDistance=600
dimensionWhiteList=true
dimensionList=0
biomeGroupList=nogg
biomeWhiteList=true
biomeList=minecraft:birch_forest,minecraft:birch_forest_hills
leveling=20
fill=10
border=7
blockSwap=false
territoryName=nogg
biomeReplacement=minecraft:
minGenerationHeight=0
maxGenerationHeight=0
:endvalidation

#### LAYERS ####
layer: 0
1,1,1,1,1,1,1,1,1,1,1,1,1,1,1,1,1,1,1,1,1,1,1,1,1,1,1,1,1,1,1,1,1,1,1,1,1
1,1,1,1,1,1,1,1,1,1,1,1,1,1,1,1,1,1,1,1,1,1,1,1,1,1,1,1,1,1,1,1,1,1,1,1,1
1,1,1,1,1,1,1,1,1,1,1,1,1,1,1,1,1,1,1,1,1,1,1,1,1,1,1,1,1,1,1,1,1,1,1,1,1
1,1,1,1,1,1,1,1,1,1,1,1,1,1,1,1,1,1,1,1,1,1,1,1,1,1,1,1,1,1,1,1,1,1,1,1,1
1,1,1,1,1,1,1,1,1,1,1,1,1,1,1,1,1,1,1,1,1,1,1,1,1,1,1,1,1,1,1,1,1,1,1,1,1
1,1,1,1,1,1,1,1,1,1,1,1,1,1,1,1,1,1,1,1,1,1,1,1,1,1,1,1,1,1,1,1,1,1,1,1,1
1,1,1,1,1,1,1,1,1,1,1,1,1,1,1,1,1,1,1,1,1,1,1,1,1,1,1,1,1,1,1,1,1,1,1,1,1
1,1,1,1,1,1,1,1,1,1,1,1,1,1,1,1,1,1,1,1,1,1,1,1,1,1,1,1,1,1,1,1,1,1,1,1,1
1,1,1,1,1,1,1,1,1,1,1,1,1,1,1,1,1,1,1,1,1,1,1,1,1,1,1,1,1,1,1,1,1,1,1,1,1
1,1,1,1,1,1,1,1,1,1,1,1,1,1,1,1,1,1,1,1,1,1,1,1,1,1,1,1,1,1,1,1,1,1,1,1,1
1,1,1,1,1,1,1,1,1,1,1,1,1,1,1,1,1,1,1,1,1,1,1,1,1,1,1,1,1,1,1,1,1,1,1,1,1
1,1,1,1,1,1,1,1,1,1,1,1,1,1,1,1,1,1,1,1,1,1,1,1,1,1,1,1,1,1,1,1,1,1,1,1,1
1,1,1,1,1,1,1,1,1,1,1,1,1,1,1,1,1,1,1,1,1,1,1,1,1,1,1,1,1,1,1,1,1,1,1,1,1
1,1,1,1,1,1,1,1,1,1,1,1,1,1,1,1,1,1,1,1,1,1,1,1,1,1,1,1,1,1,1,1,1,1,1,1,1
1,1,1,1,1,1,1,1,1,1,1,1,1,1,1,1,1,1,1,1,1,1,1,1,1,1,1,1,1,1,1,1,1,1,1,1,1
1,1,1,1,1,1,1,1,1,1,1,1,1,1,1,1,1,1,1,1,1,1,1,1,1,1,1,1,1,1,1,1,1,1,1,1,1
1,1,1,1,1,1,1,1,1,1,1,1,1,1,1,1,1,1,1,1,1,1,1,1,1,1,1,1,1,1,1,1,1,1,1,1,1
1,1,1,1,1,1,1,1,1,1,1,1,1,1,1,1,1,1,1,1,1,1,1,1,1,1,1,1,1,1,1,1,1,1,1,1,1
1,1,1,1,1,1,1,1,1,1,1,1,1,1,1,1,1,1,1,1,1,1,1,1,1,1,1,1,1,1,1,1,1,1,1,1,1
1,1,1,1,1,1,1,1,1,1,1,1,1,1,1,1,1,1,1,1,1,1,1,1,1,1,1,1,1,1,1,1,1,1,1,1,1
1,1,1,1,1,1,1,1,1,1,1,1,1,1,1,1,1,1,1,1,1,1,1,1,1,1,1,1,1,1,1,1,1,1,1,1,1
1,1,1,1,1,1,1,1,1,1,1,1,1,1,1,1,1,1,1,1,1,1,1,1,1,1,1,1,1,1,1,1,1,1,1,1,1
1,1,1,1,1,1,1,1,1,1,1,1,1,1,1,1,1,1,1,1,1,1,1,1,1,1,1,1,1,1,1,1,1,1,1,1,1
1,1,1,1,1,1,1,1,1,1,1,1,1,1,1,1,1,1,1,1,1,1,1,1,1,1,1,1,1,1,1,1,1,1,1,1,1
1,1,1,1,1,1,1,1,1,1,1,1,1,1,1,1,1,1,1,1,1,1,1,1,1,1,1,1,1,1,1,1,1,1,1,1,1
1,1,1,1,1,1,1,1,1,1,1,1,1,1,1,1,1,1,1,1,1,1,1,1,1,1,1,1,1,1,1,1,1,1,1,1,1
1,1,1,1,1,1,1,1,1,1,1,1,1,1,1,1,1,1,1,1,1,1,1,1,1,1,1,1,1,1,1,1,1,1,1,1,1
1,1,1,1,1,1,1,1,1,1,1,1,1,1,1,1,1,1,1,1,1,1,1,1,1,1,1,1,1,1,1,1,1,1,1,1,1
1,1,1,1,1,1,1,1,1,1,1,1,1,1,1,1,1,1,1,1,1,1,1,1,1,1,1,1,1,1,1,1,1,1,1,1,1
1,1,1,1,1,1,1,1,1,1,1,1,1,1,1,1,1,1,1,1,1,1,1,1,1,1,1,1,1,1,1,1,1,1,1,1,1
1,1,1,1,1,1,1,1,1,1,1,1,1,1,1,1,1,1,1,1,1,1,1,1,1,1,1,1,1,1,1,1,1,1,1,1,1
1,1,1,1,1,1,1,1,1,1,1,1,1,1,1,1,1,1,1,1,1,1,1,1,1,1,1,1,1,1,1,1,1,1,1,1,1
1,1,1,1,1,1,1,1,1,1,1,1,1,1,1,1,1,1,1,1,1,1,1,1,1,1,1,1,1,1,1,1,1,1,1,1,1
1,1,1,1,1,1,1,1,1,1,1,1,1,1,1,1,1,1,1,1,1,1,1,1,1,1,1,1,1,1,1,1,1,1,1,1,1
1,1,1,1,1,1,1,1,1,1,1,1,1,1,1,1,1,1,1,1,1,1,1,1,1,1,1,1,1,1,1,1,1,1,1,1,1
1,1,1,1,1,1,1,1,1,1,1,1,1,1,1,1,1,1,1,1,1,1,1,1,1,1,1,1,1,1,1,1,1,1,1,1,1
1,1,1,1,1,1,1,1,1,1,1,1,1,1,1,1,1,1,1,1,1,1,1,1,1,1,1,1,1,1,1,1,1,1,1,1,1
:endlayer
layer: 1
1,1,1,1,1,1,1,1,1,1,1,1,1,1,1,1,1,1,1,1,1,1,1,1,1,1,1,1,1,1,1,1,1,1,1,1,1
1,1,1,1,1,1,1,1,1,1,1,1,1,1,1,1,1,1,1,1,1,1,1,1,1,1,1,1,1,1,1,1,1,1,1,1,1
1,1,1,1,1,1,1,1,1,1,1,1,1,1,1,1,1,1,1,1,1,1,1,1,1,1,1,1,1,1,1,1,1,1,1,1,1
1,1,1,1,1,1,1,1,1,1,1,1,1,1,1,1,1,1,1,1,1,1,1,1,1,1,1,1,1,1,1,1,1,1,1,1,1
1,1,1,1,1,1,1,1,1,1,1,1,1,1,1,1,1,1,1,1,1,1,1,1,1,1,1,1,1,1,1,1,1,1,1,1,1
1,1,1,1,1,1,1,1,1,1,1,1,1,1,1,1,1,1,1,1,1,1,1,1,1,1,1,1,1,1,1,1,1,1,1,1,1
1,1,1,1,1,1,1,1,1,1,1,1,1,1,1,1,1,1,1,1,1,1,1,1,1,1,1,1,1,1,1,1,1,1,1,1,1
1,1,1,1,1,1,1,1,1,1,1,1,1,1,1,1,1,1,1,1,1,1,1,1,1,1,1,1,1,1,1,1,1,1,1,1,1
1,1,1,1,1,1,1,1,1,1,1,1,1,1,1,1,1,1,1,1,1,1,1,1,1,1,1,1,1,1,1,1,1,1,1,1,1
1,1,1,1,1,1,1,1,1,1,1,1,1,1,1,1,1,1,1,1,1,1,1,1,1,1,1,1,1,1,1,1,1,1,1,1,1
1,1,1,1,1,1,1,1,1,1,1,1,1,1,1,1,1,1,1,1,1,1,1,1,1,1,1,1,1,1,1,1,1,1,1,1,1
1,1,1,1,1,1,1,1,1,1,1,1,1,1,1,1,1,1,1,1,1,1,1,1,1,1,1,1,1,1,1,1,1,1,1,1,1
1,1,1,1,1,1,1,1,1,1,1,1,1,1,1,1,1,1,1,1,1,1,1,1,1,1,1,1,1,1,1,1,1,1,1,1,1
1,1,1,1,1,1,1,1,1,1,1,1,1,1,1,1,1,1,1,1,1,1,1,1,1,1,1,1,1,1,1,1,1,1,1,1,1
1,1,1,1,1,1,1,1,1,1,1,1,1,1,1,1,1,1,1,1,1,1,1,1,1,1,1,1,1,1,1,1,1,1,1,1,1
1,1,1,1,1,1,1,1,1,1,1,1,1,1,1,1,1,1,1,1,1,1,1,1,1,1,1,1,1,1,1,1,1,1,1,1,1
1,1,1,1,1,1,1,1,1,1,1,1,1,1,1,1,1,1,1,1,1,1,1,1,1,1,1,1,1,1,1,1,1,1,1,1,1
1,1,1,1,1,1,1,1,1,1,1,1,1,1,1,1,1,1,1,1,1,1,1,1,1,1,1,1,1,1,1,1,1,1,1,1,1
1,1,1,1,1,1,1,1,1,1,1,1,1,1,1,1,1,1,1,1,1,1,1,1,1,1,1,1,1,1,1,1,1,1,1,1,1
1,1,1,1,1,1,1,1,1,1,1,1,1,1,1,1,1,1,1,1,1,1,1,1,1,1,1,1,1,1,1,1,1,1,1,1,1
1,1,1,1,1,1,1,1,1,1,1,1,1,1,1,1,1,1,1,1,1,1,1,1,1,1,1,1,1,1,1,1,1,1,1,1,1
1,1,1,1,1,1,1,1,1,1,1,1,1,1,1,1,1,1,1,1,1,1,1,1,1,1,1,1,1,1,1,1,1,1,1,1,1
1,1,1,1,1,1,1,1,1,1,1,1,1,1,1,1,1,1,1,1,1,1,1,1,1,1,1,1,1,1,1,1,1,1,1,1,1
1,1,1,1,1,1,1,1,1,1,1,1,1,1,1,1,1,1,1,1,1,1,1,1,1,1,1,1,1,1,1,1,1,1,1,1,1
1,1,1,1,1,1,1,1,1,1,1,1,1,1,1,1,1,1,1,1,1,1,1,1,1,1,1,1,1,1,1,1,1,1,1,1,1
1,1,1,1,1,1,1,1,1,1,1,1,1,1,1,1,1,1,1,1,1,1,1,1,1,1,1,1,1,1,1,1,1,1,1,1,1
1,1,1,1,1,1,1,1,1,1,1,1,1,1,1,1,1,1,1,1,1,1,1,1,1,1,1,1,1,1,1,1,1,1,1,1,1
1,1,1,1,1,1,1,1,1,1,1,1,1,1,1,1,1,1,1,1,1,1,1,1,1,1,1,1,1,1,1,1,1,1,1,1,1
1,1,1,1,1,1,1,1,1,1,1,1,1,1,1,1,1,1,1,1,1,1,1,1,1,1,1,1,1,1,1,1,1,1,1,1,1
1,1,1,1,1,1,1,1,1,1,1,1,1,1,1,1,1,1,1,1,1,1,1,1,1,1,1,1,1,1,1,1,1,1,1,1,1
1,1,1,1,1,1,1,1,1,1,1,1,1,1,1,1,1,1,1,1,1,1,1,1,1,1,1,1,1,1,1,1,1,1,1,1,1
1,1,1,1,1,1,1,1,1,1,1,1,1,1,1,1,1,1,1,1,1,1,1,1,1,1,1,1,1,1,1,1,1,1,1,1,1
1,1,1,1,1,1,1,1,1,1,1,1,1,1,1,1,1,1,1,1,1,1,1,1,1,1,1,1,1,1,1,1,1,1,1,1,1
1,1,1,1,1,1,1,1,1,1,1,1,1,1,1,1,1,1,1,1,1,1,1,1,1,1,1,1,1,1,1,1,1,1,1,1,1
1,1,1,1,1,1,1,1,1,1,1,1,1,1,1,1,1,1,1,1,1,1,1,1,1,1,1,1,1,1,1,1,1,1,1,1,1
1,1,1,1,1,1,1,1,1,1,1,1,1,1,1,1,1,1,1,1,1,1,1,1,1,1,1,1,1,1,1,1,1,1,1,1,1
1,1,1,1,1,1,1,1,1,1,1,1,1,1,1,1,1,1,1,1,1,1,1,1,1,1,1,1,1,1,1,1,1,1,1,1,1
:endlayer
layer: 2
1,1,1,1,1,1,1,1,1,1,1,1,1,1,1,1,1,1,1,1,1,1,1,1,1,1,1,1,1,1,1,1,1,1,1,1,1
1,1,1,1,1,1,1,1,1,1,1,1,1,1,1,1,1,1,1,1,1,1,1,1,1,1,1,1,1,1,1,1,1,1,1,1,1
1,1,1,1,1,1,1,1,1,1,1,1,1,1,1,1,1,1,1,1,1,1,1,1,1,1,1,1,1,1,1,1,1,1,1,1,1
1,1,1,1,1,1,1,1,1,1,1,1,1,1,1,1,1,1,1,1,1,1,1,1,1,1,1,1,1,1,1,1,1,1,1,1,1
1,1,1,1,1,1,1,1,1,1,1,1,1,1,1,1,1,1,1,1,1,1,1,1,1,1,1,1,1,1,1,1,1,1,1,1,1
1,1,1,1,1,1,1,1,1,1,1,1,1,1,1,1,1,1,1,1,1,1,1,1,1,1,1,1,1,1,1,1,1,1,1,1,1
1,1,1,1,1,1,1,1,1,1,1,1,1,1,1,1,1,1,1,1,1,1,1,1,1,1,1,1,1,1,1,1,1,1,1,1,1
1,1,1,1,1,1,1,1,1,1,1,1,1,1,1,1,1,1,1,1,1,1,1,1,1,1,1,1,1,1,1,1,1,1,1,1,1
1,1,1,1,1,1,1,1,1,1,1,1,1,1,1,1,1,1,1,1,1,1,1,1,1,1,1,1,1,1,1,1,1,1,1,1,1
1,1,1,1,1,1,1,1,1,1,1,1,1,1,1,1,1,1,1,1,1,1,1,1,1,1,1,1,1,1,1,1,1,1,1,1,1
1,1,1,1,1,1,1,1,1,1,1,1,1,1,1,1,1,1,1,1,1,1,1,1,1,1,1,1,1,1,1,1,1,1,1,1,1
1,1,1,1,1,1,1,1,1,1,1,1,1,1,1,1,1,1,1,1,1,1,1,1,1,1,1,1,1,1,1,1,1,1,1,1,1
1,1,1,1,1,1,1,1,1,1,1,1,1,1,1,1,1,1,1,1,1,1,1,1,1,1,1,1,1,1,1,1,1,1,1,1,1
1,1,1,1,1,1,1,1,1,1,1,1,1,1,1,1,1,1,1,1,1,1,1,1,1,1,1,1,1,1,1,1,1,1,1,1,1
1,1,1,1,1,1,1,1,1,1,1,1,1,1,1,1,1,1,1,1,1,1,1,1,1,1,1,1,1,1,1,1,1,1,1,1,1
1,1,1,1,1,1,1,1,1,1,1,1,1,1,1,1,1,1,1,1,1,1,1,1,1,1,1,1,1,1,1,1,1,1,1,1,1
1,1,1,1,1,1,1,1,1,1,1,1,1,1,1,1,1,1,1,1,1,1,1,1,1,1,1,1,1,1,1,1,1,1,1,1,1
1,1,1,1,1,1,1,1,1,1,1,1,1,1,1,1,1,1,1,1,1,1,1,1,1,1,1,1,1,1,1,1,1,1,1,1,1
1,1,1,1,1,1,1,1,1,1,1,1,1,1,1,1,1,1,1,1,1,1,1,1,1,1,1,1,1,1,1,1,1,1,1,1,1
1,1,1,1,1,1,1,1,1,1,1,1,1,1,1,1,1,1,1,1,1,1,1,1,1,1,1,1,1,1,1,1,1,1,1,1,1
1,1,1,1,1,1,1,1,1,1,1,1,1,1,1,1,1,1,1,1,1,1,1,1,1,1,1,1,1,1,1,1,1,1,1,1,1
1,1,1,1,1,1,1,1,1,1,1,1,1,1,1,1,1,1,1,1,1,1,1,1,1,1,1,1,1,1,1,1,1,1,1,1,1
1,1,1,1,1,1,1,1,1,1,1,1,1,1,1,1,1,1,1,1,1,1,1,1,1,1,1,1,1,1,1,1,1,1,1,1,1
1,1,1,1,1,1,1,1,1,1,1,1,1,1,1,1,1,1,1,1,1,1,1,1,1,1,1,1,1,1,1,1,1,1,1,1,1
1,1,1,1,1,1,1,1,1,1,1,1,1,1,1,1,1,1,1,1,1,1,1,1,1,1,1,1,1,1,1,1,1,1,1,1,1
1,1,1,1,1,1,1,1,1,1,1,1,1,1,1,1,1,1,1,1,1,1,1,1,1,1,1,1,1,1,1,1,1,1,1,1,1
1,1,1,1,1,1,1,1,1,1,1,1,1,1,1,1,1,1,1,1,1,1,1,1,1,1,1,1,1,1,1,1,1,1,1,1,1
1,1,1,1,1,1,1,1,1,1,1,1,1,1,1,1,1,1,1,1,1,1,1,1,1,1,1,1,1,1,1,1,1,1,1,1,1
1,1,1,1,1,1,1,1,1,1,1,1,1,1,1,1,1,1,1,1,1,1,1,1,1,1,1,1,1,1,1,1,1,1,1,1,1
1,1,1,1,1,1,1,1,1,1,1,1,1,1,1,1,1,1,1,1,1,1,1,1,1,1,1,1,1,1,1,1,1,1,1,1,1
1,1,1,1,1,1,1,1,1,1,1,1,1,1,1,1,1,1,1,1,1,1,1,1,1,1,1,1,1,1,1,1,1,1,1,1,1
1,1,1,1,1,1,1,1,1,1,1,1,1,1,1,1,1,1,1,1,1,1,1,1,1,1,1,1,1,1,1,1,1,1,1,1,1
1,1,1,1,1,1,1,1,1,1,1,1,1,1,1,1,1,1,1,1,1,1,1,1,1,1,1,1,1,1,1,1,1,1,1,1,1
1,1,1,1,1,1,1,1,1,1,1,1,1,1,1,1,1,1,1,1,1,1,1,1,1,1,1,1,1,1,1,1,1,1,1,1,1
1,1,1,1,1,1,1,1,1,1,1,1,1,1,1,1,1,1,1,1,1,1,1,1,1,1,1,1,1,1,1,1,1,1,1,1,1
1,1,1,1,1,1,1,1,1,1,1,1,1,1,1,1,1,1,1,1,1,1,1,1,1,1,1,1,1,1,1,1,1,1,1,1,1
1,1,1,1,1,1,1,1,1,1,1,1,1,1,1,1,1,1,1,1,1,1,1,1,1,1,1,1,1,1,1,1,1,1,1,1,1
:endlayer
layer: 3
2,2,2,2,2,2,2,2,2,2,2,2,2,2,2,2,2,2,2,2,2,2,2,2,2,2,2,2,2,2,2,2,2,2,2,2,2
2,2,2,2,2,2,2,2,2,2,2,2,2,2,2,2,2,2,2,2,2,2,2,2,2,2,2,2,2,2,2,2,2,2,2,2,2
2,2,2,2,2,2,2,2,2,2,2,2,2,2,2,2,2,2,2,2,2,2,2,2,2,2,2,2,2,2,2,2,2,2,2,2,2
2,2,2,2,2,2,2,2,2,2,2,2,2,2,2,2,2,2,2,2,2,2,2,2,2,2,2,2,2,2,2,2,2,2,2,2,2
2,2,2,2,2,2,2,2,2,2,2,2,2,2,2,2,2,2,2,2,2,2,2,2,2,2,2,2,2,2,2,2,2,2,2,2,2
2,2,2,2,2,2,2,2,2,2,2,2,2,2,2,2,2,2,2,2,2,2,2,2,2,2,2,2,2,2,2,2,2,2,2,2,2
2,2,2,2,2,2,2,2,2,2,2,2,2,2,2,2,2,2,2,2,2,2,2,2,2,2,2,2,2,2,2,2,2,2,2,2,2
2,2,2,2,2,2,2,2,2,2,2,2,2,2,2,2,2,2,2,2,2,2,2,2,2,2,2,2,2,2,2,2,2,2,2,2,2
2,2,2,2,2,2,2,2,2,2,2,2,2,2,2,2,2,2,2,2,2,2,2,2,2,2,2,2,2,2,2,2,2,2,2,2,2
2,2,2,2,2,2,2,2,2,2,2,2,2,2,2,2,2,2,2,2,2,2,2,2,2,2,2,2,2,2,2,2,2,2,2,2,2
2,2,2,2,2,2,2,2,2,2,2,2,2,2,2,2,2,2,2,2,2,2,2,2,2,2,2,2,2,2,2,2,2,2,2,2,2
2,2,2,2,2,2,2,2,2,2,2,2,2,2,2,2,2,2,2,2,2,2,2,2,2,2,2,2,2,2,2,2,2,2,2,2,2
2,2,2,2,2,2,2,2,2,2,2,2,2,2,2,2,2,2,2,2,2,2,2,2,2,2,2,2,2,2,2,2,2,2,2,2,2
2,2,2,2,2,2,2,2,2,2,2,2,2,2,2,2,2,2,2,2,2,2,2,2,2,2,2,2,2,2,2,2,2,2,2,2,2
2,2,2,2,2,2,2,2,2,2,2,2,2,2,2,2,2,2,2,2,2,2,2,2,2,2,2,2,2,2,2,2,2,2,2,2,2
2,2,2,2,2,2,2,2,2,2,2,2,2,2,2,2,2,2,2,2,2,2,2,2,2,2,2,2,2,2,2,2,2,2,2,2,2
2,2,2,2,2,2,2,2,2,2,2,2,2,2,2,2,2,2,2,2,2,2,2,2,2,2,2,2,2,2,2,2,2,2,2,2,2
2,2,2,2,2,2,2,2,2,2,2,2,2,2,2,2,2,2,2,2,2,2,2,2,2,2,2,2,2,2,2,2,2,2,2,2,2
2,2,2,2,2,2,2,2,2,2,2,2,2,2,2,2,2,2,2,2,2,2,2,2,2,2,2,2,2,2,2,2,2,2,2,2,2
2,2,2,2,2,2,2,2,2,2,2,2,2,2,2,2,2,2,2,2,2,2,2,2,2,2,2,2,2,2,2,2,2,2,2,2,2
2,2,2,2,2,2,2,2,2,2,2,2,2,2,2,2,2,2,2,2,2,2,2,2,2,2,2,2,2,2,2,2,2,2,2,2,2
2,2,2,2,2,2,2,2,2,2,2,2,2,2,2,2,2,2,2,2,2,2,2,2,2,2,2,2,2,2,2,2,2,2,2,2,2
2,2,2,2,2,2,2,2,2,2,2,2,2,2,2,2,2,2,2,2,2,2,2,2,2,2,2,2,2,2,2,2,2,2,2,2,2
2,2,2,2,2,2,2,2,2,2,2,2,2,2,2,2,2,2,2,2,2,2,2,2,2,2,2,2,2,2,2,2,2,2,2,2,2
2,2,2,2,2,2,2,2,2,2,2,2,2,2,2,2,2,2,2,2,2,2,2,2,2,2,2,2,2,2,2,2,2,2,2,2,2
2,2,2,2,2,2,2,2,2,2,2,2,2,2,2,2,2,2,2,2,2,2,2,2,2,2,2,2,2,2,2,2,2,2,2,2,2
2,2,2,2,2,2,2,2,2,2,2,2,2,2,2,2,2,2,2,2,2,2,2,2,2,2,2,2,2,2,2,2,2,2,2,2,2
2,2,2,2,2,2,2,2,2,2,2,2,2,2,2,2,2,2,2,2,2,2,2,2,2,2,2,2,2,2,2,2,2,2,2,2,2
2,2,2,2,2,2,2,2,2,2,2,2,2,2,2,2,2,2,2,2,2,2,2,2,2,2,2,2,2,2,2,2,2,2,2,2,2
2,2,2,2,2,2,2,2,2,2,2,2,2,2,2,2,2,2,2,2,2,2,2,2,2,2,2,2,2,2,2,2,2,2,2,2,2
2,2,2,2,2,2,3,2,2,2,2,2,2,2,2,2,2,2,3,2,2,2,2,2,2,2,2,2,2,2,3,2,2,2,2,2,2
2,2,2,2,2,2,2,2,2,2,2,2,2,2,2,2,2,2,2,2,2,2,2,2,2,2,2,2,2,2,2,2,2,2,2,2,2
2,2,2,2,2,2,2,2,2,2,2,2,2,2,2,2,2,2,2,2,2,2,2,2,2,2,2,2,2,2,2,2,2,2,2,2,2
2,2,2,2,2,2,2,2,2,2,2,2,2,2,2,2,2,2,2,2,2,2,2,2,2,2,2,2,2,2,2,2,2,2,2,2,2
2,2,2,2,2,2,2,2,2,2,2,2,2,2,2,2,2,2,2,2,2,2,2,2,2,2,2,2,2,2,2,2,2,2,2,2,2
2,2,2,2,2,2,2,2,2,2,2,2,2,2,2,2,2,2,2,2,2,2,2,2,2,2,2,2,2,2,2,2,2,2,2,2,2
2,2,2,2,2,2,2,2,2,2,2,2,2,2,2,2,2,2,2,2,2,2,2,2,2,2,2,2,2,2,2,2,2,2,2,2,2
:endlayer
layer: 4
4,4,4,4,4,4,4,4,4,4,4,4,4,4,4,4,4,4,4,4,4,4,4,4,4,4,4,4,4,4,4,4,4,4,4,4,4
4,3,4,4,4,4,4,4,4,4,4,4,4,4,4,4,4,4,3,4,4,4,4,4,4,4,4,4,4,4,4,4,4,4,4,4,4
4,4,4,4,4,4,4,4,4,4,4,4,4,4,4,4,4,4,4,4,4,4,4,5,5,5,5,4,4,4,4,3,6,6,3,4,4
4,4,4,4,4,4,4,4,4,4,2,4,4,4,4,4,4,4,3,6,6,6,3,5,5,5,5,3,6,6,6,7,8,8,7,4,4
4,4,4,4,4,4,4,4,4,4,4,4,4,4,4,4,4,4,7,8,8,8,8,5,5,5,5,8,8,8,8,7,8,8,7,4,4
4,4,4,4,4,4,4,4,4,4,4,4,4,4,4,4,4,4,7,8,8,8,8,8,8,8,8,8,8,8,8,3,6,6,3,4,4
4,3,4,4,4,4,4,4,4,3,4,4,4,4,4,4,4,4,7,8,8,8,8,8,8,8,8,8,8,8,8,8,8,7,4,4,4
4,4,4,4,4,4,4,4,4,3,6,6,3,6,6,3,6,6,3,8,8,8,8,8,8,8,8,8,8,8,8,8,8,7,4,4,4
4,4,4,2,4,9,9,9,9,7,10,10,4,5,4,11,10,5,7,8,8,8,8,8,8,8,8,8,8,8,8,8,8,7,4,4,4
4,4,4,4,4,9,9,9,9,7,11,5,10,5,5,4,4,5,7,8,8,8,8,8,8,8,8,8,8,8,8,8,8,7,4,4,4
4,4,4,4,4,9,9,9,9,7,11,4,5,11,4,11,4,10,7,8,8,8,8,8,3,6,6,3,6,6,3,6,6,3,4,3,4
4,4,4,4,4,9,9,9,9,7,4,4,11,11,4,5,10,10,7,8,8,8,8,8,7,4,4,4,9,9,4,4,4,4,4,4,4
4,4,4,4,4,9,9,9,4,3,6,6,3,6,6,3,6,6,3,8,8,8,8,8,7,4,4,4,9,9,4,4,4,4,4,4,4
4,4,4,4,4,9,9,9,4,4,4,4,4,4,4,7,8,8,8,8,8,8,8,8,7,4,4,4,9,9,4,4,4,4,4,4,4
4,4,4,4,4,9,9,9,4,4,4,4,4,4,4,7,8,8,8,8,8,8,8,8,7,4,4,4,9,9,4,4,4,4,4,4,4
4,4,4,4,4,9,9,9,4,4,4,4,4,4,4,7,8,8,8,8,8,8,8,8,7,4,4,4,9,9,4,4,2,4,4,4,4
4,4,4,4,4,9,9,9,4,4,4,4,4,4,4,3,6,6,3,6,6,3,6,6,3,4,4,4,9,9,4,4,4,4,4,4,4
4,4,4,2,4,9,9,9,4,4,4,4,4,4,4,4,4,4,7,8,8,7,4,4,4,4,4,4,9,9,4,4,4,4,4,4,4
4,4,4,4,4,9,9,9,4,4,4,4,4,4,4,4,4,4,7,8,8,7,4,4,4,4,4,4,9,9,4,4,4,4,4,4,4
4,4,4,4,4,9,9,9,4,3,4,4,4,4,4,4,4,4,3,6,6,3,4,4,4,4,4,3,9,9,3,4,4,4,4,3,4
4,4,4,4,4,9,9,9,4,4,4,4,4,4,4,4,4,4,4,9,9,4,4,4,4,4,4,4,9,9,4,4,4,4,4,4,4
9,9,9,9,9,9,9,9,9,9,9,9,9,9,9,9,9,9,9,9,9,9,9,9,9,9,9,9,9,9,9,9,9,9,9,9,9
9,9,9,9,9,9,9,9,9,9,9,9,9,9,9,9,9,9,9,9,9,9,9,9,9,9,9,9,9,9,9,9,9,9,9,9,9
9,9,9,9,9,9,9,9,9,9,9,9,9,9,9,9,9,9,9,9,9,9,9,9,9,9,9,9,9,9,9,9,9,9,9,9,9
4,4,4,4,4,4,4,4,4,4,4,4,4,4,4,4,4,4,4,4,4,4,4,4,4,4,4,4,4,4,4,4,4,4,4,4,4
4,3,4,4,4,4,4,4,4,4,4,3,4,3,4,4,4,4,4,4,4,4,4,3,4,3,4,4,4,4,4,4,4,4,4,3,4
4,4,12,12,12,12,12,12,12,12,12,4,4,4,12,12,12,12,12,12,12,12,12,4,4,4,12,12,12,12,12,12,12,12,12,4,4
4,4,12,12,12,12,12,12,12,12,12,4,4,4,12,12,12,12,12,12,12,12,12,4,4,4,12,12,12,12,12,12,12,12,12,4,4
4,4,12,12,12,12,12,12,12,12,12,4,4,4,12,12,12,12,12,12,12,12,12,4,4,4,12,12,12,12,12,12,12,12,12,4,4
4,4,12,12,12,12,12,12,12,12,12,4,4,4,12,12,12,12,12,12,12,12,12,4,4,4,12,12,12,12,12,12,12,12,12,4,4
4,4,12,12,12,12,13,12,12,12,12,4,4,4,12,12,12,12,13,12,12,12,12,4,4,4,12,12,12,12,13,12,12,12,12,4,4
4,4,12,12,12,12,12,12,12,12,12,4,4,4,12,12,12,12,12,12,12,12,12,4,4,4,12,12,12,12,12,12,12,12,12,4,4
4,4,12,12,12,12,12,12,12,12,12,4,4,4,12,12,12,12,12,12,12,12,12,4,4,4,12,12,12,12,12,12,12,12,12,4,4
4,4,12,12,12,12,12,12,12,12,12,4,4,4,12,12,12,12,12,12,12,12,12,4,4,4,12,12,12,12,12,12,12,12,12,4,4
4,4,12,12,12,12,12,12,12,12,12,4,4,4,12,12,12,12,12,12,12,12,12,4,4,4,12,12,12,12,12,12,12,12,12,4,4
4,3,4,4,4,4,4,4,4,4,4,3,4,3,4,4,4,4,4,4,4,4,4,3,4,3,4,4,4,4,4,4,4,4,4,3,4
4,4,4,4,4,4,4,4,4,4,4,4,4,4,4,4,4,4,4,4,4,4,4,4,4,4,4,4,4,4,4,4,4,4,4,4,4
:endlayer
layer: 5
14,14,14,0,0,0,14,14,14,14,0,0,0,14,14,0,0,0,0,0,14,14,14,14,15,0,0,14,14,14,14,0,0,16,14,16,14
14,3,17,17,17,17,17,17,17,17,17,17,17,17,17,17,17,17,3,0,14,15,14,14,0,0,0,0,15,14,14,16,0,15,18,14,14
14,17,0,19,19,14,14,14,0,14,0,0,14,14,0,14,0,0,17,0,14,0,16,5,5,5,5,14,18,14,14,3,20,20,3,14,14
14,17,0,21,21,14,14,14,14,0,3,14,14,14,14,14,0,0,3,22,22,22,3,5,23,23,5,3,22,22,22,20,0,0,20,14,0
14,17,16,21,21,14,14,14,14,24,16,14,14,0,14,14,0,0,22,0,25,21,26,5,27,27,5,28,29,30,30,20,0,0,20,0,14
14,17,0,19,19,14,0,14,0,0,0,14,14,14,14,0,0,0,31,0,0,0,0,0,0,0,0,0,32,0,0,3,33,20,3,14,0
0,3,17,17,17,17,17,17,17,3,14,0,14,14,0,0,0,0,22,0,0,0,0,0,0,0,0,0,0,0,0,0,0,22,14,14,14
0,14,0,0,0,0,0,0,0,3,34,34,3,34,34,3,34,34,3,35,0,0,0,36,21,21,36,0,0,0,0,37,38,22,14,14,14
14,16,0,3,14,0,0,0,0,39,0,0,0,0,0,0,0,0,20,40,0,0,0,36,21,21,36,0,0,0,0,37,38,22,41,14,14
0,14,14,14,14,0,0,0,0,42,0,0,0,0,43,0,0,0,44,0,0,0,0,36,21,21,36,45,0,0,0,46,47,22,0,14,14
0,14,14,14,14,0,0,0,0,48,0,0,0,0,0,0,0,0,44,0,0,0,49,50,3,22,22,3,33,33,3,22,22,3,17,3,0
0,14,14,14,14,0,0,0,0,51,0,0,0,0,0,0,0,0,20,52,0,0,37,38,22,0,0,0,0,0,0,0,0,14,0,17,14
0,14,14,53,0,0,0,0,0,3,54,54,3,54,54,3,20,20,3,55,0,0,0,26,22,0,0,0,0,0,36,21,21,36,14,17,14
14,14,14,0,0,0,0,0,14,17,14,0,0,0,0,22,56,57,26,0,58,0,37,38,22,14,14,0,0,0,36,21,21,36,0,17,41
14,14,14,14,0,0,0,0,14,17,25,21,25,0,0,31,0,0,0,0,0,0,37,38,22,14,59,14,0,0,0,0,0,14,0,17,0
14,14,14,14,0,0,0,0,14,17,41,14,60,14,0,22,21,25,0,0,0,0,0,26,22,14,14,14,0,0,0,0,3,0,0,17,0
14,14,14,14,0,0,0,0,14,17,14,14,14,14,0,3,54,54,3,0,0,3,54,54,3,14,61,14,0,0,0,0,0,0,14,17,14
0,14,14,3,0,0,0,0,0,17,14,0,62,14,0,0,0,0,20,63,0,20,0,0,0,0,14,16,0,0,14,0,14,14,14,17,0
14,14,14,14,0,0,0,0,0,17,0,14,18,0,14,14,0,0,20,0,0,20,0,14,0,0,0,14,0,0,0,14,14,14,14,17,64
14,14,14,14,14,0,0,0,14,3,17,17,17,17,17,17,17,17,3,33,33,3,17,17,17,17,17,3,0,0,3,17,17,17,17,3,14
14,0,18,59,65,0,0,0,14,14,41,14,14,16,14,14,0,0,66,0,0,14,14,18,0,0,0,0,0,0,14,14,14,0,14,18,0
0,0,0,0,0,0,0,0,0,0,0,0,0,0,0,0,0,0,0,0,0,0,0,0,0,0,0,0,0,0,0,0,0,0,0,0,0
0,0,0,0,0,0,0,0,0,0,0,0,0,0,0,0,0,0,0,0,0,0,0,0,0,0,0,0,0,0,0,0,0,0,0,0,0
0,0,0,0,0,0,0,0,0,0,0,0,0,0,0,0,0,0,0,0,0,0,0,0,0,0,0,0,0,0,0,0,0,0,0,0,0
0,0,0,0,41,14,67,0,0,0,0,14,68,0,18,14,14,18,69,14,14,14,14,14,14,14,0,0,0,14,70,14,0,0,0,0,14
0,3,17,17,17,17,71,17,17,17,17,3,0,3,17,17,17,17,71,17,17,17,17,3,14,3,17,17,17,17,71,17,17,17,17,3,14
0,17,72,72,72,72,72,72,72,72,72,17,14,17,73,73,73,73,73,73,73,73,73,17,14,17,74,74,74,74,74,74,74,74,74,17,0
14,17,72,72,72,72,72,72,72,72,72,17,41,17,73,73,73,73,73,73,73,73,73,17,14,17,74,74,74,74,74,74,74,74,74,17,0
0,17,72,72,72,72,72,72,72,72,72,17,14,17,73,73,73,73,73,73,73,73,73,17,14,17,74,74,74,74,74,74,74,74,74,17,14
14,17,72,72,72,72,72,72,72,72,72,17,14,17,73,73,73,73,73,73,73,73,73,17,14,17,74,74,74,74,74,74,74,74,74,17,14
75,76,72,72,72,72,77,72,72,72,72,78,79,78,73,73,73,73,77,73,73,73,73,78,80,78,74,74,74,74,77,74,74,74,74,78,81
14,17,72,72,72,72,72,72,72,72,72,17,14,17,73,73,73,73,73,73,73,73,73,17,18,17,74,74,74,74,74,74,74,74,74,17,14
14,17,72,72,72,72,72,72,72,72,72,17,14,17,73,73,73,73,73,73,73,73,73,17,14,17,74,74,74,74,74,74,74,74,74,17,14
14,17,72,72,72,72,72,72,72,72,72,17,14,17,73,73,73,73,73,73,73,73,73,17,18,17,74,74,74,74,74,74,74,74,74,17,14
14,17,72,72,72,72,72,72,72,72,72,17,0,17,73,73,73,73,73,73,73,73,73,17,14,17,74,74,74,74,74,74,74,74,74,17,14
18,3,17,17,17,17,82,17,17,17,17,3,14,3,17,17,17,17,82,17,17,17,17,3,14,3,17,17,17,17,82,17,17,17,17,3,14
0,0,0,14,0,14,83,0,0,41,18,14,14,14,0,0,0,14,84,14,0,0,0,14,14,16,14,14,0,14,85,14,14,0,16,14,0
:endlayer
layer: 6
0,0,0,0,0,0,0,0,0,0,0,0,0,0,0,0,0,0,0,0,0,0,0,0,0,0,0,0,0,0,0,0,0,0,0,0,0
0,77,0,0,0,0,0,0,0,0,0,0,0,0,0,0,0,0,77,0,0,0,0,0,0,0,0,0,0,0,0,0,0,0,0,0,0
0,0,0,0,0,0,0,0,0,0,0,0,0,0,0,0,0,0,0,0,0,0,0,5,5,5,5,0,0,0,0,3,86,86,3,0,0
0,0,0,0,0,0,0,0,0,0,3,0,0,0,0,0,0,0,3,22,86,22,3,5,0,0,5,3,22,86,22,20,0,0,86,0,0
0,0,0,0,0,0,0,0,0,0,0,0,0,0,0,0,0,0,22,0,0,0,0,87,0,0,87,0,0,0,0,20,0,0,86,0,0
0,0,0,0,0,0,0,0,0,0,0,0,0,0,0,0,0,0,88,0,0,0,0,0,0,0,0,0,0,0,0,3,88,20,3,0,0
0,77,0,0,0,0,0,0,0,77,0,0,0,0,0,0,0,0,22,0,0,0,0,0,0,0,0,0,0,0,0,0,0,22,0,0,0
0,0,0,0,0,0,0,0,0,3,34,34,3,34,34,3,34,34,3,0,0,0,0,0,0,0,0,0,0,0,0,0,0,86,0,0,0
0,0,0,3,0,0,0,0,0,89,0,0,0,0,0,0,0,0,20,0,0,0,0,0,0,0,0,0,0,0,0,0,0,86,0,0,0
0,0,0,0,0,0,0,0,0,90,0,0,0,0,0,0,0,0,88,0,0,0,0,0,0,0,0,0,0,0,0,0,0,22,0,0,0
0,0,0,0,0,0,0,0,0,91,0,0,0,0,0,0,0,0,92,0,0,0,0,0,3,86,86,3,92,88,3,86,86,3,0,77,0
0,0,0,0,0,0,0,0,0,93,0,0,0,0,0,0,0,0,20,0,0,0,0,0,22,0,0,0,0,0,0,0,0,0,0,0,0
0,0,0,0,0,0,0,0,0,3,54,54,3,54,54,3,20,20,3,0,0,0,0,0,86,0,0,0,0,0,0,0,0,0,0,0,0
0,0,0,0,0,0,0,0,0,0,0,0,0,0,0,22,94,95,0,0,0,0,0,0,22,0,0,0,0,0,0,0,0,0,0,0,0
0,0,0,0,0,0,0,0,0,0,0,0,0,0,0,92,0,0,0,0,0,0,0,0,86,0,0,0,0,0,0,0,0,0,0,0,0
0,0,0,0,0,0,0,0,0,0,0,0,0,0,0,22,0,0,0,0,0,0,0,0,22,0,0,0,0,0,0,0,3,0,0,0,0
0,0,0,0,0,0,0,0,0,0,0,0,0,0,0,3,54,54,3,0,0,3,54,54,3,0,0,0,0,0,0,0,0,0,0,0,0
0,0,0,3,0,0,0,0,0,0,0,0,0,0,0,0,0,0,86,0,0,86,0,0,0,0,0,0,0,0,0,0,0,0,0,0,0
0,0,0,0,0,0,0,0,0,0,0,0,0,0,0,0,0,0,86,0,0,86,0,0,0,0,0,0,0,0,0,0,0,0,0,0,0
0,0,0,0,0,0,0,0,0,77,0,0,0,0,0,0,0,0,3,92,88,3,0,0,0,0,0,3,0,0,3,0,0,0,0,77,0
0,0,0,0,0,0,0,0,0,0,0,0,0,0,0,0,0,0,0,0,0,0,0,0,0,0,0,0,0,0,0,0,0,0,0,0,0
0,0,0,0,0,0,0,0,0,0,0,0,0,0,0,0,0,0,0,0,0,0,0,0,0,0,0,0,0,0,0,0,0,0,0,0,0
0,0,0,0,0,0,0,0,0,0,0,0,0,0,0,0,0,0,0,0,0,0,0,0,0,0,0,0,0,0,0,0,96,0,0,0,0
0,0,0,0,0,0,0,0,0,0,0,0,0,0,0,0,0,0,0,0,0,0,0,0,0,0,0,0,0,0,0,0,0,0,0,0,0
0,0,0,0,0,0,0,0,0,0,0,0,0,0,0,0,0,0,0,0,0,0,0,0,0,0,0,0,0,0,0,0,0,0,0,0,0
0,77,0,0,97,0,0,0,97,0,0,77,0,77,0,0,97,0,0,0,97,0,0,77,0,77,0,0,97,0,0,0,97,0,0,77,0
0,0,0,0,0,0,0,0,0,0,0,0,0,0,0,0,0,0,0,0,0,0,0,0,0,0,0,0,0,0,0,0,0,0,0,0,0
0,0,0,0,0,0,0,0,0,0,0,0,0,0,0,0,0,0,0,0,0,0,0,0,0,0,0,0,0,0,0,0,0,0,0,0,0
0,97,0,0,0,0,0,0,0,0,0,97,0,97,0,0,0,0,0,0,0,0,0,97,0,97,0,0,0,0,0,0,0,0,0,97,0
0,0,0,0,0,0,0,0,0,0,0,0,0,0,0,0,0,0,0,0,0,0,0,0,0,0,0,0,0,0,0,0,0,0,0,0,0
0,0,0,0,0,0,0,0,0,0,0,0,0,0,0,0,0,0,98,0,0,0,0,0,0,0,0,0,0,0,99,0,0,0,0,0,0
0,0,0,0,0,0,0,0,0,0,0,0,0,0,0,0,0,0,0,0,0,0,0,0,0,0,0,0,0,0,0,0,0,0,0,0,0
0,97,0,0,0,0,0,0,0,0,0,97,0,97,0,0,0,0,0,0,0,0,0,97,0,97,0,0,0,0,0,0,0,0,0,97,0
0,0,0,0,0,0,0,0,0,0,0,0,0,0,0,0,0,0,0,0,0,0,0,0,0,0,0,0,0,0,0,0,0,0,0,0,0
0,0,0,0,0,0,0,0,0,0,0,0,0,0,0,0,0,0,0,0,0,0,0,0,0,0,0,0,0,0,0,0,0,0,0,0,0
0,77,0,0,97,0,0,0,97,0,0,77,0,77,0,0,97,0,0,0,97,0,0,77,0,77,0,0,97,0,0,0,97,0,0,77,0
0,0,0,0,0,0,0,0,0,0,0,0,0,0,0,0,0,0,0,0,0,0,0,0,0,0,0,0,0,0,0,0,0,0,0,0,0
:endlayer
layer: 7
0,0,0,0,0,0,0,0,0,0,0,0,0,0,0,0,0,0,0,0,0,0,0,0,0,0,0,0,0,0,0,0,0,0,0,0,0
0,0,0,0,0,0,0,0,0,0,0,0,0,0,0,0,0,0,0,0,0,0,0,0,0,0,0,0,0,0,0,100,0,0,100,0,0
0,0,0,0,0,0,0,0,0,0,0,0,0,0,0,0,0,0,100,0,0,0,100,101,5,5,101,100,0,0,102,3,86,86,3,103,0
0,0,0,0,0,0,0,0,0,0,3,0,0,0,0,0,0,102,3,22,86,22,3,5,104,104,5,3,22,86,22,20,0,0,86,0,0
0,0,0,0,0,0,0,0,0,0,0,0,0,0,0,0,0,0,22,0,0,0,0,27,105,105,27,0,0,0,0,20,0,0,86,0,0
0,0,0,0,0,0,0,0,0,0,0,0,0,0,0,0,0,0,22,0,0,0,0,0,0,0,0,0,0,0,0,3,20,20,3,103,0
0,0,0,0,0,0,0,0,0,100,0,0,100,0,0,100,0,0,22,0,0,0,0,0,0,0,0,0,0,0,0,0,0,22,106,0,0
0,0,0,0,0,0,0,0,102,3,34,34,3,34,34,3,34,34,3,0,0,0,0,0,0,0,0,0,0,0,0,0,0,86,0,0,0
0,0,0,3,0,0,0,0,0,107,0,0,0,0,0,0,0,0,20,0,0,0,0,0,0,0,0,0,0,0,0,0,0,86,0,0,0
0,0,0,0,0,0,0,0,0,108,0,0,0,0,0,0,0,0,20,0,0,0,0,0,0,0,0,0,0,0,0,0,0,22,0,0,0
0,0,0,0,0,0,0,0,0,109,0,0,0,0,0,0,0,0,20,0,0,0,0,0,3,86,86,3,22,22,3,86,86,3,103,0,0
0,0,0,0,0,0,0,0,0,110,0,0,0,0,0,0,0,0,20,0,0,0,0,0,22,0,0,106,0,0,106,0,0,106,0,0,0
0,0,0,0,0,0,0,0,102,3,54,54,3,54,54,3,20,20,3,0,0,0,0,0,86,0,0,0,0,0,0,0,0,0,0,0,0
0,0,0,0,0,0,0,0,0,106,0,0,106,0,0,22,0,0,0,0,0,0,0,0,22,0,0,0,0,0,111,111,111,111,111,0,0
0,0,0,0,0,0,0,0,0,0,0,0,0,0,0,22,0,0,0,0,0,0,0,0,86,0,0,0,0,0,111,111,111,111,111,0,0
0,0,0,0,0,0,0,0,0,0,0,0,0,0,0,22,0,0,0,0,0,0,0,0,22,0,0,0,0,0,111,111,3,111,111,0,0
0,0,0,0,0,0,0,0,0,0,0,0,0,0,102,3,54,54,3,0,0,3,54,54,3,103,0,0,0,0,111,111,111,111,111,0,0
0,0,0,3,0,0,0,0,0,0,0,0,0,0,0,106,0,0,86,0,0,86,0,0,106,0,0,0,0,0,111,111,111,111,111,0,0
0,0,0,0,0,0,0,0,0,0,0,0,0,0,0,0,0,0,86,0,0,86,0,0,0,0,0,0,0,0,0,0,0,0,0,0,0
0,0,0,0,0,0,0,0,0,0,0,0,0,0,0,0,0,102,3,20,20,3,103,0,0,0,0,77,0,0,77,0,0,0,0,0,0
0,0,0,0,0,0,0,0,0,0,0,0,0,0,0,0,0,0,0,0,0,0,0,0,0,0,0,0,0,0,0,0,0,0,0,0,0
0,0,0,0,0,0,0,0,0,0,0,0,0,0,0,0,0,0,0,0,0,0,0,0,0,0,0,0,0,0,0,0,0,0,0,0,0
0,0,0,0,0,0,0,0,0,0,0,0,0,0,0,0,0,0,0,0,0,0,0,0,0,0,0,0,0,0,0,0,0,0,0,0,0
0,0,0,0,0,0,0,0,0,0,0,0,0,0,0,0,0,0,0,0,0,0,0,0,0,0,0,0,0,0,0,0,0,0,0,0,0
0,0,0,0,0,0,0,0,0,0,0,0,0,0,0,0,0,0,0,0,0,0,0,0,0,0,0,0,0,0,0,0,0,0,0,0,0
0,0,0,0,0,0,0,0,0,0,0,0,0,0,0,0,0,0,0,0,0,0,0,0,0,0,0,0,0,0,0,0,0,0,0,0,0
0,0,0,0,0,0,0,0,0,0,0,0,0,0,0,0,0,0,0,0,0,0,0,0,0,0,0,0,0,0,0,0,0,0,0,0,0
0,0,0,0,0,0,0,0,0,0,0,0,0,0,0,0,0,0,0,0,0,0,0,0,0,0,0,0,0,0,0,0,0,0,0,0,0
0,0,0,0,0,0,0,0,0,0,0,0,0,0,0,0,0,0,0,0,0,0,0,0,0,0,0,0,0,0,0,0,0,0,0,0,0
0,0,0,0,0,0,0,0,0,0,0,0,0,0,0,0,0,0,0,0,0,0,0,0,0,0,0,0,0,0,0,0,0,0,0,0,0
0,0,0,0,0,0,0,0,0,0,0,0,0,0,0,0,0,0,0,0,0,0,0,0,0,0,0,0,0,0,0,0,0,0,0,0,0
0,0,0,0,0,0,0,0,0,0,0,0,0,0,0,0,0,0,0,0,0,0,0,0,0,0,0,0,0,0,0,0,0,0,0,0,0
0,0,0,0,0,0,0,0,0,0,0,0,0,0,0,0,0,0,0,0,0,0,0,0,0,0,0,0,0,0,0,0,0,0,0,0,0
0,0,0,0,0,0,0,0,0,0,0,0,0,0,0,0,0,0,0,0,0,0,0,0,0,0,0,0,0,0,0,0,0,0,0,0,0
0,0,0,0,0,0,0,0,0,0,0,0,0,0,0,0,0,0,0,0,0,0,0,0,0,0,0,0,0,0,0,0,0,0,0,0,0
0,0,0,0,0,0,0,0,0,0,0,0,0,0,0,0,0,0,0,0,0,0,0,0,0,0,0,0,0,0,0,0,0,0,0,0,0
0,0,0,0,0,0,0,0,0,0,0,0,0,0,0,0,0,0,0,0,0,0,0,0,0,0,0,0,0,0,0,0,0,0,0,0,0
:endlayer
layer: 8
0,0,0,0,0,0,0,0,0,0,0,0,0,0,0,0,0,0,0,0,0,0,0,0,0,0,0,0,0,0,0,0,0,0,0,0,0
0,0,0,0,0,0,0,0,111,111,111,111,111,0,0,0,0,0,0,0,0,0,0,0,0,0,0,0,0,0,0,0,0,0,0,0,0
0,0,0,0,0,0,0,0,111,111,111,111,111,0,0,0,0,112,112,112,112,112,112,112,5,5,112,112,112,112,112,3,6,6,3,0,0
0,0,0,0,0,0,0,0,111,111,3,111,111,0,0,0,0,0,3,6,6,6,6,6,6,6,6,6,6,6,6,7,0,0,7,0,0
0,0,0,0,0,0,0,0,111,111,111,111,111,0,0,0,0,0,7,0,0,0,106,0,0,0,0,106,0,0,0,7,0,0,7,0,0
0,0,0,0,0,0,0,0,0,111,111,111,0,0,0,0,0,0,7,0,0,0,0,0,0,0,0,0,0,0,102,3,6,6,3,0,0
0,0,111,111,111,0,0,0,112,112,112,112,112,112,112,112,112,112,7,0,0,0,0,0,0,0,0,0,0,0,0,106,0,7,0,0,0
0,111,111,111,111,111,0,0,0,3,6,6,6,6,6,6,6,6,7,103,0,0,0,0,0,0,0,0,0,0,0,0,0,7,0,0,0
0,111,111,3,111,111,0,0,0,7,103,0,106,0,0,106,0,102,7,0,0,0,0,0,0,0,0,0,0,0,0,0,0,7,0,0,0
0,111,111,111,111,111,0,0,0,7,0,0,0,0,0,0,0,0,7,0,0,0,0,0,100,0,0,100,0,0,100,0,0,7,0,0,0
0,111,111,111,111,0,0,0,0,7,0,0,0,0,0,0,0,0,7,0,0,0,0,102,3,6,6,6,6,6,6,6,6,3,0,0,0
0,0,0,0,0,0,0,0,0,7,103,0,100,0,0,100,0,102,7,0,0,0,0,0,7,112,0,0,0,0,0,0,112,112,112,0,0
0,0,0,0,0,0,0,0,0,3,6,6,6,6,6,6,6,6,3,103,0,0,0,0,7,112,0,0,0,0,0,0,0,0,0,0,0
0,0,0,0,0,0,0,0,112,112,112,112,112,112,112,7,0,0,106,0,0,0,0,0,7,112,0,0,0,0,111,111,111,111,0,0,0
0,0,0,0,0,0,0,0,0,0,0,0,0,0,112,7,0,0,0,0,0,0,0,0,7,112,0,0,0,0,111,111,111,111,111,0,0
0,0,0,0,0,0,0,0,0,0,0,0,0,0,112,7,0,0,100,0,0,100,0,0,7,112,0,0,0,0,111,111,3,111,111,0,0
0,0,0,0,0,0,0,0,0,0,0,0,0,0,112,3,6,6,3,6,6,3,6,6,3,112,0,0,0,0,111,111,111,111,111,0,0
0,0,0,3,0,0,0,0,0,0,0,0,0,0,112,0,0,0,7,0,0,7,0,0,0,112,0,0,0,0,0,111,111,111,0,0,0
0,0,0,0,0,0,0,0,0,0,0,0,0,0,0,0,0,0,7,100,100,7,0,0,0,0,0,0,0,0,0,0,0,0,0,0,0
0,0,0,0,0,0,0,0,0,0,0,0,0,0,0,0,0,0,3,6,6,3,0,0,0,0,0,0,0,0,0,0,0,0,0,0,0
0,0,0,0,0,0,0,0,0,0,0,0,0,0,0,0,0,0,106,0,0,106,0,0,0,0,0,0,0,0,0,0,0,0,0,0,0
0,0,0,0,0,0,0,0,0,0,0,0,0,0,0,0,0,0,0,0,0,0,0,0,0,0,0,0,0,0,0,0,0,0,0,0,0
0,0,0,0,0,0,0,0,0,0,0,0,0,0,0,0,0,0,0,0,0,0,0,0,0,0,0,0,0,0,0,0,0,0,0,0,0
0,0,0,0,0,0,0,0,0,0,0,0,0,0,0,0,0,0,0,0,0,0,0,0,0,0,0,0,0,0,0,0,0,0,0,0,0
0,0,0,0,0,0,0,0,0,0,0,0,0,0,0,0,0,0,0,0,0,0,0,0,0,0,0,0,0,0,0,0,0,0,0,0,0
0,0,0,0,0,0,0,0,0,0,0,0,0,0,0,0,0,0,0,0,0,0,0,0,0,0,0,0,0,0,0,0,0,0,0,0,0
0,0,0,0,0,0,0,0,0,0,0,0,0,0,0,0,0,0,0,0,0,0,0,0,0,0,0,0,0,0,0,0,0,0,0,0,0
0,0,0,0,0,0,0,0,0,0,0,0,0,0,0,0,0,0,0,0,0,0,0,0,0,0,0,0,0,0,0,0,0,0,0,0,0
0,0,0,0,0,0,0,0,0,0,0,0,0,0,0,0,0,0,0,0,0,0,0,0,0,0,0,0,0,0,0,0,0,0,0,0,0
0,0,0,0,0,0,0,0,0,0,0,0,0,0,0,0,0,0,0,0,0,0,0,0,0,0,0,0,0,0,0,0,0,0,0,0,0
0,0,0,0,0,0,0,0,0,0,0,0,0,0,0,0,0,0,0,0,0,0,0,0,0,0,0,0,0,0,0,0,0,0,0,0,0
0,0,0,0,0,0,0,0,0,0,0,0,0,0,0,0,0,0,0,0,0,0,0,0,0,0,0,0,0,0,0,0,0,0,0,0,0
0,0,0,0,0,0,0,0,0,0,0,0,0,0,0,0,0,0,0,0,0,0,0,0,0,0,0,0,0,0,0,0,0,0,0,0,0
0,0,0,0,0,0,0,0,0,0,0,0,0,0,0,0,0,0,0,0,0,0,0,0,0,0,0,0,0,0,0,0,0,0,0,0,0
0,0,0,0,0,0,0,0,0,0,0,0,0,0,0,0,0,0,0,0,0,0,0,0,0,0,0,0,0,0,0,0,0,0,0,0,0
0,0,0,0,0,0,0,0,0,0,0,0,0,0,0,0,0,0,0,0,0,0,0,0,0,0,0,0,0,0,0,0,0,0,0,0,0
0,0,0,0,0,0,0,0,0,0,0,0,0,0,0,0,0,0,0,0,0,0,0,0,0,0,0,0,0,0,0,0,0,0,0,0,0
:endlayer
layer: 9
0,0,0,0,0,0,0,0,0,0,0,0,0,0,0,0,0,0,0,0,0,0,0,0,0,0,0,0,0,0,0,0,0,0,0,0,0
0,0,0,0,0,0,0,0,0,111,111,111,111,0,0,0,0,0,0,0,0,0,0,0,0,0,0,0,0,0,0,0,0,0,0,0,0
0,0,0,0,0,0,0,0,111,111,111,111,111,0,0,0,0,0,0,0,0,0,0,0,5,5,0,0,0,0,0,3,20,20,3,0,0
0,0,0,0,0,0,0,0,111,111,3,111,111,0,0,0,0,77,77,77,77,77,77,77,77,77,77,77,77,77,77,20,0,0,20,0,0
0,0,0,0,0,0,0,0,111,111,111,111,111,0,0,0,0,112,20,112,112,112,112,112,112,112,112,112,112,112,112,20,0,0,20,0,0
0,0,0,0,0,0,0,0,0,111,111,111,0,0,0,0,0,0,20,0,0,0,0,0,0,0,0,0,0,0,0,3,20,20,3,0,0
0,0,111,111,111,111,0,0,0,0,0,0,0,0,0,0,0,0,20,0,0,0,0,0,0,0,0,0,0,0,0,0,0,20,0,0,0
0,111,111,111,111,111,0,0,77,77,77,77,77,77,77,77,77,77,20,0,0,0,0,0,0,0,0,0,0,0,0,0,0,20,0,0,0
0,111,111,3,111,111,0,0,112,20,112,112,112,112,112,112,112,112,20,0,0,0,0,0,0,0,0,0,0,0,0,0,0,20,0,0,0
0,111,111,111,111,111,0,0,0,20,0,0,0,0,0,0,0,0,20,0,0,0,0,112,112,112,112,112,112,112,112,112,112,20,112,0,0
0,111,111,111,111,0,0,0,0,20,0,0,0,0,0,0,0,0,20,0,0,0,0,112,77,77,77,20,20,20,20,77,77,77,77,0,0
0,0,0,0,0,0,0,0,112,20,112,112,112,112,112,112,112,112,20,0,0,0,0,112,77,0,77,112,0,0,112,77,0,0,0,0,0
0,0,0,0,0,0,0,0,77,77,77,77,77,77,77,77,20,20,20,0,0,0,0,112,77,0,0,0,0,0,0,0,0,0,0,0,0
0,0,0,0,0,0,0,0,0,0,0,0,0,0,0,77,112,0,0,0,0,0,0,112,77,0,0,0,0,0,0,0,0,0,0,0,0
0,0,0,0,0,0,0,0,0,0,0,0,0,0,0,77,112,0,0,0,0,0,0,112,77,0,0,0,0,0,0,111,111,111,0,0,0
0,111,111,111,111,0,0,0,0,0,0,0,0,0,0,77,112,0,0,0,0,0,0,112,77,0,0,0,0,0,0,111,3,111,0,0,0
0,111,111,111,111,111,0,0,0,0,0,0,0,0,0,77,20,20,3,20,20,3,20,20,77,0,0,0,0,0,0,111,111,0,0,0,0
0,111,111,3,111,111,0,0,0,0,0,0,0,0,0,77,112,0,86,0,0,86,0,112,77,0,0,0,0,0,0,0,0,0,0,0,0
0,111,111,111,111,111,0,0,0,0,0,0,0,0,0,0,0,0,86,0,0,86,0,0,0,0,0,0,0,0,0,0,0,0,0,0,0
0,111,111,111,111,0,0,0,0,0,0,0,0,0,0,0,0,0,3,86,86,3,0,0,0,0,0,0,0,0,0,0,0,0,0,0,0
0,0,0,0,0,0,0,0,0,0,0,0,0,0,0,0,0,0,0,0,0,0,0,0,0,0,0,0,0,0,0,0,0,0,0,0,0
0,0,0,0,0,0,0,0,0,0,0,0,0,0,0,0,0,0,0,0,0,0,0,0,0,0,0,0,0,0,0,0,0,0,0,0,0
0,0,0,0,0,0,0,0,0,0,0,0,0,0,0,0,0,0,0,0,0,0,0,0,0,0,0,0,0,0,0,0,0,0,0,0,0
0,0,0,0,0,0,0,0,0,0,0,0,0,0,0,0,0,0,0,0,0,0,0,0,0,0,0,0,0,0,0,0,0,0,0,0,0
0,0,0,0,0,0,0,0,0,0,0,0,0,0,0,0,0,0,0,0,0,0,0,0,0,0,0,0,0,0,0,0,0,0,0,0,0
0,0,0,0,0,0,0,0,0,0,0,0,0,0,0,0,0,0,0,0,0,0,0,0,0,0,0,0,0,0,0,0,0,0,0,0,0
0,0,0,0,0,0,0,0,0,0,0,0,0,0,0,0,0,0,0,0,0,0,0,0,0,0,0,0,0,0,0,0,0,0,0,0,0
0,0,0,0,0,0,0,0,0,0,0,0,0,0,0,0,0,0,0,0,0,0,0,0,0,0,0,0,0,0,0,0,0,0,0,0,0
0,0,0,0,0,0,0,0,0,0,0,0,0,0,0,0,0,0,0,0,0,0,0,0,0,0,0,0,0,0,0,0,0,0,0,0,0
0,0,0,0,0,0,0,0,0,0,0,0,0,0,0,0,0,0,0,0,0,0,0,0,0,0,0,0,0,0,0,0,0,0,0,0,0
0,0,0,0,0,0,0,0,0,0,0,0,0,0,0,0,0,0,0,0,0,0,0,0,0,0,0,0,0,0,0,0,0,0,0,0,0
0,0,0,0,0,0,0,0,0,0,0,0,0,0,0,0,0,0,0,0,0,0,0,0,0,0,0,0,0,0,0,0,0,0,0,0,0
0,0,0,0,0,0,0,0,0,0,0,0,0,0,0,0,0,0,0,0,0,0,0,0,0,0,0,0,0,0,0,0,0,0,0,0,0
0,0,0,0,0,0,0,0,0,0,0,0,0,0,0,0,0,0,0,0,0,0,0,0,0,0,0,0,0,0,0,0,0,0,0,0,0
0,0,0,0,0,0,0,0,0,0,0,0,0,0,0,0,0,0,0,0,0,0,0,0,0,0,0,0,0,0,0,0,0,0,0,0,0
0,0,0,0,0,0,0,0,0,0,0,0,0,0,0,0,0,0,0,0,0,0,0,0,0,0,0,0,0,0,0,0,0,0,0,0,0
0,0,0,0,0,0,0,0,0,0,0,0,0,0,0,0,0,0,0,0,0,0,0,0,0,0,0,0,0,0,0,0,0,0,0,0,0
:endlayer
layer: 10
0,0,0,0,0,0,0,0,0,0,0,0,0,0,0,0,0,0,0,0,0,0,0,0,0,0,0,0,0,0,0,0,0,0,0,0,0
0,0,0,0,0,0,0,0,0,0,0,0,0,0,0,0,0,0,0,0,0,0,0,0,0,0,0,0,0,0,0,0,0,0,0,0,0
0,0,0,0,0,0,0,0,0,111,111,0,0,0,0,0,0,0,0,0,0,0,0,0,5,5,0,0,0,0,0,3,86,86,3,0,0
0,0,0,0,0,0,0,0,0,111,3,111,0,0,0,0,0,0,0,0,0,0,0,0,0,0,0,0,0,0,0,86,0,0,86,0,0
0,0,0,0,0,0,0,0,0,111,111,111,0,0,0,0,0,0,0,0,0,0,0,0,0,0,0,0,0,0,0,86,0,0,86,0,0
0,0,0,0,0,0,0,0,0,0,0,0,0,0,0,0,0,77,77,77,77,77,77,77,77,77,77,77,77,77,77,3,20,20,3,0,0
0,0,0,0,0,0,0,0,0,0,0,0,0,0,0,0,0,112,20,112,112,112,112,112,112,112,112,112,112,112,112,112,112,20,112,0,0
0,0,111,111,0,0,0,0,0,0,0,0,0,0,0,0,0,112,20,0,0,112,112,112,112,112,112,112,112,112,112,112,112,20,112,0,0
0,0,111,3,111,0,0,0,0,0,0,0,0,0,0,0,0,77,20,0,0,112,77,77,77,77,77,77,77,77,77,77,77,77,77,0,0
0,0,111,111,111,0,0,0,77,77,77,77,77,77,77,77,77,77,20,0,0,112,77,0,0,0,0,0,77,77,0,0,0,0,0,0,0
0,0,0,0,0,0,0,0,77,77,77,77,77,77,77,77,77,77,20,0,0,112,77,0,0,0,0,0,77,77,0,0,0,0,0,0,0
0,0,0,0,0,0,0,0,0,0,0,0,0,0,0,0,0,77,20,0,0,112,77,0,0,0,0,0,77,77,0,0,0,0,0,0,0
0,0,0,0,0,0,0,0,0,0,0,0,0,0,0,0,0,77,20,0,0,112,77,0,0,0,0,0,0,0,0,0,0,0,0,0,0
0,0,0,0,0,0,0,0,0,0,0,0,0,0,0,0,0,77,112,0,0,112,77,0,0,0,0,0,0,0,0,0,0,0,0,0,0
0,0,0,0,0,0,0,0,0,0,0,0,0,0,0,0,0,77,112,0,0,112,77,0,0,0,0,0,0,0,0,0,111,0,0,0,0
0,0,111,111,111,111,0,0,0,0,0,0,0,0,0,0,0,77,112,0,0,112,77,0,0,0,0,0,0,0,0,111,111,111,0,0,0
0,111,111,111,111,111,0,0,0,0,0,0,0,0,0,0,0,77,3,20,20,3,77,0,0,0,0,0,0,0,0,0,111,0,0,0,0
0,111,111,3,111,111,0,0,0,0,0,0,0,0,0,0,0,77,86,0,0,86,77,0,0,0,0,0,0,0,0,0,0,0,0,0,0
0,111,111,111,111,111,0,0,0,0,0,0,0,0,0,0,0,0,86,0,0,86,0,0,0,0,0,0,0,0,0,0,0,0,0,0,0
0,0,111,111,111,111,0,0,0,0,0,0,0,0,0,0,0,0,3,86,86,3,0,0,0,0,0,0,0,0,0,0,0,0,0,0,0
0,0,0,0,0,0,0,0,0,0,0,0,0,0,0,0,0,0,0,0,0,0,0,0,0,0,0,0,0,0,0,0,0,0,0,0,0
0,0,0,0,0,0,0,0,0,0,0,0,0,0,0,0,0,0,0,0,0,0,0,0,0,0,0,0,0,0,0,0,0,0,0,0,0
0,0,0,0,0,0,0,0,0,0,0,0,0,0,0,0,0,0,0,0,0,0,0,0,0,0,0,0,0,0,0,0,0,0,0,0,0
0,0,0,0,0,0,0,0,0,0,0,0,0,0,0,0,0,0,0,0,0,0,0,0,0,0,0,0,0,0,0,0,0,0,0,0,0
0,0,0,0,0,0,0,0,0,0,0,0,0,0,0,0,0,0,0,0,0,0,0,0,0,0,0,0,0,0,0,0,0,0,0,0,0
0,0,0,0,0,0,0,0,0,0,0,0,0,0,0,0,0,0,0,0,0,0,0,0,0,0,0,0,0,0,0,0,0,0,0,0,0
0,0,0,0,0,0,0,0,0,0,0,0,0,0,0,0,0,0,0,0,0,0,0,0,0,0,0,0,0,0,0,0,0,0,0,0,0
0,0,0,0,0,0,0,0,0,0,0,0,0,0,0,0,0,0,0,0,0,0,0,0,0,0,0,0,0,0,0,0,0,0,0,0,0
0,0,0,0,0,0,0,0,0,0,0,0,0,0,0,0,0,0,0,0,0,0,0,0,0,0,0,0,0,0,0,0,0,0,0,0,0
0,0,0,0,0,0,0,0,0,0,0,0,0,0,0,0,0,0,0,0,0,0,0,0,0,0,0,0,0,0,0,0,0,0,0,0,0
0,0,0,0,0,0,0,0,0,0,0,0,0,0,0,0,0,0,0,0,0,0,0,0,0,0,0,0,0,0,0,0,0,0,0,0,0
0,0,0,0,0,0,0,0,0,0,0,0,0,0,0,0,0,0,0,0,0,0,0,0,0,0,0,0,0,0,0,0,0,0,0,0,0
0,0,0,0,0,0,0,0,0,0,0,0,0,0,0,0,0,0,0,0,0,0,0,0,0,0,0,0,0,0,0,0,0,0,0,0,0
0,0,0,0,0,0,0,0,0,0,0,0,0,0,0,0,0,0,0,0,0,0,0,0,0,0,0,0,0,0,0,0,0,0,0,0,0
0,0,0,0,0,0,0,0,0,0,0,0,0,0,0,0,0,0,0,0,0,0,0,0,0,0,0,0,0,0,0,0,0,0,0,0,0
0,0,0,0,0,0,0,0,0,0,0,0,0,0,0,0,0,0,0,0,0,0,0,0,0,0,0,0,0,0,0,0,0,0,0,0,0
0,0,0,0,0,0,0,0,0,0,0,0,0,0,0,0,0,0,0,0,0,0,0,0,0,0,0,0,0,0,0,0,0,0,0,0,0
:endlayer
layer: 11
0,0,0,0,0,0,0,0,0,0,0,0,0,0,0,0,0,0,0,0,0,0,0,0,0,0,0,0,0,0,0,0,0,0,0,0,0
0,0,0,0,0,0,0,0,0,0,0,0,0,0,0,0,0,0,0,0,0,0,0,0,0,0,0,0,0,0,0,0,0,0,0,0,0
0,0,0,0,0,0,0,0,0,0,111,0,0,0,0,0,0,0,0,0,0,0,0,0,113,5,0,0,0,0,0,3,86,86,3,0,0
0,0,0,0,0,0,0,0,0,111,111,111,0,0,0,0,0,0,0,0,0,0,0,0,0,0,0,0,0,0,0,86,0,0,86,0,0
0,0,0,0,0,0,0,0,0,0,111,0,0,0,0,0,0,0,0,0,0,0,0,0,0,0,0,0,0,0,0,86,0,0,86,0,0
0,0,0,0,0,0,0,0,0,0,0,0,0,0,0,0,0,0,0,0,0,0,0,0,0,0,0,0,0,0,0,3,20,20,3,0,0
0,0,0,0,0,0,0,0,0,0,0,0,0,0,0,0,0,0,0,0,0,0,0,0,0,0,0,0,0,0,0,0,0,0,0,0,0
0,0,0,111,0,0,0,0,0,0,0,0,0,0,0,0,0,0,0,77,77,0,0,0,0,0,0,0,0,0,0,0,0,0,0,0,0
0,0,111,111,111,0,0,0,0,0,0,0,0,0,0,0,0,0,0,77,77,0,0,0,0,0,0,0,0,0,0,0,0,0,0,0,0
0,0,0,111,0,0,0,0,0,0,0,0,0,0,0,0,0,0,0,77,77,0,0,0,0,0,0,0,0,0,0,0,0,0,0,0,0
0,0,0,0,0,0,0,0,0,0,0,0,0,0,0,0,0,0,0,77,77,0,0,0,0,0,0,0,0,0,0,0,0,0,0,0,0
0,0,0,0,0,0,0,0,0,0,0,0,0,0,0,0,0,0,0,77,77,0,0,0,0,0,0,0,0,0,0,0,0,0,0,0,0
0,0,0,0,0,0,0,0,0,0,0,0,0,0,0,0,0,0,0,77,77,0,0,0,0,0,0,0,0,0,0,0,0,0,0,0,0
0,0,0,0,0,0,0,0,0,0,0,0,0,0,0,0,0,0,0,77,77,0,0,0,0,0,0,0,0,0,0,0,0,0,0,0,0
0,0,0,0,0,0,0,0,0,0,0,0,0,0,0,0,0,0,0,77,77,0,0,0,0,0,0,0,0,0,0,0,0,0,0,0,0
0,0,0,0,0,0,0,0,0,0,0,0,0,0,0,0,0,0,112,77,77,112,0,0,0,0,0,0,0,0,0,0,0,0,0,0,0
0,0,0,111,111,0,0,0,0,0,0,0,0,0,0,0,0,112,3,6,6,3,112,0,0,0,0,0,0,0,0,0,0,0,0,0,0
0,0,111,3,111,0,0,0,0,0,0,0,0,0,0,0,0,0,7,0,0,7,0,0,0,0,0,0,0,0,0,0,0,0,0,0,0
0,0,111,111,111,0,0,0,0,0,0,0,0,0,0,0,0,0,7,0,0,7,0,0,0,0,0,0,0,0,0,0,0,0,0,0,0
0,0,0,0,0,0,0,0,0,0,0,0,0,0,0,0,0,112,3,6,6,3,112,0,0,0,0,0,0,0,0,0,0,0,0,0,0
0,0,0,0,0,0,0,0,0,0,0,0,0,0,0,0,0,0,112,0,0,112,0,0,0,0,0,0,0,0,0,0,0,0,0,0,0
0,0,0,0,0,0,0,0,0,0,0,0,0,0,0,0,0,0,0,0,0,0,0,0,0,0,0,0,0,0,0,0,0,0,0,0,0
0,0,0,0,0,0,0,0,0,0,0,0,0,0,0,0,0,0,0,0,0,0,0,0,0,0,0,0,0,0,0,0,0,0,0,0,0
0,0,0,0,0,0,0,0,0,0,0,0,0,0,0,0,0,0,0,0,0,0,0,0,0,0,0,0,0,0,0,0,0,0,0,0,0
0,0,0,0,0,0,0,0,0,0,0,0,0,0,0,0,0,0,0,0,0,0,0,0,0,0,0,0,0,0,0,0,0,0,0,0,0
0,0,0,0,0,0,0,0,0,0,0,0,0,0,0,0,0,0,0,0,0,0,0,0,0,0,0,0,0,0,0,0,0,0,0,0,0
0,0,0,0,0,0,0,0,0,0,0,0,0,0,0,0,0,0,0,0,0,0,0,0,0,0,0,0,0,0,0,0,0,0,0,0,0
0,0,0,0,0,0,0,0,0,0,0,0,0,0,0,0,0,0,0,0,0,0,0,0,0,0,0,0,0,0,0,0,0,0,0,0,0
0,0,0,0,0,0,0,0,0,0,0,0,0,0,0,0,0,0,0,0,0,0,0,0,0,0,0,0,0,0,0,0,0,0,0,0,0
0,0,0,0,0,0,0,0,0,0,0,0,0,0,0,0,0,0,0,0,0,0,0,0,0,0,0,0,0,0,0,0,0,0,0,0,0
0,0,0,0,0,0,0,0,0,0,0,0,0,0,0,0,0,0,0,0,0,0,0,0,0,0,0,0,0,0,0,0,0,0,0,0,0
0,0,0,0,0,0,0,0,0,0,0,0,0,0,0,0,0,0,0,0,0,0,0,0,0,0,0,0,0,0,0,0,0,0,0,0,0
0,0,0,0,0,0,0,0,0,0,0,0,0,0,0,0,0,0,0,0,0,0,0,0,0,0,0,0,0,0,0,0,0,0,0,0,0
0,0,0,0,0,0,0,0,0,0,0,0,0,0,0,0,0,0,0,0,0,0,0,0,0,0,0,0,0,0,0,0,0,0,0,0,0
0,0,0,0,0,0,0,0,0,0,0,0,0,0,0,0,0,0,0,0,0,0,0,0,0,0,0,0,0,0,0,0,0,0,0,0,0
0,0,0,0,0,0,0,0,0,0,0,0,0,0,0,0,0,0,0,0,0,0,0,0,0,0,0,0,0,0,0,0,0,0,0,0,0
0,0,0,0,0,0,0,0,0,0,0,0,0,0,0,0,0,0,0,0,0,0,0,0,0,0,0,0,0,0,0,0,0,0,0,0,0
:endlayer
layer: 12
0,0,0,0,0,0,0,0,0,0,0,0,0,0,0,0,0,0,0,0,0,0,0,0,0,0,0,0,0,0,0,0,0,0,0,0,0
0,0,0,0,0,0,0,0,0,0,0,0,0,0,0,0,0,0,0,0,0,0,0,0,0,0,0,0,0,0,0,112,0,0,112,0,0
0,0,0,0,0,0,0,0,0,0,0,0,0,0,0,0,0,0,0,0,0,0,0,0,0,5,0,0,0,0,112,3,6,6,3,112,0
0,0,0,0,0,0,0,0,0,0,0,0,0,0,0,0,0,0,0,0,0,0,0,0,0,0,0,0,0,0,0,7,0,0,7,0,0
0,0,0,0,0,0,0,0,0,0,0,0,0,0,0,0,0,0,0,0,0,0,0,0,0,0,0,0,0,0,0,7,0,0,7,0,0
0,0,0,0,0,0,0,0,0,0,0,0,0,0,0,0,0,0,0,0,0,0,0,0,0,0,0,0,0,0,112,3,6,6,3,112,0
0,0,0,0,0,0,0,0,0,0,0,0,0,0,0,0,0,0,0,0,0,0,0,0,0,0,0,0,0,0,0,112,0,0,112,0,0
0,0,0,0,0,0,0,0,0,0,0,0,0,0,0,0,0,0,0,0,0,0,0,0,0,0,0,0,0,0,0,0,0,0,0,0,0
0,0,0,0,0,0,0,0,0,0,0,0,0,0,0,0,0,0,0,0,0,0,0,0,0,0,0,0,0,0,0,0,0,0,0,0,0
0,0,0,0,0,0,0,0,0,0,0,0,0,0,0,0,0,0,0,0,0,0,0,0,0,0,0,0,0,0,0,0,0,0,0,0,0
0,0,0,0,0,0,0,0,0,0,0,0,0,0,0,0,0,0,0,0,0,0,0,0,0,0,0,0,0,0,0,0,0,0,0,0,0
0,0,0,0,0,0,0,0,0,0,0,0,0,0,0,0,0,0,0,0,0,0,0,0,0,0,0,0,0,0,0,0,0,0,0,0,0
0,0,0,0,0,0,0,0,0,0,0,0,0,0,0,0,0,0,0,0,0,0,0,0,0,0,0,0,0,0,0,0,0,0,0,0,0
0,0,0,0,0,0,0,0,0,0,0,0,0,0,0,0,0,0,0,0,0,0,0,0,0,0,0,0,0,0,0,0,0,0,0,0,0
0,0,0,0,0,0,0,0,0,0,0,0,0,0,0,0,0,0,0,0,0,0,0,0,0,0,0,0,0,0,0,0,0,0,0,0,0
0,0,0,0,0,0,0,0,0,0,0,0,0,0,0,0,0,0,0,77,77,0,0,0,0,0,0,0,0,0,0,0,0,0,0,0,0
0,0,0,111,0,0,0,0,0,0,0,0,0,0,0,0,0,0,77,20,20,77,0,0,0,0,0,0,0,0,0,0,0,0,0,0,0
0,0,111,111,111,0,0,0,0,0,0,0,0,0,0,0,0,77,20,20,20,20,77,0,0,0,0,0,0,0,0,0,0,0,0,0,0
0,0,0,111,0,0,0,0,0,0,0,0,0,0,0,0,0,77,20,20,20,20,77,0,0,0,0,0,0,0,0,0,0,0,0,0,0
0,0,0,0,0,0,0,0,0,0,0,0,0,0,0,0,0,0,77,20,20,77,0,0,0,0,0,0,0,0,0,0,0,0,0,0,0
0,0,0,0,0,0,0,0,0,0,0,0,0,0,0,0,0,0,0,77,77,0,0,0,0,0,0,0,0,0,0,0,0,0,0,0,0
0,0,0,0,0,0,0,0,0,0,0,0,0,0,0,0,0,0,0,0,0,0,0,0,0,0,0,0,0,0,0,0,0,0,0,0,0
0,0,0,0,0,0,0,0,0,0,0,0,0,0,0,0,0,0,0,0,0,0,0,0,0,0,0,0,0,0,0,0,0,0,0,0,0
0,0,0,0,0,0,0,0,0,0,0,0,0,0,0,0,0,0,0,0,0,0,0,0,0,0,0,0,0,0,0,0,0,0,0,0,0
0,0,0,0,0,0,0,0,0,0,0,0,0,0,0,0,0,0,0,0,0,0,0,0,0,0,0,0,0,0,0,0,0,0,0,0,0
0,0,0,0,0,0,0,0,0,0,0,0,0,0,0,0,0,0,0,0,0,0,0,0,0,0,0,0,0,0,0,0,0,0,0,0,0
0,0,0,0,0,0,0,0,0,0,0,0,0,0,0,0,0,0,0,0,0,0,0,0,0,0,0,0,0,0,0,0,0,0,0,0,0
0,0,0,0,0,0,0,0,0,0,0,0,0,0,0,0,0,0,0,0,0,0,0,0,0,0,0,0,0,0,0,0,0,0,0,0,0
0,0,0,0,0,0,0,0,0,0,0,0,0,0,0,0,0,0,0,0,0,0,0,0,0,0,0,0,0,0,0,0,0,0,0,0,0
0,0,0,0,0,0,0,0,0,0,0,0,0,0,0,0,0,0,0,0,0,0,0,0,0,0,0,0,0,0,0,0,0,0,0,0,0
0,0,0,0,0,0,0,0,0,0,0,0,0,0,0,0,0,0,0,0,0,0,0,0,0,0,0,0,0,0,0,0,0,0,0,0,0
0,0,0,0,0,0,0,0,0,0,0,0,0,0,0,0,0,0,0,0,0,0,0,0,0,0,0,0,0,0,0,0,0,0,0,0,0
0,0,0,0,0,0,0,0,0,0,0,0,0,0,0,0,0,0,0,0,0,0,0,0,0,0,0,0,0,0,0,0,0,0,0,0,0
0,0,0,0,0,0,0,0,0,0,0,0,0,0,0,0,0,0,0,0,0,0,0,0,0,0,0,0,0,0,0,0,0,0,0,0,0
0,0,0,0,0,0,0,0,0,0,0,0,0,0,0,0,0,0,0,0,0,0,0,0,0,0,0,0,0,0,0,0,0,0,0,0,0
0,0,0,0,0,0,0,0,0,0,0,0,0,0,0,0,0,0,0,0,0,0,0,0,0,0,0,0,0,0,0,0,0,0,0,0,0
0,0,0,0,0,0,0,0,0,0,0,0,0,0,0,0,0,0,0,0,0,0,0,0,0,0,0,0,0,0,0,0,0,0,0,0,0
:endlayer
layer: 13
0,0,0,0,0,0,0,0,0,0,0,0,0,0,0,0,0,0,0,0,0,0,0,0,0,0,0,0,0,0,0,0,0,0,0,0,0
0,0,0,0,0,0,0,0,0,0,0,0,0,0,0,0,0,0,0,0,0,0,0,0,0,0,0,0,0,0,0,0,77,77,0,0,0
0,0,0,0,0,0,0,0,0,0,0,0,0,0,0,0,0,0,0,0,0,0,0,0,0,114,0,0,0,0,0,77,20,20,77,0,0
0,0,0,0,0,0,0,0,0,0,0,0,0,0,0,0,0,0,0,0,0,0,0,0,0,0,0,0,0,0,77,20,20,20,20,77,0
0,0,0,0,0,0,0,0,0,0,0,0,0,0,0,0,0,0,0,0,0,0,0,0,0,0,0,0,0,0,77,20,20,20,20,77,0
0,0,0,0,0,0,0,0,0,0,0,0,0,0,0,0,0,0,0,0,0,0,0,0,0,0,0,0,0,0,0,77,20,20,77,0,0
0,0,0,0,0,0,0,0,0,0,0,0,0,0,0,0,0,0,0,0,0,0,0,0,0,0,0,0,0,0,0,0,77,77,0,0,0
0,0,0,0,0,0,0,0,0,0,0,0,0,0,0,0,0,0,0,0,0,0,0,0,0,0,0,0,0,0,0,0,0,0,0,0,0
0,0,0,0,0,0,0,0,0,0,0,0,0,0,0,0,0,0,0,0,0,0,0,0,0,0,0,0,0,0,0,0,0,0,0,0,0
0,0,0,0,0,0,0,0,0,0,0,0,0,0,0,0,0,0,0,0,0,0,0,0,0,0,0,0,0,0,0,0,0,0,0,0,0
0,0,0,0,0,0,0,0,0,0,0,0,0,0,0,0,0,0,0,0,0,0,0,0,0,0,0,0,0,0,0,0,0,0,0,0,0
0,0,0,0,0,0,0,0,0,0,0,0,0,0,0,0,0,0,0,0,0,0,0,0,0,0,0,0,0,0,0,0,0,0,0,0,0
0,0,0,0,0,0,0,0,0,0,0,0,0,0,0,0,0,0,0,0,0,0,0,0,0,0,0,0,0,0,0,0,0,0,0,0,0
0,0,0,0,0,0,0,0,0,0,0,0,0,0,0,0,0,0,0,0,0,0,0,0,0,0,0,0,0,0,0,0,0,0,0,0,0
0,0,0,0,0,0,0,0,0,0,0,0,0,0,0,0,0,0,0,0,0,0,0,0,0,0,0,0,0,0,0,0,0,0,0,0,0
0,0,0,0,0,0,0,0,0,0,0,0,0,0,0,0,0,0,0,0,0,0,0,0,0,0,0,0,0,0,0,0,0,0,0,0,0
0,0,0,0,0,0,0,0,0,0,0,0,0,0,0,0,0,0,0,0,0,0,0,0,0,0,0,0,0,0,0,0,0,0,0,0,0
0,0,0,0,0,0,0,0,0,0,0,0,0,0,0,0,0,0,0,77,77,0,0,0,0,0,0,0,0,0,0,0,0,0,0,0,0
0,0,0,0,0,0,0,0,0,0,0,0,0,0,0,0,0,0,0,77,77,0,0,0,0,0,0,0,0,0,0,0,0,0,0,0,0
0,0,0,0,0,0,0,0,0,0,0,0,0,0,0,0,0,0,0,0,0,0,0,0,0,0,0,0,0,0,0,0,0,0,0,0,0
0,0,0,0,0,0,0,0,0,0,0,0,0,0,0,0,0,0,0,0,0,0,0,0,0,0,0,0,0,0,0,0,0,0,0,0,0
0,0,0,0,0,0,0,0,0,0,0,0,0,0,0,0,0,0,0,0,0,0,0,0,0,0,0,0,0,0,0,0,0,0,0,0,0
0,0,0,0,0,0,0,0,0,0,0,0,0,0,0,0,0,0,0,0,0,0,0,0,0,0,0,0,0,0,0,0,0,0,0,0,0
0,0,0,0,0,0,0,0,0,0,0,0,0,0,0,0,0,0,0,0,0,0,0,0,0,0,0,0,0,0,0,0,0,0,0,0,0
0,0,0,0,0,0,0,0,0,0,0,0,0,0,0,0,0,0,0,0,0,0,0,0,0,0,0,0,0,0,0,0,0,0,0,0,0
0,0,0,0,0,0,0,0,0,0,0,0,0,0,0,0,0,0,0,0,0,0,0,0,0,0,0,0,0,0,0,0,0,0,0,0,0
0,0,0,0,0,0,0,0,0,0,0,0,0,0,0,0,0,0,0,0,0,0,0,0,0,0,0,0,0,0,0,0,0,0,0,0,0
0,0,0,0,0,0,0,0,0,0,0,0,0,0,0,0,0,0,0,0,0,0,0,0,0,0,0,0,0,0,0,0,0,0,0,0,0
0,0,0,0,0,0,0,0,0,0,0,0,0,0,0,0,0,0,0,0,0,0,0,0,0,0,0,0,0,0,0,0,0,0,0,0,0
0,0,0,0,0,0,0,0,0,0,0,0,0,0,0,0,0,0,0,0,0,0,0,0,0,0,0,0,0,0,0,0,0,0,0,0,0
0,0,0,0,0,0,0,0,0,0,0,0,0,0,0,0,0,0,0,0,0,0,0,0,0,0,0,0,0,0,0,0,0,0,0,0,0
0,0,0,0,0,0,0,0,0,0,0,0,0,0,0,0,0,0,0,0,0,0,0,0,0,0,0,0,0,0,0,0,0,0,0,0,0
0,0,0,0,0,0,0,0,0,0,0,0,0,0,0,0,0,0,0,0,0,0,0,0,0,0,0,0,0,0,0,0,0,0,0,0,0
0,0,0,0,0,0,0,0,0,0,0,0,0,0,0,0,0,0,0,0,0,0,0,0,0,0,0,0,0,0,0,0,0,0,0,0,0
0,0,0,0,0,0,0,0,0,0,0,0,0,0,0,0,0,0,0,0,0,0,0,0,0,0,0,0,0,0,0,0,0,0,0,0,0
0,0,0,0,0,0,0,0,0,0,0,0,0,0,0,0,0,0,0,0,0,0,0,0,0,0,0,0,0,0,0,0,0,0,0,0,0
0,0,0,0,0,0,0,0,0,0,0,0,0,0,0,0,0,0,0,0,0,0,0,0,0,0,0,0,0,0,0,0,0,0,0,0,0
:endlayer
layer: 14
0,0,0,0,0,0,0,0,0,0,0,0,0,0,0,0,0,0,0,0,0,0,0,0,0,0,0,0,0,0,0,0,0,0,0,0,0
0,0,0,0,0,0,0,0,0,0,0,0,0,0,0,0,0,0,0,0,0,0,0,0,0,0,0,0,0,0,0,0,0,0,0,0,0
0,0,0,0,0,0,0,0,0,0,0,0,0,0,0,0,0,0,0,0,0,0,0,0,0,27,0,0,0,0,0,0,0,0,0,0,0
0,0,0,0,0,0,0,0,0,0,0,0,0,0,0,0,0,0,0,0,0,0,0,0,0,0,0,0,0,0,0,0,77,77,0,0,0
0,0,0,0,0,0,0,0,0,0,0,0,0,0,0,0,0,0,0,0,0,0,0,0,0,0,0,0,0,0,0,0,77,77,0,0,0
0,0,0,0,0,0,0,0,0,0,0,0,0,0,0,0,0,0,0,0,0,0,0,0,0,0,0,0,0,0,0,0,0,0,0,0,0
0,0,0,0,0,0,0,0,0,0,0,0,0,0,0,0,0,0,0,0,0,0,0,0,0,0,0,0,0,0,0,0,0,0,0,0,0
0,0,0,0,0,0,0,0,0,0,0,0,0,0,0,0,0,0,0,0,0,0,0,0,0,0,0,0,0,0,0,0,0,0,0,0,0
0,0,0,0,0,0,0,0,0,0,0,0,0,0,0,0,0,0,0,0,0,0,0,0,0,0,0,0,0,0,0,0,0,0,0,0,0
0,0,0,0,0,0,0,0,0,0,0,0,0,0,0,0,0,0,0,0,0,0,0,0,0,0,0,0,0,0,0,0,0,0,0,0,0
0,0,0,0,0,0,0,0,0,0,0,0,0,0,0,0,0,0,0,0,0,0,0,0,0,0,0,0,0,0,0,0,0,0,0,0,0
0,0,0,0,0,0,0,0,0,0,0,0,0,0,0,0,0,0,0,0,0,0,0,0,0,0,0,0,0,0,0,0,0,0,0,0,0
0,0,0,0,0,0,0,0,0,0,0,0,0,0,0,0,0,0,0,0,0,0,0,0,0,0,0,0,0,0,0,0,0,0,0,0,0
0,0,0,0,0,0,0,0,0,0,0,0,0,0,0,0,0,0,0,0,0,0,0,0,0,0,0,0,0,0,0,0,0,0,0,0,0
0,0,0,0,0,0,0,0,0,0,0,0,0,0,0,0,0,0,0,0,0,0,0,0,0,0,0,0,0,0,0,0,0,0,0,0,0
0,0,0,0,0,0,0,0,0,0,0,0,0,0,0,0,0,0,0,0,0,0,0,0,0,0,0,0,0,0,0,0,0,0,0,0,0
0,0,0,0,0,0,0,0,0,0,0,0,0,0,0,0,0,0,0,0,0,0,0,0,0,0,0,0,0,0,0,0,0,0,0,0,0
0,0,0,0,0,0,0,0,0,0,0,0,0,0,0,0,0,0,0,0,0,0,0,0,0,0,0,0,0,0,0,0,0,0,0,0,0
0,0,0,0,0,0,0,0,0,0,0,0,0,0,0,0,0,0,0,0,0,0,0,0,0,0,0,0,0,0,0,0,0,0,0,0,0
0,0,0,0,0,0,0,0,0,0,0,0,0,0,0,0,0,0,0,0,0,0,0,0,0,0,0,0,0,0,0,0,0,0,0,0,0
0,0,0,0,0,0,0,0,0,0,0,0,0,0,0,0,0,0,0,0,0,0,0,0,0,0,0,0,0,0,0,0,0,0,0,0,0
0,0,0,0,0,0,0,0,0,0,0,0,0,0,0,0,0,0,0,0,0,0,0,0,0,0,0,0,0,0,0,0,0,0,0,0,0
0,0,0,0,0,0,0,0,0,0,0,0,0,0,0,0,0,0,0,0,0,0,0,0,0,0,0,0,0,0,0,0,0,0,0,0,0
0,0,0,0,0,0,0,0,0,0,0,0,0,0,0,0,0,0,0,0,0,0,0,0,0,0,0,0,0,0,0,0,0,0,0,0,0
0,0,0,0,0,0,0,0,0,0,0,0,0,0,0,0,0,0,0,0,0,0,0,0,0,0,0,0,0,0,0,0,0,0,0,0,0
0,0,0,0,0,0,0,0,0,0,0,0,0,0,0,0,0,0,0,0,0,0,0,0,0,0,0,0,0,0,0,0,0,0,0,0,0
0,0,0,0,0,0,0,0,0,0,0,0,0,0,0,0,0,0,0,0,0,0,0,0,0,0,0,0,0,0,0,0,0,0,0,0,0
0,0,0,0,0,0,0,0,0,0,0,0,0,0,0,0,0,0,0,0,0,0,0,0,0,0,0,0,0,0,0,0,0,0,0,0,0
0,0,0,0,0,0,0,0,0,0,0,0,0,0,0,0,0,0,0,0,0,0,0,0,0,0,0,0,0,0,0,0,0,0,0,0,0
0,0,0,0,0,0,0,0,0,0,0,0,0,0,0,0,0,0,0,0,0,0,0,0,0,0,0,0,0,0,0,0,0,0,0,0,0
0,0,0,0,0,0,0,0,0,0,0,0,0,0,0,0,0,0,0,0,0,0,0,0,0,0,0,0,0,0,0,0,0,0,0,0,0
0,0,0,0,0,0,0,0,0,0,0,0,0,0,0,0,0,0,0,0,0,0,0,0,0,0,0,0,0,0,0,0,0,0,0,0,0
0,0,0,0,0,0,0,0,0,0,0,0,0,0,0,0,0,0,0,0,0,0,0,0,0,0,0,0,0,0,0,0,0,0,0,0,0
0,0,0,0,0,0,0,0,0,0,0,0,0,0,0,0,0,0,0,0,0,0,0,0,0,0,0,0,0,0,0,0,0,0,0,0,0
0,0,0,0,0,0,0,0,0,0,0,0,0,0,0,0,0,0,0,0,0,0,0,0,0,0,0,0,0,0,0,0,0,0,0,0,0
0,0,0,0,0,0,0,0,0,0,0,0,0,0,0,0,0,0,0,0,0,0,0,0,0,0,0,0,0,0,0,0,0,0,0,0,0
0,0,0,0,0,0,0,0,0,0,0,0,0,0,0,0,0,0,0,0,0,0,0,0,0,0,0,0,0,0,0,0,0,0,0,0,0
:endlayer

#### RULES ####
rule:
plugin=vanillaBlocks
number=1
data:
JSON:{blockState:{blockName:"minecraft:stone",properties:{variant:"stone"}}}
:enddata
:endrule

rule:
plugin=vanillaBlocks
number=2
data:
JSON:{blockState:{blockName:"minecraft:dirt",properties:{variant:"dirt",snowy:"false"}}}
:enddata
:endrule

rule:
plugin=vanillaBlocks
number=3
data:
JSON:{blockState:{blockName:"minecraft:log",properties:{variant:"birch",axis:"y"}}}
:enddata
:endrule

rule:
plugin=vanillaBlocks
number=4
data:
JSON:{blockState:{blockName:"minecraft:grass",properties:{snowy:"false"}}}
:enddata
:endrule

rule:
plugin=vanillaBlocks
number=5
data:
JSON:{blockState:{blockName:"minecraft:cobblestone"}}
:enddata
:endrule

rule:
plugin=vanillaBlocks
number=6
data:
JSON:{blockState:{blockName:"minecraft:log",properties:{variant:"birch",axis:"x"}}}
:enddata
:endrule

rule:
plugin=vanillaBlocks
number=7
data:
JSON:{blockState:{blockName:"minecraft:log",properties:{variant:"birch",axis:"z"}}}
:enddata
:endrule

rule:
plugin=vanillaBlocks
number=8
data:
JSON:{blockState:{blockName:"minecraft:planks",properties:{variant:"oak"}}}
:enddata
:endrule

rule:
plugin=vanillaBlocks
number=9
data:
JSON:{blockState:{blockName:"minecraft:grass_path"}}
:enddata
:endrule

rule:
plugin=vanillaBlocks
number=10
data:
JSON:{blockState:{blockName:"minecraft:gravel"}}
:enddata
:endrule

rule:
plugin=vanillaBlocks
number=11
data:
JSON:{blockState:{blockName:"minecraft:dirt",properties:{variant:"coarse_dirt",snowy:"false"}}}
:enddata
:endrule

rule:
plugin=vanillaBlocks
number=12
data:
JSON:{blockState:{blockName:"minecraft:farmland",properties:{moisture:"7"}}}
:enddata
:endrule

rule:
plugin=fluid
number=13
data:
JSON:{blockState:{blockName:"minecraft:water",properties:{level:"0"}}}
:enddata
:endrule

rule:
plugin=vanillaBlocks
number=14
data:
JSON:{blockState:{blockName:"minecraft:tallgrass",properties:{type:"tall_grass"}}}
:enddata
:endrule

rule:
plugin=vanillaBlocks
number=15
data:
JSON:{blockState:{blockName:"minecraft:red_flower",properties:{type:"oxeye_daisy"}}}
:enddata
:endrule

rule:
plugin=vanillaBlocks
number=16
data:
JSON:{blockState:{blockName:"minecraft:red_flower",properties:{type:"houstonia"}}}
:enddata
:endrule

rule:
plugin=vanillaBlocks
number=17
data:
JSON:{blockState:{blockName:"minecraft:birch_fence",properties:{east:"false",south:"false",north:"false",west:"false"}}}
:enddata
:endrule

rule:
plugin=vanillaBlocks
number=18
data:
JSON:{blockState:{blockName:"minecraft:yellow_flower",properties:{type:"dandelion"}}}
:enddata
:endrule

rule:
plugin=vanillaBlocks
number=19
data:
JSON:{blockState:{blockName:"ancientwarfarestructure:bench",properties:{legs:"none",variant:"birch",axis:"x"}}}
:enddata
:endrule

rule:
plugin=vanillaBlocks
number=20
data:
JSON:{blockState:{blockName:"minecraft:planks",properties:{variant:"birch"}}}
:enddata
:endrule

rule:
plugin=vanillaBlocks
number=21
data:
JSON:{blockState:{blockName:"ancientwarfarestructure:table",properties:{leg_southwest:"true",leg_northwest:"true",variant:"birch",leg_northeast:"true",leg_southeast:"true"}}}
:enddata
:endrule

rule:
plugin=vanillaBlocks
number=22
data:
JSON:{blockState:{blockName:"minecraft:stained_hardened_clay",properties:{color:"white"}}}
:enddata
:endrule

rule:
plugin=vanillaBlocks
number=23
data:
JSON:{blockState:{blockName:"ancientwarfarestructure:fire_pit",properties:{lit:"true",variant:"default"}}}
:enddata
:endrule

rule:
plugin=blockTile
number=24
data:
JSON:{blockState:{blockName:"ancientwarfarestructure:advanced_spawner",properties:{transparent:"true"}},teData:{id:"ancientwarfarestructure:advanced_spawner_tile",spawnerSettings:{minDelay:10,spawnDelay:8,lightSensitive:0b,spawnGroups:[{settingsList:[{remainingSpawnCount:1,hostile:1b,customTag:{ArmorDropChances:[0.085f,0.085f,0.085f,0.085f],hasCustomEquipment:0b,ArmorItems:[{},{},{},{}],skinSettings:{npcTypeName:"custom",skinTypeSelected:"default"},HandDropChances:[0.085f,0.085f],factionName:"nogg",HandItems:[{},{}]},maxToSpawn:1,entityId:"ancientwarfarenpc:faction.civilian.male",minToSpawn:1}],groupWeight:1}],playerRange:16,respondToRedstone:0b,inventory:{Size:9,Items:[]},spawnRange:0,transparent:1b,maxDelay:10,spawnYOffset:0,xpToDrop:0,mobRange:0,debugMode:0b,maxNearbyMonsters:0}}}
:enddata
:endrule

rule:
plugin=vanillaBlocks
number=25
data:
JSON:{blockState:{blockName:"ancientwarfarestructure:stool",properties:{variant:"birch"}}}
:enddata
:endrule

rule:
plugin=vanillaBlocks
number=26
data:
JSON:{blockState:{blockName:"minecraft:crafting_table"}}
:enddata
:endrule

rule:
plugin=vanillaBlocks
number=27
data:
JSON:{blockState:{blockName:"minecraft:stone_slab",properties:{half:"bottom",variant:"cobblestone"}}}
:enddata
:endrule

rule:
plugin=inventory
number=28
data:
JSON:{blockState:{blockName:"minecraft:furnace",properties:{facing:"south"}},lootLevel:0,teData:{CookTime:0,BurnTime:0,Items:[],id:"minecraft:furnace",CookTimeTotal:0,Lock:""},inventoryData:{length:0,inventoryContents:[]},legacyFeatures:0b}
:enddata
:endrule

rule:
plugin=inventory
number=29
data:
JSON:{blockState:{blockName:"minecraft:furnace",properties:{facing:"south"}},lootLevel:0,teData:{CookTime:0,BurnTime:0,Items:[],id:"minecraft:furnace",CookTimeTotal:0,Lock:""},inventoryData:{length:0,inventoryContents:[]},legacyFeatures:0b}
:enddata
:endrule

rule:
plugin=vanillaBlocks
number=30
data:
JSON:{blockState:{blockName:"minecraft:stone",properties:{variant:"smooth_andesite"}}}
:enddata
:endrule

rule:
plugin=doors
number=31
data:
JSON:{blockState:{blockName:"minecraft:birch_door",properties:{hinge:"left",half:"lower",powered:"false",facing:"east",open:"false"}}}
:enddata
:endrule

rule:
plugin=blockTile
number=32
data:
JSON:{blockState:{blockName:"ancientwarfarestructure:advanced_spawner",properties:{transparent:"true"}},teData:{id:"ancientwarfarestructure:advanced_spawner_tile",spawnerSettings:{minDelay:10,spawnDelay:7,lightSensitive:0b,spawnGroups:[{settingsList:[{remainingSpawnCount:1,hostile:1b,customTag:{ArmorDropChances:[0.085f,0.085f,0.085f,0.085f],hasCustomEquipment:0b,ArmorItems:[{},{},{},{}],skinSettings:{npcTypeName:"custom",skinTypeSelected:"default"},HandDropChances:[0.085f,0.085f],factionName:"nogg",HandItems:[{},{}]},maxToSpawn:1,entityId:"ancientwarfarenpc:faction.civilian.female",minToSpawn:1}],groupWeight:1}],playerRange:16,respondToRedstone:0b,inventory:{Size:9,Items:[]},spawnRange:0,transparent:1b,maxDelay:10,spawnYOffset:0,xpToDrop:0,mobRange:0,debugMode:0b,maxNearbyMonsters:0}}}
:enddata
:endrule

rule:
plugin=doors
number=33
data:
JSON:{blockState:{blockName:"minecraft:birch_door",properties:{hinge:"left",half:"lower",powered:"false",facing:"north",open:"false"}}}
:enddata
:endrule

rule:
plugin=vanillaBlocks
number=34
data:
JSON:{blockState:{blockName:"minecraft:birch_stairs",properties:{half:"bottom",shape:"straight",facing:"south"}}}
:enddata
:endrule

rule:
plugin=inventory
number=35
data:
JSON:{blockState:{blockName:"minecraft:chest",properties:{facing:"east"}},lootLevel:0,teData:{Items:[],id:"minecraft:chest",Lock:""},inventoryData:{length:0,inventoryContents:[]},legacyFeatures:1b}
:enddata
:endrule

rule:
plugin=vanillaBlocks
number=36
data:
JSON:{blockState:{blockName:"ancientwarfarestructure:bench",properties:{legs:"none",variant:"birch",axis:"z"}}}
:enddata
:endrule

rule:
plugin=bed
number=37
data:
JSON:{blockState:{blockName:"minecraft:bed",properties:{part:"foot",facing:"east",occupied:"false"}},bedColor:2}
:enddata
:endrule

rule:
plugin=bed
number=38
data:
JSON:{blockState:{blockName:"minecraft:bed",properties:{part:"head",facing:"east",occupied:"false"}},bedColor:2}
:enddata
:endrule

rule:
plugin=blockTile
number=39
data:
JSON:{blockState:{blockName:"ancientwarfarestructure:gate_proxy"},teData:{lsb:-8404065744215508488L,id:"ancientwarfarestructure:gate_proxy_tile",msb:-4486452760721078973L,render:1b}}
:enddata
:endrule

rule:
plugin=inventory
number=40
data:
JSON:{blockState:{blockName:"minecraft:chest",properties:{facing:"east"}},lootLevel:0,teData:{Items:[],id:"minecraft:chest",Lock:""},inventoryData:{length:0,inventoryContents:[]},legacyFeatures:1b}
:enddata
:endrule

rule:
plugin=vanillaBlocks
number=41
data:
JSON:{blockState:{blockName:"minecraft:red_flower",properties:{type:"poppy"}}}
:enddata
:endrule

rule:
plugin=blockTile
number=42
data:
JSON:{blockState:{blockName:"ancientwarfarestructure:gate_proxy"},teData:{lsb:-8404065744215508488L,id:"ancientwarfarestructure:gate_proxy_tile",msb:-4486452760721078973L,render:0b}}
:enddata
:endrule

rule:
plugin=blockTile
number=43
data:
JSON:{blockState:{blockName:"ancientwarfarestructure:advanced_spawner",properties:{transparent:"true"}},teData:{id:"ancientwarfarestructure:advanced_spawner_tile",spawnerSettings:{minDelay:10,spawnDelay:8,lightSensitive:0b,spawnGroups:[{settingsList:[{remainingSpawnCount:1,hostile:1b,customTag:{ArmorDropChances:[0.085f,0.085f,0.085f,0.085f],hasCustomEquipment:0b,ArmorItems:[{},{},{},{}],skinSettings:{npcTypeName:"custom",skinTypeSelected:"default"},HandDropChances:[0.085f,0.085f],factionName:"nogg",HandItems:[{},{}]},maxToSpawn:1,entityId:"ancientwarfarenpc:faction.civilian.female",minToSpawn:1}],groupWeight:1}],playerRange:16,respondToRedstone:0b,inventory:{Size:9,Items:[]},spawnRange:0,transparent:1b,maxDelay:10,spawnYOffset:0,xpToDrop:0,mobRange:0,debugMode:0b,maxNearbyMonsters:0}}}
:enddata
:endrule

rule:
plugin=doors
number=44
data:
JSON:{blockState:{blockName:"minecraft:birch_door",properties:{hinge:"left",half:"lower",powered:"false",facing:"west",open:"false"}}}
:enddata
:endrule

rule:
plugin=blockTile
number=45
data:
JSON:{blockState:{blockName:"ancientwarfarestructure:advanced_spawner",properties:{transparent:"true"}},teData:{id:"ancientwarfarestructure:advanced_spawner_tile",spawnerSettings:{minDelay:10,spawnDelay:6,lightSensitive:0b,spawnGroups:[{settingsList:[{remainingSpawnCount:1,hostile:1b,customTag:{ArmorDropChances:[0.085f,0.085f,0.085f,0.085f],hasCustomEquipment:0b,ArmorItems:[{},{},{},{}],skinSettings:{npcTypeName:"custom",skinTypeSelected:"default"},HandDropChances:[0.085f,0.085f],factionName:"nogg",HandItems:[{},{}]},maxToSpawn:1,entityId:"ancientwarfarenpc:faction.civilian.male",minToSpawn:1}],groupWeight:1}],playerRange:16,respondToRedstone:0b,inventory:{Size:9,Items:[]},spawnRange:0,transparent:1b,maxDelay:10,spawnYOffset:0,xpToDrop:0,mobRange:0,debugMode:0b,maxNearbyMonsters:0}}}
:enddata
:endrule

rule:
plugin=inventory
number=46
data:
JSON:{blockState:{blockName:"minecraft:chest",properties:{facing:"north"}},lootLevel:0,teData:{Items:[],id:"minecraft:chest",Lock:""},inventoryData:{length:0,inventoryContents:[]},legacyFeatures:1b}
:enddata
:endrule

rule:
plugin=inventory
number=47
data:
JSON:{blockState:{blockName:"minecraft:chest",properties:{facing:"north"}},lootLevel:0,teData:{Items:[],id:"minecraft:chest",Lock:""},inventoryData:{length:0,inventoryContents:[]},legacyFeatures:1b}
:enddata
:endrule

rule:
plugin=blockTile
number=48
data:
JSON:{blockState:{blockName:"ancientwarfarestructure:gate_proxy"},teData:{lsb:-8404065744215508488L,id:"ancientwarfarestructure:gate_proxy_tile",msb:-4486452760721078973L,render:0b}}
:enddata
:endrule

rule:
plugin=inventory
number=49
data:
JSON:{blockState:{blockName:"minecraft:chest",properties:{facing:"south"}},lootLevel:0,teData:{Items:[],id:"minecraft:chest",Lock:""},inventoryData:{length:0,inventoryContents:[]},legacyFeatures:1b}
:enddata
:endrule

rule:
plugin=inventory
number=50
data:
JSON:{blockState:{blockName:"minecraft:chest",properties:{facing:"south"}},lootLevel:0,teData:{Items:[],id:"minecraft:chest",Lock:""},inventoryData:{length:0,inventoryContents:[]},legacyFeatures:1b}
:enddata
:endrule

rule:
plugin=blockTile
number=51
data:
JSON:{blockState:{blockName:"ancientwarfarestructure:gate_proxy"},teData:{lsb:-8404065744215508488L,id:"ancientwarfarestructure:gate_proxy_tile",msb:-4486452760721078973L,render:0b}}
:enddata
:endrule

rule:
plugin=inventory
number=52
data:
JSON:{blockState:{blockName:"minecraft:chest",properties:{facing:"east"}},lootLevel:0,teData:{Items:[],id:"minecraft:chest",Lock:""},inventoryData:{length:0,inventoryContents:[]},legacyFeatures:1b}
:enddata
:endrule

rule:
plugin=blockTile
number=53
data:
JSON:{blockState:{blockName:"ancientwarfarestructure:advanced_spawner",properties:{transparent:"true"}},teData:{id:"ancientwarfarestructure:advanced_spawner_tile",spawnerSettings:{minDelay:10,spawnDelay:7,lightSensitive:0b,spawnGroups:[{settingsList:[{remainingSpawnCount:1,hostile:1b,customTag:{ArmorDropChances:[0.085f,0.085f,0.085f,0.085f],hasCustomEquipment:0b,ArmorItems:[{},{},{},{}],skinSettings:{npcTypeName:"custom",skinTypeSelected:"default"},HandDropChances:[0.085f,0.085f],factionName:"nogg",HandItems:[{id:"ancientwarfarenpc:iron_lance",Count:1b,Damage:0s},{id:"ancientwarfarenpc:shield_round_5",Count:1b,Damage:0s}]},maxToSpawn:1,entityId:"ancientwarfarenpc:faction.cavalry",minToSpawn:1}],groupWeight:1}],playerRange:16,respondToRedstone:0b,inventory:{Size:9,Items:[]},spawnRange:0,transparent:1b,maxDelay:10,spawnYOffset:0,xpToDrop:0,mobRange:0,debugMode:0b,maxNearbyMonsters:0}}}
:enddata
:endrule

rule:
plugin=vanillaBlocks
number=54
data:
JSON:{blockState:{blockName:"minecraft:birch_stairs",properties:{half:"bottom",shape:"straight",facing:"north"}}}
:enddata
:endrule

rule:
plugin=inventory
number=55
data:
JSON:{blockState:{blockName:"minecraft:chest",properties:{facing:"east"}},lootLevel:0,teData:{Items:[],id:"minecraft:chest",Lock:""},inventoryData:{length:0,inventoryContents:[]},legacyFeatures:1b}
:enddata
:endrule

rule:
plugin=inventory
number=56
data:
JSON:{blockState:{blockName:"minecraft:chest",properties:{facing:"south"}},lootLevel:0,teData:{Items:[],id:"minecraft:chest",Lock:""},inventoryData:{length:0,inventoryContents:[]},legacyFeatures:1b}
:enddata
:endrule

rule:
plugin=inventory
number=57
data:
JSON:{blockState:{blockName:"minecraft:chest",properties:{facing:"south"}},lootLevel:0,teData:{Items:[],id:"minecraft:chest",Lock:""},inventoryData:{length:0,inventoryContents:[]},legacyFeatures:1b}
:enddata
:endrule

rule:
plugin=blockTile
number=58
data:
JSON:{blockState:{blockName:"ancientwarfarestructure:advanced_spawner",properties:{transparent:"true"}},teData:{id:"ancientwarfarestructure:advanced_spawner_tile",spawnerSettings:{minDelay:10,spawnDelay:2,lightSensitive:0b,spawnGroups:[{settingsList:[{remainingSpawnCount:1,hostile:1b,customTag:{ArmorDropChances:[0.085f,0.085f,0.085f,0.085f],hasCustomEquipment:0b,ArmorItems:[{},{},{},{}],skinSettings:{npcTypeName:"custom",skinTypeSelected:"default"},HandDropChances:[0.085f,0.085f],factionName:"nogg",HandItems:[{},{}]},maxToSpawn:1,entityId:"ancientwarfarenpc:faction.civilian.male",minToSpawn:1}],groupWeight:1}],playerRange:16,respondToRedstone:0b,inventory:{Size:9,Items:[]},spawnRange:0,transparent:1b,maxDelay:10,spawnYOffset:0,xpToDrop:0,mobRange:0,debugMode:0b,maxNearbyMonsters:0}}}
:enddata
:endrule

rule:
plugin=vanillaBlocks
number=59
data:
JSON:{blockState:{blockName:"minecraft:red_flower",properties:{type:"pink_tulip"}}}
:enddata
:endrule

rule:
plugin=vanillaBlocks
number=60
data:
JSON:{blockState:{blockName:"minecraft:red_flower",properties:{type:"white_tulip"}}}
:enddata
:endrule

rule:
plugin=blockTile
number=61
data:
JSON:{blockState:{blockName:"ancientwarfarestructure:advanced_spawner",properties:{transparent:"true"}},teData:{id:"ancientwarfarestructure:advanced_spawner_tile",spawnerSettings:{minDelay:10,spawnDelay:3,lightSensitive:0b,spawnGroups:[{settingsList:[{remainingSpawnCount:1,hostile:1b,customTag:{ArmorDropChances:[0.085f,0.085f,0.085f,0.085f],hasCustomEquipment:0b,ArmorItems:[{},{},{},{}],skinSettings:{npcTypeName:"custom",skinTypeSelected:"default"},HandDropChances:[0.085f,0.085f],factionName:"nogg",HandItems:[{id:"minecraft:bow",Count:1b,Damage:0s},{}]},maxToSpawn:1,entityId:"ancientwarfarenpc:faction.archer.elite",minToSpawn:1}],groupWeight:1}],playerRange:32,respondToRedstone:0b,inventory:{Size:9,Items:[]},spawnRange:0,transparent:1b,maxDelay:10,spawnYOffset:0,xpToDrop:0,mobRange:0,debugMode:0b,maxNearbyMonsters:0}}}
:enddata
:endrule

rule:
plugin=blockTile
number=62
data:
JSON:{blockState:{blockName:"ancientwarfarestructure:advanced_spawner",properties:{transparent:"true"}},teData:{id:"ancientwarfarestructure:advanced_spawner_tile",spawnerSettings:{minDelay:10,spawnDelay:2,lightSensitive:0b,spawnGroups:[{settingsList:[{remainingSpawnCount:1,hostile:1b,customTag:{ArmorDropChances:[0.085f,0.085f,0.085f,0.085f],hasCustomEquipment:0b,ArmorItems:[{},{},{},{}],skinSettings:{npcTypeName:"custom",skinTypeSelected:"default"},HandDropChances:[0.085f,0.085f],factionName:"nogg",HandItems:[{},{}]},maxToSpawn:1,entityId:"ancientwarfarenpc:faction.civilian.female",minToSpawn:1}],groupWeight:1}],playerRange:16,respondToRedstone:0b,inventory:{Size:9,Items:[]},spawnRange:0,transparent:1b,maxDelay:10,spawnYOffset:0,xpToDrop:0,mobRange:0,debugMode:0b,maxNearbyMonsters:0}}}
:enddata
:endrule

rule:
plugin=blockTile
number=63
data:
JSON:{blockState:{blockName:"ancientwarfarestructure:advanced_spawner",properties:{transparent:"true"}},teData:{id:"ancientwarfarestructure:advanced_spawner_tile",spawnerSettings:{minDelay:10,spawnDelay:6,lightSensitive:0b,spawnGroups:[{settingsList:[{remainingSpawnCount:1,hostile:1b,customTag:{ArmorDropChances:[0.085f,0.085f,0.085f,0.085f],hasCustomEquipment:0b,ArmorItems:[{},{},{},{}],skinSettings:{npcTypeName:"custom",skinTypeSelected:"default"},HandDropChances:[0.085f,0.085f],factionName:"nogg",HandItems:[{},{}]},maxToSpawn:1,entityId:"ancientwarfarenpc:faction.civilian.female",minToSpawn:1}],groupWeight:1}],playerRange:16,respondToRedstone:0b,inventory:{Size:9,Items:[]},spawnRange:0,transparent:1b,maxDelay:10,spawnYOffset:0,xpToDrop:0,mobRange:0,debugMode:0b,maxNearbyMonsters:0}}}
:enddata
:endrule

rule:
plugin=vanillaBlocks
number=64
data:
JSON:{blockState:{blockName:"minecraft:red_flower",properties:{type:"orange_tulip"}}}
:enddata
:endrule

rule:
plugin=blockTile
number=65
data:
JSON:{blockState:{blockName:"ancientwarfarestructure:advanced_spawner",properties:{transparent:"true"}},teData:{id:"ancientwarfarestructure:advanced_spawner_tile",spawnerSettings:{minDelay:10,spawnDelay:10,lightSensitive:0b,spawnGroups:[{settingsList:[{remainingSpawnCount:1,hostile:1b,customTag:{ArmorDropChances:[0.085f,0.085f,0.085f,0.085f],hasCustomEquipment:0b,ArmorItems:[{},{},{},{}],skinSettings:{npcTypeName:"custom",skinTypeSelected:"default"},HandDropChances:[0.085f,0.085f],factionName:"nogg",HandItems:[{id:"minecraft:bow",Count:1b,Damage:0s},{}]},maxToSpawn:1,entityId:"ancientwarfarenpc:faction.mounted_archer",minToSpawn:1}],groupWeight:1}],playerRange:32,respondToRedstone:0b,inventory:{Size:9,Items:[]},spawnRange:0,transparent:1b,maxDelay:10,spawnYOffset:0,xpToDrop:0,mobRange:0,debugMode:0b,maxNearbyMonsters:0}}}
:enddata
:endrule

rule:
plugin=blockTile
number=66
data:
JSON:{blockState:{blockName:"ancientwarfarestructure:advanced_spawner",properties:{transparent:"true"}},teData:{id:"ancientwarfarestructure:advanced_spawner_tile",spawnerSettings:{minDelay:10,spawnDelay:4,lightSensitive:0b,spawnGroups:[{settingsList:[{remainingSpawnCount:1,hostile:1b,customTag:{ArmorDropChances:[0.085f,0.085f,0.085f,0.085f],hasCustomEquipment:0b,ArmorItems:[{},{},{},{}],skinSettings:{npcTypeName:"custom",skinTypeSelected:"default"},HandDropChances:[0.085f,0.085f],factionName:"nogg",HandItems:[{id:"ancientwarfarenpc:iron_halberd",Count:1b,Damage:0s},{}]},maxToSpawn:1,entityId:"ancientwarfarenpc:faction.soldier",minToSpawn:1}],groupWeight:1}],playerRange:16,respondToRedstone:0b,inventory:{Size:9,Items:[]},spawnRange:0,transparent:1b,maxDelay:10,spawnYOffset:0,xpToDrop:0,mobRange:0,debugMode:0b,maxNearbyMonsters:0}}}
:enddata
:endrule

rule:
plugin=blockTile
number=67
data:
JSON:{blockState:{blockName:"ancientwarfarestructure:advanced_spawner",properties:{transparent:"true"}},teData:{id:"ancientwarfarestructure:advanced_spawner_tile",spawnerSettings:{minDelay:10,spawnDelay:5,lightSensitive:0b,spawnGroups:[{settingsList:[{remainingSpawnCount:1,hostile:1b,customTag:{ArmorDropChances:[0.085f,0.085f,0.085f,0.085f],hasCustomEquipment:0b,ArmorItems:[{},{},{},{}],skinSettings:{npcTypeName:"custom",skinTypeSelected:"default"},HandDropChances:[0.085f,0.085f],factionName:"nogg",HandItems:[{id:"ancientwarfarenpc:iron_halberd",Count:1b,Damage:0s},{}]},maxToSpawn:1,entityId:"ancientwarfarenpc:faction.soldier",minToSpawn:1}],groupWeight:1}],playerRange:16,respondToRedstone:0b,inventory:{Size:9,Items:[]},spawnRange:0,transparent:1b,maxDelay:10,spawnYOffset:0,xpToDrop:0,mobRange:0,debugMode:0b,maxNearbyMonsters:0}}}
:enddata
:endrule

rule:
plugin=blockTile
number=68
data:
JSON:{blockState:{blockName:"ancientwarfarestructure:advanced_spawner",properties:{transparent:"true"}},teData:{id:"ancientwarfarestructure:advanced_spawner_tile",spawnerSettings:{minDelay:10,spawnDelay:9,lightSensitive:0b,spawnGroups:[{settingsList:[{remainingSpawnCount:1,hostile:1b,customTag:{ArmorDropChances:[0.085f,0.085f,0.085f,0.085f],hasCustomEquipment:0b,ArmorItems:[{},{},{},{}],skinSettings:{npcTypeName:"custom",skinTypeSelected:"default"},HandDropChances:[0.085f,0.085f],factionName:"nogg",HandItems:[{id:"minecraft:bow",Count:1b,Damage:0s},{}]},maxToSpawn:1,entityId:"ancientwarfarenpc:faction.archer.elite",minToSpawn:1}],groupWeight:1}],playerRange:32,respondToRedstone:0b,inventory:{Size:9,Items:[]},spawnRange:0,transparent:1b,maxDelay:10,spawnYOffset:0,xpToDrop:0,mobRange:0,debugMode:0b,maxNearbyMonsters:0}}}
:enddata
:endrule

rule:
plugin=blockTile
number=69
data:
JSON:{blockState:{blockName:"ancientwarfarestructure:advanced_spawner",properties:{transparent:"true"}},teData:{id:"ancientwarfarestructure:advanced_spawner_tile",spawnerSettings:{minDelay:10,spawnDelay:4,lightSensitive:0b,spawnGroups:[{settingsList:[{remainingSpawnCount:1,hostile:1b,customTag:{ArmorDropChances:[0.085f,0.085f,0.085f,0.085f],hasCustomEquipment:0b,ArmorItems:[{},{},{},{}],skinSettings:{npcTypeName:"custom",skinTypeSelected:"default"},HandDropChances:[0.085f,0.085f],factionName:"nogg",HandItems:[{id:"ancientwarfarenpc:iron_halberd",Count:1b,Damage:0s},{}]},maxToSpawn:1,entityId:"ancientwarfarenpc:faction.soldier",minToSpawn:1}],groupWeight:1}],playerRange:16,respondToRedstone:0b,inventory:{Size:9,Items:[]},spawnRange:0,transparent:1b,maxDelay:10,spawnYOffset:0,xpToDrop:0,mobRange:0,debugMode:0b,maxNearbyMonsters:0}}}
:enddata
:endrule

rule:
plugin=blockTile
number=70
data:
JSON:{blockState:{blockName:"ancientwarfarestructure:advanced_spawner",properties:{transparent:"true"}},teData:{id:"ancientwarfarestructure:advanced_spawner_tile",spawnerSettings:{minDelay:10,spawnDelay:1,lightSensitive:0b,spawnGroups:[{settingsList:[{remainingSpawnCount:1,hostile:1b,customTag:{ArmorDropChances:[0.085f,0.085f,0.085f,0.085f],hasCustomEquipment:0b,ArmorItems:[{},{},{},{}],skinSettings:{npcTypeName:"custom",skinTypeSelected:"default"},HandDropChances:[0.085f,0.085f],factionName:"nogg",HandItems:[{id:"ancientwarfarenpc:iron_halberd",Count:1b,Damage:0s},{}]},maxToSpawn:1,entityId:"ancientwarfarenpc:faction.soldier",minToSpawn:1}],groupWeight:1}],playerRange:16,respondToRedstone:0b,inventory:{Size:9,Items:[]},spawnRange:0,transparent:1b,maxDelay:10,spawnYOffset:0,xpToDrop:0,mobRange:0,debugMode:0b,maxNearbyMonsters:0}}}
:enddata
:endrule

rule:
plugin=vanillaBlocks
number=71
data:
JSON:{blockState:{blockName:"minecraft:birch_fence_gate",properties:{in_wall:"false",powered:"false",facing:"north",open:"false"}}}
:enddata
:endrule

rule:
plugin=vanillaBlocks
number=72
data:
JSON:{blockState:{blockName:"minecraft:beetroots",properties:{age:"3"}}}
:enddata
:endrule

rule:
plugin=vanillaBlocks
number=73
data:
JSON:{blockState:{blockName:"minecraft:carrots",properties:{age:"7"}}}
:enddata
:endrule

rule:
plugin=vanillaBlocks
number=74
data:
JSON:{blockState:{blockName:"minecraft:potatoes",properties:{age:"7"}}}
:enddata
:endrule

rule:
plugin=blockTile
number=75
data:
JSON:{blockState:{blockName:"ancientwarfarestructure:advanced_spawner",properties:{transparent:"true"}},teData:{id:"ancientwarfarestructure:advanced_spawner_tile",spawnerSettings:{minDelay:10,spawnDelay:9,lightSensitive:0b,spawnGroups:[{settingsList:[{remainingSpawnCount:1,hostile:1b,customTag:{ArmorDropChances:[0.085f,0.085f,0.085f,0.085f],hasCustomEquipment:0b,ArmorItems:[{},{},{},{}],skinSettings:{npcTypeName:"custom",skinTypeSelected:"default"},HandDropChances:[0.085f,0.085f],factionName:"nogg",HandItems:[{id:"ancientwarfarenpc:iron_halberd",Count:1b,Damage:0s},{}]},maxToSpawn:1,entityId:"ancientwarfarenpc:faction.soldier",minToSpawn:1}],groupWeight:1}],playerRange:16,respondToRedstone:0b,inventory:{Size:9,Items:[]},spawnRange:0,transparent:1b,maxDelay:10,spawnYOffset:0,xpToDrop:0,mobRange:0,debugMode:0b,maxNearbyMonsters:0}}}
:enddata
:endrule

rule:
plugin=vanillaBlocks
number=76
data:
JSON:{blockState:{blockName:"minecraft:birch_fence_gate",properties:{in_wall:"false",powered:"false",facing:"west",open:"false"}}}
:enddata
:endrule

rule:
plugin=vanillaBlocks
number=77
data:
JSON:{blockState:{blockName:"minecraft:wooden_slab",properties:{half:"bottom",variant:"birch"}}}
:enddata
:endrule

rule:
plugin=vanillaBlocks
number=78
data:
JSON:{blockState:{blockName:"minecraft:birch_fence_gate",properties:{in_wall:"false",powered:"false",facing:"east",open:"false"}}}
:enddata
:endrule

rule:
plugin=blockTile
number=79
data:
JSON:{blockState:{blockName:"ancientwarfarestructure:advanced_spawner",properties:{transparent:"true"}},teData:{id:"ancientwarfarestructure:advanced_spawner_tile",spawnerSettings:{minDelay:10,spawnDelay:3,lightSensitive:0b,spawnGroups:[{settingsList:[{remainingSpawnCount:1,hostile:1b,customTag:{ArmorDropChances:[0.085f,0.085f,0.085f,0.085f],hasCustomEquipment:0b,ArmorItems:[{},{},{},{}],skinSettings:{npcTypeName:"custom",skinTypeSelected:"default"},HandDropChances:[0.085f,0.085f],factionName:"nogg",HandItems:[{id:"ancientwarfarenpc:iron_halberd",Count:1b,Damage:0s},{}]},maxToSpawn:1,entityId:"ancientwarfarenpc:faction.soldier",minToSpawn:1}],groupWeight:1}],playerRange:16,respondToRedstone:0b,inventory:{Size:9,Items:[]},spawnRange:0,transparent:1b,maxDelay:10,spawnYOffset:0,xpToDrop:0,mobRange:0,debugMode:0b,maxNearbyMonsters:0}}}
:enddata
:endrule

rule:
plugin=blockTile
number=80
data:
JSON:{blockState:{blockName:"ancientwarfarestructure:advanced_spawner",properties:{transparent:"true"}},teData:{id:"ancientwarfarestructure:advanced_spawner_tile",spawnerSettings:{minDelay:10,spawnDelay:5,lightSensitive:0b,spawnGroups:[{settingsList:[{remainingSpawnCount:1,hostile:1b,customTag:{ArmorDropChances:[0.085f,0.085f,0.085f,0.085f],hasCustomEquipment:0b,ArmorItems:[{},{},{},{}],skinSettings:{npcTypeName:"custom",skinTypeSelected:"default"},HandDropChances:[0.085f,0.085f],factionName:"nogg",HandItems:[{id:"ancientwarfarenpc:iron_halberd",Count:1b,Damage:0s},{}]},maxToSpawn:1,entityId:"ancientwarfarenpc:faction.soldier",minToSpawn:1}],groupWeight:1}],playerRange:16,respondToRedstone:0b,inventory:{Size:9,Items:[]},spawnRange:0,transparent:1b,maxDelay:10,spawnYOffset:0,xpToDrop:0,mobRange:0,debugMode:0b,maxNearbyMonsters:0}}}
:enddata
:endrule

rule:
plugin=blockTile
number=81
data:
JSON:{blockState:{blockName:"ancientwarfarestructure:advanced_spawner",properties:{transparent:"true"}},teData:{id:"ancientwarfarestructure:advanced_spawner_tile",spawnerSettings:{minDelay:10,spawnDelay:7,lightSensitive:0b,spawnGroups:[{settingsList:[{remainingSpawnCount:1,hostile:1b,customTag:{ArmorDropChances:[0.085f,0.085f,0.085f,0.085f],hasCustomEquipment:0b,ArmorItems:[{},{},{},{}],skinSettings:{npcTypeName:"custom",skinTypeSelected:"default"},HandDropChances:[0.085f,0.085f],factionName:"nogg",HandItems:[{id:"ancientwarfarenpc:iron_halberd",Count:1b,Damage:0s},{}]},maxToSpawn:1,entityId:"ancientwarfarenpc:faction.soldier",minToSpawn:1}],groupWeight:1}],playerRange:16,respondToRedstone:0b,inventory:{Size:9,Items:[]},spawnRange:0,transparent:1b,maxDelay:10,spawnYOffset:0,xpToDrop:0,mobRange:0,debugMode:0b,maxNearbyMonsters:0}}}
:enddata
:endrule

rule:
plugin=vanillaBlocks
number=82
data:
JSON:{blockState:{blockName:"minecraft:birch_fence_gate",properties:{in_wall:"false",powered:"false",facing:"south",open:"false"}}}
:enddata
:endrule

rule:
plugin=blockTile
number=83
data:
JSON:{blockState:{blockName:"ancientwarfarestructure:advanced_spawner",properties:{transparent:"true"}},teData:{id:"ancientwarfarestructure:advanced_spawner_tile",spawnerSettings:{minDelay:10,spawnDelay:5,lightSensitive:0b,spawnGroups:[{settingsList:[{remainingSpawnCount:1,hostile:1b,customTag:{ArmorDropChances:[0.085f,0.085f,0.085f,0.085f],hasCustomEquipment:0b,ArmorItems:[{},{},{},{}],skinSettings:{npcTypeName:"custom",skinTypeSelected:"default"},HandDropChances:[0.085f,0.085f],factionName:"nogg",HandItems:[{id:"ancientwarfarenpc:iron_halberd",Count:1b,Damage:0s},{}]},maxToSpawn:1,entityId:"ancientwarfarenpc:faction.soldier",minToSpawn:1}],groupWeight:1}],playerRange:16,respondToRedstone:0b,inventory:{Size:9,Items:[]},spawnRange:0,transparent:1b,maxDelay:10,spawnYOffset:0,xpToDrop:0,mobRange:0,debugMode:0b,maxNearbyMonsters:0}}}
:enddata
:endrule

rule:
plugin=blockTile
number=84
data:
JSON:{blockState:{blockName:"ancientwarfarestructure:advanced_spawner",properties:{transparent:"true"}},teData:{id:"ancientwarfarestructure:advanced_spawner_tile",spawnerSettings:{minDelay:10,spawnDelay:6,lightSensitive:0b,spawnGroups:[{settingsList:[{remainingSpawnCount:1,hostile:1b,customTag:{ArmorDropChances:[0.085f,0.085f,0.085f,0.085f],hasCustomEquipment:0b,ArmorItems:[{},{},{},{}],skinSettings:{npcTypeName:"custom",skinTypeSelected:"default"},HandDropChances:[0.085f,0.085f],factionName:"nogg",HandItems:[{id:"ancientwarfarenpc:iron_halberd",Count:1b,Damage:0s},{}]},maxToSpawn:1,entityId:"ancientwarfarenpc:faction.soldier",minToSpawn:1}],groupWeight:1}],playerRange:16,respondToRedstone:0b,inventory:{Size:9,Items:[]},spawnRange:0,transparent:1b,maxDelay:10,spawnYOffset:0,xpToDrop:0,mobRange:0,debugMode:0b,maxNearbyMonsters:0}}}
:enddata
:endrule

rule:
plugin=blockTile
number=85
data:
JSON:{blockState:{blockName:"ancientwarfarestructure:advanced_spawner",properties:{transparent:"true"}},teData:{id:"ancientwarfarestructure:advanced_spawner_tile",spawnerSettings:{minDelay:10,spawnDelay:1,lightSensitive:0b,spawnGroups:[{settingsList:[{remainingSpawnCount:1,hostile:1b,customTag:{ArmorDropChances:[0.085f,0.085f,0.085f,0.085f],hasCustomEquipment:0b,ArmorItems:[{},{},{},{}],skinSettings:{npcTypeName:"custom",skinTypeSelected:"default"},HandDropChances:[0.085f,0.085f],factionName:"nogg",HandItems:[{id:"ancientwarfarenpc:iron_halberd",Count:1b,Damage:0s},{}]},maxToSpawn:1,entityId:"ancientwarfarenpc:faction.soldier",minToSpawn:1}],groupWeight:1}],playerRange:16,respondToRedstone:0b,inventory:{Size:9,Items:[]},spawnRange:0,transparent:1b,maxDelay:10,spawnYOffset:0,xpToDrop:0,mobRange:0,debugMode:0b,maxNearbyMonsters:0}}}
:enddata
:endrule

rule:
plugin=vanillaBlocks
number=86
data:
JSON:{blockState:{blockName:"minecraft:glass_pane",properties:{east:"false",south:"false",north:"false",west:"false"}}}
:enddata
:endrule

rule:
plugin=vanillaBlocks
number=87
data:
JSON:{blockState:{blockName:"minecraft:stone_stairs",properties:{half:"bottom",shape:"straight",facing:"north"}}}
:enddata
:endrule

rule:
plugin=doors
number=88
data:
JSON:{blockState:{blockName:"minecraft:birch_door",properties:{hinge:"right",half:"upper",powered:"false",facing:"north",open:"false"}}}
:enddata
:endrule

rule:
plugin=blockTile
number=89
data:
JSON:{blockState:{blockName:"ancientwarfarestructure:gate_proxy"},teData:{lsb:-8404065744215508488L,id:"ancientwarfarestructure:gate_proxy_tile",msb:-4486452760721078973L,render:0b}}
:enddata
:endrule

rule:
plugin=blockTile
number=90
data:
JSON:{blockState:{blockName:"ancientwarfarestructure:gate_proxy"},teData:{lsb:-8404065744215508488L,id:"ancientwarfarestructure:gate_proxy_tile",msb:-4486452760721078973L,render:0b}}
:enddata
:endrule

rule:
plugin=blockTile
number=91
data:
JSON:{blockState:{blockName:"ancientwarfarestructure:gate_proxy"},teData:{lsb:-8404065744215508488L,id:"ancientwarfarestructure:gate_proxy_tile",msb:-4486452760721078973L,render:0b}}
:enddata
:endrule

rule:
plugin=doors
number=92
data:
JSON:{blockState:{blockName:"minecraft:birch_door",properties:{hinge:"left",half:"upper",powered:"false",facing:"north",open:"false"}}}
:enddata
:endrule

rule:
plugin=blockTile
number=93
data:
JSON:{blockState:{blockName:"ancientwarfarestructure:gate_proxy"},teData:{lsb:-8404065744215508488L,id:"ancientwarfarestructure:gate_proxy_tile",msb:-4486452760721078973L,render:0b}}
:enddata
:endrule

rule:
plugin=inventory
number=94
data:
JSON:{blockState:{blockName:"minecraft:chest",properties:{facing:"south"}},lootLevel:0,teData:{Items:[],id:"minecraft:chest",Lock:""},inventoryData:{length:0,inventoryContents:[]},legacyFeatures:1b}
:enddata
:endrule

rule:
plugin=inventory
number=95
data:
JSON:{blockState:{blockName:"minecraft:chest",properties:{facing:"south"}},lootLevel:0,teData:{Items:[],id:"minecraft:chest",Lock:""},inventoryData:{length:0,inventoryContents:[]},legacyFeatures:1b}
:enddata
:endrule

rule:
plugin=blockTile
number=96
data:
JSON:{blockState:{blockName:"ancientwarfarestructure:advanced_spawner",properties:{transparent:"true"}},teData:{id:"ancientwarfarestructure:advanced_spawner_tile",spawnerSettings:{minDelay:10,spawnDelay:6,lightSensitive:0b,spawnGroups:[{settingsList:[{remainingSpawnCount:1,hostile:1b,customTag:{ArmorDropChances:[0.085f,0.085f,0.085f,0.085f],hasCustomEquipment:0b,ArmorItems:[{},{},{},{}],skinSettings:{npcTypeName:"custom",skinTypeSelected:"default"},HandDropChances:[0.085f,0.085f],factionName:"nogg",HandItems:[{id:"ancientwarfarenpc:iron_lance",Count:1b,Damage:0s},{id:"ancientwarfarenpc:shield_round_5",Count:1b,Damage:0s}]},maxToSpawn:1,entityId:"ancientwarfarenpc:faction.cavalry",minToSpawn:1}],groupWeight:1}],playerRange:16,respondToRedstone:0b,inventory:{Size:9,Items:[]},spawnRange:0,transparent:1b,maxDelay:10,spawnYOffset:0,xpToDrop:0,mobRange:0,debugMode:0b,maxNearbyMonsters:0}}}
:enddata
:endrule

rule:
plugin=vanillaBlocks
number=97
data:
JSON:{blockState:{blockName:"minecraft:torch",properties:{facing:"up"}}}
:enddata
:endrule

rule:
plugin=blockTile
number=98
data:
JSON:{blockState:{blockName:"ancientwarfarestructure:advanced_spawner",properties:{transparent:"true"}},teData:{id:"ancientwarfarestructure:advanced_spawner_tile",spawnerSettings:{minDelay:10,spawnDelay:2,lightSensitive:0b,spawnGroups:[{settingsList:[{remainingSpawnCount:1,hostile:1b,customTag:{ArmorDropChances:[0.085f,0.085f,0.085f,0.085f],hasCustomEquipment:0b,ArmorItems:[{},{},{},{}],skinSettings:{npcTypeName:"custom",skinTypeSelected:"default"},HandDropChances:[0.085f,0.085f],factionName:"nogg",HandItems:[{},{}]},maxToSpawn:1,entityId:"ancientwarfarenpc:faction.civilian.male",minToSpawn:1}],groupWeight:1}],playerRange:16,respondToRedstone:0b,inventory:{Size:9,Items:[]},spawnRange:0,transparent:1b,maxDelay:10,spawnYOffset:0,xpToDrop:0,mobRange:0,debugMode:0b,maxNearbyMonsters:0}}}
:enddata
:endrule

rule:
plugin=blockTile
number=99
data:
JSON:{blockState:{blockName:"ancientwarfarestructure:advanced_spawner",properties:{transparent:"true"}},teData:{id:"ancientwarfarestructure:advanced_spawner_tile",spawnerSettings:{minDelay:10,spawnDelay:4,lightSensitive:0b,spawnGroups:[{settingsList:[{remainingSpawnCount:1,hostile:1b,customTag:{ArmorDropChances:[0.085f,0.085f,0.085f,0.085f],hasCustomEquipment:0b,ArmorItems:[{},{},{},{}],skinSettings:{npcTypeName:"custom",skinTypeSelected:"default"},HandDropChances:[0.085f,0.085f],factionName:"nogg",HandItems:[{},{}]},maxToSpawn:1,entityId:"ancientwarfarenpc:faction.civilian.female",minToSpawn:1}],groupWeight:1}],playerRange:16,respondToRedstone:0b,inventory:{Size:9,Items:[]},spawnRange:0,transparent:1b,maxDelay:10,spawnYOffset:0,xpToDrop:0,mobRange:0,debugMode:0b,maxNearbyMonsters:0}}}
:enddata
:endrule

rule:
plugin=vanillaBlocks
number=100
data:
JSON:{blockState:{blockName:"minecraft:torch",properties:{facing:"north"}}}
:enddata
:endrule

rule:
plugin=vanillaBlocks
number=101
data:
JSON:{blockState:{blockName:"minecraft:stone_stairs",properties:{half:"bottom",shape:"straight",facing:"south"}}}
:enddata
:endrule

rule:
plugin=vanillaBlocks
number=102
data:
JSON:{blockState:{blockName:"minecraft:torch",properties:{facing:"west"}}}
:enddata
:endrule

rule:
plugin=vanillaBlocks
number=103
data:
JSON:{blockState:{blockName:"minecraft:torch",properties:{facing:"east"}}}
:enddata
:endrule

rule:
plugin=vanillaBlocks
number=104
data:
JSON:{blockState:{blockName:"minecraft:stone_stairs",properties:{half:"top",shape:"straight",facing:"south"}}}
:enddata
:endrule

rule:
plugin=vanillaBlocks
number=105
data:
JSON:{blockState:{blockName:"minecraft:stone_slab",properties:{half:"top",variant:"cobblestone"}}}
:enddata
:endrule

rule:
plugin=vanillaBlocks
number=106
data:
JSON:{blockState:{blockName:"minecraft:torch",properties:{facing:"south"}}}
:enddata
:endrule

rule:
plugin=blockTile
number=107
data:
JSON:{blockState:{blockName:"ancientwarfarestructure:gate_proxy"},teData:{lsb:-8404065744215508488L,id:"ancientwarfarestructure:gate_proxy_tile",msb:-4486452760721078973L,render:0b}}
:enddata
:endrule

rule:
plugin=blockTile
number=108
data:
JSON:{blockState:{blockName:"ancientwarfarestructure:gate_proxy"},teData:{lsb:-8404065744215508488L,id:"ancientwarfarestructure:gate_proxy_tile",msb:-4486452760721078973L,render:0b}}
:enddata
:endrule

rule:
plugin=blockTile
number=109
data:
JSON:{blockState:{blockName:"ancientwarfarestructure:gate_proxy"},teData:{lsb:-8404065744215508488L,id:"ancientwarfarestructure:gate_proxy_tile",msb:-4486452760721078973L,render:0b}}
:enddata
:endrule

rule:
plugin=blockTile
number=110
data:
JSON:{blockState:{blockName:"ancientwarfarestructure:gate_proxy"},teData:{lsb:-8404065744215508488L,id:"ancientwarfarestructure:gate_proxy_tile",msb:-4486452760721078973L,render:0b}}
:enddata
:endrule

rule:
plugin=vanillaBlocks
number=111
data:
JSON:{blockState:{blockName:"minecraft:leaves",properties:{check_decay:"false",decayable:"true",variant:"birch"}}}
:enddata
:endrule

rule:
plugin=vanillaBlocks
number=112
data:
JSON:{blockState:{blockName:"minecraft:wooden_slab",properties:{half:"top",variant:"birch"}}}
:enddata
:endrule

rule:
plugin=vanillaBlocks
number=113
data:
JSON:{blockState:{blockName:"minecraft:stone_stairs",properties:{half:"bottom",shape:"straight",facing:"east"}}}
:enddata
:endrule

rule:
plugin=vanillaBlocks
number=114
data:
JSON:{blockState:{blockName:"minecraft:cobblestone_wall",properties:{east:"false",south:"false",north:"false",variant:"cobblestone",west:"false",up:"false"}}}
:enddata
:endrule

#### ENTITIES ####
entity:
plugin=awGate
number=0
data:
JSON:{owner:"",orientation:5b,pos1:{x:0,y:0,z:-2},pos2:{x:0,y:2,z:1},position:2474236706826L,gateType:"gate.doubleWood"}
:enddata
:endentity

