# Ancient Warfare Structure Template File
# Auto-generated structure template file. created on: 3/15/2024 at: 14:32:27
# Lines beginning with # denote comments

header:
version=2.11
name=MinossianFortress
mods=
size=24,22,27
offset=12,6,26
:endheader

#### VALIDATION ####
validation:
type=ground
structureAuthor=TheOddlySeagull
survival=false
worldGenEnabled=true
unique=false
preserveBlocks=false
preventNaturalHostileSpawns=true
selectionWeight=50
clusterValue=10
minDuplicateDistance=1000
dimensionWhiteList=true
dimensionList=0
biomeGroupList=minossian
biomeWhiteList=true
biomeList=biomesoplenty:tropical_island,nt:iron_beach,biomesoplenty:origin_beach,nt:orange_beach,nt:purple_beach,nt:aegean_archipelago,biomesoplenty:white_beach,minecraft:beaches,biomesoplenty:mangrove,nt:black_beach
leveling=12
fill=12
border=6
blockSwap=false
territoryName=minossian
biomeReplacement=minecraft:
minGenerationHeight=0
maxGenerationHeight=255
:endvalidation

#### LAYERS ####
layer: 0
1,1,1,1,1,1,1,1,1,1,1,1,1,1,1,1,1,1,1,1,1,1,1,1
1,1,1,1,1,1,1,1,1,1,1,1,1,1,1,1,1,1,1,1,1,1,1,1
1,1,1,1,1,1,1,1,1,1,1,1,1,1,1,1,1,1,1,1,1,1,1,1
1,1,1,1,1,1,1,1,1,1,1,1,1,1,1,1,1,1,1,1,1,1,1,1
1,1,1,1,1,1,1,1,1,1,1,1,1,1,1,1,1,1,1,1,1,1,1,1
1,1,1,1,1,1,1,1,1,1,1,1,1,1,1,1,1,1,1,1,1,1,1,1
1,1,1,1,1,1,1,1,1,1,1,1,1,1,1,1,1,1,1,1,1,1,1,1
1,1,1,1,1,1,1,1,1,1,1,1,1,1,1,1,1,1,1,1,1,1,1,1
1,1,1,1,1,1,1,1,1,1,1,1,1,1,1,1,1,1,1,1,1,1,1,1
1,1,1,1,1,1,1,1,1,1,1,1,1,1,1,1,1,1,1,1,1,1,1,1
1,1,1,1,1,1,1,1,1,1,1,1,1,1,1,1,1,1,1,1,1,1,1,1
1,1,1,1,1,1,1,1,1,1,1,1,1,1,1,1,1,1,1,1,1,1,1,1
1,1,1,1,1,1,1,1,1,1,1,1,1,1,1,1,1,1,1,1,1,1,1,1
1,1,1,1,1,1,1,1,1,1,1,1,1,1,1,1,1,1,1,1,1,1,1,1
1,1,1,1,1,1,1,1,1,1,1,1,1,1,1,1,1,1,1,1,1,1,1,1
1,1,1,1,1,1,1,1,1,1,1,1,1,1,1,1,1,1,1,1,1,1,1,1
1,1,1,1,1,1,1,1,1,1,1,1,1,1,1,1,1,1,1,1,1,1,1,1
1,1,1,1,1,1,1,1,1,1,1,1,1,1,1,1,1,1,1,1,1,1,1,1
1,1,1,1,1,1,1,1,1,1,1,1,1,1,1,1,1,1,1,1,1,1,1,1
1,1,1,1,1,1,1,1,1,1,1,1,1,1,1,1,1,1,1,1,1,1,1,1
1,1,1,1,1,1,1,1,1,1,1,1,1,1,1,1,1,1,1,1,1,1,1,1
1,1,1,1,1,1,1,1,1,1,1,1,1,1,1,1,1,1,1,1,1,1,1,1
1,1,1,1,1,1,1,1,1,1,1,1,1,1,1,1,1,1,1,1,1,1,1,1
1,1,1,1,1,1,1,1,1,1,1,1,1,1,1,1,1,1,1,1,1,1,1,1
1,1,1,1,1,1,1,1,1,1,1,1,1,1,1,1,1,1,1,1,1,1,1,1
1,1,1,1,1,1,1,1,1,1,1,1,1,1,1,1,1,1,1,1,1,1,1,1
1,1,1,1,1,1,1,1,1,1,1,1,1,1,1,1,1,1,1,1,1,1,1,1
:endlayer
layer: 1
1,1,1,1,1,1,1,1,1,1,1,1,1,1,1,1,1,1,1,1,1,1,1,1
1,1,1,1,1,1,1,1,1,1,1,1,1,1,1,1,1,1,1,1,1,1,1,1
1,1,1,1,1,1,1,1,1,1,1,1,1,1,1,1,1,1,1,1,1,1,1,1
1,1,1,1,1,1,1,1,1,1,1,1,1,1,1,1,1,1,1,1,1,1,1,1
1,1,1,1,1,1,1,1,1,1,1,1,1,1,1,1,1,1,1,1,1,1,1,1
1,1,1,1,1,1,1,1,1,1,1,1,1,1,1,1,1,1,1,1,1,1,1,1
1,1,1,1,1,1,1,1,1,1,1,1,1,1,1,1,1,1,1,1,1,1,1,1
1,1,1,1,1,1,1,1,1,1,1,1,1,1,1,1,1,1,1,1,1,1,1,1
1,1,1,1,1,1,1,1,1,1,1,1,1,1,1,1,1,1,1,1,1,1,1,1
1,1,1,1,1,1,1,1,1,1,1,1,1,1,1,1,1,1,1,1,1,1,1,1
1,1,1,1,1,1,1,1,1,1,1,1,1,1,1,1,1,1,1,1,1,1,1,1
1,1,1,1,1,1,1,1,1,1,1,1,1,1,1,1,1,1,1,1,1,1,1,1
1,1,1,1,1,1,1,1,1,1,1,1,1,1,1,1,1,1,1,1,1,1,1,1
1,1,1,1,1,1,1,1,1,1,1,1,1,1,1,1,1,1,1,1,1,1,1,1
1,1,1,1,1,1,1,1,1,1,1,1,1,1,1,1,1,1,1,1,1,1,1,1
1,1,1,1,1,1,1,1,1,1,1,1,1,1,1,1,1,1,1,1,1,1,1,1
1,1,1,1,1,1,1,1,1,1,1,1,1,1,1,1,1,1,1,1,1,1,1,1
1,1,1,1,1,1,1,1,1,1,1,1,1,1,1,1,1,1,1,1,1,1,1,1
1,1,1,1,1,1,1,1,1,1,1,1,1,1,1,1,1,1,1,1,1,1,1,1
1,1,1,1,1,1,1,1,1,1,1,1,1,1,1,1,1,1,1,1,1,1,1,1
1,1,1,1,1,1,1,1,1,1,1,1,1,1,1,1,1,1,1,1,1,1,1,1
1,1,1,1,1,1,1,1,1,1,1,1,1,1,1,1,1,1,1,1,1,1,1,1
1,1,1,1,1,1,1,1,1,1,1,1,1,1,1,1,1,1,1,1,1,1,1,1
1,1,1,1,1,1,1,1,1,1,1,1,1,1,1,1,1,1,1,1,1,1,1,1
1,1,1,1,1,1,1,1,1,1,1,1,1,1,1,1,1,1,1,1,1,1,1,1
1,1,1,1,1,1,1,1,1,1,1,1,1,1,1,1,1,1,1,1,1,1,1,1
1,1,1,1,1,1,1,1,1,1,1,1,1,1,1,1,1,1,1,1,1,1,1,1
:endlayer
layer: 2
1,1,1,1,1,1,1,1,1,1,1,1,1,1,1,1,1,1,1,1,1,1,1,1
1,1,1,1,1,1,1,1,1,1,1,1,1,1,1,1,1,1,1,1,1,1,1,1
1,1,1,1,1,1,1,1,1,1,1,1,1,1,1,1,1,1,1,1,1,1,1,1
1,1,1,1,1,1,1,1,1,1,1,1,1,1,1,1,1,1,1,1,1,1,1,1
1,1,1,1,1,1,1,1,1,1,1,1,1,1,1,1,1,1,1,1,1,1,1,1
1,1,1,1,1,1,1,1,1,1,1,1,1,1,1,1,1,1,1,1,1,1,1,1
1,1,1,1,1,1,1,1,1,1,1,1,1,1,1,1,1,1,1,1,1,1,1,1
1,1,1,1,1,1,1,1,1,1,1,1,1,1,1,1,1,1,1,1,1,1,1,1
1,1,1,1,1,1,1,1,1,1,1,1,1,1,1,1,1,1,1,1,1,1,1,1
1,1,1,1,1,1,1,1,1,1,1,1,1,1,1,1,1,1,1,1,1,1,1,1
1,1,1,1,1,1,1,1,1,1,1,1,1,1,1,1,1,1,1,1,1,1,1,1
1,1,1,1,1,1,1,1,1,1,1,1,1,1,1,1,1,1,1,1,1,1,1,1
1,1,1,1,1,1,1,1,1,1,1,1,1,1,1,1,1,1,1,1,1,1,1,1
1,1,1,1,1,1,1,1,1,1,1,1,1,1,1,1,1,1,1,1,1,1,1,1
1,1,1,1,1,1,1,1,1,1,1,1,1,1,1,1,1,1,1,1,1,1,1,1
1,1,1,1,1,1,1,1,1,1,1,1,1,1,1,1,1,1,1,1,1,1,1,1
1,1,1,1,1,1,1,1,1,1,1,1,1,1,1,1,1,1,1,1,1,1,1,1
1,1,1,1,1,1,1,1,1,1,1,1,1,1,1,1,1,1,1,1,1,1,1,1
1,1,1,1,1,1,1,1,1,1,1,1,1,1,1,1,1,1,1,1,1,1,1,1
1,1,1,1,1,1,1,1,1,1,1,1,1,1,1,1,1,1,1,1,1,1,1,1
1,1,1,1,1,1,1,1,1,1,1,1,1,1,1,1,1,1,1,1,1,1,1,1
1,1,1,1,1,1,1,1,1,1,1,1,1,1,1,1,1,1,1,1,1,1,1,1
1,1,1,1,1,1,1,1,1,1,1,1,1,1,1,1,1,1,1,1,1,1,1,1
1,1,1,1,1,1,1,1,1,1,1,1,1,1,1,1,1,1,1,1,1,1,1,1
1,1,1,1,1,1,1,1,1,1,1,1,1,1,1,1,1,1,1,1,1,1,1,1
1,1,1,1,1,1,1,1,1,1,1,1,1,1,1,1,1,1,1,1,1,1,1,1
1,1,1,1,1,1,1,1,1,1,1,1,1,1,1,1,1,1,1,1,1,1,1,1
:endlayer
layer: 3
1,1,1,1,1,1,1,1,1,1,1,1,1,1,1,1,1,1,1,1,1,1,1,1
1,1,1,1,1,1,1,1,1,1,1,1,1,1,1,1,1,1,1,1,1,1,1,1
1,1,1,1,1,1,1,1,1,1,1,1,1,1,1,1,1,1,1,1,1,1,1,1
1,1,1,1,1,1,1,1,1,1,1,1,1,1,1,1,1,1,1,1,1,1,1,1
1,1,1,1,1,1,1,1,1,1,1,1,1,1,1,1,1,1,1,1,1,1,1,1
1,1,1,1,1,1,1,1,1,1,1,1,1,1,1,1,1,1,1,1,1,1,1,1
1,1,1,1,1,1,1,1,1,1,1,1,1,1,1,1,1,1,1,1,1,1,1,1
1,1,1,1,1,1,1,1,1,1,1,1,1,1,1,1,1,1,1,1,1,1,1,1
1,1,1,1,1,1,1,1,1,1,1,1,1,1,1,1,1,1,1,1,1,1,1,1
1,1,1,1,1,1,1,1,1,1,1,1,1,1,1,1,1,1,1,1,1,1,1,1
1,1,1,1,1,1,1,1,1,1,1,1,1,1,1,1,1,1,1,1,1,1,1,1
1,1,1,1,1,1,1,1,1,1,1,1,1,1,1,1,1,1,1,1,1,1,1,1
1,1,1,1,1,1,1,1,1,1,1,1,1,1,1,1,1,1,1,1,1,1,1,1
1,1,1,1,1,1,1,1,1,1,1,1,1,1,1,1,1,1,1,1,1,1,1,1
1,1,1,1,1,1,1,1,1,1,1,1,1,1,1,1,1,1,1,1,1,1,1,1
1,1,1,1,1,1,1,1,1,1,1,1,1,1,1,1,1,1,1,1,1,1,1,1
1,1,1,1,1,1,1,1,1,1,1,1,1,1,1,1,1,1,1,1,1,1,1,1
1,1,1,1,1,1,1,1,1,1,1,1,1,1,1,1,1,1,1,1,1,1,1,1
1,1,1,1,1,1,1,1,1,1,1,1,1,1,1,1,1,1,1,1,1,1,1,1
1,1,1,1,1,1,1,1,1,1,1,1,1,1,1,1,1,1,1,1,1,1,1,1
1,1,1,1,1,1,1,1,1,1,1,1,1,1,1,1,1,1,1,1,1,1,1,1
1,1,1,1,1,1,1,1,1,1,1,1,1,1,1,1,1,1,1,1,1,1,1,1
1,1,1,1,1,1,1,1,1,1,1,1,1,1,1,1,1,1,1,1,1,1,1,1
1,1,1,1,1,1,1,1,1,1,1,1,1,1,1,1,1,1,1,1,1,1,1,1
1,1,1,1,1,1,1,1,1,1,1,1,1,1,1,1,1,1,1,1,1,1,1,1
1,1,1,1,1,1,1,1,1,1,1,1,1,1,1,1,1,1,1,1,1,1,1,1
1,1,1,1,1,1,1,1,1,1,1,1,1,1,1,1,1,1,1,1,1,1,1,1
:endlayer
layer: 4
2,2,2,2,2,2,2,2,2,2,2,2,2,2,2,2,2,2,2,2,2,2,2,2
2,1,1,1,1,1,1,1,1,1,1,1,1,1,1,1,1,1,1,1,1,1,1,2
2,1,1,1,1,1,1,1,1,1,1,1,1,1,1,1,1,1,1,1,1,1,1,2
2,1,1,1,1,1,1,1,1,1,1,1,1,1,1,1,1,1,1,1,1,1,1,2
2,1,1,1,1,1,1,1,1,1,1,1,1,1,1,1,1,1,1,1,1,1,1,2
2,1,1,1,1,1,1,1,1,1,1,1,1,1,1,1,1,1,1,1,1,1,1,2
2,1,1,1,1,1,1,1,1,1,1,1,1,1,1,1,1,1,1,1,1,1,1,2
2,1,1,1,1,1,1,1,1,1,1,1,1,1,1,1,1,1,1,1,1,1,1,2
2,1,1,1,1,1,1,1,1,1,1,1,1,1,1,1,1,1,1,1,1,1,1,2
2,1,1,1,1,1,1,1,1,1,1,1,1,1,1,1,1,1,1,1,1,1,1,2
2,1,1,1,1,1,1,1,1,1,1,1,1,1,1,1,1,1,1,1,1,1,1,2
2,1,1,1,1,1,1,1,1,1,1,1,1,1,1,1,1,1,1,1,1,1,1,2
2,1,1,1,1,1,1,1,1,1,1,1,1,1,1,1,1,1,1,1,1,1,1,2
2,1,1,1,1,1,1,1,1,1,1,1,1,1,1,1,1,1,1,1,1,1,1,2
2,1,1,1,1,1,1,1,1,1,1,1,1,1,1,1,1,1,1,1,1,1,1,2
2,1,1,1,1,1,1,1,1,1,1,1,1,1,1,1,1,1,1,1,1,1,1,2
2,1,1,1,1,1,1,1,1,1,1,1,1,1,1,1,1,1,1,1,1,1,1,2
2,1,1,1,1,1,1,1,1,1,1,1,1,1,1,1,1,1,1,1,1,1,1,2
2,1,1,1,1,1,1,1,1,1,1,1,1,1,1,1,1,1,1,1,1,1,1,2
2,1,1,1,1,1,1,1,1,1,1,1,1,1,1,1,1,1,1,1,1,1,1,2
2,1,1,1,1,1,1,1,1,1,1,1,1,1,1,1,1,1,1,1,1,1,1,2
2,1,1,1,1,1,1,1,1,1,1,1,1,1,1,1,1,1,1,1,1,1,1,2
2,1,1,1,1,1,1,1,1,1,1,1,1,1,1,1,1,1,1,1,1,1,1,2
2,1,1,1,1,1,1,1,1,1,1,1,1,1,1,1,1,1,1,1,1,1,1,2
2,1,1,1,1,1,1,1,1,1,1,1,1,1,1,1,1,1,1,1,1,1,1,2
2,1,1,1,1,1,1,1,1,1,1,1,1,1,1,1,1,1,1,1,1,1,1,2
2,2,2,2,2,2,2,2,2,2,2,2,2,2,2,2,2,2,2,2,2,2,2,2
:endlayer
layer: 5
2,2,2,2,2,2,2,2,2,2,2,2,2,2,2,2,2,2,2,2,2,2,2,2
2,2,2,2,2,1,1,1,1,1,1,1,1,1,1,1,1,1,1,2,2,2,2,2
2,2,2,2,2,1,1,1,1,1,1,1,1,1,1,1,1,1,1,2,2,2,2,2
2,1,1,1,1,1,1,1,1,1,1,1,1,1,1,1,1,1,1,1,1,1,1,2
2,1,1,1,1,1,1,1,1,1,1,1,1,1,1,1,1,1,1,1,1,1,1,2
2,1,1,1,1,1,1,1,1,1,1,1,1,1,1,1,1,1,1,1,1,1,1,2
2,1,1,1,4,11,11,11,11,5,1,1,1,1,1,1,1,1,1,1,1,1,1,2
2,1,1,1,4,6,7,7,6,5,1,1,1,1,1,1,1,1,1,1,1,1,1,2
2,1,1,8,4,7,9,9,7,5,8,1,1,1,1,1,1,1,1,1,1,1,1,2
2,1,1,1,4,10,9,9,10,5,1,1,1,1,1,1,1,1,1,1,1,1,1,2
2,1,1,1,4,10,9,9,10,5,1,1,1,1,1,1,1,1,1,1,1,1,1,2
2,1,1,8,4,7,9,9,7,5,8,1,1,1,1,1,1,1,1,1,1,1,1,2
2,1,1,1,4,6,7,7,6,5,1,1,1,1,1,1,1,1,1,1,1,1,1,2
2,1,1,1,4,3,3,3,3,3,1,1,1,1,1,1,1,1,1,1,1,1,1,2
2,1,1,1,1,1,1,1,1,1,1,1,1,1,1,1,1,1,1,1,1,1,1,2
2,1,1,1,1,1,1,1,1,1,1,1,1,1,1,1,1,1,1,1,1,1,1,2
2,1,1,1,1,1,1,1,1,1,1,1,1,1,1,1,1,1,1,1,1,1,1,2
2,1,1,1,1,1,1,1,1,1,1,1,1,1,1,1,1,1,1,1,1,1,1,2
2,1,1,1,1,1,1,1,1,1,1,1,1,1,1,1,1,1,1,1,1,1,1,2
2,1,1,1,1,1,1,1,1,1,1,1,1,1,1,1,1,1,1,1,1,1,1,2
2,1,1,1,1,1,1,1,1,1,1,1,1,1,1,1,1,1,1,1,1,1,1,2
2,1,1,1,1,1,1,1,1,1,1,1,1,1,1,1,1,1,1,1,1,1,1,2
2,1,1,1,1,1,1,1,1,1,1,1,1,1,1,1,1,1,1,1,1,1,1,2
2,1,1,1,1,1,1,1,1,1,1,1,1,1,1,1,1,1,1,1,1,1,1,2
2,1,1,1,1,1,1,1,1,1,1,1,1,1,1,1,1,1,1,1,1,1,1,2
2,1,1,1,1,1,1,1,1,1,1,1,1,1,1,1,1,1,1,1,1,1,1,2
2,2,2,2,2,2,2,2,2,2,2,2,2,2,2,2,2,2,2,2,2,2,2,2
:endlayer
layer: 6
0,0,0,0,0,0,0,0,0,0,0,0,0,0,0,0,0,0,0,0,0,0,0,0
0,0,0,0,0,0,0,0,0,0,0,0,0,0,0,0,0,0,0,0,0,0,0,0
0,0,0,0,0,0,56,1,1,1,57,57,57,57,1,1,1,54,0,0,0,53,0,0
0,0,0,0,0,0,56,1,1,1,1,55,55,1,1,1,1,54,0,0,53,53,53,0
0,0,16,1,1,1,1,1,1,1,1,1,1,1,1,1,1,1,1,1,1,16,53,0
0,0,1,6,0,0,0,0,52,51,6,1,1,44,43,34,33,16,0,42,0,1,0,0
0,0,1,0,0,0,0,0,0,0,0,1,1,0,50,0,0,0,0,29,42,1,0,0
0,0,1,0,0,6,0,0,6,0,0,1,1,0,0,29,49,16,42,29,42,1,0,0
0,0,1,0,0,0,48,0,0,0,0,1,1,0,16,16,16,16,0,42,0,1,0,0
0,0,1,0,0,0,0,47,0,0,0,1,1,0,16,29,0,0,46,0,0,1,0,0
0,0,1,0,0,0,0,0,0,0,0,1,1,45,16,44,43,16,0,0,42,1,0,0
0,0,1,0,0,0,41,0,0,40,0,1,1,16,16,16,16,16,16,0,16,1,0,0
0,0,1,0,0,6,0,0,6,0,0,0,0,0,0,0,39,16,21,0,21,1,0,0
0,0,1,38,0,0,0,0,0,0,0,0,0,0,0,37,0,0,0,0,0,1,0,0
0,0,1,6,0,0,0,0,0,0,6,0,0,0,0,0,0,16,0,0,0,1,0,0
0,0,1,1,1,1,1,1,1,1,1,1,1,16,16,16,16,16,0,0,0,1,36,0
0,0,1,21,0,21,6,21,0,21,6,1,1,35,0,34,33,16,32,0,31,1,0,0
0,0,1,0,0,0,0,0,0,0,30,1,1,0,0,0,29,16,0,0,0,1,0,0
0,0,1,0,1,0,28,0,1,0,27,1,1,26,0,0,25,16,0,0,0,1,0,0
0,0,1,0,21,0,0,0,21,0,1,1,1,1,0,0,0,16,21,0,21,1,0,0
0,0,1,0,21,0,0,0,21,0,1,1,1,1,16,0,16,16,16,0,16,1,0,0
0,0,1,0,1,0,0,0,1,0,1,1,1,1,0,0,0,24,0,0,0,1,0,0
0,0,1,0,23,0,0,0,22,0,1,1,1,1,0,1,0,0,0,1,0,1,0,0
0,0,1,21,0,0,0,0,0,21,1,1,1,1,20,19,0,0,0,0,0,1,0,0
0,0,16,1,1,1,17,1,1,1,16,18,18,16,1,1,1,17,1,1,1,16,0,0
0,0,0,0,15,0,0,0,14,0,0,0,0,0,0,13,0,0,0,12,0,0,0,0
0,0,0,0,0,0,0,0,0,0,0,0,0,0,0,0,0,0,0,0,0,0,0,0
:endlayer
layer: 7
0,0,0,0,0,0,0,0,0,0,0,0,0,0,0,0,0,0,0,0,0,0,0,0
0,0,0,0,0,0,0,0,0,0,0,0,0,0,0,0,0,0,0,0,0,0,0,0
0,0,0,0,0,0,0,56,1,1,0,0,0,0,1,1,54,0,0,0,0,0,0,0
0,0,0,0,0,0,0,56,1,1,1,0,0,1,1,1,54,0,0,0,0,53,53,0
0,0,16,1,1,1,1,1,1,1,1,1,1,1,1,1,1,1,1,1,1,16,0,0
0,0,1,65,0,0,0,0,0,0,65,1,1,0,0,0,0,16,0,0,0,1,0,0
0,0,1,0,0,0,0,0,0,0,0,1,1,0,0,0,0,0,0,0,0,1,0,0
0,0,1,0,0,6,0,0,6,0,0,1,1,0,0,67,0,16,0,0,0,1,0,0
0,0,1,0,0,0,0,0,0,0,0,1,1,0,16,16,16,16,0,0,0,1,0,0
0,0,1,0,0,0,0,0,0,0,0,1,1,0,16,66,0,0,0,0,0,1,0,0
0,0,1,0,0,0,0,0,0,0,0,1,1,0,16,0,0,16,0,0,0,1,0,0
0,0,1,0,0,0,0,0,0,0,0,1,1,16,16,16,16,16,16,0,16,1,0,0
0,0,1,0,0,6,0,0,6,0,0,0,0,0,0,0,0,16,21,0,21,1,0,0
0,0,1,0,0,0,0,0,0,0,0,0,0,0,0,0,0,0,0,0,0,1,0,0
0,0,1,65,0,0,0,0,0,0,61,0,0,0,0,0,0,16,0,0,0,1,0,0
0,0,1,1,1,1,1,1,1,1,1,1,1,16,16,16,16,16,0,0,0,1,0,0
0,0,1,21,0,21,64,21,0,21,63,1,1,0,0,0,0,16,0,0,0,1,0,0
0,0,1,0,0,0,0,0,0,0,0,1,1,0,0,0,62,16,0,0,0,1,0,0
0,0,1,0,61,0,0,0,61,0,0,1,1,0,0,0,0,16,0,0,0,1,0,0
0,0,1,0,0,0,0,0,0,0,1,1,1,61,0,0,0,16,21,0,21,1,0,0
0,0,1,0,0,0,0,0,0,0,1,1,1,1,16,0,16,16,16,0,16,1,0,0
0,0,1,0,61,0,0,0,61,0,1,1,1,1,0,0,0,0,0,0,0,1,0,0
0,0,1,0,0,0,0,0,0,0,1,1,1,1,0,61,0,0,0,61,0,1,0,0
0,0,1,21,0,0,0,0,0,21,1,18,18,1,0,0,0,0,0,0,0,1,0,0
0,0,58,1,1,1,60,1,1,1,58,0,0,58,1,1,1,59,1,1,1,58,0,0
0,0,0,0,0,0,0,0,0,0,0,0,0,0,0,0,0,0,0,0,0,0,0,0
0,0,0,0,0,0,0,0,0,0,0,0,0,0,0,0,0,0,0,0,0,0,0,0
:endlayer
layer: 8
0,0,0,0,0,0,0,0,0,0,0,0,0,0,0,0,0,0,0,0,0,0,0,0
0,0,0,0,0,0,0,0,0,0,0,0,0,0,0,0,0,0,0,0,0,0,0,0
0,0,0,0,0,0,0,0,56,1,0,0,0,0,1,54,0,0,0,0,0,0,0,0
0,0,0,0,0,0,0,0,56,1,1,72,71,1,1,54,0,0,0,0,0,53,53,0
0,0,58,1,21,1,1,1,1,1,1,1,1,1,1,1,1,1,1,21,1,58,0,0
0,0,1,0,0,0,0,0,0,0,0,1,1,0,0,0,0,16,0,0,0,1,0,0
0,0,1,0,0,0,0,0,0,0,0,1,1,0,0,0,0,16,0,0,0,1,0,0
0,0,1,0,0,6,0,0,6,0,0,1,1,0,0,0,0,16,0,0,0,1,0,0
0,0,1,0,0,0,0,0,0,0,0,1,1,16,16,16,16,16,0,0,0,1,0,0
0,0,1,0,0,0,0,0,0,0,0,1,1,0,16,0,0,16,0,0,0,1,0,0
0,0,1,0,0,0,0,0,0,0,0,1,1,0,16,0,0,16,0,0,0,1,0,0
0,0,1,0,0,0,0,0,0,0,0,1,1,16,16,16,16,16,16,16,16,1,0,0
0,0,1,0,0,6,0,0,6,0,0,70,70,0,0,0,0,16,21,21,21,1,0,0
0,0,1,0,0,0,0,0,0,0,0,0,0,0,0,0,0,16,0,0,0,1,0,0
0,0,1,0,0,0,0,0,0,0,0,69,69,0,0,0,0,16,0,0,0,1,0,0
0,0,1,1,1,1,1,1,1,1,1,1,1,16,16,16,16,16,0,0,0,1,0,0
0,0,1,21,0,21,0,21,0,21,0,1,1,0,0,0,0,16,0,0,0,1,0,0
0,0,1,0,0,0,0,0,0,0,0,1,1,0,0,0,0,16,0,0,0,1,0,0
0,0,1,0,0,0,0,0,0,0,0,1,1,0,0,0,0,16,0,0,0,1,0,0
0,0,1,0,0,0,0,0,0,0,1,1,1,0,0,0,0,16,21,21,21,1,0,0
0,0,1,0,0,0,0,0,0,0,1,1,1,1,16,16,16,16,16,16,16,1,0,0
0,0,1,0,0,0,0,0,0,0,1,1,1,1,0,0,0,0,0,0,0,1,0,0
0,0,1,0,0,0,0,0,0,0,1,18,18,1,0,0,0,0,0,0,0,1,0,0
0,0,1,21,0,0,0,0,0,21,1,0,0,1,0,0,0,0,0,0,0,1,0,0
0,0,16,1,1,1,68,1,1,1,16,0,0,16,1,1,1,68,1,1,1,16,0,0
0,0,0,0,0,0,0,0,0,0,0,0,0,0,0,0,0,0,0,0,0,0,0,0
0,0,0,0,0,0,0,0,0,0,0,0,0,0,0,0,0,0,0,0,0,0,0,0
:endlayer
layer: 9
0,0,0,0,0,0,0,0,0,0,0,0,0,0,0,0,0,0,0,0,0,0,0,0
0,0,0,0,0,0,0,0,0,0,0,0,0,0,0,0,0,0,0,0,0,0,0,0
0,0,0,0,0,0,0,0,0,56,72,0,0,71,54,0,0,0,0,0,0,0,0,0
0,0,0,0,0,0,0,0,0,56,1,1,1,1,54,0,0,0,0,0,0,0,0,0
0,0,16,1,1,1,1,1,1,1,1,1,1,1,1,1,1,1,1,1,1,16,0,0
0,0,1,72,70,70,70,70,70,70,71,1,1,72,70,70,70,16,70,70,71,1,0,0
0,0,1,72,0,0,0,0,0,0,71,1,1,72,0,0,0,16,72,0,71,1,0,0
0,0,1,72,0,6,73,73,6,0,71,1,1,72,69,69,69,16,72,0,71,1,0,0
0,0,1,72,0,73,0,0,73,0,71,1,1,16,16,16,16,16,72,0,71,1,0,0
0,0,1,72,0,74,0,0,74,0,71,1,1,16,16,70,71,16,72,0,71,1,0,0
0,0,1,72,0,74,0,0,74,0,71,1,1,16,16,72,69,16,72,69,71,1,0,0
0,0,1,72,0,73,0,0,73,0,71,1,1,16,16,16,16,16,16,16,16,1,0,0
0,0,1,72,0,6,73,73,6,0,71,1,1,72,70,70,70,16,72,70,71,1,0,0
0,0,1,72,0,0,0,0,0,0,71,1,1,72,0,0,71,16,72,0,71,1,0,0
0,0,1,72,69,69,69,69,69,69,71,1,1,72,69,69,71,16,72,0,71,1,0,0
0,0,1,1,1,1,1,1,1,1,1,1,1,16,16,16,16,16,72,0,71,1,0,0
0,0,1,72,70,70,70,70,70,70,71,1,1,72,70,70,70,16,72,0,71,1,0,0
0,0,1,72,0,0,0,0,0,0,71,1,1,72,0,0,71,16,72,0,71,1,0,0
0,0,1,72,0,0,0,0,0,71,69,1,1,72,0,0,71,16,72,0,71,1,0,0
0,0,1,72,0,0,0,0,0,71,1,1,1,72,69,69,69,16,69,69,71,1,0,0
0,0,1,72,0,0,0,0,0,71,1,1,1,1,1,1,1,1,1,1,1,1,0,0
0,0,1,72,0,0,0,0,0,71,1,18,18,1,72,70,70,70,70,70,71,1,0,0
0,0,1,72,0,0,0,0,0,71,1,0,0,1,72,0,0,0,0,0,71,1,0,0
0,0,1,69,69,69,69,69,69,71,1,0,0,1,72,69,69,69,69,69,69,1,0,0
0,0,16,1,1,1,1,1,1,1,16,0,0,16,1,1,1,1,1,1,1,16,0,0
0,0,0,0,0,0,0,0,0,0,0,0,0,0,0,0,0,0,0,0,0,0,0,0
0,0,0,0,0,0,0,0,0,0,0,0,0,0,0,0,0,0,0,0,0,0,0,0
:endlayer
layer: 10
0,0,0,0,0,0,0,0,0,0,0,0,0,0,0,0,0,0,0,0,0,0,0,0
0,0,0,0,0,0,0,0,0,0,0,0,0,0,0,0,0,0,0,0,0,0,0,0
0,0,0,0,0,0,0,0,0,0,56,1,1,54,0,0,0,0,0,0,0,0,0,0
0,0,69,75,69,75,69,0,0,0,56,1,1,54,0,0,0,69,75,69,75,69,0,0
0,71,16,1,1,1,1,1,1,1,1,1,1,1,1,1,1,1,1,1,1,16,72,0
0,75,16,1,1,1,1,1,1,1,1,1,1,1,1,1,1,1,1,1,1,16,75,0
0,71,16,1,1,1,1,1,1,1,1,1,1,1,1,1,1,1,1,1,1,16,72,0
0,75,16,1,1,1,1,1,1,1,1,1,1,1,1,1,1,1,1,1,1,16,75,0
0,71,16,1,1,1,1,1,1,1,1,1,1,1,1,1,1,1,1,1,1,16,72,0
0,75,16,1,1,1,1,1,1,1,1,1,1,1,1,1,1,1,1,1,1,16,75,0
0,71,16,1,1,1,1,1,1,1,1,1,1,1,1,1,1,1,1,1,1,16,72,0
0,75,16,1,1,1,1,1,1,1,1,1,1,1,1,1,1,1,1,1,1,16,75,0
0,71,16,1,1,1,1,1,1,1,1,1,1,1,1,1,1,1,1,1,1,16,72,0
0,75,16,1,1,1,1,1,1,1,1,1,1,1,1,1,1,1,1,1,1,16,75,0
0,71,16,1,1,1,1,1,1,1,1,1,1,1,1,1,1,1,1,1,1,16,72,0
0,75,16,1,1,1,1,1,1,1,1,1,1,1,1,1,1,1,1,1,1,16,75,0
0,71,16,1,1,1,1,1,1,1,1,1,1,1,1,1,1,1,1,1,1,16,72,0
0,75,16,1,1,1,1,1,1,1,1,1,1,1,1,1,1,1,1,1,1,16,75,0
0,71,16,1,1,1,1,1,1,1,1,1,1,1,1,1,1,1,1,1,1,16,72,0
0,75,16,1,1,1,1,1,1,1,16,1,1,16,1,1,1,1,1,1,1,16,75,0
0,71,16,1,1,1,1,1,1,1,16,18,18,16,1,1,1,1,1,1,1,16,72,0
0,75,16,1,1,1,1,1,1,1,16,0,0,16,1,1,1,1,1,1,1,16,75,0
0,71,16,1,1,1,1,1,1,1,16,0,0,16,1,1,1,1,1,1,1,16,72,0
0,75,16,1,1,1,1,1,1,1,16,0,0,16,1,1,1,1,1,1,1,16,75,0
0,71,16,16,16,16,16,16,16,16,16,0,0,16,16,16,16,16,16,16,16,16,72,0
0,0,70,75,70,75,70,75,70,75,70,0,0,70,75,70,75,70,75,70,75,70,0,0
0,0,0,0,0,0,0,0,0,0,0,0,0,0,0,0,0,0,0,0,0,0,0,0
:endlayer
layer: 11
0,0,0,0,0,0,0,0,0,0,0,0,0,0,0,0,0,0,0,0,0,0,0,0
0,0,0,0,0,0,0,0,0,0,0,0,0,0,0,0,0,0,0,0,0,0,0,0
0,0,0,0,0,0,0,0,0,0,0,0,0,0,0,0,0,0,0,0,0,0,0,0
0,0,58,76,58,76,58,0,0,0,0,88,0,0,0,0,0,58,76,58,76,58,0,0
0,58,0,0,0,0,0,76,58,76,0,0,0,0,76,58,76,0,0,0,0,0,58,0
0,76,0,0,6,0,6,0,6,0,6,0,0,6,0,6,0,6,0,6,0,0,76,0
0,58,0,0,0,0,0,0,0,0,0,0,0,0,0,0,0,0,0,0,0,0,58,0
0,76,0,0,6,0,0,0,0,87,0,0,0,0,86,0,0,0,0,6,0,0,76,0
0,58,0,0,0,0,0,0,0,0,0,0,0,0,0,0,0,0,0,0,0,0,58,0
0,76,0,0,6,0,0,0,0,0,6,84,84,6,0,0,0,0,0,6,0,0,76,0
0,58,0,0,0,0,0,0,0,0,84,0,11,84,0,0,0,0,0,0,0,0,58,0
0,76,0,0,6,0,0,85,0,0,84,0,0,84,0,0,83,0,0,6,0,0,76,0
0,58,0,0,0,0,0,0,0,0,6,82,81,6,0,0,0,0,0,0,0,0,58,0
0,76,0,0,6,0,0,0,0,0,0,0,0,0,0,0,0,0,0,6,0,0,76,0
0,58,0,0,0,0,0,0,0,0,0,0,0,0,0,80,0,0,0,0,0,0,58,0
0,76,0,0,6,0,0,0,0,0,0,0,0,0,0,0,0,0,0,6,0,0,76,0
0,58,0,0,0,0,0,0,0,0,0,0,0,0,0,0,0,0,0,0,0,0,58,0
0,76,0,0,6,0,79,0,6,0,6,0,0,6,0,6,0,0,0,6,0,0,76,0
0,58,0,0,0,0,0,0,0,0,0,0,0,0,0,0,0,0,0,0,0,0,58,0
0,76,0,0,6,0,0,0,6,0,0,0,78,0,0,6,0,0,0,6,0,0,76,0
0,58,0,0,0,0,0,0,0,0,76,0,0,76,0,0,0,77,0,0,0,0,58,0
0,76,0,0,6,0,0,0,6,0,58,0,0,58,0,6,0,0,0,6,0,0,76,0
0,58,0,0,0,0,0,0,0,0,76,0,0,76,0,0,0,0,0,0,0,0,58,0
0,76,0,0,6,0,6,0,6,0,58,0,0,58,0,6,0,6,0,6,0,0,76,0
0,58,0,0,0,0,0,0,0,0,76,0,0,76,0,0,0,0,0,0,0,0,58,0
0,0,58,76,58,76,58,76,58,76,58,0,0,58,76,58,76,58,76,58,76,58,0,0
0,0,0,0,0,0,0,0,0,0,0,0,0,0,0,0,0,0,0,0,0,0,0,0
:endlayer
layer: 12
0,0,0,0,0,0,0,0,0,0,0,0,0,0,0,0,0,0,0,0,0,0,0,0
0,0,0,0,0,0,0,0,0,0,0,0,0,0,0,0,0,0,0,0,0,0,0,0
0,0,0,0,0,0,0,0,0,0,0,0,0,0,0,0,0,0,0,0,0,0,0,0
0,0,61,0,0,0,0,0,0,0,0,0,0,0,0,0,0,0,0,0,0,61,0,0
0,61,0,0,0,0,0,0,61,0,0,0,0,0,0,61,0,0,0,0,0,0,61,0
0,0,0,0,6,0,6,0,6,0,6,0,0,6,0,6,0,6,0,6,0,0,0,0
0,0,0,0,0,0,0,0,0,0,0,0,0,0,0,0,0,0,0,0,0,0,0,0
0,0,0,0,6,0,0,0,0,0,0,0,0,0,0,0,0,0,0,6,0,0,0,0
0,0,0,0,0,0,0,0,0,0,0,0,0,0,0,0,0,0,0,0,0,0,0,0
0,0,0,0,6,0,0,0,0,0,6,84,84,6,0,0,0,0,0,6,0,0,0,0
0,61,0,0,0,0,0,0,0,0,84,4,0,84,0,0,0,0,0,0,0,0,61,0
0,0,0,0,6,0,0,0,0,0,84,0,0,84,0,0,0,0,0,6,0,0,0,0
0,0,0,0,0,0,0,0,0,0,6,82,81,6,0,0,0,0,0,0,0,0,0,0
0,0,0,0,6,0,0,0,0,0,0,0,0,0,0,0,0,0,0,6,0,0,0,0
0,0,0,0,0,0,0,0,0,0,0,0,0,0,0,0,0,0,0,0,0,0,0,0
0,0,0,0,6,0,0,0,0,0,0,0,0,0,0,0,0,0,0,6,0,0,0,0
0,0,0,0,0,0,0,0,0,0,0,0,0,0,0,0,0,0,0,0,0,0,0,0
0,0,0,0,6,0,0,0,6,0,6,0,0,6,0,6,0,0,0,6,0,0,0,0
0,61,0,0,0,0,0,0,0,0,0,0,0,0,0,0,0,0,0,0,0,0,61,0
0,0,0,0,6,0,0,0,6,0,0,0,0,0,0,6,0,0,0,6,0,0,0,0
0,0,0,0,0,0,0,0,0,0,0,0,0,0,0,0,0,0,0,0,0,0,0,0
0,0,0,0,6,0,0,0,6,0,61,0,0,61,0,6,0,0,0,6,0,0,0,0
0,0,0,0,0,0,0,0,0,0,0,0,0,0,0,0,0,0,0,0,0,0,0,0
0,0,0,0,6,0,6,0,6,0,0,0,0,0,0,6,0,6,0,6,0,0,0,0
0,61,0,0,0,0,0,0,0,0,0,0,0,0,0,0,0,0,0,0,0,0,61,0
0,0,61,0,0,0,0,0,0,0,61,0,0,61,0,0,0,0,0,0,0,61,0,0
0,0,0,0,0,0,0,0,0,0,0,0,0,0,0,0,0,0,0,0,0,0,0,0
:endlayer
layer: 13
0,0,0,0,0,0,0,0,0,0,0,0,0,0,0,0,0,0,0,0,0,0,0,0
0,0,0,0,0,0,0,0,0,0,0,0,0,0,0,0,0,0,0,0,0,0,0,0
0,0,0,0,0,0,0,0,0,0,0,0,0,0,0,0,0,0,0,0,0,0,0,0
0,0,0,0,0,0,0,0,0,0,0,0,0,0,0,0,0,0,0,0,0,0,0,0
0,0,0,0,0,0,0,0,0,0,0,0,0,0,0,0,0,0,0,0,0,0,0,0
0,0,0,0,6,0,6,0,6,0,6,90,89,6,0,6,0,6,0,6,0,0,0,0
0,0,0,0,0,0,0,0,0,0,0,0,0,0,0,0,0,0,0,0,0,0,0,0
0,0,0,0,6,0,0,0,0,0,0,0,0,0,0,0,0,0,0,6,0,0,0,0
0,0,0,0,0,0,0,0,0,0,0,0,0,0,0,0,0,0,0,0,0,0,0,0
0,0,0,0,6,0,0,0,0,0,6,84,84,6,0,0,0,0,0,6,0,0,0,0
0,0,0,0,0,0,0,0,0,0,84,0,0,84,0,0,0,0,0,0,0,0,0,0
0,0,0,0,6,0,0,0,0,0,84,3,0,84,0,0,0,0,0,6,0,0,0,0
0,0,0,0,0,0,0,0,0,0,6,84,84,6,0,0,0,0,0,0,0,0,0,0
0,0,0,0,6,0,0,0,0,0,0,0,0,0,0,0,0,0,0,6,0,0,0,0
0,0,0,0,0,0,0,0,0,0,0,0,0,0,0,0,0,0,0,0,0,0,0,0
0,0,0,0,6,0,0,0,0,0,0,0,0,0,0,0,0,0,0,6,0,0,0,0
0,0,0,0,0,0,0,0,0,0,0,0,0,0,0,0,0,0,0,0,0,0,0,0
0,0,0,0,6,0,0,0,6,0,6,90,89,6,0,6,0,0,0,6,0,0,0,0
0,0,0,0,0,0,0,0,0,0,0,0,0,0,0,0,0,0,0,0,0,0,0,0
0,0,0,0,6,0,0,0,6,0,0,0,0,0,0,6,0,0,0,6,0,0,0,0
0,0,0,0,0,0,0,0,0,0,0,0,0,0,0,0,0,0,0,0,0,0,0,0
0,0,0,0,6,0,0,0,6,0,0,0,0,0,0,6,0,0,0,6,0,0,0,0
0,0,0,0,0,0,0,0,0,0,0,0,0,0,0,0,0,0,0,0,0,0,0,0
0,0,0,0,6,0,6,0,6,0,0,0,0,0,0,6,0,6,0,6,0,0,0,0
0,0,0,0,0,0,0,0,0,0,0,0,0,0,0,0,0,0,0,0,0,0,0,0
0,0,0,0,0,0,0,0,0,0,0,0,0,0,0,0,0,0,0,0,0,0,0,0
0,0,0,0,0,0,0,0,0,0,0,0,0,0,0,0,0,0,0,0,0,0,0,0
:endlayer
layer: 14
0,0,0,0,0,0,0,0,0,0,0,0,0,0,0,0,0,0,0,0,0,0,0,0
0,0,0,0,0,0,0,0,0,0,0,0,0,0,0,0,0,0,0,0,0,0,0,0
0,0,0,0,0,0,0,0,0,0,0,0,0,0,0,0,0,0,0,0,0,0,0,0
0,0,0,0,0,0,0,0,0,0,0,0,0,0,0,0,0,0,0,0,0,0,0,0
0,0,0,0,0,0,0,0,0,0,0,0,0,0,0,0,0,0,0,0,0,0,0,0
0,0,0,0,6,0,6,0,6,0,6,0,0,6,0,6,0,6,0,6,0,0,0,0
0,0,0,0,0,0,0,0,0,0,0,0,0,0,0,0,0,0,0,0,0,0,0,0
0,0,0,0,6,0,0,0,0,0,0,0,0,0,0,0,0,0,0,6,0,0,0,0
0,0,0,0,0,0,0,0,0,0,0,0,0,0,0,0,0,0,0,0,0,0,0,0
0,0,0,0,6,0,0,0,0,0,6,84,84,6,0,0,0,0,0,6,0,0,0,0
0,0,0,0,0,0,0,0,0,0,84,0,0,84,0,0,0,0,0,0,0,0,0,0
0,0,0,0,6,0,0,0,0,0,84,0,5,84,0,0,0,0,0,6,0,0,0,0
0,0,0,0,0,0,0,0,0,0,6,84,84,6,0,0,0,0,0,0,0,0,0,0
0,0,0,0,6,0,0,0,0,0,0,0,0,0,0,0,0,0,0,6,0,0,0,0
0,0,0,0,0,0,0,0,0,0,0,0,0,0,0,0,0,0,0,0,0,0,0,0
0,0,0,0,6,0,0,0,0,0,0,0,0,0,0,0,0,0,0,6,0,0,0,0
0,0,0,0,0,0,0,0,0,0,0,0,0,0,0,0,0,0,0,0,0,0,0,0
0,0,0,0,6,0,0,0,6,0,6,0,0,6,0,6,0,0,0,6,0,0,0,0
0,0,0,0,0,0,0,0,0,0,0,0,0,0,0,0,0,0,0,0,0,0,0,0
0,0,0,0,6,0,0,0,6,0,0,0,0,0,0,6,0,0,0,6,0,0,0,0
0,0,0,0,0,0,0,0,0,0,0,0,0,0,0,0,0,0,0,0,0,0,0,0
0,0,0,0,6,0,0,0,6,0,0,0,0,0,0,6,0,0,0,6,0,0,0,0
0,0,0,0,0,0,0,0,0,0,0,0,0,0,0,0,0,0,0,0,0,0,0,0
0,0,0,0,6,0,6,0,6,0,0,0,0,0,0,6,0,6,0,6,0,0,0,0
0,0,0,0,0,0,0,0,0,0,0,0,0,0,0,0,0,0,0,0,0,0,0,0
0,0,0,0,0,0,0,0,0,0,0,0,0,0,0,0,0,0,0,0,0,0,0,0
0,0,0,0,0,0,0,0,0,0,0,0,0,0,0,0,0,0,0,0,0,0,0,0
:endlayer
layer: 15
0,0,0,0,0,0,0,0,0,0,0,0,0,0,0,0,0,0,0,0,0,0,0,0
0,0,0,0,0,0,0,0,0,0,0,0,0,0,0,0,0,0,0,0,0,0,0,0
0,0,0,0,0,0,0,0,0,0,0,0,0,0,0,0,0,0,0,0,0,0,0,0
0,0,0,0,0,0,0,0,0,0,0,0,0,0,0,0,0,0,0,0,0,0,0,0
0,0,0,0,92,0,92,0,92,0,92,0,0,92,0,92,0,92,0,92,0,0,0,0
0,0,0,89,91,92,91,92,91,92,91,92,92,91,92,91,92,91,92,91,90,0,0,0
0,0,0,0,89,0,68,0,68,0,68,0,0,68,0,68,0,68,0,90,0,0,0,0
0,0,0,89,91,90,0,0,0,0,0,0,0,0,0,0,0,0,89,91,90,0,0,0
0,0,0,0,89,0,0,0,0,0,92,0,0,92,0,0,0,0,0,90,0,0,0,0
0,0,0,89,91,90,0,0,0,89,6,84,84,6,90,0,0,0,89,91,90,0,0,0
0,0,0,0,89,0,0,0,0,0,84,0,11,84,0,0,0,0,0,90,0,0,0,0
0,0,0,89,91,90,0,0,0,0,84,0,0,84,0,0,0,0,89,91,90,0,0,0
0,0,0,0,89,0,0,0,0,89,6,84,84,6,90,0,0,0,0,90,0,0,0,0
0,0,0,89,91,90,0,0,0,0,68,0,0,68,0,0,0,0,89,91,90,0,0,0
0,0,0,0,89,0,0,0,0,0,0,0,0,0,0,0,0,0,0,90,0,0,0,0
0,0,0,89,91,90,0,0,0,0,0,0,0,0,0,0,0,0,89,91,90,0,0,0
0,0,0,0,89,0,0,0,92,0,92,0,0,92,0,92,0,0,0,90,0,0,0,0
0,0,0,89,91,90,0,89,91,68,91,68,68,91,68,91,90,0,89,91,90,0,0,0
0,0,0,0,89,0,0,0,90,0,68,0,0,68,0,89,0,0,0,90,0,0,0,0
0,0,0,89,91,90,0,89,91,90,0,0,0,0,89,91,90,0,89,91,90,0,0,0
0,0,0,0,89,0,0,0,90,0,0,0,0,0,0,89,0,0,0,90,0,0,0,0
0,0,0,89,91,90,0,89,91,90,0,0,0,0,89,91,90,0,89,91,90,0,0,0
0,0,0,0,89,0,92,0,90,0,0,0,0,0,0,89,0,92,0,90,0,0,0,0
0,0,0,89,91,68,91,68,91,90,0,0,0,0,89,91,68,91,68,91,90,0,0,0
0,0,0,0,68,0,68,0,68,0,0,0,0,0,0,68,0,68,0,68,0,0,0,0
0,0,0,0,0,0,0,0,0,0,0,0,0,0,0,0,0,0,0,0,0,0,0,0
0,0,0,0,0,0,0,0,0,0,0,0,0,0,0,0,0,0,0,0,0,0,0,0
:endlayer
layer: 16
0,0,0,0,0,0,0,0,0,0,0,0,0,0,0,0,0,0,0,0,0,0,0,0
0,0,0,0,0,0,0,0,0,0,0,0,0,0,0,0,0,0,0,0,0,0,0,0
0,0,0,0,0,0,0,0,0,0,0,0,0,0,0,0,0,0,0,0,0,0,0,0
0,0,0,0,0,0,0,0,0,0,0,0,0,0,0,0,0,0,0,0,0,0,0,0
0,0,0,74,10,74,10,74,10,74,10,74,74,10,74,10,74,10,74,10,74,0,0,0
0,0,0,8,93,93,93,93,93,93,93,93,93,93,93,93,93,93,93,93,8,0,0,0
0,0,0,74,93,91,91,91,91,91,94,95,95,94,91,91,91,91,91,93,74,0,0,0
0,0,0,8,93,8,8,8,8,8,10,95,95,10,8,8,8,8,8,93,8,0,0,0
0,0,0,74,93,91,91,91,91,91,94,95,95,94,91,91,91,91,91,93,74,0,0,0
0,0,0,8,93,8,8,8,8,8,10,8,8,10,8,8,8,8,8,93,8,0,0,0
0,0,0,74,93,91,91,91,91,91,10,4,0,10,91,91,91,91,91,93,74,0,0,0
0,0,0,8,93,8,8,8,8,8,10,0,0,10,8,8,8,8,8,93,8,0,0,0
0,0,0,74,93,91,91,91,91,91,94,8,8,94,91,91,91,91,91,93,74,0,0,0
0,0,0,8,93,8,8,8,8,8,10,95,95,10,8,8,8,8,8,93,8,0,0,0
0,0,0,74,93,91,91,91,91,91,94,95,95,94,91,91,91,91,91,93,74,0,0,0
0,0,0,8,93,8,8,8,8,8,10,95,95,10,8,8,8,8,8,93,8,0,0,0
0,0,0,74,93,91,91,91,91,91,94,95,95,94,91,91,91,91,91,93,74,0,0,0
0,0,0,8,93,8,8,8,93,93,93,91,91,93,93,93,8,8,8,93,8,0,0,0
0,0,0,74,93,91,91,91,93,74,10,74,74,10,74,93,91,91,91,93,74,0,0,0
0,0,0,8,93,8,8,8,93,8,0,0,0,0,8,93,8,8,8,93,8,0,0,0
0,0,0,74,93,91,91,91,93,74,0,0,0,0,74,93,91,91,91,93,74,0,0,0
0,0,0,8,93,8,8,8,93,8,0,0,0,0,8,93,8,8,8,93,8,0,0,0
0,0,0,74,93,91,91,91,93,74,0,0,0,0,74,93,91,91,91,93,74,0,0,0
0,0,0,8,93,93,93,93,93,8,0,0,0,0,8,93,93,93,93,93,8,0,0,0
0,0,0,74,10,74,10,74,10,74,0,0,0,0,74,10,74,10,74,10,74,0,0,0
0,0,0,0,0,0,0,0,0,0,0,0,0,0,0,0,0,0,0,0,0,0,0,0
0,0,0,0,0,0,0,0,0,0,0,0,0,0,0,0,0,0,0,0,0,0,0,0
:endlayer
layer: 17
0,0,0,0,0,0,0,0,0,0,0,0,0,0,0,0,0,0,0,0,0,0,0,0
0,0,0,0,0,0,0,0,0,0,0,0,0,0,0,0,0,0,0,0,0,0,0,0
0,0,0,0,0,0,0,0,0,0,0,0,0,0,0,0,0,0,0,0,0,0,0,0
0,0,0,0,0,0,0,0,0,0,0,0,0,0,0,0,0,0,0,0,0,0,0,0
0,0,0,73,106,73,73,73,73,73,3,73,73,3,73,73,73,73,73,106,73,0,0,0
0,0,0,96,93,93,93,93,93,4,6,3,3,6,5,93,93,93,93,93,96,0,0,0
0,0,0,96,93,93,93,93,93,93,93,91,91,93,93,93,93,93,93,93,96,0,0,0
0,0,0,96,93,93,93,93,4,0,105,21,21,104,103,5,93,93,93,93,96,0,0,0
0,0,0,96,93,93,93,93,4,0,0,0,0,0,102,5,93,93,93,93,96,0,0,0
0,0,0,96,93,93,93,93,4,0,94,21,21,94,0,5,93,93,93,93,96,0,0,0
0,0,0,96,93,93,93,93,4,0,21,0,0,21,0,5,93,93,93,93,96,0,0,0
0,0,0,96,93,93,93,93,4,0,21,0,0,21,0,5,93,93,93,93,96,0,0,0
0,0,0,96,93,93,93,93,4,0,94,21,21,94,0,5,93,93,93,93,96,0,0,0
0,0,0,96,93,93,93,93,4,0,0,0,0,0,0,5,93,93,93,93,96,0,0,0
0,0,0,96,93,93,93,93,4,0,0,0,0,0,0,5,93,93,93,93,96,0,0,0
0,0,0,96,93,93,93,93,4,0,0,101,0,0,0,5,93,93,93,93,96,0,0,0
0,0,0,96,93,93,93,93,4,100,0,21,21,99,98,5,93,93,93,93,96,0,0,0
0,0,0,96,93,93,93,93,93,93,93,91,91,93,93,93,93,93,93,93,96,0,0,0
0,0,0,96,93,93,93,93,93,4,93,8,8,93,5,93,93,93,93,93,96,0,0,0
0,0,0,96,93,93,93,93,97,73,11,73,73,11,73,97,93,93,93,93,96,0,0,0
0,0,0,96,93,93,93,93,93,96,0,0,0,0,96,93,93,93,93,93,96,0,0,0
0,0,0,96,93,93,93,93,93,96,0,0,0,0,96,93,93,93,93,93,96,0,0,0
0,0,0,96,93,93,93,93,93,96,0,0,0,0,96,93,93,93,93,93,96,0,0,0
0,0,0,96,93,93,94,93,93,96,0,0,0,0,96,93,93,94,93,93,96,0,0,0
0,0,0,73,74,0,0,0,74,73,0,0,0,0,73,74,0,0,0,74,73,0,0,0
0,0,0,0,0,0,0,0,0,0,0,0,0,0,0,0,0,0,0,0,0,0,0,0
0,0,0,0,0,0,0,0,0,0,0,0,0,0,0,0,0,0,0,0,0,0,0,0
:endlayer
layer: 18
0,0,0,0,0,0,0,0,0,0,0,0,0,0,0,0,0,0,0,0,0,0,0,0
0,0,0,0,0,0,0,0,0,0,0,0,0,0,0,0,0,0,0,0,0,0,0,0
0,0,0,0,0,0,0,0,0,0,0,0,0,0,0,0,0,0,0,0,0,0,0,0
0,0,0,0,0,0,0,0,0,0,0,0,0,0,0,0,0,0,0,0,0,0,0,0
0,0,0,0,0,73,74,0,0,0,0,0,0,0,0,0,0,74,73,0,0,0,0,0
0,0,0,0,0,96,93,93,8,94,6,0,0,6,94,8,93,93,96,0,0,0,0,0
0,0,0,0,0,96,93,93,93,93,93,91,91,93,93,93,93,93,96,0,0,0,0,0
0,0,0,0,0,96,93,93,90,0,0,21,21,0,0,89,93,93,96,0,0,0,0,0
0,0,0,0,0,96,93,93,90,0,0,0,0,0,0,89,93,93,96,0,0,0,0,0
0,0,0,0,0,96,93,93,90,0,61,0,0,61,0,89,93,93,96,0,0,0,0,0
0,0,0,0,0,96,93,93,90,0,0,0,0,0,0,89,93,93,96,0,0,0,0,0
0,0,0,0,0,96,93,93,90,0,0,0,0,0,0,89,93,93,96,0,0,0,0,0
0,0,0,0,0,96,93,93,90,0,61,0,0,61,0,89,93,93,96,0,0,0,0,0
0,0,0,0,0,96,93,93,90,0,0,0,0,0,0,89,93,93,96,0,0,0,0,0
0,0,0,0,0,96,93,93,90,0,0,0,0,0,0,89,93,93,96,0,0,0,0,0
0,0,0,0,0,96,93,93,90,0,0,0,0,0,0,89,93,93,96,0,0,0,0,0
0,0,0,0,0,96,93,93,90,0,0,21,21,0,0,89,93,93,96,0,0,0,0,0
0,0,0,0,0,96,93,93,93,93,93,91,91,93,93,93,93,93,96,0,0,0,0,0
0,0,0,0,0,96,93,93,8,94,6,11,11,6,94,8,93,93,96,0,0,0,0,0
0,0,0,0,0,96,97,73,0,0,0,0,0,0,0,0,73,97,96,0,0,0,0,0
0,0,0,0,0,96,93,96,0,0,0,0,0,0,0,0,96,93,96,0,0,0,0,0
0,0,0,0,0,96,93,96,0,0,0,0,0,0,0,0,96,93,96,0,0,0,0,0
0,0,0,0,0,96,93,96,0,0,0,0,0,0,0,0,96,93,96,0,0,0,0,0
0,0,0,0,0,96,93,96,0,0,0,0,0,0,0,0,96,93,96,0,0,0,0,0
0,0,0,0,0,73,74,73,0,0,0,0,0,0,0,0,73,74,73,0,0,0,0,0
0,0,0,0,0,0,0,0,0,0,0,0,0,0,0,0,0,0,0,0,0,0,0,0
0,0,0,0,0,0,0,0,0,0,0,0,0,0,0,0,0,0,0,0,0,0,0,0
:endlayer
layer: 19
0,0,0,0,0,0,0,0,0,0,0,0,0,0,0,0,0,0,0,0,0,0,0,0
0,0,0,0,0,0,0,0,0,0,0,0,0,0,0,0,0,0,0,0,0,0,0,0
0,0,0,0,0,0,0,0,0,0,0,0,0,0,0,0,0,0,0,0,0,0,0,0
0,0,0,0,0,0,0,0,0,0,0,0,0,0,0,0,0,0,0,0,0,0,0,0
0,0,0,0,0,0,0,73,74,0,0,0,0,0,0,74,73,0,0,0,0,0,0,0
0,0,0,0,0,0,0,96,93,90,6,73,73,6,89,93,96,0,0,0,0,0,0,0
0,0,0,0,0,0,0,96,93,93,93,91,91,93,93,93,96,0,0,0,0,0,0,0
0,0,0,0,0,0,0,96,93,90,74,21,21,74,89,93,96,0,0,0,0,0,0,0
0,0,0,0,0,0,0,96,93,90,74,0,0,74,89,93,96,0,0,0,0,0,0,0
0,0,0,0,0,0,0,96,93,90,74,0,0,74,89,93,96,0,0,0,0,0,0,0
0,0,0,0,0,0,0,96,93,90,74,0,0,74,89,93,96,0,0,0,0,0,0,0
0,0,0,0,0,0,0,96,93,90,74,0,0,74,89,93,96,0,0,0,0,0,0,0
0,0,0,0,0,0,0,96,93,90,74,0,0,74,89,93,96,0,0,0,0,0,0,0
0,0,0,0,0,0,0,96,93,90,74,0,0,74,89,93,96,0,0,0,0,0,0,0
0,0,0,0,0,0,0,96,93,90,74,0,0,74,89,93,96,0,0,0,0,0,0,0
0,0,0,0,0,0,0,96,93,90,74,0,0,74,89,93,96,0,0,0,0,0,0,0
0,0,0,0,0,0,0,96,93,90,74,21,21,74,89,93,96,0,0,0,0,0,0,0
0,0,0,0,0,0,0,96,93,93,93,91,91,93,93,93,96,0,0,0,0,0,0,0
0,0,0,0,0,0,0,96,93,90,6,0,0,6,89,93,96,0,0,0,0,0,0,0
0,0,0,0,0,0,0,73,74,0,0,0,0,0,0,74,73,0,0,0,0,0,0,0
0,0,0,0,0,0,0,0,0,0,0,0,0,0,0,0,0,0,0,0,0,0,0,0
0,0,0,0,0,0,0,0,0,0,0,0,0,0,0,0,0,0,0,0,0,0,0,0
0,0,0,0,0,0,0,0,0,0,0,0,0,0,0,0,0,0,0,0,0,0,0,0
0,0,0,0,0,0,0,0,0,0,0,0,0,0,0,0,0,0,0,0,0,0,0,0
0,0,0,0,0,0,0,0,0,0,0,0,0,0,0,0,0,0,0,0,0,0,0,0
0,0,0,0,0,0,0,0,0,0,0,0,0,0,0,0,0,0,0,0,0,0,0,0
0,0,0,0,0,0,0,0,0,0,0,0,0,0,0,0,0,0,0,0,0,0,0,0
:endlayer
layer: 20
0,0,0,0,0,0,0,0,0,0,0,0,0,0,0,0,0,0,0,0,0,0,0,0
0,0,0,0,0,0,0,0,0,0,0,0,0,0,0,0,0,0,0,0,0,0,0,0
0,0,0,0,0,0,0,0,0,0,0,0,0,0,0,0,0,0,0,0,0,0,0,0
0,0,0,0,0,0,0,0,0,0,0,0,0,0,0,0,0,0,0,0,0,0,0,0
0,0,0,0,0,0,0,0,0,73,92,0,0,92,73,0,0,0,0,0,0,0,0,0
0,0,0,0,0,0,0,0,0,96,93,97,97,93,96,0,0,0,0,0,0,0,0,0
0,0,0,0,0,0,0,0,0,96,93,97,97,93,96,0,0,0,0,0,0,0,0,0
0,0,0,0,0,0,0,0,0,96,93,97,97,93,96,0,0,0,0,0,0,0,0,0
0,0,0,0,0,0,0,0,0,96,93,97,97,93,96,0,0,0,0,0,0,0,0,0
0,0,0,0,0,0,0,0,0,96,93,97,97,93,96,0,0,0,0,0,0,0,0,0
0,0,0,0,0,0,0,0,0,96,93,97,97,93,96,0,0,0,0,0,0,0,0,0
0,0,0,0,0,0,0,0,0,96,93,97,97,93,96,0,0,0,0,0,0,0,0,0
0,0,0,0,0,0,0,0,0,96,93,97,97,93,96,0,0,0,0,0,0,0,0,0
0,0,0,0,0,0,0,0,0,96,93,97,97,93,96,0,0,0,0,0,0,0,0,0
0,0,0,0,0,0,0,0,0,96,93,97,97,93,96,0,0,0,0,0,0,0,0,0
0,0,0,0,0,0,0,0,0,96,93,97,97,93,96,0,0,0,0,0,0,0,0,0
0,0,0,0,0,0,0,0,0,96,93,97,97,93,96,0,0,0,0,0,0,0,0,0
0,0,0,0,0,0,0,0,0,96,93,91,91,93,96,0,0,0,0,0,0,0,0,0
0,0,0,0,0,0,0,0,0,96,93,90,89,93,96,0,0,0,0,0,0,0,0,0
0,0,0,0,0,0,0,0,0,73,68,0,0,68,73,0,0,0,0,0,0,0,0,0
0,0,0,0,0,0,0,0,0,0,0,0,0,0,0,0,0,0,0,0,0,0,0,0
0,0,0,0,0,0,0,0,0,0,0,0,0,0,0,0,0,0,0,0,0,0,0,0
0,0,0,0,0,0,0,0,0,0,0,0,0,0,0,0,0,0,0,0,0,0,0,0
0,0,0,0,0,0,0,0,0,0,0,0,0,0,0,0,0,0,0,0,0,0,0,0
0,0,0,0,0,0,0,0,0,0,0,0,0,0,0,0,0,0,0,0,0,0,0,0
0,0,0,0,0,0,0,0,0,0,0,0,0,0,0,0,0,0,0,0,0,0,0,0
0,0,0,0,0,0,0,0,0,0,0,0,0,0,0,0,0,0,0,0,0,0,0,0
:endlayer
layer: 21
0,0,0,0,0,0,0,0,0,0,0,0,0,0,0,0,0,0,0,0,0,0,0,0
0,0,0,0,0,0,0,0,0,0,0,0,0,0,0,0,0,0,0,0,0,0,0,0
0,0,0,0,0,0,0,0,0,0,0,0,0,0,0,0,0,0,0,0,0,0,0,0
0,0,0,0,0,0,0,0,0,0,0,0,0,0,0,0,0,0,0,0,0,0,0,0
0,0,0,0,0,0,0,0,0,0,0,73,73,0,0,0,0,0,0,0,0,0,0,0
0,0,0,0,0,0,0,0,0,0,0,96,96,0,0,0,0,0,0,0,0,0,0,0
0,0,0,0,0,0,0,0,0,0,0,96,96,0,0,0,0,0,0,0,0,0,0,0
0,0,0,0,0,0,0,0,0,0,0,96,96,0,0,0,0,0,0,0,0,0,0,0
0,0,0,0,0,0,0,0,0,0,0,96,96,0,0,0,0,0,0,0,0,0,0,0
0,0,0,0,0,0,0,0,0,0,0,96,96,0,0,0,0,0,0,0,0,0,0,0
0,0,0,0,0,0,0,0,0,0,0,96,96,0,0,0,0,0,0,0,0,0,0,0
0,0,0,0,0,0,0,0,0,0,0,96,96,0,0,0,0,0,0,0,0,0,0,0
0,0,0,0,0,0,0,0,0,0,0,96,96,0,0,0,0,0,0,0,0,0,0,0
0,0,0,0,0,0,0,0,0,0,0,96,96,0,0,0,0,0,0,0,0,0,0,0
0,0,0,0,0,0,0,0,0,0,0,96,96,0,0,0,0,0,0,0,0,0,0,0
0,0,0,0,0,0,0,0,0,0,0,96,96,0,0,0,0,0,0,0,0,0,0,0
0,0,0,0,0,0,0,0,0,0,0,96,96,0,0,0,0,0,0,0,0,0,0,0
0,0,0,0,0,0,0,0,0,0,0,96,96,0,0,0,0,0,0,0,0,0,0,0
0,0,0,0,0,0,0,0,0,0,0,96,96,0,0,0,0,0,0,0,0,0,0,0
0,0,0,0,0,0,0,0,0,0,0,73,73,0,0,0,0,0,0,0,0,0,0,0
0,0,0,0,0,0,0,0,0,0,0,0,0,0,0,0,0,0,0,0,0,0,0,0
0,0,0,0,0,0,0,0,0,0,0,0,0,0,0,0,0,0,0,0,0,0,0,0
0,0,0,0,0,0,0,0,0,0,0,0,0,0,0,0,0,0,0,0,0,0,0,0
0,0,0,0,0,0,0,0,0,0,0,0,0,0,0,0,0,0,0,0,0,0,0,0
0,0,0,0,0,0,0,0,0,0,0,0,0,0,0,0,0,0,0,0,0,0,0,0
0,0,0,0,0,0,0,0,0,0,0,0,0,0,0,0,0,0,0,0,0,0,0,0
0,0,0,0,0,0,0,0,0,0,0,0,0,0,0,0,0,0,0,0,0,0,0,0
:endlayer

#### RULES ####
rule:
plugin=vanillaBlocks
number=1
data:
JSON:{blockState:{blockName:"minecraft:sandstone",properties:{type:"sandstone"}}}
:enddata
:endrule

rule:
plugin=vanillaBlocks
number=2
data:
JSON:{blockState:{blockName:"minecraft:sand",properties:{variant:"sand"}}}
:enddata
:endrule

rule:
plugin=vanillaBlocks
number=3
data:
JSON:{blockState:{blockName:"minecraft:quartz_stairs",properties:{half:"bottom",shape:"straight",facing:"south"}}}
:enddata
:endrule

rule:
plugin=vanillaBlocks
number=4
data:
JSON:{blockState:{blockName:"minecraft:quartz_stairs",properties:{half:"bottom",shape:"straight",facing:"west"}}}
:enddata
:endrule

rule:
plugin=vanillaBlocks
number=5
data:
JSON:{blockState:{blockName:"minecraft:quartz_stairs",properties:{half:"bottom",shape:"straight",facing:"east"}}}
:enddata
:endrule

rule:
plugin=vanillaBlocks
number=6
data:
JSON:{blockState:{blockName:"minecraft:quartz_block",properties:{variant:"lines_y"}}}
:enddata
:endrule

rule:
plugin=vanillaBlocks
number=7
data:
JSON:{blockState:{blockName:"minecraft:iron_block"}}
:enddata
:endrule

rule:
plugin=vanillaBlocks
number=8
data:
JSON:{blockState:{blockName:"minecraft:quartz_block",properties:{variant:"lines_x"}}}
:enddata
:endrule

rule:
plugin=vanillaBlocks
number=9
data:
JSON:{blockState:{blockName:"minecraft:lapis_block"}}
:enddata
:endrule

rule:
plugin=vanillaBlocks
number=10
data:
JSON:{blockState:{blockName:"minecraft:quartz_block",properties:{variant:"lines_z"}}}
:enddata
:endrule

rule:
plugin=vanillaBlocks
number=11
data:
JSON:{blockState:{blockName:"minecraft:quartz_stairs",properties:{half:"bottom",shape:"straight",facing:"north"}}}
:enddata
:endrule

rule:
plugin=blockTile
number=12
data:
JSON:{blockState:{blockName:"ancientwarfarestructure:advanced_spawner",properties:{transparent:"true"}},teData:{id:"ancientwarfarestructure:advanced_spawner_tile",spawnerSettings:{minDelay:10,spawnDelay:1,lightSensitive:0b,spawnGroups:[{settingsList:[{remainingSpawnCount:1,hostile:1b,customTag:{ArmorDropChances:[0.085f,0.085f,0.085f,0.085f],hasCustomEquipment:0b,ArmorItems:[{},{},{},{}],skinSettings:{npcTypeName:"custom",skinTypeSelected:"default"},HandDropChances:[0.085f,0.085f],factionName:"minossian",HandItems:[{id:"minecraft:iron_axe",Count:1b,Damage:0s},{}]},maxToSpawn:1,entityId:"ancientwarfarenpc:faction.soldier.elite",minToSpawn:1}],groupWeight:1}],playerRange:16,respondToRedstone:0b,inventory:{Size:9,Items:[]},spawnRange:0,transparent:1b,maxDelay:10,spawnYOffset:0,xpToDrop:0,mobRange:0,debugMode:0b,maxNearbyMonsters:0}}}
:enddata
:endrule

rule:
plugin=blockTile
number=13
data:
JSON:{blockState:{blockName:"ancientwarfarestructure:advanced_spawner",properties:{transparent:"true"}},teData:{id:"ancientwarfarestructure:advanced_spawner_tile",spawnerSettings:{minDelay:10,spawnDelay:3,lightSensitive:0b,spawnGroups:[{settingsList:[{remainingSpawnCount:1,hostile:1b,customTag:{ArmorDropChances:[0.085f,0.085f,0.085f,0.085f],hasCustomEquipment:0b,ArmorItems:[{},{},{},{}],skinSettings:{npcTypeName:"custom",skinTypeSelected:"default"},HandDropChances:[0.085f,0.085f],factionName:"minossian",HandItems:[{id:"minecraft:iron_axe",Count:1b,Damage:0s},{}]},maxToSpawn:1,entityId:"ancientwarfarenpc:faction.soldier.elite",minToSpawn:1}],groupWeight:1}],playerRange:16,respondToRedstone:0b,inventory:{Size:9,Items:[]},spawnRange:0,transparent:1b,maxDelay:10,spawnYOffset:0,xpToDrop:0,mobRange:0,debugMode:0b,maxNearbyMonsters:0}}}
:enddata
:endrule

rule:
plugin=blockTile
number=14
data:
JSON:{blockState:{blockName:"ancientwarfarestructure:advanced_spawner",properties:{transparent:"true"}},teData:{id:"ancientwarfarestructure:advanced_spawner_tile",spawnerSettings:{minDelay:10,spawnDelay:7,lightSensitive:0b,spawnGroups:[{settingsList:[{remainingSpawnCount:1,hostile:1b,customTag:{ArmorDropChances:[0.085f,0.085f,0.085f,0.085f],hasCustomEquipment:0b,ArmorItems:[{},{},{},{}],skinSettings:{npcTypeName:"custom",skinTypeSelected:"default"},HandDropChances:[0.085f,0.085f],factionName:"minossian",HandItems:[{id:"minecraft:iron_axe",Count:1b,Damage:0s},{}]},maxToSpawn:1,entityId:"ancientwarfarenpc:faction.soldier.elite",minToSpawn:1}],groupWeight:1}],playerRange:16,respondToRedstone:0b,inventory:{Size:9,Items:[]},spawnRange:0,transparent:1b,maxDelay:10,spawnYOffset:0,xpToDrop:0,mobRange:0,debugMode:0b,maxNearbyMonsters:0}}}
:enddata
:endrule

rule:
plugin=blockTile
number=15
data:
JSON:{blockState:{blockName:"ancientwarfarestructure:advanced_spawner",properties:{transparent:"true"}},teData:{id:"ancientwarfarestructure:advanced_spawner_tile",spawnerSettings:{minDelay:10,spawnDelay:5,lightSensitive:0b,spawnGroups:[{settingsList:[{remainingSpawnCount:1,hostile:1b,customTag:{ArmorDropChances:[0.085f,0.085f,0.085f,0.085f],hasCustomEquipment:0b,ArmorItems:[{},{},{},{}],skinSettings:{npcTypeName:"custom",skinTypeSelected:"default"},HandDropChances:[0.085f,0.085f],factionName:"minossian",HandItems:[{id:"minecraft:iron_axe",Count:1b,Damage:0s},{}]},maxToSpawn:1,entityId:"ancientwarfarenpc:faction.soldier.elite",minToSpawn:1}],groupWeight:1}],playerRange:16,respondToRedstone:0b,inventory:{Size:9,Items:[]},spawnRange:0,transparent:1b,maxDelay:10,spawnYOffset:0,xpToDrop:0,mobRange:0,debugMode:0b,maxNearbyMonsters:0}}}
:enddata
:endrule

rule:
plugin=vanillaBlocks
number=16
data:
JSON:{blockState:{blockName:"minecraft:sandstone",properties:{type:"smooth_sandstone"}}}
:enddata
:endrule

rule:
plugin=doors
number=17
data:
JSON:{blockState:{blockName:"minecraft:acacia_door",properties:{hinge:"left",half:"lower",powered:"false",facing:"south",open:"false"}}}
:enddata
:endrule

rule:
plugin=vanillaBlocks
number=18
data:
JSON:{blockState:{blockName:"minecraft:sandstone_stairs",properties:{half:"bottom",shape:"straight",facing:"north"}}}
:enddata
:endrule

rule:
plugin=blockTile
number=19
data:
JSON:{blockState:{blockName:"ancientwarfarestructure:urn"},teData:{lootSettings:{lootRolls:1,splashPotion:1b,effects:[{Ambient:0b,CurativeItems:[{id:"minecraft:milk_bucket",Count:1b,Damage:0s}],ShowParticles:1b,RegistryName:"minecraft:instant_health",Duration:120,Amplifier:1b}],hasMessage:0b,hasLoot:1b,lootTableName:"minecraft:chests/simple_dungeon",spawnEntity:0b,entity:"minecraft:"},id:"ancientwarfarestructure:urn_tile"}}
:enddata
:endrule

rule:
plugin=blockTile
number=20
data:
JSON:{blockState:{blockName:"ancientwarfarestructure:urn"},teData:{lootSettings:{lootRolls:1,splashPotion:1b,effects:[{Ambient:0b,CurativeItems:[{id:"minecraft:milk_bucket",Count:1b,Damage:0s}],ShowParticles:1b,RegistryName:"minecraft:instant_health",Duration:120,Amplifier:1b}],hasMessage:0b,hasLoot:1b,lootTableName:"minecraft:chests/simple_dungeon",spawnEntity:0b,entity:"minecraft:"},id:"ancientwarfarestructure:urn_tile"}}
:enddata
:endrule

rule:
plugin=vanillaBlocks
number=21
data:
JSON:{blockState:{blockName:"minecraft:iron_bars",properties:{east:"false",south:"false",north:"false",west:"false"}}}
:enddata
:endrule

rule:
plugin=blockTile
number=22
data:
JSON:{blockState:{blockName:"ancientwarfarestructure:advanced_spawner",properties:{transparent:"true"}},teData:{id:"ancientwarfarestructure:advanced_spawner_tile",spawnerSettings:{minDelay:10,spawnDelay:1,lightSensitive:0b,spawnGroups:[{settingsList:[{remainingSpawnCount:1,hostile:1b,customTag:{ArmorDropChances:[0.085f,0.085f,0.085f,0.085f],hasCustomEquipment:0b,ArmorItems:[{},{},{},{}],skinSettings:{npcTypeName:"custom",skinTypeSelected:"default"},HandDropChances:[0.085f,0.085f],factionName:"minossian",HandItems:[{id:"minecraft:iron_axe",Count:1b,Damage:0s},{}]},maxToSpawn:1,entityId:"ancientwarfarenpc:faction.soldier.elite",minToSpawn:1}],groupWeight:1}],playerRange:16,respondToRedstone:0b,inventory:{Size:9,Items:[]},spawnRange:0,transparent:1b,maxDelay:10,spawnYOffset:0,xpToDrop:0,mobRange:0,debugMode:0b,maxNearbyMonsters:0}}}
:enddata
:endrule

rule:
plugin=blockTile
number=23
data:
JSON:{blockState:{blockName:"ancientwarfarestructure:advanced_spawner",properties:{transparent:"true"}},teData:{id:"ancientwarfarestructure:advanced_spawner_tile",spawnerSettings:{minDelay:10,spawnDelay:2,lightSensitive:0b,spawnGroups:[{settingsList:[{remainingSpawnCount:1,hostile:1b,customTag:{ArmorDropChances:[0.085f,0.085f,0.085f,0.085f],hasCustomEquipment:0b,ArmorItems:[{},{},{},{}],skinSettings:{npcTypeName:"custom",skinTypeSelected:"default"},HandDropChances:[0.085f,0.085f],factionName:"minossian",HandItems:[{id:"minecraft:iron_axe",Count:1b,Damage:0s},{}]},maxToSpawn:1,entityId:"ancientwarfarenpc:faction.soldier.elite",minToSpawn:1}],groupWeight:1}],playerRange:16,respondToRedstone:0b,inventory:{Size:9,Items:[]},spawnRange:0,transparent:1b,maxDelay:10,spawnYOffset:0,xpToDrop:0,mobRange:0,debugMode:0b,maxNearbyMonsters:0}}}
:enddata
:endrule

rule:
plugin=blockTile
number=24
data:
JSON:{blockState:{blockName:"ancientwarfarestructure:advanced_spawner",properties:{transparent:"true"}},teData:{id:"ancientwarfarestructure:advanced_spawner_tile",spawnerSettings:{minDelay:10,spawnDelay:3,lightSensitive:0b,spawnGroups:[{settingsList:[{remainingSpawnCount:1,hostile:1b,customTag:{ArmorDropChances:[0.085f,0.085f,0.085f,0.085f],hasCustomEquipment:0b,ArmorItems:[{},{},{},{}],skinSettings:{npcTypeName:"custom",skinTypeSelected:"default"},HandDropChances:[0.085f,0.085f],factionName:"minossian",HandItems:[{id:"minecraft:iron_axe",Count:1b,Damage:0s},{}]},maxToSpawn:1,entityId:"ancientwarfarenpc:faction.soldier.elite",minToSpawn:1}],groupWeight:1}],playerRange:16,respondToRedstone:0b,inventory:{Size:9,Items:[]},spawnRange:0,transparent:1b,maxDelay:10,spawnYOffset:0,xpToDrop:0,mobRange:0,debugMode:0b,maxNearbyMonsters:0}}}
:enddata
:endrule

rule:
plugin=blockTile
number=25
data:
JSON:{blockState:{blockName:"ancientwarfarestructure:advanced_spawner",properties:{transparent:"true"}},teData:{id:"ancientwarfarestructure:advanced_spawner_tile",spawnerSettings:{minDelay:10,spawnDelay:1,lightSensitive:0b,spawnGroups:[{settingsList:[{remainingSpawnCount:1,hostile:1b,customTag:{ArmorDropChances:[0.085f,0.085f,0.085f,0.085f],hasCustomEquipment:0b,ArmorItems:[{},{},{},{}],skinSettings:{npcTypeName:"custom",skinTypeSelected:"default"},HandDropChances:[0.085f,0.085f],factionName:"minossian",HandItems:[{id:"minecraft:iron_axe",Count:1b,Damage:0s},{}]},maxToSpawn:1,entityId:"ancientwarfarenpc:faction.soldier.elite",minToSpawn:1}],groupWeight:1}],playerRange:16,respondToRedstone:0b,inventory:{Size:9,Items:[]},spawnRange:0,transparent:1b,maxDelay:10,spawnYOffset:0,xpToDrop:0,mobRange:0,debugMode:0b,maxNearbyMonsters:0}}}
:enddata
:endrule

rule:
plugin=blockTile
number=26
data:
JSON:{blockState:{blockName:"ancientwarfarestructure:advanced_spawner",properties:{transparent:"true"}},teData:{id:"ancientwarfarestructure:advanced_spawner_tile",spawnerSettings:{minDelay:10,spawnDelay:2,lightSensitive:0b,spawnGroups:[{settingsList:[{remainingSpawnCount:1,hostile:1b,customTag:{ArmorDropChances:[0.085f,0.085f,0.085f,0.085f],hasCustomEquipment:0b,ArmorItems:[{},{},{},{}],skinSettings:{npcTypeName:"custom",skinTypeSelected:"default"},HandDropChances:[0.085f,0.085f],factionName:"minossian",HandItems:[{id:"minecraft:iron_axe",Count:1b,Damage:0s},{}]},maxToSpawn:1,entityId:"ancientwarfarenpc:faction.soldier.elite",minToSpawn:1}],groupWeight:1}],playerRange:16,respondToRedstone:0b,inventory:{Size:9,Items:[]},spawnRange:0,transparent:1b,maxDelay:10,spawnYOffset:0,xpToDrop:0,mobRange:0,debugMode:0b,maxNearbyMonsters:0}}}
:enddata
:endrule

rule:
plugin=blockTile
number=27
data:
JSON:{blockState:{blockName:"ancientwarfarestructure:urn"},teData:{lootSettings:{lootRolls:1,splashPotion:1b,effects:[{Ambient:0b,CurativeItems:[{id:"minecraft:milk_bucket",Count:1b,Damage:0s}],ShowParticles:1b,RegistryName:"minecraft:instant_health",Duration:120,Amplifier:1b}],hasMessage:0b,hasLoot:1b,lootTableName:"minecraft:chests/simple_dungeon",spawnEntity:0b,entity:"minecraft:"},id:"ancientwarfarestructure:urn_tile"}}
:enddata
:endrule

rule:
plugin=blockTile
number=28
data:
JSON:{blockState:{blockName:"ancientwarfarestructure:advanced_spawner",properties:{transparent:"true"}},teData:{id:"ancientwarfarestructure:advanced_spawner_tile",spawnerSettings:{minDelay:10,spawnDelay:8,lightSensitive:0b,spawnGroups:[{settingsList:[{remainingSpawnCount:1,hostile:1b,customTag:{ArmorDropChances:[0.085f,0.085f,0.085f,0.085f],hasCustomEquipment:0b,ArmorItems:[{},{},{},{}],skinSettings:{npcTypeName:"custom",skinTypeSelected:"default"},HandDropChances:[0.085f,0.085f],factionName:"minossian",HandItems:[{},{}]},maxToSpawn:1,entityId:"ancientwarfarenpc:faction.leader",minToSpawn:1}],groupWeight:1}],playerRange:16,respondToRedstone:0b,inventory:{Size:9,Items:[]},spawnRange:0,transparent:1b,maxDelay:10,spawnYOffset:0,xpToDrop:0,mobRange:0,debugMode:0b,maxNearbyMonsters:0}}}
:enddata
:endrule

rule:
plugin=vanillaBlocks
number=29
data:
JSON:{blockState:{blockName:"ancientwarfarestructure:table",properties:{leg_southwest:"true",leg_northwest:"true",variant:"spruce",leg_northeast:"true",leg_southeast:"true"}}}
:enddata
:endrule

rule:
plugin=blockTile
number=30
data:
JSON:{blockState:{blockName:"ancientwarfarestructure:advanced_loot_chest",properties:{facing:"west"}},teData:{lootSettings:{lootRolls:1,splashPotion:1b,effects:[{Ambient:0b,CurativeItems:[{id:"minecraft:milk_bucket",Count:1b,Damage:0s}],ShowParticles:1b,RegistryName:"minecraft:instant_damage",Duration:20,Amplifier:2b}],hasMessage:0b,hasLoot:1b,lootTableName:"ancientwarfare:chests/minossian",spawnEntity:0b,entity:"minecraft:"},Items:[],id:"ancientwarfarestructure:advanced_loot_chest_tile",Lock:""}}
:enddata
:endrule

rule:
plugin=blockTile
number=31
data:
JSON:{blockState:{blockName:"ancientwarfarestructure:advanced_spawner",properties:{transparent:"true"}},teData:{id:"ancientwarfarestructure:advanced_spawner_tile",spawnerSettings:{minDelay:10,spawnDelay:1,lightSensitive:0b,spawnGroups:[{settingsList:[{remainingSpawnCount:1,hostile:1b,customTag:{ArmorDropChances:[0.085f,0.085f,0.085f,0.085f],hasCustomEquipment:0b,ArmorItems:[{},{},{},{}],skinSettings:{npcTypeName:"custom",skinTypeSelected:"default"},HandDropChances:[0.085f,0.085f],factionName:"minossian",HandItems:[{id:"minecraft:iron_axe",Count:1b,Damage:0s},{}]},maxToSpawn:1,entityId:"ancientwarfarenpc:faction.soldier.elite",minToSpawn:1}],groupWeight:1}],playerRange:16,respondToRedstone:0b,inventory:{Size:9,Items:[]},spawnRange:0,transparent:1b,maxDelay:10,spawnYOffset:0,xpToDrop:0,mobRange:0,debugMode:0b,maxNearbyMonsters:0}}}
:enddata
:endrule

rule:
plugin=blockTile
number=32
data:
JSON:{blockState:{blockName:"ancientwarfarestructure:advanced_loot_chest",properties:{facing:"east"}},teData:{lootSettings:{lootRolls:1,splashPotion:0b,hasMessage:0b,hasLoot:1b,lootTableName:"ancientwarfare:chests/minossian",spawnEntity:0b,entity:"minecraft:"},Items:[],id:"ancientwarfarestructure:advanced_loot_chest_tile",Lock:""}}
:enddata
:endrule

rule:
plugin=bed
number=33
data:
JSON:{blockState:{blockName:"minecraft:bed",properties:{part:"head",facing:"east",occupied:"false"}},bedColor:0}
:enddata
:endrule

rule:
plugin=bed
number=34
data:
JSON:{blockState:{blockName:"minecraft:bed",properties:{part:"foot",facing:"east",occupied:"false"}},bedColor:0}
:enddata
:endrule

rule:
plugin=blockTile
number=35
data:
JSON:{blockState:{blockName:"ancientwarfarestructure:urn"},teData:{lootSettings:{lootRolls:1,splashPotion:1b,effects:[{Ambient:0b,CurativeItems:[{id:"minecraft:milk_bucket",Count:1b,Damage:0s}],ShowParticles:1b,RegistryName:"minecraft:instant_health",Duration:120,Amplifier:1b}],hasMessage:0b,hasLoot:1b,lootTableName:"minecraft:chests/simple_dungeon",spawnEntity:0b,entity:"minecraft:"},id:"ancientwarfarestructure:urn_tile"}}
:enddata
:endrule

rule:
plugin=blockTile
number=36
data:
JSON:{blockState:{blockName:"ancientwarfarestructure:urn"},teData:{lootSettings:{lootRolls:0,splashPotion:0b,hasMessage:0b,hasLoot:0b,entityNBT:{IsBaby:1b},lootTableName:"minecraft:",spawnEntity:1b,entity:"minecraft:zombie"},id:"ancientwarfarestructure:urn_tile"}}
:enddata
:endrule

rule:
plugin=blockTile
number=37
data:
JSON:{blockState:{blockName:"ancientwarfarestructure:advanced_spawner",properties:{transparent:"true"}},teData:{id:"ancientwarfarestructure:advanced_spawner_tile",spawnerSettings:{minDelay:10,spawnDelay:2,lightSensitive:0b,spawnGroups:[{settingsList:[{remainingSpawnCount:1,hostile:1b,customTag:{ArmorDropChances:[0.085f,0.085f,0.085f,0.085f],hasCustomEquipment:0b,ArmorItems:[{},{},{},{}],skinSettings:{npcTypeName:"custom",skinTypeSelected:"default"},HandDropChances:[0.085f,0.085f],factionName:"minossian",HandItems:[{id:"minecraft:iron_axe",Count:1b,Damage:0s},{}]},maxToSpawn:1,entityId:"ancientwarfarenpc:faction.soldier.elite",minToSpawn:1}],groupWeight:1}],playerRange:16,respondToRedstone:0b,inventory:{Size:9,Items:[]},spawnRange:0,transparent:1b,maxDelay:10,spawnYOffset:0,xpToDrop:0,mobRange:0,debugMode:0b,maxNearbyMonsters:0}}}
:enddata
:endrule

rule:
plugin=blockTile
number=38
data:
JSON:{blockState:{blockName:"ancientwarfarestructure:advanced_loot_chest",properties:{facing:"east"}},teData:{lootSettings:{lootRolls:0,splashPotion:0b,hasMessage:0b,hasLoot:0b,lootTableName:"minecraft:",spawnEntity:0b,entity:"minecraft:"},Items:[],id:"ancientwarfarestructure:advanced_loot_chest_tile",Lock:""}}
:enddata
:endrule

rule:
plugin=blockTile
number=39
data:
JSON:{blockState:{blockName:"ancientwarfarestructure:urn"},teData:{lootSettings:{lootRolls:1,splashPotion:1b,effects:[{Ambient:0b,CurativeItems:[{id:"minecraft:milk_bucket",Count:1b,Damage:0s}],ShowParticles:1b,RegistryName:"minecraft:instant_health",Duration:120,Amplifier:1b}],hasMessage:0b,hasLoot:1b,lootTableName:"minecraft:chests/simple_dungeon",spawnEntity:0b,entity:"minecraft:"},id:"ancientwarfarestructure:urn_tile"}}
:enddata
:endrule

rule:
plugin=blockTile
number=40
data:
JSON:{blockState:{blockName:"ancientwarfarestructure:advanced_spawner",properties:{transparent:"true"}},teData:{id:"ancientwarfarestructure:advanced_spawner_tile",spawnerSettings:{minDelay:10,spawnDelay:4,lightSensitive:0b,spawnGroups:[{settingsList:[{remainingSpawnCount:1,hostile:1b,customTag:{ArmorDropChances:[0.085f,0.085f,0.085f,0.085f],hasCustomEquipment:0b,ArmorItems:[{},{},{},{}],skinSettings:{npcTypeName:"custom",skinTypeSelected:"default"},HandDropChances:[0.085f,0.085f],factionName:"minossian",HandItems:[{id:"minecraft:iron_axe",Count:1b,Damage:0s},{}]},maxToSpawn:1,entityId:"ancientwarfarenpc:faction.soldier.elite",minToSpawn:1}],groupWeight:1}],playerRange:16,respondToRedstone:0b,inventory:{Size:9,Items:[]},spawnRange:0,transparent:1b,maxDelay:10,spawnYOffset:0,xpToDrop:0,mobRange:0,debugMode:0b,maxNearbyMonsters:0}}}
:enddata
:endrule

rule:
plugin=blockTile
number=41
data:
JSON:{blockState:{blockName:"ancientwarfarestructure:advanced_spawner",properties:{transparent:"true"}},teData:{id:"ancientwarfarestructure:advanced_spawner_tile",spawnerSettings:{minDelay:10,spawnDelay:8,lightSensitive:0b,spawnGroups:[{settingsList:[{remainingSpawnCount:1,hostile:1b,customTag:{ArmorDropChances:[0.085f,0.085f,0.085f,0.085f],hasCustomEquipment:0b,ArmorItems:[{},{},{},{}],skinSettings:{npcTypeName:"custom",skinTypeSelected:"default"},HandDropChances:[0.085f,0.085f],factionName:"minossian",HandItems:[{id:"minecraft:diamond_axe",Count:1b,Damage:0s},{}]},maxToSpawn:1,entityId:"ancientwarfarenpc:faction.leader.elite",minToSpawn:1}],groupWeight:1}],playerRange:16,respondToRedstone:0b,inventory:{Size:9,Items:[]},spawnRange:0,transparent:1b,maxDelay:10,spawnYOffset:0,xpToDrop:0,mobRange:0,debugMode:0b,maxNearbyMonsters:0}}}
:enddata
:endrule

rule:
plugin=vanillaBlocks
number=42
data:
JSON:{blockState:{blockName:"ancientwarfarestructure:stool",properties:{variant:"spruce"}}}
:enddata
:endrule

rule:
plugin=bed
number=43
data:
JSON:{blockState:{blockName:"minecraft:bed",properties:{part:"foot",facing:"west",occupied:"false"}},bedColor:0}
:enddata
:endrule

rule:
plugin=bed
number=44
data:
JSON:{blockState:{blockName:"minecraft:bed",properties:{part:"head",facing:"west",occupied:"false"}},bedColor:0}
:enddata
:endrule

rule:
plugin=blockTile
number=45
data:
JSON:{blockState:{blockName:"ancientwarfarestructure:urn"},teData:{lootSettings:{lootRolls:1,splashPotion:1b,effects:[{Ambient:0b,CurativeItems:[{id:"minecraft:milk_bucket",Count:1b,Damage:0s}],ShowParticles:1b,RegistryName:"minecraft:instant_health",Duration:120,Amplifier:1b}],hasMessage:0b,hasLoot:1b,lootTableName:"minecraft:chests/simple_dungeon",spawnEntity:0b,entity:"minecraft:"},id:"ancientwarfarestructure:urn_tile"}}
:enddata
:endrule

rule:
plugin=blockTile
number=46
data:
JSON:{blockState:{blockName:"ancientwarfarestructure:advanced_spawner",properties:{transparent:"true"}},teData:{id:"ancientwarfarestructure:advanced_spawner_tile",spawnerSettings:{minDelay:10,spawnDelay:10,lightSensitive:0b,spawnGroups:[{settingsList:[{remainingSpawnCount:1,hostile:1b,customTag:{ArmorDropChances:[0.085f,0.085f,0.085f,0.085f],hasCustomEquipment:0b,ArmorItems:[{},{},{},{}],skinSettings:{npcTypeName:"custom",skinTypeSelected:"default"},HandDropChances:[0.085f,0.085f],factionName:"minossian",HandItems:[{id:"minecraft:iron_axe",Count:1b,Damage:0s},{}]},maxToSpawn:1,entityId:"ancientwarfarenpc:faction.soldier.elite",minToSpawn:1}],groupWeight:1}],playerRange:16,respondToRedstone:0b,inventory:{Size:9,Items:[]},spawnRange:0,transparent:1b,maxDelay:10,spawnYOffset:0,xpToDrop:0,mobRange:0,debugMode:0b,maxNearbyMonsters:0}}}
:enddata
:endrule

rule:
plugin=blockTile
number=47
data:
JSON:{blockState:{blockName:"ancientwarfarestructure:advanced_spawner",properties:{transparent:"true"}},teData:{id:"ancientwarfarestructure:advanced_spawner_tile",spawnerSettings:{minDelay:10,spawnDelay:10,lightSensitive:0b,spawnGroups:[{settingsList:[{remainingSpawnCount:1,hostile:1b,customTag:{ArmorDropChances:[0.085f,0.085f,0.085f,0.085f],hasCustomEquipment:0b,ArmorItems:[{},{},{},{}],skinSettings:{npcTypeName:"custom",skinTypeSelected:"default"},HandDropChances:[0.085f,0.085f],factionName:"minossian",HandItems:[{id:"minecraft:iron_axe",Count:1b,Damage:0s},{}]},maxToSpawn:1,entityId:"ancientwarfarenpc:faction.soldier.elite",minToSpawn:1}],groupWeight:1}],playerRange:16,respondToRedstone:0b,inventory:{Size:9,Items:[]},spawnRange:0,transparent:1b,maxDelay:10,spawnYOffset:0,xpToDrop:0,mobRange:0,debugMode:0b,maxNearbyMonsters:0}}}
:enddata
:endrule

rule:
plugin=blockTile
number=48
data:
JSON:{blockState:{blockName:"ancientwarfarestructure:advanced_spawner",properties:{transparent:"true"}},teData:{id:"ancientwarfarestructure:advanced_spawner_tile",spawnerSettings:{minDelay:10,spawnDelay:5,lightSensitive:0b,spawnGroups:[{settingsList:[{remainingSpawnCount:1,hostile:1b,customTag:{ArmorDropChances:[0.085f,0.085f,0.085f,0.085f],hasCustomEquipment:0b,ArmorItems:[{},{},{},{}],skinSettings:{npcTypeName:"custom",skinTypeSelected:"default"},HandDropChances:[0.085f,0.085f],factionName:"minossian",HandItems:[{id:"minecraft:book",Count:1b,Damage:0s},{}]},maxToSpawn:1,entityId:"ancientwarfarenpc:faction.priest",minToSpawn:1}],groupWeight:1}],playerRange:16,respondToRedstone:0b,inventory:{Size:9,Items:[]},spawnRange:0,transparent:1b,maxDelay:10,spawnYOffset:0,xpToDrop:0,mobRange:0,debugMode:0b,maxNearbyMonsters:0}}}
:enddata
:endrule

rule:
plugin=blockTile
number=49
data:
JSON:{blockState:{blockName:"ancientwarfarestructure:advanced_loot_chest",properties:{facing:"north"}},teData:{lootSettings:{lootRolls:1,splashPotion:0b,hasMessage:0b,hasLoot:1b,lootTableName:"ancientwarfare:chests/minossian",spawnEntity:0b,entity:"minecraft:"},Items:[],id:"ancientwarfarestructure:advanced_loot_chest_tile",Lock:""}}
:enddata
:endrule

rule:
plugin=blockTile
number=50
data:
JSON:{blockState:{blockName:"ancientwarfarestructure:advanced_spawner",properties:{transparent:"true"}},teData:{id:"ancientwarfarestructure:advanced_spawner_tile",spawnerSettings:{minDelay:10,spawnDelay:10,lightSensitive:0b,spawnGroups:[{settingsList:[{remainingSpawnCount:1,hostile:1b,customTag:{ArmorDropChances:[0.085f,0.085f,0.085f,0.085f],hasCustomEquipment:0b,ArmorItems:[{},{},{},{}],skinSettings:{npcTypeName:"custom",skinTypeSelected:"default"},HandDropChances:[0.085f,0.085f],factionName:"minossian",HandItems:[{id:"minecraft:iron_axe",Count:1b,Damage:0s},{}]},maxToSpawn:1,entityId:"ancientwarfarenpc:faction.soldier.elite",minToSpawn:1}],groupWeight:1}],playerRange:16,respondToRedstone:0b,inventory:{Size:9,Items:[]},spawnRange:0,transparent:1b,maxDelay:10,spawnYOffset:0,xpToDrop:0,mobRange:0,debugMode:0b,maxNearbyMonsters:0}}}
:enddata
:endrule

rule:
plugin=blockTile
number=51
data:
JSON:{blockState:{blockName:"ancientwarfarestructure:advanced_loot_chest",properties:{facing:"south"}},teData:{lootSettings:{lootRolls:1,splashPotion:0b,hasMessage:0b,hasLoot:1b,lootTableName:"ancientwarfare:chests/minossian",spawnEntity:0b,entity:"minecraft:"},Items:[],id:"ancientwarfarestructure:advanced_loot_chest_tile",Lock:""}}
:enddata
:endrule

rule:
plugin=blockTile
number=52
data:
JSON:{blockState:{blockName:"ancientwarfarestructure:urn"},teData:{lootSettings:{lootRolls:1,splashPotion:1b,effects:[{Ambient:0b,CurativeItems:[{id:"minecraft:milk_bucket",Count:1b,Damage:0s}],ShowParticles:1b,RegistryName:"minecraft:instant_health",Duration:120,Amplifier:1b}],hasMessage:0b,hasLoot:1b,lootTableName:"minecraft:chests/simple_dungeon",spawnEntity:0b,entity:"minecraft:"},id:"ancientwarfarestructure:urn_tile"}}
:enddata
:endrule

rule:
plugin=vanillaBlocks
number=53
data:
JSON:{blockState:{blockName:"minecraft:leaves",properties:{check_decay:"false",decayable:"false",variant:"oak"}}}
:enddata
:endrule

rule:
plugin=vanillaBlocks
number=54
data:
JSON:{blockState:{blockName:"minecraft:sandstone_stairs",properties:{half:"bottom",shape:"straight",facing:"west"}}}
:enddata
:endrule

rule:
plugin=fluid
number=55
data:
JSON:{blockState:{blockName:"minecraft:water",properties:{level:"0"}}}
:enddata
:endrule

rule:
plugin=vanillaBlocks
number=56
data:
JSON:{blockState:{blockName:"minecraft:sandstone_stairs",properties:{half:"bottom",shape:"straight",facing:"east"}}}
:enddata
:endrule

rule:
plugin=vanillaBlocks
number=57
data:
JSON:{blockState:{blockName:"minecraft:sandstone_stairs",properties:{half:"bottom",shape:"straight",facing:"south"}}}
:enddata
:endrule

rule:
plugin=vanillaBlocks
number=58
data:
JSON:{blockState:{blockName:"minecraft:sandstone",properties:{type:"chiseled_sandstone"}}}
:enddata
:endrule

rule:
plugin=doors
number=59
data:
JSON:{blockState:{blockName:"minecraft:acacia_door",properties:{hinge:"left",half:"upper",powered:"false",facing:"south",open:"false"}}}
:enddata
:endrule

rule:
plugin=doors
number=60
data:
JSON:{blockState:{blockName:"minecraft:acacia_door",properties:{hinge:"right",half:"upper",powered:"false",facing:"south",open:"false"}}}
:enddata
:endrule

rule:
plugin=vanillaBlocks
number=61
data:
JSON:{blockState:{blockName:"ancientwarfarestructure:brazier_flame",properties:{lit:"true"}}}
:enddata
:endrule

rule:
plugin=blockTile
number=62
data:
JSON:{blockState:{blockName:"ancientwarfarestructure:altar_candle"},teData:{customColor:0b,dyeColor:0,customData:"",id:"ancientwarfarestructure:altar_candle_tile",unlocalizedNamePart:""}}
:enddata
:endrule

rule:
plugin=vanillaBlocks
number=63
data:
JSON:{blockState:{blockName:"ancientwarfarestructure:coin_stack_gold",properties:{size:"16"}}}
:enddata
:endrule

rule:
plugin=flag
number=64
data:
JSON:{blockState:{blockName:"ancientwarfarestructure:protection_flag",properties:{rotation:"0"}},teData:{name:"minossian",id:"ancientwarfarestructure:protection_flag_tile"}}
:enddata
:endrule

rule:
plugin=vanillaBlocks
number=65
data:
JSON:{blockState:{blockName:"ancientwarfarestructure:brazier_flame",properties:{lit:"false"}}}
:enddata
:endrule

rule:
plugin=blockTile
number=66
data:
JSON:{blockState:{blockName:"ancientwarfarestructure:altar_candle"},teData:{customColor:0b,dyeColor:0,customData:"",id:"ancientwarfarestructure:altar_candle_tile",unlocalizedNamePart:""}}
:enddata
:endrule

rule:
plugin=blockTile
number=67
data:
JSON:{blockState:{blockName:"ancientwarfarestructure:altar_candle"},teData:{customColor:0b,dyeColor:0,customData:"",id:"ancientwarfarestructure:altar_candle_tile",unlocalizedNamePart:""}}
:enddata
:endrule

rule:
plugin=vanillaBlocks
number=68
data:
JSON:{blockState:{blockName:"minecraft:quartz_stairs",properties:{half:"top",shape:"straight",facing:"north"}}}
:enddata
:endrule

rule:
plugin=vanillaBlocks
number=69
data:
JSON:{blockState:{blockName:"minecraft:sandstone_stairs",properties:{half:"top",shape:"straight",facing:"south"}}}
:enddata
:endrule

rule:
plugin=vanillaBlocks
number=70
data:
JSON:{blockState:{blockName:"minecraft:sandstone_stairs",properties:{half:"top",shape:"straight",facing:"north"}}}
:enddata
:endrule

rule:
plugin=vanillaBlocks
number=71
data:
JSON:{blockState:{blockName:"minecraft:sandstone_stairs",properties:{half:"top",shape:"straight",facing:"east"}}}
:enddata
:endrule

rule:
plugin=vanillaBlocks
number=72
data:
JSON:{blockState:{blockName:"minecraft:sandstone_stairs",properties:{half:"top",shape:"straight",facing:"west"}}}
:enddata
:endrule

rule:
plugin=vanillaBlocks
number=73
data:
JSON:{blockState:{blockName:"minecraft:stone_slab",properties:{half:"bottom",variant:"quartz"}}}
:enddata
:endrule

rule:
plugin=vanillaBlocks
number=74
data:
JSON:{blockState:{blockName:"minecraft:stone_slab",properties:{half:"top",variant:"quartz"}}}
:enddata
:endrule

rule:
plugin=vanillaBlocks
number=75
data:
JSON:{blockState:{blockName:"minecraft:stone_slab",properties:{half:"top",variant:"sandstone"}}}
:enddata
:endrule

rule:
plugin=vanillaBlocks
number=76
data:
JSON:{blockState:{blockName:"minecraft:stone_slab",properties:{half:"bottom",variant:"sandstone"}}}
:enddata
:endrule

rule:
plugin=blockTile
number=77
data:
JSON:{blockState:{blockName:"ancientwarfarestructure:advanced_spawner",properties:{transparent:"true"}},teData:{id:"ancientwarfarestructure:advanced_spawner_tile",spawnerSettings:{minDelay:10,spawnDelay:10,lightSensitive:0b,spawnGroups:[{settingsList:[{remainingSpawnCount:1,hostile:1b,customTag:{ArmorDropChances:[0.085f,0.085f,0.085f,0.085f],hasCustomEquipment:0b,ArmorItems:[{},{},{},{}],skinSettings:{npcTypeName:"custom",skinTypeSelected:"default"},HandDropChances:[0.085f,0.085f],factionName:"minossian",HandItems:[{id:"minecraft:iron_axe",Count:1b,Damage:0s},{}]},maxToSpawn:1,entityId:"ancientwarfarenpc:faction.soldier.elite",minToSpawn:1}],groupWeight:1}],playerRange:16,respondToRedstone:0b,inventory:{Size:9,Items:[]},spawnRange:0,transparent:1b,maxDelay:10,spawnYOffset:0,xpToDrop:0,mobRange:0,debugMode:0b,maxNearbyMonsters:0}}}
:enddata
:endrule

rule:
plugin=blockTile
number=78
data:
JSON:{blockState:{blockName:"ancientwarfarestructure:advanced_spawner",properties:{transparent:"true"}},teData:{id:"ancientwarfarestructure:advanced_spawner_tile",spawnerSettings:{minDelay:10,spawnDelay:2,lightSensitive:0b,spawnGroups:[{settingsList:[{remainingSpawnCount:1,hostile:1b,customTag:{ArmorDropChances:[0.085f,0.085f,0.085f,0.085f],hasCustomEquipment:0b,ArmorItems:[{},{},{},{}],skinSettings:{npcTypeName:"custom",skinTypeSelected:"default"},HandDropChances:[0.085f,0.085f],factionName:"minossian",HandItems:[{id:"minecraft:iron_axe",Count:1b,Damage:0s},{}]},maxToSpawn:1,entityId:"ancientwarfarenpc:faction.soldier.elite",minToSpawn:1}],groupWeight:1}],playerRange:16,respondToRedstone:0b,inventory:{Size:9,Items:[]},spawnRange:0,transparent:1b,maxDelay:10,spawnYOffset:0,xpToDrop:0,mobRange:0,debugMode:0b,maxNearbyMonsters:0}}}
:enddata
:endrule

rule:
plugin=blockTile
number=79
data:
JSON:{blockState:{blockName:"ancientwarfarestructure:advanced_spawner",properties:{transparent:"true"}},teData:{id:"ancientwarfarestructure:advanced_spawner_tile",spawnerSettings:{minDelay:10,spawnDelay:10,lightSensitive:0b,spawnGroups:[{settingsList:[{remainingSpawnCount:1,hostile:1b,customTag:{ArmorDropChances:[0.085f,0.085f,0.085f,0.085f],hasCustomEquipment:0b,ArmorItems:[{},{},{},{}],skinSettings:{npcTypeName:"custom",skinTypeSelected:"default"},HandDropChances:[0.085f,0.085f],factionName:"minossian",HandItems:[{id:"minecraft:iron_axe",Count:1b,Damage:0s},{}]},maxToSpawn:1,entityId:"ancientwarfarenpc:faction.soldier.elite",minToSpawn:1}],groupWeight:1}],playerRange:16,respondToRedstone:0b,inventory:{Size:9,Items:[]},spawnRange:0,transparent:1b,maxDelay:10,spawnYOffset:0,xpToDrop:0,mobRange:0,debugMode:0b,maxNearbyMonsters:0}}}
:enddata
:endrule

rule:
plugin=blockTile
number=80
data:
JSON:{blockState:{blockName:"ancientwarfarestructure:advanced_spawner",properties:{transparent:"true"}},teData:{id:"ancientwarfarestructure:advanced_spawner_tile",spawnerSettings:{minDelay:10,spawnDelay:10,lightSensitive:0b,spawnGroups:[{settingsList:[{remainingSpawnCount:1,hostile:1b,customTag:{ArmorDropChances:[0.085f,0.085f,0.085f,0.085f],hasCustomEquipment:0b,ArmorItems:[{},{},{},{}],skinSettings:{npcTypeName:"custom",skinTypeSelected:"default"},HandDropChances:[0.085f,0.085f],factionName:"minossian",HandItems:[{id:"minecraft:iron_axe",Count:1b,Damage:0s},{}]},maxToSpawn:1,entityId:"ancientwarfarenpc:faction.soldier.elite",minToSpawn:1}],groupWeight:1}],playerRange:16,respondToRedstone:0b,inventory:{Size:9,Items:[]},spawnRange:0,transparent:1b,maxDelay:10,spawnYOffset:0,xpToDrop:0,mobRange:0,debugMode:0b,maxNearbyMonsters:0}}}
:enddata
:endrule

rule:
plugin=vanillaBlocks
number=81
data:
JSON:{blockState:{blockName:"minecraft:birch_fence_gate",properties:{in_wall:"false",powered:"false",facing:"south",open:"false"}}}
:enddata
:endrule

rule:
plugin=vanillaBlocks
number=82
data:
JSON:{blockState:{blockName:"minecraft:birch_fence_gate",properties:{in_wall:"false",powered:"false",facing:"north",open:"false"}}}
:enddata
:endrule

rule:
plugin=blockTile
number=83
data:
JSON:{blockState:{blockName:"ancientwarfarestructure:advanced_spawner",properties:{transparent:"true"}},teData:{id:"ancientwarfarestructure:advanced_spawner_tile",spawnerSettings:{minDelay:10,spawnDelay:5,lightSensitive:0b,spawnGroups:[{settingsList:[{remainingSpawnCount:1,hostile:1b,customTag:{ArmorDropChances:[0.085f,0.085f,0.085f,0.085f],hasCustomEquipment:0b,ArmorItems:[{},{},{},{}],skinSettings:{npcTypeName:"custom",skinTypeSelected:"default"},HandDropChances:[0.085f,0.085f],factionName:"minossian",HandItems:[{id:"minecraft:diamond_axe",Count:1b,Damage:0s},{}]},maxToSpawn:1,entityId:"ancientwarfarenpc:faction.leader.elite",minToSpawn:1}],groupWeight:1}],playerRange:16,respondToRedstone:0b,inventory:{Size:9,Items:[]},spawnRange:0,transparent:1b,maxDelay:10,spawnYOffset:0,xpToDrop:0,mobRange:0,debugMode:0b,maxNearbyMonsters:0}}}
:enddata
:endrule

rule:
plugin=vanillaBlocks
number=84
data:
JSON:{blockState:{blockName:"minecraft:birch_fence",properties:{east:"false",south:"false",north:"false",west:"false"}}}
:enddata
:endrule

rule:
plugin=blockTile
number=85
data:
JSON:{blockState:{blockName:"ancientwarfarestructure:advanced_spawner",properties:{transparent:"true"}},teData:{id:"ancientwarfarestructure:advanced_spawner_tile",spawnerSettings:{minDelay:10,spawnDelay:1,lightSensitive:0b,spawnGroups:[{settingsList:[{remainingSpawnCount:1,hostile:1b,customTag:{ArmorDropChances:[0.085f,0.085f,0.085f,0.085f],hasCustomEquipment:0b,ArmorItems:[{},{},{},{}],skinSettings:{npcTypeName:"custom",skinTypeSelected:"default"},HandDropChances:[0.085f,0.085f],factionName:"minossian",HandItems:[{id:"minecraft:iron_axe",Count:1b,Damage:0s},{}]},maxToSpawn:1,entityId:"ancientwarfarenpc:faction.soldier.elite",minToSpawn:1}],groupWeight:1}],playerRange:16,respondToRedstone:0b,inventory:{Size:9,Items:[]},spawnRange:0,transparent:1b,maxDelay:10,spawnYOffset:0,xpToDrop:0,mobRange:0,debugMode:0b,maxNearbyMonsters:0}}}
:enddata
:endrule

rule:
plugin=blockTile
number=86
data:
JSON:{blockState:{blockName:"ancientwarfarestructure:advanced_spawner",properties:{transparent:"true"}},teData:{id:"ancientwarfarestructure:advanced_spawner_tile",spawnerSettings:{minDelay:10,spawnDelay:7,lightSensitive:0b,spawnGroups:[{settingsList:[{remainingSpawnCount:1,hostile:1b,customTag:{ArmorDropChances:[0.085f,0.085f,0.085f,0.085f],hasCustomEquipment:0b,ArmorItems:[{},{},{},{}],skinSettings:{npcTypeName:"custom",skinTypeSelected:"default"},HandDropChances:[0.085f,0.085f],factionName:"minossian",HandItems:[{id:"minecraft:iron_axe",Count:1b,Damage:0s},{}]},maxToSpawn:1,entityId:"ancientwarfarenpc:faction.soldier.elite",minToSpawn:1}],groupWeight:1}],playerRange:16,respondToRedstone:0b,inventory:{Size:9,Items:[]},spawnRange:0,transparent:1b,maxDelay:10,spawnYOffset:0,xpToDrop:0,mobRange:0,debugMode:0b,maxNearbyMonsters:0}}}
:enddata
:endrule

rule:
plugin=blockTile
number=87
data:
JSON:{blockState:{blockName:"ancientwarfarestructure:advanced_spawner",properties:{transparent:"true"}},teData:{id:"ancientwarfarestructure:advanced_spawner_tile",spawnerSettings:{minDelay:10,spawnDelay:10,lightSensitive:0b,spawnGroups:[{settingsList:[{remainingSpawnCount:1,hostile:1b,customTag:{ArmorDropChances:[0.085f,0.085f,0.085f,0.085f],hasCustomEquipment:0b,ArmorItems:[{},{},{},{}],skinSettings:{npcTypeName:"custom",skinTypeSelected:"default"},HandDropChances:[0.085f,0.085f],factionName:"minossian",HandItems:[{id:"minecraft:iron_axe",Count:1b,Damage:0s},{}]},maxToSpawn:1,entityId:"ancientwarfarenpc:faction.soldier.elite",minToSpawn:1}],groupWeight:1}],playerRange:16,respondToRedstone:0b,inventory:{Size:9,Items:[]},spawnRange:0,transparent:1b,maxDelay:10,spawnYOffset:0,xpToDrop:0,mobRange:0,debugMode:0b,maxNearbyMonsters:0}}}
:enddata
:endrule

rule:
plugin=blockTile
number=88
data:
JSON:{blockState:{blockName:"ancientwarfarestructure:advanced_spawner",properties:{transparent:"true"}},teData:{id:"ancientwarfarestructure:advanced_spawner_tile",spawnerSettings:{minDelay:10,spawnDelay:10,lightSensitive:0b,spawnGroups:[{settingsList:[{remainingSpawnCount:1,hostile:1b,customTag:{ArmorDropChances:[0.085f,0.085f,0.085f,0.085f],hasCustomEquipment:0b,ArmorItems:[{},{},{},{}],skinSettings:{npcTypeName:"custom",skinTypeSelected:"default"},HandDropChances:[0.085f,0.085f],factionName:"minossian",HandItems:[{id:"minecraft:iron_axe",Count:1b,Damage:0s},{}]},maxToSpawn:1,entityId:"ancientwarfarenpc:faction.soldier.elite",minToSpawn:1}],groupWeight:1}],playerRange:16,respondToRedstone:0b,inventory:{Size:9,Items:[]},spawnRange:0,transparent:1b,maxDelay:10,spawnYOffset:0,xpToDrop:0,mobRange:0,debugMode:0b,maxNearbyMonsters:0}}}
:enddata
:endrule

rule:
plugin=vanillaBlocks
number=89
data:
JSON:{blockState:{blockName:"minecraft:quartz_stairs",properties:{half:"top",shape:"straight",facing:"east"}}}
:enddata
:endrule

rule:
plugin=vanillaBlocks
number=90
data:
JSON:{blockState:{blockName:"minecraft:quartz_stairs",properties:{half:"top",shape:"straight",facing:"west"}}}
:enddata
:endrule

rule:
plugin=vanillaBlocks
number=91
data:
JSON:{blockState:{blockName:"minecraft:stained_hardened_clay",properties:{color:"white"}}}
:enddata
:endrule

rule:
plugin=vanillaBlocks
number=92
data:
JSON:{blockState:{blockName:"minecraft:quartz_stairs",properties:{half:"top",shape:"straight",facing:"south"}}}
:enddata
:endrule

rule:
plugin=vanillaBlocks
number=93
data:
JSON:{blockState:{blockName:"minecraft:planks",properties:{variant:"acacia"}}}
:enddata
:endrule

rule:
plugin=vanillaBlocks
number=94
data:
JSON:{blockState:{blockName:"minecraft:quartz_block",properties:{variant:"chiseled"}}}
:enddata
:endrule

rule:
plugin=vanillaBlocks
number=95
data:
JSON:{blockState:{blockName:"minecraft:stained_hardened_clay",properties:{color:"red"}}}
:enddata
:endrule

rule:
plugin=vanillaBlocks
number=96
data:
JSON:{blockState:{blockName:"minecraft:wooden_slab",properties:{half:"bottom",variant:"acacia"}}}
:enddata
:endrule

rule:
plugin=vanillaBlocks
number=97
data:
JSON:{blockState:{blockName:"minecraft:quartz_block",properties:{variant:"default"}}}
:enddata
:endrule

rule:
plugin=blockTile
number=98
data:
JSON:{blockState:{blockName:"ancientwarfarestructure:urn"},teData:{lootSettings:{lootRolls:1,splashPotion:1b,effects:[{Ambient:0b,CurativeItems:[{id:"minecraft:milk_bucket",Count:1b,Damage:0s}],ShowParticles:1b,RegistryName:"minecraft:instant_health",Duration:120,Amplifier:1b}],hasMessage:0b,hasLoot:1b,lootTableName:"minecraft:chests/simple_dungeon",spawnEntity:0b,entity:"minecraft:"},id:"ancientwarfarestructure:urn_tile"}}
:enddata
:endrule

rule:
plugin=blockTile
number=99
data:
JSON:{blockState:{blockName:"ancientwarfarestructure:urn"},teData:{lootSettings:{lootRolls:1,splashPotion:1b,effects:[{Ambient:0b,CurativeItems:[{id:"minecraft:milk_bucket",Count:1b,Damage:0s}],ShowParticles:1b,RegistryName:"minecraft:instant_health",Duration:120,Amplifier:1b}],hasMessage:0b,hasLoot:1b,lootTableName:"minecraft:chests/simple_dungeon",spawnEntity:0b,entity:"minecraft:"},id:"ancientwarfarestructure:urn_tile"}}
:enddata
:endrule

rule:
plugin=blockTile
number=100
data:
JSON:{blockState:{blockName:"ancientwarfarestructure:urn"},teData:{lootSettings:{lootRolls:1,splashPotion:1b,effects:[{Ambient:0b,CurativeItems:[{id:"minecraft:milk_bucket",Count:1b,Damage:0s}],ShowParticles:1b,RegistryName:"minecraft:instant_health",Duration:120,Amplifier:1b}],hasMessage:0b,hasLoot:1b,lootTableName:"minecraft:chests/simple_dungeon",spawnEntity:0b,entity:"minecraft:"},id:"ancientwarfarestructure:urn_tile"}}
:enddata
:endrule

rule:
plugin=inventory
number=101
data:
JSON:{blockState:{blockName:"minecraft:chest",properties:{facing:"north"}},lootLevel:0,teData:{Items:[],id:"minecraft:chest",Lock:""},inventoryData:{length:0,inventoryContents:[]},legacyFeatures:1b}
:enddata
:endrule

rule:
plugin=blockTile
number=102
data:
JSON:{blockState:{blockName:"ancientwarfarestructure:urn"},teData:{lootSettings:{lootRolls:1,splashPotion:1b,effects:[{Ambient:0b,CurativeItems:[{id:"minecraft:milk_bucket",Count:1b,Damage:0s}],ShowParticles:1b,RegistryName:"minecraft:instant_health",Duration:120,Amplifier:1b}],hasMessage:0b,hasLoot:1b,lootTableName:"minecraft:chests/simple_dungeon",spawnEntity:0b,entity:"minecraft:"},id:"ancientwarfarestructure:urn_tile"}}
:enddata
:endrule

rule:
plugin=blockTile
number=103
data:
JSON:{blockState:{blockName:"ancientwarfarestructure:urn"},teData:{lootSettings:{lootRolls:1,splashPotion:1b,effects:[{Ambient:0b,CurativeItems:[{id:"minecraft:milk_bucket",Count:1b,Damage:0s}],ShowParticles:1b,RegistryName:"minecraft:instant_health",Duration:120,Amplifier:1b}],hasMessage:0b,hasLoot:1b,lootTableName:"minecraft:chests/simple_dungeon",spawnEntity:0b,entity:"minecraft:"},id:"ancientwarfarestructure:urn_tile"}}
:enddata
:endrule

rule:
plugin=blockTile
number=104
data:
JSON:{blockState:{blockName:"ancientwarfarestructure:advanced_loot_chest",properties:{facing:"south"}},teData:{lootSettings:{lootRolls:1,splashPotion:0b,hasMessage:0b,hasLoot:1b,lootTableName:"ancientwarfare:chests/minossian",spawnEntity:0b,entity:"minecraft:"},Items:[],id:"ancientwarfarestructure:advanced_loot_chest_tile",Lock:""}}
:enddata
:endrule

rule:
plugin=blockTile
number=105
data:
JSON:{blockState:{blockName:"ancientwarfarestructure:advanced_loot_chest",properties:{facing:"south"}},teData:{lootSettings:{lootRolls:1,splashPotion:0b,hasMessage:0b,hasLoot:1b,lootTableName:"ancientwarfare:chests/minossian",spawnEntity:0b,entity:"minecraft:"},Items:[],id:"ancientwarfarestructure:advanced_loot_chest_tile",Lock:""}}
:enddata
:endrule

rule:
plugin=vanillaBlocks
number=106
data:
JSON:{blockState:{blockName:"minecraft:double_stone_slab",properties:{seamless:"false",variant:"quartz"}}}
:enddata
:endrule

#### ENTITIES ####
