# Ancient Warfare Structure Template File
# Auto-generated structure template file. created on: 3/7/2024 at: 17:21:21
# Lines beginning with # denote comments

header:
version=2.11
name=SarkonidPashaFamilyPalace
mods=
size=53,38,48
offset=26,5,47
:endheader

#### VALIDATION ####
validation:
type=ground
structureAuthor=TheOddlySeagull
survival=false
worldGenEnabled=true
unique=false
preserveBlocks=false
preventNaturalHostileSpawns=true
selectionWeight=20
clusterValue=50
minDuplicateDistance=5000
dimensionWhiteList=true
dimensionList=0
biomeGroupList=sarkonid
biomeWhiteList=true
biomeList=environs:sandstone_ranges,nt:sahel,minecraft:desert,minecraft:mutated_desert,minecraft:desert_hills
leveling=10
fill=10
border=6
blockSwap=false
territoryName=sarkonid
biomeReplacement=minecraft:
minGenerationHeight=0
maxGenerationHeight=255
:endvalidation

#### LAYERS ####
layer: 0
1,1,1,1,1,1,1,1,1,1,1,1,1,1,1,1,1,1,1,1,1,1,1,1,1,1,1,1,1,1,1,1,1,1,1,1,1,1,1,1,1,1,1,1,1,1,1,1,1,1,1,1,1
1,1,1,1,1,1,1,1,1,1,1,1,1,1,1,1,1,1,1,1,1,1,1,1,1,1,1,1,1,1,1,1,1,1,1,1,1,1,1,1,1,1,1,1,1,1,1,1,1,1,1,1,1
1,1,1,1,1,1,1,1,1,1,1,1,1,1,1,1,1,1,1,1,1,1,1,1,1,1,1,1,1,1,1,1,1,1,1,1,1,1,1,1,1,1,1,1,1,1,1,1,1,1,1,1,1
1,1,1,1,1,1,1,1,1,1,1,1,1,1,1,1,1,1,1,1,1,1,1,1,1,1,1,1,1,1,1,1,1,1,1,1,1,1,1,1,1,1,1,1,1,1,1,1,1,1,1,1,1
1,1,1,1,1,1,1,1,1,1,1,1,1,1,1,1,1,1,1,1,1,1,1,1,1,1,1,1,1,1,1,1,1,1,1,1,1,1,1,1,1,1,1,1,1,1,1,1,1,1,1,1,1
1,1,1,1,1,1,1,1,1,1,1,1,1,1,1,1,1,1,1,1,1,1,1,1,1,1,1,1,1,1,1,1,1,1,1,1,1,1,1,1,1,1,1,1,1,1,1,1,1,1,1,1,1
1,1,1,1,1,1,1,1,1,1,1,1,1,1,1,1,1,1,1,1,1,1,1,1,1,1,1,1,1,1,1,1,1,1,1,1,1,1,1,1,1,1,1,1,1,1,1,1,1,1,1,1,1
1,1,1,1,1,1,1,1,1,1,1,1,1,1,1,1,1,1,1,1,1,1,1,1,1,1,1,1,1,1,1,1,1,1,1,1,1,1,1,1,1,1,1,1,1,1,1,1,1,1,1,1,1
1,1,1,1,1,1,1,1,1,1,1,1,1,1,1,1,1,1,1,1,1,1,1,1,1,1,1,1,1,1,1,1,1,1,1,1,1,1,1,1,1,1,1,1,1,1,1,1,1,1,1,1,1
1,1,1,1,1,1,1,1,1,1,1,1,1,1,1,1,1,1,1,1,1,1,1,1,1,1,1,1,1,1,1,1,1,1,1,1,1,1,1,1,1,1,1,1,1,1,1,1,1,1,1,1,1
1,1,1,1,1,1,1,1,1,1,1,1,1,1,1,1,1,1,1,1,1,1,1,1,1,1,1,1,1,1,1,1,1,1,1,1,1,1,1,1,1,1,1,1,1,1,1,1,1,1,1,1,1
1,1,1,1,1,1,1,1,1,1,1,1,1,1,1,1,1,1,1,1,1,1,1,1,1,1,1,1,1,1,1,1,1,1,1,1,1,1,1,1,1,1,1,1,1,1,1,1,1,1,1,1,1
1,1,1,1,1,1,1,1,1,1,1,1,1,1,1,1,1,1,1,1,1,1,1,1,1,1,1,1,1,1,1,1,1,1,1,1,1,1,1,1,1,1,1,1,1,1,1,1,1,1,1,1,1
1,1,1,1,1,1,1,1,1,1,1,1,1,1,1,1,1,1,1,1,1,1,1,1,1,1,1,1,1,1,1,1,1,1,1,1,1,1,1,1,1,1,1,1,1,1,1,1,1,1,1,1,1
1,1,1,1,1,1,1,1,1,1,1,1,1,1,1,1,1,1,1,1,1,1,1,1,1,1,1,1,1,1,1,1,1,1,1,1,1,1,1,1,1,1,1,1,1,1,1,1,1,1,1,1,1
1,1,1,1,1,1,1,1,1,1,1,1,1,1,1,1,1,1,1,1,1,1,1,1,1,1,1,1,1,1,1,1,1,1,1,1,1,1,1,1,1,1,1,1,1,1,1,1,1,1,1,1,1
1,1,1,1,1,1,1,1,1,1,1,1,1,1,1,1,1,1,1,1,1,1,1,1,1,1,1,1,1,1,1,1,1,1,1,1,1,1,1,1,1,1,1,1,1,1,1,1,1,1,1,1,1
1,1,1,1,1,1,1,1,1,1,1,1,1,1,1,1,1,1,1,1,1,1,1,1,1,1,1,1,1,1,1,1,1,1,1,1,1,1,1,1,1,1,1,1,1,1,1,1,1,1,1,1,1
1,1,1,1,1,1,1,1,1,1,1,1,1,1,1,1,1,1,1,1,1,1,1,1,1,1,1,1,1,1,1,1,1,1,1,1,1,1,1,1,1,1,1,1,1,1,1,1,1,1,1,1,1
1,1,1,1,1,1,1,1,1,1,1,1,1,1,1,1,1,1,1,1,1,1,1,1,1,1,1,1,1,1,1,1,1,1,1,1,1,1,1,1,1,1,1,1,1,1,1,1,1,1,1,1,1
1,1,1,1,1,1,1,1,1,1,1,1,1,1,1,1,1,1,1,1,1,1,1,1,1,1,1,1,1,1,1,1,1,1,1,1,1,1,1,1,1,1,1,1,1,1,1,1,1,1,1,1,1
1,1,1,1,1,1,1,1,1,1,1,1,1,1,1,1,1,1,1,1,1,1,1,1,1,1,1,1,1,1,1,1,1,1,1,1,1,1,1,1,1,1,1,1,1,1,1,1,1,1,1,1,1
1,1,1,1,1,1,1,1,1,1,1,1,1,1,1,1,1,1,1,1,1,1,1,1,1,1,1,1,1,1,1,1,1,1,1,1,1,1,1,1,1,1,1,1,1,1,1,1,1,1,1,1,1
1,1,1,1,1,1,1,1,1,1,1,1,1,1,1,1,1,1,1,1,1,1,1,1,1,1,1,1,1,1,1,1,1,1,1,1,1,1,1,1,1,1,1,1,1,1,1,1,1,1,1,1,1
1,1,1,1,1,1,1,1,1,1,1,1,1,1,1,1,1,1,1,1,1,1,1,1,1,1,1,1,1,1,1,1,1,1,1,1,1,1,1,1,1,1,1,1,1,1,1,1,1,1,1,1,1
1,1,1,1,1,1,1,1,1,1,1,1,1,1,1,1,1,1,1,1,1,1,1,1,1,1,1,1,1,1,1,1,1,1,1,1,1,1,1,1,1,1,1,1,1,1,1,1,1,1,1,1,1
1,1,1,1,1,1,1,1,1,1,1,1,1,1,1,1,1,1,1,1,1,1,1,1,1,1,1,1,1,1,1,1,1,1,1,1,1,1,1,1,1,1,1,1,1,1,1,1,1,1,1,1,1
1,1,1,1,1,1,1,1,1,1,1,1,1,1,1,1,1,1,1,1,1,1,1,1,1,1,1,1,1,1,1,1,1,1,1,1,1,1,1,1,1,1,1,1,1,1,1,1,1,1,1,1,1
1,1,1,1,1,1,1,1,1,1,1,1,1,1,1,1,1,1,1,1,1,1,1,1,1,1,1,1,1,1,1,1,1,1,1,1,1,1,1,1,1,1,1,1,1,1,1,1,1,1,1,1,1
1,1,1,1,1,1,1,1,1,1,1,1,1,1,1,1,1,1,1,1,1,1,1,1,1,1,1,1,1,1,1,1,1,1,1,1,1,1,1,1,1,1,1,1,1,1,1,1,1,1,1,1,1
1,1,1,1,1,1,1,1,1,1,1,1,1,1,1,1,1,1,1,1,1,1,1,1,1,1,1,1,1,1,1,1,1,1,1,1,1,1,1,1,1,1,1,1,1,1,1,1,1,1,1,1,1
1,1,1,1,1,1,1,1,1,1,1,1,1,1,1,1,1,1,1,1,1,1,1,1,1,1,1,1,1,1,1,1,1,1,1,1,1,1,1,1,1,1,1,1,1,1,1,1,1,1,1,1,1
1,1,1,1,1,1,1,1,1,1,1,1,1,1,1,1,1,1,1,1,1,1,1,1,1,1,1,1,1,1,1,1,1,1,1,1,1,1,1,1,1,1,1,1,1,1,1,1,1,1,1,1,1
1,1,1,1,1,1,1,1,1,1,1,1,1,1,1,1,1,1,1,1,1,1,1,1,1,1,1,1,1,1,1,1,1,1,1,1,1,1,1,1,1,1,1,1,1,1,1,1,1,1,1,1,1
1,1,1,1,1,1,1,1,1,1,1,1,1,1,1,1,1,1,1,1,1,1,1,1,1,1,1,1,1,1,1,1,1,1,1,1,1,1,1,1,1,1,1,1,1,1,1,1,1,1,1,1,1
1,1,1,1,1,1,1,1,1,1,1,1,1,1,1,1,1,1,1,1,1,1,1,1,1,1,1,1,1,1,1,1,1,1,1,1,1,1,1,1,1,1,1,1,1,1,1,1,1,1,1,1,1
1,1,1,1,1,1,1,1,1,1,1,1,1,1,1,1,1,1,1,1,1,1,1,1,1,1,1,1,1,1,1,1,1,1,1,1,1,1,1,1,1,1,1,1,1,1,1,1,1,1,1,1,1
1,1,1,1,1,1,1,1,1,1,1,1,1,1,1,1,1,1,1,1,1,1,1,1,1,1,1,1,1,1,1,1,1,1,1,1,1,1,1,1,1,1,1,1,1,1,1,1,1,1,1,1,1
1,1,1,1,1,1,1,1,1,1,1,1,1,1,1,1,1,1,1,1,1,1,1,1,1,1,1,1,1,1,1,1,1,1,1,1,1,1,1,1,1,1,1,1,1,1,1,1,1,1,1,1,1
1,1,1,1,1,1,1,1,1,1,1,1,1,1,1,1,1,1,1,1,1,1,1,1,1,1,1,1,1,1,1,1,1,1,1,1,1,1,1,1,1,1,1,1,1,1,1,1,1,1,1,1,1
1,1,1,1,1,1,1,1,1,1,1,1,1,1,1,1,1,1,1,1,1,1,1,1,1,1,1,1,1,1,1,1,1,1,1,1,1,1,1,1,1,1,1,1,1,1,1,1,1,1,1,1,1
1,1,1,1,1,1,1,1,1,1,1,1,1,1,1,1,1,1,1,1,1,1,1,1,1,1,1,1,1,1,1,1,1,1,1,1,1,1,1,1,1,1,1,1,1,1,1,1,1,1,1,1,1
1,1,1,1,1,1,1,1,1,1,1,1,1,1,1,1,1,1,1,1,1,1,1,1,1,1,1,1,1,1,1,1,1,1,1,1,1,1,1,1,1,1,1,1,1,1,1,1,1,1,1,1,1
1,1,1,1,1,1,1,1,1,1,1,1,1,1,1,1,1,1,1,1,1,1,1,1,1,1,1,1,1,1,1,1,1,1,1,1,1,1,1,1,1,1,1,1,1,1,1,1,1,1,1,1,1
1,1,1,1,1,1,1,1,1,1,1,1,1,1,1,1,1,1,1,1,1,1,1,1,1,1,1,1,1,1,1,1,1,1,1,1,1,1,1,1,1,1,1,1,1,1,1,1,1,1,1,1,1
1,1,1,1,1,1,1,1,1,1,1,1,1,1,1,1,1,1,1,1,1,1,1,1,1,1,1,1,1,1,1,1,1,1,1,1,1,1,1,1,1,1,1,1,1,1,1,1,1,1,1,1,1
1,1,1,1,1,1,1,1,1,1,1,1,1,1,1,1,1,1,1,1,1,1,1,1,1,1,1,1,1,1,1,1,1,1,1,1,1,1,1,1,1,1,1,1,1,1,1,1,1,1,1,1,1
1,1,1,1,1,1,1,1,1,1,1,1,1,1,1,1,1,1,1,1,1,1,1,1,1,1,1,1,1,1,1,1,1,1,1,1,1,1,1,1,1,1,1,1,1,1,1,1,1,1,1,1,1
:endlayer
layer: 1
1,1,1,1,1,1,1,1,1,1,1,1,1,1,1,1,1,1,1,1,1,1,1,1,1,1,1,1,1,1,1,1,1,1,1,1,1,1,1,1,1,1,1,1,1,1,1,1,1,1,1,1,1
1,1,1,1,1,1,1,1,1,1,1,1,1,1,1,1,1,1,1,1,1,1,1,1,1,1,1,1,1,1,1,1,1,1,1,1,1,1,1,1,1,1,1,1,1,1,1,1,1,1,1,1,1
1,1,1,1,1,1,1,1,1,1,1,1,1,1,1,1,1,1,1,1,1,1,1,1,1,1,1,1,1,1,1,1,1,1,1,1,1,1,1,1,1,1,1,1,1,1,1,1,1,1,1,1,1
1,1,1,1,1,1,1,1,1,1,1,1,1,1,1,1,1,1,1,1,1,1,1,1,1,1,1,1,1,1,1,1,1,1,1,1,1,1,1,1,1,1,1,1,1,1,1,1,1,1,1,1,1
1,1,1,1,1,1,1,1,1,1,1,1,1,1,1,1,1,1,1,1,1,1,1,1,1,1,1,1,1,1,1,1,1,1,1,1,1,1,1,1,1,1,1,1,1,1,1,1,1,1,1,1,1
1,1,1,1,1,1,1,1,1,1,1,1,1,1,1,1,1,1,1,1,1,1,1,1,1,1,1,1,1,1,1,1,1,1,1,1,1,1,1,1,1,1,1,1,1,1,1,1,1,1,1,1,1
1,1,1,1,1,1,1,1,1,1,1,1,1,1,1,1,1,1,1,1,1,1,1,1,1,1,1,1,1,1,1,1,1,1,1,1,1,1,1,1,1,1,1,1,1,1,1,1,1,1,1,1,1
1,1,1,1,1,1,1,1,1,1,1,1,1,1,1,1,1,1,1,1,1,1,1,1,1,1,1,1,1,1,1,1,1,1,1,1,1,1,1,1,1,1,1,1,1,1,1,1,1,1,1,1,1
1,1,1,1,1,1,1,1,1,1,1,1,1,1,1,1,1,1,1,1,1,1,1,1,1,1,1,1,1,1,1,1,1,1,1,1,1,1,1,1,1,1,1,1,1,1,1,1,1,1,1,1,1
1,1,1,1,1,1,1,1,1,1,1,1,1,1,1,1,1,1,1,1,1,1,1,1,1,1,1,1,1,1,1,1,1,1,1,1,1,1,1,1,1,1,1,1,1,1,1,1,1,1,1,1,1
1,1,1,1,1,1,1,1,1,1,1,1,1,1,1,1,1,1,1,1,1,1,1,1,1,1,1,1,1,1,1,1,1,1,1,1,1,1,1,1,1,1,1,1,1,1,1,1,1,1,1,1,1
1,1,1,1,1,1,1,1,1,1,1,1,1,1,1,1,1,1,1,1,1,1,1,1,1,1,1,1,1,1,1,1,1,1,1,1,1,1,1,1,1,1,1,1,1,1,1,1,1,1,1,1,1
1,1,1,1,1,1,1,1,1,1,1,1,1,1,1,1,1,1,1,1,1,1,1,1,1,1,1,1,1,1,1,1,1,1,1,1,1,1,1,1,1,1,1,1,1,1,1,1,1,1,1,1,1
1,1,1,1,1,1,1,1,1,1,1,1,1,1,1,1,1,1,1,1,1,1,1,1,1,1,1,1,1,1,1,1,1,1,1,1,1,1,1,1,1,1,1,1,1,1,1,1,1,1,1,1,1
1,1,1,1,1,1,1,1,1,1,1,1,1,1,1,1,1,1,1,1,1,1,1,1,1,1,1,1,1,1,1,1,1,1,1,1,1,1,1,1,1,1,1,1,1,1,1,1,1,1,1,1,1
1,1,1,1,1,1,1,1,1,1,1,1,1,1,1,1,1,1,1,1,1,1,1,1,1,1,1,1,1,1,1,1,1,1,1,1,1,1,1,1,1,1,1,1,1,1,1,1,1,1,1,1,1
1,1,1,1,1,1,1,1,1,1,1,1,1,1,1,1,1,1,1,1,1,1,1,1,1,1,1,1,1,1,1,1,1,1,1,1,1,1,1,1,1,1,1,1,1,1,1,1,1,1,1,1,1
1,1,1,1,1,1,1,1,1,1,1,1,1,1,1,1,1,1,1,1,1,1,1,1,1,1,1,1,1,1,1,1,1,1,1,1,1,1,1,1,1,1,1,1,1,1,1,1,1,1,1,1,1
1,1,1,1,1,1,1,1,1,1,1,1,1,1,1,1,1,1,1,1,1,1,1,1,1,1,1,1,1,1,1,1,1,1,1,1,1,1,1,1,1,1,1,1,1,1,1,1,1,1,1,1,1
1,1,1,1,1,1,1,1,1,1,1,1,1,1,1,1,1,1,1,1,1,1,1,1,1,1,1,1,1,1,1,1,1,1,1,1,1,1,1,1,1,1,1,1,1,1,1,1,1,1,1,1,1
1,1,1,1,1,1,1,1,1,1,1,1,1,1,1,1,1,1,1,1,1,1,1,1,1,1,1,1,1,1,1,1,1,1,1,1,1,1,1,1,1,1,1,1,1,1,1,1,1,1,1,1,1
1,1,1,1,1,1,1,1,1,1,1,1,1,1,1,1,1,1,1,1,1,1,1,1,1,1,1,1,1,1,1,1,1,1,1,1,1,1,1,1,1,1,1,1,1,1,1,1,1,1,1,1,1
1,1,1,1,1,1,1,1,1,1,1,1,1,1,1,1,1,1,1,1,1,1,1,1,1,1,1,1,1,1,1,1,1,1,1,1,1,1,1,1,1,1,1,1,1,1,1,1,1,1,1,1,1
1,1,1,1,1,1,1,1,1,1,1,1,1,1,1,1,1,1,1,1,1,1,1,1,1,1,1,1,1,1,1,1,1,1,1,1,1,1,1,1,1,1,1,1,1,1,1,1,1,1,1,1,1
1,1,1,1,1,1,1,1,1,1,1,1,1,1,1,1,1,1,1,1,1,1,1,1,1,1,1,1,1,1,1,1,1,1,1,1,1,1,1,1,1,1,1,1,1,1,1,1,1,1,1,1,1
1,1,1,1,1,1,1,1,1,1,1,1,1,1,1,1,1,1,1,1,1,1,1,1,1,1,1,1,1,1,1,1,1,1,1,1,1,1,1,1,1,1,1,1,1,1,1,1,1,1,1,1,1
1,1,1,1,1,1,1,1,1,1,1,1,1,1,1,1,1,1,1,1,1,1,1,1,1,1,1,1,1,1,1,1,1,1,1,1,1,1,1,1,1,1,1,1,1,1,1,1,1,1,1,1,1
1,1,1,1,1,1,1,1,1,1,1,1,1,1,1,1,1,1,1,1,1,1,1,1,1,1,1,1,1,1,1,1,1,1,1,1,1,1,1,1,1,1,1,1,1,1,1,1,1,1,1,1,1
1,1,1,1,1,1,1,1,1,1,1,1,1,1,1,1,1,1,1,1,1,1,1,1,1,1,1,1,1,1,1,1,1,1,1,1,1,1,1,1,1,1,1,1,1,1,1,1,1,1,1,1,1
1,1,1,1,1,1,1,1,1,1,1,1,1,1,1,1,1,1,1,1,1,1,1,1,1,1,1,1,1,1,1,1,1,1,1,1,1,1,1,1,1,1,1,1,1,1,1,1,1,1,1,1,1
1,1,1,1,1,1,1,1,1,1,1,1,1,1,1,1,1,1,1,1,1,1,1,1,1,1,1,1,1,1,1,1,1,1,1,1,1,1,1,1,1,1,1,1,1,1,1,1,1,1,1,1,1
1,1,1,1,1,1,1,1,1,1,1,1,1,1,1,1,1,1,1,1,1,1,1,1,1,1,1,1,1,1,1,1,1,1,1,1,1,1,1,1,1,1,1,1,1,1,1,1,1,1,1,1,1
1,1,1,1,1,1,1,1,1,1,1,1,1,1,1,1,1,1,1,1,1,1,1,1,1,1,1,1,1,1,1,1,1,1,1,1,1,1,1,1,1,1,1,1,1,1,1,1,1,1,1,1,1
1,1,1,1,1,1,1,1,1,1,1,1,1,1,1,1,1,1,1,1,1,1,1,1,1,1,1,1,1,1,1,1,1,1,1,1,1,1,1,1,1,1,1,1,1,1,1,1,1,1,1,1,1
1,1,1,1,1,1,1,1,1,1,1,1,1,1,1,1,1,1,1,1,1,1,1,1,1,1,1,1,1,1,1,1,1,1,1,1,1,1,1,1,1,1,1,1,1,1,1,1,1,1,1,1,1
1,1,1,1,1,1,1,1,1,1,1,1,1,1,1,1,1,1,1,1,1,1,1,1,1,1,1,1,1,1,1,1,1,1,1,1,1,1,1,1,1,1,1,1,1,1,1,1,1,1,1,1,1
1,1,1,1,1,1,1,1,1,1,1,1,1,1,1,1,1,1,1,1,1,1,1,1,1,1,1,1,1,1,1,1,1,1,1,1,1,1,1,1,1,1,1,1,1,1,1,1,1,1,1,1,1
1,1,1,1,1,1,1,1,1,1,1,1,1,1,1,1,1,1,1,1,1,1,1,1,1,1,1,1,1,1,1,1,1,1,1,1,1,1,1,1,1,1,1,1,1,1,1,1,1,1,1,1,1
1,1,1,1,1,1,1,1,1,1,1,1,1,1,1,1,1,1,1,1,1,1,1,1,1,1,1,1,1,1,1,1,1,1,1,1,1,1,1,1,1,1,1,1,1,1,1,1,1,1,1,1,1
1,1,1,1,1,1,1,1,1,1,1,1,1,1,1,1,1,1,1,1,1,1,1,1,1,1,1,1,1,1,1,1,1,1,1,1,1,1,1,1,1,1,1,1,1,1,1,1,1,1,1,1,1
1,1,1,1,1,1,1,1,1,1,1,1,1,1,1,1,1,1,1,1,1,1,1,1,1,1,1,1,1,1,1,1,1,1,1,1,1,1,1,1,1,1,1,1,1,1,1,1,1,1,1,1,1
1,1,1,1,1,1,1,1,1,1,1,1,1,1,1,1,1,1,1,1,1,1,1,1,1,1,1,1,1,1,1,1,1,1,1,1,1,1,1,1,1,1,1,1,1,1,1,1,1,1,1,1,1
1,1,1,1,1,1,1,1,1,1,1,1,1,1,1,1,1,1,1,1,1,1,1,1,1,1,1,1,1,1,1,1,1,1,1,1,1,1,1,1,1,1,1,1,1,1,1,1,1,1,1,1,1
1,1,1,1,1,1,1,1,1,1,1,1,1,1,1,1,1,1,1,1,1,1,1,1,1,1,1,1,1,1,1,1,1,1,1,1,1,1,1,1,1,1,1,1,1,1,1,1,1,1,1,1,1
1,1,1,1,1,1,1,1,1,1,1,1,1,1,1,1,1,1,1,1,1,1,1,1,1,1,1,1,1,1,1,1,1,1,1,1,1,1,1,1,1,1,1,1,1,1,1,1,1,1,1,1,1
1,1,1,1,1,1,1,1,1,1,1,1,1,1,1,1,1,1,1,1,1,1,1,1,1,1,1,1,1,1,1,1,1,1,1,1,1,1,1,1,1,1,1,1,1,1,1,1,1,1,1,1,1
1,1,1,1,1,1,1,1,1,1,1,1,1,1,1,1,1,1,1,1,1,1,1,1,1,1,1,1,1,1,1,1,1,1,1,1,1,1,1,1,1,1,1,1,1,1,1,1,1,1,1,1,1
1,1,1,1,1,1,1,1,1,1,1,1,1,1,1,1,1,1,1,1,1,1,1,1,1,1,1,1,1,1,1,1,1,1,1,1,1,1,1,1,1,1,1,1,1,1,1,1,1,1,1,1,1
:endlayer
layer: 2
1,1,1,1,1,1,1,1,1,1,1,1,1,1,1,1,1,1,1,1,1,1,1,1,1,1,1,1,1,1,1,1,1,1,1,1,1,1,1,1,1,1,1,1,1,1,1,1,1,1,1,1,1
1,1,1,1,1,1,1,1,1,1,1,1,1,1,1,1,1,1,1,1,1,1,1,1,1,1,1,1,1,1,1,1,1,1,1,1,1,1,1,1,1,1,1,1,1,1,1,1,1,1,1,1,1
1,1,1,1,1,1,1,1,1,1,1,1,1,1,1,1,1,1,1,1,1,1,1,1,1,1,1,1,1,1,1,1,1,1,1,1,1,1,1,1,1,1,1,1,1,1,1,1,1,1,1,1,1
1,1,1,1,1,1,1,1,1,1,1,1,1,1,1,1,1,1,1,1,1,1,1,1,1,1,1,1,1,1,1,1,1,1,1,1,1,1,1,1,1,1,1,1,1,1,1,1,1,1,1,1,1
1,1,1,1,1,1,1,1,1,1,1,1,1,1,1,1,1,1,1,1,1,1,1,1,1,1,1,1,1,1,1,1,1,1,1,1,1,1,1,1,1,1,1,1,1,1,1,1,1,1,1,1,1
1,1,1,1,1,1,1,1,1,1,1,1,1,1,1,1,1,1,1,1,1,1,1,1,1,1,1,1,1,1,1,1,1,1,1,1,1,1,1,1,1,1,1,1,1,1,1,1,1,1,1,1,1
1,1,1,1,1,1,1,1,1,1,1,1,1,1,1,1,1,1,1,1,1,1,1,1,1,1,1,1,1,1,1,1,1,1,1,1,1,1,1,1,1,1,1,1,1,1,1,1,1,1,1,1,1
1,1,1,1,1,1,1,1,1,1,1,1,1,1,1,1,1,1,1,1,1,1,1,1,1,1,1,1,1,1,1,1,1,1,1,1,1,1,1,1,1,1,1,1,1,1,1,1,1,1,1,1,1
1,1,1,1,1,1,1,1,1,1,1,1,1,1,1,1,1,1,1,1,1,1,1,1,1,1,1,1,1,1,1,1,1,1,1,1,1,1,1,1,1,1,1,1,1,1,1,1,1,1,1,1,1
1,1,1,1,1,1,1,1,1,1,1,1,1,1,1,1,1,1,1,1,1,1,1,1,1,1,1,1,1,1,1,1,1,1,1,1,1,1,1,1,1,1,1,1,1,1,1,1,1,1,1,1,1
1,1,1,1,1,1,1,1,1,1,1,1,1,1,1,1,1,1,1,1,1,1,1,1,1,1,1,1,1,1,1,1,1,1,1,1,1,1,1,1,1,1,1,1,1,1,1,1,1,1,1,1,1
1,1,1,1,1,1,1,1,1,1,1,1,1,1,1,1,1,1,1,1,1,1,1,1,1,1,1,1,1,1,1,1,1,1,1,1,1,1,1,1,1,1,1,1,1,1,1,1,1,1,1,1,1
1,1,1,1,1,1,1,1,1,1,1,1,1,1,1,1,1,1,1,1,1,1,1,1,1,1,1,1,1,1,1,1,1,1,1,1,1,1,1,1,1,1,1,1,1,1,1,1,1,1,1,1,1
1,1,1,1,1,1,1,1,1,1,1,1,1,1,1,1,1,1,1,1,1,1,1,1,1,1,1,1,1,1,1,1,1,1,1,1,1,1,1,1,1,1,1,1,1,1,1,1,1,1,1,1,1
1,1,1,1,1,1,1,1,1,1,1,1,1,1,1,1,1,1,1,1,1,1,1,1,1,1,1,1,1,1,1,1,1,1,1,1,1,1,1,1,1,1,1,1,1,1,1,1,1,1,1,1,1
1,1,1,1,1,1,1,1,1,1,1,1,1,1,1,1,1,1,1,1,1,1,1,1,1,1,1,1,1,1,1,1,1,1,1,1,1,1,1,1,1,1,1,1,1,1,1,1,1,1,1,1,1
1,1,1,1,1,1,1,1,1,1,1,1,1,1,1,1,1,1,1,1,1,1,1,1,1,1,1,1,1,1,1,1,1,1,1,1,1,1,1,1,1,1,1,1,1,1,1,1,1,1,1,1,1
1,1,1,1,1,1,1,1,1,1,1,1,1,1,1,1,1,1,1,1,1,1,1,1,1,1,1,1,1,1,1,1,1,1,1,1,1,1,1,1,1,1,1,1,1,1,1,1,1,1,1,1,1
1,1,1,1,1,1,1,1,1,1,1,1,1,1,1,1,1,1,1,1,1,1,1,1,1,1,1,1,1,1,1,1,1,1,1,1,1,1,1,1,1,1,1,1,1,1,1,1,1,1,1,1,1
1,1,1,1,1,1,1,1,1,1,1,1,1,1,1,1,1,1,1,1,1,1,1,1,1,1,1,1,1,1,1,1,1,1,1,1,1,1,1,1,1,1,1,1,1,1,1,1,1,1,1,1,1
1,1,1,1,1,1,1,1,1,1,1,1,1,1,1,1,1,1,1,1,1,1,1,1,1,1,1,1,1,1,1,1,1,1,1,1,1,1,1,1,1,1,1,1,1,1,1,1,1,1,1,1,1
1,1,1,1,1,1,1,1,1,1,1,1,1,1,1,1,1,1,1,1,1,1,1,1,1,1,1,1,1,1,1,1,1,1,1,1,1,1,1,1,1,1,1,1,1,1,1,1,1,1,1,1,1
1,1,1,1,1,1,1,1,1,1,1,1,1,1,1,1,1,1,1,1,1,1,1,1,1,1,1,1,1,1,1,1,1,1,1,1,1,1,1,1,1,1,1,1,1,1,1,1,1,1,1,1,1
1,1,1,1,1,1,1,1,1,1,1,1,1,1,1,1,1,1,1,1,1,1,1,1,1,1,1,1,1,1,1,1,1,1,1,1,1,1,1,1,1,1,1,1,1,1,1,1,1,1,1,1,1
1,1,1,1,1,1,1,1,1,1,1,1,1,1,1,1,1,1,1,1,1,1,1,1,1,1,1,1,1,1,1,1,1,1,1,1,1,1,1,1,1,1,1,1,1,1,1,1,1,1,1,1,1
1,1,1,1,1,1,1,1,1,1,1,1,1,1,1,1,1,1,1,1,1,1,1,1,1,1,1,1,1,1,1,1,1,1,1,1,1,1,1,1,1,1,1,1,1,1,1,1,1,1,1,1,1
1,1,1,1,1,1,1,1,1,1,1,1,1,1,1,1,1,1,1,1,1,1,1,1,1,1,1,1,1,1,1,1,1,1,1,1,1,1,1,1,1,1,1,1,1,1,1,1,1,1,1,1,1
1,1,1,1,1,1,1,1,1,1,1,1,1,1,1,1,1,1,1,1,1,1,1,1,1,1,1,1,1,1,1,1,1,1,1,1,1,1,1,1,1,1,1,1,1,1,1,1,1,1,1,1,1
1,1,1,1,1,1,1,1,1,1,1,1,1,1,1,1,1,1,1,1,1,1,1,1,1,1,1,1,1,1,1,1,1,1,1,1,1,1,1,1,1,1,1,1,1,1,1,1,1,1,1,1,1
1,1,1,1,1,1,1,1,1,1,1,1,1,1,1,1,1,1,1,1,1,1,1,1,1,1,1,1,1,1,1,1,1,1,1,1,1,1,1,1,1,1,1,1,1,1,1,1,1,1,1,1,1
1,1,1,1,1,1,1,1,1,1,1,1,1,1,1,1,1,1,1,1,1,1,1,1,1,1,1,1,1,1,1,1,1,1,1,1,1,1,1,1,1,1,1,1,1,1,1,1,1,1,1,1,1
1,1,1,1,1,1,1,1,1,1,1,1,1,1,1,1,1,1,1,1,1,1,1,1,1,1,1,1,1,1,1,1,1,1,1,1,1,1,1,1,1,1,1,1,1,1,1,1,1,1,1,1,1
1,1,1,1,1,1,1,1,1,1,1,1,1,1,1,1,1,1,1,1,1,1,1,1,1,1,1,1,1,1,1,1,1,1,1,1,1,1,1,1,1,1,1,1,1,1,1,1,1,1,1,1,1
1,1,1,1,1,1,1,1,1,1,1,1,1,1,1,1,1,1,1,1,1,1,1,1,1,1,1,1,1,1,1,1,1,1,1,1,1,1,1,1,1,1,1,1,1,1,1,1,1,1,1,1,1
1,1,1,1,1,1,1,1,1,1,1,1,1,1,1,1,1,1,1,1,1,1,1,1,1,1,1,1,1,1,1,1,1,1,1,1,1,1,1,1,1,1,1,1,1,1,1,1,1,1,1,1,1
1,1,1,1,1,1,1,1,1,1,1,1,1,1,1,1,1,1,1,1,1,1,1,1,1,1,1,1,1,1,1,1,1,1,1,1,1,1,1,1,1,1,1,1,1,1,1,1,1,1,1,1,1
1,1,1,1,1,1,1,1,1,1,1,1,1,1,1,1,1,1,1,1,1,1,1,1,1,1,1,1,1,1,1,1,1,1,1,1,1,1,1,1,1,1,1,1,1,1,1,1,1,1,1,1,1
1,1,1,1,1,1,1,1,1,1,1,1,1,1,1,1,1,1,1,1,1,1,1,1,1,1,1,1,1,1,1,1,1,1,1,1,1,1,1,1,1,1,1,1,1,1,1,1,1,1,1,1,1
1,1,1,1,1,1,1,1,1,1,1,1,1,1,1,1,1,1,1,1,1,1,1,1,1,1,1,1,1,1,1,1,1,1,1,1,1,1,1,1,1,1,1,1,1,1,1,1,1,1,1,1,1
1,1,1,1,1,1,1,1,1,1,1,1,1,1,1,1,1,1,1,1,1,1,1,1,1,1,1,1,1,1,1,1,1,1,1,1,1,1,1,1,1,1,1,1,1,1,1,1,1,1,1,1,1
1,1,1,1,1,1,1,1,1,1,1,1,1,1,1,1,1,1,1,1,1,1,1,1,1,1,1,1,1,1,1,1,1,1,1,1,1,1,1,1,1,1,1,1,1,1,1,1,1,1,1,1,1
1,1,1,1,1,1,1,1,1,1,1,1,1,1,1,1,1,1,1,1,1,1,1,1,1,1,1,1,1,1,1,1,1,1,1,1,1,1,1,1,1,1,1,1,1,1,1,1,1,1,1,1,1
1,1,1,1,1,1,1,1,1,1,1,1,1,1,1,1,1,1,1,1,1,1,1,1,1,1,1,1,1,1,1,1,1,1,1,1,1,1,1,1,1,1,1,1,1,1,1,1,1,1,1,1,1
1,1,1,1,1,1,1,1,1,1,1,1,1,1,1,1,1,1,1,1,1,1,1,1,1,1,1,1,1,1,1,1,1,1,1,1,1,1,1,1,1,1,1,1,1,1,1,1,1,1,1,1,1
1,1,1,1,1,1,1,1,1,1,1,1,1,1,1,1,1,1,1,1,1,1,1,1,1,1,1,1,1,1,1,1,1,1,1,1,1,1,1,1,1,1,1,1,1,1,1,1,1,1,1,1,1
1,1,1,1,1,1,1,1,1,1,1,1,1,1,1,1,1,1,1,1,1,1,1,1,1,1,1,1,1,1,1,1,1,1,1,1,1,1,1,1,1,1,1,1,1,1,1,1,1,1,1,1,1
1,1,1,1,1,1,1,1,1,1,1,1,1,1,1,1,1,1,1,1,1,1,1,1,1,1,1,1,1,1,1,1,1,1,1,1,1,1,1,1,1,1,1,1,1,1,1,1,1,1,1,1,1
1,1,1,1,1,1,1,1,1,1,1,1,1,1,1,1,1,1,1,1,1,1,1,1,1,1,1,1,1,1,1,1,1,1,1,1,1,1,1,1,1,1,1,1,1,1,1,1,1,1,1,1,1
:endlayer
layer: 3
2,2,2,2,2,2,2,2,2,2,2,2,2,2,2,2,2,2,2,2,2,2,2,2,2,2,2,2,2,2,2,2,2,2,2,2,2,2,2,2,2,2,2,2,2,2,2,2,2,2,2,2,2
2,2,2,2,2,2,2,2,2,2,2,2,2,2,2,2,2,2,2,2,2,2,2,2,2,2,2,2,2,2,2,2,2,2,2,2,2,2,2,2,2,2,2,2,2,2,2,2,2,2,2,2,2
2,1,2,2,1,2,2,1,2,2,1,2,2,1,2,2,1,2,2,1,2,2,1,1,1,1,1,1,1,1,1,2,2,1,2,2,1,2,2,1,2,2,1,2,2,1,2,2,1,2,2,1,2
2,2,2,2,2,2,2,2,2,2,2,2,2,2,2,2,2,2,2,2,2,2,1,2,2,2,2,2,2,2,1,2,2,2,2,2,2,2,2,2,2,2,2,2,2,2,2,2,2,2,2,2,2
2,2,2,2,2,2,2,2,2,2,2,2,2,2,2,2,2,2,2,2,2,2,1,2,2,2,2,2,2,2,1,2,2,2,2,2,2,2,2,2,2,2,2,2,2,2,2,2,2,2,2,2,2
2,1,1,1,1,1,1,1,1,1,1,1,1,1,1,1,1,1,1,1,1,1,1,2,2,2,2,2,2,2,1,1,1,1,1,1,1,1,1,1,1,1,1,1,1,1,1,1,1,1,1,1,2
2,1,2,2,2,2,2,2,2,2,2,2,2,2,2,2,2,2,2,2,2,2,2,2,2,2,2,2,2,2,2,2,2,2,2,2,2,2,2,2,2,2,2,2,2,2,2,2,2,2,2,1,2
2,1,2,2,2,2,2,2,2,2,2,2,2,2,2,2,2,2,2,2,2,2,2,2,2,2,2,2,2,2,2,2,2,2,2,2,2,2,2,2,2,2,2,2,2,2,2,2,2,2,2,1,2
2,1,2,2,2,2,2,2,2,2,2,2,2,2,2,2,2,2,2,2,2,2,2,2,2,2,2,2,2,2,2,2,2,2,2,2,2,2,2,2,2,2,2,2,2,2,2,2,2,2,2,1,2
2,1,2,2,2,2,2,2,2,2,2,2,2,2,2,2,2,2,2,2,2,2,2,2,2,2,2,2,2,2,2,2,2,2,2,2,2,2,2,2,2,2,2,2,2,2,2,2,2,2,2,1,2
2,1,1,1,1,1,1,1,1,1,1,1,2,2,2,2,2,2,2,2,2,2,2,2,2,2,2,2,2,2,2,2,2,2,2,2,2,2,2,2,2,1,1,1,1,1,1,1,1,1,1,1,2
2,2,2,1,2,1,2,2,2,2,2,1,1,1,1,1,1,1,1,1,1,1,1,1,1,1,1,1,1,1,1,1,1,1,1,1,1,1,1,1,1,1,2,2,2,2,2,1,2,1,2,2,2
2,2,2,2,2,1,2,2,2,2,2,1,2,2,2,2,2,2,2,2,2,2,2,2,2,2,2,2,2,2,2,2,2,2,2,2,2,2,2,2,2,1,2,2,2,2,2,1,2,2,2,2,2
2,2,2,2,2,1,2,2,2,2,2,1,2,2,2,2,2,2,2,2,2,2,2,2,2,2,2,2,2,2,2,2,2,2,2,2,2,2,2,2,2,1,2,2,2,2,2,1,2,2,2,2,2
2,2,2,1,2,1,2,2,2,2,2,1,2,2,2,2,2,2,2,2,2,2,2,2,2,2,2,2,2,2,2,2,2,2,2,2,2,2,2,2,2,1,2,2,2,2,2,1,2,1,2,2,2
2,2,2,2,2,1,2,2,2,2,2,1,2,2,2,2,2,2,2,2,2,2,2,2,2,2,2,2,2,2,2,2,2,2,2,2,2,2,2,2,2,1,2,2,2,2,2,1,2,2,2,2,2
2,2,2,2,2,1,2,2,2,1,1,1,2,2,2,2,2,2,2,2,2,2,2,2,2,2,2,2,2,2,2,2,2,2,2,2,2,2,2,2,2,1,1,1,2,2,2,1,2,2,2,2,2
2,2,2,1,2,1,2,2,2,1,2,2,2,2,2,2,2,2,2,2,2,2,2,2,2,2,2,2,2,2,2,2,2,2,2,2,2,2,2,2,2,2,2,1,2,2,2,1,2,1,2,2,2
2,2,2,2,2,1,2,2,2,1,2,2,2,2,2,2,2,2,2,2,2,2,2,2,2,2,2,2,2,2,2,2,2,2,2,2,2,2,2,2,2,2,2,1,2,2,2,1,2,2,2,2,2
2,2,2,2,2,1,2,2,2,1,2,2,2,2,2,2,2,2,2,2,2,2,2,2,2,2,2,2,2,2,2,2,2,2,2,2,2,2,2,2,2,2,2,1,2,2,2,1,2,2,2,2,2
2,2,2,1,2,1,2,2,2,1,2,2,2,2,2,2,2,2,2,2,2,2,2,2,2,2,2,2,2,2,2,2,2,2,2,2,2,2,2,2,2,2,2,1,2,2,2,1,2,1,2,2,2
2,2,2,2,2,1,2,2,2,1,2,2,2,2,2,2,2,2,2,2,2,2,2,2,2,2,2,2,2,2,2,2,2,2,2,2,2,2,2,2,2,2,2,1,2,2,2,1,2,2,2,2,2
2,2,2,2,2,1,2,2,2,1,1,1,2,2,2,2,2,2,2,2,2,2,2,2,2,2,2,2,2,2,2,2,2,2,2,2,2,2,2,2,2,1,1,1,2,2,2,1,2,2,2,2,2
2,2,2,1,2,1,2,2,2,2,2,1,2,2,2,2,2,2,2,2,2,2,2,2,2,2,2,2,2,2,2,2,2,2,2,2,2,2,2,2,2,1,2,2,2,2,2,1,2,1,2,2,2
2,2,2,2,2,1,2,2,2,2,2,1,2,2,2,2,2,2,2,2,2,2,2,2,2,2,2,2,2,2,2,2,2,2,2,2,2,2,2,2,2,1,2,2,2,2,2,1,2,2,2,2,2
2,2,2,2,2,1,2,2,2,2,2,1,2,2,2,2,2,2,2,2,2,2,2,2,2,2,2,2,2,2,2,2,2,2,2,2,2,2,2,2,2,1,2,2,2,2,2,1,2,2,2,2,2
2,2,2,1,2,1,2,2,2,2,2,1,2,2,2,2,2,2,2,2,2,2,2,2,2,2,2,2,2,2,2,2,2,2,2,2,2,2,2,2,2,1,2,2,2,2,2,1,2,1,2,2,2
2,2,2,2,2,1,2,2,2,2,2,1,2,2,2,2,2,2,2,2,2,2,2,2,2,2,2,2,2,2,2,2,2,2,2,2,2,2,2,2,2,1,2,2,2,2,2,1,2,2,2,2,2
2,2,2,2,2,1,2,2,2,2,2,1,2,2,2,2,2,2,2,2,2,2,2,2,2,2,2,2,2,2,2,2,2,2,2,2,2,2,2,2,2,1,2,2,2,2,2,1,2,2,2,2,2
2,2,2,1,2,1,2,2,2,2,2,1,2,2,2,2,2,2,2,2,2,2,2,2,2,2,2,2,2,2,2,2,2,2,2,2,2,2,2,2,2,1,2,2,2,2,2,1,2,1,2,2,2
2,2,2,2,2,1,2,2,2,2,2,1,1,1,1,1,2,2,2,2,2,2,2,2,2,2,2,2,2,2,2,2,2,2,2,2,2,1,1,1,1,1,2,2,2,2,2,1,2,2,2,2,2
2,2,2,2,2,1,2,2,2,2,2,2,2,2,2,1,2,2,2,2,2,2,2,2,2,2,2,2,2,2,2,2,2,2,2,2,2,1,2,2,2,2,2,2,2,2,2,1,2,2,2,2,2
2,2,2,1,2,1,2,2,2,2,2,2,2,2,2,1,2,2,2,2,2,2,2,2,2,2,2,2,2,2,2,2,2,2,2,2,2,1,2,2,2,2,2,2,2,2,2,1,2,1,2,2,2
2,2,2,2,2,1,2,2,2,2,2,2,2,2,2,1,2,2,2,2,2,2,2,2,2,2,2,2,2,2,2,2,2,2,2,2,2,1,2,2,2,2,2,2,2,2,2,1,2,2,2,2,2
2,2,2,2,2,1,2,2,2,2,2,2,2,2,2,1,1,1,1,1,1,1,1,1,1,1,1,1,1,1,1,1,1,1,1,1,1,1,2,2,2,2,2,2,2,2,2,1,2,2,2,2,2
2,2,2,1,2,1,2,2,2,2,2,2,2,2,2,2,2,2,2,2,2,2,2,2,2,2,2,2,2,2,2,2,2,2,2,2,2,2,2,2,2,2,2,2,2,2,2,1,2,1,2,2,2
2,2,2,2,2,1,2,2,2,2,2,2,2,2,2,2,2,2,2,2,2,2,2,2,2,2,2,2,2,2,2,2,2,2,2,2,2,2,2,2,2,2,2,2,2,2,2,1,2,2,2,2,2
2,2,2,2,2,1,2,2,2,2,2,2,2,2,2,2,2,2,2,2,2,2,2,2,2,2,2,2,2,2,2,2,2,2,2,2,2,2,2,2,2,2,2,2,2,2,2,1,2,2,2,2,2
2,2,2,1,2,1,2,2,2,2,2,2,2,2,2,2,2,2,2,2,2,2,2,2,2,2,2,2,2,2,2,2,2,2,2,2,2,2,2,2,2,2,2,2,2,2,2,1,2,1,2,2,2
2,2,1,1,1,1,1,2,2,2,2,2,2,2,2,2,2,2,2,2,2,2,2,2,2,2,2,2,2,2,2,2,2,2,2,2,2,2,2,2,2,2,2,2,2,2,1,1,1,1,1,2,2
2,2,1,2,2,2,1,2,2,2,2,2,2,2,2,2,2,2,2,2,2,2,2,2,2,2,2,2,2,2,2,2,2,2,2,2,2,2,2,2,2,2,2,2,2,2,1,2,2,2,1,2,2
2,2,1,2,2,2,1,2,2,2,2,2,2,2,2,2,2,2,2,2,1,2,2,2,1,2,2,2,1,2,2,2,1,2,2,2,2,2,2,2,2,2,2,2,2,2,1,2,2,2,1,2,2
2,2,1,2,2,2,1,1,1,1,1,1,1,1,1,1,1,1,1,1,1,2,2,2,2,2,2,2,2,2,2,2,1,1,1,1,1,1,1,1,1,1,1,1,1,1,1,2,2,2,1,2,2
2,2,1,1,1,1,1,1,1,2,2,2,2,2,2,2,2,2,2,2,1,2,2,2,2,2,2,2,2,2,2,2,1,2,2,2,2,2,2,2,2,2,2,2,1,1,1,1,1,1,1,2,2
2,2,1,2,1,1,2,2,1,2,2,1,2,2,1,2,2,1,2,2,1,2,2,2,2,2,2,2,2,2,2,2,1,2,2,1,2,2,1,2,2,1,2,2,1,2,2,1,1,2,1,2,2
2,2,1,1,1,2,2,2,2,2,2,2,2,2,2,2,2,2,2,2,1,2,2,2,1,2,2,2,1,2,2,2,1,2,2,2,2,2,2,2,2,2,2,2,2,2,2,2,1,1,1,2,2
2,2,2,2,2,2,2,2,2,2,2,2,2,2,2,2,2,2,2,2,2,2,2,2,2,2,2,2,2,2,2,2,2,2,2,2,2,2,2,2,2,2,2,2,2,2,2,2,2,2,2,2,2
2,2,2,2,2,2,2,2,2,2,2,2,2,2,2,2,2,2,2,2,2,2,2,2,2,2,2,2,2,2,2,2,2,2,2,2,2,2,2,2,2,2,2,2,2,2,2,2,2,2,2,2,2
:endlayer
layer: 4
2,2,2,2,2,2,2,2,2,2,2,2,2,2,2,2,2,2,2,2,2,2,2,2,2,2,2,2,2,2,2,2,2,2,2,2,2,2,2,2,2,2,2,2,2,2,2,2,2,2,2,2,2
2,2,2,2,2,2,2,2,2,2,2,2,2,2,2,2,2,2,2,2,2,2,2,2,2,2,2,2,2,2,2,2,2,2,2,2,2,2,2,2,2,2,2,2,2,2,2,2,2,2,2,2,2
2,1,2,2,1,2,2,1,2,2,1,2,2,1,2,2,1,2,2,1,2,2,1,1,1,1,1,1,1,1,1,2,2,1,2,2,1,2,2,1,2,2,1,2,2,1,2,2,1,2,2,1,2
2,2,2,2,2,2,2,2,2,2,2,2,2,2,2,2,2,2,2,2,2,2,1,2,2,2,2,2,2,2,1,2,2,2,2,2,2,2,2,2,2,2,2,2,2,2,2,2,2,2,2,2,2
2,2,2,2,2,2,2,2,2,2,2,2,2,2,2,2,2,2,2,2,2,2,1,2,2,2,2,2,2,2,1,2,2,2,2,2,2,2,2,2,2,2,2,2,2,2,2,2,2,2,2,2,2
2,1,1,1,1,1,1,1,1,1,1,1,1,1,1,1,1,1,1,1,1,1,1,2,2,2,2,2,2,2,1,1,1,1,1,1,1,1,1,1,1,1,1,1,1,1,1,1,1,1,1,1,2
2,1,2,2,2,2,2,2,2,2,2,2,2,2,2,2,2,2,2,2,2,2,2,2,2,2,2,2,2,2,2,2,2,2,2,2,2,2,2,2,2,2,2,2,2,2,2,2,2,2,2,1,2
2,1,2,2,2,2,2,2,2,2,2,2,2,2,2,2,2,2,2,2,2,2,2,2,2,2,2,2,2,2,2,2,2,2,2,2,2,2,2,2,2,2,2,2,2,2,2,2,2,2,2,1,2
2,1,2,2,2,2,2,2,2,2,2,2,2,2,2,2,2,2,2,2,2,2,2,2,2,2,2,2,2,2,2,2,2,2,2,2,2,2,2,2,2,2,2,2,2,2,2,2,2,2,2,1,2
2,1,2,2,2,2,2,2,2,1,2,2,2,2,2,2,2,2,2,2,2,2,2,2,2,2,2,2,2,2,2,2,2,2,2,2,2,2,2,2,2,2,2,1,2,2,2,2,2,2,2,1,2
2,1,1,1,1,1,1,1,1,1,1,1,2,2,2,2,2,2,2,2,2,2,2,2,2,2,2,2,2,2,2,2,2,2,2,2,2,2,2,2,2,1,1,1,1,1,1,1,1,1,1,1,2
2,2,2,1,2,1,2,2,2,1,2,1,1,1,1,1,1,1,1,1,1,1,1,1,1,1,1,1,1,1,1,1,1,1,1,1,1,1,1,1,1,1,2,1,2,2,2,1,2,1,2,2,2
2,2,2,2,2,1,7,7,7,6,8,1,8,8,8,8,8,8,8,8,8,8,8,8,8,8,8,8,8,8,8,8,8,8,8,8,8,8,8,8,8,1,8,6,7,7,7,1,2,2,2,2,2
2,2,2,2,2,1,6,6,6,6,5,1,8,8,8,8,8,8,8,8,8,8,8,8,8,8,8,8,8,8,8,8,8,8,8,8,8,8,8,8,8,1,5,6,6,6,6,1,2,2,2,2,2
2,2,2,1,2,1,7,6,7,7,5,1,8,8,8,8,8,8,8,8,8,8,8,8,8,8,8,8,8,8,8,8,8,8,8,8,8,8,8,8,8,1,5,7,7,6,7,1,2,1,2,2,2
2,2,2,2,2,1,7,6,7,7,8,1,8,8,8,8,8,8,8,8,8,8,8,8,8,8,8,8,8,8,8,8,8,8,8,8,8,8,8,8,8,1,8,7,7,6,7,1,2,2,2,2,2
2,2,2,2,2,1,7,6,7,1,1,1,8,8,8,8,8,8,8,8,8,8,8,8,8,8,8,8,8,8,8,8,8,8,8,8,8,8,8,8,8,1,1,1,7,6,7,1,2,2,2,2,2
2,2,2,1,2,1,7,6,7,1,8,8,8,8,8,8,8,8,8,8,8,8,8,8,8,8,8,8,8,8,8,8,8,8,8,8,8,8,8,8,8,8,8,1,7,6,7,1,2,1,2,2,2
2,2,2,2,2,1,7,6,7,1,8,8,8,8,8,8,8,8,8,8,8,8,8,8,8,8,8,8,8,8,8,8,8,8,8,8,8,8,8,8,8,8,8,1,7,6,7,1,2,2,2,2,2
2,2,2,2,2,1,7,6,7,1,8,8,8,8,8,8,8,8,8,8,8,8,8,8,8,8,8,8,8,8,8,8,8,8,8,8,8,8,8,8,8,8,8,1,7,6,7,1,2,2,2,2,2
2,2,2,1,2,1,7,6,7,1,8,8,8,8,8,8,8,8,8,8,8,8,8,8,8,8,8,8,8,8,8,8,8,8,8,8,8,8,8,8,8,8,8,1,7,6,7,1,2,1,2,2,2
2,2,2,2,2,1,7,6,7,1,8,8,8,8,8,8,8,8,8,8,8,8,8,8,8,8,8,8,8,8,8,8,8,8,8,8,8,8,8,8,8,8,8,1,7,6,7,1,2,2,2,2,2
2,2,2,2,2,1,7,6,7,1,1,1,8,8,8,8,8,8,8,8,8,8,8,8,8,8,8,8,8,8,8,8,8,8,8,8,8,8,8,8,8,1,1,1,7,6,7,1,2,2,2,2,2
2,2,2,1,2,1,7,6,7,7,7,1,8,8,8,8,8,8,8,8,8,8,8,8,8,8,8,8,8,8,8,8,8,8,8,8,8,8,8,8,8,1,7,7,7,6,7,1,2,1,2,2,2
2,2,2,2,2,1,7,6,7,7,7,1,8,8,8,8,8,8,8,8,8,8,8,8,8,8,8,8,8,8,8,8,8,8,8,8,8,8,8,8,8,1,7,7,7,6,7,1,2,2,2,2,2
2,2,2,2,2,1,7,6,7,7,7,1,8,8,8,8,8,8,8,8,8,8,8,8,8,8,8,8,8,8,8,8,8,8,8,8,8,8,8,8,8,1,7,7,7,6,7,1,2,2,2,2,2
2,2,2,1,2,1,7,6,7,7,7,1,8,8,8,8,8,8,8,8,8,8,8,8,8,8,8,8,8,8,8,8,8,8,8,8,8,8,8,8,8,1,7,7,7,6,7,1,2,1,2,2,2
2,2,2,2,2,1,7,6,7,7,7,1,8,8,8,8,8,8,8,8,8,8,8,8,8,8,8,8,8,8,8,8,8,8,8,8,8,8,8,8,8,1,7,7,7,6,7,1,2,2,2,2,2
2,2,2,2,2,1,7,6,7,7,7,1,8,8,8,8,8,8,8,8,8,8,8,8,8,8,8,8,8,8,8,8,8,8,8,8,8,8,8,8,8,1,7,7,7,6,7,1,2,2,2,2,2
2,2,2,1,2,1,7,6,7,7,7,1,8,8,8,8,8,8,8,8,8,8,8,8,8,8,8,8,8,8,8,8,8,8,8,8,8,8,8,8,8,1,7,7,7,6,7,1,2,1,2,2,2
2,2,2,2,2,1,7,6,7,7,7,1,1,1,1,1,8,8,8,8,8,8,8,8,8,8,8,8,8,8,8,8,8,8,8,8,8,1,1,1,1,1,7,7,7,6,7,1,2,2,2,2,2
2,2,2,2,2,1,7,6,7,7,7,7,7,7,7,1,8,8,8,8,8,8,7,7,7,7,7,7,7,7,7,8,8,8,8,8,8,1,7,7,7,7,7,7,7,6,7,1,2,2,2,2,2
2,2,2,1,2,1,7,6,7,7,7,7,7,7,7,1,8,8,8,8,8,8,7,4,9,4,3,4,9,4,7,8,8,8,8,8,8,1,7,7,7,7,7,7,7,6,7,1,2,1,2,2,2
2,2,2,2,2,1,7,6,7,7,7,7,7,7,7,1,8,8,8,8,8,8,7,3,4,9,4,9,4,3,7,8,8,8,8,8,8,1,7,7,7,7,8,7,7,6,7,1,2,2,2,2,2
2,2,2,2,2,1,7,6,7,7,7,7,7,7,7,1,1,1,1,1,1,1,1,3,3,4,9,4,3,3,1,1,1,1,1,1,1,1,7,7,7,7,7,7,7,6,7,1,2,2,2,2,2
2,2,2,1,2,1,7,6,7,7,7,7,8,7,7,7,7,7,7,7,7,8,7,3,4,3,4,3,4,3,7,8,7,7,7,7,7,7,7,7,7,7,7,7,7,6,7,1,2,1,2,2,2
2,2,2,2,2,1,7,6,7,7,7,7,7,7,7,7,7,7,7,7,7,7,7,3,3,4,9,4,3,3,7,7,7,7,7,7,7,7,7,7,7,7,7,7,7,6,7,1,2,2,2,2,2
2,2,2,2,2,1,7,6,7,7,7,7,7,7,7,7,7,7,7,7,7,7,7,3,4,9,4,9,4,3,7,7,7,7,7,7,7,7,7,7,7,7,7,7,7,6,7,1,2,2,2,2,2
2,2,2,1,2,1,7,6,7,7,7,7,7,7,7,7,7,8,7,7,7,7,7,7,3,4,9,4,3,7,7,7,7,7,8,7,7,7,7,7,7,7,8,7,7,6,7,1,2,1,2,2,2
2,2,1,1,1,1,1,6,7,7,7,7,7,7,7,7,7,7,7,7,7,7,7,7,3,3,4,3,3,7,7,7,7,7,7,7,7,7,7,7,7,7,7,7,7,6,1,1,1,1,1,2,2
2,2,1,1,1,1,1,6,6,6,6,6,6,6,6,6,6,6,6,6,6,6,6,6,3,3,3,3,3,6,6,6,6,6,6,6,6,6,6,6,6,6,6,6,6,6,1,2,1,1,1,2,2
2,2,1,1,1,2,1,6,7,7,7,7,7,7,7,7,7,7,7,7,1,1,1,1,1,3,4,3,1,1,1,1,1,7,7,7,7,7,7,7,7,7,7,7,7,6,1,2,1,2,1,2,2
2,2,1,1,1,2,1,5,1,1,1,1,1,1,1,1,1,1,1,1,1,1,1,1,1,3,3,3,1,1,1,1,1,1,1,1,1,1,1,1,1,1,1,1,1,5,1,1,1,2,1,2,2
2,2,1,1,1,1,1,1,1,2,2,2,2,2,2,2,2,2,2,2,1,1,1,1,1,3,4,3,1,1,1,1,1,2,2,2,2,2,2,2,2,2,2,2,1,1,1,1,1,1,1,2,2
2,2,1,2,1,1,2,2,1,2,2,1,2,2,1,2,2,1,2,2,1,1,1,1,1,3,3,3,1,1,1,1,1,2,2,1,2,2,1,2,2,1,2,2,1,2,2,1,1,2,1,2,2
2,2,1,1,1,2,2,2,2,2,2,2,2,2,2,2,2,2,2,2,1,1,1,1,1,3,4,3,1,1,1,1,1,2,2,2,2,2,2,2,2,2,2,2,2,2,2,2,1,1,1,2,2
2,2,2,2,2,2,2,2,2,2,2,2,2,2,2,2,2,2,2,2,2,2,2,2,2,3,3,3,2,2,2,2,2,2,2,2,2,2,2,2,2,2,2,2,2,2,2,2,2,2,2,2,2
2,2,2,2,2,2,2,2,2,2,2,2,2,2,2,2,2,2,2,2,2,2,2,2,2,3,3,3,2,2,2,2,2,2,2,2,2,2,2,2,2,2,2,2,2,2,2,2,2,2,2,2,2
:endlayer
layer: 5
0,0,0,0,0,0,0,0,0,0,0,0,0,0,0,0,0,0,0,0,0,0,0,0,0,0,0,0,0,0,0,0,0,0,0,0,0,0,0,0,0,0,0,0,0,0,0,0,0,0,0,0,0
86,0,0,0,0,0,0,0,0,0,0,0,0,0,0,0,0,0,0,0,0,0,0,0,85,56,56,56,85,0,0,0,0,0,0,0,0,0,0,0,0,0,0,0,0,0,0,0,0,0,0,0,84
0,17,0,0,17,0,0,17,0,83,17,0,0,17,0,0,17,0,0,17,0,0,17,1,1,46,46,46,1,1,17,0,0,17,0,0,17,0,0,17,0,82,17,0,0,17,0,0,17,0,0,17,0
0,0,0,0,0,0,0,0,0,0,0,0,0,0,0,0,0,0,0,0,0,0,1,1,1,1,1,1,1,1,1,0,0,0,0,0,0,0,0,0,0,0,0,0,0,0,0,0,0,0,0,0,0
0,0,0,0,0,0,0,0,0,0,0,0,0,0,0,0,0,0,0,0,0,0,1,1,1,1,1,1,1,1,1,0,0,0,0,0,0,0,0,0,0,0,0,0,0,0,0,0,0,0,0,0,0
0,17,1,1,1,1,1,1,1,1,1,1,1,1,1,1,1,1,1,1,1,1,1,1,1,1,1,1,1,1,1,1,1,1,1,1,1,1,1,1,1,1,1,1,1,1,1,1,1,1,1,17,0
0,1,1,1,1,1,1,1,1,1,1,1,1,1,1,1,1,1,1,1,1,1,1,1,1,1,1,1,1,1,1,1,1,1,1,1,1,1,1,1,1,1,1,1,1,1,1,1,1,1,1,1,0
0,1,1,1,1,1,1,1,1,1,1,1,1,1,1,1,1,1,1,1,1,1,1,1,1,1,1,1,1,1,1,1,1,1,1,1,1,1,1,1,1,1,1,1,1,1,1,1,1,1,1,1,0
0,1,1,1,1,1,1,1,16,16,16,1,1,1,1,1,1,1,1,1,1,1,1,1,1,1,1,1,1,1,1,1,1,1,1,1,1,1,1,1,1,1,16,16,16,1,1,1,1,1,1,1,0
0,1,1,1,1,1,1,1,20,0,22,1,1,1,1,1,1,1,1,1,1,1,1,1,1,1,1,1,1,1,1,1,1,1,1,1,1,1,1,1,1,1,20,0,22,1,1,1,1,1,1,1,0
0,17,1,1,1,1,1,1,1,0,1,17,1,1,1,1,1,1,1,1,1,1,1,1,1,1,1,1,1,1,1,1,1,1,1,1,1,1,1,1,1,17,1,0,1,1,1,1,1,1,1,17,0
0,0,0,17,0,1,1,1,1,81,1,1,4,4,4,4,4,4,4,4,4,4,4,4,4,4,4,4,4,4,4,4,4,4,4,4,4,4,4,4,4,1,1,81,1,1,1,1,0,17,0,0,0
0,0,0,0,0,1,79,0,29,0,1,1,4,4,4,4,4,4,4,4,4,4,4,4,4,4,4,4,4,4,4,4,4,4,4,4,4,4,4,4,4,1,1,0,80,29,79,1,0,0,0,0,0
0,0,0,0,0,1,0,0,0,0,78,1,55,55,55,55,55,55,55,55,1,4,4,1,4,4,4,4,4,1,4,4,1,55,55,55,55,55,55,55,55,1,77,0,0,0,0,1,0,0,0,0,0
0,0,0,17,0,1,0,0,29,29,76,1,3,3,3,3,3,3,3,3,55,4,4,1,1,1,1,1,1,1,4,4,55,3,3,3,3,3,3,3,3,1,75,0,0,0,29,1,0,17,0,0,0
0,0,0,0,0,1,74,0,29,0,1,1,3,62,62,62,62,62,62,3,55,4,4,4,1,1,1,1,1,4,4,4,55,3,62,62,62,62,62,62,3,1,1,29,29,0,67,1,0,0,0,0,0
0,0,0,0,0,1,0,0,0,17,1,17,3,62,62,62,62,62,62,3,55,4,4,4,1,1,1,1,1,4,4,4,55,3,62,62,62,62,62,62,3,17,1,17,29,0,0,1,0,0,0,0,0
0,73,0,17,0,1,72,0,45,1,3,3,3,62,62,62,62,62,62,3,1,4,4,1,1,1,1,1,1,1,4,4,1,3,62,62,62,62,62,62,3,3,3,1,45,0,0,1,0,17,0,0,0
0,0,0,0,0,1,0,0,44,46,3,62,62,62,62,62,62,62,62,3,55,4,4,4,1,1,1,1,1,4,4,4,55,3,62,62,62,62,62,62,62,62,3,46,29,0,0,1,0,0,71,0,0
0,0,0,0,0,1,0,0,29,46,3,62,62,62,62,62,62,62,62,3,55,4,4,4,1,1,1,1,1,4,4,4,55,3,62,62,62,62,62,62,62,62,3,46,44,0,29,1,0,0,0,0,0
0,0,0,17,0,1,0,0,70,46,3,62,62,62,62,62,62,62,62,3,55,4,4,4,1,1,1,1,1,4,4,4,55,3,62,62,62,62,62,62,62,62,3,46,69,0,29,1,0,17,0,0,0
0,0,0,0,0,1,0,0,45,1,3,3,3,62,62,62,62,62,62,3,1,55,55,55,55,61,61,61,55,55,55,55,1,3,62,62,62,62,62,62,3,3,3,1,45,0,68,1,0,0,0,0,0
0,0,0,0,0,1,0,0,0,17,1,17,3,62,62,62,62,62,62,3,55,4,9,4,55,61,61,61,55,4,9,4,55,3,62,62,62,62,62,62,3,17,1,17,29,0,0,1,0,0,0,0,0
0,0,0,17,0,1,0,0,0,0,45,1,3,62,62,62,62,62,62,3,55,9,65,9,55,61,61,61,55,9,65,9,55,3,62,62,62,62,62,62,3,1,45,29,29,0,0,1,0,17,0,0,0
0,0,0,0,0,1,29,0,0,0,0,46,3,62,62,62,62,62,62,3,55,4,9,4,55,61,61,61,55,4,9,4,55,3,62,62,62,62,62,62,3,46,0,0,67,0,29,1,0,0,0,0,0
0,0,0,0,0,1,29,0,0,0,0,46,3,62,62,62,62,62,62,3,1,55,55,55,55,61,61,61,55,55,55,55,1,3,62,62,62,62,62,62,3,46,29,29,0,0,44,1,0,0,0,0,0
0,0,0,17,0,1,0,0,0,66,45,1,3,62,62,62,62,62,62,3,55,4,9,4,55,61,61,61,55,4,9,4,55,3,62,62,62,62,62,62,3,1,45,0,0,0,29,1,0,17,0,0,0
0,0,0,0,0,1,0,0,0,0,0,46,3,62,62,62,62,62,62,3,55,9,65,9,55,61,61,61,55,9,65,9,55,3,62,62,62,62,62,62,3,46,0,29,64,0,29,1,0,0,0,0,0
0,0,0,0,0,1,0,0,63,29,0,46,3,62,62,62,62,62,62,3,55,4,9,4,55,61,61,61,55,4,9,4,55,3,62,62,62,62,62,62,3,46,29,29,29,0,0,1,0,0,0,0,0
0,0,0,17,0,1,0,0,0,40,45,1,3,3,3,3,3,3,3,3,1,55,55,55,55,61,61,61,55,55,55,55,1,3,3,3,3,3,3,3,3,1,45,29,29,0,0,1,0,17,0,0,0
0,0,0,0,0,1,60,0,29,29,29,17,1,46,1,17,4,4,4,4,55,17,17,17,17,17,17,17,17,17,17,17,55,4,4,4,4,17,1,46,1,17,29,29,0,0,0,1,0,0,0,0,0
0,0,0,0,0,1,0,0,29,29,29,29,45,0,45,1,4,4,4,4,55,17,56,56,56,56,56,56,56,56,56,17,55,4,4,4,4,1,45,0,45,0,29,29,59,0,0,1,0,0,0,0,0
0,0,0,17,0,1,0,0,0,29,29,29,29,0,0,46,4,4,4,4,55,17,56,0,0,0,58,0,0,0,56,17,55,4,4,4,4,46,0,29,40,0,29,0,43,0,29,1,0,17,0,0,0
0,0,0,0,0,1,29,0,0,57,29,0,0,29,45,1,4,4,4,4,55,17,56,0,0,0,0,0,0,0,56,17,55,4,4,4,4,1,45,29,29,29,33,0,29,0,44,1,0,0,0,0,0
0,54,0,0,0,1,40,0,0,29,29,0,29,0,0,17,1,46,46,46,1,1,1,53,52,51,50,49,48,47,1,1,1,46,46,46,1,17,0,29,43,29,29,0,0,0,29,1,0,0,0,0,0
0,0,0,17,0,1,29,0,29,0,0,29,33,0,29,44,45,29,0,0,45,5,45,0,0,0,0,0,0,0,45,5,45,0,29,0,45,40,40,29,29,29,0,0,0,0,0,1,0,17,0,0,0
0,0,0,0,0,1,0,0,29,29,0,29,0,29,29,29,29,29,29,29,29,29,0,0,0,0,0,0,0,0,0,0,29,29,44,0,29,0,29,29,29,29,40,43,0,0,42,1,0,0,0,41,0
0,0,0,0,0,1,0,0,40,29,29,39,0,0,29,29,29,29,0,0,29,29,38,0,0,0,0,0,0,0,37,29,29,29,29,0,29,0,29,29,36,0,0,0,0,0,0,1,0,0,0,0,0
0,0,0,17,0,1,0,0,29,29,29,0,0,0,29,29,29,33,0,29,29,29,35,0,0,0,34,0,0,0,29,29,29,29,33,29,29,0,0,29,29,29,33,0,0,0,0,1,0,17,0,0,0
0,0,1,1,1,1,1,0,29,0,29,0,29,0,29,29,29,0,0,0,29,0,29,0,0,0,0,0,0,0,0,0,0,29,0,0,0,29,0,29,29,0,0,0,0,0,1,1,1,1,1,0,0
0,0,1,0,0,0,32,0,0,0,0,0,0,0,0,0,0,0,0,0,0,0,0,0,0,0,0,0,0,0,0,0,0,0,0,0,0,0,0,0,0,0,0,0,0,0,31,0,0,0,1,0,0
0,0,1,0,0,30,1,0,0,0,0,0,0,29,29,29,29,0,0,0,17,0,0,0,17,0,0,0,17,0,0,0,17,0,0,29,29,29,0,0,0,0,0,28,0,0,1,27,0,0,1,0,0
0,0,1,0,0,0,1,26,1,1,1,1,1,1,1,1,1,1,1,1,1,0,0,0,0,0,0,0,0,0,0,0,1,1,1,1,1,1,1,1,1,1,1,1,1,25,1,0,0,0,1,0,0
0,0,1,1,1,1,1,1,1,0,0,0,0,0,0,0,0,0,0,0,1,0,24,0,0,0,0,0,0,0,23,0,1,0,0,0,0,0,0,0,0,0,0,0,1,1,1,1,1,1,1,0,0
0,0,22,1,1,17,21,21,17,0,0,17,0,0,17,0,0,17,0,0,1,0,0,0,0,0,0,0,0,0,0,0,1,0,0,17,0,0,17,0,0,17,0,0,17,21,21,17,1,1,20,0,0
0,0,1,16,1,0,0,0,0,0,0,0,0,0,0,0,0,0,0,0,17,0,19,0,17,0,0,0,17,0,18,0,17,0,0,0,0,0,0,0,0,0,0,0,0,0,0,0,1,16,1,0,0
0,15,0,0,0,0,0,0,0,0,0,0,14,0,0,0,0,0,0,0,13,0,0,0,0,0,0,0,0,0,0,0,12,0,0,0,0,0,0,0,11,0,0,0,0,0,0,0,0,0,0,10,0
0,0,0,0,0,0,0,0,0,0,0,0,0,0,0,0,0,0,0,0,0,0,0,0,0,0,0,0,0,0,0,0,0,0,0,0,0,0,0,0,0,0,0,0,0,0,0,0,0,0,0,0,0
:endlayer
layer: 6
0,0,0,0,0,0,0,0,0,0,0,0,0,0,0,0,0,0,0,0,0,0,0,0,0,0,0,0,0,0,0,0,0,0,0,0,0,0,0,0,0,0,0,0,0,0,0,0,0,0,0,0,0
0,0,0,0,0,0,0,0,0,0,0,0,0,0,0,0,0,0,0,0,0,0,0,0,45,0,188,0,45,0,0,0,0,0,0,0,0,0,0,0,0,0,0,0,0,0,0,0,0,0,0,0,0
0,88,0,0,88,0,0,88,0,0,88,0,0,88,0,0,88,0,0,88,0,0,88,1,1,85,85,85,1,1,88,0,0,88,0,0,88,0,0,88,0,0,88,0,0,88,0,0,88,0,0,88,0
0,0,0,0,0,0,0,0,0,0,0,0,0,0,0,0,0,0,0,0,0,0,1,100,0,120,187,122,0,100,1,0,0,0,0,0,0,0,0,0,0,0,0,0,0,0,0,0,0,0,0,0,0
0,0,0,0,0,0,0,0,0,0,0,0,0,0,0,0,0,0,0,0,0,0,1,0,0,0,0,0,0,0,1,0,0,0,0,0,0,0,0,0,0,0,0,0,0,0,0,0,0,0,0,0,0
0,88,1,1,1,1,1,1,1,1,1,1,1,1,1,1,1,1,1,1,1,1,1,186,154,154,154,154,154,185,1,1,1,1,1,1,1,1,1,1,1,1,1,1,1,1,1,1,1,1,1,88,0
0,1,184,0,0,0,0,178,0,0,0,0,0,0,0,0,0,0,0,0,0,0,45,0,154,164,165,164,154,0,45,0,0,0,0,0,183,182,0,181,0,0,0,0,0,172,0,0,0,0,0,1,0
0,22,180,0,179,0,0,178,0,0,0,177,0,0,0,0,0,176,0,0,0,175,0,0,154,165,164,165,154,0,0,0,0,174,0,0,0,0,0,0,0,0,173,0,0,172,0,0,0,0,0,20,0
0,22,171,0,0,170,0,1,0,0,0,0,169,156,156,168,167,156,156,166,0,0,0,0,154,164,165,164,154,0,0,0,163,0,163,0,163,0,163,0,163,0,0,0,0,1,0,0,0,162,0,20,0
0,1,161,0,160,160,160,1,0,0,0,0,159,156,156,158,157,156,156,155,0,0,45,0,154,154,154,154,154,0,45,153,148,152,148,151,148,150,148,149,148,147,0,0,0,1,0,0,0,0,0,1,0
0,88,1,1,1,1,1,1,1,0,1,46,1,1,1,1,1,1,1,1,1,1,1,1,1,0,0,0,1,1,1,1,1,1,1,1,1,1,1,1,1,46,1,0,1,1,1,1,1,1,1,88,0
0,0,0,88,0,1,0,146,1,91,1,1,100,0,0,0,0,100,0,0,0,0,100,145,0,0,0,0,0,145,100,0,0,0,0,100,0,0,0,0,100,1,1,144,1,143,0,1,0,88,0,0,0
0,0,0,0,0,20,0,0,0,0,1,1,0,0,0,0,0,0,0,0,0,0,0,0,0,0,0,0,0,0,0,0,0,0,0,0,0,0,0,0,0,1,1,0,0,0,0,22,0,0,0,0,0
0,0,0,0,0,20,0,0,0,0,0,1,0,0,0,0,0,0,0,0,46,0,142,46,45,0,0,0,45,46,0,0,46,0,0,0,0,0,0,0,0,1,0,0,0,0,0,22,0,0,0,0,0
0,0,0,88,0,1,0,0,0,0,0,1,0,0,0,141,0,0,0,0,0,0,0,1,1,1,140,1,1,1,0,0,0,139,0,0,0,0,0,0,0,1,0,0,0,0,0,1,0,88,0,0,0
0,0,0,0,0,20,0,0,0,0,1,1,0,0,0,0,0,0,0,0,0,0,0,138,1,0,0,0,1,137,0,0,0,0,0,112,112,112,112,104,0,1,1,0,0,0,0,22,0,0,0,0,0
0,0,0,0,0,20,0,0,0,46,1,46,0,0,0,0,136,0,0,0,0,0,0,135,1,0,0,0,1,134,0,133,0,0,0,106,105,105,105,104,0,46,1,46,0,0,0,22,0,0,0,0,0
0,0,0,88,0,1,0,0,45,1,100,0,0,0,132,109,109,109,131,0,46,0,0,1,1,0,0,0,1,1,0,0,46,0,0,106,105,0,0,0,0,0,100,1,45,0,0,1,0,88,0,0,0
0,0,0,0,0,20,0,0,0,22,122,0,0,0,0,109,109,109,0,0,0,0,0,0,1,0,130,0,1,0,0,0,0,0,0,106,105,0,109,109,0,0,120,20,0,0,0,22,0,0,0,0,0
0,0,0,0,0,20,0,0,0,22,129,128,0,0,127,109,109,109,126,0,0,0,0,0,1,125,125,125,1,0,0,0,0,0,0,106,105,0,109,109,0,124,123,20,0,0,0,22,0,0,0,0,0
0,0,0,88,0,1,0,0,0,22,122,0,0,0,0,109,109,109,0,0,0,0,0,0,46,121,121,121,46,0,0,0,0,0,0,106,105,0,0,0,0,0,120,20,0,0,0,1,0,88,0,0,0
0,0,0,0,0,20,0,0,45,1,100,0,0,0,119,109,109,109,118,0,46,0,0,0,100,0,0,0,100,0,0,0,46,0,0,106,103,0,0,0,0,0,100,1,45,0,0,22,0,0,0,0,0
0,0,0,0,0,20,0,0,0,46,1,46,0,0,0,109,109,109,0,0,0,0,0,0,0,0,0,0,0,0,0,0,0,0,0,0,0,0,117,0,0,46,1,46,0,0,0,22,0,0,0,0,0
0,0,0,88,0,1,0,0,0,0,45,1,0,0,116,109,109,109,115,0,0,0,114,0,0,0,0,0,0,0,113,0,0,0,0,0,0,0,0,112,112,1,45,0,0,0,0,1,0,88,0,0,0
0,0,0,0,0,20,0,0,0,0,0,22,0,0,0,0,111,0,0,0,0,0,0,0,0,0,0,0,0,0,0,0,0,0,0,0,109,109,0,105,104,20,0,0,0,0,0,22,0,0,0,0,0
0,0,0,0,0,20,0,0,0,0,0,22,0,0,0,110,0,0,0,0,46,0,0,0,0,0,0,0,0,0,0,0,46,0,0,0,109,109,0,105,104,20,0,0,0,0,0,22,0,0,0,0,0
0,0,0,88,0,1,0,0,0,0,45,1,0,0,0,0,0,0,0,0,0,0,0,0,0,0,0,0,0,0,0,0,0,0,0,0,109,109,0,105,104,1,45,0,0,0,0,1,0,88,0,0,0
0,0,0,0,0,20,0,0,0,0,0,22,0,0,0,0,0,0,0,0,0,0,108,0,0,0,0,0,0,0,107,0,0,0,0,0,0,0,0,105,104,20,0,0,0,0,0,22,0,0,0,0,0
0,0,0,0,0,20,0,0,0,0,0,22,0,0,0,0,0,0,0,0,0,0,0,0,0,0,0,0,0,0,0,0,0,0,0,0,0,106,105,105,104,20,0,0,0,0,0,22,0,0,0,0,0
0,0,0,88,0,1,0,0,0,0,45,1,100,0,0,0,0,0,0,0,46,0,0,0,0,0,0,0,0,0,0,0,46,0,0,0,0,103,103,103,100,1,45,0,0,0,0,1,0,88,0,0,0
0,0,0,0,0,20,0,0,0,0,0,46,1,16,1,46,0,0,0,0,0,102,0,0,0,0,0,0,0,0,0,101,0,0,0,0,0,46,1,16,1,46,0,0,0,0,0,22,0,0,0,0,0
0,0,0,0,0,20,0,0,0,0,0,0,45,0,45,1,0,0,0,0,0,0,0,0,0,0,0,0,0,0,0,0,0,0,0,0,0,1,45,0,45,0,0,0,0,0,0,22,0,0,0,0,0
0,0,0,88,0,1,0,0,0,0,0,0,0,0,0,22,0,0,0,0,0,0,0,0,0,0,0,0,0,0,0,0,0,0,0,0,0,20,0,0,0,0,0,0,0,0,0,1,0,88,0,0,0
0,0,0,0,0,20,0,0,0,0,0,0,0,0,45,1,100,0,0,0,0,0,0,0,0,0,0,0,0,0,0,0,0,0,0,0,100,1,45,0,0,0,33,0,0,0,0,22,0,0,0,0,0
0,0,0,0,0,20,0,0,0,0,0,0,0,0,0,46,1,16,16,16,1,46,1,99,98,97,96,95,94,93,1,46,1,16,16,16,1,46,0,0,0,0,0,0,0,0,0,22,0,0,0,0,0
0,0,0,88,0,1,0,0,0,0,0,0,33,0,0,0,45,0,0,0,45,5,45,0,0,0,0,0,0,0,45,5,45,0,0,0,45,0,0,0,0,0,0,0,0,0,0,1,0,88,0,0,0
0,0,0,0,0,20,0,0,0,0,0,0,0,0,0,0,0,0,0,0,0,0,0,0,0,0,0,0,0,0,0,0,0,0,0,0,0,0,0,0,0,0,0,0,0,0,0,22,0,0,0,0,0
0,0,0,0,0,20,0,0,0,0,0,0,0,0,0,0,0,0,0,0,0,0,0,0,0,0,0,0,0,0,0,0,0,0,0,0,0,0,0,0,0,0,0,0,0,0,0,22,0,0,0,0,0
0,0,0,88,0,1,0,0,0,0,0,0,0,0,0,0,0,33,0,0,0,0,0,0,0,0,0,0,0,0,0,0,0,0,33,0,0,0,0,0,0,0,33,0,0,0,0,1,0,88,0,0,0
0,0,1,1,1,1,1,0,0,0,0,0,0,0,0,0,0,0,0,0,0,0,0,0,0,0,0,0,0,0,0,0,0,0,0,0,0,0,0,0,0,0,0,0,0,0,1,1,1,1,1,0,0
0,0,1,0,0,0,92,0,0,0,0,0,0,0,0,0,0,0,0,0,0,0,0,0,0,0,0,0,0,0,0,0,0,0,0,0,0,0,0,0,0,0,0,0,0,0,91,0,0,0,1,0,0
0,0,22,0,0,30,1,0,0,0,0,0,0,0,0,0,0,0,0,0,88,0,0,0,88,0,0,0,88,0,0,0,88,0,0,0,0,0,0,0,0,0,0,0,0,0,1,27,0,0,20,0,0
0,0,1,0,0,0,1,0,1,85,85,1,85,85,1,85,85,1,85,85,1,0,0,0,0,0,0,0,0,0,0,0,1,85,85,1,85,85,1,85,85,1,85,85,1,0,1,0,0,0,1,0,0
0,0,1,1,1,1,1,1,1,0,0,0,0,0,0,0,0,0,0,0,22,0,0,0,0,0,0,0,0,0,0,0,20,0,0,0,0,0,0,0,0,0,0,0,1,1,1,1,1,1,1,0,0
0,0,90,1,1,88,0,0,88,0,0,88,0,0,88,0,0,88,0,0,1,0,0,0,0,0,0,0,0,0,0,0,1,0,0,88,0,0,88,0,0,88,0,0,88,0,0,88,1,1,89,0,0
0,0,1,87,1,0,0,0,0,0,0,0,0,0,0,0,0,0,0,0,88,0,0,0,88,0,0,0,88,0,0,0,88,0,0,0,0,0,0,0,0,0,0,0,0,0,0,0,1,87,1,0,0
0,0,0,0,0,0,0,0,0,0,0,0,0,0,0,0,0,0,0,0,0,0,0,0,0,0,0,0,0,0,0,0,0,0,0,0,0,0,0,0,0,0,0,0,0,0,0,0,0,0,0,0,0
0,0,0,0,0,0,0,0,0,0,0,0,0,0,0,0,0,0,0,0,0,0,0,0,0,0,0,0,0,0,0,0,0,0,0,0,0,0,0,0,0,0,0,0,0,0,0,0,0,0,0,0,0
:endlayer
layer: 7
0,0,0,0,0,0,0,0,0,0,0,0,0,0,0,0,0,0,0,0,0,0,0,0,0,0,0,0,0,0,0,0,0,0,0,0,0,0,0,0,0,0,0,0,0,0,0,0,0,0,0,0,0
0,0,0,0,0,0,0,0,0,0,0,0,0,0,0,0,0,0,0,0,0,0,0,0,45,0,0,0,45,0,0,0,0,0,0,0,0,0,0,0,0,0,0,0,0,0,0,0,0,0,0,0,0
0,88,0,0,88,0,0,88,0,0,88,0,0,88,0,0,88,0,0,88,0,0,88,1,1,190,190,190,1,1,88,0,0,88,0,0,88,0,0,88,0,0,88,0,0,88,0,0,88,0,0,88,0
0,0,0,0,0,0,0,0,0,0,0,0,0,0,0,0,0,0,0,0,0,0,1,198,0,0,222,0,0,198,1,0,0,0,0,0,0,0,0,0,0,0,0,0,0,0,0,0,0,0,0,0,0
0,0,0,0,0,0,0,0,0,0,0,0,0,0,0,0,0,0,0,0,0,0,1,0,0,0,0,0,0,0,1,0,0,0,0,0,0,0,0,0,0,0,0,0,0,0,0,0,0,0,0,0,0
0,88,1,1,1,1,1,1,1,1,1,1,1,1,1,1,1,1,1,1,1,1,1,0,0,0,0,0,0,0,1,1,1,1,1,1,1,1,1,1,1,1,1,1,1,1,1,1,1,1,1,88,0
0,1,216,0,0,0,0,92,0,0,0,0,0,0,0,0,0,0,0,0,0,0,45,0,0,0,0,0,0,0,45,0,0,0,0,0,0,0,0,0,0,0,0,0,0,91,0,0,0,0,0,1,0
0,190,0,0,0,0,0,91,0,0,0,0,0,0,0,0,0,0,0,0,0,0,0,0,0,0,221,0,0,0,0,0,0,0,0,0,0,0,0,0,0,0,0,0,0,92,0,0,0,0,0,190,0
0,190,0,0,0,0,0,1,0,0,0,0,220,0,0,219,218,0,0,217,0,0,0,0,0,0,0,0,0,0,0,0,0,0,0,0,0,0,0,0,0,0,0,0,0,1,0,0,0,0,0,190,0
0,1,216,0,0,0,0,1,0,0,0,0,215,0,0,214,213,0,0,212,0,0,45,0,0,0,0,0,0,0,45,0,0,0,0,0,0,0,0,0,0,0,0,0,0,1,0,0,0,0,0,1,0
0,88,1,1,1,1,1,1,1,189,1,46,1,1,1,1,1,1,1,1,1,1,1,1,1,0,0,0,1,1,1,1,1,1,1,1,1,1,1,1,1,46,1,189,1,1,1,1,1,1,1,88,0
0,0,0,88,0,1,0,0,146,1,1,1,198,0,61,61,0,198,0,61,61,0,198,145,0,0,0,0,0,145,198,0,61,61,0,198,0,61,61,0,198,1,1,1,143,0,0,1,0,88,0,0,0
0,0,0,0,0,45,0,0,0,0,1,1,0,0,0,0,0,0,0,0,0,0,0,0,0,0,0,0,0,0,0,0,0,0,0,0,0,0,0,0,0,1,1,0,0,0,0,45,0,0,0,0,0
0,0,0,0,0,45,0,0,0,0,90,1,0,0,0,0,0,0,0,0,46,0,0,46,45,0,0,0,45,46,0,0,46,0,0,0,0,0,0,0,0,1,89,0,0,0,0,45,0,0,0,0,0
0,0,0,88,0,1,0,0,0,0,90,1,0,0,0,0,0,0,0,0,0,0,0,1,1,1,92,1,1,1,0,0,0,0,0,0,0,0,0,0,0,1,89,0,0,0,0,1,0,88,0,0,0
0,0,0,0,0,45,0,0,0,0,1,1,0,0,0,0,0,0,0,0,0,0,0,187,1,0,0,0,1,187,0,0,0,0,0,0,0,0,0,0,0,1,1,0,0,0,0,45,0,0,0,0,0
0,0,0,0,0,45,0,0,0,46,1,46,0,0,0,0,211,0,0,0,0,0,0,187,1,0,0,0,1,187,0,0,0,0,0,0,0,0,0,0,0,46,1,46,0,0,0,45,0,0,0,0,0
0,0,0,88,0,1,0,0,45,1,198,0,0,0,210,0,0,0,209,0,46,0,0,1,1,0,0,0,1,1,0,0,46,0,0,0,0,0,0,0,0,0,198,1,45,0,0,1,0,88,0,0,0
0,0,0,0,0,45,0,0,0,190,0,0,0,0,0,0,0,0,0,0,0,0,0,0,1,208,208,208,1,0,0,0,0,0,0,0,0,0,0,0,0,0,0,190,0,0,0,45,0,0,0,0,0
0,0,0,0,0,45,0,0,0,190,205,0,0,0,207,0,0,0,206,0,0,0,0,0,1,121,121,121,1,0,0,0,0,0,0,0,0,0,0,0,0,0,205,190,0,0,0,45,0,0,0,0,0
0,0,0,88,0,1,0,0,0,190,0,0,0,0,0,0,0,0,0,0,0,0,0,0,79,0,0,0,79,0,0,0,0,0,0,0,0,0,0,0,0,0,0,190,0,0,0,1,0,88,0,0,0
0,0,0,0,0,45,0,0,45,1,198,0,0,0,204,0,0,0,203,0,46,0,0,0,198,0,0,0,198,0,0,0,46,0,0,0,0,0,0,0,0,0,198,1,45,0,0,45,0,0,0,0,0
0,0,0,0,0,45,0,0,0,46,1,46,0,0,0,0,0,0,0,0,0,0,0,0,0,0,0,0,0,0,0,0,0,0,0,0,0,0,0,0,0,46,1,46,0,0,0,45,0,0,0,0,0
0,0,0,88,0,1,0,0,0,0,45,1,0,0,202,0,0,0,201,0,0,0,0,0,0,0,0,0,0,0,0,0,0,0,0,0,0,0,0,0,0,1,45,0,0,0,0,1,0,88,0,0,0
0,0,0,0,0,45,0,0,0,0,0,190,0,0,0,0,200,0,0,0,0,0,0,0,0,0,0,0,0,0,0,0,0,0,0,0,0,0,0,0,0,190,0,0,0,0,0,45,0,0,0,0,0
0,0,0,0,0,45,0,0,0,0,0,190,0,0,0,0,0,0,0,0,46,0,0,0,0,0,0,0,0,0,0,0,46,0,0,0,0,0,0,0,0,190,0,0,0,0,0,45,0,0,0,0,0
0,0,0,88,0,1,0,0,0,0,45,1,0,0,0,0,0,0,0,0,0,0,0,0,0,0,0,0,0,0,0,0,0,0,0,0,0,0,0,0,0,1,45,0,0,0,0,1,0,88,0,0,0
0,0,0,0,0,45,0,0,0,0,0,190,0,0,0,0,0,0,0,0,0,0,0,0,0,0,0,0,0,0,0,0,0,0,0,0,0,0,0,0,0,190,0,0,0,0,0,45,0,0,0,0,0
0,0,0,0,0,45,0,0,0,0,0,190,0,0,0,0,0,0,0,0,0,0,0,0,0,0,0,0,0,0,0,0,0,0,0,0,0,0,0,0,0,190,0,0,0,0,0,45,0,0,0,0,0
0,0,0,88,0,1,0,0,0,0,45,1,198,0,0,0,0,0,0,0,46,0,0,0,0,0,0,0,0,0,0,0,46,0,0,0,0,0,0,0,198,1,45,0,0,0,0,1,0,88,0,0,0
0,0,0,0,0,45,0,0,0,0,0,46,1,190,1,46,0,0,0,0,0,0,0,0,0,0,0,0,0,0,0,0,0,0,0,0,0,46,1,190,1,46,0,0,0,0,0,45,0,0,0,0,0
0,0,0,0,0,45,0,0,0,0,0,0,45,0,45,1,0,0,0,0,0,0,0,0,0,0,0,0,0,0,0,0,0,0,0,0,0,1,45,0,45,0,0,0,0,0,0,45,0,0,0,0,0
0,0,0,88,0,1,0,0,0,0,0,0,0,0,0,190,0,0,0,0,0,0,0,0,0,0,0,0,0,0,0,0,0,0,0,0,0,190,0,0,0,0,0,0,0,0,0,1,0,88,0,0,0
0,0,0,0,0,45,0,0,0,0,0,0,0,0,45,1,199,0,0,0,0,0,0,0,0,0,0,0,0,0,0,0,0,0,0,0,198,1,45,0,0,0,33,0,0,0,0,45,0,0,0,0,0
0,0,0,0,0,45,0,0,0,0,0,0,0,0,0,46,1,190,190,190,1,46,1,197,196,195,194,193,192,191,1,46,1,190,190,190,1,46,0,0,0,0,0,0,0,0,0,45,0,0,0,0,0
0,0,0,88,0,1,0,0,0,0,0,0,33,0,0,0,45,0,0,0,45,5,45,0,0,0,0,0,0,0,45,5,45,0,0,0,45,0,0,0,0,0,0,0,0,0,0,1,0,88,0,0,0
0,0,0,0,0,45,0,0,0,0,0,0,0,0,0,0,0,0,0,0,0,0,0,0,0,0,0,0,0,0,0,0,0,0,0,0,0,0,0,0,0,0,0,0,0,0,0,45,0,0,0,0,0
0,0,0,0,0,45,0,0,0,0,0,0,0,0,0,0,0,0,0,0,0,0,0,0,0,0,0,0,0,0,0,0,0,0,0,0,0,0,0,0,0,0,0,0,0,0,0,45,0,0,0,0,0
0,0,0,88,0,1,0,0,0,0,0,0,0,0,0,0,0,33,0,0,0,0,0,0,0,0,0,0,0,0,0,0,0,0,33,0,0,0,0,0,0,0,33,0,0,0,0,1,0,88,0,0,0
0,0,1,1,1,1,1,0,0,0,0,0,0,0,0,0,0,0,0,0,0,0,0,0,0,0,0,0,0,0,0,0,0,0,0,0,0,0,0,0,0,0,0,0,0,0,1,1,1,1,1,0,0
0,0,1,0,0,0,1,0,0,0,0,0,0,0,0,0,0,0,0,0,0,0,0,0,0,0,0,0,0,0,0,0,0,0,0,0,0,0,0,0,0,0,0,0,0,0,1,0,0,0,1,0,0
0,0,45,0,0,30,1,0,0,0,0,0,0,0,0,0,0,0,0,0,88,0,0,0,88,0,0,0,88,0,0,0,88,0,0,0,0,0,0,0,0,0,0,0,0,0,1,27,0,0,45,0,0
0,0,1,0,0,0,1,189,1,45,45,1,45,45,1,45,45,1,45,45,1,0,0,0,0,0,0,0,0,0,0,0,1,45,45,1,45,45,1,45,45,1,45,45,1,189,1,0,0,0,1,0,0
0,0,1,1,1,1,1,1,1,0,0,0,0,0,0,0,0,0,0,0,45,0,0,0,0,0,0,0,0,0,0,0,45,0,0,0,0,0,0,0,0,0,0,0,1,1,1,1,1,1,1,0,0
0,0,22,0,1,88,0,0,88,0,0,88,0,0,88,0,0,88,0,0,1,0,0,0,0,0,0,0,0,0,0,0,1,0,0,88,0,0,88,0,0,88,0,0,88,0,0,88,1,0,20,0,0
0,0,1,16,1,0,0,0,0,0,0,0,0,0,0,0,0,0,0,0,88,0,0,0,88,0,0,0,88,0,0,0,88,0,0,0,0,0,0,0,0,0,0,0,0,0,0,0,1,16,1,0,0
0,0,0,0,0,0,0,0,0,0,0,0,0,0,0,0,0,0,0,0,0,0,0,0,0,0,0,0,0,0,0,0,0,0,0,0,0,0,0,0,0,0,0,0,0,0,0,0,0,0,0,0,0
0,0,0,0,0,0,0,0,0,0,0,0,0,0,0,0,0,0,0,0,0,0,0,0,0,0,0,0,0,0,0,0,0,0,0,0,0,0,0,0,0,0,0,0,0,0,0,0,0,0,0,0,0
:endlayer
layer: 8
0,0,0,0,0,0,0,0,0,0,0,0,0,0,0,0,0,0,0,0,0,0,0,0,0,0,0,0,0,0,0,0,0,0,0,0,0,0,0,0,0,0,0,0,0,0,0,0,0,0,0,0,0
0,0,0,0,0,0,0,0,0,0,0,0,0,0,0,0,0,0,0,0,0,0,0,0,45,0,0,0,45,0,0,0,0,0,0,0,0,0,0,0,0,0,0,0,0,0,0,0,0,0,0,0,0
0,223,89,90,223,89,90,223,89,90,223,89,90,223,89,90,223,89,90,223,89,90,223,1,1,190,190,190,1,1,223,89,90,223,89,90,223,89,90,223,89,90,223,89,90,223,89,90,223,89,90,223,0
0,87,0,0,240,0,0,240,0,0,240,0,0,240,0,0,240,0,0,240,0,0,1,198,0,0,0,0,0,198,1,0,0,240,0,0,240,0,0,240,0,0,240,0,0,240,0,0,240,0,0,87,0
0,189,0,0,0,0,0,0,0,0,0,0,0,0,0,0,0,0,0,0,0,0,1,0,0,0,0,0,0,0,1,0,0,0,0,0,0,0,0,0,0,0,0,0,0,0,0,0,0,0,0,189,0
0,223,1,1,1,1,1,1,1,1,1,1,1,1,1,1,1,1,1,1,1,1,1,0,0,0,0,0,0,0,1,1,1,1,1,1,1,1,1,1,1,1,1,1,1,1,1,1,1,1,1,223,0
0,1,216,240,0,240,0,1,0,240,0,240,0,240,0,240,0,240,0,240,0,240,45,0,0,0,0,0,0,0,45,240,0,240,243,240,0,240,242,240,0,240,241,240,0,1,0,240,0,240,0,1,0
0,190,0,0,0,0,0,1,0,0,0,0,0,0,0,0,0,0,0,0,0,0,0,0,0,0,0,0,0,0,0,0,0,0,0,0,0,0,0,0,0,0,0,0,0,1,0,0,0,0,0,190,0
0,190,0,0,0,0,0,1,0,0,0,0,0,0,0,0,0,0,0,0,0,0,0,0,0,0,0,0,0,0,0,0,0,0,0,0,0,0,0,0,0,0,0,0,0,1,0,0,0,0,0,190,0
0,1,216,130,0,130,0,1,0,130,0,130,0,130,0,130,0,130,0,130,0,130,45,0,0,0,0,0,0,0,45,130,0,130,0,130,0,130,0,130,0,130,0,130,0,1,0,130,0,130,0,1,0
0,223,1,1,1,1,1,1,1,1,1,46,1,1,1,1,1,1,1,1,1,1,1,1,1,239,0,238,1,1,1,1,1,1,1,1,1,1,1,1,1,46,1,1,1,1,1,1,1,1,1,223,0
0,0,0,223,225,1,225,0,0,146,1,1,198,61,61,61,61,198,61,61,61,61,198,145,0,0,0,0,0,145,198,61,61,61,61,198,61,61,61,61,198,1,1,143,0,0,224,1,224,223,0,0,0
0,0,0,87,0,87,0,0,0,0,1,1,0,0,0,0,0,0,0,0,0,0,0,0,0,0,0,0,0,0,0,0,0,0,0,0,0,0,0,0,0,1,1,0,0,0,0,87,0,87,0,0,0
0,0,0,189,0,189,0,0,0,0,1,1,0,0,0,0,0,0,0,45,46,45,0,46,89,237,237,237,90,46,0,45,46,45,0,0,0,0,0,0,0,1,1,0,0,0,0,189,0,189,0,0,0
0,0,0,223,225,1,225,0,0,0,1,1,0,0,0,0,0,0,0,0,0,0,0,1,1,1,1,1,1,1,0,0,0,0,0,0,0,0,0,0,0,1,1,0,0,0,224,1,224,223,0,0,0
0,0,0,87,0,87,0,0,0,0,1,1,0,0,0,0,0,0,0,0,0,0,0,236,1,0,0,0,1,235,0,0,0,0,0,0,0,0,0,0,0,1,1,0,0,0,0,87,0,87,0,0,0
0,0,0,189,0,189,0,0,0,46,1,46,45,0,0,0,0,0,0,0,0,0,0,234,1,225,0,224,1,233,0,0,0,0,0,0,0,0,0,0,45,46,1,46,0,0,0,189,0,189,0,0,0
0,0,0,223,225,1,225,0,45,1,198,45,0,0,0,0,0,0,0,45,46,45,0,1,1,208,208,208,1,1,0,45,46,45,0,0,0,0,0,0,0,45,198,1,45,0,224,1,224,223,0,0,0
0,0,0,87,0,87,0,0,0,190,0,0,0,0,0,0,0,0,0,0,0,0,0,0,1,121,121,121,1,0,0,0,0,0,0,0,0,0,0,0,0,0,0,190,0,0,0,87,0,87,0,0,0
0,0,0,189,0,189,0,0,0,190,0,0,0,0,0,0,0,0,0,0,0,0,0,0,79,0,0,0,79,0,0,0,0,0,0,0,0,0,0,0,0,0,0,190,0,0,0,189,0,189,0,0,0
0,0,0,223,225,1,225,0,0,190,0,0,0,0,0,0,0,0,0,0,0,0,0,0,0,0,0,0,0,0,0,0,0,0,0,0,0,0,0,0,0,0,0,190,0,0,224,1,224,223,0,0,0
0,0,0,87,0,87,0,0,45,1,198,45,0,0,0,0,0,0,0,45,46,45,0,0,198,0,0,0,198,0,0,45,46,45,0,0,0,0,0,0,0,45,198,1,45,0,0,87,0,87,0,0,0
0,0,0,189,0,189,0,0,0,46,1,46,45,0,0,0,0,0,0,0,0,0,0,0,0,0,0,0,0,0,0,0,0,0,0,0,0,0,0,0,45,46,1,46,0,0,0,189,0,189,0,0,0
0,0,0,223,225,1,225,0,0,0,45,1,0,0,0,0,0,0,0,0,0,0,0,0,0,0,0,0,0,0,0,0,0,0,0,0,0,0,0,0,0,1,45,0,0,0,224,1,224,223,0,0,0
0,0,0,87,0,87,0,0,0,0,0,190,0,0,0,0,0,0,0,0,0,0,0,0,0,0,0,0,0,0,0,0,0,0,0,0,0,0,0,0,0,190,0,0,0,0,0,87,0,87,0,0,0
0,0,0,189,0,189,0,0,0,0,0,190,0,0,0,0,0,0,0,45,46,45,0,0,0,0,0,0,0,0,0,45,46,45,0,0,0,0,0,0,0,190,0,0,0,0,0,189,0,189,0,0,0
0,0,0,223,225,1,225,0,0,0,45,1,0,0,0,0,0,0,0,0,0,0,0,0,0,0,0,0,0,0,0,0,0,0,0,0,0,0,0,0,0,1,45,0,0,0,224,1,224,223,0,0,0
0,0,0,87,0,87,0,0,0,0,0,190,0,0,0,0,0,0,0,0,0,0,0,0,0,0,0,0,0,0,0,0,0,0,0,0,0,0,0,0,0,190,0,0,0,0,0,87,0,87,0,0,0
0,0,0,189,0,189,0,0,0,0,0,190,0,0,0,0,0,0,0,0,0,0,0,0,0,0,0,0,0,0,0,0,0,0,0,0,0,0,0,0,0,190,0,0,0,0,0,189,0,189,0,0,0
0,0,0,223,225,1,225,0,0,0,45,1,198,0,0,45,0,0,0,45,46,45,0,0,0,0,0,0,0,0,0,45,46,45,0,0,0,45,0,0,198,1,45,0,0,0,224,1,224,223,0,0,0
0,0,0,87,0,87,0,0,0,0,0,46,1,190,1,46,45,0,0,0,0,0,0,0,0,0,0,0,0,0,0,0,0,0,0,0,45,46,1,190,1,46,0,0,0,0,0,87,0,87,0,0,0
0,0,0,189,0,189,0,0,0,0,0,0,45,0,45,1,0,0,0,0,0,0,0,0,0,0,0,0,0,0,0,0,0,0,0,0,0,1,45,0,45,0,0,0,0,0,0,189,0,189,0,0,0
0,0,0,223,225,1,225,0,0,0,0,0,0,0,0,190,0,0,0,0,0,0,0,0,0,0,0,0,0,0,0,0,0,0,0,0,0,190,0,0,0,0,0,0,0,0,224,1,224,223,0,0,0
0,0,0,87,0,87,0,0,0,0,0,0,0,0,45,1,199,0,0,0,0,45,0,0,0,0,0,0,0,0,0,45,0,0,0,0,198,1,45,0,0,0,33,0,0,0,0,87,0,87,0,0,0
0,0,0,189,0,189,0,0,0,0,0,0,0,0,0,46,1,190,190,190,1,46,1,232,231,230,229,228,227,226,1,46,1,190,190,190,1,46,0,0,0,0,0,0,0,0,0,189,0,189,0,0,0
0,0,0,223,225,1,225,0,0,0,0,0,0,0,0,0,45,0,0,0,45,5,45,0,0,0,0,0,0,0,45,5,45,0,0,0,45,0,0,0,0,0,0,0,0,0,224,1,224,223,0,0,0
0,0,0,87,0,87,0,0,0,0,0,0,33,0,0,0,0,0,0,0,0,0,0,0,0,0,0,0,0,0,0,0,0,0,0,0,0,0,0,0,0,0,0,0,0,0,0,87,0,87,0,0,0
0,0,0,189,0,189,0,0,0,0,0,0,0,0,0,0,0,0,0,0,0,0,0,0,0,0,0,0,0,0,0,0,0,0,0,0,0,0,0,0,0,0,0,0,0,0,0,189,0,189,0,0,0
0,0,0,223,225,1,225,0,0,0,0,0,0,0,0,0,0,33,0,0,0,0,0,0,0,0,0,0,0,0,0,0,0,0,33,0,0,0,0,0,0,0,33,0,0,0,224,1,224,223,0,0,0
0,0,1,1,1,1,1,0,0,0,0,0,0,0,0,0,0,0,0,0,0,0,0,0,0,0,0,0,0,0,0,0,0,0,0,0,0,0,0,0,0,0,0,0,0,0,1,1,1,1,1,0,0
0,45,1,0,0,0,45,0,0,0,0,0,0,0,0,0,0,0,0,0,0,0,0,0,0,0,0,0,0,0,0,0,0,0,0,0,0,0,0,0,0,0,0,0,0,0,45,0,0,0,1,45,0
0,0,45,0,0,30,1,0,130,0,0,130,0,0,130,0,0,130,0,0,88,0,0,0,88,0,0,0,88,0,0,0,88,0,0,130,0,0,130,0,0,130,0,0,130,0,1,27,0,0,45,0,0
0,45,1,0,0,0,1,1,1,89,90,1,89,90,1,89,90,1,89,90,1,0,0,0,0,0,0,0,0,0,0,0,1,89,90,1,89,90,1,89,90,1,89,90,1,1,1,0,0,0,1,45,0
0,0,1,1,1,1,1,1,1,0,0,130,0,0,130,0,0,130,0,0,45,0,0,0,0,0,0,0,0,0,0,0,45,0,0,130,0,0,130,0,0,130,0,0,1,1,1,1,1,1,1,0,0
0,0,45,0,1,223,89,90,223,89,90,223,89,90,223,89,90,223,89,90,1,0,0,0,0,0,0,0,0,0,0,0,1,89,90,223,89,90,223,89,90,223,89,90,223,89,90,223,1,0,45,0,0
0,0,1,45,1,0,0,0,0,0,0,0,0,0,0,0,0,0,0,0,88,0,0,0,88,0,0,0,88,0,0,0,88,0,0,0,0,0,0,0,0,0,0,0,0,0,0,0,1,45,1,0,0
0,0,0,0,0,0,0,0,0,0,0,0,0,0,0,0,0,0,0,0,0,0,0,0,0,0,0,0,0,0,0,0,0,0,0,0,0,0,0,0,0,0,0,0,0,0,0,0,0,0,0,0,0
0,0,0,0,0,0,0,0,0,0,0,0,0,0,0,0,0,0,0,0,0,0,0,0,0,0,0,0,0,0,0,0,0,0,0,0,0,0,0,0,0,0,0,0,0,0,0,0,0,0,0,0,0
:endlayer
layer: 9
0,0,0,0,0,0,0,0,0,0,0,0,0,0,0,0,0,0,0,0,0,0,0,0,0,0,0,0,0,0,0,0,0,0,0,0,0,0,0,0,0,0,0,0,0,0,0,0,0,0,0,0,0
0,189,244,244,189,244,244,189,244,244,189,244,244,189,244,244,189,244,244,189,244,244,189,0,189,237,0,237,189,0,189,244,244,189,244,244,189,244,244,189,244,244,189,244,244,189,244,244,189,244,244,189,0
90,55,55,55,55,55,55,55,55,55,55,55,55,55,55,55,55,55,55,55,55,55,55,1,1,190,190,190,1,1,55,55,55,55,55,55,55,55,55,55,55,55,55,55,55,55,55,55,55,55,55,55,89
244,55,1,1,1,1,1,1,1,1,1,1,1,1,1,1,1,1,1,1,1,1,1,0,0,0,0,0,0,0,1,1,1,1,1,1,1,1,1,1,1,1,1,1,1,1,1,1,1,1,1,55,244
244,55,1,1,1,1,1,1,1,1,1,1,1,1,1,1,1,1,1,1,1,1,1,0,0,0,0,0,0,0,1,1,1,1,1,1,1,1,1,1,1,1,1,1,1,1,1,1,1,1,1,55,244
90,55,1,1,1,1,1,1,1,1,1,1,1,1,1,1,1,1,1,1,1,1,1,0,0,0,0,0,0,0,1,1,1,1,1,1,1,1,1,1,1,1,1,1,1,1,1,1,1,1,1,55,89
244,1,55,55,55,55,55,55,55,55,55,55,55,55,55,55,55,55,55,55,55,55,239,0,0,0,0,0,0,0,238,55,55,55,55,55,55,55,55,55,55,55,55,55,55,55,55,55,55,55,55,1,244
244,5,55,55,55,55,55,55,55,55,55,55,55,55,55,55,55,55,55,55,55,55,239,0,0,0,0,0,0,0,238,55,55,55,55,55,55,55,55,55,55,55,55,55,55,55,55,55,55,55,55,5,244
244,5,55,55,55,55,55,55,55,55,55,55,55,55,55,55,55,55,55,55,55,55,239,0,0,0,0,0,0,0,238,55,55,55,55,55,55,55,55,55,55,55,55,55,55,55,55,55,55,55,55,5,244
244,1,55,55,55,55,55,55,55,55,55,55,55,55,55,55,55,55,55,55,55,55,239,0,0,0,0,0,0,0,238,55,55,55,55,55,55,55,55,55,55,55,55,55,55,55,55,55,55,55,55,1,244
90,55,55,55,55,55,55,55,55,55,55,46,1,1,1,1,1,1,1,1,1,1,1,1,1,1,1,1,1,1,1,1,1,1,1,1,1,1,1,1,1,46,55,55,55,55,55,55,55,55,55,55,89
0,87,90,55,0,55,0,0,0,0,0,1,0,61,61,61,61,0,61,61,61,61,0,145,0,0,0,0,0,145,0,61,61,61,61,0,61,61,61,61,0,1,0,0,0,0,0,55,0,55,89,87,0
0,0,244,55,0,55,0,0,0,0,253,1,0,0,0,0,0,0,0,0,0,0,0,0,0,0,130,0,0,0,0,0,0,0,0,0,0,0,0,0,0,1,253,0,0,0,0,55,0,55,244,0,0
0,0,244,55,0,55,0,0,0,0,1,1,0,0,0,0,0,0,0,252,46,252,0,46,1,1,1,1,1,46,0,252,46,252,0,0,0,0,0,0,0,1,1,0,0,0,0,55,0,55,244,0,0
0,0,90,55,0,55,0,0,0,0,1,1,0,0,0,0,0,0,0,0,0,0,0,1,1,125,125,125,1,1,0,0,0,0,0,0,0,0,0,0,0,1,1,0,0,0,0,55,0,55,89,0,0
0,0,244,55,0,55,0,0,0,130,1,1,0,0,0,0,0,0,0,0,0,0,0,238,1,125,125,125,1,239,0,0,0,0,0,0,0,0,0,0,0,1,1,130,0,0,0,55,0,55,244,0,0
0,0,244,55,0,55,0,0,224,46,1,46,252,0,0,0,0,0,0,0,0,0,0,238,1,125,125,125,1,239,0,0,0,0,0,0,0,0,0,0,252,46,1,46,225,0,0,55,0,55,244,0,0
0,0,90,55,0,55,0,0,90,1,0,252,0,0,0,0,0,0,0,252,46,252,0,1,1,121,121,121,1,1,0,252,46,252,0,0,0,0,0,0,0,252,0,1,89,0,0,55,0,55,89,0,0
0,0,244,55,0,55,0,0,237,190,0,0,0,0,0,0,0,0,0,0,0,0,0,0,79,0,0,0,79,0,0,0,0,0,0,0,0,0,0,0,0,0,0,190,237,0,0,55,0,55,244,0,0
0,0,244,55,0,55,0,0,0,190,0,0,0,0,0,0,0,0,0,0,0,0,0,0,0,0,0,0,0,0,0,0,0,0,0,0,0,0,0,0,0,0,0,190,0,0,0,55,0,55,244,0,0
0,0,90,55,0,55,0,0,237,190,0,0,0,0,0,0,0,0,0,0,0,0,0,0,0,0,0,0,0,0,0,0,0,0,0,0,0,0,0,0,0,0,0,190,237,0,0,55,0,55,89,0,0
0,0,244,55,0,55,0,0,90,1,0,252,0,0,0,0,0,0,0,252,46,252,0,0,0,0,0,0,0,0,0,252,46,252,0,0,0,0,0,0,0,252,0,1,89,0,0,55,0,55,244,0,0
0,0,244,55,0,55,0,0,224,46,1,46,252,0,0,0,0,0,0,0,0,0,0,0,0,0,0,0,0,0,0,0,0,0,0,0,0,0,0,0,252,46,1,46,225,0,0,55,0,55,244,0,0
0,0,90,55,0,55,0,0,0,240,90,1,0,0,0,0,0,0,0,0,0,0,0,0,0,0,0,0,0,0,0,0,0,0,0,0,0,0,0,0,0,1,89,240,0,0,0,55,0,55,89,0,0
0,0,244,55,0,55,0,0,0,0,237,190,0,0,0,0,0,0,0,0,0,0,0,0,0,0,45,0,0,0,0,0,0,0,0,0,0,0,0,0,0,190,237,0,0,0,0,55,0,55,244,0,0
0,0,244,55,0,55,0,0,0,0,237,190,0,0,0,0,0,0,0,252,46,252,0,0,0,45,45,45,0,0,0,252,46,252,0,0,0,0,0,0,0,190,237,0,0,0,0,55,0,55,244,0,0
0,0,90,55,0,55,0,0,0,0,90,1,0,0,0,0,0,0,0,0,0,0,0,0,0,0,45,0,0,0,0,0,0,0,0,0,0,0,0,0,0,1,89,0,0,0,0,55,0,55,89,0,0
0,0,244,55,0,55,0,0,0,0,237,190,0,0,0,0,0,0,0,0,0,0,0,0,0,0,0,0,0,0,0,0,0,0,0,0,0,0,0,0,0,190,237,0,0,0,0,55,0,55,244,0,0
0,0,244,55,0,55,0,0,0,0,237,190,0,0,0,0,0,0,0,0,0,0,0,0,0,0,0,0,0,0,0,0,0,0,0,0,0,0,0,0,0,190,237,0,0,0,0,55,0,55,244,0,0
0,0,90,55,0,55,0,0,0,0,90,1,0,0,0,252,0,0,0,252,46,252,0,0,0,0,45,0,0,0,0,252,46,252,0,0,0,252,0,0,0,1,89,0,0,0,0,55,0,55,89,0,0
0,0,244,55,0,55,0,0,0,0,224,46,1,190,1,46,252,0,0,0,0,0,0,0,0,45,45,45,0,0,0,0,0,0,0,0,252,46,1,190,1,46,225,0,0,0,0,55,0,55,244,0,0
0,0,244,55,0,55,0,0,0,0,0,240,87,237,5,1,0,0,0,0,0,0,0,0,0,0,45,0,0,0,0,0,0,0,0,0,0,1,5,237,87,240,0,0,0,0,0,55,0,55,244,0,0
0,0,90,55,0,55,0,0,0,0,0,0,0,0,237,190,0,0,0,0,0,0,0,0,0,0,0,0,0,0,0,0,0,0,0,0,0,190,237,0,0,0,0,0,0,0,0,55,0,55,89,0,0
0,0,244,55,0,55,0,0,0,0,0,0,0,0,90,1,0,0,0,0,0,252,0,0,0,0,0,0,0,0,0,252,0,0,0,0,0,1,89,0,0,0,33,0,0,0,0,55,0,55,244,0,0
0,0,244,55,0,55,0,0,0,0,0,0,0,0,224,46,1,190,190,190,1,46,1,251,250,249,248,247,246,245,1,46,1,190,190,190,1,46,225,0,0,0,0,0,0,0,0,55,0,55,244,0,0
0,0,90,55,0,55,0,0,0,0,0,0,0,0,0,240,87,237,0,237,87,5,89,0,0,0,0,0,0,0,90,5,87,237,0,237,87,240,0,0,0,0,0,0,0,0,0,55,0,55,89,0,0
0,0,244,55,0,55,0,0,0,0,0,0,33,0,0,0,0,0,0,0,0,0,0,0,0,0,0,0,0,0,0,0,0,0,0,0,0,0,0,0,0,0,0,0,0,0,0,55,0,55,244,0,0
0,0,244,55,0,55,0,0,0,0,0,0,0,0,0,0,0,0,0,0,0,0,0,0,0,0,0,0,0,0,0,0,0,0,0,0,0,0,0,0,0,0,0,0,0,0,0,55,0,55,244,0,0
0,0,90,55,0,55,0,0,0,0,0,0,0,0,0,0,0,33,0,0,0,0,0,0,0,0,0,0,0,0,0,0,0,0,33,0,0,0,0,0,0,0,0,0,0,0,0,55,0,55,89,0,0
0,0,1,1,1,1,1,0,0,0,0,0,0,0,0,0,0,0,0,0,0,0,0,0,0,0,0,0,0,0,0,0,0,0,0,0,0,0,0,0,0,0,33,0,0,0,1,1,1,1,1,0,0
0,56,1,0,0,0,1,0,0,0,0,0,0,0,0,0,0,0,0,0,0,0,0,0,0,0,0,0,0,0,0,0,0,0,0,0,0,0,0,0,0,0,0,0,0,0,1,0,0,0,1,56,0
0,56,1,0,0,30,1,0,0,0,0,0,0,0,0,0,0,0,0,0,223,89,237,90,223,89,237,90,223,89,237,90,223,0,0,0,0,0,0,0,0,0,0,0,0,0,1,27,0,0,1,56,0
0,56,1,0,0,0,1,55,55,55,55,55,55,55,55,55,55,55,55,55,1,0,0,0,0,0,0,0,0,0,0,0,1,55,55,55,55,55,55,55,55,55,55,55,55,55,1,0,0,0,1,56,0
0,0,1,1,1,1,1,1,55,0,0,0,0,0,0,0,0,0,0,0,1,0,0,0,0,0,0,0,0,0,0,0,1,0,0,0,0,0,0,0,0,0,0,0,55,1,1,1,1,1,1,0,0
0,0,90,0,1,55,55,55,55,55,55,55,55,55,55,55,55,55,55,55,1,0,0,0,0,0,0,0,0,0,0,0,1,55,55,55,55,55,55,55,55,55,55,55,55,55,55,55,1,0,89,0,0
0,0,1,87,1,87,244,244,87,244,244,87,244,244,87,244,244,87,244,244,223,89,237,90,223,89,237,90,223,89,237,90,223,244,244,87,244,244,87,244,244,87,244,244,87,244,244,87,1,87,1,0,0
0,0,0,0,0,0,0,0,0,0,0,0,0,0,0,0,0,0,0,0,0,0,0,0,0,0,0,0,0,0,0,0,0,0,0,0,0,0,0,0,0,0,0,0,0,0,0,0,0,0,0,0,0
0,0,0,0,0,0,0,0,0,0,0,0,0,0,0,0,0,0,0,0,0,0,0,0,0,0,0,0,0,0,0,0,0,0,0,0,0,0,0,0,0,0,0,0,0,0,0,0,0,0,0,0,0
:endlayer
layer: 10
0,0,0,0,0,0,0,0,0,0,0,0,0,0,0,0,0,0,0,0,0,0,0,0,0,0,0,0,0,0,0,0,0,0,0,0,0,0,0,0,0,0,0,0,0,0,0,0,0,0,0,0,0
0,0,45,237,237,45,237,237,45,237,237,45,237,237,45,237,237,45,237,237,45,237,45,0,0,56,56,56,0,0,45,237,45,237,237,45,237,237,45,237,237,45,237,237,45,237,237,45,237,237,45,0,0
0,46,1,1,1,1,1,1,1,1,1,1,1,1,1,1,1,1,1,1,1,1,1,1,1,1,1,1,1,1,1,1,1,1,1,1,1,1,1,1,1,1,1,1,1,1,1,1,1,1,1,46,0
45,1,55,55,55,55,55,55,55,55,55,55,55,55,55,55,55,55,55,55,55,55,55,55,55,55,55,55,55,55,55,55,55,55,55,55,55,55,55,55,55,55,55,55,55,55,55,55,55,55,55,1,45
237,1,55,55,55,55,55,55,55,55,55,55,55,55,55,55,55,55,55,55,55,55,55,55,55,55,55,55,55,55,55,55,55,55,55,55,55,55,55,55,55,55,55,55,55,55,55,55,55,55,55,1,237
237,1,55,55,55,55,55,55,55,55,55,55,55,55,55,55,55,55,55,55,55,55,55,55,55,55,55,55,55,55,55,55,55,55,55,55,55,55,55,55,55,55,55,55,55,55,55,55,55,55,55,1,237
45,1,55,55,55,55,55,55,55,55,55,55,55,55,55,55,55,55,55,55,55,55,55,55,55,55,55,55,55,55,55,55,55,55,55,55,55,55,55,55,55,55,55,55,55,55,55,55,55,55,55,1,45
237,1,55,55,55,55,55,55,55,55,55,55,55,55,55,55,55,55,55,55,55,55,55,55,55,55,55,55,55,55,55,55,55,55,55,55,55,55,55,55,55,55,55,55,55,55,55,55,55,55,55,1,237
237,1,55,55,55,55,55,55,55,55,55,55,55,55,55,55,55,55,55,55,55,55,55,55,55,55,55,55,55,55,55,55,55,55,55,55,55,55,55,55,55,55,55,55,55,55,55,55,55,55,55,1,237
45,1,55,55,55,55,55,55,55,55,55,55,55,55,55,55,55,55,55,55,55,55,55,55,55,55,55,55,55,55,55,55,55,55,55,55,55,55,55,55,55,55,55,55,55,55,55,55,55,55,55,1,45
0,46,1,1,1,1,1,1,1,1,1,46,1,1,1,1,1,1,1,1,1,1,1,1,1,1,1,1,1,1,1,1,1,1,1,1,1,1,1,1,1,46,1,1,1,1,1,1,1,1,1,46,0
0,0,0,1,1,1,0,0,0,0,0,1,145,145,145,145,145,145,145,145,145,145,145,145,145,145,145,145,145,145,145,145,145,145,145,145,145,145,145,145,145,1,0,0,0,0,0,1,1,1,0,0,0
0,0,0,22,1,20,0,0,0,0,0,1,0,0,0,0,0,0,0,0,255,0,0,0,0,0,0,0,0,0,0,0,255,0,0,0,0,0,0,0,0,1,0,0,0,0,0,22,1,20,0,0,0
0,0,0,22,1,20,0,0,0,0,253,1,0,0,0,0,0,0,0,256,46,258,0,46,46,46,46,46,46,46,0,256,46,258,0,0,0,0,0,0,0,1,253,0,0,0,0,22,1,20,0,0,0
0,0,0,1,1,1,0,0,0,0,1,1,0,0,0,0,0,0,0,0,257,0,238,1,260,0,0,0,259,1,239,0,257,0,0,0,0,0,0,0,0,1,1,0,0,0,0,1,1,1,0,0,0
0,0,0,22,1,20,0,0,0,0,1,1,0,0,0,0,0,0,0,0,0,0,238,1,260,0,261,0,259,1,239,0,0,0,0,0,0,0,0,0,0,1,1,0,0,0,0,22,1,20,0,0,0
0,0,0,22,1,20,0,0,0,46,1,46,258,0,0,0,0,0,0,0,255,0,238,1,260,0,0,0,259,1,239,0,255,0,0,0,0,0,0,0,256,46,1,46,0,0,0,22,1,20,0,0,0
0,0,0,1,1,1,0,0,0,1,0,257,0,0,0,0,0,0,0,256,46,258,238,1,1,0,0,0,1,1,239,256,46,258,0,0,0,0,0,0,0,257,0,1,0,0,0,1,1,1,0,0,0
0,0,0,22,1,20,0,0,56,5,0,0,0,0,0,0,0,0,0,0,257,0,0,0,0,0,0,0,0,0,0,0,257,0,0,0,0,0,0,0,0,0,0,5,56,0,0,22,1,20,0,0,0
0,0,0,22,1,20,0,0,56,17,0,0,0,0,0,0,0,0,0,0,0,0,0,0,0,0,0,0,0,0,0,0,0,0,0,0,0,0,0,0,0,0,0,17,56,0,0,22,1,20,0,0,0
0,0,0,1,1,1,0,0,56,5,0,0,0,0,0,0,0,0,0,0,255,0,0,0,0,0,0,0,0,0,0,0,255,0,0,0,0,0,0,0,0,0,0,5,56,0,0,1,1,1,0,0,0
0,0,0,22,1,20,0,0,0,1,0,255,0,0,0,0,0,0,0,256,46,258,0,0,0,0,0,0,0,0,0,256,46,258,0,0,0,0,0,0,0,255,0,1,0,0,0,22,1,20,0,0,0
0,0,0,22,1,20,0,0,0,46,1,46,258,0,0,0,0,0,0,0,257,0,0,0,0,0,0,0,0,0,0,0,257,0,0,0,0,0,0,0,256,46,1,46,0,0,0,22,1,20,0,0,0
0,0,0,1,1,1,0,0,0,0,0,1,0,0,0,0,0,0,0,0,0,0,0,0,0,0,0,0,0,0,0,0,0,0,0,0,0,0,0,0,0,1,0,0,0,0,0,1,1,1,0,0,0
0,0,0,22,1,20,0,0,0,0,56,17,0,0,0,0,0,0,0,0,255,0,0,0,0,0,252,0,0,0,0,0,255,0,0,0,0,0,0,0,0,17,56,0,0,0,0,22,1,20,0,0,0
0,0,0,22,1,20,0,0,0,0,56,17,0,0,0,0,0,0,0,256,46,258,0,0,0,252,45,252,0,0,0,256,46,258,0,0,0,0,0,0,0,17,56,0,0,0,0,22,1,20,0,0,0
0,0,0,1,1,1,0,0,0,0,0,1,0,0,0,0,0,0,0,0,257,0,0,0,0,0,252,0,0,0,0,0,257,0,0,0,0,0,0,0,0,1,0,0,0,0,0,1,1,1,0,0,0
0,0,0,22,1,20,0,0,0,0,56,17,0,0,0,0,0,0,0,0,0,0,0,0,0,0,0,0,0,0,0,0,0,0,0,0,0,0,0,0,0,17,56,0,0,0,0,22,1,20,0,0,0
0,0,0,22,1,20,0,0,0,0,56,17,0,0,0,0,0,0,0,0,255,0,0,0,0,0,0,0,0,0,0,0,255,0,0,0,0,0,0,0,0,17,56,0,0,0,0,22,1,20,0,0,0
0,0,0,1,1,1,0,0,0,0,0,1,0,0,0,255,0,0,0,256,46,258,0,0,0,0,252,0,0,0,0,256,46,258,0,0,0,255,0,0,0,1,0,0,0,0,0,1,1,1,0,0,0
0,0,0,22,1,20,0,0,0,0,0,46,1,17,1,46,258,0,0,0,257,0,0,0,0,252,45,252,0,0,0,0,257,0,0,0,256,46,1,17,1,46,0,0,0,0,0,22,1,20,0,0,0
0,0,0,22,1,20,0,0,0,0,0,0,0,56,0,1,0,0,0,0,0,0,0,0,0,0,252,0,0,0,0,0,0,0,0,0,0,1,0,56,0,0,0,0,0,0,0,22,1,20,0,0,0
0,0,0,1,1,1,0,0,0,0,0,0,0,0,56,17,0,0,0,0,0,0,0,0,0,0,0,0,0,0,0,0,0,0,0,0,0,17,56,0,0,0,0,0,0,0,0,1,1,1,0,0,0
0,0,0,22,1,20,0,0,0,0,0,0,0,0,0,1,0,0,0,0,0,255,0,0,0,0,0,0,0,0,0,255,0,0,0,0,0,1,0,0,0,0,0,0,0,0,0,22,1,20,0,0,0
0,0,0,22,1,20,0,0,0,0,0,0,0,0,0,46,1,5,17,5,1,46,1,1,1,1,1,1,1,1,1,46,1,5,17,5,1,46,0,0,0,0,33,0,0,0,0,22,1,20,0,0,0
0,0,0,1,1,1,0,0,0,0,0,0,0,0,0,0,0,56,56,56,0,5,5,89,237,237,45,237,237,90,5,5,0,56,56,56,0,0,0,0,0,0,0,0,0,0,0,1,1,1,0,0,0
0,0,0,22,1,20,0,0,0,0,0,0,33,0,0,0,0,0,0,0,0,0,0,0,0,0,0,0,0,0,0,0,0,0,0,0,0,0,0,0,0,0,0,0,0,0,0,22,1,20,0,0,0
0,0,0,22,1,20,0,0,0,0,0,0,0,0,0,0,0,0,0,0,0,0,0,0,0,0,0,0,0,0,0,0,0,0,0,0,0,0,0,0,0,0,0,0,0,0,0,22,1,20,0,0,0
0,0,0,1,1,1,0,0,0,0,0,0,0,0,0,0,0,33,0,0,0,0,0,0,0,0,0,0,0,0,0,0,0,0,33,0,0,0,0,0,0,0,0,0,0,0,0,1,1,1,0,0,0
0,0,46,46,46,46,46,0,0,0,0,0,0,0,0,0,0,0,0,0,0,0,0,0,0,0,0,0,0,0,0,0,0,0,0,0,0,0,0,0,0,0,33,0,0,0,46,46,46,46,46,0,0
0,0,46,1,1,1,46,0,0,0,0,0,0,0,0,0,0,0,0,0,0,0,0,0,0,0,0,0,0,0,0,0,0,0,0,0,0,0,0,0,0,0,0,0,0,0,46,1,1,1,46,0,0
0,0,46,1,1,30,46,0,0,0,0,0,0,0,0,0,0,0,0,0,55,55,55,55,55,55,55,55,55,55,55,55,55,0,0,0,0,0,0,0,0,0,0,0,0,0,46,27,1,1,46,0,0
0,0,46,1,1,1,46,85,1,85,85,1,85,85,1,85,85,1,85,85,55,87,87,87,87,87,87,87,87,87,87,87,55,85,85,1,85,85,1,85,85,1,85,85,1,85,46,1,1,1,46,0,0
0,244,46,46,46,1,1,1,1,1,1,1,1,1,1,1,1,1,1,1,55,89,244,244,244,244,237,244,244,244,244,90,55,1,1,1,1,1,1,1,1,1,1,1,1,1,1,1,46,46,46,244,0
0,90,46,0,46,1,16,16,1,16,16,1,16,16,1,16,16,1,16,16,55,89,189,189,189,189,189,189,189,189,189,90,55,16,16,1,16,16,1,16,16,1,16,16,1,16,16,1,46,0,46,89,0
0,244,46,46,46,244,0,0,0,0,0,0,0,0,0,0,0,0,0,238,55,55,55,55,55,55,55,55,55,55,55,55,55,239,0,0,0,0,0,0,0,0,0,0,0,0,0,244,46,46,46,244,0
0,0,244,87,244,0,0,0,0,0,0,0,0,0,0,0,0,0,0,0,254,244,254,244,254,244,254,244,254,244,254,244,254,0,0,0,0,0,0,0,0,0,0,0,0,0,0,0,244,87,244,0,0
0,0,0,0,0,0,0,0,0,0,0,0,0,0,0,0,0,0,0,0,0,0,0,0,0,0,0,0,0,0,0,0,0,0,0,0,0,0,0,0,0,0,0,0,0,0,0,0,0,0,0,0,0
:endlayer
layer: 11
0,0,0,0,0,0,0,0,0,0,0,0,0,0,0,0,0,0,0,0,0,0,0,0,0,0,0,0,0,0,0,0,0,0,0,0,0,0,0,0,0,0,0,0,0,0,0,0,0,0,0,0,0
0,0,56,0,0,56,0,0,56,0,0,56,0,0,56,0,0,56,0,0,56,0,56,0,0,0,0,0,0,0,56,0,56,0,0,56,0,0,56,0,0,56,0,0,56,0,0,56,0,0,56,0,0
0,46,1,253,253,1,253,253,1,253,253,1,253,253,1,253,253,1,253,253,1,88,85,85,88,85,85,85,88,85,85,88,1,253,253,1,253,253,1,253,253,1,253,253,1,253,253,1,253,253,1,46,0
56,1,292,301,301,292,100,292,301,301,292,1,274,274,274,122,302,302,120,274,274,274,100,307,274,306,305,304,274,303,100,274,274,274,122,302,302,120,274,274,274,1,292,301,301,292,100,292,301,301,292,1,56
0,22,292,296,296,292,300,292,296,296,292,1,100,0,0,0,0,0,0,0,0,0,0,0,274,0,299,0,274,298,0,0,0,0,0,0,0,0,0,0,100,1,292,296,296,292,297,292,296,296,292,20,0
0,22,292,292,292,292,0,292,292,292,292,0,0,0,0,0,295,0,294,0,0,0,0,30,274,27,0,30,274,27,0,0,0,0,0,0,293,0,0,0,0,0,292,292,292,292,0,292,292,292,292,20,0
56,1,100,1,27,0,0,0,0,291,0,290,0,0,0,0,156,156,156,0,0,289,0,0,275,0,0,0,275,0,0,0,0,0,0,156,156,156,0,0,0,288,0,287,0,0,0,0,30,1,100,1,56
0,22,286,0,0,0,0,0,0,0,0,0,0,0,0,0,156,156,156,0,0,0,0,0,0,0,285,0,0,0,0,0,0,0,0,156,156,156,0,0,0,0,0,0,0,0,0,0,0,0,284,20,0
0,22,283,0,0,0,0,0,0,156,156,1,100,0,0,0,0,282,0,280,281,0,0,146,1,1,1,1,1,143,0,0,0,280,0,0,279,278,0,0,100,1,156,156,277,0,0,0,0,0,276,20,0
56,1,100,0,0,0,156,0,0,156,156,1,274,274,274,274,274,274,274,274,275,0,0,146,1,1,1,1,1,143,0,0,275,274,274,274,274,274,274,274,274,1,156,156,273,0,156,0,0,0,100,1,56
0,46,1,5,81,5,1,79,79,79,1,46,1,1,1,1,1,1,1,1,1,1,1,1,1,1,1,1,1,1,1,1,1,1,1,1,1,1,1,1,1,46,1,79,79,79,1,5,81,5,1,46,0
0,0,0,22,0,20,0,0,0,0,0,1,55,55,55,55,55,55,55,55,55,55,55,55,55,55,55,55,55,55,55,55,55,55,55,55,55,55,55,55,55,1,0,0,0,0,0,22,0,20,0,0,0
0,0,0,21,0,21,0,0,0,0,0,1,55,55,55,55,55,55,55,55,55,55,55,55,55,55,55,55,55,55,55,55,55,55,55,55,55,55,55,55,55,1,0,0,0,0,0,21,0,21,0,0,0
0,0,0,21,0,21,0,0,0,0,0,1,55,55,55,55,55,55,55,55,55,46,46,46,55,55,55,55,55,46,46,46,55,55,55,55,55,55,55,55,55,1,0,0,0,0,0,21,0,21,0,0,0
0,0,0,22,0,20,0,0,0,0,253,1,55,55,55,55,55,55,55,55,55,46,55,260,0,0,0,0,0,259,55,46,55,55,55,55,55,55,55,55,55,1,253,0,0,0,0,22,0,20,0,0,0
0,0,0,21,0,21,0,0,0,0,1,1,55,55,55,55,55,55,55,55,55,46,55,260,0,0,0,0,0,259,55,46,55,55,55,55,55,55,55,55,55,1,1,0,0,0,0,21,0,21,0,0,0
0,0,0,21,0,21,0,0,0,55,55,55,55,55,55,55,55,55,55,55,55,46,55,260,0,0,0,0,0,259,55,46,55,55,55,55,55,55,55,55,55,55,55,55,0,0,0,21,0,21,0,0,0
0,0,0,22,0,20,0,0,0,55,55,55,55,55,55,55,55,55,55,55,55,46,1,1,143,0,0,0,146,1,1,46,55,55,55,55,55,55,55,55,55,55,55,55,0,0,0,22,0,20,0,0,0
0,0,0,21,0,21,0,0,0,55,55,55,55,55,55,55,55,55,55,55,55,46,239,0,0,0,0,0,0,0,238,46,55,55,55,55,55,55,55,55,55,55,55,55,0,0,0,21,0,21,0,0,0
0,0,0,21,272,21,0,0,0,55,55,55,55,55,55,55,55,55,55,55,55,46,239,0,0,0,0,0,0,0,238,46,55,55,55,55,55,55,55,55,55,55,55,55,0,0,0,21,0,21,0,0,0
0,0,0,22,0,20,0,0,0,55,55,55,55,55,55,55,55,55,55,55,55,46,239,0,0,0,0,0,0,0,238,46,55,55,55,55,55,55,55,55,55,55,55,55,0,0,0,22,271,20,0,0,0
0,0,0,21,0,21,0,0,0,55,55,55,55,55,55,55,55,55,55,55,55,46,270,270,0,0,0,0,0,270,270,46,55,55,55,55,55,55,55,55,55,55,55,55,0,0,0,21,0,21,0,0,0
0,0,0,21,0,21,0,0,0,55,55,55,55,55,55,55,55,55,55,55,55,46,46,239,0,0,0,0,0,238,46,46,55,55,55,55,55,55,55,55,55,55,55,55,0,0,0,21,0,21,0,0,0
0,0,0,22,0,20,0,0,0,0,0,55,55,55,55,55,55,55,55,55,55,55,46,239,270,270,270,270,270,238,46,55,55,55,55,55,55,55,55,55,55,55,0,0,0,0,0,22,0,20,0,0,0
0,0,0,21,0,21,0,0,0,0,0,55,55,55,55,55,55,55,55,55,55,55,46,46,46,46,46,46,46,46,46,55,55,55,55,55,55,55,55,55,55,55,0,0,0,0,0,21,0,21,0,0,0
0,0,0,21,0,21,0,0,0,0,0,55,55,55,55,55,55,55,55,55,55,55,55,55,46,65,65,65,46,55,55,55,55,55,55,55,55,55,55,55,55,55,0,0,0,0,0,21,0,21,0,0,0
0,0,0,22,0,20,0,0,0,0,0,55,55,55,55,55,55,55,55,55,55,55,55,55,46,65,55,65,46,55,55,55,55,55,55,55,55,55,55,55,55,55,0,0,0,0,0,22,0,20,0,0,0
0,0,0,21,0,21,0,0,0,0,0,55,55,55,55,55,55,55,55,55,55,55,55,55,46,65,55,65,46,55,55,55,55,55,55,55,55,55,55,55,55,55,0,0,0,0,0,21,0,21,0,0,0
0,0,0,21,0,21,0,0,0,0,0,55,55,55,55,55,55,55,55,55,55,55,55,55,46,65,55,65,46,55,55,55,55,55,55,55,55,55,55,55,55,55,0,0,0,0,0,21,0,21,0,0,0
0,0,0,22,0,20,0,0,0,0,0,55,55,55,55,55,55,55,55,55,55,55,55,55,46,65,55,65,46,55,55,55,55,55,55,55,55,55,55,55,55,55,0,0,0,0,0,22,0,20,0,0,0
0,0,0,21,269,21,0,0,0,0,0,46,55,55,55,46,55,55,55,55,55,55,55,55,46,65,55,65,46,55,55,55,55,55,55,55,55,46,55,55,55,46,0,0,0,0,0,21,0,21,0,0,0
0,0,0,21,0,21,0,0,0,0,0,0,0,0,0,55,55,55,55,55,55,55,55,55,46,65,55,65,46,55,55,55,55,55,55,55,55,55,0,0,0,0,0,0,0,0,0,21,0,21,0,0,0
0,0,0,22,0,20,0,0,0,0,0,0,0,0,0,55,55,55,55,55,55,55,55,55,46,65,55,65,46,55,55,55,55,55,55,55,55,55,0,0,0,0,0,0,0,0,0,22,0,20,0,0,0
0,0,0,21,0,21,0,0,0,0,0,0,0,0,0,55,55,55,55,55,55,55,55,55,46,65,65,65,46,55,55,55,55,55,55,55,55,55,0,0,0,0,0,0,0,0,0,21,0,21,0,0,0
0,0,0,21,0,21,0,0,0,0,0,0,0,0,0,46,55,55,55,55,55,55,55,55,55,55,55,55,55,55,55,55,55,55,55,55,55,46,0,0,0,0,33,0,0,0,0,21,0,21,0,0,0
0,0,0,22,0,20,0,0,0,0,0,0,0,0,0,0,0,0,0,0,0,0,5,5,5,5,5,5,5,5,5,0,0,0,0,0,0,0,0,0,0,0,0,0,0,0,0,22,268,20,0,0,0
0,0,0,21,0,21,0,0,0,0,0,0,0,0,0,0,0,0,0,0,0,0,0,0,0,0,0,0,0,0,0,0,0,0,0,0,0,0,0,0,0,0,0,0,0,0,0,21,0,21,0,0,0
0,0,0,21,0,21,0,0,0,0,0,0,33,0,0,0,0,0,0,0,0,0,0,0,0,0,0,0,0,0,0,0,0,0,0,0,0,0,0,0,0,0,0,0,0,0,0,21,0,21,0,0,0
0,0,0,22,0,20,0,0,0,0,0,0,0,0,0,0,0,0,0,0,0,0,0,0,0,0,0,0,0,0,0,0,0,0,0,0,0,0,0,0,0,0,0,0,0,0,0,22,0,20,0,0,0
0,0,5,85,21,85,5,0,0,0,0,0,0,0,0,0,0,33,0,0,0,0,0,0,0,0,0,0,0,0,0,0,0,0,33,0,0,0,0,0,0,0,33,0,0,0,5,85,21,85,5,0,0
0,0,22,267,21,21,20,0,0,0,0,0,0,0,0,0,0,0,0,0,0,0,0,0,0,0,0,0,0,0,0,0,0,0,0,0,0,0,0,0,0,0,0,0,0,0,22,21,21,266,20,0,0
0,0,5,5,20,30,5,0,0,0,0,0,0,0,0,0,0,0,0,0,1,85,1,85,1,85,1,85,1,85,1,85,1,0,0,0,0,0,0,0,0,0,0,0,0,0,5,27,22,5,5,0,0
0,0,22,21,21,21,21,21,85,21,21,85,21,21,85,21,21,85,21,21,1,21,21,21,21,21,265,21,21,21,21,21,1,21,21,85,21,21,85,21,21,85,21,21,85,21,21,21,21,21,20,0,0
0,56,5,5,5,0,0,0,0,0,264,0,0,0,0,0,0,0,0,0,0,0,0,0,0,0,0,0,0,0,0,0,0,0,0,0,0,0,0,0,263,0,0,0,0,0,0,0,5,5,5,56,0
0,21,5,0,5,16,21,21,16,21,21,16,21,21,16,21,21,16,21,21,1,21,21,21,21,21,262,21,21,21,21,21,1,21,21,16,21,21,16,21,21,16,21,21,16,21,21,16,5,0,5,21,0
0,56,5,5,5,56,0,0,0,0,0,0,0,0,0,0,0,0,0,0,46,16,46,16,46,16,46,16,46,16,46,16,46,0,0,0,0,0,0,0,0,0,0,0,0,0,0,56,5,5,5,56,0
0,0,56,21,56,0,0,0,0,0,0,0,0,0,0,0,0,0,0,0,0,0,0,0,0,0,0,0,0,0,0,0,0,0,0,0,0,0,0,0,0,0,0,0,0,0,0,0,56,21,56,0,0
0,0,0,0,0,0,0,0,0,0,0,0,0,0,0,0,0,0,0,0,0,0,0,0,0,0,0,0,0,0,0,0,0,0,0,0,0,0,0,0,0,0,0,0,0,0,0,0,0,0,0,0,0
:endlayer
layer: 12
0,0,0,0,0,0,0,0,0,0,0,0,0,0,0,0,0,0,0,0,0,0,0,0,0,0,0,0,0,0,0,0,0,0,0,0,0,0,0,0,0,0,0,0,0,0,0,0,0,0,0,0,0
0,0,0,0,0,0,0,0,0,0,0,0,0,0,0,0,0,0,0,0,0,0,0,0,0,0,0,0,0,0,0,0,0,0,0,0,0,0,0,0,0,0,0,0,0,0,0,0,0,0,0,0,0
0,46,1,190,190,1,190,190,1,190,190,1,190,190,1,190,190,1,190,190,1,1,190,190,1,190,190,190,1,190,190,1,1,190,190,1,190,190,1,190,190,1,190,190,1,190,190,1,190,190,1,46,0
0,1,0,0,0,0,198,0,0,0,0,1,0,0,275,0,0,275,0,0,275,275,198,0,274,0,323,0,274,0,198,275,275,0,0,275,0,0,275,0,0,1,0,0,0,0,198,0,0,0,0,1,0
0,190,0,0,0,0,0,0,0,0,0,1,198,0,0,0,0,0,0,0,0,0,0,0,274,0,0,0,274,0,0,0,0,0,0,0,0,0,0,0,198,1,0,0,0,0,0,0,0,0,0,190,0
0,190,0,0,0,0,0,0,0,0,0,0,0,0,0,0,322,0,321,0,0,0,0,30,274,27,0,30,274,27,0,0,0,0,0,0,320,0,0,0,0,0,0,0,0,0,0,0,0,0,0,190,0
0,1,198,1,27,0,0,0,0,0,0,0,0,0,0,0,0,0,0,0,0,0,0,0,275,0,0,0,275,0,0,0,0,0,0,0,0,0,0,0,0,0,0,0,0,0,0,0,30,1,198,1,0
0,190,0,0,0,0,0,0,0,0,0,0,0,0,0,0,0,0,0,0,0,0,0,0,0,0,0,0,0,0,0,0,0,0,0,0,0,0,0,0,0,0,0,0,0,0,0,0,0,0,0,190,0
0,190,0,0,0,0,0,0,0,0,0,1,198,0,0,0,0,319,0,280,0,0,0,0,146,1,1,1,143,0,0,0,0,280,0,0,318,317,0,0,198,1,0,0,316,0,0,0,0,0,0,190,0
0,1,198,0,0,0,315,0,0,0,0,1,274,274,274,274,274,274,274,274,275,0,0,0,146,1,1,1,143,0,0,0,275,274,274,274,274,274,274,274,274,1,0,0,314,0,313,0,0,0,198,1,0
0,46,1,5,91,5,1,190,190,190,1,46,1,1,1,1,1,1,1,1,1,1,1,1,1,1,1,1,1,1,1,1,1,1,1,1,1,1,1,1,1,46,1,190,190,190,1,5,144,5,1,46,0
0,0,0,0,0,0,0,0,0,0,0,1,55,55,55,55,55,55,55,55,55,55,55,55,55,55,55,55,55,55,55,55,55,55,55,55,55,55,55,55,55,1,0,0,0,0,0,0,0,0,0,0,0
0,0,0,0,0,0,0,0,0,0,0,1,55,55,55,55,55,55,312,312,55,55,55,55,55,55,55,55,55,55,55,55,55,312,312,55,55,55,55,55,55,1,0,0,0,0,0,0,0,0,0,0,0
0,0,0,0,0,0,0,0,0,0,0,1,55,55,55,55,55,46,312,223,312,46,46,46,46,46,46,46,46,46,46,46,312,223,312,46,55,55,55,55,55,1,0,0,0,0,0,0,0,0,0,0,0
0,0,0,0,0,0,0,0,0,0,0,1,55,55,55,55,55,46,312,223,223,312,260,0,0,0,240,0,0,0,259,312,223,223,312,46,55,55,55,55,55,1,0,0,0,0,0,0,0,0,0,0,0
0,0,0,0,0,0,0,0,0,0,253,1,55,55,55,55,55,46,312,223,223,312,260,0,0,0,0,0,0,0,259,312,223,223,312,46,55,55,55,55,55,1,253,0,0,0,0,0,0,0,0,0,0
0,0,0,0,0,0,0,0,0,1,1,1,55,55,55,55,55,55,312,223,223,312,260,0,0,0,0,0,0,0,259,312,223,223,312,55,55,55,55,55,55,1,1,1,0,0,0,0,0,0,0,0,0
0,0,0,0,0,0,0,0,0,1,1,1,55,55,55,55,55,55,55,223,223,312,1,143,0,0,0,0,0,146,1,312,223,223,55,55,55,55,55,55,55,1,1,1,0,0,0,0,0,0,0,0,0
0,0,0,0,0,0,0,0,0,1,1,1,55,55,55,55,55,55,312,223,223,312,1,0,0,0,0,0,0,0,1,312,223,223,312,55,55,55,55,55,55,1,1,1,0,0,0,0,0,0,0,0,0
0,0,0,0,0,0,0,0,0,1,1,1,55,55,55,55,55,55,312,223,223,312,1,0,0,0,0,0,0,0,1,312,223,223,312,55,55,55,55,55,55,1,1,1,0,0,0,0,0,0,0,0,0
0,0,0,0,0,0,0,0,0,1,1,1,55,55,55,55,55,55,55,223,223,312,1,0,0,0,0,0,0,0,1,312,223,223,55,55,55,55,55,55,55,1,1,1,0,0,0,0,0,0,0,0,0
0,0,0,0,0,0,0,0,0,1,1,1,55,55,55,55,55,55,312,223,223,312,312,1,0,0,0,0,0,1,312,312,223,223,312,55,55,55,55,55,55,1,1,1,0,0,0,0,0,0,0,0,0
0,0,0,0,0,0,0,0,0,1,1,1,55,55,55,55,55,46,312,223,223,223,312,1,0,0,130,0,0,1,312,223,223,223,312,46,55,55,55,55,55,1,1,1,0,0,0,0,0,0,0,0,0
0,0,0,0,0,0,0,0,0,0,0,1,55,55,55,55,55,46,312,223,223,223,312,312,1,1,1,1,1,312,312,223,223,223,312,46,55,55,55,55,55,1,0,0,0,0,0,0,0,0,0,0,0
0,0,0,0,0,0,0,0,0,0,0,1,55,55,55,55,55,55,312,223,312,223,223,312,312,312,312,312,312,312,223,223,312,223,312,55,55,55,55,55,55,1,0,0,0,0,0,0,0,0,0,0,0
0,0,0,0,0,0,0,0,0,0,0,1,55,55,55,55,55,55,55,223,312,223,223,223,223,223,223,223,223,223,223,223,312,223,55,55,55,55,55,55,55,1,0,0,0,0,0,0,0,0,0,0,0
0,0,0,0,0,0,0,0,0,0,0,1,55,55,55,55,55,55,312,223,223,312,223,4,312,4,223,4,312,4,223,312,223,223,312,55,55,55,55,55,55,1,0,0,0,0,0,0,0,0,0,0,0
0,0,0,0,0,0,0,0,0,0,0,1,55,55,55,55,55,55,312,223,223,223,4,312,223,312,4,312,223,312,4,223,223,223,312,55,55,55,55,55,55,1,0,0,0,0,0,0,0,0,0,0,0
0,0,0,0,0,0,0,0,0,0,0,1,55,55,55,55,55,55,312,312,223,223,223,4,312,4,4,4,312,4,223,223,223,312,312,55,55,55,55,55,55,1,0,0,0,0,0,0,0,0,0,0,0
0,0,0,0,0,0,0,0,0,0,0,1,55,55,55,55,55,55,9,312,312,223,223,223,223,223,223,223,223,223,223,223,312,312,9,55,55,55,55,55,55,1,0,0,0,0,0,0,0,0,0,0,0
0,0,0,0,0,0,0,0,0,0,0,46,1,1,1,46,55,55,55,9,312,312,312,223,223,223,223,223,223,223,312,312,312,9,55,55,55,46,1,1,1,46,0,0,0,0,0,0,0,0,0,0,0
0,0,0,0,0,0,0,0,0,0,0,0,0,0,0,1,9,9,9,9,9,9,312,312,312,312,312,312,312,312,312,9,9,9,9,9,9,1,0,0,0,0,0,0,0,0,0,0,0,0,0,0,0
0,0,0,0,0,0,0,0,0,0,0,0,0,0,0,1,9,9,9,9,9,9,9,9,9,9,9,9,9,9,9,9,9,9,9,9,9,1,0,0,0,0,0,0,0,0,0,0,0,0,0,0,0
0,0,0,0,0,0,0,0,0,0,0,0,0,0,0,1,9,9,9,9,9,9,9,9,9,9,9,9,9,9,9,9,9,9,9,9,9,1,0,0,0,0,0,0,0,0,0,0,0,0,0,0,0
0,0,0,0,0,0,0,0,0,0,0,0,0,0,0,46,1,1,1,1,1,1,1,1,1,1,1,1,1,1,1,1,1,1,1,1,1,46,0,0,0,0,33,0,0,0,0,0,0,0,0,0,0
0,0,0,0,0,0,0,0,0,0,0,0,0,0,0,0,0,0,0,0,0,0,0,0,0,0,0,0,0,0,0,0,0,0,0,0,0,0,0,0,0,0,0,0,0,0,0,0,0,0,0,0,0
0,0,0,0,0,0,0,0,0,0,0,0,0,0,0,0,0,0,0,0,0,0,0,0,0,0,0,0,0,0,0,0,0,0,0,0,0,0,0,0,0,0,0,0,0,0,0,0,0,0,0,0,0
0,0,0,0,0,0,0,0,0,0,0,0,33,0,0,0,0,0,0,0,0,0,0,0,0,0,0,0,0,0,0,0,0,0,0,0,0,0,0,0,0,0,0,0,0,0,0,0,0,0,0,0,0
0,0,0,0,0,0,0,0,0,0,0,0,0,0,0,0,0,0,0,0,0,0,0,0,0,0,0,0,0,0,0,0,0,0,0,0,0,0,0,0,0,0,0,0,0,0,0,0,0,0,0,0,0
0,0,21,0,0,0,21,0,0,0,0,0,0,0,0,0,0,33,0,0,0,0,0,0,0,0,0,0,0,0,0,0,0,0,33,0,0,0,0,0,0,0,33,0,0,0,21,0,0,0,21,0,0
0,0,0,0,0,0,0,0,0,0,0,0,0,0,0,0,0,0,0,0,0,0,0,0,0,0,0,0,0,0,0,0,0,0,0,0,0,0,0,0,0,0,0,0,0,0,0,0,0,0,0,0,0
0,0,21,0,0,0,21,0,0,0,0,0,0,0,0,0,0,0,0,0,1,45,1,45,1,45,1,45,1,45,1,45,1,0,0,0,0,0,0,0,0,0,0,0,0,0,21,0,0,0,21,0,0
0,0,0,0,311,0,0,0,0,0,0,0,0,0,0,0,0,0,0,0,1,0,0,0,0,0,265,0,0,0,0,0,1,0,0,0,0,0,0,0,0,0,0,0,0,0,0,0,310,0,0,0,0
0,0,1,85,1,0,0,0,0,0,0,0,0,0,0,0,0,0,0,0,0,0,0,0,0,0,0,0,0,0,0,0,0,0,0,0,0,0,0,0,0,0,0,0,0,0,0,0,1,85,1,0,0
0,0,22,0,20,0,0,0,0,0,0,0,0,0,0,0,0,0,0,0,1,0,0,309,0,0,0,0,0,308,0,0,1,0,0,0,0,0,0,0,0,0,0,0,0,0,0,0,22,0,20,0,0
0,0,1,16,1,0,0,0,0,0,0,0,0,0,0,0,0,0,0,0,1,0,1,0,1,0,1,0,1,0,1,0,1,0,0,0,0,0,0,0,0,0,0,0,0,0,0,0,1,16,1,0,0
0,0,0,0,0,0,0,0,0,0,0,0,0,0,0,0,0,0,0,0,0,0,0,0,0,0,0,0,0,0,0,0,0,0,0,0,0,0,0,0,0,0,0,0,0,0,0,0,0,0,0,0,0
0,0,0,0,0,0,0,0,0,0,0,0,0,0,0,0,0,0,0,0,0,0,0,0,0,0,0,0,0,0,0,0,0,0,0,0,0,0,0,0,0,0,0,0,0,0,0,0,0,0,0,0,0
:endlayer
layer: 13
0,0,0,0,0,0,0,0,0,0,0,0,0,0,0,0,0,0,0,0,0,0,0,0,0,0,0,0,0,0,0,0,0,0,0,0,0,0,0,0,0,0,0,0,0,0,0,0,0,0,0,0,0
0,0,0,0,0,0,0,0,0,0,0,0,0,0,0,0,0,0,0,0,0,0,0,0,0,0,0,0,0,0,0,0,0,0,0,0,0,0,0,0,0,0,0,0,0,0,0,0,0,0,0,0,0
0,46,1,190,190,1,190,190,1,190,190,1,190,190,1,190,190,1,190,190,1,1,190,190,1,190,190,190,1,190,190,1,1,190,190,1,190,190,1,190,190,1,190,190,1,190,190,1,190,190,1,46,0
0,1,0,0,0,0,198,0,0,0,0,1,0,0,275,0,0,275,0,0,275,275,198,0,274,0,0,0,274,0,198,275,275,0,0,275,0,0,275,0,0,1,0,0,0,0,198,0,0,0,0,1,0
0,190,0,0,0,0,0,0,0,0,0,1,199,0,0,0,0,0,0,0,0,0,0,0,274,0,0,0,274,0,0,0,0,0,0,0,0,0,0,0,199,1,0,0,0,0,0,0,0,0,0,190,0
0,190,0,0,0,0,0,0,0,0,0,254,0,0,0,0,0,0,0,0,0,0,0,30,274,27,0,30,274,27,0,0,0,0,0,0,0,0,0,0,0,254,0,0,0,0,0,0,0,0,0,190,0
0,1,198,1,27,0,0,0,0,0,0,0,0,0,0,0,0,0,0,0,0,0,0,0,275,0,0,0,275,0,0,0,0,0,0,0,0,0,0,0,0,0,0,0,0,0,0,0,30,1,198,1,0
0,190,0,0,0,0,0,0,0,0,0,270,0,0,0,0,0,0,0,0,0,0,0,0,0,0,0,0,0,0,0,0,0,0,0,0,0,0,0,0,0,270,0,0,0,0,0,0,0,0,0,190,0
0,190,0,0,0,0,0,0,0,0,0,1,198,0,0,0,0,0,0,280,0,0,0,0,0,0,0,0,0,0,0,0,0,280,0,0,0,0,0,0,198,1,0,0,0,0,0,0,0,0,0,190,0
0,1,198,0,0,0,0,0,0,0,0,1,274,274,274,274,274,274,274,274,275,0,0,0,0,0,0,0,0,0,0,0,275,274,274,274,274,274,274,274,274,1,0,0,0,0,0,0,0,0,198,1,0
0,46,1,5,16,5,1,190,190,190,1,46,1,1,1,1,1,1,1,1,1,1,1,1,1,0,0,0,1,1,1,1,1,1,1,1,1,1,1,1,1,46,1,190,190,190,1,5,16,5,1,46,0
0,0,0,0,0,0,0,0,0,0,0,223,376,367,367,376,375,1,46,0,0,0,0,0,0,0,374,0,0,0,0,0,0,0,46,1,373,112,105,105,112,223,0,0,0,0,0,0,0,0,0,0,0
0,0,0,0,0,0,0,0,0,0,0,146,367,371,370,367,0,1,0,0,0,0,0,0,0,0,0,0,0,0,0,0,0,0,0,1,0,105,372,372,105,143,0,0,0,0,0,0,0,0,0,0,0
0,0,0,0,0,0,0,0,0,0,0,146,367,371,370,367,369,0,0,0,0,1,238,46,239,239,1,238,238,46,239,1,0,0,0,0,0,105,368,368,105,143,0,0,0,0,0,0,0,0,0,0,0
0,0,0,0,0,0,0,0,0,0,0,223,366,367,367,366,0,0,0,0,0,0,0,0,0,0,0,0,0,0,0,0,0,0,0,0,0,103,105,105,103,223,0,0,0,0,0,0,0,0,0,0,0
0,0,0,0,0,0,0,0,0,0,0,146,365,0,0,0,0,0,0,0,0,0,0,0,0,0,0,0,0,0,0,0,0,0,0,0,0,0,364,0,0,143,0,0,0,0,0,0,0,0,0,0,0
0,0,0,0,0,0,0,0,0,88,0,146,363,0,0,0,0,1,0,0,0,0,0,0,0,0,0,0,0,0,0,0,0,0,0,1,0,0,0,362,109,143,0,88,0,0,0,0,0,0,0,0,0
0,0,0,0,0,0,0,0,0,146,0,223,1,1,1,1,1,1,46,0,0,0,1,225,0,0,0,0,0,224,1,0,0,0,46,1,1,1,1,1,1,223,0,143,0,0,0,0,0,0,0,0,0
0,0,0,0,0,0,0,0,0,88,0,31,0,0,0,0,0,0,0,0,361,0,254,0,0,0,0,0,0,0,254,0,360,0,0,0,0,0,0,0,0,32,0,88,0,0,0,0,0,0,0,0,0
0,0,0,0,0,0,0,0,0,146,0,31,0,0,0,0,0,0,0,0,0,0,270,0,0,0,0,0,0,0,270,0,0,0,0,0,0,0,0,0,0,32,0,143,0,0,0,0,0,0,0,0,0
0,0,0,0,0,0,0,0,0,88,0,223,1,1,1,1,1,1,46,0,0,0,1,359,0,0,0,0,0,358,1,0,0,0,46,1,1,1,1,1,1,223,0,88,0,0,0,0,0,0,0,0,0
0,0,0,0,0,0,0,0,0,146,0,146,356,356,0,0,0,1,0,0,0,0,0,254,0,0,0,0,0,254,0,0,0,0,0,1,0,0,0,357,156,143,0,143,0,0,0,0,0,0,0,0,0
0,0,0,0,0,0,0,0,0,88,79,1,356,356,349,349,0,0,0,0,0,0,0,270,355,0,0,0,354,270,0,0,0,0,0,0,0,0,0,0,0,1,79,88,0,0,0,0,0,0,0,0,0
0,0,0,0,0,0,0,0,0,0,0,223,353,352,349,349,0,0,0,0,351,0,0,0,1,239,1,238,1,0,0,0,350,0,0,0,0,165,165,165,0,223,0,0,0,0,0,0,0,0,0,0,0
0,0,0,0,0,0,0,0,0,0,0,146,0,0,349,349,0,1,0,0,0,0,0,0,0,0,0,0,0,0,0,0,0,0,0,1,0,165,165,165,0,143,0,0,0,0,0,0,0,0,0,0,0
0,0,0,0,0,0,0,0,0,0,0,146,0,0,348,0,0,1,46,0,0,0,0,0,0,0,0,0,0,0,0,0,0,0,46,1,0,0,347,0,0,143,0,0,0,0,0,0,0,0,0,0,0
0,0,0,0,0,0,0,0,0,0,0,223,337,338,338,337,0,1,346,0,0,0,0,0,0,0,0,0,0,0,0,0,0,0,346,1,0,333,205,205,331,223,0,0,0,0,0,0,0,0,0,0,0
0,0,0,0,0,0,0,0,0,0,0,146,338,345,345,338,0,1,340,0,0,0,343,343,0,0,344,0,0,343,343,0,0,0,340,1,0,205,342,342,205,143,0,0,0,0,0,0,0,0,0,0,0
0,0,0,0,0,0,0,0,0,0,0,146,338,341,341,338,0,1,340,0,0,0,333,205,0,156,156,156,0,205,331,0,0,0,340,1,0,205,339,339,205,143,0,0,0,0,0,0,0,0,0,0,0
0,0,0,0,0,0,0,0,0,0,0,223,337,338,338,337,336,1,335,0,0,0,333,205,0,156,156,156,0,205,331,0,0,0,335,1,334,333,205,205,331,223,0,0,0,0,0,0,0,0,0,0,0
0,0,0,0,0,0,0,0,0,0,0,46,223,79,223,46,1,1,46,0,0,0,333,205,0,156,156,156,0,205,331,0,0,0,46,1,1,46,223,79,223,46,0,0,0,0,0,0,0,0,0,0,0
0,0,0,0,0,0,0,0,0,0,0,0,0,0,0,223,122,0,0,0,0,0,333,326,0,0,332,0,0,326,331,0,0,0,0,0,120,223,0,0,0,0,325,0,0,0,0,0,0,0,0,0,0
0,0,0,0,0,0,0,0,0,0,0,0,0,0,0,146,330,329,0,0,0,0,0,0,0,205,205,205,0,0,0,0,0,0,0,328,327,143,0,0,325,0,325,0,325,0,0,0,0,0,0,0,0
0,0,0,0,0,0,0,0,0,0,0,0,324,0,0,223,122,0,0,0,100,0,0,0,100,326,326,326,100,0,0,0,100,0,0,0,120,223,0,0,0,0,0,0,0,0,0,0,0,0,0,0,0
0,0,0,0,0,0,0,0,0,325,0,0,325,0,0,46,223,79,79,79,223,79,79,79,223,79,79,79,223,79,79,79,223,79,79,79,223,46,0,325,325,0,33,0,325,325,0,0,0,0,0,0,0
0,0,0,0,0,0,0,0,0,0,325,0,0,0,325,0,0,0,0,0,0,0,0,0,0,0,0,0,0,0,0,0,0,0,0,0,0,0,0,0,0,0,0,0,0,0,0,0,0,0,0,0,0
0,0,0,0,0,0,0,0,0,0,0,0,324,0,0,0,0,0,0,0,0,0,0,0,0,0,0,0,0,0,0,0,0,0,0,0,0,0,0,0,325,0,325,0,325,0,0,0,0,0,0,0,0
0,0,0,0,0,0,0,0,324,325,0,324,33,325,0,325,325,0,0,0,0,0,0,0,0,0,0,0,0,0,0,0,0,0,0,0,0,0,0,0,0,0,324,0,0,0,0,0,0,0,0,0,0
0,0,0,0,0,0,0,0,0,0,0,0,324,0,0,0,0,0,0,0,0,0,0,0,0,0,0,0,0,0,0,0,0,0,0,0,0,0,0,0,0,0,0,0,0,0,0,0,0,0,0,0,0
0,0,0,0,0,0,0,0,0,0,325,0,0,0,325,0,0,33,0,0,0,0,0,0,0,0,0,0,0,0,0,0,0,0,33,0,0,0,0,0,0,0,33,0,0,0,0,0,0,0,0,0,0
0,0,0,0,0,0,0,0,0,325,0,0,325,0,0,325,0,0,0,0,0,0,0,0,0,0,0,0,0,0,0,0,0,0,0,0,0,0,0,0,0,0,0,0,0,0,0,0,0,0,0,0,0
0,0,0,0,0,0,0,0,0,0,0,0,324,0,0,0,0,0,0,0,1,45,1,45,1,45,1,45,1,45,1,45,1,0,0,0,0,0,0,0,0,0,0,0,0,0,0,0,0,0,0,0,0
0,0,0,0,0,0,0,0,0,0,0,0,0,0,0,0,0,0,0,45,1,0,0,0,0,0,265,0,0,0,0,0,1,45,0,0,0,0,0,0,0,0,0,0,0,0,0,0,0,0,0,0,0
0,0,1,189,1,0,0,0,0,0,0,0,0,0,0,0,0,0,0,0,22,0,0,0,0,0,0,0,0,0,0,0,20,0,0,0,0,0,0,0,0,0,0,0,0,0,0,0,1,189,1,0,0
0,0,90,0,89,0,0,0,0,0,0,0,0,0,0,0,0,0,0,45,1,0,0,0,0,0,0,0,0,0,0,0,1,45,0,0,0,0,0,0,0,0,0,0,0,0,0,0,90,0,89,0,0
0,0,1,87,1,0,0,0,0,0,0,0,0,0,0,0,0,0,0,0,1,0,1,0,1,0,1,0,1,0,1,0,1,0,0,0,0,0,0,0,0,0,0,0,0,0,0,0,1,87,1,0,0
0,0,0,0,0,0,0,0,0,0,0,0,0,0,0,0,0,0,0,0,0,0,0,0,0,0,0,0,0,0,0,0,0,0,0,0,0,0,0,0,0,0,0,0,0,0,0,0,0,0,0,0,0
0,0,0,0,0,0,0,0,0,0,0,0,0,0,0,0,0,0,0,0,0,0,0,0,0,0,0,0,0,0,0,0,0,0,0,0,0,0,0,0,0,0,0,0,0,0,0,0,0,0,0,0,0
:endlayer
layer: 14
0,0,0,0,0,0,0,0,0,0,0,0,0,0,0,0,0,0,0,0,0,0,0,0,0,0,0,0,0,0,0,0,0,0,0,0,0,0,0,0,0,0,0,0,0,0,0,0,0,0,0,0,0
0,0,0,0,0,0,0,0,0,0,0,0,0,0,0,0,0,0,0,0,0,0,0,0,0,0,0,0,0,0,0,0,0,0,0,0,0,0,0,0,0,0,0,0,0,0,0,0,0,0,0,0,0
0,46,1,190,190,1,190,190,1,190,190,1,190,190,1,190,190,1,190,190,1,1,190,190,1,190,190,190,1,190,190,1,1,190,190,1,190,190,1,190,190,1,190,190,1,190,190,1,190,190,1,46,0
0,1,240,0,0,240,0,0,240,0,0,1,0,0,275,0,0,275,0,0,275,275,0,0,274,0,0,0,274,0,0,275,275,0,0,275,0,0,275,0,0,1,0,0,240,0,0,240,0,0,240,1,0
0,90,0,0,0,0,0,0,0,0,0,1,0,0,0,0,0,0,0,0,0,0,0,0,274,0,0,0,274,0,0,0,0,0,0,0,0,0,0,0,0,1,0,0,0,0,0,0,0,0,0,89,0
0,90,0,0,0,0,0,0,0,0,0,1,0,0,0,0,0,0,0,0,0,0,0,30,274,27,0,30,274,27,0,0,0,0,0,0,0,0,0,0,0,1,0,0,0,0,0,0,0,0,0,89,0
0,1,225,1,27,0,0,0,0,0,224,1,225,0,0,0,0,0,0,0,0,0,0,0,275,0,0,0,275,0,0,0,0,0,0,0,0,0,0,0,224,1,225,0,0,0,0,0,30,1,224,1,0
0,90,0,0,0,0,0,0,0,0,0,1,0,0,0,0,0,0,0,0,0,0,0,0,0,0,0,0,0,0,0,0,0,0,0,0,0,0,0,0,0,1,0,0,0,0,0,0,0,0,0,89,0
0,90,0,0,0,0,0,0,0,0,0,1,0,0,0,0,0,0,0,280,0,0,0,0,0,0,0,0,0,0,0,0,0,280,0,0,0,0,0,0,0,1,0,0,0,0,0,0,0,0,0,89,0
0,1,130,0,0,0,130,0,0,0,130,1,274,274,274,274,274,274,274,274,275,0,0,0,130,0,0,0,130,0,0,0,275,274,274,274,274,274,274,274,274,1,130,0,0,0,130,0,0,0,130,1,0
0,46,1,46,46,46,1,190,190,190,1,46,1,1,1,1,1,1,1,1,1,1,1,1,1,0,0,0,1,1,1,1,1,1,1,1,1,1,1,1,1,46,1,190,190,190,1,46,46,46,1,46,0
0,0,0,0,240,0,0,0,0,0,0,1,45,0,0,45,0,1,46,0,0,0,0,0,0,0,0,0,0,0,0,0,0,0,46,1,0,390,0,0,390,1,0,0,0,0,0,0,240,0,0,0,0
0,0,0,0,0,0,0,0,0,0,0,190,0,0,0,0,0,1,0,0,0,0,0,0,0,0,0,0,0,0,0,0,0,0,0,1,0,0,0,0,0,190,0,0,0,0,0,0,0,0,0,0,0
0,0,0,0,0,0,0,0,0,0,0,190,0,0,0,0,0,0,0,0,0,56,56,46,56,56,56,56,56,46,56,56,0,0,0,0,0,0,0,0,0,190,0,0,0,0,0,0,0,0,0,0,0
0,0,0,0,0,0,0,0,0,0,0,1,45,0,0,45,0,0,0,0,0,0,0,0,0,0,0,0,0,0,0,0,0,0,0,0,0,390,0,0,390,1,0,0,0,0,0,0,0,0,0,0,0
0,0,0,0,0,0,0,0,0,0,0,190,389,0,0,0,0,0,0,0,0,0,0,0,0,0,0,0,0,0,0,0,0,0,0,0,0,0,0,0,0,190,0,0,0,0,0,0,0,0,0,0,0
0,0,0,0,0,0,0,0,0,21,0,190,0,0,0,0,0,1,0,0,0,0,0,0,0,0,0,0,0,0,0,0,0,0,0,1,0,0,0,388,0,190,0,21,0,0,0,0,0,0,0,0,0
0,0,0,0,0,0,0,0,0,0,0,1,1,1,1,1,1,1,46,0,0,0,56,0,0,0,0,0,0,0,56,0,0,0,46,1,1,1,1,1,1,1,0,0,0,0,0,0,0,0,0,0,0
0,0,0,0,0,0,0,0,0,21,0,91,0,0,0,0,0,0,0,0,0,0,56,0,0,0,0,0,0,0,56,0,0,0,0,0,0,0,0,0,0,92,0,21,0,0,0,0,0,0,0,0,0
0,0,0,0,0,0,0,0,0,0,0,92,0,0,0,0,0,0,0,0,0,0,56,0,0,0,0,0,0,0,56,0,0,0,0,0,0,0,0,0,0,91,0,0,0,0,0,0,0,0,0,0,0
0,0,0,0,0,0,0,0,0,21,0,1,1,1,1,1,1,1,46,0,0,0,56,0,0,0,0,0,0,0,56,0,0,0,46,1,1,1,1,1,1,1,0,21,0,0,0,0,0,0,0,0,0
0,0,0,0,0,0,0,0,0,0,0,190,0,0,0,0,0,1,0,0,0,0,0,56,0,0,0,0,0,56,0,0,0,0,0,1,0,0,0,387,0,190,0,0,0,0,0,0,0,0,0,0,0
0,0,0,0,0,0,0,0,0,21,0,190,0,0,0,0,0,0,0,0,0,0,0,56,0,0,0,0,0,56,0,0,0,0,0,0,0,0,0,0,0,190,0,21,0,0,0,0,0,0,0,0,0
0,0,0,0,0,0,0,0,0,0,0,1,386,385,0,0,0,0,0,0,0,0,0,0,56,56,56,56,56,0,0,0,0,0,0,0,0,0,0,0,0,1,0,0,0,0,0,0,0,0,0,0,0
0,0,0,0,0,0,0,0,0,0,0,190,0,0,0,0,0,1,0,0,0,0,0,0,0,0,0,0,0,0,0,0,0,0,0,1,0,0,0,0,0,190,0,0,0,0,0,0,0,0,0,0,0
0,0,0,0,0,0,0,0,0,0,0,190,0,0,0,0,0,1,46,0,0,0,0,0,0,0,0,0,0,0,0,0,0,0,46,1,0,0,0,0,0,190,0,0,0,0,0,0,0,0,0,0,0
0,0,0,0,0,0,0,0,0,0,0,1,381,0,0,381,0,1,0,0,0,0,0,0,0,0,0,0,0,0,0,0,0,0,0,1,0,275,0,0,275,1,0,0,0,0,0,0,0,0,0,0,0
0,0,0,0,0,0,0,0,0,0,0,190,0,0,0,0,0,1,0,0,0,0,0,0,0,0,0,0,0,0,0,0,0,0,384,1,0,0,0,0,0,190,0,0,0,0,0,0,0,0,0,0,0
0,0,0,0,0,0,0,0,0,0,0,190,0,0,0,0,0,1,383,0,0,0,0,0,0,0,0,0,0,0,0,0,0,0,382,1,0,0,0,0,0,190,0,0,0,0,0,0,0,0,0,0,0
0,0,0,0,0,0,0,0,0,0,0,1,381,0,0,381,0,1,0,0,0,0,0,380,0,0,379,0,0,378,0,0,0,0,0,1,0,275,0,0,275,1,0,0,0,0,0,0,0,0,0,0,0
0,0,0,0,0,0,0,0,0,0,0,46,1,190,1,46,1,1,46,0,0,0,0,0,0,0,0,0,0,0,0,0,0,0,46,1,1,46,1,190,1,46,0,0,0,0,0,0,0,0,0,0,0
0,0,0,0,0,0,0,0,0,0,0,0,0,0,0,1,0,0,0,0,0,0,0,0,0,0,0,0,0,0,0,0,0,0,0,0,0,1,0,0,0,0,0,0,0,0,0,0,0,0,0,0,0
0,0,0,0,0,0,0,0,0,0,0,0,0,0,0,190,205,0,0,0,0,0,0,0,0,0,0,0,0,0,0,0,0,0,0,0,205,190,0,0,0,0,325,0,0,0,0,0,0,0,0,0,0
0,0,0,0,0,0,0,0,0,0,0,0,0,0,0,1,0,0,0,0,198,0,0,0,198,0,0,0,198,0,0,0,198,0,0,0,0,1,0,0,0,325,325,325,0,0,0,0,0,0,0,0,0
0,0,0,0,0,0,0,0,0,0,0,0,325,0,0,46,1,190,190,190,1,190,190,190,1,190,190,190,1,190,190,190,1,190,190,190,1,46,0,0,325,325,325,325,325,0,0,0,0,0,0,0,0
0,0,0,0,0,0,0,0,0,0,325,0,325,0,325,0,0,0,0,0,0,0,0,0,0,0,0,0,0,0,0,0,0,0,0,0,0,0,0,0,0,325,325,325,0,0,0,0,0,0,0,0,0
0,0,0,0,0,0,0,0,0,0,0,325,325,325,0,0,0,0,0,0,0,0,0,0,0,0,0,0,0,0,0,0,0,0,324,0,0,0,0,0,0,0,325,0,0,0,0,0,0,0,0,0,0
0,0,0,0,0,0,0,0,0,325,325,325,325,325,325,325,0,0,0,0,0,0,0,0,0,0,0,0,0,0,0,0,0,0,324,0,0,0,0,0,0,0,0,0,0,0,0,0,0,0,0,0,0
0,0,0,0,0,0,0,0,0,0,0,325,325,325,0,0,0,0,0,0,0,0,0,0,0,0,0,0,0,0,0,0,0,0,0,0,0,0,0,0,0,0,0,0,0,0,0,0,0,0,0,0,0
0,0,0,0,0,0,0,0,0,0,325,0,325,0,325,0,0,33,0,0,0,0,0,0,0,0,0,0,0,0,0,324,324,0,33,0,324,324,0,0,0,0,33,0,0,0,0,0,0,0,0,0,0
0,0,0,0,0,0,0,0,0,0,0,0,325,0,0,0,0,0,0,0,0,0,0,0,0,0,0,0,0,0,0,0,0,0,0,0,0,0,0,0,0,0,0,0,0,0,0,0,0,0,0,0,0
0,0,0,0,0,0,0,0,0,0,0,0,0,0,0,0,0,0,0,0,1,5,1,5,1,5,1,5,1,5,1,5,1,0,324,0,0,0,0,0,0,0,0,0,0,0,0,0,0,0,0,0,0
0,0,0,0,0,0,0,0,0,0,0,0,0,0,0,0,0,0,0,21,1,244,244,244,244,244,265,244,244,244,244,244,1,21,324,0,0,0,0,0,0,0,0,0,0,0,0,0,0,0,0,0,0
0,0,1,85,1,0,0,0,0,0,0,0,0,0,0,0,0,0,0,21,1,244,0,0,0,0,0,0,0,0,0,244,1,21,0,0,0,0,0,0,0,0,0,0,0,0,0,0,1,85,1,0,0
0,0,22,0,20,0,0,0,0,0,0,0,0,0,0,0,0,0,0,21,1,244,244,244,244,244,244,244,244,244,244,244,1,21,0,0,0,0,0,0,0,0,0,0,0,0,0,0,22,0,20,0,0
0,0,1,16,1,0,0,0,0,0,0,0,0,0,0,0,0,0,0,0,377,5,377,5,377,5,377,5,377,5,377,5,377,0,0,0,0,0,0,0,0,0,0,0,0,0,0,0,1,16,1,0,0
0,0,0,0,0,0,0,0,0,0,0,0,0,0,0,0,0,0,0,0,0,0,0,0,0,0,0,0,0,0,0,0,0,0,0,0,0,0,0,0,0,0,0,0,0,0,0,0,0,0,0,0,0
0,0,0,0,0,0,0,0,0,0,0,0,0,0,0,0,0,0,0,0,0,0,0,0,0,0,0,0,0,0,0,0,0,0,0,0,0,0,0,0,0,0,0,0,0,0,0,0,0,0,0,0,0
:endlayer
layer: 15
0,0,0,0,0,0,0,0,0,0,0,0,0,0,0,0,0,0,0,0,0,0,0,0,0,0,0,0,0,0,0,0,0,0,0,0,0,0,0,0,0,0,0,0,0,0,0,0,0,0,0,0,0
0,0,0,0,0,0,0,0,0,0,0,0,0,0,0,0,0,0,0,0,0,0,0,0,0,0,0,0,0,0,0,0,0,0,0,0,0,0,0,0,0,0,0,0,0,0,0,0,0,0,0,0,0
0,223,223,1,1,223,1,1,223,1,1,223,1,1,223,1,1,223,1,1,223,223,189,189,223,189,189,189,223,189,189,223,223,1,1,223,1,1,223,1,1,223,1,1,223,1,1,223,1,1,223,223,0
0,1,407,407,407,407,407,407,407,407,407,1,407,407,407,407,407,407,407,407,407,407,407,407,239,0,0,0,238,407,407,407,407,407,407,407,407,407,407,407,407,1,407,407,407,407,407,407,407,407,407,1,0
0,1,407,407,407,407,407,407,407,407,407,1,407,407,407,407,407,407,407,407,407,407,407,407,239,0,0,0,238,407,407,407,407,407,407,407,407,407,407,407,407,1,407,407,407,407,407,407,407,407,407,1,0
0,1,407,407,407,407,407,407,407,407,407,1,407,407,407,407,407,407,407,407,407,407,407,407,239,0,0,0,238,407,407,407,407,407,407,407,407,407,407,407,407,1,407,407,407,407,407,407,407,407,407,1,0
0,1,407,407,27,407,407,407,407,407,407,1,407,407,407,407,407,407,407,407,407,407,407,407,239,0,0,0,238,407,407,407,407,407,407,407,407,407,407,407,407,1,407,407,407,407,407,407,30,407,407,1,0
0,1,407,407,407,407,407,407,407,407,407,1,407,407,407,407,407,407,407,407,407,407,407,407,239,0,0,0,238,407,407,407,407,407,407,407,407,407,407,407,407,1,407,407,407,407,407,407,407,407,407,1,0
0,1,407,407,407,407,407,407,407,407,407,1,407,407,407,407,407,407,407,407,407,407,407,407,239,0,0,0,238,407,407,407,407,407,407,407,407,407,407,407,407,1,407,407,407,407,407,407,407,407,407,1,0
0,1,407,407,407,407,407,407,407,407,407,1,407,407,407,407,407,407,407,407,407,407,407,407,239,0,0,0,238,407,407,407,407,407,407,407,407,407,407,407,407,1,407,407,407,407,407,407,407,407,407,1,0
0,223,1,1,1,1,1,1,1,1,1,46,1,1,1,1,1,1,1,1,1,1,1,1,1,239,0,238,1,1,1,1,1,1,1,1,1,1,1,1,1,46,1,1,1,1,1,1,1,1,1,223,0
0,0,0,0,0,0,0,0,0,0,0,1,45,0,0,45,0,1,46,45,0,406,0,405,0,0,0,0,0,404,0,403,0,45,46,1,0,390,240,240,390,1,0,0,0,0,0,0,0,0,0,0,0
0,0,0,0,0,0,0,0,0,0,0,190,0,0,0,0,0,1,45,0,0,0,0,0,0,0,0,0,0,0,0,0,0,0,45,1,0,0,0,0,0,190,0,0,0,0,0,0,0,0,0,0,0
0,0,0,0,0,0,0,0,0,0,0,190,0,0,0,0,0,254,0,0,0,0,0,46,0,0,0,0,0,46,0,0,0,0,0,254,0,0,0,0,0,190,0,0,0,0,0,0,0,0,0,0,0
0,0,0,0,0,0,0,0,0,0,0,1,45,0,0,45,0,0,0,0,0,0,0,45,0,0,0,0,0,45,0,0,0,0,0,0,0,390,0,0,390,1,0,0,0,0,0,0,0,0,0,0,0
0,0,0,0,0,0,0,0,0,0,0,190,0,0,0,0,0,270,0,0,0,0,0,0,0,0,0,0,0,0,0,0,0,0,0,270,0,0,0,0,0,190,0,0,0,0,0,0,0,0,0,0,0
0,0,0,0,0,0,0,0,0,0,0,190,0,0,0,0,0,1,45,0,0,0,0,0,0,0,0,0,0,0,0,0,0,0,45,1,0,0,0,0,0,190,0,0,0,0,0,0,0,0,0,0,0
0,0,0,0,0,0,0,0,0,0,224,1,1,1,1,1,1,1,46,45,0,0,0,0,0,0,0,0,0,0,0,0,0,45,46,1,1,1,1,1,1,1,225,0,0,0,0,0,0,0,0,0,0
0,0,0,0,0,0,0,0,0,0,0,5,402,240,401,240,400,240,0,0,0,0,0,0,0,0,0,0,0,0,0,0,0,0,0,240,399,240,398,240,397,5,0,0,0,0,0,0,0,0,0,0,0
0,0,0,0,0,0,0,0,0,0,0,5,396,130,395,130,394,130,0,0,0,0,0,0,0,0,0,0,0,0,0,0,0,0,0,130,393,130,392,130,391,5,0,0,0,0,0,0,0,0,0,0,0
0,0,0,0,0,0,0,0,0,0,224,1,1,1,1,1,1,1,46,45,0,0,0,0,0,0,0,0,0,0,0,0,0,45,46,1,1,1,1,1,1,1,225,0,0,0,0,0,0,0,0,0,0
0,0,0,0,0,0,0,0,0,0,0,190,0,0,0,0,0,1,45,0,0,0,0,0,0,0,0,0,0,0,0,0,0,0,45,1,0,0,0,0,0,190,0,0,0,0,0,0,0,0,0,0,0
0,0,0,0,0,0,0,0,0,0,0,190,0,0,0,0,0,254,0,0,0,0,0,0,0,0,0,0,0,0,0,0,0,0,0,254,0,0,0,0,0,190,0,0,0,0,0,0,0,0,0,0,0
0,0,0,0,0,0,0,0,0,0,0,1,0,0,0,0,0,270,0,0,0,0,0,0,0,0,0,0,0,0,0,0,0,0,0,270,0,0,0,0,0,1,0,0,0,0,0,0,0,0,0,0,0
0,0,0,0,0,0,0,0,0,0,0,190,0,0,0,0,0,1,45,0,0,0,0,0,0,0,0,0,0,0,0,0,0,0,45,1,0,0,0,0,0,190,0,0,0,0,0,0,0,0,0,0,0
0,0,0,0,0,0,0,0,0,0,0,190,0,0,0,0,0,1,46,45,0,0,0,0,0,0,0,0,0,0,0,0,0,45,46,1,0,0,0,0,0,190,0,0,0,0,0,0,0,0,0,0,0
0,0,0,0,0,0,0,0,0,0,0,1,381,0,0,381,0,1,45,0,0,0,0,0,0,0,0,0,0,0,0,0,0,0,45,1,0,275,0,0,275,1,0,0,0,0,0,0,0,0,0,0,0
0,0,0,0,0,0,0,0,0,0,0,190,0,0,0,0,0,1,0,0,0,0,0,0,0,0,0,0,0,0,0,0,0,0,0,1,0,0,0,0,0,190,0,0,0,0,0,0,0,0,0,0,0
0,0,0,0,0,0,0,0,0,0,0,190,0,0,0,0,0,1,0,0,0,0,0,0,0,0,0,0,0,0,0,0,0,0,0,1,0,0,0,0,0,190,0,0,0,0,0,0,0,0,0,0,0
0,0,0,0,0,0,0,0,0,0,0,1,381,0,130,381,0,1,45,0,0,0,0,0,0,0,0,0,0,0,0,0,0,0,45,1,0,275,130,0,275,1,0,0,0,0,0,0,0,0,0,0,0
0,0,0,0,0,0,0,0,0,0,0,46,1,190,1,46,1,1,46,45,0,0,0,0,0,0,0,0,0,0,0,0,0,45,46,1,1,46,1,190,1,46,0,0,0,0,0,0,0,0,0,0,0
0,0,0,0,0,0,0,0,0,0,0,0,0,0,0,1,0,0,45,0,0,0,0,0,0,0,0,0,0,0,0,0,0,0,45,0,0,1,0,0,0,0,0,0,0,0,0,0,0,0,0,0,0
0,0,0,0,0,0,0,0,0,0,0,0,0,0,0,190,0,0,0,0,0,0,0,0,0,0,0,0,0,0,0,0,0,0,0,0,0,190,0,0,0,0,0,0,0,0,0,0,0,0,0,0,0
0,0,0,0,0,0,0,0,0,0,0,0,0,0,0,1,0,0,0,0,198,0,0,0,198,0,0,0,198,0,0,0,198,0,0,0,0,1,0,0,0,0,0,0,0,0,0,0,0,0,0,0,0
0,0,0,0,0,0,0,0,0,0,0,0,0,0,0,46,1,190,190,190,1,190,190,190,1,190,190,190,1,190,190,190,1,190,190,190,1,46,0,0,0,0,324,0,0,0,0,0,0,0,0,0,0
0,0,0,0,0,0,0,0,0,0,0,0,0,0,0,0,0,325,0,0,0,0,0,0,0,0,0,0,0,0,0,0,0,0,0,0,0,0,0,0,0,0,0,0,0,0,0,0,0,0,0,0,0
0,0,0,0,0,0,0,0,0,0,0,0,0,0,0,0,0,325,0,0,0,0,0,0,0,0,0,0,0,0,0,0,0,0,0,0,0,0,0,0,0,0,0,0,0,0,0,0,0,0,0,0,0
0,0,0,0,0,0,0,0,0,0,0,0,324,0,0,324,0,0,0,325,0,0,0,0,0,0,0,0,0,0,0,0,0,0,325,0,0,0,0,0,0,0,0,0,0,0,0,0,0,0,0,0,0
0,0,0,0,0,0,0,0,0,0,0,0,0,0,0,0,324,0,325,0,0,0,0,0,0,0,0,0,0,0,0,0,0,325,325,324,0,0,0,0,0,0,0,0,0,0,0,0,0,0,0,0,0
0,0,0,0,0,0,0,0,0,0,0,0,0,324,325,0,0,33,0,0,324,324,0,0,0,0,0,0,0,0,0,0,324,325,325,325,324,0,0,0,0,0,33,0,0,0,0,0,0,0,0,0,0
0,0,0,0,0,0,0,0,0,0,0,0,0,0,0,0,325,0,324,0,189,237,189,237,189,237,189,237,189,237,189,237,189,324,324,324,0,0,0,0,0,0,0,0,0,0,0,0,0,0,0,0,0
0,0,0,0,0,0,0,0,0,0,0,0,0,0,0,325,0,0,0,90,46,46,46,46,46,46,46,46,46,46,46,46,46,89,324,0,0,0,0,0,0,0,0,0,0,0,0,0,0,0,0,0,0
0,0,0,0,0,0,0,0,0,0,0,0,0,0,0,0,0,325,0,237,46,1,1,1,1,1,265,1,1,1,1,1,46,237,0,0,0,0,0,0,0,0,0,0,0,0,0,0,0,0,0,0,0
0,0,1,189,1,0,0,0,0,0,0,0,0,0,0,0,0,324,0,90,46,1,1,1,1,1,1,1,1,1,1,1,46,89,0,0,0,0,0,0,0,0,0,0,0,0,0,0,1,189,1,0,0
0,0,45,0,89,0,0,0,0,0,0,0,0,0,0,0,0,0,0,237,46,1,1,1,1,1,1,1,1,1,1,1,46,237,0,0,0,0,0,0,0,0,0,0,0,0,0,0,90,0,45,0,0
0,0,1,45,1,0,0,0,0,0,0,0,0,0,0,0,0,0,0,90,46,46,46,46,46,46,46,46,46,46,46,46,46,89,0,0,0,0,0,0,0,0,0,0,0,0,0,0,1,45,1,0,0
0,0,0,0,0,0,0,0,0,0,0,0,0,0,0,0,0,0,0,0,87,237,87,237,87,237,87,237,87,237,87,237,87,0,0,0,0,0,0,0,0,0,0,0,0,0,0,0,0,0,0,0,0
0,0,0,0,0,0,0,0,0,0,0,0,0,0,0,0,0,0,0,0,0,0,0,0,0,0,0,0,0,0,0,0,0,0,0,0,0,0,0,0,0,0,0,0,0,0,0,0,0,0,0,0,0
:endlayer
layer: 16
0,0,0,0,0,0,0,0,0,0,0,0,0,0,0,0,0,0,0,0,0,0,0,0,0,0,0,0,0,0,0,0,0,0,0,0,0,0,0,0,0,0,0,0,0,0,0,0,0,0,0,0,0
0,244,189,244,189,244,189,244,189,244,189,244,189,244,189,244,189,244,189,244,189,244,189,244,189,244,189,244,189,244,189,244,189,244,189,244,189,244,189,244,189,244,189,244,189,244,189,244,189,244,189,244,0
244,55,55,55,55,55,55,55,55,55,55,55,55,55,55,55,55,55,55,55,55,55,55,55,55,55,55,55,55,55,55,55,55,55,55,55,55,55,55,55,55,55,55,55,55,55,55,55,55,55,55,55,244
90,55,1,1,1,1,1,1,1,1,1,1,1,1,1,1,1,1,1,1,1,1,1,1,1,1,1,1,1,1,1,1,1,1,1,1,1,1,1,1,1,1,1,1,1,1,1,1,1,1,1,55,89
244,55,1,1,1,1,1,1,1,1,1,1,1,1,1,1,1,1,1,1,1,1,1,1,1,1,1,1,1,1,1,1,1,1,1,1,1,1,1,1,1,1,1,1,1,1,1,1,1,1,1,55,244
90,55,1,1,1,1,1,1,1,1,1,1,1,1,1,1,1,1,1,1,1,1,1,1,1,1,1,1,1,1,1,1,1,1,1,1,1,1,1,1,1,1,1,1,1,1,1,1,1,1,1,55,89
244,55,1,1,27,1,1,1,1,1,1,1,1,1,1,1,1,1,1,1,1,1,1,1,1,1,1,1,1,1,1,1,1,1,1,1,1,1,1,1,1,1,1,1,1,1,1,1,30,1,1,55,244
90,55,1,1,1,1,1,1,1,1,1,1,1,1,1,1,1,1,1,1,1,1,1,1,1,1,1,1,1,1,1,1,1,1,1,1,1,1,1,1,1,1,1,1,1,1,1,1,1,1,1,55,89
244,55,1,1,1,1,1,1,1,1,1,1,1,1,1,1,1,1,1,1,1,1,1,1,1,1,1,1,1,1,1,1,1,1,1,1,1,1,1,1,1,1,1,1,1,1,1,1,1,1,1,55,244
90,55,1,1,1,1,1,1,1,1,1,1,1,1,1,1,1,1,1,1,1,1,1,1,1,1,1,1,1,1,1,1,1,1,1,1,1,1,1,1,1,1,1,1,1,1,1,1,1,1,1,55,89
244,55,55,55,55,55,55,55,55,55,55,46,1,1,1,1,1,1,1,1,1,1,1,1,1,1,1,1,1,1,1,1,1,1,1,1,1,1,1,1,1,46,55,55,55,55,55,55,55,55,55,55,244
0,244,87,244,87,244,87,244,87,244,5,1,367,367,367,367,0,1,46,252,0,0,0,0,0,0,0,0,0,0,0,0,0,252,46,1,0,105,105,105,105,1,5,244,87,244,87,244,87,244,87,244,0
0,0,0,0,0,0,0,0,0,0,244,190,367,412,412,367,0,1,252,0,0,0,0,0,0,0,0,0,0,0,0,0,0,0,252,1,225,105,61,61,105,190,244,0,0,0,0,0,0,0,0,0,0
0,0,0,0,0,0,0,0,0,0,244,190,367,412,412,367,0,1,239,0,0,0,0,46,0,0,0,0,0,46,0,0,0,0,238,1,0,105,61,61,105,190,244,0,0,0,0,0,0,0,0,0,0
0,0,0,0,0,0,0,0,0,0,90,1,367,367,367,367,224,1,225,0,0,0,0,252,0,0,0,0,0,252,0,0,0,0,0,1,0,105,105,105,105,1,89,0,0,0,0,0,0,0,0,0,0
0,0,0,0,0,0,0,0,0,0,244,190,0,0,0,0,0,1,239,0,0,0,0,0,0,0,0,0,0,0,0,0,0,0,238,1,225,0,0,0,0,190,244,0,0,0,0,0,0,0,0,0,0
0,0,0,0,0,0,0,0,0,0,244,190,0,0,0,0,0,1,252,0,0,0,0,0,0,0,0,0,0,0,0,0,0,0,252,1,0,130,0,130,0,190,244,0,0,0,0,0,0,0,0,0,0
0,0,0,0,0,0,0,0,0,0,90,1,1,1,1,1,1,1,46,252,0,0,0,0,0,0,0,0,0,0,0,0,0,252,46,1,1,1,1,1,1,1,89,0,0,0,0,0,0,0,0,0,0
0,0,0,0,0,0,0,0,0,0,244,190,0,254,0,254,0,254,0,0,0,0,0,0,0,0,0,0,0,0,0,0,0,0,0,254,0,254,0,254,0,190,244,0,0,0,0,0,0,0,0,0,0
0,0,0,0,0,0,0,0,0,0,244,190,0,270,0,270,0,270,0,0,0,0,0,0,0,0,0,0,0,0,0,0,0,0,0,270,0,270,0,270,0,190,244,0,0,0,0,0,0,0,0,0,0
0,0,0,0,0,0,0,0,0,0,90,1,1,1,1,1,1,1,46,252,0,0,0,0,0,0,0,0,0,0,0,0,0,252,46,1,1,1,1,1,1,1,89,0,0,0,0,0,0,0,0,0,0
0,0,0,0,0,0,0,0,0,0,244,190,0,240,0,240,0,1,252,0,0,0,0,0,0,0,0,0,0,0,0,0,0,0,252,1,0,0,0,0,0,190,244,0,0,0,0,0,0,0,0,0,0
0,0,0,0,0,0,0,0,0,0,244,190,0,0,0,0,224,1,239,0,0,0,0,0,0,0,0,0,0,0,0,0,0,0,238,1,0,0,0,0,0,190,244,0,0,0,0,0,0,0,0,0,0
0,0,0,0,0,0,0,0,0,0,90,1,0,0,0,0,0,1,239,0,0,0,0,0,0,0,0,0,0,0,0,0,0,0,238,1,0,0,0,0,224,1,89,0,0,0,0,0,0,0,0,0,0
0,0,0,0,0,0,0,0,0,0,244,190,0,0,0,0,0,1,252,0,0,0,0,0,0,0,0,0,0,0,0,0,0,0,252,1,225,0,0,0,0,190,244,0,0,0,0,0,0,0,0,0,0
0,0,0,0,0,0,0,0,0,0,244,190,0,0,0,0,224,1,46,252,0,0,0,0,0,0,0,0,0,0,0,0,0,252,46,1,0,0,0,0,0,190,244,0,0,0,0,0,0,0,0,0,0
0,0,0,0,0,0,0,0,0,0,90,1,338,338,338,338,0,1,252,0,0,0,0,0,0,0,0,0,0,0,0,0,0,0,252,1,225,205,205,205,205,1,89,0,0,0,0,0,0,0,0,0,0
0,0,0,0,0,0,0,0,0,0,244,190,338,411,411,338,0,1,239,0,0,0,0,0,0,0,0,0,0,0,0,0,0,0,238,1,0,205,410,410,205,190,244,0,0,0,0,0,0,0,0,0,0
0,0,0,0,0,0,0,0,0,0,244,190,338,411,411,338,224,1,239,0,0,0,0,0,0,0,0,0,0,0,0,0,0,0,238,1,0,205,410,410,205,190,244,0,0,0,0,0,0,0,0,0,0
0,0,0,0,0,0,0,0,0,0,90,1,338,338,338,338,0,1,252,0,0,0,0,0,0,0,0,0,0,0,0,0,0,0,252,1,0,205,205,205,205,1,89,0,0,0,0,0,0,0,0,0,0
0,0,0,0,0,0,0,0,0,0,0,46,1,190,1,46,1,1,46,252,0,0,0,0,0,0,0,0,0,0,0,0,0,252,46,1,1,46,1,190,1,46,0,0,0,0,0,0,0,0,0,0,0
0,0,0,0,0,0,0,0,0,0,0,0,87,244,17,1,0,0,252,0,0,0,0,0,0,0,0,0,0,0,0,0,0,0,252,0,0,1,17,244,87,0,0,0,0,0,0,0,0,0,0,0,0
0,0,0,0,0,0,0,0,0,0,0,0,0,0,244,190,0,0,0,0,0,0,0,0,0,0,0,0,0,0,0,0,0,0,0,0,0,190,244,0,0,0,0,0,0,0,0,0,0,0,0,0,0
0,0,0,0,0,0,0,0,0,0,0,0,0,0,90,1,0,0,0,0,0,0,0,0,0,0,0,0,0,0,0,0,0,0,0,0,0,1,89,0,0,0,0,0,0,0,0,0,0,0,0,0,0
0,0,0,0,0,0,0,0,0,0,0,0,0,0,0,46,1,190,190,190,1,190,190,190,1,190,190,190,1,190,190,190,1,190,190,190,1,46,0,0,0,0,0,0,0,0,0,0,0,0,0,0,0
0,0,0,0,0,0,0,0,0,0,0,0,0,0,0,0,87,244,244,244,87,244,244,244,87,244,244,244,87,244,244,244,87,244,244,244,87,0,0,0,0,0,324,0,0,0,0,0,0,0,0,0,0
0,0,0,0,0,0,0,0,0,0,0,0,0,0,0,0,0,325,0,0,0,0,0,0,0,0,0,0,0,0,0,0,0,0,0,0,0,0,0,325,0,0,325,0,0,325,0,0,0,0,0,0,0
0,0,0,0,0,0,0,0,0,0,0,0,0,0,0,0,0,325,0,0,0,0,0,0,0,0,0,0,0,0,0,0,0,0,0,0,0,0,0,0,325,0,0,0,325,0,0,0,0,0,0,0,0
0,0,0,0,0,0,0,0,0,0,0,0,0,0,0,0,325,325,325,0,0,0,0,0,0,0,0,0,0,0,0,0,0,0,0,0,0,0,0,0,0,0,0,0,0,0,0,0,0,0,0,0,0
0,0,0,0,0,0,0,0,0,0,0,0,0,0,325,325,325,325,324,324,324,0,0,0,0,0,0,0,0,0,0,0,0,0,325,0,0,0,324,324,0,0,33,0,0,325,324,0,0,0,0,0,0
0,0,0,0,0,0,0,0,0,0,0,0,0,0,0,0,325,325,324,0,0,0,0,0,0,0,0,0,0,0,0,0,0,0,0,0,0,0,0,0,0,0,0,0,0,0,0,0,0,0,0,0,0
0,0,0,0,0,0,0,0,0,0,0,0,0,0,0,0,0,325,0,0,1,253,1,253,1,253,1,253,1,253,1,253,1,0,0,0,0,0,0,0,325,0,0,0,325,0,0,0,0,0,0,0,0
0,0,0,0,0,0,0,0,0,0,0,0,0,0,0,0,0,325,0,0,146,0,0,0,0,0,265,0,0,0,0,0,143,0,0,0,0,0,0,325,0,0,325,0,0,325,0,0,0,0,0,0,0
0,0,1,85,1,0,0,0,0,0,0,0,0,0,0,0,0,0,0,0,1,0,0,0,0,0,0,0,0,0,0,0,1,0,0,0,0,0,0,0,0,0,324,0,0,0,0,0,1,85,1,0,0
0,0,45,0,20,0,0,0,0,0,0,0,0,0,0,0,0,0,0,0,146,0,0,409,0,0,0,0,0,408,0,0,143,0,0,0,0,0,0,0,0,0,0,0,0,0,0,0,22,0,45,0,0
0,0,1,45,1,0,0,0,0,0,0,0,0,0,0,0,0,0,0,0,1,79,1,79,1,79,1,79,1,79,1,79,1,0,0,0,0,0,0,0,0,0,0,0,0,0,0,0,1,45,1,0,0
0,0,0,0,0,0,0,0,0,0,0,0,0,0,0,0,0,0,0,0,0,0,0,0,0,0,0,0,0,0,0,0,0,0,0,0,0,0,0,0,0,0,0,0,0,0,0,0,0,0,0,0,0
0,0,0,0,0,0,0,0,0,0,0,0,0,0,0,0,0,0,0,0,0,0,0,0,0,0,0,0,0,0,0,0,0,0,0,0,0,0,0,0,0,0,0,0,0,0,0,0,0,0,0,0,0
:endlayer
layer: 17
0,0,0,0,0,0,0,0,0,0,0,0,0,0,0,0,0,0,0,0,0,0,0,0,0,0,0,0,0,0,0,0,0,0,0,0,0,0,0,0,0,0,0,0,0,0,0,0,0,0,0,0,0
0,0,0,0,0,0,0,0,0,0,0,0,0,0,0,0,0,0,0,0,0,0,0,0,0,0,0,0,0,0,0,0,0,0,0,0,0,0,0,0,0,0,0,0,0,0,0,0,0,0,0,0,0
0,5,21,21,5,21,21,5,21,21,5,21,21,21,21,21,21,21,21,21,21,21,21,21,21,21,21,21,21,21,21,21,21,21,21,21,21,21,21,21,21,21,5,21,21,5,21,21,5,21,21,5,0
0,21,0,0,1,1,1,1,1,0,0,0,0,0,0,0,0,0,0,0,0,0,0,0,0,0,0,0,0,0,0,0,0,0,0,0,0,0,0,0,0,0,0,0,1,1,1,1,1,0,0,21,0
0,21,0,1,0,0,0,0,0,1,0,0,0,1,423,1,0,422,0,0,0,0,0,0,0,0,421,0,0,0,0,0,0,0,0,420,0,1,419,1,0,0,0,1,0,0,0,0,0,1,0,21,0
0,5,0,1,0,0,0,0,0,1,0,0,0,1,1,1,0,0,0,0,0,0,0,0,0,0,0,0,0,0,0,0,0,0,0,0,0,1,1,1,0,0,0,1,0,0,0,0,0,1,0,5,0
0,21,0,1,27,0,418,0,0,32,0,0,0,1,1,1,0,0,0,0,0,0,0,0,0,0,0,0,0,0,0,0,0,0,0,0,0,1,1,1,0,0,0,31,0,0,417,0,30,1,0,21,0
0,5,0,1,0,0,416,0,0,1,0,0,0,79,79,79,0,0,0,415,0,0,0,0,0,0,0,0,0,0,0,0,0,414,0,0,0,79,79,79,0,0,0,1,0,0,0,0,0,1,0,5,0
0,21,0,1,0,0,0,0,0,1,0,0,0,0,0,0,0,0,0,0,0,0,0,146,1,253,253,253,1,143,0,0,0,0,0,0,0,0,0,0,0,0,0,1,0,0,0,0,0,1,0,21,0
0,21,0,0,1,1,1,1,1,0,0,0,130,0,0,0,130,413,0,0,130,0,0,146,1,1,1,1,1,143,0,0,130,0,0,0,130,0,0,0,130,0,0,0,1,1,1,1,1,0,0,21,0
0,5,21,21,5,21,21,5,21,21,5,17,1,1,1,1,1,1,1,1,1,1,1,1,1,1,1,1,1,1,1,1,1,1,1,1,1,1,1,1,1,17,5,21,21,5,21,21,5,21,21,5,0
0,0,0,0,0,0,0,0,0,0,146,1,55,55,55,55,55,55,55,55,55,55,55,55,55,55,55,55,55,55,55,55,55,55,55,55,55,55,55,55,55,1,143,0,0,0,0,0,0,0,0,0,0
0,0,0,0,0,0,0,0,0,0,56,1,55,55,55,55,55,55,55,55,55,55,55,55,55,55,55,55,55,55,55,55,55,55,55,55,55,55,55,55,55,1,56,0,0,0,0,0,0,0,0,0,0
0,0,0,0,0,0,0,0,0,0,56,1,55,55,55,55,55,55,55,55,55,55,55,46,55,55,55,55,55,46,55,55,55,55,55,55,55,55,55,55,55,1,56,0,0,0,0,0,0,0,0,0,0
0,0,0,0,0,0,0,0,0,0,146,1,55,55,55,55,55,55,55,55,55,55,55,55,55,55,55,55,55,55,55,55,55,55,55,55,55,55,55,55,55,1,143,0,0,0,0,0,0,0,0,0,0
