# Ancient Warfare Structure Template File
# Auto-generated structure template file. created on: 3/7/2024 at: 17:23:35
# Lines beginning with # denote comments

header:
version=2.11
name=SarkonidBreweryBumgurn
mods=
size=24,31,23
offset=14,5,22
:endheader

#### VALIDATION ####
validation:
type=ground
structureAuthor=TheOddlySeagull
survival=false
worldGenEnabled=true
unique=false
preserveBlocks=false
preventNaturalHostileSpawns=true
selectionWeight=30
clusterValue=50
minDuplicateDistance=2000
dimensionWhiteList=true
dimensionList=0
biomeGroupList=sarkonid
biomeWhiteList=true
biomeList=environs:sandstone_ranges,nt:sahel,minecraft:desert,minecraft:mutated_desert,minecraft:desert_hills
leveling=10
fill=10
border=6
blockSwap=false
territoryName=sarkonid
biomeReplacement=minecraft:
minGenerationHeight=0
maxGenerationHeight=255
:endvalidation

#### LAYERS ####
layer: 0
1,1,1,1,1,1,1,1,1,1,1,1,1,1,1,1,1,1,1,1,1,1,1,1
1,1,1,1,1,1,1,1,1,1,1,1,1,1,1,1,1,1,1,1,1,1,1,1
1,1,1,1,1,1,1,1,1,1,1,1,1,1,1,1,1,1,1,1,1,1,1,1
1,1,1,1,1,1,1,1,1,1,1,1,1,1,1,1,1,1,1,1,1,1,1,1
1,1,1,1,1,1,1,1,1,1,1,1,1,1,1,1,1,1,1,1,1,1,1,1
1,1,1,1,1,1,1,1,1,1,1,1,1,1,1,1,1,1,1,1,1,1,1,1
1,1,1,1,1,1,1,1,1,1,1,1,1,1,1,1,1,1,1,1,1,1,1,1
1,1,1,1,1,1,1,1,1,1,1,1,1,1,1,1,1,1,1,1,1,1,1,1
1,1,1,1,1,1,1,1,1,1,1,1,1,1,1,1,1,1,1,1,1,1,1,1
1,1,1,1,1,1,1,1,1,1,1,1,1,1,1,1,1,1,1,1,1,1,1,1
1,1,1,1,1,1,1,1,1,1,1,1,1,1,1,1,1,1,1,1,1,1,1,1
1,1,1,1,1,1,1,1,1,1,1,1,1,1,1,1,1,1,1,1,1,1,1,1
1,1,1,1,1,1,1,1,1,1,1,1,1,1,1,1,1,1,1,1,1,1,1,1
1,1,1,1,1,1,1,1,1,1,1,1,1,1,1,1,1,1,1,1,1,1,1,1
1,1,1,1,1,1,1,1,1,1,1,1,1,1,1,1,1,1,1,1,1,1,1,1
1,1,1,1,1,1,1,1,1,1,1,1,1,1,1,1,1,1,1,1,1,1,1,1
1,1,1,1,1,1,1,1,1,1,1,1,1,1,1,1,1,1,1,1,1,1,1,1
1,1,1,1,1,1,1,1,1,1,1,1,1,1,1,1,1,1,1,1,1,1,1,1
1,1,1,1,1,1,1,1,1,1,1,1,1,1,1,1,1,1,1,1,1,1,1,1
1,1,1,1,1,1,1,1,1,1,1,1,1,1,1,1,1,1,1,1,1,1,1,1
1,1,1,1,1,1,1,1,1,1,1,1,1,1,1,1,1,1,1,1,1,1,1,1
1,1,1,1,1,1,1,1,1,1,1,1,1,1,1,1,1,1,1,1,1,1,1,1
1,1,1,1,1,1,1,1,1,1,1,1,1,1,1,1,1,1,1,1,1,1,1,1
:endlayer
layer: 1
1,1,1,1,1,1,1,1,1,1,1,1,1,1,1,1,1,1,1,1,1,1,1,1
1,1,1,1,1,1,1,1,1,1,1,1,1,1,1,1,1,1,1,1,1,1,1,1
1,1,1,1,1,1,1,1,1,1,1,1,1,1,1,1,1,1,1,1,1,1,1,1
1,1,1,1,1,1,1,1,1,1,1,1,1,1,1,1,1,1,1,1,1,1,1,1
1,1,1,1,1,1,1,1,1,1,1,1,1,1,1,1,1,1,1,1,1,1,1,1
1,1,1,1,1,1,1,1,1,1,1,1,1,1,1,1,1,1,1,1,1,1,1,1
1,1,1,1,1,1,1,1,1,1,1,1,1,1,1,1,1,1,1,1,1,1,1,1
1,1,1,1,1,1,1,1,1,1,1,1,1,1,1,1,1,1,1,1,1,1,1,1
1,1,1,1,1,1,1,1,1,1,1,1,1,1,1,1,1,1,1,1,1,1,1,1
1,1,1,1,1,1,1,1,1,1,1,1,1,1,1,1,1,1,1,1,1,1,1,1
1,1,1,1,1,1,1,1,1,1,1,1,1,1,1,1,1,1,1,1,1,1,1,1
1,1,1,1,1,1,1,1,1,1,1,1,1,1,1,1,1,1,1,1,1,1,1,1
1,1,1,1,1,1,1,1,1,1,1,1,1,1,1,1,1,1,1,1,1,1,1,1
1,1,1,1,1,1,1,1,1,1,1,1,1,1,1,1,1,1,1,1,1,1,1,1
1,1,1,1,1,1,1,1,1,1,1,1,1,1,1,1,1,1,1,1,1,1,1,1
1,1,1,1,1,1,1,1,1,1,1,1,1,1,1,1,1,1,1,1,1,1,1,1
1,1,1,1,1,1,1,1,1,1,1,1,1,1,1,1,1,1,1,1,1,1,1,1
1,1,1,1,1,1,1,1,1,1,1,1,1,1,1,1,1,1,1,1,1,1,1,1
1,1,1,1,1,1,1,1,1,1,1,1,1,1,1,1,1,1,1,1,1,1,1,1
1,1,1,1,1,1,1,1,1,1,1,1,1,1,1,1,1,1,1,1,1,1,1,1
1,1,1,1,1,1,1,1,1,1,1,1,1,1,1,1,1,1,1,1,1,1,1,1
1,1,1,1,1,1,1,1,1,1,1,1,1,1,1,1,1,1,1,1,1,1,1,1
1,1,1,1,1,1,1,1,1,1,1,1,1,1,1,1,1,1,1,1,1,1,1,1
:endlayer
layer: 2
1,1,1,1,1,1,1,1,1,1,1,1,1,1,1,1,1,1,1,1,1,1,1,1
1,1,1,1,1,1,1,1,1,1,1,1,1,1,1,1,1,1,1,1,1,1,1,1
1,1,1,1,1,1,1,1,1,1,1,1,1,1,1,1,1,1,1,1,1,1,1,1
1,1,1,1,1,1,1,1,1,1,1,1,1,1,1,1,1,1,1,1,1,1,1,1
1,1,1,1,1,1,1,1,1,1,1,1,1,1,1,1,1,1,1,1,1,1,1,1
1,1,1,1,1,1,1,1,1,1,1,1,1,1,1,1,1,1,1,1,1,1,1,1
1,1,1,1,1,1,1,1,1,1,1,1,1,1,1,1,1,1,1,1,1,1,1,1
1,1,1,1,1,1,1,1,1,1,1,1,1,1,1,1,1,1,1,1,1,1,1,1
1,1,1,1,1,1,1,1,1,1,1,1,1,1,1,1,1,1,1,1,1,1,1,1
1,1,1,1,1,1,1,1,1,1,1,1,1,1,1,1,1,1,1,1,1,1,1,1
1,1,1,1,1,1,1,1,1,1,1,1,1,1,1,1,1,1,1,1,1,1,1,1
1,1,1,1,1,1,1,1,1,1,1,1,1,1,1,1,1,1,1,1,1,1,1,1
1,1,1,1,1,1,1,1,1,1,1,1,1,1,1,1,1,1,1,1,1,1,1,1
1,1,1,1,1,1,1,1,1,1,1,1,1,1,1,1,1,1,1,1,1,1,1,1
1,1,1,1,1,1,1,1,1,1,1,1,1,1,1,1,1,1,1,1,1,1,1,1
1,1,1,1,1,1,1,1,1,1,1,1,1,1,1,1,1,1,1,1,1,1,1,1
1,1,1,1,1,1,1,1,1,1,1,1,1,1,1,1,1,1,1,1,1,1,1,1
1,1,1,1,1,1,1,1,1,1,1,1,1,1,1,1,1,1,1,1,1,1,1,1
1,1,1,1,1,1,1,1,1,1,1,1,1,1,1,1,1,1,1,1,1,1,1,1
1,1,1,1,1,1,1,1,1,1,1,1,1,1,1,1,1,1,1,1,1,1,1,1
1,1,1,1,1,1,1,1,1,1,1,1,1,1,1,1,1,1,1,1,1,1,1,1
1,1,1,1,1,1,1,1,1,1,1,1,1,1,1,1,1,1,1,1,1,1,1,1
1,1,1,1,1,1,1,1,1,1,1,1,1,1,1,1,1,1,1,1,1,1,1,1
:endlayer
layer: 3
2,2,2,2,2,2,2,2,2,2,2,2,2,2,2,2,2,2,2,2,2,2,2,2
2,2,2,2,2,2,2,2,2,2,2,2,2,2,2,2,2,2,2,2,2,2,2,2
2,2,2,2,2,2,2,2,2,2,2,2,2,2,2,2,1,1,1,1,1,1,2,2
2,2,2,2,2,2,2,2,2,2,2,2,2,2,2,2,1,2,2,2,2,1,2,2
2,2,2,2,2,2,2,2,2,1,1,1,1,1,1,1,1,2,2,2,2,1,2,2
2,2,2,2,2,2,2,2,2,1,2,2,2,2,1,2,2,2,2,2,2,1,2,2
2,2,2,1,1,1,1,1,1,1,2,2,2,2,1,2,2,2,2,2,2,1,2,2
2,2,2,1,2,2,2,2,2,1,2,2,2,2,1,1,1,1,1,1,1,1,2,2
2,2,2,1,2,2,2,2,2,1,2,2,2,2,2,2,2,2,2,2,1,2,2,2
2,2,2,1,2,2,2,2,2,1,2,2,2,2,2,2,2,2,2,2,1,2,2,2
2,2,2,1,2,2,2,2,2,1,2,2,2,2,2,2,2,2,2,2,1,2,2,2
2,2,2,1,2,2,2,2,2,1,2,2,2,2,2,2,2,2,2,2,1,2,2,2
2,2,2,1,2,2,2,2,2,1,1,1,1,1,1,1,1,1,1,1,1,2,2,2
2,2,2,1,2,2,2,2,2,1,2,2,2,2,2,2,2,2,2,2,2,2,2,2
2,2,2,1,2,2,2,2,2,1,2,2,2,2,2,2,2,2,2,2,2,2,2,2
2,2,2,1,2,2,2,2,2,1,2,2,2,2,2,2,2,2,2,2,2,2,2,2
2,2,2,1,2,2,2,2,2,1,2,2,2,2,2,2,2,2,2,2,2,2,2,2
2,2,2,1,1,1,1,1,1,1,2,2,2,2,2,2,2,2,2,2,2,2,2,2
2,2,2,2,2,2,2,2,2,2,2,2,2,2,2,2,2,2,2,2,2,2,2,2
2,2,2,2,2,2,2,2,2,2,2,2,2,2,2,2,2,2,2,2,2,2,2,2
2,2,2,2,2,2,2,2,2,2,2,2,2,2,2,2,2,2,2,2,2,2,2,2
2,2,2,1,2,2,2,2,2,1,2,2,2,2,2,2,2,2,2,2,2,2,2,2
2,2,2,2,2,2,2,2,2,2,2,2,2,2,2,2,2,2,2,2,2,2,2,2
:endlayer
layer: 4
2,2,2,2,2,2,2,2,2,2,2,2,2,2,2,2,2,2,2,2,2,2,2,2
2,2,2,2,2,2,2,2,2,2,2,2,2,2,2,2,2,2,2,2,2,2,2,2
2,2,2,2,2,2,2,2,2,2,2,2,2,2,2,2,1,1,1,1,1,1,2,2
2,2,2,2,2,2,2,2,2,2,2,2,2,2,2,2,1,2,2,2,2,1,2,2
2,2,2,2,2,2,2,2,2,1,1,1,1,1,1,1,1,2,2,2,2,1,2,2
1,1,2,2,2,2,2,2,2,1,1,1,1,1,1,2,2,2,2,2,2,1,2,2
1,1,1,1,1,1,1,1,1,1,1,1,1,1,1,2,2,2,2,2,2,1,2,2
1,1,2,1,2,2,2,2,2,1,1,1,1,1,1,1,1,1,1,1,1,1,2,2
1,2,1,1,2,2,2,2,2,1,1,1,1,1,1,1,1,1,1,1,1,2,2,2
1,2,1,1,2,2,2,2,2,1,1,1,1,1,1,1,1,1,1,1,1,2,2,2
2,1,2,1,2,2,2,2,2,1,1,1,1,1,1,1,1,1,1,1,1,2,2,2
1,2,2,1,2,2,2,2,2,1,1,1,1,1,1,1,1,1,1,1,1,2,2,2
1,1,2,1,2,2,2,2,2,1,1,1,1,1,1,1,1,1,1,1,1,2,2,2
1,2,1,1,2,2,2,2,2,1,2,2,2,1,2,2,2,2,2,2,2,2,2,2
2,1,2,1,2,2,2,2,2,1,2,2,2,1,2,1,2,2,2,2,2,2,2,2
1,1,1,1,2,2,2,2,2,1,2,2,1,1,1,2,1,1,2,2,2,2,2,2
2,2,2,1,2,2,2,2,2,1,2,2,2,2,1,1,2,2,1,2,1,2,2,2
1,2,2,1,1,1,1,1,1,1,2,2,1,2,1,1,1,1,1,2,1,2,1,2
1,2,1,2,1,2,2,1,1,2,2,2,2,2,1,1,1,1,2,2,1,1,1,1
2,2,1,2,1,2,2,1,2,2,1,2,1,1,1,2,1,2,2,1,2,1,1,1
2,2,1,1,1,2,2,1,1,1,1,2,2,2,1,1,2,1,2,1,1,2,2,2
2,2,2,1,2,2,2,1,2,1,1,2,2,1,1,1,1,2,1,2,2,2,1,2
2,2,2,2,2,2,1,1,1,1,1,2,1,1,1,2,2,1,2,2,1,2,2,1
:endlayer
layer: 5
0,0,0,0,0,0,0,0,0,0,0,0,0,0,0,0,0,0,0,0,0,0,0,0
0,0,0,0,0,0,0,0,0,0,0,0,0,0,0,0,18,35,35,35,18,0,0,0
0,0,0,0,12,11,10,0,0,0,8,7,7,8,0,0,1,35,35,35,1,1,0,0
0,0,0,0,12,11,10,0,0,37,8,7,7,8,0,0,1,35,36,35,0,1,0,0
0,0,0,0,12,11,10,15,7,1,1,1,1,1,1,34,1,0,0,0,0,14,0,0
0,0,0,33,1,1,1,1,1,1,12,11,10,0,1,11,11,0,32,0,0,14,0,0
0,3,0,1,1,1,12,11,10,1,12,11,10,0,1,11,11,0,0,31,31,1,0,0
0,0,0,1,13,18,12,11,10,1,12,11,10,0,1,1,1,1,30,1,1,1,0,0
0,0,0,16,13,0,0,0,0,0,0,0,29,0,28,0,11,0,0,27,1,0,0,0
0,0,0,16,18,0,0,0,0,0,0,0,11,11,11,11,11,0,0,20,14,0,0,0
0,0,3,1,27,0,26,0,0,0,0,0,0,0,0,0,0,25,0,24,14,0,0,0
0,0,23,1,11,0,0,13,0,1,0,0,0,0,0,0,0,0,15,22,1,0,0,0
0,0,21,1,20,0,0,0,13,1,1,19,1,0,0,0,0,1,19,1,1,0,0,0
0,0,3,1,18,0,0,0,13,1,0,0,3,0,0,0,0,3,0,0,0,0,0,0
0,0,0,16,13,0,17,0,0,14,0,0,0,0,0,0,0,0,0,0,0,0,0,0
0,0,0,16,13,13,0,0,15,14,0,0,0,0,0,0,0,0,0,0,0,0,0,0
0,0,0,1,13,0,0,0,7,1,12,11,10,0,0,0,0,0,0,0,0,0,0,0
0,3,0,1,1,0,0,0,1,1,12,11,10,0,0,0,3,0,0,0,5,5,3,0
0,0,0,0,0,0,0,0,0,0,12,11,10,0,0,0,0,5,5,0,7,7,0,0
0,0,0,8,7,7,8,0,0,0,0,0,0,0,0,0,9,7,7,0,7,7,0,0
0,0,0,8,7,7,8,0,0,0,0,0,0,0,0,0,0,7,7,0,5,5,0,0
0,0,0,3,0,0,0,6,0,3,0,0,0,0,0,0,3,5,5,0,0,4,3,0
0,0,0,0,0,0,0,0,0,0,0,0,0,0,0,0,0,0,0,0,0,0,0,0
:endlayer
layer: 6
0,0,0,0,0,0,0,0,0,0,0,0,0,0,0,0,0,0,0,0,0,0,0,0
0,0,0,0,0,48,0,0,0,0,0,0,0,0,0,0,18,35,35,35,18,0,0,0
0,0,0,0,11,11,11,0,0,0,0,38,0,0,0,0,1,35,47,35,1,1,0,0
0,0,0,0,11,11,11,0,0,0,0,0,0,0,0,0,1,35,0,35,0,1,0,0
0,0,0,0,11,11,11,0,38,1,1,1,1,34,1,3,1,0,0,0,0,3,0,0
0,0,0,0,33,1,1,1,1,1,11,11,11,0,1,11,11,0,0,0,0,3,0,0
0,3,0,1,1,1,11,11,11,1,11,11,11,0,1,11,11,0,0,31,31,1,0,0
0,0,0,1,13,18,11,11,11,1,11,11,11,0,1,1,1,1,46,1,1,1,0,0
0,0,0,3,0,0,0,39,0,0,0,39,0,0,0,0,0,0,0,31,1,0,0,0
0,0,0,3,18,0,0,0,0,0,0,0,18,0,0,0,18,0,0,45,3,0,0,0
0,0,40,1,11,0,0,0,0,0,0,0,0,0,0,0,0,0,0,44,3,0,0,0
0,0,41,1,11,43,0,0,0,1,0,0,0,0,0,0,0,0,0,42,1,0,0,0
0,0,41,1,11,0,0,0,13,1,1,3,1,0,0,0,0,1,3,1,1,0,0,0
0,0,40,1,18,0,0,0,0,1,0,0,3,0,0,0,0,3,0,0,0,0,0,0
0,0,0,3,0,0,0,0,0,3,0,0,0,0,0,0,0,0,0,0,0,0,0,0
0,0,0,3,13,0,0,0,0,3,0,0,0,0,0,0,0,0,0,0,0,0,0,0
0,0,0,1,0,0,0,0,0,1,11,11,11,0,0,0,0,0,0,0,0,0,0,0
0,3,0,1,1,0,0,0,1,1,11,11,11,0,0,0,3,0,0,0,0,0,3,0
0,0,0,0,0,0,0,0,0,0,11,11,11,0,0,0,0,0,0,0,0,0,0,0
0,0,0,0,0,38,0,0,0,0,0,39,0,0,0,0,0,0,0,0,0,38,0,0
0,0,0,0,0,0,0,0,0,0,0,0,0,0,0,0,0,38,0,0,0,0,0,0
0,0,0,3,0,0,0,0,0,3,0,0,0,0,0,0,3,0,0,0,0,0,3,0
0,0,0,0,0,0,0,0,0,0,0,0,0,0,0,0,0,0,0,0,0,0,0,0
:endlayer
layer: 7
0,0,0,0,0,0,0,0,0,0,0,0,0,0,0,0,0,0,0,0,0,0,0,0
0,0,0,0,0,0,0,0,0,0,0,0,0,0,0,0,18,60,60,60,18,0,0,0
0,0,0,0,50,11,49,0,0,0,0,0,0,0,0,0,1,35,35,35,1,1,0,0
0,0,0,0,50,11,49,0,0,0,0,0,0,0,0,0,1,36,36,36,0,1,0,0
0,0,0,0,50,11,49,0,0,1,1,1,1,3,1,3,1,0,0,0,0,3,0,0
0,0,0,0,0,33,1,1,1,1,50,11,49,0,1,0,0,0,0,0,0,3,0,0
0,3,0,1,1,1,50,11,49,1,50,11,49,0,1,18,0,0,0,31,31,1,0,0
0,0,55,1,0,18,50,11,49,1,50,11,49,3,1,1,1,1,19,1,1,1,0,0
0,0,0,3,0,0,0,0,0,59,0,0,0,0,0,0,0,0,0,0,1,0,0,0
0,0,0,3,18,0,0,0,0,53,0,0,18,0,0,0,18,0,0,0,3,0,0,0
0,0,55,1,31,0,0,0,0,58,0,0,0,0,0,0,0,0,0,0,3,0,0,0
0,0,0,1,11,0,0,0,0,1,0,0,57,0,0,0,0,57,0,0,1,0,0,0
0,0,0,1,45,0,0,0,0,1,1,3,1,54,53,53,52,1,3,1,1,0,0,0
0,0,55,1,18,0,0,0,0,1,0,0,3,0,0,0,0,3,0,56,0,0,0,0
0,0,0,3,0,0,0,0,0,3,0,0,0,0,0,0,0,0,0,0,0,0,0,0
0,0,0,3,0,0,0,0,0,3,0,0,0,0,0,0,0,0,0,0,0,0,0,0
0,0,55,1,0,0,0,0,0,1,50,11,49,0,0,0,0,0,0,0,0,0,0,0
0,3,0,1,1,54,53,52,1,1,50,11,49,0,0,0,3,0,0,0,0,0,3,0
0,0,0,0,0,0,51,0,0,0,50,11,49,0,0,0,0,0,0,0,0,0,0,0
0,0,0,0,0,0,0,0,0,0,0,0,0,0,0,0,0,0,0,0,0,0,0,0
0,0,0,0,0,0,0,0,0,0,0,0,0,0,0,0,0,0,0,0,0,0,0,0
0,0,0,3,0,0,0,0,0,3,0,0,0,0,0,0,3,0,0,0,0,0,3,0
0,0,0,0,0,0,0,0,0,0,0,0,0,0,0,0,0,0,0,0,0,0,0,0
:endlayer
layer: 8
0,0,0,0,0,0,0,0,0,0,0,0,0,0,0,0,0,0,0,0,0,0,0,0
0,0,0,0,0,0,0,0,0,0,0,0,0,0,0,0,57,18,18,18,0,57,0,0
0,0,0,0,0,0,0,0,0,0,0,0,0,0,0,55,1,1,1,1,1,1,63,0
0,0,0,0,0,0,0,0,0,0,0,0,0,0,0,0,1,0,0,0,64,1,0,0
0,0,0,0,0,0,0,0,0,1,1,1,1,1,1,1,1,0,0,0,0,1,0,0
0,0,0,3,0,0,33,1,1,1,64,0,0,64,1,63,0,0,0,0,0,1,0,0
0,40,40,1,1,1,1,1,1,1,0,0,0,0,1,18,18,18,18,18,18,1,0,0
0,40,41,1,40,40,40,40,40,1,40,40,40,40,1,1,1,1,1,1,1,1,63,0
0,40,41,1,63,0,0,0,0,1,63,0,40,0,0,0,40,0,0,55,1,64,0,0
0,40,41,1,40,0,0,0,55,1,0,0,40,40,40,40,40,0,0,0,1,0,0,0
0,40,41,1,40,0,0,0,0,1,0,0,0,0,0,0,0,0,0,0,1,0,0,0
0,40,41,1,40,0,0,0,0,1,63,0,0,0,0,0,0,0,0,55,1,0,0,0
0,40,41,1,40,0,0,0,0,1,1,1,1,1,1,1,1,1,1,1,1,63,0,0
0,40,41,1,40,0,0,0,0,1,0,0,19,53,53,53,53,19,0,0,64,0,0,0
0,40,41,1,63,0,0,0,55,1,0,0,0,0,0,0,0,0,0,0,0,0,0,0
0,40,41,1,0,0,0,0,0,1,0,0,0,0,0,0,0,0,0,0,0,0,0,0
0,40,41,1,0,0,57,0,0,1,0,0,0,0,0,0,0,0,0,0,0,0,0,0
0,40,40,1,1,1,1,1,1,1,63,0,0,0,0,0,40,40,40,40,40,40,40,0
0,0,0,40,62,61,62,61,62,40,0,0,0,0,0,0,40,61,62,61,62,61,40,0
0,0,0,40,62,61,62,61,62,40,0,0,0,0,0,0,40,61,62,61,62,61,40,0
0,0,0,40,62,61,62,61,62,40,0,0,0,0,0,0,40,61,62,61,62,61,40,0
0,0,0,40,40,40,40,40,40,40,0,0,0,0,0,0,40,40,40,40,40,40,40,0
0,0,0,0,0,0,0,0,0,0,0,0,0,0,0,0,0,0,0,0,0,0,0,0
:endlayer
layer: 9
0,0,0,0,0,0,0,0,0,0,0,0,0,0,0,0,0,0,0,0,0,0,0,0
0,0,0,0,0,0,0,0,0,0,0,0,0,0,0,0,65,58,65,65,58,65,0,0
0,0,0,69,0,0,0,0,0,0,0,0,0,0,0,0,66,66,66,66,66,66,65,0
0,0,68,11,67,0,0,0,0,65,58,65,58,65,58,65,66,1,1,1,1,66,54,0
0,0,0,3,0,0,0,0,65,66,66,66,66,66,66,66,66,1,1,1,1,66,65,0
0,0,0,3,0,0,0,33,1,1,1,1,1,1,1,1,1,1,1,1,1,66,65,0
0,0,65,66,66,66,66,66,66,66,1,1,1,1,1,1,1,1,1,1,1,66,54,0
0,0,52,66,1,1,1,1,1,66,1,1,1,1,1,1,1,1,1,1,66,66,65,0
0,0,65,66,1,1,1,1,1,66,1,1,1,1,1,1,1,1,1,1,66,65,0,0
0,0,52,66,1,1,1,1,1,1,1,1,1,1,1,1,1,1,1,1,66,54,0,0
0,0,65,66,1,1,1,1,1,66,1,1,1,1,1,1,1,1,1,1,66,65,0,0
0,0,52,66,1,1,1,1,1,66,1,1,1,1,1,1,1,1,1,1,66,54,0,0
0,0,52,66,1,1,1,1,1,66,66,66,66,66,66,66,66,66,66,66,66,65,0,0
0,0,65,66,1,1,1,1,1,66,59,65,59,65,59,59,65,59,65,59,65,0,0,0
0,0,52,66,1,1,1,1,1,66,54,0,0,0,0,0,0,0,0,0,0,0,0,0
0,0,65,66,1,1,1,1,1,66,65,0,0,0,0,0,0,0,0,0,0,0,0,0
0,0,52,66,1,1,1,1,1,66,54,0,0,0,0,0,0,0,0,0,0,0,0,0
0,0,65,66,66,66,66,66,66,66,65,0,0,0,0,0,0,0,0,0,0,0,0,0
0,0,0,65,59,65,59,65,59,65,0,0,0,0,0,0,0,0,0,0,0,0,0,0
0,0,0,0,0,0,0,0,0,0,0,0,0,0,0,0,0,0,0,0,0,0,0,0
0,0,0,0,0,0,0,0,0,0,0,0,0,0,0,0,0,0,0,0,0,0,0,0
0,0,0,0,0,0,0,0,0,0,0,0,0,0,0,0,0,0,0,0,0,0,0,0
0,0,0,0,0,0,0,0,0,0,0,0,0,0,0,0,0,0,0,0,0,0,0,0
:endlayer
layer: 10
0,0,0,0,0,0,0,0,0,0,0,0,0,0,0,0,0,0,0,0,0,0,0,0
0,0,0,0,0,0,0,0,0,0,0,0,0,0,0,0,70,70,70,70,70,70,0,0
0,0,0,0,0,0,0,0,0,0,0,0,0,0,0,0,1,1,1,1,1,1,70,0
0,0,0,38,0,0,0,0,0,70,70,70,70,70,70,70,1,38,0,0,38,1,70,0
0,0,0,0,0,0,0,0,70,1,1,1,1,1,1,1,1,1,92,92,1,1,70,0
0,0,0,57,0,0,0,0,0,82,0,91,0,0,0,0,0,90,0,0,1,1,70,0
0,0,70,1,1,1,1,1,1,1,0,0,89,88,87,0,86,86,86,0,1,1,70,0
0,0,70,1,38,0,0,0,38,16,0,0,84,84,84,0,86,86,86,85,1,1,70,0
0,0,70,1,0,0,0,0,0,1,0,0,84,84,84,83,49,71,71,50,1,70,0,0
0,0,70,1,0,0,0,0,0,82,0,0,81,80,79,0,71,78,77,71,1,70,0,0
0,0,70,1,0,0,0,0,0,1,74,0,0,0,0,0,71,78,77,71,1,70,0,0
0,0,70,1,0,0,0,0,0,16,74,76,75,74,73,72,49,71,71,50,1,70,0,0
0,0,70,1,0,5,5,5,0,1,1,1,1,1,1,1,1,1,1,1,1,70,0,0
0,0,70,1,0,7,7,7,0,1,70,70,70,70,70,70,70,70,70,70,70,0,0,0
0,0,70,1,0,7,7,7,0,1,70,0,0,0,0,0,0,0,0,0,0,0,0,0
0,0,70,1,0,5,5,5,0,1,70,0,0,0,0,0,0,0,0,0,0,0,0,0
0,0,70,1,38,0,0,0,38,1,70,0,0,0,0,0,0,0,0,0,0,0,0,0
0,0,70,1,1,1,1,1,1,1,70,0,0,0,0,0,0,0,0,0,0,0,0,0
0,0,0,70,70,70,70,70,70,70,0,0,0,0,0,0,0,0,0,0,0,0,0,0
0,0,0,0,0,0,0,0,0,0,0,0,0,0,0,0,0,0,0,0,0,0,0,0
0,0,0,0,0,0,0,0,0,0,0,0,0,0,0,0,0,0,0,0,0,0,0,0
0,0,0,0,0,0,0,0,0,0,0,0,0,0,0,0,0,0,0,0,0,0,0,0
0,0,0,0,0,0,0,0,0,0,0,0,0,0,0,0,0,0,0,0,0,0,0,0
:endlayer
layer: 11
0,0,0,0,0,0,0,0,0,0,0,0,0,0,0,0,0,0,0,0,0,0,0,0
0,0,0,0,0,0,0,0,0,0,0,0,0,0,0,0,0,0,0,0,0,0,0,0
0,0,0,0,0,0,0,0,0,0,0,0,0,0,0,0,70,0,70,70,0,70,0,0
0,0,0,0,0,0,0,0,0,0,0,0,0,0,0,0,0,0,0,0,0,0,0,0
0,0,0,0,0,0,0,0,0,1,3,1,3,1,3,1,3,1,99,46,1,70,0,0
0,0,0,0,0,0,0,0,0,46,0,0,0,0,0,0,0,90,0,0,3,70,0,0
0,0,0,70,0,70,70,70,0,1,0,0,98,97,96,0,0,0,0,0,1,0,0,0
0,0,0,0,0,0,0,0,0,3,0,0,0,0,0,0,0,0,0,0,3,70,0,0
0,0,0,70,0,0,0,0,0,1,0,0,0,0,0,0,18,0,0,18,1,0,0,0
0,0,0,0,0,0,0,0,0,46,0,0,95,94,93,0,0,0,0,0,3,0,0,0
0,0,0,70,0,0,0,0,0,1,0,0,0,0,0,0,0,0,0,0,1,0,0,0
0,0,0,0,0,0,0,0,0,3,0,0,0,0,0,0,18,0,0,18,3,0,0,0
0,0,0,0,0,0,0,0,0,1,3,1,3,1,3,3,1,3,1,3,1,0,0,0
0,0,0,70,0,0,0,0,0,70,0,0,0,0,0,0,0,0,0,0,3,0,0,0
0,0,0,0,0,0,0,0,0,0,0,0,0,0,0,0,0,0,0,0,0,0,0,0
0,0,0,70,0,0,0,0,0,70,0,0,0,0,0,0,0,0,0,0,0,0,0,0
0,0,0,0,0,0,0,0,0,0,0,0,0,0,0,0,0,0,0,0,0,0,0,0
0,0,0,70,0,70,70,70,0,70,0,0,0,0,0,0,0,0,0,0,0,0,0,0
0,0,0,0,0,0,0,0,0,0,0,0,0,0,0,0,0,0,0,0,0,0,0,0
0,0,0,0,0,0,0,0,0,0,0,0,0,0,0,0,0,0,0,0,0,0,0,0
0,0,0,0,0,0,0,0,0,0,0,0,0,0,0,0,0,0,0,0,0,0,0,0
0,0,0,0,0,0,0,0,0,0,0,0,0,0,0,0,0,0,0,0,0,0,0,0
0,0,0,0,0,0,0,0,0,0,0,0,0,0,0,0,0,0,0,0,0,0,0,0
:endlayer
layer: 12
0,0,0,0,0,0,0,0,0,0,0,0,0,0,0,0,0,0,0,0,0,0,0,0
0,0,0,0,0,0,0,0,0,0,0,0,0,0,0,0,0,0,0,0,0,0,0,0
0,0,0,0,0,0,0,0,0,0,0,0,0,0,0,0,0,0,0,0,0,0,0,0
0,0,0,0,0,0,0,0,0,0,0,0,0,0,0,0,0,0,0,0,0,0,0,0
0,0,0,0,0,0,0,0,0,1,3,1,3,1,3,1,3,1,34,34,1,0,0,0
0,0,0,0,0,0,0,0,0,1,0,64,0,64,0,64,0,90,0,0,3,0,0,0
0,0,0,0,0,0,0,0,0,1,63,0,0,0,0,0,0,0,0,55,1,0,0,0
0,0,0,0,0,0,0,0,0,3,0,0,0,0,0,0,0,0,0,0,3,0,0,0
0,0,0,0,0,0,0,0,0,1,63,0,0,0,0,0,18,0,0,18,1,0,0,0
0,0,0,0,0,0,0,0,0,16,0,0,0,0,0,0,0,0,0,0,3,0,0,0
0,0,0,0,0,0,0,0,0,1,63,0,0,0,0,0,0,0,0,55,1,0,0,0
0,0,0,0,0,0,0,0,0,3,0,57,0,57,0,0,18,0,57,18,3,0,0,0
0,0,0,0,0,0,0,0,0,1,3,1,3,1,3,3,1,3,1,3,1,0,0,0
0,0,0,0,0,0,0,0,0,0,0,0,0,0,0,0,0,0,0,0,3,0,0,0
0,0,0,0,0,0,0,0,0,0,0,0,0,0,0,0,0,0,0,0,3,0,0,0
0,0,0,0,0,0,0,0,0,0,0,0,0,0,0,0,0,0,0,102,11,101,0,0
0,0,0,0,0,0,0,0,0,0,0,0,0,0,0,0,0,0,0,0,100,0,0,0
0,0,0,0,0,0,0,0,0,0,0,0,0,0,0,0,0,0,0,0,0,0,0,0
0,0,0,0,0,0,0,0,0,0,0,0,0,0,0,0,0,0,0,0,0,0,0,0
0,0,0,0,0,0,0,0,0,0,0,0,0,0,0,0,0,0,0,0,0,0,0,0
0,0,0,0,0,0,0,0,0,0,0,0,0,0,0,0,0,0,0,0,0,0,0,0
0,0,0,0,0,0,0,0,0,0,0,0,0,0,0,0,0,0,0,0,0,0,0,0
0,0,0,0,0,0,0,0,0,0,0,0,0,0,0,0,0,0,0,0,0,0,0,0
:endlayer
layer: 13
0,0,0,0,0,0,0,0,0,0,0,0,0,0,0,0,0,0,0,0,0,0,0,0
0,0,0,0,0,0,0,0,0,0,0,0,0,0,0,0,0,0,0,0,0,0,0,0
0,0,0,0,0,0,0,0,0,0,0,0,0,0,0,0,0,0,0,0,0,0,0,0
0,0,0,0,0,0,0,0,0,0,0,0,0,0,0,0,0,0,0,0,0,0,0,0
0,0,0,0,0,0,0,0,0,1,1,1,1,1,1,1,1,1,1,1,1,0,0,0
0,0,0,0,0,0,0,0,0,1,0,0,0,0,0,0,0,90,0,0,1,0,0,0
0,0,0,0,0,0,0,0,0,1,0,0,0,0,0,0,0,0,0,0,1,0,0,0
0,0,0,0,0,0,0,0,0,1,0,0,0,0,0,0,0,0,0,0,1,0,0,0
0,0,0,0,0,0,0,0,0,1,0,0,0,0,0,0,71,71,71,71,1,0,0,0
0,0,0,0,0,0,0,0,0,1,0,0,0,0,0,0,103,103,103,103,1,0,0,0
0,0,0,0,0,0,0,0,0,1,0,0,0,0,0,0,103,103,103,103,1,0,0,0
0,0,0,0,0,0,0,0,0,1,0,0,0,0,0,0,71,71,71,71,1,0,0,0
0,0,0,0,0,0,0,0,0,1,1,1,1,1,1,1,1,1,1,1,1,0,0,0
0,0,0,0,0,0,0,0,0,0,0,0,0,0,0,0,0,0,0,0,0,0,0,0
0,0,0,0,0,0,0,0,0,0,0,0,0,0,0,0,0,0,0,0,0,0,0,0
0,0,0,0,0,0,0,0,0,0,0,0,0,0,0,0,0,0,0,0,38,0,0,0
0,0,0,0,0,0,0,0,0,0,0,0,0,0,0,0,0,0,0,0,0,0,0,0
0,0,0,0,0,0,0,0,0,0,0,0,0,0,0,0,0,0,0,0,0,0,0,0
0,0,0,0,0,0,0,0,0,0,0,0,0,0,0,0,0,0,0,0,0,0,0,0
0,0,0,0,0,0,0,0,0,0,0,0,0,0,0,0,0,0,0,0,0,0,0,0
0,0,0,0,0,0,0,0,0,0,0,0,0,0,0,0,0,0,0,0,0,0,0,0
0,0,0,0,0,0,0,0,0,0,0,0,0,0,0,0,0,0,0,0,0,0,0,0
0,0,0,0,0,0,0,0,0,0,0,0,0,0,0,0,0,0,0,0,0,0,0,0
:endlayer
layer: 14
0,0,0,0,0,0,0,0,0,0,0,0,0,0,0,0,0,0,0,0,0,0,0,0
0,0,0,0,0,0,0,0,0,0,0,0,0,0,0,0,0,0,0,0,0,0,0,0
0,0,0,0,0,0,0,0,0,0,0,0,0,0,0,0,0,0,0,0,0,0,0,0
0,0,0,0,0,0,0,0,0,65,58,65,58,65,58,58,65,58,65,58,65,0,0,0
0,0,0,0,0,0,0,0,65,66,66,66,66,66,66,66,66,66,66,66,66,65,0,0
0,0,0,0,0,0,0,0,52,66,1,1,1,1,1,1,1,90,1,1,66,54,0,0
0,0,0,0,0,0,0,0,65,66,1,1,1,1,1,1,1,1,1,1,66,65,0,0
0,0,0,0,0,0,0,0,52,66,1,1,1,1,1,1,1,1,1,1,66,54,0,0
0,0,0,0,0,0,0,0,65,66,1,1,1,1,1,1,1,1,1,1,66,65,0,0
0,0,0,0,0,0,0,0,52,66,1,1,1,1,1,1,1,1,1,1,66,54,0,0
0,0,0,0,0,0,0,0,65,66,1,1,1,1,1,1,1,1,1,1,66,65,0,0
0,0,0,0,0,0,0,0,52,66,1,1,1,1,1,1,1,1,1,1,66,54,0,0
0,0,0,0,0,0,0,0,65,66,66,66,66,66,66,66,66,66,66,66,66,65,0,0
0,0,0,0,0,0,0,0,0,65,59,65,59,65,59,59,65,59,65,59,65,0,0,0
0,0,0,0,0,0,0,0,0,0,0,0,0,0,0,0,0,0,0,0,0,0,0,0
0,0,0,0,0,0,0,0,0,0,0,0,0,0,0,0,0,0,0,0,0,0,0,0
0,0,0,0,0,0,0,0,0,0,0,0,0,0,0,0,0,0,0,0,0,0,0,0
0,0,0,0,0,0,0,0,0,0,0,0,0,0,0,0,0,0,0,0,0,0,0,0
0,0,0,0,0,0,0,0,0,0,0,0,0,0,0,0,0,0,0,0,0,0,0,0
0,0,0,0,0,0,0,0,0,0,0,0,0,0,0,0,0,0,0,0,0,0,0,0
0,0,0,0,0,0,0,0,0,0,0,0,0,0,0,0,0,0,0,0,0,0,0,0
0,0,0,0,0,0,0,0,0,0,0,0,0,0,0,0,0,0,0,0,0,0,0,0
0,0,0,0,0,0,0,0,0,0,0,0,0,0,0,0,0,0,0,0,0,0,0,0
:endlayer
layer: 15
0,0,0,0,0,0,0,0,0,0,0,0,0,0,0,0,0,0,0,0,0,0,0,0
0,0,0,0,0,0,0,0,0,0,0,0,0,0,0,0,0,0,0,0,0,0,0,0
0,0,0,0,0,0,0,0,0,0,0,0,0,0,0,0,0,0,0,0,0,0,0,0
0,0,0,0,0,0,0,0,0,70,70,70,70,70,70,70,70,70,70,70,70,0,0,0
0,0,0,0,0,0,0,0,70,1,1,1,1,1,1,1,1,1,1,1,1,70,0,0
0,0,0,0,0,0,0,0,70,1,38,0,0,0,0,0,0,90,0,38,1,70,0,0
0,0,0,0,0,0,0,0,70,1,0,1,3,0,3,1,0,0,0,0,1,70,0,0
0,0,0,0,0,0,0,0,70,1,0,3,0,0,0,3,0,0,0,0,1,70,0,0
0,0,0,0,0,0,0,0,70,1,0,0,0,3,0,0,0,0,0,0,1,70,0,0
0,0,0,0,0,0,0,0,70,1,0,3,0,0,0,3,0,0,0,0,1,70,0,0
0,0,0,0,0,0,0,0,70,1,0,1,3,0,3,1,0,0,0,0,1,70,0,0
0,0,0,0,0,0,0,0,70,1,38,0,0,0,0,0,0,0,0,38,1,70,0,0
0,0,0,0,0,0,0,0,70,1,1,1,1,1,1,1,1,1,1,1,1,70,0,0
0,0,0,0,0,0,0,0,0,70,70,70,70,70,70,70,70,70,70,70,70,0,0,0
0,0,0,0,0,0,0,0,0,0,0,0,0,0,0,0,0,0,0,0,0,0,0,0
0,0,0,0,0,0,0,0,0,0,0,0,0,0,0,0,0,0,0,0,0,0,0,0
0,0,0,0,0,0,0,0,0,0,0,0,0,0,0,0,0,0,0,0,0,0,0,0
0,0,0,0,0,0,0,0,0,0,0,0,0,0,0,0,0,0,0,0,0,0,0,0
0,0,0,0,0,0,0,0,0,0,0,0,0,0,0,0,0,0,0,0,0,0,0,0
0,0,0,0,0,0,0,0,0,0,0,0,0,0,0,0,0,0,0,0,0,0,0,0
0,0,0,0,0,0,0,0,0,0,0,0,0,0,0,0,0,0,0,0,0,0,0,0
0,0,0,0,0,0,0,0,0,0,0,0,0,0,0,0,0,0,0,0,0,0,0,0
0,0,0,0,0,0,0,0,0,0,0,0,0,0,0,0,0,0,0,0,0,0,0,0
:endlayer
layer: 16
0,0,0,0,0,0,0,0,0,0,0,0,0,0,0,0,0,0,0,0,0,0,0,0
0,0,0,0,0,0,0,0,0,0,0,0,0,0,0,0,0,0,0,0,0,0,0,0
0,0,0,0,0,0,0,0,0,0,0,0,0,0,0,0,0,0,0,0,0,0,0,0
0,0,0,0,0,0,0,0,0,0,0,0,0,0,0,0,0,0,0,0,0,0,0,0
0,0,0,0,0,0,0,0,0,70,0,70,0,70,104,104,70,0,70,0,70,0,0,0
0,0,0,0,0,0,0,0,0,0,0,0,0,0,0,0,0,0,0,0,0,0,0,0
0,0,0,0,0,0,0,0,0,70,0,1,3,0,3,1,0,0,0,0,70,0,0,0
0,0,0,0,0,0,0,0,0,0,0,3,0,0,0,3,0,0,0,0,0,0,0,0
0,0,0,0,0,0,0,0,0,70,0,0,0,3,0,0,0,0,0,0,70,0,0,0
0,0,0,0,0,0,0,0,0,0,0,3,0,0,0,3,0,0,0,0,0,0,0,0
0,0,0,0,0,0,0,0,0,70,0,1,3,0,3,1,0,0,0,0,70,0,0,0
0,0,0,0,0,0,0,0,0,0,0,0,0,0,0,0,0,0,0,0,0,0,0,0
0,0,0,0,0,0,0,0,0,70,0,70,0,70,104,104,70,0,70,0,70,0,0,0
0,0,0,0,0,0,0,0,0,0,0,0,0,0,0,0,0,0,0,0,0,0,0,0
0,0,0,0,0,0,0,0,0,0,0,0,0,0,0,0,0,0,0,0,0,0,0,0
0,0,0,0,0,0,0,0,0,0,0,0,0,0,0,0,0,0,0,0,0,0,0,0
0,0,0,0,0,0,0,0,0,0,0,0,0,0,0,0,0,0,0,0,0,0,0,0
0,0,0,0,0,0,0,0,0,0,0,0,0,0,0,0,0,0,0,0,0,0,0,0
0,0,0,0,0,0,0,0,0,0,0,0,0,0,0,0,0,0,0,0,0,0,0,0
0,0,0,0,0,0,0,0,0,0,0,0,0,0,0,0,0,0,0,0,0,0,0,0
0,0,0,0,0,0,0,0,0,0,0,0,0,0,0,0,0,0,0,0,0,0,0,0
0,0,0,0,0,0,0,0,0,0,0,0,0,0,0,0,0,0,0,0,0,0,0,0
0,0,0,0,0,0,0,0,0,0,0,0,0,0,0,0,0,0,0,0,0,0,0,0
:endlayer
layer: 17
0,0,0,0,0,0,0,0,0,0,0,0,0,0,0,0,0,0,0,0,0,0,0,0
0,0,0,0,0,0,0,0,0,0,0,0,0,0,0,0,0,0,0,0,0,0,0,0
0,0,0,0,0,0,0,0,0,0,0,0,0,0,0,0,0,0,0,0,0,0,0,0
0,0,0,0,0,0,0,0,0,0,0,0,0,0,0,0,0,0,0,0,0,0,0,0
0,0,0,0,0,0,0,0,0,0,0,0,0,0,0,0,0,0,0,0,0,0,0,0
0,0,0,0,0,0,0,0,0,0,0,0,0,0,0,0,0,0,0,0,0,0,0,0
0,0,0,0,0,0,0,0,0,0,0,1,3,3,3,1,0,0,0,0,0,0,0,0
0,0,0,0,0,0,0,0,0,0,0,3,0,0,0,3,0,0,0,0,0,0,0,0
0,0,0,0,0,0,0,0,0,0,0,3,0,3,0,3,0,0,0,0,0,0,0,0
0,0,0,0,0,0,0,0,0,0,0,3,0,0,0,3,0,0,0,0,0,0,0,0
0,0,0,0,0,0,0,0,0,0,0,1,3,3,3,1,0,0,0,0,0,0,0,0
0,0,0,0,0,0,0,0,0,0,0,0,0,0,0,0,0,0,0,0,0,0,0,0
0,0,0,0,0,0,0,0,0,0,0,0,0,0,0,0,0,0,0,0,0,0,0,0
0,0,0,0,0,0,0,0,0,0,0,0,0,0,0,0,0,0,0,0,0,0,0,0
0,0,0,0,0,0,0,0,0,0,0,0,0,0,0,0,0,0,0,0,0,0,0,0
0,0,0,0,0,0,0,0,0,0,0,0,0,0,0,0,0,0,0,0,0,0,0,0
0,0,0,0,0,0,0,0,0,0,0,0,0,0,0,0,0,0,0,0,0,0,0,0
0,0,0,0,0,0,0,0,0,0,0,0,0,0,0,0,0,0,0,0,0,0,0,0
0,0,0,0,0,0,0,0,0,0,0,0,0,0,0,0,0,0,0,0,0,0,0,0
0,0,0,0,0,0,0,0,0,0,0,0,0,0,0,0,0,0,0,0,0,0,0,0
0,0,0,0,0,0,0,0,0,0,0,0,0,0,0,0,0,0,0,0,0,0,0,0
0,0,0,0,0,0,0,0,0,0,0,0,0,0,0,0,0,0,0,0,0,0,0,0
0,0,0,0,0,0,0,0,0,0,0,0,0,0,0,0,0,0,0,0,0,0,0,0
:endlayer
layer: 18
0,0,0,0,0,0,0,0,0,0,0,0,0,0,0,0,0,0,0,0,0,0,0,0
0,0,0,0,0,0,0,0,0,0,0,0,0,0,0,0,0,0,0,0,0,0,0,0
0,0,0,0,0,0,0,0,0,0,0,0,0,0,0,0,0,0,0,0,0,0,0,0
0,0,0,0,0,0,0,0,0,0,0,0,0,0,0,0,0,0,0,0,0,0,0,0
0,0,0,0,0,0,0,0,0,0,0,0,0,0,0,0,0,0,0,0,0,0,0,0
0,0,0,0,0,0,0,0,0,0,0,0,0,0,0,0,0,0,0,0,0,0,0,0
0,0,0,0,0,0,0,0,0,0,0,1,14,70,16,1,0,0,0,0,0,0,0,0
0,0,0,0,0,0,0,0,0,0,0,19,1,3,1,19,0,0,0,0,0,0,0,0
0,0,0,0,0,0,0,0,0,0,0,70,3,106,3,70,0,0,0,0,0,0,0,0
0,0,0,0,0,0,0,0,0,0,0,34,1,3,1,34,0,0,0,0,0,0,0,0
0,0,0,0,0,0,0,0,0,0,0,1,14,70,16,1,0,0,0,0,0,0,0,0
0,0,0,0,0,0,0,0,0,0,0,0,0,105,0,0,0,0,0,0,0,0,0,0
0,0,0,0,0,0,0,0,0,0,0,0,0,0,0,0,0,0,0,0,0,0,0,0
0,0,0,0,0,0,0,0,0,0,0,0,0,0,0,0,0,0,0,0,0,0,0,0
0,0,0,0,0,0,0,0,0,0,0,0,0,0,0,0,0,0,0,0,0,0,0,0
0,0,0,0,0,0,0,0,0,0,0,0,0,0,0,0,0,0,0,0,0,0,0,0
0,0,0,0,0,0,0,0,0,0,0,0,0,0,0,0,0,0,0,0,0,0,0,0
0,0,0,0,0,0,0,0,0,0,0,0,0,0,0,0,0,0,0,0,0,0,0,0
0,0,0,0,0,0,0,0,0,0,0,0,0,0,0,0,0,0,0,0,0,0,0,0
0,0,0,0,0,0,0,0,0,0,0,0,0,0,0,0,0,0,0,0,0,0,0,0
0,0,0,0,0,0,0,0,0,0,0,0,0,0,0,0,0,0,0,0,0,0,0,0
0,0,0,0,0,0,0,0,0,0,0,0,0,0,0,0,0,0,0,0,0,0,0,0
0,0,0,0,0,0,0,0,0,0,0,0,0,0,0,0,0,0,0,0,0,0,0,0
:endlayer
layer: 19
0,0,0,0,0,0,0,0,0,0,0,0,0,0,0,0,0,0,0,0,0,0,0,0
0,0,0,0,0,0,0,0,0,0,0,0,0,0,0,0,0,0,0,0,0,0,0,0
0,0,0,0,0,0,0,0,0,0,0,0,0,0,0,0,0,0,0,0,0,0,0,0
0,0,0,0,0,0,0,0,0,0,0,0,0,0,0,0,0,0,0,0,0,0,0,0
0,0,0,0,0,0,0,0,0,0,0,0,0,0,0,0,0,0,0,0,0,0,0,0
0,0,0,0,0,0,0,0,0,0,0,0,0,0,0,0,0,0,0,0,0,0,0,0
0,0,0,0,0,0,0,0,0,0,0,70,0,0,0,70,0,0,0,0,0,0,0,0
0,0,0,0,0,0,0,0,0,0,0,0,1,38,1,0,0,0,0,0,0,0,0,0
0,0,0,0,0,0,0,0,0,0,0,0,38,3,38,0,0,0,0,0,0,0,0,0
0,0,0,0,0,0,0,0,0,0,0,0,1,38,1,0,0,0,0,0,0,0,0,0
0,0,0,0,0,0,0,0,0,0,0,70,0,0,0,70,0,0,0,0,0,0,0,0
0,0,0,0,0,0,0,0,0,0,0,0,0,108,107,0,0,0,0,0,0,0,0,0
0,0,0,0,0,0,0,0,0,0,0,0,0,0,0,0,0,0,0,0,0,0,0,0
0,0,0,0,0,0,0,0,0,0,0,0,0,0,0,0,0,0,0,0,0,0,0,0
0,0,0,0,0,0,0,0,0,0,0,0,0,0,0,0,0,0,0,0,0,0,0,0
0,0,0,0,0,0,0,0,0,0,0,0,0,0,0,0,0,0,0,0,0,0,0,0
0,0,0,0,0,0,0,0,0,0,0,0,0,0,0,0,0,0,0,0,0,0,0,0
0,0,0,0,0,0,0,0,0,0,0,0,0,0,0,0,0,0,0,0,0,0,0,0
0,0,0,0,0,0,0,0,0,0,0,0,0,0,0,0,0,0,0,0,0,0,0,0
0,0,0,0,0,0,0,0,0,0,0,0,0,0,0,0,0,0,0,0,0,0,0,0
0,0,0,0,0,0,0,0,0,0,0,0,0,0,0,0,0,0,0,0,0,0,0,0
0,0,0,0,0,0,0,0,0,0,0,0,0,0,0,0,0,0,0,0,0,0,0,0
0,0,0,0,0,0,0,0,0,0,0,0,0,0,0,0,0,0,0,0,0,0,0,0
:endlayer
layer: 20
0,0,0,0,0,0,0,0,0,0,0,0,0,0,0,0,0,0,0,0,0,0,0,0
0,0,0,0,0,0,0,0,0,0,0,0,0,0,0,0,0,0,0,0,0,0,0,0
0,0,0,0,0,0,0,0,0,0,0,0,0,0,0,0,0,0,0,0,0,0,0,0
0,0,0,0,0,0,0,0,0,0,0,0,0,0,0,0,0,0,0,0,0,0,0,0
0,0,0,0,0,0,0,0,0,0,0,0,0,0,0,0,0,0,0,0,0,0,0,0
0,0,0,0,0,0,0,0,0,0,0,0,0,0,0,0,0,0,0,0,0,0,0,0
0,0,0,0,0,0,0,0,0,0,0,0,0,0,0,0,0,0,0,0,0,0,0,0
0,0,0,0,0,0,0,0,0,0,0,0,1,58,1,0,0,0,0,0,0,0,0,0
0,0,0,0,0,0,0,0,0,0,0,0,52,3,54,0,0,0,0,0,0,0,0,0
0,0,0,0,0,0,0,0,0,0,0,0,1,59,1,0,0,0,0,0,0,0,0,0
0,0,0,0,0,0,0,0,0,0,0,0,0,0,0,0,0,0,0,0,0,0,0,0
0,0,0,0,0,0,0,0,0,0,0,0,0,3,107,0,0,0,0,0,0,0,0,0
0,0,0,0,0,0,0,0,0,0,0,0,0,0,0,0,0,0,0,0,0,0,0,0
0,0,0,0,0,0,0,0,0,0,0,0,0,0,0,0,0,0,0,0,0,0,0,0
0,0,0,0,0,0,0,0,0,0,0,0,0,0,0,0,0,0,0,0,0,0,0,0
0,0,0,0,0,0,0,0,0,0,0,0,0,0,0,0,0,0,0,0,0,0,0,0
0,0,0,0,0,0,0,0,0,0,0,0,0,0,0,0,0,0,0,0,0,0,0,0
0,0,0,0,0,0,0,0,0,0,0,0,0,0,0,0,0,0,0,0,0,0,0,0
0,0,0,0,0,0,0,0,0,0,0,0,0,0,0,0,0,0,0,0,0,0,0,0
0,0,0,0,0,0,0,0,0,0,0,0,0,0,0,0,0,0,0,0,0,0,0,0
0,0,0,0,0,0,0,0,0,0,0,0,0,0,0,0,0,0,0,0,0,0,0,0
0,0,0,0,0,0,0,0,0,0,0,0,0,0,0,0,0,0,0,0,0,0,0,0
0,0,0,0,0,0,0,0,0,0,0,0,0,0,0,0,0,0,0,0,0,0,0,0
:endlayer
layer: 21
0,0,0,0,0,0,0,0,0,0,0,0,0,0,0,0,0,0,0,0,0,0,0,0
0,0,0,0,0,0,0,0,0,0,0,0,0,0,0,0,0,0,0,0,0,0,0,0
0,0,0,0,0,0,0,0,0,0,0,0,0,0,0,0,0,0,0,0,0,0,0,0
0,0,0,0,0,0,0,0,0,0,0,0,0,0,0,0,0,0,0,0,0,0,0,0
0,0,0,0,0,0,0,0,0,0,0,0,0,0,0,0,0,0,0,0,0,0,0,0
0,0,0,0,0,0,0,0,0,0,0,0,0,0,0,0,0,0,0,0,0,0,0,0
0,0,0,0,0,0,0,0,0,0,0,0,0,0,0,0,0,0,0,0,0,0,0,0
0,0,0,0,0,0,0,0,0,0,0,0,1,0,1,0,0,0,0,0,0,0,0,0
0,0,0,0,0,0,0,0,0,0,0,0,0,3,0,0,0,0,0,0,0,0,0,0
0,0,0,0,0,0,0,0,0,0,0,0,1,0,1,0,0,0,0,0,0,0,0,0
0,0,0,0,0,0,0,0,0,0,0,0,0,0,0,0,0,0,0,0,0,0,0,0
0,0,0,0,0,0,0,0,0,0,0,0,0,3,107,0,0,0,0,0,0,0,0,0
0,0,0,0,0,0,0,0,0,0,0,0,0,0,0,0,0,0,0,0,0,0,0,0
0,0,0,0,0,0,0,0,0,0,0,0,0,0,0,0,0,0,0,0,0,0,0,0
0,0,0,0,0,0,0,0,0,0,0,0,0,0,0,0,0,0,0,0,0,0,0,0
0,0,0,0,0,0,0,0,0,0,0,0,0,0,0,0,0,0,0,0,0,0,0,0
0,0,0,0,0,0,0,0,0,0,0,0,0,0,0,0,0,0,0,0,0,0,0,0
0,0,0,0,0,0,0,0,0,0,0,0,0,0,0,0,0,0,0,0,0,0,0,0
0,0,0,0,0,0,0,0,0,0,0,0,0,0,0,0,0,0,0,0,0,0,0,0
0,0,0,0,0,0,0,0,0,0,0,0,0,0,0,0,0,0,0,0,0,0,0,0
0,0,0,0,0,0,0,0,0,0,0,0,0,0,0,0,0,0,0,0,0,0,0,0
0,0,0,0,0,0,0,0,0,0,0,0,0,0,0,0,0,0,0,0,0,0,0,0
0,0,0,0,0,0,0,0,0,0,0,0,0,0,0,0,0,0,0,0,0,0,0,0
:endlayer
layer: 22
0,0,0,0,0,0,0,0,0,0,0,0,0,0,0,0,0,0,0,0,0,0,0,0
0,0,0,0,0,0,0,0,0,0,0,0,0,0,0,0,0,0,0,0,0,0,0,0
0,0,0,0,0,0,0,0,0,0,0,0,0,0,0,0,0,0,0,0,0,0,0,0
0,0,0,0,0,0,0,0,0,0,0,0,0,0,0,0,0,0,0,0,0,0,0,0
0,0,0,0,0,0,0,0,0,0,0,0,0,0,0,0,0,0,0,0,0,0,0,0
0,0,0,0,0,0,0,0,0,0,0,0,0,0,0,0,0,0,0,0,0,0,0,0
0,0,0,0,0,0,0,0,0,0,0,0,0,0,0,0,0,0,0,0,0,0,0,0
0,0,0,0,0,0,0,0,0,0,0,0,1,58,1,0,0,0,0,0,0,0,0,0
0,0,0,0,0,0,0,0,0,0,0,0,52,3,54,0,0,0,0,0,0,0,0,0
0,0,0,0,0,0,0,0,0,0,0,0,1,59,1,0,0,0,0,0,0,0,0,0
0,0,0,0,0,0,0,0,0,0,0,0,0,0,0,0,0,0,0,0,0,0,0,0
0,0,0,0,0,0,0,0,0,0,0,107,107,3,108,107,0,0,0,0,0,0,0,0
0,0,0,0,0,0,0,0,0,0,0,0,0,0,0,0,0,0,0,0,0,0,0,0
0,0,0,0,0,0,0,0,0,0,0,0,0,0,0,0,0,0,0,0,0,0,0,0
0,0,0,0,0,0,0,0,0,0,0,0,0,0,0,0,0,0,0,0,0,0,0,0
0,0,0,0,0,0,0,0,0,0,0,0,0,0,0,0,0,0,0,0,0,0,0,0
0,0,0,0,0,0,0,0,0,0,0,0,0,0,0,0,0,0,0,0,0,0,0,0
0,0,0,0,0,0,0,0,0,0,0,0,0,0,0,0,0,0,0,0,0,0,0,0
0,0,0,0,0,0,0,0,0,0,0,0,0,0,0,0,0,0,0,0,0,0,0,0
0,0,0,0,0,0,0,0,0,0,0,0,0,0,0,0,0,0,0,0,0,0,0,0
0,0,0,0,0,0,0,0,0,0,0,0,0,0,0,0,0,0,0,0,0,0,0,0
0,0,0,0,0,0,0,0,0,0,0,0,0,0,0,0,0,0,0,0,0,0,0,0
0,0,0,0,0,0,0,0,0,0,0,0,0,0,0,0,0,0,0,0,0,0,0,0
:endlayer
layer: 23
0,0,0,0,0,0,0,0,0,0,0,0,0,0,0,0,0,0,0,0,0,0,0,0
0,0,0,0,0,0,0,0,0,0,0,0,0,0,0,0,0,0,0,0,0,0,0,0
0,0,0,0,0,0,0,0,0,0,0,0,0,0,0,0,0,0,0,0,0,0,0,0
0,0,0,0,0,0,0,0,0,0,0,0,0,0,0,0,0,0,0,0,0,0,0,0
0,0,0,0,0,0,0,0,0,0,0,0,0,0,0,0,0,0,0,0,0,0,0,0
0,0,0,0,0,0,0,0,0,0,0,0,0,0,0,0,0,0,0,0,0,0,0,0
0,0,0,0,0,0,0,0,0,0,0,0,0,0,0,0,0,0,0,0,0,0,0,0
0,0,0,0,0,0,0,0,0,0,0,0,1,1,1,0,0,0,0,0,0,0,0,0
0,0,0,0,0,0,0,0,0,0,0,0,1,106,1,0,0,0,0,0,0,0,0,0
0,0,0,0,0,0,0,0,0,0,0,0,1,1,1,0,0,0,0,0,0,0,0,0
0,0,0,0,0,0,0,0,0,0,0,0,0,0,0,0,0,0,0,0,0,0,0,0
0,0,0,0,0,0,0,0,107,107,107,108,108,3,108,107,0,0,0,0,0,0,0,0
0,0,0,0,0,0,0,0,0,0,0,0,0,0,0,0,0,0,0,0,0,0,0,0
0,0,0,0,0,0,0,0,0,0,0,0,0,0,0,0,0,0,0,0,0,0,0,0
0,0,0,0,0,0,0,0,0,0,0,0,0,0,0,0,0,0,0,0,0,0,0,0
0,0,0,0,0,0,0,0,0,0,0,0,0,0,0,0,0,0,0,0,0,0,0,0
0,0,0,0,0,0,0,0,0,0,0,0,0,0,0,0,0,0,0,0,0,0,0,0
0,0,0,0,0,0,0,0,0,0,0,0,0,0,0,0,0,0,0,0,0,0,0,0
0,0,0,0,0,0,0,0,0,0,0,0,0,0,0,0,0,0,0,0,0,0,0,0
0,0,0,0,0,0,0,0,0,0,0,0,0,0,0,0,0,0,0,0,0,0,0,0
0,0,0,0,0,0,0,0,0,0,0,0,0,0,0,0,0,0,0,0,0,0,0,0
0,0,0,0,0,0,0,0,0,0,0,0,0,0,0,0,0,0,0,0,0,0,0,0
0,0,0,0,0,0,0,0,0,0,0,0,0,0,0,0,0,0,0,0,0,0,0,0
:endlayer
layer: 24
0,0,0,0,0,0,0,0,0,0,0,0,0,0,0,0,0,0,0,0,0,0,0,0
0,0,0,0,0,0,0,0,0,0,0,0,0,0,0,0,0,0,0,0,0,0,0,0
0,0,0,0,0,0,0,0,0,0,0,0,0,0,0,0,0,0,0,0,0,0,0,0
0,0,0,0,0,0,0,0,0,0,0,0,0,0,0,0,0,0,0,0,0,0,0,0
0,0,0,0,0,0,0,0,0,0,0,0,0,0,0,0,0,0,0,0,0,0,0,0
0,0,0,0,0,0,0,0,0,0,0,0,0,0,0,0,0,0,0,0,0,0,0,0
0,0,0,0,0,0,0,0,0,0,0,0,0,0,0,0,0,0,0,0,0,0,0,0
0,0,0,0,0,0,0,0,0,0,0,0,16,1,14,0,0,0,0,0,0,0,0,0
0,0,0,0,0,0,0,0,0,0,0,0,16,106,14,0,0,0,0,0,0,0,0,0
0,0,0,0,0,0,0,0,0,0,0,0,16,111,14,0,0,0,0,0,0,0,0,0
0,0,0,0,0,0,0,0,0,0,0,0,0,111,0,0,0,0,0,0,0,0,0,0
0,0,0,0,0,0,0,112,108,3,3,3,3,111,3,3,3,3,108,110,0,0,0,0
0,0,0,0,0,0,0,0,0,0,0,0,0,109,0,0,0,0,0,0,0,0,0,0
0,0,0,0,0,0,0,0,0,0,0,0,0,0,0,0,0,0,0,0,0,0,0,0
0,0,0,0,0,0,0,0,0,0,0,0,0,0,0,0,0,0,0,0,0,0,0,0
0,0,0,0,0,0,0,0,0,0,0,0,0,0,0,0,0,0,0,0,0,0,0,0
0,0,0,0,0,0,0,0,0,0,0,0,0,0,0,0,0,0,0,0,0,0,0,0
0,0,0,0,0,0,0,0,0,0,0,0,0,0,0,0,0,0,0,0,0,0,0,0
0,0,0,0,0,0,0,0,0,0,0,0,0,0,0,0,0,0,0,0,0,0,0,0
0,0,0,0,0,0,0,0,0,0,0,0,0,0,0,0,0,0,0,0,0,0,0,0
0,0,0,0,0,0,0,0,0,0,0,0,0,0,0,0,0,0,0,0,0,0,0,0
0,0,0,0,0,0,0,0,0,0,0,0,0,0,0,0,0,0,0,0,0,0,0,0
0,0,0,0,0,0,0,0,0,0,0,0,0,0,0,0,0,0,0,0,0,0,0,0
:endlayer
layer: 25
0,0,0,0,0,0,0,0,0,0,0,0,0,0,0,0,0,0,0,0,0,0,0,0
0,0,0,0,0,0,0,0,0,0,0,0,0,0,0,0,0,0,0,0,0,0,0,0
0,0,0,0,0,0,0,0,0,0,0,0,0,0,0,0,0,0,0,0,0,0,0,0
0,0,0,0,0,0,0,0,0,0,0,0,0,0,0,0,0,0,0,0,0,0,0,0
0,0,0,0,0,0,0,0,0,0,0,0,0,0,0,0,0,0,0,0,0,0,0,0
0,0,0,0,0,0,0,0,0,0,0,0,0,0,0,0,0,0,0,0,0,0,0,0
0,0,0,0,0,0,0,0,0,0,0,0,0,0,0,0,0,0,0,0,0,0,0,0
0,0,0,0,0,0,0,0,0,0,0,0,0,70,0,0,0,0,0,0,0,0,0,0
0,0,0,0,0,0,0,0,0,0,0,0,0,1,0,0,0,0,0,0,0,0,0,0
0,0,0,0,0,0,0,0,0,0,0,0,0,70,0,0,0,0,0,0,0,0,0,0
0,0,0,0,0,0,0,0,0,0,0,0,0,38,0,0,0,0,0,0,0,0,0,0
0,0,0,0,0,0,0,0,0,0,0,107,108,3,108,108,107,107,107,0,0,0,0,0
0,0,0,0,0,0,0,0,0,0,0,0,0,0,0,0,0,0,0,0,0,0,0,0
0,0,0,0,0,0,0,0,0,0,0,0,0,0,0,0,0,0,0,0,0,0,0,0
0,0,0,0,0,0,0,0,0,0,0,0,0,0,0,0,0,0,0,0,0,0,0,0
0,0,0,0,0,0,0,0,0,0,0,0,0,0,0,0,0,0,0,0,0,0,0,0
0,0,0,0,0,0,0,0,0,0,0,0,0,0,0,0,0,0,0,0,0,0,0,0
0,0,0,0,0,0,0,0,0,0,0,0,0,0,0,0,0,0,0,0,0,0,0,0
0,0,0,0,0,0,0,0,0,0,0,0,0,0,0,0,0,0,0,0,0,0,0,0
0,0,0,0,0,0,0,0,0,0,0,0,0,0,0,0,0,0,0,0,0,0,0,0
0,0,0,0,0,0,0,0,0,0,0,0,0,0,0,0,0,0,0,0,0,0,0,0
0,0,0,0,0,0,0,0,0,0,0,0,0,0,0,0,0,0,0,0,0,0,0,0
0,0,0,0,0,0,0,0,0,0,0,0,0,0,0,0,0,0,0,0,0,0,0,0
:endlayer
layer: 26
0,0,0,0,0,0,0,0,0,0,0,0,0,0,0,0,0,0,0,0,0,0,0,0
0,0,0,0,0,0,0,0,0,0,0,0,0,0,0,0,0,0,0,0,0,0,0,0
0,0,0,0,0,0,0,0,0,0,0,0,0,0,0,0,0,0,0,0,0,0,0,0
0,0,0,0,0,0,0,0,0,0,0,0,0,0,0,0,0,0,0,0,0,0,0,0
0,0,0,0,0,0,0,0,0,0,0,0,0,0,0,0,0,0,0,0,0,0,0,0
0,0,0,0,0,0,0,0,0,0,0,0,0,0,0,0,0,0,0,0,0,0,0,0
0,0,0,0,0,0,0,0,0,0,0,0,0,0,0,0,0,0,0,0,0,0,0,0
0,0,0,0,0,0,0,0,0,0,0,0,0,0,0,0,0,0,0,0,0,0,0,0
0,0,0,0,0,0,0,0,0,0,0,0,0,3,0,0,0,0,0,0,0,0,0,0
0,0,0,0,0,0,0,0,0,0,0,0,0,0,0,0,0,0,0,0,0,0,0,0
0,0,0,0,0,0,0,0,0,0,0,0,0,0,0,0,0,0,0,0,0,0,0,0
0,0,0,0,0,0,0,0,0,0,0,107,108,3,107,107,0,0,0,0,0,0,0,0
0,0,0,0,0,0,0,0,0,0,0,0,0,0,0,0,0,0,0,0,0,0,0,0
0,0,0,0,0,0,0,0,0,0,0,0,0,0,0,0,0,0,0,0,0,0,0,0
0,0,0,0,0,0,0,0,0,0,0,0,0,0,0,0,0,0,0,0,0,0,0,0
0,0,0,0,0,0,0,0,0,0,0,0,0,0,0,0,0,0,0,0,0,0,0,0
0,0,0,0,0,0,0,0,0,0,0,0,0,0,0,0,0,0,0,0,0,0,0,0
0,0,0,0,0,0,0,0,0,0,0,0,0,0,0,0,0,0,0,0,0,0,0,0
0,0,0,0,0,0,0,0,0,0,0,0,0,0,0,0,0,0,0,0,0,0,0,0
0,0,0,0,0,0,0,0,0,0,0,0,0,0,0,0,0,0,0,0,0,0,0,0
0,0,0,0,0,0,0,0,0,0,0,0,0,0,0,0,0,0,0,0,0,0,0,0
0,0,0,0,0,0,0,0,0,0,0,0,0,0,0,0,0,0,0,0,0,0,0,0
0,0,0,0,0,0,0,0,0,0,0,0,0,0,0,0,0,0,0,0,0,0,0,0
:endlayer
layer: 27
0,0,0,0,0,0,0,0,0,0,0,0,0,0,0,0,0,0,0,0,0,0,0,0
0,0,0,0,0,0,0,0,0,0,0,0,0,0,0,0,0,0,0,0,0,0,0,0
0,0,0,0,0,0,0,0,0,0,0,0,0,0,0,0,0,0,0,0,0,0,0,0
0,0,0,0,0,0,0,0,0,0,0,0,0,0,0,0,0,0,0,0,0,0,0,0
0,0,0,0,0,0,0,0,0,0,0,0,0,0,62,0,0,0,0,0,0,0,0,0
0,0,0,0,0,0,0,0,0,0,0,0,0,0,62,0,0,0,0,0,0,0,0,0
0,0,0,0,0,0,0,0,0,0,0,0,0,62,0,0,0,0,0,0,0,0,0,0
0,0,0,0,0,0,0,0,0,0,0,0,0,62,0,0,0,0,0,0,0,0,0,0
0,0,0,0,0,0,0,0,0,0,0,0,0,3,0,0,0,0,0,0,0,0,0,0
0,0,0,0,0,0,0,0,0,0,0,0,0,0,0,0,0,0,0,0,0,0,0,0
0,0,0,0,0,0,0,0,0,0,0,0,0,0,0,0,0,0,0,0,0,0,0,0
0,0,0,0,0,0,0,0,0,0,0,0,107,3,0,0,0,0,0,0,0,0,0,0
0,0,0,0,0,0,0,0,0,0,0,0,0,0,0,0,0,0,0,0,0,0,0,0
0,0,0,0,0,0,0,0,0,0,0,0,0,0,0,0,0,0,0,0,0,0,0,0
0,0,0,0,0,0,0,0,0,0,0,0,0,0,0,0,0,0,0,0,0,0,0,0
0,0,0,0,0,0,0,0,0,0,0,0,0,0,0,0,0,0,0,0,0,0,0,0
0,0,0,0,0,0,0,0,0,0,0,0,0,0,0,0,0,0,0,0,0,0,0,0
0,0,0,0,0,0,0,0,0,0,0,0,0,0,0,0,0,0,0,0,0,0,0,0
0,0,0,0,0,0,0,0,0,0,0,0,0,0,0,0,0,0,0,0,0,0,0,0
0,0,0,0,0,0,0,0,0,0,0,0,0,0,0,0,0,0,0,0,0,0,0,0
0,0,0,0,0,0,0,0,0,0,0,0,0,0,0,0,0,0,0,0,0,0,0,0
0,0,0,0,0,0,0,0,0,0,0,0,0,0,0,0,0,0,0,0,0,0,0,0
0,0,0,0,0,0,0,0,0,0,0,0,0,0,0,0,0,0,0,0,0,0,0,0
:endlayer
layer: 28
0,0,0,0,0,0,0,0,0,0,0,0,0,0,0,0,0,0,0,0,0,0,0,0
0,0,0,0,0,0,0,0,0,0,0,0,0,0,0,0,0,0,0,0,0,0,0,0
0,0,0,0,0,0,0,0,0,0,0,0,0,0,0,0,0,0,0,0,0,0,0,0
0,0,0,0,0,0,0,0,0,0,0,0,0,0,0,0,0,0,0,0,0,0,0,0
0,0,0,0,0,0,0,0,0,0,0,0,0,0,0,0,0,0,0,0,0,0,0,0
0,0,0,0,0,0,0,0,0,0,0,0,0,0,62,0,0,0,0,0,0,0,0,0
0,0,0,0,0,0,0,0,0,0,0,0,0,0,62,0,0,0,0,0,0,0,0,0
0,0,0,0,0,0,0,0,0,0,0,0,0,62,0,0,0,0,0,0,0,0,0,0
0,0,0,0,0,0,0,0,0,0,0,0,0,3,0,0,0,0,0,0,0,0,0,0
0,0,0,0,0,0,0,0,0,0,0,0,0,0,0,0,0,0,0,0,0,0,0,0
0,0,0,0,0,0,0,0,0,0,0,0,0,0,0,0,0,0,0,0,0,0,0,0
0,0,0,0,0,0,0,0,0,0,0,0,107,3,0,0,0,0,0,0,0,0,0,0
0,0,0,0,0,0,0,0,0,0,0,0,0,0,0,0,0,0,0,0,0,0,0,0
0,0,0,0,0,0,0,0,0,0,0,0,0,0,0,0,0,0,0,0,0,0,0,0
0,0,0,0,0,0,0,0,0,0,0,0,0,0,0,0,0,0,0,0,0,0,0,0
0,0,0,0,0,0,0,0,0,0,0,0,0,0,0,0,0,0,0,0,0,0,0,0
0,0,0,0,0,0,0,0,0,0,0,0,0,0,0,0,0,0,0,0,0,0,0,0
0,0,0,0,0,0,0,0,0,0,0,0,0,0,0,0,0,0,0,0,0,0,0,0
0,0,0,0,0,0,0,0,0,0,0,0,0,0,0,0,0,0,0,0,0,0,0,0
0,0,0,0,0,0,0,0,0,0,0,0,0,0,0,0,0,0,0,0,0,0,0,0
0,0,0,0,0,0,0,0,0,0,0,0,0,0,0,0,0,0,0,0,0,0,0,0
0,0,0,0,0,0,0,0,0,0,0,0,0,0,0,0,0,0,0,0,0,0,0,0
0,0,0,0,0,0,0,0,0,0,0,0,0,0,0,0,0,0,0,0,0,0,0,0
:endlayer
layer: 29
0,0,0,0,0,0,0,0,0,0,0,0,0,0,0,0,0,0,0,0,0,0,0,0
0,0,0,0,0,0,0,0,0,0,0,0,0,0,0,0,0,0,0,0,0,0,0,0
0,0,0,0,0,0,0,0,0,0,0,0,0,0,0,0,0,0,0,0,0,0,0,0
0,0,0,0,0,0,0,0,0,0,0,0,0,0,0,0,0,0,0,0,0,0,0,0
0,0,0,0,0,0,0,0,0,0,0,0,0,0,0,0,0,0,0,0,0,0,0,0
0,0,0,0,0,0,0,0,0,0,0,0,0,0,0,0,0,0,0,0,0,0,0,0
0,0,0,0,0,0,0,0,0,0,0,0,0,0,0,0,0,0,0,0,0,0,0,0
0,0,0,0,0,0,0,0,0,0,0,0,0,0,0,0,0,0,0,0,0,0,0,0
0,0,0,0,0,0,0,0,0,0,0,0,0,38,0,0,0,0,0,0,0,0,0,0
0,0,0,0,0,0,0,0,0,0,0,0,0,0,0,0,0,0,0,0,0,0,0,0
0,0,0,0,0,0,0,0,0,0,0,0,0,0,0,0,0,0,0,0,0,0,0,0
0,0,0,0,0,0,0,0,0,0,0,0,107,108,0,0,0,0,0,0,0,0,0,0
0,0,0,0,0,0,0,0,0,0,0,0,0,0,0,0,0,0,0,0,0,0,0,0
0,0,0,0,0,0,0,0,0,0,0,0,0,0,0,0,0,0,0,0,0,0,0,0
0,0,0,0,0,0,0,0,0,0,0,0,0,0,0,0,0,0,0,0,0,0,0,0
0,0,0,0,0,0,0,0,0,0,0,0,0,0,0,0,0,0,0,0,0,0,0,0
0,0,0,0,0,0,0,0,0,0,0,0,0,0,0,0,0,0,0,0,0,0,0,0
0,0,0,0,0,0,0,0,0,0,0,0,0,0,0,0,0,0,0,0,0,0,0,0
0,0,0,0,0,0,0,0,0,0,0,0,0,0,0,0,0,0,0,0,0,0,0,0
0,0,0,0,0,0,0,0,0,0,0,0,0,0,0,0,0,0,0,0,0,0,0,0
0,0,0,0,0,0,0,0,0,0,0,0,0,0,0,0,0,0,0,0,0,0,0,0
0,0,0,0,0,0,0,0,0,0,0,0,0,0,0,0,0,0,0,0,0,0,0,0
0,0,0,0,0,0,0,0,0,0,0,0,0,0,0,0,0,0,0,0,0,0,0,0
:endlayer
layer: 30
0,0,0,0,0,0,0,0,0,0,0,0,0,0,0,0,0,0,0,0,0,0,0,0
0,0,0,0,0,0,0,0,0,0,0,0,0,0,0,0,0,0,0,0,0,0,0,0
0,0,0,0,0,0,0,0,0,0,0,0,0,0,0,0,0,0,0,0,0,0,0,0
0,0,0,0,0,0,0,0,0,0,0,0,0,0,0,0,0,0,0,0,0,0,0,0
0,0,0,0,0,0,0,0,0,0,0,0,0,0,0,0,0,0,0,0,0,0,0,0
0,0,0,0,0,0,0,0,0,0,0,0,0,0,0,0,0,0,0,0,0,0,0,0
0,0,0,0,0,0,0,0,0,0,0,0,0,0,0,0,0,0,0,0,0,0,0,0
0,0,0,0,0,0,0,0,0,0,0,0,0,0,0,0,0,0,0,0,0,0,0,0
0,0,0,0,0,0,0,0,0,0,0,0,0,0,0,0,0,0,0,0,0,0,0,0
0,0,0,0,0,0,0,0,0,0,0,0,0,0,0,0,0,0,0,0,0,0,0,0
0,0,0,0,0,0,0,0,0,0,0,0,0,0,0,0,0,0,0,0,0,0,0,0
0,0,0,0,0,0,0,0,0,0,0,0,0,113,0,0,0,0,0,0,0,0,0,0
0,0,0,0,0,0,0,0,0,0,0,0,0,0,0,0,0,0,0,0,0,0,0,0
0,0,0,0,0,0,0,0,0,0,0,0,0,0,0,0,0,0,0,0,0,0,0,0
0,0,0,0,0,0,0,0,0,0,0,0,0,0,0,0,0,0,0,0,0,0,0,0
0,0,0,0,0,0,0,0,0,0,0,0,0,0,0,0,0,0,0,0,0,0,0,0
0,0,0,0,0,0,0,0,0,0,0,0,0,0,0,0,0,0,0,0,0,0,0,0
0,0,0,0,0,0,0,0,0,0,0,0,0,0,0,0,0,0,0,0,0,0,0,0
0,0,0,0,0,0,0,0,0,0,0,0,0,0,0,0,0,0,0,0,0,0,0,0
0,0,0,0,0,0,0,0,0,0,0,0,0,0,0,0,0,0,0,0,0,0,0,0
0,0,0,0,0,0,0,0,0,0,0,0,0,0,0,0,0,0,0,0,0,0,0,0
0,0,0,0,0,0,0,0,0,0,0,0,0,0,0,0,0,0,0,0,0,0,0,0
0,0,0,0,0,0,0,0,0,0,0,0,0,0,0,0,0,0,0,0,0,0,0,0
:endlayer

#### RULES ####
rule:
plugin=vanillaBlocks
number=1
data:
JSON:{blockState:{blockName:"minecraft:sandstone",properties:{type:"sandstone"}}}
:enddata
:endrule

rule:
plugin=vanillaBlocks
number=2
data:
JSON:{blockState:{blockName:"minecraft:sand",properties:{variant:"sand"}}}
:enddata
:endrule

rule:
plugin=vanillaBlocks
number=3
data:
JSON:{blockState:{blockName:"minecraft:birch_fence",properties:{east:"false",south:"false",north:"false",west:"false"}}}
:enddata
:endrule

rule:
plugin=blockTile
number=4
data:
JSON:{blockState:{blockName:"ancientwarfarestructure:advanced_spawner",properties:{transparent:"true"}},teData:{id:"ancientwarfarestructure:advanced_spawner_tile",spawnerSettings:{minDelay:10,spawnDelay:5,lightSensitive:0b,spawnGroups:[{settingsList:[{remainingSpawnCount:1,hostile:1b,customTag:{ArmorDropChances:[0.085f,0.085f,0.085f,0.085f],hasCustomEquipment:0b,ArmorItems:[{},{},{},{}],skinSettings:{npcTypeName:"custom",skinTypeSelected:"default"},HandDropChances:[0.085f,0.085f],factionName:"sarkonid",HandItems:[{},{}]},maxToSpawn:1,entityId:"ancientwarfarenpc:faction.civilian.male",minToSpawn:1}],groupWeight:1}],playerRange:16,respondToRedstone:0b,inventory:{Size:9,Items:[]},spawnRange:0,transparent:1b,maxDelay:10,spawnYOffset:0,xpToDrop:0,mobRange:0,debugMode:0b,maxNearbyMonsters:0}}}
:enddata
:endrule

rule:
plugin=vanillaBlocks
number=5
data:
JSON:{blockState:{blockName:"ancientwarfarestructure:bench",properties:{legs:"none",variant:"oak",axis:"x"}}}
:enddata
:endrule

rule:
plugin=blockTile
number=6
data:
JSON:{blockState:{blockName:"ancientwarfarestructure:advanced_spawner",properties:{transparent:"true"}},teData:{id:"ancientwarfarestructure:advanced_spawner_tile",spawnerSettings:{minDelay:10,spawnDelay:2,lightSensitive:0b,spawnGroups:[{settingsList:[{remainingSpawnCount:1,hostile:1b,customTag:{ArmorDropChances:[0.085f,0.085f,0.085f,0.085f],hasCustomEquipment:0b,ArmorItems:[{},{},{},{}],skinSettings:{npcTypeName:"custom",skinTypeSelected:"default"},HandDropChances:[0.085f,0.085f],factionName:"sarkonid",HandItems:[{},{}]},maxToSpawn:1,entityId:"ancientwarfarenpc:faction.civilian.female",minToSpawn:1}],groupWeight:1}],playerRange:16,respondToRedstone:0b,inventory:{Size:9,Items:[]},spawnRange:0,transparent:1b,maxDelay:10,spawnYOffset:0,xpToDrop:0,mobRange:0,debugMode:0b,maxNearbyMonsters:0}}}
:enddata
:endrule

rule:
plugin=vanillaBlocks
number=7
data:
JSON:{blockState:{blockName:"ancientwarfarestructure:table",properties:{leg_southwest:"true",leg_northwest:"true",variant:"oak",leg_northeast:"true",leg_southeast:"true"}}}
:enddata
:endrule

rule:
plugin=vanillaBlocks
number=8
data:
JSON:{blockState:{blockName:"ancientwarfarestructure:bench",properties:{legs:"none",variant:"oak",axis:"z"}}}
:enddata
:endrule

rule:
plugin=blockTile
number=9
data:
JSON:{blockState:{blockName:"ancientwarfarestructure:advanced_spawner",properties:{transparent:"true"}},teData:{id:"ancientwarfarestructure:advanced_spawner_tile",spawnerSettings:{minDelay:10,spawnDelay:7,lightSensitive:0b,spawnGroups:[{settingsList:[{remainingSpawnCount:1,hostile:1b,customTag:{ArmorDropChances:[0.085f,0.085f,0.085f,0.085f],hasCustomEquipment:0b,ArmorItems:[{},{},{},{}],skinSettings:{npcTypeName:"custom",skinTypeSelected:"default"},HandDropChances:[0.085f,0.085f],factionName:"sarkonid",HandItems:[{},{}]},maxToSpawn:1,entityId:"ancientwarfarenpc:faction.civilian.female",minToSpawn:1}],groupWeight:1}],playerRange:16,respondToRedstone:0b,inventory:{Size:9,Items:[]},spawnRange:0,transparent:1b,maxDelay:10,spawnYOffset:0,xpToDrop:0,mobRange:0,debugMode:0b,maxNearbyMonsters:0}}}
:enddata
:endrule

rule:
plugin=vanillaBlocks
number=10
data:
JSON:{blockState:{blockName:"minecraft:spruce_stairs",properties:{half:"top",shape:"straight",facing:"west"}}}
:enddata
:endrule

rule:
plugin=vanillaBlocks
number=11
data:
JSON:{blockState:{blockName:"minecraft:planks",properties:{variant:"spruce"}}}
:enddata
:endrule

rule:
plugin=vanillaBlocks
number=12
data:
JSON:{blockState:{blockName:"minecraft:spruce_stairs",properties:{half:"top",shape:"straight",facing:"east"}}}
:enddata
:endrule

rule:
plugin=vanillaBlocks
number=13
data:
JSON:{blockState:{blockName:"minecraft:crafting_table"}}
:enddata
:endrule

rule:
plugin=vanillaBlocks
number=14
data:
JSON:{blockState:{blockName:"minecraft:red_sandstone_stairs",properties:{half:"bottom",shape:"straight",facing:"west"}}}
:enddata
:endrule

rule:
plugin=vanillaBlocks
number=15
data:
JSON:{blockState:{blockName:"ancientwarfarestructure:stool",properties:{variant:"oak"}}}
:enddata
:endrule

rule:
plugin=vanillaBlocks
number=16
data:
JSON:{blockState:{blockName:"minecraft:red_sandstone_stairs",properties:{half:"bottom",shape:"straight",facing:"east"}}}
:enddata
:endrule

rule:
plugin=blockTile
number=17
data:
JSON:{blockState:{blockName:"ancientwarfarestructure:advanced_spawner",properties:{transparent:"true"}},teData:{id:"ancientwarfarestructure:advanced_spawner_tile",spawnerSettings:{minDelay:10,spawnDelay:2,lightSensitive:0b,spawnGroups:[{settingsList:[{remainingSpawnCount:1,hostile:1b,customTag:{ArmorDropChances:[0.085f,0.085f,0.085f,0.085f],hasCustomEquipment:0b,ArmorItems:[{},{},{},{}],skinSettings:{npcTypeName:"custom",skinTypeSelected:"default"},HandDropChances:[0.085f,0.085f],factionName:"sarkonid",HandItems:[{},{}]},maxToSpawn:1,entityId:"ancientwarfarenpc:faction.civilian.male",minToSpawn:1}],groupWeight:1}],playerRange:16,respondToRedstone:0b,inventory:{Size:9,Items:[]},spawnRange:0,transparent:1b,maxDelay:10,spawnYOffset:0,xpToDrop:0,mobRange:0,debugMode:0b,maxNearbyMonsters:0}}}
:enddata
:endrule

rule:
plugin=vanillaBlocks
number=18
data:
JSON:{blockState:{blockName:"minecraft:spruce_fence",properties:{east:"false",south:"false",north:"false",west:"false"}}}
:enddata
:endrule

rule:
plugin=vanillaBlocks
number=19
data:
JSON:{blockState:{blockName:"minecraft:red_sandstone_stairs",properties:{half:"bottom",shape:"straight",facing:"north"}}}
:enddata
:endrule

rule:
plugin=vanillaBlocks
number=20
data:
JSON:{blockState:{blockName:"minecraft:spruce_stairs",properties:{half:"top",shape:"straight",facing:"north"}}}
:enddata
:endrule

rule:
plugin=inventory
number=21
data:
JSON:{blockState:{blockName:"minecraft:chest",properties:{facing:"west"}},lootLevel:0,teData:{Items:[],id:"minecraft:chest",Lock:""},inventoryData:{length:0,inventoryContents:[]},legacyFeatures:1b}
:enddata
:endrule

rule:
plugin=vanillaBlocks
number=22
data:
JSON:{blockState:{blockName:"minecraft:oak_stairs",properties:{half:"top",shape:"straight",facing:"north"}}}
:enddata
:endrule

rule:
plugin=inventory
number=23
data:
JSON:{blockState:{blockName:"minecraft:chest",properties:{facing:"west"}},lootLevel:0,teData:{Items:[],id:"minecraft:chest",Lock:""},inventoryData:{length:0,inventoryContents:[]},legacyFeatures:1b}
:enddata
:endrule

rule:
plugin=vanillaBlocks
number=24
data:
JSON:{blockState:{blockName:"minecraft:oak_stairs",properties:{half:"top",shape:"straight",facing:"south"}}}
:enddata
:endrule

rule:
plugin=blockTile
number=25
data:
JSON:{blockState:{blockName:"ancientwarfarestructure:advanced_spawner",properties:{transparent:"true"}},teData:{id:"ancientwarfarestructure:advanced_spawner_tile",spawnerSettings:{minDelay:10,spawnDelay:8,lightSensitive:0b,spawnGroups:[{settingsList:[{remainingSpawnCount:1,hostile:1b,customTag:{ArmorDropChances:[0.085f,0.085f,0.085f,0.085f],hasCustomEquipment:0b,ArmorItems:[{},{},{},{}],skinSettings:{npcTypeName:"custom",skinTypeSelected:"default"},HandDropChances:[0.085f,0.085f],factionName:"sarkonid",HandItems:[{},{}]},maxToSpawn:1,entityId:"ancientwarfarenpc:faction.civilian.female",minToSpawn:1}],groupWeight:1}],playerRange:16,respondToRedstone:0b,inventory:{Size:9,Items:[]},spawnRange:0,transparent:1b,maxDelay:10,spawnYOffset:0,xpToDrop:0,mobRange:0,debugMode:0b,maxNearbyMonsters:0}}}
:enddata
:endrule

rule:
plugin=blockTile
number=26
data:
JSON:{blockState:{blockName:"ancientwarfarestructure:advanced_spawner",properties:{transparent:"true"}},teData:{id:"ancientwarfarestructure:advanced_spawner_tile",spawnerSettings:{minDelay:10,spawnDelay:8,lightSensitive:0b,spawnGroups:[{settingsList:[{remainingSpawnCount:1,hostile:1b,customTag:{ArmorDropChances:[0.085f,0.085f,0.085f,0.085f],hasCustomEquipment:0b,ArmorItems:[{},{},{},{}],skinSettings:{npcTypeName:"custom",skinTypeSelected:"default"},HandDropChances:[0.085f,0.085f],factionName:"sarkonid",HandItems:[{},{}]},maxToSpawn:1,entityId:"ancientwarfarenpc:faction.civilian.male",minToSpawn:1}],groupWeight:1}],playerRange:16,respondToRedstone:0b,inventory:{Size:9,Items:[]},spawnRange:0,transparent:1b,maxDelay:10,spawnYOffset:0,xpToDrop:0,mobRange:0,debugMode:0b,maxNearbyMonsters:0}}}
:enddata
:endrule

rule:
plugin=vanillaBlocks
number=27
data:
JSON:{blockState:{blockName:"minecraft:spruce_stairs",properties:{half:"top",shape:"straight",facing:"south"}}}
:enddata
:endrule

rule:
plugin=blockTile
number=28
data:
JSON:{blockState:{blockName:"ancientwarfarestructure:advanced_spawner",properties:{transparent:"true"}},teData:{id:"ancientwarfarestructure:advanced_spawner_tile",spawnerSettings:{minDelay:10,spawnDelay:5,lightSensitive:0b,spawnGroups:[{settingsList:[{remainingSpawnCount:1,hostile:1b,customTag:{ArmorDropChances:[0.085f,0.085f,0.085f,0.085f],CustomName:"Bumgurn brewer",hasCustomEquipment:1b,ArmorItems:[{},{},{},{}],skinSettings:{npcTypeName:"custom",skinTypeSelected:"default"},HandDropChances:[0.085f,0.085f],factionName:"sarkonid",tradeList:{tradeList:[{refillFrequency:6000,currentAvailable:20,inputItems:[{id:"minecraft:glass_bottle",Count:1b,slot:4,Damage:0s}],outputItems:[{id:"ancientwarfarenpc:coin",Count:4b,tag:{metal:"copper"},slot:4,Damage:0s}],refillTime:14350442L,maxAvailable:20},{refillFrequency:6000,currentAvailable:4,inputItems:[{id:"ancientwarfarenpc:coin",Count:1b,tag:{metal:"gold"},slot:4,Damage:0s}],outputItems:[{id:"minecraft:potion",Count:1b,tag:{CustomPotionEffects:[{ShowParticles:0b,Duration:1200,Id:1b,Amplifier:2b},{ShowParticles:0b,Duration:1200,Id:3b,Amplifier:1b},{ShowParticles:0b,Duration:200,Id:9b,Amplifier:0b},{ShowParticles:0b,Duration:600,Id:16b,Amplifier:0b},{ShowParticles:0b,Duration:100,Id:17b,Amplifier:1b},{ShowParticles:0b,Duration:60,Id:24b,Amplifier:0b},{ShowParticles:0b,Duration:100,Id:25b,Amplifier:1b},{ShowParticles:0b,Duration:2400,Id:27b,Amplifier:9b}],CustomPotionColor:2555896,HideFlags:32,display:{Lore:["so powerful it'll make you fly!"],Name:"Bumgurn Brewery serum"}},slot:4,Damage:0s}],refillTime:14350442L,maxAvailable:4},{refillFrequency:6000,currentAvailable:27,inputItems:[{id:"ancientwarfarenpc:coin",Count:5b,tag:{metal:"silver"},slot:4,Damage:0s}],outputItems:[{id:"minecraft:potion",Count:1b,tag:{CustomPotionEffects:[{ShowParticles:0b,Duration:600,Id:1b,Amplifier:1b},{ShowParticles:0b,Duration:600,Id:3b,Amplifier:1b},{ShowParticles:0b,Duration:1,Id:7b,Amplifier:0b}],CustomPotionColor:10033817,HideFlags:32,display:{Lore:["spicy!"],Name:"local desert brew"}},slot:4,Damage:0s}],refillTime:0L,maxAvailable:27},{refillFrequency:6000,currentAvailable:24,inputItems:[{id:"ancientwarfarenpc:coin",Count:5b,tag:{metal:"silver"},slot:4,Damage:0s}],outputItems:[{id:"minecraft:potion",Count:1b,tag:{CustomPotionEffects:[{ShowParticles:0b,Duration:1,Id:7b,Amplifier:0b},{ShowParticles:0b,Duration:400,Id:15b,Amplifier:1b},{ShowParticles:0b,Duration:100,Id:19b,Amplifier:1b},{ShowParticles:0b,Duration:400,Id:23b,Amplifier:1b},{ShowParticles:0b,Duration:600,Id:26b,Amplifier:1b}],CustomPotionColor:10064427,HideFlags:32,display:{Lore:["They are known to be dangerous."],Name:"Sarkonid's speciality"}},slot:4,Damage:0s}],refillTime:0L,maxAvailable:24}]},HandItems:[{id:"minecraft:potion",Count:1b,tag:{CustomPotionEffects:[{ShowParticles:0b,Duration:1200,Id:1b,Amplifier:2b},{ShowParticles:0b,Duration:1200,Id:3b,Amplifier:1b},{ShowParticles:0b,Duration:200,Id:9b,Amplifier:0b},{ShowParticles:0b,Duration:600,Id:16b,Amplifier:0b},{ShowParticles:0b,Duration:100,Id:17b,Amplifier:1b},{ShowParticles:0b,Duration:60,Id:24b,Amplifier:0b},{ShowParticles:0b,Duration:100,Id:25b,Amplifier:1b},{ShowParticles:0b,Duration:2400,Id:27b,Amplifier:9b}],CustomPotionColor:2555896,HideFlags:32,display:{Lore:["so powerful it'll make you fly!"],Name:"Bumgurn Brewery serum"}},Damage:0s},{}]},maxToSpawn:1,entityId:"ancientwarfarenpc:faction.trader",minToSpawn:1}],groupWeight:1}],playerRange:16,respondToRedstone:0b,inventory:{Size:9,Items:[]},spawnRange:0,transparent:1b,maxDelay:10,spawnYOffset:0,xpToDrop:0,mobRange:0,debugMode:0b,maxNearbyMonsters:0}}}
:enddata
:endrule

rule:
plugin=vanillaBlocks
number=29
data:
JSON:{blockState:{blockName:"minecraft:trapdoor",properties:{half:"top",facing:"north",open:"false"}}}
:enddata
:endrule

rule:
plugin=doors
number=30
data:
JSON:{blockState:{blockName:"minecraft:spruce_door",properties:{hinge:"left",half:"lower",powered:"false",facing:"north",open:"false"}}}
:enddata
:endrule

rule:
plugin=vanillaBlocks
number=31
data:
JSON:{blockState:{blockName:"minecraft:spruce_stairs",properties:{half:"bottom",shape:"straight",facing:"south"}}}
:enddata
:endrule

rule:
plugin=blockTile
number=32
data:
JSON:{blockState:{blockName:"ancientwarfarestructure:advanced_spawner",properties:{transparent:"true"}},teData:{id:"ancientwarfarestructure:advanced_spawner_tile",spawnerSettings:{minDelay:10,spawnDelay:9,lightSensitive:0b,spawnGroups:[{settingsList:[{remainingSpawnCount:1,hostile:1b,customTag:{ArmorDropChances:[0.085f,0.085f,0.085f,0.085f],hasCustomEquipment:0b,ArmorItems:[{},{},{},{}],skinSettings:{npcTypeName:"custom",skinTypeSelected:"default"},HandDropChances:[0.085f,0.085f],factionName:"sarkonid",HandItems:[{},{}]},maxToSpawn:1,entityId:"ancientwarfarenpc:faction.civilian.male",minToSpawn:1}],groupWeight:1}],playerRange:16,respondToRedstone:0b,inventory:{Size:9,Items:[]},spawnRange:0,transparent:1b,maxDelay:10,spawnYOffset:0,xpToDrop:0,mobRange:0,debugMode:0b,maxNearbyMonsters:0}}}
:enddata
:endrule

rule:
plugin=vanillaBlocks
number=33
data:
JSON:{blockState:{blockName:"minecraft:sandstone_stairs",properties:{half:"bottom",shape:"straight",facing:"east"}}}
:enddata
:endrule

rule:
plugin=vanillaBlocks
number=34
data:
JSON:{blockState:{blockName:"minecraft:red_sandstone_stairs",properties:{half:"bottom",shape:"straight",facing:"south"}}}
:enddata
:endrule

rule:
plugin=vanillaBlocks
number=35
data:
JSON:{blockState:{blockName:"minecraft:brick_block"}}
:enddata
:endrule

rule:
plugin=vanillaBlocks
number=36
data:
JSON:{blockState:{blockName:"minecraft:brick_stairs",properties:{half:"bottom",shape:"straight",facing:"north"}}}
:enddata
:endrule

rule:
plugin=blockTile
number=37
data:
JSON:{blockState:{blockName:"ancientwarfarestructure:advanced_spawner",properties:{transparent:"true"}},teData:{id:"ancientwarfarestructure:advanced_spawner_tile",spawnerSettings:{minDelay:10,spawnDelay:4,lightSensitive:0b,spawnGroups:[{settingsList:[{remainingSpawnCount:1,hostile:1b,customTag:{ArmorDropChances:[0.085f,0.085f,0.085f,0.085f],hasCustomEquipment:0b,ArmorItems:[{},{},{},{}],skinSettings:{npcTypeName:"custom",skinTypeSelected:"default"},HandDropChances:[0.085f,0.085f],factionName:"sarkonid",HandItems:[{},{}]},maxToSpawn:1,entityId:"ancientwarfarenpc:faction.civilian.male",minToSpawn:1}],groupWeight:1}],playerRange:16,respondToRedstone:0b,inventory:{Size:9,Items:[]},spawnRange:0,transparent:1b,maxDelay:10,spawnYOffset:0,xpToDrop:0,mobRange:0,debugMode:0b,maxNearbyMonsters:0}}}
:enddata
:endrule

rule:
plugin=vanillaBlocks
number=38
data:
JSON:{blockState:{blockName:"minecraft:torch",properties:{facing:"up"}}}
:enddata
:endrule

rule:
plugin=vanillaBlocks
number=39
data:
JSON:{blockState:{blockName:"minecraft:tripwire_hook",properties:{powered:"false",attached:"false",facing:"south"}}}
:enddata
:endrule

rule:
plugin=vanillaBlocks
number=40
data:
JSON:{blockState:{blockName:"minecraft:wooden_slab",properties:{half:"bottom",variant:"birch"}}}
:enddata
:endrule

rule:
plugin=vanillaBlocks
number=41
data:
JSON:{blockState:{blockName:"minecraft:wooden_slab",properties:{half:"top",variant:"birch"}}}
:enddata
:endrule

rule:
plugin=vanillaBlocks
number=42
data:
JSON:{blockState:{blockName:"minecraft:oak_stairs",properties:{half:"bottom",shape:"straight",facing:"north"}}}
:enddata
:endrule

rule:
plugin=vanillaBlocks
number=43
data:
JSON:{blockState:{blockName:"minecraft:tripwire_hook",properties:{powered:"false",attached:"false",facing:"east"}}}
:enddata
:endrule

rule:
plugin=vanillaBlocks
number=44
data:
JSON:{blockState:{blockName:"minecraft:oak_stairs",properties:{half:"bottom",shape:"straight",facing:"south"}}}
:enddata
:endrule

rule:
plugin=vanillaBlocks
number=45
data:
JSON:{blockState:{blockName:"minecraft:spruce_stairs",properties:{half:"bottom",shape:"straight",facing:"north"}}}
:enddata
:endrule

rule:
plugin=doors
number=46
data:
JSON:{blockState:{blockName:"minecraft:spruce_door",properties:{hinge:"left",half:"upper",powered:"false",facing:"south",open:"false"}}}
:enddata
:endrule

rule:
plugin=vanillaBlocks
number=47
data:
JSON:{blockState:{blockName:"ancientwarfarestructure:fire_pit",properties:{lit:"true",variant:"default"}}}
:enddata
:endrule

rule:
plugin=vanillaBlocks
number=48
data:
JSON:{blockState:{blockName:"minecraft:tripwire_hook",properties:{powered:"false",attached:"false",facing:"north"}}}
:enddata
:endrule

rule:
plugin=vanillaBlocks
number=49
data:
JSON:{blockState:{blockName:"minecraft:spruce_stairs",properties:{half:"bottom",shape:"straight",facing:"west"}}}
:enddata
:endrule

rule:
plugin=vanillaBlocks
number=50
data:
JSON:{blockState:{blockName:"minecraft:spruce_stairs",properties:{half:"bottom",shape:"straight",facing:"east"}}}
:enddata
:endrule

rule:
plugin=vanillaSign
number=51
data:
JSON:{signContents0:"Sarkovid§r",blockState:{blockName:"minecraft:wall_sign",properties:{facing:"south"}},signContents2:"Bumgurn§r",signContents1:"",signContents3:"Brewery§r",rotation:0}
:enddata
:endrule

rule:
plugin=vanillaBlocks
number=52
data:
JSON:{blockState:{blockName:"minecraft:red_sandstone_stairs",properties:{half:"top",shape:"straight",facing:"east"}}}
:enddata
:endrule

rule:
plugin=vanillaBlocks
number=53
data:
JSON:{blockState:{blockName:"minecraft:stone_slab2",properties:{half:"top",variant:"red_sandstone"}}}
:enddata
:endrule

rule:
plugin=vanillaBlocks
number=54
data:
JSON:{blockState:{blockName:"minecraft:red_sandstone_stairs",properties:{half:"top",shape:"straight",facing:"west"}}}
:enddata
:endrule

rule:
plugin=vanillaBlocks
number=55
data:
JSON:{blockState:{blockName:"minecraft:torch",properties:{facing:"west"}}}
:enddata
:endrule

rule:
plugin=vanillaSign
number=56
data:
JSON:{signContents0:"Sarkovid§r",blockState:{blockName:"minecraft:wall_sign",properties:{facing:"south"}},signContents2:"Bumgurn§r",signContents1:"",signContents3:"Brewery§r",rotation:0}
:enddata
:endrule

rule:
plugin=vanillaBlocks
number=57
data:
JSON:{blockState:{blockName:"minecraft:torch",properties:{facing:"north"}}}
:enddata
:endrule

rule:
plugin=vanillaBlocks
number=58
data:
JSON:{blockState:{blockName:"minecraft:red_sandstone_stairs",properties:{half:"top",shape:"straight",facing:"south"}}}
:enddata
:endrule

rule:
plugin=vanillaBlocks
number=59
data:
JSON:{blockState:{blockName:"minecraft:red_sandstone_stairs",properties:{half:"top",shape:"straight",facing:"north"}}}
:enddata
:endrule

rule:
plugin=vanillaBlocks
number=60
data:
JSON:{blockState:{blockName:"minecraft:brick_stairs",properties:{half:"bottom",shape:"straight",facing:"south"}}}
:enddata
:endrule

rule:
plugin=vanillaBlocks
number=61
data:
JSON:{blockState:{blockName:"minecraft:wool",properties:{color:"green"}}}
:enddata
:endrule

rule:
plugin=vanillaBlocks
number=62
data:
JSON:{blockState:{blockName:"minecraft:wool",properties:{color:"red"}}}
:enddata
:endrule

rule:
plugin=vanillaBlocks
number=63
data:
JSON:{blockState:{blockName:"minecraft:torch",properties:{facing:"east"}}}
:enddata
:endrule

rule:
plugin=vanillaBlocks
number=64
data:
JSON:{blockState:{blockName:"minecraft:torch",properties:{facing:"south"}}}
:enddata
:endrule

rule:
plugin=vanillaBlocks
number=65
data:
JSON:{blockState:{blockName:"minecraft:stone_slab",properties:{half:"top",variant:"sandstone"}}}
:enddata
:endrule

rule:
plugin=vanillaBlocks
number=66
data:
JSON:{blockState:{blockName:"minecraft:stained_hardened_clay",properties:{color:"yellow"}}}
:enddata
:endrule

rule:
plugin=vanillaSign
number=67
data:
JSON:{signContents0:"Sarkovid§r",blockState:{blockName:"minecraft:wall_sign",properties:{facing:"east"}},signContents2:"Bumgurn§r",signContents1:"",signContents3:"Brewery§r",rotation:0}
:enddata
:endrule

rule:
plugin=vanillaSign
number=68
data:
JSON:{signContents0:"Sarkovid§r",blockState:{blockName:"minecraft:wall_sign",properties:{facing:"west"}},signContents2:"Bumgurn§r",signContents1:"",signContents3:"Brewery§r",rotation:0}
:enddata
:endrule

rule:
plugin=vanillaSign
number=69
data:
JSON:{signContents0:"Sarkovid§r",blockState:{blockName:"minecraft:wall_sign",properties:{facing:"north"}},signContents2:"Bumgurn§r",signContents1:"",signContents3:"Brewery§r",rotation:0}
:enddata
:endrule

rule:
plugin=vanillaBlocks
number=70
data:
JSON:{blockState:{blockName:"minecraft:stone_slab2",properties:{half:"bottom",variant:"red_sandstone"}}}
:enddata
:endrule

rule:
plugin=vanillaBlocks
number=71
data:
JSON:{blockState:{blockName:"minecraft:wooden_slab",properties:{half:"bottom",variant:"spruce"}}}
:enddata
:endrule

rule:
plugin=inventory
number=72
data:
JSON:{blockState:{blockName:"minecraft:chest",properties:{facing:"north"}},lootLevel:0,teData:{Items:[],id:"minecraft:chest",Lock:""},inventoryData:{length:0,inventoryContents:[]},legacyFeatures:1b}
:enddata
:endrule

rule:
plugin=inventory
number=73
data:
JSON:{blockState:{blockName:"minecraft:chest",properties:{facing:"north"}},lootLevel:0,teData:{Items:[],id:"minecraft:chest",Lock:""},inventoryData:{length:0,inventoryContents:[]},legacyFeatures:1b}
:enddata
:endrule

rule:
plugin=vanillaBlocks
number=74
data:
JSON:{blockState:{blockName:"minecraft:stone",properties:{variant:"smooth_andesite"}}}
:enddata
:endrule

rule:
plugin=inventory
number=75
data:
JSON:{blockState:{blockName:"minecraft:furnace",properties:{facing:"north"}},lootLevel:0,teData:{CookTime:0,BurnTime:0,Items:[],id:"minecraft:furnace",CookTimeTotal:0,Lock:""},inventoryData:{length:0,inventoryContents:[]},legacyFeatures:0b}
:enddata
:endrule

rule:
plugin=inventory
number=76
data:
JSON:{blockState:{blockName:"minecraft:furnace",properties:{facing:"north"}},lootLevel:0,teData:{CookTime:0,BurnTime:0,Items:[],id:"minecraft:furnace",CookTimeTotal:0,Lock:""},inventoryData:{length:0,inventoryContents:[]},legacyFeatures:0b}
:enddata
:endrule

rule:
plugin=bed
number=77
data:
JSON:{blockState:{blockName:"minecraft:bed",properties:{part:"head",facing:"east",occupied:"false"}},bedColor:12}
:enddata
:endrule

rule:
plugin=bed
number=78
data:
JSON:{blockState:{blockName:"minecraft:bed",properties:{part:"foot",facing:"east",occupied:"false"}},bedColor:12}
:enddata
:endrule

rule:
plugin=blockTile
number=79
data:
JSON:{blockState:{blockName:"ancientwarfarestructure:chair",properties:{visible:"true",variant:"birch",facing:"south"}},facing:"north",teData:{facing:"south",id:"ancientwarfarestructure:chair_tile"}}
:enddata
:endrule

rule:
plugin=blockTile
number=80
data:
JSON:{blockState:{blockName:"ancientwarfarestructure:chair",properties:{visible:"true",variant:"birch",facing:"south"}},facing:"north",teData:{facing:"south",id:"ancientwarfarestructure:chair_tile"}}
:enddata
:endrule

rule:
plugin=blockTile
number=81
data:
JSON:{blockState:{blockName:"ancientwarfarestructure:chair",properties:{visible:"true",variant:"birch",facing:"south"}},facing:"north",teData:{facing:"south",id:"ancientwarfarestructure:chair_tile"}}
:enddata
:endrule

rule:
plugin=doors
number=82
data:
JSON:{blockState:{blockName:"minecraft:spruce_door",properties:{hinge:"left",half:"lower",powered:"false",facing:"east",open:"false"}}}
:enddata
:endrule

rule:
plugin=blockTile
number=83
data:
JSON:{blockState:{blockName:"ancientwarfarestructure:advanced_spawner",properties:{transparent:"true"}},teData:{id:"ancientwarfarestructure:advanced_spawner_tile",spawnerSettings:{minDelay:10,spawnDelay:7,lightSensitive:0b,spawnGroups:[{settingsList:[{remainingSpawnCount:1,hostile:1b,customTag:{ArmorDropChances:[0.085f,0.085f,0.085f,0.085f],hasCustomEquipment:0b,ArmorItems:[{},{},{},{}],skinSettings:{npcTypeName:"custom",skinTypeSelected:"default"},HandDropChances:[0.085f,0.085f],factionName:"sarkonid",HandItems:[{},{}]},maxToSpawn:1,entityId:"ancientwarfarenpc:faction.civilian.female",minToSpawn:1}],groupWeight:1}],playerRange:16,respondToRedstone:0b,inventory:{Size:9,Items:[]},spawnRange:0,transparent:1b,maxDelay:10,spawnYOffset:0,xpToDrop:0,mobRange:0,debugMode:0b,maxNearbyMonsters:0}}}
:enddata
:endrule

rule:
plugin=vanillaBlocks
number=84
data:
JSON:{blockState:{blockName:"ancientwarfarestructure:table",properties:{leg_southwest:"true",leg_northwest:"true",variant:"birch",leg_northeast:"true",leg_southeast:"true"}}}
:enddata
:endrule

rule:
plugin=inventory
number=85
data:
JSON:{blockState:{blockName:"minecraft:chest",properties:{facing:"west"}},lootLevel:0,teData:{Items:[],id:"minecraft:chest",Lock:""},inventoryData:{length:0,inventoryContents:[]},legacyFeatures:1b}
:enddata
:endrule

rule:
plugin=vanillaBlocks
number=86
data:
JSON:{blockState:{blockName:"minecraft:carpet",properties:{color:"orange"}}}
:enddata
:endrule

rule:
plugin=blockTile
number=87
data:
JSON:{blockState:{blockName:"ancientwarfarestructure:chair",properties:{visible:"true",variant:"birch",facing:"south"}},facing:"south",teData:{facing:"north",id:"ancientwarfarestructure:chair_tile"}}
:enddata
:endrule

rule:
plugin=blockTile
number=88
data:
JSON:{blockState:{blockName:"ancientwarfarestructure:chair",properties:{visible:"true",variant:"birch",facing:"south"}},facing:"south",teData:{facing:"north",id:"ancientwarfarestructure:chair_tile"}}
:enddata
:endrule

rule:
plugin=blockTile
number=89
data:
JSON:{blockState:{blockName:"ancientwarfarestructure:chair",properties:{visible:"true",variant:"birch",facing:"south"}},facing:"south",teData:{facing:"north",id:"ancientwarfarestructure:chair_tile"}}
:enddata
:endrule

rule:
plugin=vanillaBlocks
number=90
data:
JSON:{blockState:{blockName:"minecraft:ladder",properties:{facing:"south"}}}
:enddata
:endrule

rule:
plugin=blockTile
number=91
data:
JSON:{blockState:{blockName:"ancientwarfarestructure:advanced_spawner",properties:{transparent:"true"}},teData:{id:"ancientwarfarestructure:advanced_spawner_tile",spawnerSettings:{minDelay:10,spawnDelay:6,lightSensitive:0b,spawnGroups:[{settingsList:[{remainingSpawnCount:1,hostile:1b,customTag:{ArmorDropChances:[0.085f,0.085f,0.085f,0.085f],hasCustomEquipment:0b,ArmorItems:[{},{},{},{}],skinSettings:{npcTypeName:"custom",skinTypeSelected:"default"},HandDropChances:[0.085f,0.085f],factionName:"sarkonid",HandItems:[{},{}]},maxToSpawn:1,entityId:"ancientwarfarenpc:faction.civilian.male",minToSpawn:1}],groupWeight:1}],playerRange:16,respondToRedstone:0b,inventory:{Size:9,Items:[]},spawnRange:0,transparent:1b,maxDelay:10,spawnYOffset:0,xpToDrop:0,mobRange:0,debugMode:0b,maxNearbyMonsters:0}}}
:enddata
:endrule

rule:
plugin=doors
number=92
data:
JSON:{blockState:{blockName:"minecraft:spruce_door",properties:{hinge:"left",half:"lower",powered:"false",facing:"south",open:"false"}}}
:enddata
:endrule

rule:
plugin=blockTile
number=93
data:
JSON:{blockState:{blockName:"ancientwarfarestructure:chair",properties:{visible:"false",variant:"birch",facing:"south"}},facing:"north",teData:{facing:"south",id:"ancientwarfarestructure:chair_tile",mainBlockPos:-204233144009710L}}
:enddata
:endrule

rule:
plugin=blockTile
number=94
data:
JSON:{blockState:{blockName:"ancientwarfarestructure:chair",properties:{visible:"false",variant:"birch",facing:"south"}},facing:"north",teData:{facing:"south",id:"ancientwarfarestructure:chair_tile",mainBlockPos:-203958266102766L}}
:enddata
:endrule

rule:
plugin=blockTile
number=95
data:
JSON:{blockState:{blockName:"ancientwarfarestructure:chair",properties:{visible:"false",variant:"birch",facing:"south"}},facing:"north",teData:{facing:"south",id:"ancientwarfarestructure:chair_tile",mainBlockPos:-203683388195822L}}
:enddata
:endrule

rule:
plugin=blockTile
number=96
data:
JSON:{blockState:{blockName:"ancientwarfarestructure:chair",properties:{visible:"false",variant:"birch",facing:"south"}},facing:"south",teData:{facing:"north",id:"ancientwarfarestructure:chair_tile",mainBlockPos:-204233144009707L}}
:enddata
:endrule

rule:
plugin=blockTile
number=97
data:
JSON:{blockState:{blockName:"ancientwarfarestructure:chair",properties:{visible:"false",variant:"birch",facing:"south"}},facing:"south",teData:{facing:"north",id:"ancientwarfarestructure:chair_tile",mainBlockPos:-203958266102763L}}
:enddata
:endrule

rule:
plugin=blockTile
number=98
data:
JSON:{blockState:{blockName:"ancientwarfarestructure:chair",properties:{visible:"false",variant:"birch",facing:"south"}},facing:"south",teData:{facing:"north",id:"ancientwarfarestructure:chair_tile",mainBlockPos:-203683388195819L}}
:enddata
:endrule

rule:
plugin=doors
number=99
data:
JSON:{blockState:{blockName:"minecraft:spruce_door",properties:{hinge:"right",half:"upper",powered:"false",facing:"south",open:"false"}}}
:enddata
:endrule

rule:
plugin=vanillaSign
number=100
data:
JSON:{signContents0:"Sarkovid§r",blockState:{blockName:"minecraft:wall_sign",properties:{facing:"south"}},signContents2:"Bumgurn§r",signContents1:"",signContents3:"Brewery§r",rotation:0}
:enddata
:endrule

rule:
plugin=vanillaSign
number=101
data:
JSON:{signContents0:"Sarkovid§r",blockState:{blockName:"minecraft:wall_sign",properties:{facing:"east"}},signContents2:"Bumgurn§r",signContents1:"",signContents3:"Brewery§r",rotation:0}
:enddata
:endrule

rule:
plugin=vanillaSign
number=102
data:
JSON:{signContents0:"Sarkovid§r",blockState:{blockName:"minecraft:wall_sign",properties:{facing:"west"}},signContents2:"Bumgurn§r",signContents1:"",signContents3:"Brewery§r",rotation:0}
:enddata
:endrule

rule:
plugin=vanillaBlocks
number=103
data:
JSON:{blockState:{blockName:"minecraft:wooden_slab",properties:{half:"top",variant:"spruce"}}}
:enddata
:endrule

rule:
plugin=vanillaBlocks
number=104
data:
JSON:{blockState:{blockName:"minecraft:red_sandstone",properties:{type:"red_sandstone"}}}
:enddata
:endrule

rule:
plugin=vanillaBlocks
number=105
data:
JSON:{blockState:{blockName:"minecraft:wooden_button",properties:{powered:"false",facing:"down"}}}
:enddata
:endrule

rule:
plugin=vanillaBlocks
number=106
data:
JSON:{blockState:{blockName:"minecraft:planks",properties:{variant:"birch"}}}
:enddata
:endrule

rule:
plugin=vanillaBlocks
number=107
data:
JSON:{blockState:{blockName:"minecraft:wool",properties:{color:"silver"}}}
:enddata
:endrule

rule:
plugin=vanillaBlocks
number=108
data:
JSON:{blockState:{blockName:"minecraft:wool",properties:{color:"white"}}}
:enddata
:endrule

rule:
plugin=vanillaBlocks
number=109
data:
JSON:{blockState:{blockName:"minecraft:wooden_button",properties:{powered:"false",facing:"south"}}}
:enddata
:endrule

rule:
plugin=vanillaBlocks
number=110
data:
JSON:{blockState:{blockName:"minecraft:wooden_button",properties:{powered:"false",facing:"east"}}}
:enddata
:endrule

rule:
plugin=vanillaBlocks
number=111
data:
JSON:{blockState:{blockName:"minecraft:log",properties:{variant:"oak",axis:"z"}}}
:enddata
:endrule

rule:
plugin=vanillaBlocks
number=112
data:
JSON:{blockState:{blockName:"minecraft:wooden_button",properties:{powered:"false",facing:"west"}}}
:enddata
:endrule

rule:
plugin=vanillaBlocks
number=113
data:
JSON:{blockState:{blockName:"minecraft:wooden_button",properties:{powered:"false",facing:"up"}}}
:enddata
:endrule

#### ENTITIES ####
